package apocalypse.fandomcraft.fable;

import net.minecraft.world.*;
import java.util.*;
import net.minecraft.init.*;
import net.minecraft.block.*;
import net.minecraft.tileentity.*;
import net.minecraftforge.common.*;
import net.minecraft.util.*;
import net.minecraft.inventory.*;
import net.minecraft.world.gen.structure.*;
import net.minecraft.nbt.*;

public class StructureTemple extends StructureComponent
{
    public void generateSurface(final World world, final Random random, final int chunkX, final int chunkY, final int chunkZ) {
        final int h = world.getHeightValue(chunkX, chunkZ) - 7;
        if (random.nextInt(10) + 1 <= 9) {
            final boolean place = true;
            if (place) {
                world.setBlock(chunkX + 1, h + 0, chunkZ + 1, Blocks.stonebrick, 3, 2);
                world.setBlock(chunkX + 2, h + 0, chunkZ + 1, Blocks.stonebrick, 3, 2);
                world.setBlock(chunkX + 3, h + 0, chunkZ + 1, Blocks.stonebrick, 3, 2);
                world.setBlock(chunkX + 4, h + 0, chunkZ + 1, Blocks.stonebrick, 3, 2);
                world.setBlock(chunkX + 5, h + 0, chunkZ + 1, Blocks.stonebrick, 3, 2);
                world.setBlock(chunkX + 6, h + 0, chunkZ + 1, Blocks.stonebrick, 3, 2);
                world.setBlock(chunkX + 7, h + 0, chunkZ + 1, Blocks.stonebrick, 3, 2);
                world.setBlock(chunkX + 8, h + 0, chunkZ + 1, Blocks.stonebrick, 3, 2);
                world.setBlock(chunkX + 9, h + 0, chunkZ + 1, Blocks.stonebrick, 3, 2);
                world.setBlock(chunkX + 1, h + 0, chunkZ + 2, Blocks.stonebrick, 3, 2);
                world.setBlock(chunkX + 2, h + 0, chunkZ + 2, Blocks.nether_brick, 0, 2);
                world.setBlock(chunkX + 3, h + 0, chunkZ + 2, Blocks.nether_brick, 0, 2);
                world.setBlock(chunkX + 4, h + 0, chunkZ + 2, Blocks.nether_brick, 0, 2);
                world.setBlock(chunkX + 5, h + 0, chunkZ + 2, Blocks.nether_brick, 0, 2);
                world.setBlock(chunkX + 6, h + 0, chunkZ + 2, Blocks.nether_brick, 0, 2);
                world.setBlock(chunkX + 7, h + 0, chunkZ + 2, Blocks.nether_brick, 0, 2);
                world.setBlock(chunkX + 8, h + 0, chunkZ + 2, Blocks.nether_brick, 0, 2);
                world.setBlock(chunkX + 9, h + 0, chunkZ + 2, Blocks.stonebrick, 3, 2);
                world.setBlock(chunkX + 1, h + 0, chunkZ + 3, Blocks.stonebrick, 3, 2);
                world.setBlock(chunkX + 2, h + 0, chunkZ + 3, Blocks.nether_brick, 0, 2);
                world.setBlock(chunkX + 3, h + 0, chunkZ + 3, Blocks.nether_brick, 0, 2);
                world.setBlock(chunkX + 4, h + 0, chunkZ + 3, Blocks.nether_brick, 0, 2);
                world.setBlock(chunkX + 5, h + 0, chunkZ + 3, Blocks.nether_brick, 0, 2);
                world.setBlock(chunkX + 6, h + 0, chunkZ + 3, Blocks.nether_brick, 0, 2);
                world.setBlock(chunkX + 7, h + 0, chunkZ + 3, Blocks.nether_brick, 0, 2);
                world.setBlock(chunkX + 8, h + 0, chunkZ + 3, Blocks.nether_brick, 0, 2);
                world.setBlock(chunkX + 9, h + 0, chunkZ + 3, Blocks.stonebrick, 3, 2);
                world.setBlock(chunkX + 1, h + 0, chunkZ + 4, Blocks.stonebrick, 3, 2);
                world.setBlock(chunkX + 2, h + 0, chunkZ + 4, Blocks.nether_brick, 0, 2);
                world.setBlock(chunkX + 3, h + 0, chunkZ + 4, Blocks.nether_brick, 0, 2);
                world.setBlock(chunkX + 4, h + 0, chunkZ + 4, Blocks.nether_brick, 0, 2);
                world.setBlock(chunkX + 5, h + 0, chunkZ + 4, Blocks.nether_brick, 0, 2);
                world.setBlock(chunkX + 6, h + 0, chunkZ + 4, Blocks.nether_brick, 0, 2);
                world.setBlock(chunkX + 7, h + 0, chunkZ + 4, Blocks.nether_brick, 0, 2);
                world.setBlock(chunkX + 8, h + 0, chunkZ + 4, Blocks.nether_brick, 0, 2);
                world.setBlock(chunkX + 9, h + 0, chunkZ + 4, Blocks.stonebrick, 3, 2);
                world.setBlock(chunkX + 10, h + 0, chunkZ + 4, Blocks.air, 0, 2);
                world.setBlock(chunkX + 0, h + 0, chunkZ + 5, Blocks.air, 0, 2);
                world.setBlock(chunkX + 1, h + 0, chunkZ + 5, Blocks.stonebrick, 3, 2);
                world.setBlock(chunkX + 2, h + 0, chunkZ + 5, Blocks.nether_brick, 0, 2);
                world.setBlock(chunkX + 3, h + 0, chunkZ + 5, Blocks.nether_brick, 0, 2);
                world.setBlock(chunkX + 4, h + 0, chunkZ + 5, Blocks.nether_brick, 0, 2);
                world.setBlock(chunkX + 5, h + 0, chunkZ + 5, Blocks.nether_brick, 0, 2);
                world.setBlock(chunkX + 6, h + 0, chunkZ + 5, Blocks.nether_brick, 0, 2);
                world.setBlock(chunkX + 7, h + 0, chunkZ + 5, Blocks.nether_brick, 0, 2);
                world.setBlock(chunkX + 8, h + 0, chunkZ + 5, Blocks.nether_brick, 0, 2);
                world.setBlock(chunkX + 9, h + 0, chunkZ + 5, Blocks.stonebrick, 3, 2);
                world.setBlock(chunkX + 1, h + 0, chunkZ + 6, Blocks.stonebrick, 3, 2);
                world.setBlock(chunkX + 2, h + 0, chunkZ + 6, Blocks.nether_brick, 0, 2);
                world.setBlock(chunkX + 3, h + 0, chunkZ + 6, Blocks.nether_brick, 0, 2);
                world.setBlock(chunkX + 4, h + 0, chunkZ + 6, Blocks.nether_brick, 0, 2);
                world.setBlock(chunkX + 5, h + 0, chunkZ + 6, Blocks.nether_brick, 0, 2);
                world.setBlock(chunkX + 6, h + 0, chunkZ + 6, Blocks.nether_brick, 0, 2);
                world.setBlock(chunkX + 7, h + 0, chunkZ + 6, Blocks.nether_brick, 0, 2);
                world.setBlock(chunkX + 8, h + 0, chunkZ + 6, Blocks.nether_brick, 0, 2);
                world.setBlock(chunkX + 9, h + 0, chunkZ + 6, Blocks.stonebrick, 3, 2);
                world.setBlock(chunkX + 1, h + 0, chunkZ + 7, Blocks.stonebrick, 3, 2);
                world.setBlock(chunkX + 2, h + 0, chunkZ + 7, Blocks.nether_brick, 0, 2);
                world.setBlock(chunkX + 3, h + 0, chunkZ + 7, Blocks.nether_brick, 0, 2);
                world.setBlock(chunkX + 4, h + 0, chunkZ + 7, Blocks.nether_brick, 0, 2);
                world.setBlock(chunkX + 5, h + 0, chunkZ + 7, Blocks.nether_brick, 0, 2);
                world.setBlock(chunkX + 6, h + 0, chunkZ + 7, Blocks.nether_brick, 0, 2);
                world.setBlock(chunkX + 7, h + 0, chunkZ + 7, Blocks.nether_brick, 0, 2);
                world.setBlock(chunkX + 8, h + 0, chunkZ + 7, Blocks.nether_brick, 0, 2);
                world.setBlock(chunkX + 9, h + 0, chunkZ + 7, Blocks.stonebrick, 3, 2);
                world.setBlock(chunkX + 1, h + 0, chunkZ + 8, Blocks.stonebrick, 3, 2);
                world.setBlock(chunkX + 2, h + 0, chunkZ + 8, Blocks.nether_brick, 0, 2);
                world.setBlock(chunkX + 3, h + 0, chunkZ + 8, Blocks.nether_brick, 0, 2);
                world.setBlock(chunkX + 4, h + 0, chunkZ + 8, Blocks.nether_brick, 0, 2);
                world.setBlock(chunkX + 5, h + 0, chunkZ + 8, Blocks.nether_brick, 0, 2);
                world.setBlock(chunkX + 6, h + 0, chunkZ + 8, Blocks.nether_brick, 0, 2);
                world.setBlock(chunkX + 7, h + 0, chunkZ + 8, Blocks.nether_brick, 0, 2);
                world.setBlock(chunkX + 8, h + 0, chunkZ + 8, Blocks.nether_brick, 0, 2);
                world.setBlock(chunkX + 9, h + 0, chunkZ + 8, Blocks.stonebrick, 3, 2);
                world.setBlock(chunkX + 1, h + 0, chunkZ + 9, Blocks.stonebrick, 3, 2);
                world.setBlock(chunkX + 2, h + 0, chunkZ + 9, Blocks.nether_brick, 0, 2);
                world.setBlock(chunkX + 3, h + 0, chunkZ + 9, Blocks.nether_brick, 0, 2);
                world.setBlock(chunkX + 4, h + 0, chunkZ + 9, Blocks.nether_brick, 0, 2);
                world.setBlock(chunkX + 5, h + 0, chunkZ + 9, Blocks.nether_brick, 0, 2);
                world.setBlock(chunkX + 6, h + 0, chunkZ + 9, Blocks.nether_brick, 0, 2);
                world.setBlock(chunkX + 7, h + 0, chunkZ + 9, Blocks.nether_brick, 0, 2);
                world.setBlock(chunkX + 8, h + 0, chunkZ + 9, Blocks.nether_brick, 0, 2);
                world.setBlock(chunkX + 9, h + 0, chunkZ + 9, Blocks.stonebrick, 3, 2);
                world.setBlock(chunkX + 1, h + 0, chunkZ + 10, Blocks.stonebrick, 3, 2);
                world.setBlock(chunkX + 2, h + 0, chunkZ + 10, Blocks.nether_brick, 0, 2);
                world.setBlock(chunkX + 3, h + 0, chunkZ + 10, Blocks.nether_brick, 0, 2);
                world.setBlock(chunkX + 4, h + 0, chunkZ + 10, Blocks.nether_brick, 0, 2);
                world.setBlock(chunkX + 5, h + 0, chunkZ + 10, Blocks.nether_brick, 0, 2);
                world.setBlock(chunkX + 6, h + 0, chunkZ + 10, Blocks.nether_brick, 0, 2);
                world.setBlock(chunkX + 7, h + 0, chunkZ + 10, Blocks.nether_brick, 0, 2);
                world.setBlock(chunkX + 8, h + 0, chunkZ + 10, Blocks.nether_brick, 0, 2);
                world.setBlock(chunkX + 9, h + 0, chunkZ + 10, Blocks.stonebrick, 3, 2);
                world.setBlock(chunkX + 1, h + 0, chunkZ + 11, Blocks.stonebrick, 3, 2);
                world.setBlock(chunkX + 2, h + 0, chunkZ + 11, Blocks.nether_brick, 0, 2);
                world.setBlock(chunkX + 3, h + 0, chunkZ + 11, Blocks.nether_brick, 0, 2);
                world.setBlock(chunkX + 4, h + 0, chunkZ + 11, Blocks.nether_brick, 0, 2);
                world.setBlock(chunkX + 5, h + 0, chunkZ + 11, Blocks.nether_brick, 0, 2);
                world.setBlock(chunkX + 6, h + 0, chunkZ + 11, Blocks.nether_brick, 0, 2);
                world.setBlock(chunkX + 7, h + 0, chunkZ + 11, Blocks.nether_brick, 0, 2);
                world.setBlock(chunkX + 8, h + 0, chunkZ + 11, Blocks.nether_brick, 0, 2);
                world.setBlock(chunkX + 9, h + 0, chunkZ + 11, Blocks.stonebrick, 3, 2);
                world.setBlock(chunkX + 1, h + 0, chunkZ + 12, Blocks.stonebrick, 3, 2);
                world.setBlock(chunkX + 2, h + 0, chunkZ + 12, Blocks.stonebrick, 3, 2);
                world.setBlock(chunkX + 3, h + 0, chunkZ + 12, Blocks.stonebrick, 3, 2);
                world.setBlock(chunkX + 4, h + 0, chunkZ + 12, Blocks.stonebrick, 3, 2);
                world.setBlock(chunkX + 5, h + 0, chunkZ + 12, Blocks.stonebrick, 3, 2);
                world.setBlock(chunkX + 6, h + 0, chunkZ + 12, Blocks.stonebrick, 3, 2);
                world.setBlock(chunkX + 7, h + 0, chunkZ + 12, Blocks.stonebrick, 3, 2);
                world.setBlock(chunkX + 8, h + 0, chunkZ + 12, Blocks.stonebrick, 3, 2);
                world.setBlock(chunkX + 9, h + 0, chunkZ + 12, Blocks.stonebrick, 3, 2);
                world.setBlock(chunkX + 0, h + 1, chunkZ + 0, Blocks.air, 0, 2);
                world.setBlock(chunkX + 1, h + 1, chunkZ + 0, Blocks.air, 0, 2);
                world.setBlock(chunkX + 2, h + 1, chunkZ + 0, Blocks.air, 0, 2);
                world.setBlock(chunkX + 3, h + 1, chunkZ + 0, Blocks.air, 0, 2);
                world.setBlock(chunkX + 4, h + 1, chunkZ + 0, Blocks.air, 0, 2);
                world.setBlock(chunkX + 5, h + 1, chunkZ + 0, Blocks.air, 0, 2);
                world.setBlock(chunkX + 6, h + 1, chunkZ + 0, Blocks.air, 0, 2);
                world.setBlock(chunkX + 7, h + 1, chunkZ + 0, Blocks.air, 0, 2);
                world.setBlock(chunkX + 8, h + 1, chunkZ + 0, Blocks.air, 0, 2);
                world.setBlock(chunkX + 9, h + 1, chunkZ + 0, Blocks.air, 0, 2);
                world.setBlock(chunkX + 10, h + 1, chunkZ + 0, Blocks.air, 0, 2);
                world.setBlock(chunkX + 0, h + 1, chunkZ + 1, Blocks.air, 0, 2);
                world.setBlock(chunkX + 1, h + 1, chunkZ + 1, Blocks.stonebrick, 3, 2);
                world.setBlock(chunkX + 2, h + 1, chunkZ + 1, Blocks.stonebrick, 3, 2);
                world.setBlock(chunkX + 3, h + 1, chunkZ + 1, Blocks.stonebrick, 3, 2);
                world.setBlock(chunkX + 4, h + 1, chunkZ + 1, Blocks.stonebrick, 3, 2);
                world.setBlock(chunkX + 5, h + 1, chunkZ + 1, Blocks.stonebrick, 3, 2);
                world.setBlock(chunkX + 6, h + 1, chunkZ + 1, Blocks.stonebrick, 3, 2);
                world.setBlock(chunkX + 7, h + 1, chunkZ + 1, Blocks.stonebrick, 3, 2);
                world.setBlock(chunkX + 8, h + 1, chunkZ + 1, Blocks.stonebrick, 3, 2);
                world.setBlock(chunkX + 9, h + 1, chunkZ + 1, Blocks.stonebrick, 3, 2);
                world.setBlock(chunkX + 10, h + 1, chunkZ + 1, Blocks.air, 0, 2);
                world.setBlock(chunkX + 0, h + 1, chunkZ + 2, Blocks.air, 0, 2);
                world.setBlock(chunkX + 1, h + 1, chunkZ + 2, Blocks.stonebrick, 3, 2);
                world.setBlock(chunkX + 2, h + 1, chunkZ + 2, Blocks.air, 0, 2);
                world.setBlock(chunkX + 3, h + 1, chunkZ + 2, Blocks.air, 0, 2);
                world.setBlock(chunkX + 4, h + 1, chunkZ + 2, Blocks.air, 0, 2);
                world.setBlock(chunkX + 5, h + 1, chunkZ + 2, Blocks.air, 0, 2);
                world.setBlock(chunkX + 6, h + 1, chunkZ + 2, Blocks.air, 0, 2);
                world.setBlock(chunkX + 7, h + 1, chunkZ + 2, Blocks.air, 0, 2);
                world.setBlock(chunkX + 8, h + 1, chunkZ + 2, Blocks.air, 0, 2);
                world.setBlock(chunkX + 9, h + 1, chunkZ + 2, Blocks.stonebrick, 3, 2);
                world.setBlock(chunkX + 10, h + 1, chunkZ + 2, Blocks.air, 0, 2);
                world.setBlock(chunkX + 0, h + 1, chunkZ + 3, Blocks.air, 0, 2);
                world.setBlock(chunkX + 1, h + 1, chunkZ + 3, Blocks.stonebrick, 3, 2);
                world.setBlock(chunkX + 2, h + 1, chunkZ + 3, Blocks.air, 0, 2);
                world.setBlock(chunkX + 3, h + 1, chunkZ + 3, Blocks.air, 0, 2);
                world.setBlock(chunkX + 4, h + 1, chunkZ + 3, Blocks.air, 0, 2);
                world.setBlock(chunkX + 5, h + 1, chunkZ + 3, Blocks.air, 0, 2);
                world.setBlock(chunkX + 6, h + 1, chunkZ + 3, Blocks.air, 0, 2);
                world.setBlock(chunkX + 7, h + 1, chunkZ + 3, Blocks.air, 0, 2);
                world.setBlock(chunkX + 8, h + 1, chunkZ + 3, Blocks.air, 0, 2);
                world.setBlock(chunkX + 9, h + 1, chunkZ + 3, Blocks.stonebrick, 3, 2);
                world.setBlock(chunkX + 10, h + 1, chunkZ + 3, Blocks.air, 0, 2);
                world.setBlock(chunkX + 0, h + 1, chunkZ + 4, Blocks.air, 0, 2);
                world.setBlock(chunkX + 1, h + 1, chunkZ + 4, Blocks.stonebrick, 3, 2);
                world.setBlock(chunkX + 2, h + 1, chunkZ + 4, Blocks.air, 0, 2);
                world.setBlock(chunkX + 3, h + 1, chunkZ + 4, Blocks.air, 0, 2);
                world.setBlock(chunkX + 4, h + 1, chunkZ + 4, Blocks.air, 0, 2);
                world.setBlock(chunkX + 5, h + 1, chunkZ + 4, Blocks.air, 0, 2);
                world.setBlock(chunkX + 6, h + 1, chunkZ + 4, Blocks.air, 0, 2);
                world.setBlock(chunkX + 7, h + 1, chunkZ + 4, Blocks.air, 0, 2);
                world.setBlock(chunkX + 8, h + 1, chunkZ + 4, Blocks.air, 0, 2);
                world.setBlock(chunkX + 9, h + 1, chunkZ + 4, Blocks.stonebrick, 3, 2);
                world.setBlock(chunkX + 10, h + 1, chunkZ + 4, Blocks.air, 0, 2);
                world.setBlock(chunkX + 0, h + 1, chunkZ + 5, Blocks.air, 0, 2);
                world.setBlock(chunkX + 1, h + 1, chunkZ + 5, Blocks.stonebrick, 3, 2);
                world.setBlock(chunkX + 2, h + 1, chunkZ + 5, Blocks.air, 0, 2);
                world.setBlock(chunkX + 3, h + 1, chunkZ + 5, Blocks.air, 0, 2);
                world.setBlock(chunkX + 4, h + 1, chunkZ + 5, Blocks.air, 0, 2);
                world.setBlock(chunkX + 5, h + 1, chunkZ + 5, Blocks.air, 0, 2);
                world.setBlock(chunkX + 6, h + 1, chunkZ + 5, Blocks.air, 0, 2);
                world.setBlock(chunkX + 7, h + 1, chunkZ + 5, Blocks.air, 0, 2);
                world.setBlock(chunkX + 8, h + 1, chunkZ + 5, Blocks.air, 0, 2);
                world.setBlock(chunkX + 9, h + 1, chunkZ + 5, Blocks.stonebrick, 3, 2);
                world.setBlock(chunkX + 10, h + 1, chunkZ + 5, Blocks.air, 0, 2);
                world.setBlock(chunkX + 0, h + 1, chunkZ + 6, Blocks.air, 0, 2);
                world.setBlock(chunkX + 1, h + 1, chunkZ + 6, Blocks.stonebrick, 3, 2);
                world.setBlock(chunkX + 2, h + 1, chunkZ + 6, Blocks.air, 0, 2);
                world.setBlock(chunkX + 3, h + 1, chunkZ + 6, Blocks.air, 0, 2);
                world.setBlock(chunkX + 4, h + 1, chunkZ + 6, Blocks.air, 0, 2);
                world.setBlock(chunkX + 5, h + 1, chunkZ + 6, Blocks.air, 0, 2);
                world.setBlock(chunkX + 6, h + 1, chunkZ + 6, Blocks.air, 0, 2);
                world.setBlock(chunkX + 7, h + 1, chunkZ + 6, Blocks.air, 0, 2);
                world.setBlock(chunkX + 8, h + 1, chunkZ + 6, Blocks.air, 0, 2);
                world.setBlock(chunkX + 9, h + 1, chunkZ + 6, Blocks.stonebrick, 3, 2);
                world.setBlock(chunkX + 10, h + 1, chunkZ + 6, Blocks.air, 0, 2);
                world.setBlock(chunkX + 0, h + 1, chunkZ + 7, Blocks.air, 0, 2);
                world.setBlock(chunkX + 1, h + 1, chunkZ + 7, Blocks.stonebrick, 3, 2);
                world.setBlock(chunkX + 2, h + 1, chunkZ + 7, Blocks.air, 0, 2);
                world.setBlock(chunkX + 3, h + 1, chunkZ + 7, Blocks.air, 0, 2);
                world.setBlock(chunkX + 4, h + 1, chunkZ + 7, Blocks.air, 0, 2);
                world.setBlock(chunkX + 5, h + 1, chunkZ + 7, Blocks.air, 0, 2);
                world.setBlock(chunkX + 6, h + 1, chunkZ + 7, Blocks.air, 0, 2);
                world.setBlock(chunkX + 7, h + 1, chunkZ + 7, Blocks.air, 0, 2);
                world.setBlock(chunkX + 8, h + 1, chunkZ + 7, Blocks.air, 0, 2);
                world.setBlock(chunkX + 9, h + 1, chunkZ + 7, Blocks.stonebrick, 3, 2);
                world.setBlock(chunkX + 10, h + 1, chunkZ + 7, Blocks.air, 0, 2);
                world.setBlock(chunkX + 0, h + 1, chunkZ + 8, Blocks.air, 0, 2);
                world.setBlock(chunkX + 1, h + 1, chunkZ + 8, Blocks.stonebrick, 3, 2);
                world.setBlock(chunkX + 2, h + 1, chunkZ + 8, Blocks.air, 0, 2);
                world.setBlock(chunkX + 3, h + 1, chunkZ + 8, Blocks.air, 0, 2);
                world.setBlock(chunkX + 4, h + 1, chunkZ + 8, Blocks.air, 0, 2);
                world.setBlock(chunkX + 5, h + 1, chunkZ + 8, Blocks.mob_spawner, 0, 2);
                final int xm = chunkX + 5;
                final int ym = h + 1;
                final int zm = chunkZ + 8;
                final TileEntityMobSpawner tileentitymobspawner = (TileEntityMobSpawner)world.getTileEntity(xm, ym, zm);
                if (tileentitymobspawner == null) {
                    System.err.println("Failed to fetch mob spawner entity at (" + xm + ", " + ym + ", " + zm + ")");
                }
                else {
                    tileentitymobspawner.func_145881_a().setEntityName("EntityHollowMan");
                }
                world.setBlock(chunkX + 6, h + 1, chunkZ + 8, Blocks.air, 0, 2);
                world.setBlock(chunkX + 7, h + 1, chunkZ + 8, Blocks.air, 0, 2);
                world.setBlock(chunkX + 8, h + 1, chunkZ + 8, Blocks.air, 0, 2);
                world.setBlock(chunkX + 9, h + 1, chunkZ + 8, Blocks.stonebrick, 3, 2);
                world.setBlock(chunkX + 10, h + 1, chunkZ + 8, Blocks.air, 0, 2);
                world.setBlock(chunkX + 0, h + 1, chunkZ + 9, Blocks.air, 0, 2);
                world.setBlock(chunkX + 1, h + 1, chunkZ + 9, Blocks.stonebrick, 3, 2);
                world.setBlock(chunkX + 2, h + 1, chunkZ + 9, Blocks.air, 0, 2);
                world.setBlock(chunkX + 3, h + 1, chunkZ + 9, Blocks.air, 0, 2);
                world.setBlock(chunkX + 4, h + 1, chunkZ + 9, Blocks.air, 0, 2);
                world.setBlock(chunkX + 5, h + 1, chunkZ + 9, Blocks.air, 0, 2);
                world.setBlock(chunkX + 6, h + 1, chunkZ + 9, Blocks.air, 0, 2);
                world.setBlock(chunkX + 7, h + 1, chunkZ + 9, Blocks.air, 0, 2);
                world.setBlock(chunkX + 8, h + 1, chunkZ + 9, Blocks.air, 0, 2);
                world.setBlock(chunkX + 9, h + 1, chunkZ + 9, Blocks.stonebrick, 3, 2);
                world.setBlock(chunkX + 10, h + 1, chunkZ + 9, Blocks.air, 0, 2);
                world.setBlock(chunkX + 0, h + 1, chunkZ + 10, Blocks.air, 0, 2);
                world.setBlock(chunkX + 1, h + 1, chunkZ + 10, Blocks.stonebrick, 3, 2);
                world.setBlock(chunkX + 2, h + 1, chunkZ + 10, Blocks.air, 0, 2);
                world.setBlock(chunkX + 3, h + 1, chunkZ + 10, Blocks.air, 0, 2);
                world.setBlock(chunkX + 4, h + 1, chunkZ + 10, Blocks.air, 0, 2);
                world.setBlock(chunkX + 5, h + 1, chunkZ + 10, Blocks.air, 0, 2);
                world.setBlock(chunkX + 6, h + 1, chunkZ + 10, Blocks.air, 0, 2);
                world.setBlock(chunkX + 7, h + 1, chunkZ + 10, Blocks.air, 0, 2);
                world.setBlock(chunkX + 8, h + 1, chunkZ + 10, Blocks.air, 0, 2);
                world.setBlock(chunkX + 9, h + 1, chunkZ + 10, Blocks.stonebrick, 3, 2);
                world.setBlock(chunkX + 10, h + 1, chunkZ + 10, Blocks.air, 0, 2);
                world.setBlock(chunkX + 0, h + 1, chunkZ + 11, Blocks.air, 0, 2);
                world.setBlock(chunkX + 1, h + 1, chunkZ + 11, Blocks.stonebrick, 3, 2);
                world.setBlock(chunkX + 2, h + 1, chunkZ + 11, Blocks.air, 0, 2);
                world.setBlock(chunkX + 3, h + 1, chunkZ + 11, Blocks.air, 0, 2);
                world.setBlock(chunkX + 4, h + 1, chunkZ + 11, Blocks.air, 0, 2);
                world.setBlock(chunkX + 5, h + 1, chunkZ + 11, Blocks.air, 0, 2);
                world.setBlock(chunkX + 6, h + 1, chunkZ + 11, Blocks.air, 0, 2);
                world.setBlock(chunkX + 7, h + 1, chunkZ + 11, Blocks.air, 0, 2);
                world.setBlock(chunkX + 8, h + 1, chunkZ + 11, Blocks.air, 0, 2);
                world.setBlock(chunkX + 9, h + 1, chunkZ + 11, Blocks.stonebrick, 3, 2);
                world.setBlock(chunkX + 10, h + 1, chunkZ + 11, Blocks.air, 0, 2);
                world.setBlock(chunkX + 0, h + 1, chunkZ + 12, Blocks.air, 0, 2);
                world.setBlock(chunkX + 1, h + 1, chunkZ + 12, Blocks.stonebrick, 3, 2);
                world.setBlock(chunkX + 2, h + 1, chunkZ + 12, Blocks.stonebrick, 3, 2);
                world.setBlock(chunkX + 3, h + 1, chunkZ + 12, Blocks.stonebrick, 3, 2);
                world.setBlock(chunkX + 4, h + 1, chunkZ + 12, Blocks.stonebrick, 3, 2);
                world.setBlock(chunkX + 5, h + 1, chunkZ + 12, Blocks.stonebrick, 3, 2);
                world.setBlock(chunkX + 6, h + 1, chunkZ + 12, Blocks.stonebrick, 3, 2);
                world.setBlock(chunkX + 7, h + 1, chunkZ + 12, Blocks.stonebrick, 3, 2);
                world.setBlock(chunkX + 8, h + 1, chunkZ + 12, Blocks.stonebrick, 3, 2);
                world.setBlock(chunkX + 9, h + 1, chunkZ + 12, Blocks.stonebrick, 3, 2);
                world.setBlock(chunkX + 10, h + 1, chunkZ + 12, Blocks.air, 0, 2);
                world.setBlock(chunkX + 0, h + 1, chunkZ + 13, Blocks.air, 0, 2);
                world.setBlock(chunkX + 1, h + 1, chunkZ + 13, Blocks.air, 0, 2);
                world.setBlock(chunkX + 2, h + 1, chunkZ + 13, Blocks.air, 0, 2);
                world.setBlock(chunkX + 3, h + 1, chunkZ + 13, Blocks.air, 0, 2);
                world.setBlock(chunkX + 4, h + 1, chunkZ + 13, Blocks.air, 0, 2);
                world.setBlock(chunkX + 5, h + 1, chunkZ + 13, Blocks.air, 0, 2);
                world.setBlock(chunkX + 6, h + 1, chunkZ + 13, Blocks.air, 0, 2);
                world.setBlock(chunkX + 7, h + 1, chunkZ + 13, Blocks.air, 0, 2);
                world.setBlock(chunkX + 8, h + 1, chunkZ + 13, Blocks.air, 0, 2);
                world.setBlock(chunkX + 9, h + 1, chunkZ + 13, Blocks.air, 0, 2);
                world.setBlock(chunkX + 10, h + 1, chunkZ + 13, Blocks.air, 0, 2);
                world.setBlock(chunkX + 0, h + 2, chunkZ + 0, Blocks.air, 0, 2);
                world.setBlock(chunkX + 1, h + 2, chunkZ + 0, Blocks.air, 0, 2);
                world.setBlock(chunkX + 2, h + 2, chunkZ + 0, Blocks.air, 0, 2);
                world.setBlock(chunkX + 3, h + 2, chunkZ + 0, Blocks.air, 0, 2);
                world.setBlock(chunkX + 4, h + 2, chunkZ + 0, Blocks.air, 0, 2);
                world.setBlock(chunkX + 5, h + 2, chunkZ + 0, Blocks.air, 0, 2);
                world.setBlock(chunkX + 6, h + 2, chunkZ + 0, Blocks.air, 0, 2);
                world.setBlock(chunkX + 7, h + 2, chunkZ + 0, Blocks.air, 0, 2);
                world.setBlock(chunkX + 8, h + 2, chunkZ + 0, Blocks.air, 0, 2);
                world.setBlock(chunkX + 9, h + 2, chunkZ + 0, Blocks.air, 0, 2);
                world.setBlock(chunkX + 10, h + 2, chunkZ + 0, Blocks.air, 0, 2);
                world.setBlock(chunkX + 0, h + 2, chunkZ + 1, Blocks.air, 0, 2);
                world.setBlock(chunkX + 1, h + 2, chunkZ + 1, Blocks.stonebrick, 3, 2);
                world.setBlock(chunkX + 2, h + 2, chunkZ + 1, Blocks.stonebrick, 3, 2);
                world.setBlock(chunkX + 3, h + 2, chunkZ + 1, Blocks.stonebrick, 3, 2);
                world.setBlock(chunkX + 4, h + 2, chunkZ + 1, Blocks.stonebrick, 3, 2);
                world.setBlock(chunkX + 5, h + 2, chunkZ + 1, Blocks.stonebrick, 3, 2);
                world.setBlock(chunkX + 6, h + 2, chunkZ + 1, Blocks.stonebrick, 3, 2);
                world.setBlock(chunkX + 7, h + 2, chunkZ + 1, Blocks.stonebrick, 3, 2);
                world.setBlock(chunkX + 8, h + 2, chunkZ + 1, Blocks.stonebrick, 3, 2);
                world.setBlock(chunkX + 9, h + 2, chunkZ + 1, Blocks.stonebrick, 3, 2);
                world.setBlock(chunkX + 10, h + 2, chunkZ + 1, Blocks.air, 0, 2);
                world.setBlock(chunkX + 0, h + 2, chunkZ + 2, Blocks.air, 0, 2);
                world.setBlock(chunkX + 1, h + 2, chunkZ + 2, Blocks.stonebrick, 3, 2);
                world.setBlock(chunkX + 2, h + 2, chunkZ + 2, Blocks.air, 0, 2);
                world.setBlock(chunkX + 3, h + 2, chunkZ + 2, Blocks.air, 0, 2);
                world.setBlock(chunkX + 4, h + 2, chunkZ + 2, Blocks.air, 0, 2);
                world.setBlock(chunkX + 5, h + 2, chunkZ + 2, Blocks.air, 0, 2);
                world.setBlock(chunkX + 6, h + 2, chunkZ + 2, Blocks.air, 0, 2);
                world.setBlock(chunkX + 7, h + 2, chunkZ + 2, Blocks.air, 0, 2);
                world.setBlock(chunkX + 8, h + 2, chunkZ + 2, Blocks.air, 0, 2);
                world.setBlock(chunkX + 9, h + 2, chunkZ + 2, Blocks.stonebrick, 3, 2);
                world.setBlock(chunkX + 10, h + 2, chunkZ + 2, Blocks.air, 0, 2);
                world.setBlock(chunkX + 0, h + 2, chunkZ + 3, Blocks.air, 0, 2);
                world.setBlock(chunkX + 1, h + 2, chunkZ + 3, Blocks.stonebrick, 3, 2);
                world.setBlock(chunkX + 2, h + 2, chunkZ + 3, Blocks.air, 0, 2);
                world.setBlock(chunkX + 3, h + 2, chunkZ + 3, Blocks.air, 0, 2);
                world.setBlock(chunkX + 4, h + 2, chunkZ + 3, Blocks.air, 0, 2);
                world.setBlock(chunkX + 5, h + 2, chunkZ + 3, Blocks.air, 0, 2);
                world.setBlock(chunkX + 6, h + 2, chunkZ + 3, Blocks.air, 0, 2);
                world.setBlock(chunkX + 7, h + 2, chunkZ + 3, Blocks.air, 0, 2);
                world.setBlock(chunkX + 8, h + 2, chunkZ + 3, Blocks.air, 0, 2);
                world.setBlock(chunkX + 9, h + 2, chunkZ + 3, Blocks.stonebrick, 3, 2);
                world.setBlock(chunkX + 10, h + 2, chunkZ + 3, Blocks.air, 0, 2);
                world.setBlock(chunkX + 0, h + 2, chunkZ + 4, Blocks.air, 0, 2);
                world.setBlock(chunkX + 1, h + 2, chunkZ + 4, Blocks.stonebrick, 3, 2);
                world.setBlock(chunkX + 2, h + 2, chunkZ + 4, Blocks.air, 0, 2);
                world.setBlock(chunkX + 3, h + 2, chunkZ + 4, Blocks.air, 0, 2);
                world.setBlock(chunkX + 4, h + 2, chunkZ + 4, Blocks.air, 0, 2);
                world.setBlock(chunkX + 5, h + 2, chunkZ + 4, Blocks.air, 0, 2);
                world.setBlock(chunkX + 6, h + 2, chunkZ + 4, Blocks.air, 0, 2);
                world.setBlock(chunkX + 7, h + 2, chunkZ + 4, Blocks.air, 0, 2);
                world.setBlock(chunkX + 8, h + 2, chunkZ + 4, Blocks.air, 0, 2);
                world.setBlock(chunkX + 9, h + 2, chunkZ + 4, Blocks.stonebrick, 3, 2);
                world.setBlock(chunkX + 10, h + 2, chunkZ + 4, Blocks.air, 0, 2);
                world.setBlock(chunkX + 0, h + 2, chunkZ + 5, Blocks.air, 0, 2);
                world.setBlock(chunkX + 1, h + 2, chunkZ + 5, Blocks.stonebrick, 3, 2);
                world.setBlock(chunkX + 2, h + 2, chunkZ + 5, Blocks.air, 0, 2);
                world.setBlock(chunkX + 3, h + 2, chunkZ + 5, Blocks.air, 0, 2);
                world.setBlock(chunkX + 4, h + 2, chunkZ + 5, Blocks.air, 0, 2);
                world.setBlock(chunkX + 5, h + 2, chunkZ + 5, Blocks.air, 0, 2);
                world.setBlock(chunkX + 6, h + 2, chunkZ + 5, Blocks.air, 0, 2);
                world.setBlock(chunkX + 7, h + 2, chunkZ + 5, Blocks.air, 0, 2);
                world.setBlock(chunkX + 8, h + 2, chunkZ + 5, Blocks.air, 0, 2);
                world.setBlock(chunkX + 9, h + 2, chunkZ + 5, Blocks.stonebrick, 3, 2);
                world.setBlock(chunkX + 10, h + 2, chunkZ + 5, Blocks.air, 0, 2);
                world.setBlock(chunkX + 0, h + 2, chunkZ + 6, Blocks.air, 0, 2);
                world.setBlock(chunkX + 1, h + 2, chunkZ + 6, Blocks.stonebrick, 3, 2);
                world.setBlock(chunkX + 2, h + 2, chunkZ + 6, Blocks.air, 0, 2);
                world.setBlock(chunkX + 3, h + 2, chunkZ + 6, Blocks.air, 0, 2);
                world.setBlock(chunkX + 4, h + 2, chunkZ + 6, Blocks.air, 0, 2);
                world.setBlock(chunkX + 5, h + 2, chunkZ + 6, Blocks.air, 0, 2);
                world.setBlock(chunkX + 6, h + 2, chunkZ + 6, Blocks.air, 0, 2);
                world.setBlock(chunkX + 7, h + 2, chunkZ + 6, Blocks.air, 0, 2);
                world.setBlock(chunkX + 8, h + 2, chunkZ + 6, Blocks.air, 0, 2);
                world.setBlock(chunkX + 9, h + 2, chunkZ + 6, Blocks.stonebrick, 3, 2);
                world.setBlock(chunkX + 10, h + 2, chunkZ + 6, Blocks.air, 0, 2);
                world.setBlock(chunkX + 0, h + 2, chunkZ + 7, Blocks.air, 0, 2);
                world.setBlock(chunkX + 1, h + 2, chunkZ + 7, Blocks.stonebrick, 3, 2);
                world.setBlock(chunkX + 2, h + 2, chunkZ + 7, Blocks.air, 0, 2);
                world.setBlock(chunkX + 3, h + 2, chunkZ + 7, Blocks.air, 0, 2);
                world.setBlock(chunkX + 4, h + 2, chunkZ + 7, Blocks.air, 0, 2);
                world.setBlock(chunkX + 5, h + 2, chunkZ + 7, Blocks.air, 0, 2);
                world.setBlock(chunkX + 6, h + 2, chunkZ + 7, Blocks.air, 0, 2);
                world.setBlock(chunkX + 7, h + 2, chunkZ + 7, Blocks.air, 0, 2);
                world.setBlock(chunkX + 8, h + 2, chunkZ + 7, Blocks.air, 0, 2);
                world.setBlock(chunkX + 9, h + 2, chunkZ + 7, Blocks.stonebrick, 3, 2);
                world.setBlock(chunkX + 10, h + 2, chunkZ + 7, Blocks.air, 0, 2);
                world.setBlock(chunkX + 0, h + 2, chunkZ + 8, Blocks.air, 0, 2);
                world.setBlock(chunkX + 1, h + 2, chunkZ + 8, Blocks.stonebrick, 3, 2);
                world.setBlock(chunkX + 2, h + 2, chunkZ + 8, Blocks.air, 0, 2);
                world.setBlock(chunkX + 3, h + 2, chunkZ + 8, Blocks.air, 0, 2);
                world.setBlock(chunkX + 4, h + 2, chunkZ + 8, Blocks.air, 0, 2);
                world.setBlock(chunkX + 5, h + 2, chunkZ + 8, Blocks.air, 0, 2);
                world.setBlock(chunkX + 6, h + 2, chunkZ + 8, Blocks.air, 0, 2);
                world.setBlock(chunkX + 7, h + 2, chunkZ + 8, Blocks.air, 0, 2);
                world.setBlock(chunkX + 8, h + 2, chunkZ + 8, Blocks.air, 0, 2);
                world.setBlock(chunkX + 9, h + 2, chunkZ + 8, Blocks.stonebrick, 3, 2);
                world.setBlock(chunkX + 10, h + 2, chunkZ + 8, Blocks.air, 0, 2);
                world.setBlock(chunkX + 0, h + 2, chunkZ + 9, Blocks.air, 0, 2);
                world.setBlock(chunkX + 1, h + 2, chunkZ + 9, Blocks.stonebrick, 3, 2);
                world.setBlock(chunkX + 2, h + 2, chunkZ + 9, Blocks.air, 0, 2);
                world.setBlock(chunkX + 3, h + 2, chunkZ + 9, Blocks.air, 0, 2);
                world.setBlock(chunkX + 4, h + 2, chunkZ + 9, Blocks.air, 0, 2);
                world.setBlock(chunkX + 5, h + 2, chunkZ + 9, Blocks.air, 0, 2);
                world.setBlock(chunkX + 6, h + 2, chunkZ + 9, Blocks.air, 0, 2);
                world.setBlock(chunkX + 7, h + 2, chunkZ + 9, Blocks.air, 0, 2);
                world.setBlock(chunkX + 8, h + 2, chunkZ + 9, Blocks.air, 0, 2);
                world.setBlock(chunkX + 9, h + 2, chunkZ + 9, Blocks.stonebrick, 3, 2);
                world.setBlock(chunkX + 10, h + 2, chunkZ + 9, Blocks.air, 0, 2);
                world.setBlock(chunkX + 0, h + 2, chunkZ + 10, Blocks.air, 0, 2);
                world.setBlock(chunkX + 1, h + 2, chunkZ + 10, Blocks.stonebrick, 3, 2);
                world.setBlock(chunkX + 2, h + 2, chunkZ + 10, Blocks.air, 0, 2);
                world.setBlock(chunkX + 3, h + 2, chunkZ + 10, Blocks.air, 0, 2);
                world.setBlock(chunkX + 4, h + 2, chunkZ + 10, Blocks.air, 0, 2);
                world.setBlock(chunkX + 5, h + 2, chunkZ + 10, Blocks.air, 0, 2);
                world.setBlock(chunkX + 6, h + 2, chunkZ + 10, Blocks.air, 0, 2);
                world.setBlock(chunkX + 7, h + 2, chunkZ + 10, Blocks.air, 0, 2);
                world.setBlock(chunkX + 8, h + 2, chunkZ + 10, Blocks.air, 0, 2);
                world.setBlock(chunkX + 9, h + 2, chunkZ + 10, Blocks.stonebrick, 3, 2);
                world.setBlock(chunkX + 10, h + 2, chunkZ + 10, Blocks.air, 0, 2);
                world.setBlock(chunkX + 0, h + 2, chunkZ + 11, Blocks.air, 0, 2);
                world.setBlock(chunkX + 1, h + 2, chunkZ + 11, Blocks.stonebrick, 3, 2);
                world.setBlock(chunkX + 2, h + 2, chunkZ + 11, Blocks.air, 0, 2);
                world.setBlock(chunkX + 3, h + 2, chunkZ + 11, Blocks.air, 0, 2);
                world.setBlock(chunkX + 4, h + 2, chunkZ + 11, Blocks.air, 0, 2);
                world.setBlock(chunkX + 5, h + 2, chunkZ + 11, Blocks.air, 0, 2);
                world.setBlock(chunkX + 6, h + 2, chunkZ + 11, Blocks.air, 0, 2);
                world.setBlock(chunkX + 7, h + 2, chunkZ + 11, Blocks.air, 0, 2);
                world.setBlock(chunkX + 8, h + 2, chunkZ + 11, Blocks.air, 0, 2);
                world.setBlock(chunkX + 9, h + 2, chunkZ + 11, Blocks.stonebrick, 3, 2);
                world.setBlock(chunkX + 10, h + 2, chunkZ + 11, Blocks.air, 0, 2);
                world.setBlock(chunkX + 0, h + 2, chunkZ + 12, Blocks.air, 0, 2);
                world.setBlock(chunkX + 1, h + 2, chunkZ + 12, Blocks.stonebrick, 3, 2);
                world.setBlock(chunkX + 2, h + 2, chunkZ + 12, Blocks.stonebrick, 3, 2);
                world.setBlock(chunkX + 3, h + 2, chunkZ + 12, Blocks.stonebrick, 3, 2);
                world.setBlock(chunkX + 4, h + 2, chunkZ + 12, Blocks.stonebrick, 3, 2);
                world.setBlock(chunkX + 5, h + 2, chunkZ + 12, Blocks.stonebrick, 3, 2);
                world.setBlock(chunkX + 6, h + 2, chunkZ + 12, Blocks.stonebrick, 3, 2);
                world.setBlock(chunkX + 7, h + 2, chunkZ + 12, Blocks.stonebrick, 3, 2);
                world.setBlock(chunkX + 8, h + 2, chunkZ + 12, Blocks.stonebrick, 3, 2);
                world.setBlock(chunkX + 9, h + 2, chunkZ + 12, Blocks.stonebrick, 3, 2);
                world.setBlock(chunkX + 10, h + 2, chunkZ + 12, Blocks.air, 0, 2);
                world.setBlock(chunkX + 0, h + 2, chunkZ + 13, Blocks.air, 0, 2);
                world.setBlock(chunkX + 1, h + 2, chunkZ + 13, Blocks.air, 0, 2);
                world.setBlock(chunkX + 2, h + 2, chunkZ + 13, Blocks.air, 0, 2);
                world.setBlock(chunkX + 3, h + 2, chunkZ + 13, Blocks.air, 0, 2);
                world.setBlock(chunkX + 4, h + 2, chunkZ + 13, Blocks.air, 0, 2);
                world.setBlock(chunkX + 5, h + 2, chunkZ + 13, Blocks.air, 0, 2);
                world.setBlock(chunkX + 6, h + 2, chunkZ + 13, Blocks.air, 0, 2);
                world.setBlock(chunkX + 7, h + 2, chunkZ + 13, Blocks.air, 0, 2);
                world.setBlock(chunkX + 8, h + 2, chunkZ + 13, Blocks.air, 0, 2);
                world.setBlock(chunkX + 9, h + 2, chunkZ + 13, Blocks.air, 0, 2);
                world.setBlock(chunkX + 10, h + 2, chunkZ + 13, Blocks.air, 0, 2);
                world.setBlock(chunkX + 0, h + 3, chunkZ + 0, Blocks.air, 0, 2);
                world.setBlock(chunkX + 1, h + 3, chunkZ + 0, Blocks.air, 0, 2);
                world.setBlock(chunkX + 2, h + 3, chunkZ + 0, Blocks.air, 0, 2);
                world.setBlock(chunkX + 3, h + 3, chunkZ + 0, Blocks.air, 0, 2);
                world.setBlock(chunkX + 4, h + 3, chunkZ + 0, Blocks.air, 0, 2);
                world.setBlock(chunkX + 5, h + 3, chunkZ + 0, Blocks.air, 0, 2);
                world.setBlock(chunkX + 6, h + 3, chunkZ + 0, Blocks.air, 0, 2);
                world.setBlock(chunkX + 7, h + 3, chunkZ + 0, Blocks.air, 0, 2);
                world.setBlock(chunkX + 8, h + 3, chunkZ + 0, Blocks.air, 0, 2);
                world.setBlock(chunkX + 9, h + 3, chunkZ + 0, Blocks.air, 0, 2);
                world.setBlock(chunkX + 10, h + 3, chunkZ + 0, Blocks.air, 0, 2);
                world.setBlock(chunkX + 0, h + 3, chunkZ + 1, Blocks.air, 0, 2);
                world.setBlock(chunkX + 1, h + 3, chunkZ + 1, Blocks.stonebrick, 3, 2);
                world.setBlock(chunkX + 2, h + 3, chunkZ + 1, Blocks.stonebrick, 3, 2);
                world.setBlock(chunkX + 3, h + 3, chunkZ + 1, Blocks.stonebrick, 3, 2);
                world.setBlock(chunkX + 4, h + 3, chunkZ + 1, Blocks.stonebrick, 3, 2);
                world.setBlock(chunkX + 5, h + 3, chunkZ + 1, Blocks.stonebrick, 3, 2);
                world.setBlock(chunkX + 6, h + 3, chunkZ + 1, Blocks.stonebrick, 3, 2);
                world.setBlock(chunkX + 7, h + 3, chunkZ + 1, Blocks.stonebrick, 3, 2);
                world.setBlock(chunkX + 8, h + 3, chunkZ + 1, Blocks.stonebrick, 3, 2);
                world.setBlock(chunkX + 9, h + 3, chunkZ + 1, Blocks.stonebrick, 3, 2);
                world.setBlock(chunkX + 10, h + 3, chunkZ + 1, Blocks.air, 0, 2);
                world.setBlock(chunkX + 0, h + 3, chunkZ + 2, Blocks.air, 0, 2);
                world.setBlock(chunkX + 1, h + 3, chunkZ + 2, Blocks.stonebrick, 3, 2);
                world.setBlock(chunkX + 2, h + 3, chunkZ + 2, Blocks.air, 0, 2);
                world.setBlock(chunkX + 3, h + 3, chunkZ + 2, Blocks.air, 0, 2);
                world.setBlock(chunkX + 4, h + 3, chunkZ + 2, Blocks.stonebrick, 0, 2);
                world.setBlock(chunkX + 5, h + 3, chunkZ + 2, Blocks.stonebrick, 0, 2);
                world.setBlock(chunkX + 6, h + 3, chunkZ + 2, Blocks.stonebrick, 0, 2);
                world.setBlock(chunkX + 7, h + 3, chunkZ + 2, Blocks.air, 0, 2);
                world.setBlock(chunkX + 8, h + 3, chunkZ + 2, Blocks.air, 0, 2);
                world.setBlock(chunkX + 9, h + 3, chunkZ + 2, Blocks.stonebrick, 3, 2);
                world.setBlock(chunkX + 10, h + 3, chunkZ + 2, Blocks.air, 0, 2);
                world.setBlock(chunkX + 0, h + 3, chunkZ + 3, Blocks.air, 0, 2);
                world.setBlock(chunkX + 1, h + 3, chunkZ + 3, Blocks.stonebrick, 3, 2);
                world.setBlock(chunkX + 2, h + 3, chunkZ + 3, Blocks.air, 0, 2);
                world.setBlock(chunkX + 3, h + 3, chunkZ + 3, Blocks.air, 0, 2);
                world.setBlock(chunkX + 4, h + 3, chunkZ + 3, Blocks.air, 0, 2);
                world.setBlock(chunkX + 5, h + 3, chunkZ + 3, Blocks.air, 0, 2);
                world.setBlock(chunkX + 6, h + 3, chunkZ + 3, Blocks.air, 0, 2);
                world.setBlock(chunkX + 7, h + 3, chunkZ + 3, Blocks.air, 0, 2);
                world.setBlock(chunkX + 8, h + 3, chunkZ + 3, Blocks.air, 0, 2);
                world.setBlock(chunkX + 9, h + 3, chunkZ + 3, Blocks.stonebrick, 3, 2);
                world.setBlock(chunkX + 10, h + 3, chunkZ + 3, Blocks.air, 0, 2);
                world.setBlock(chunkX + 0, h + 3, chunkZ + 4, Blocks.air, 0, 2);
                world.setBlock(chunkX + 1, h + 3, chunkZ + 4, Blocks.stonebrick, 3, 2);
                world.setBlock(chunkX + 2, h + 3, chunkZ + 4, Blocks.air, 0, 2);
                world.setBlock(chunkX + 3, h + 3, chunkZ + 4, Blocks.air, 0, 2);
                world.setBlock(chunkX + 4, h + 3, chunkZ + 4, Blocks.air, 0, 2);
                world.setBlock(chunkX + 5, h + 3, chunkZ + 4, Blocks.air, 0, 2);
                world.setBlock(chunkX + 6, h + 3, chunkZ + 4, Blocks.air, 0, 2);
                world.setBlock(chunkX + 7, h + 3, chunkZ + 4, Blocks.air, 0, 2);
                world.setBlock(chunkX + 8, h + 3, chunkZ + 4, Blocks.air, 0, 2);
                world.setBlock(chunkX + 9, h + 3, chunkZ + 4, Blocks.stonebrick, 3, 2);
                world.setBlock(chunkX + 10, h + 3, chunkZ + 4, Blocks.air, 0, 2);
                world.setBlock(chunkX + 0, h + 3, chunkZ + 5, Blocks.air, 0, 2);
                world.setBlock(chunkX + 1, h + 3, chunkZ + 5, Blocks.stonebrick, 3, 2);
                world.setBlock(chunkX + 2, h + 3, chunkZ + 5, Blocks.air, 0, 2);
                world.setBlock(chunkX + 3, h + 3, chunkZ + 5, Blocks.air, 0, 2);
                world.setBlock(chunkX + 4, h + 3, chunkZ + 5, Blocks.air, 0, 2);
                world.setBlock(chunkX + 5, h + 3, chunkZ + 5, Blocks.air, 0, 2);
                world.setBlock(chunkX + 6, h + 3, chunkZ + 5, Blocks.air, 0, 2);
                world.setBlock(chunkX + 7, h + 3, chunkZ + 5, Blocks.air, 0, 2);
                world.setBlock(chunkX + 8, h + 3, chunkZ + 5, Blocks.air, 0, 2);
                world.setBlock(chunkX + 9, h + 3, chunkZ + 5, Blocks.stonebrick, 3, 2);
                world.setBlock(chunkX + 10, h + 3, chunkZ + 5, Blocks.air, 0, 2);
                world.setBlock(chunkX + 0, h + 3, chunkZ + 6, Blocks.air, 0, 2);
                world.setBlock(chunkX + 1, h + 3, chunkZ + 6, Blocks.stonebrick, 3, 2);
                world.setBlock(chunkX + 2, h + 3, chunkZ + 6, Blocks.air, 0, 2);
                world.setBlock(chunkX + 3, h + 3, chunkZ + 6, Blocks.air, 0, 2);
                world.setBlock(chunkX + 4, h + 3, chunkZ + 6, Blocks.air, 0, 2);
                world.setBlock(chunkX + 5, h + 3, chunkZ + 6, Blocks.air, 0, 2);
                world.setBlock(chunkX + 6, h + 3, chunkZ + 6, Blocks.air, 0, 2);
                world.setBlock(chunkX + 7, h + 3, chunkZ + 6, Blocks.air, 0, 2);
                world.setBlock(chunkX + 8, h + 3, chunkZ + 6, Blocks.air, 0, 2);
                world.setBlock(chunkX + 9, h + 3, chunkZ + 6, Blocks.stonebrick, 3, 2);
                world.setBlock(chunkX + 10, h + 3, chunkZ + 6, Blocks.air, 0, 2);
                world.setBlock(chunkX + 0, h + 3, chunkZ + 7, Blocks.air, 0, 2);
                world.setBlock(chunkX + 1, h + 3, chunkZ + 7, Blocks.stonebrick, 3, 2);
                world.setBlock(chunkX + 2, h + 3, chunkZ + 7, Blocks.air, 0, 2);
                world.setBlock(chunkX + 3, h + 3, chunkZ + 7, Blocks.air, 0, 2);
                world.setBlock(chunkX + 4, h + 3, chunkZ + 7, Blocks.air, 0, 2);
                world.setBlock(chunkX + 5, h + 3, chunkZ + 7, Blocks.air, 0, 2);
                world.setBlock(chunkX + 6, h + 3, chunkZ + 7, Blocks.air, 0, 2);
                world.setBlock(chunkX + 7, h + 3, chunkZ + 7, Blocks.air, 0, 2);
                world.setBlock(chunkX + 8, h + 3, chunkZ + 7, Blocks.air, 0, 2);
                world.setBlock(chunkX + 9, h + 3, chunkZ + 7, Blocks.stonebrick, 3, 2);
                world.setBlock(chunkX + 10, h + 3, chunkZ + 7, Blocks.air, 0, 2);
                world.setBlock(chunkX + 0, h + 3, chunkZ + 8, Blocks.air, 0, 2);
                world.setBlock(chunkX + 1, h + 3, chunkZ + 8, Blocks.stonebrick, 3, 2);
                world.setBlock(chunkX + 2, h + 3, chunkZ + 8, Blocks.air, 0, 2);
                world.setBlock(chunkX + 3, h + 3, chunkZ + 8, Blocks.air, 0, 2);
                world.setBlock(chunkX + 4, h + 3, chunkZ + 8, Blocks.air, 0, 2);
                world.setBlock(chunkX + 5, h + 3, chunkZ + 8, Blocks.air, 0, 2);
                world.setBlock(chunkX + 6, h + 3, chunkZ + 8, Blocks.air, 0, 2);
                world.setBlock(chunkX + 7, h + 3, chunkZ + 8, Blocks.air, 0, 2);
                world.setBlock(chunkX + 8, h + 3, chunkZ + 8, Blocks.air, 0, 2);
                world.setBlock(chunkX + 9, h + 3, chunkZ + 8, Blocks.stonebrick, 3, 2);
                world.setBlock(chunkX + 10, h + 3, chunkZ + 8, Blocks.air, 0, 2);
                world.setBlock(chunkX + 0, h + 3, chunkZ + 9, Blocks.air, 0, 2);
                world.setBlock(chunkX + 1, h + 3, chunkZ + 9, Blocks.stonebrick, 3, 2);
                world.setBlock(chunkX + 2, h + 3, chunkZ + 9, Blocks.air, 0, 2);
                world.setBlock(chunkX + 3, h + 3, chunkZ + 9, Blocks.air, 0, 2);
                world.setBlock(chunkX + 4, h + 3, chunkZ + 9, Blocks.air, 0, 2);
                world.setBlock(chunkX + 5, h + 3, chunkZ + 9, Blocks.air, 0, 2);
                world.setBlock(chunkX + 6, h + 3, chunkZ + 9, Blocks.air, 0, 2);
                world.setBlock(chunkX + 7, h + 3, chunkZ + 9, Blocks.air, 0, 2);
                world.setBlock(chunkX + 8, h + 3, chunkZ + 9, Blocks.air, 0, 2);
                world.setBlock(chunkX + 9, h + 3, chunkZ + 9, Blocks.stonebrick, 3, 2);
                world.setBlock(chunkX + 10, h + 3, chunkZ + 9, Blocks.air, 0, 2);
                world.setBlock(chunkX + 0, h + 3, chunkZ + 10, Blocks.air, 0, 2);
                world.setBlock(chunkX + 1, h + 3, chunkZ + 10, Blocks.stonebrick, 3, 2);
                world.setBlock(chunkX + 2, h + 3, chunkZ + 10, Blocks.air, 0, 2);
                world.setBlock(chunkX + 3, h + 3, chunkZ + 10, Blocks.air, 0, 2);
                world.setBlock(chunkX + 4, h + 3, chunkZ + 10, Blocks.air, 0, 2);
                world.setBlock(chunkX + 5, h + 3, chunkZ + 10, Blocks.air, 0, 2);
                world.setBlock(chunkX + 6, h + 3, chunkZ + 10, Blocks.air, 0, 2);
                world.setBlock(chunkX + 7, h + 3, chunkZ + 10, Blocks.air, 0, 2);
                world.setBlock(chunkX + 8, h + 3, chunkZ + 10, Blocks.air, 0, 2);
                world.setBlock(chunkX + 9, h + 3, chunkZ + 10, Blocks.stonebrick, 3, 2);
                world.setBlock(chunkX + 10, h + 3, chunkZ + 10, Blocks.air, 0, 2);
                world.setBlock(chunkX + 0, h + 3, chunkZ + 11, Blocks.air, 0, 2);
                world.setBlock(chunkX + 1, h + 3, chunkZ + 11, Blocks.stonebrick, 3, 2);
                world.setBlock(chunkX + 2, h + 3, chunkZ + 11, Blocks.air, 0, 2);
                world.setBlock(chunkX + 3, h + 3, chunkZ + 11, Blocks.air, 0, 2);
                world.setBlock(chunkX + 4, h + 3, chunkZ + 11, Blocks.air, 0, 2);
                world.setBlock(chunkX + 5, h + 3, chunkZ + 11, Blocks.air, 0, 2);
                world.setBlock(chunkX + 6, h + 3, chunkZ + 11, Blocks.air, 0, 2);
                world.setBlock(chunkX + 7, h + 3, chunkZ + 11, Blocks.air, 0, 2);
                world.setBlock(chunkX + 8, h + 3, chunkZ + 11, Blocks.air, 0, 2);
                world.setBlock(chunkX + 9, h + 3, chunkZ + 11, Blocks.stonebrick, 3, 2);
                world.setBlock(chunkX + 10, h + 3, chunkZ + 11, Blocks.air, 0, 2);
                world.setBlock(chunkX + 0, h + 3, chunkZ + 12, Blocks.air, 0, 2);
                world.setBlock(chunkX + 1, h + 3, chunkZ + 12, Blocks.stonebrick, 3, 2);
                world.setBlock(chunkX + 2, h + 3, chunkZ + 12, Blocks.stonebrick, 3, 2);
                world.setBlock(chunkX + 3, h + 3, chunkZ + 12, Blocks.stonebrick, 3, 2);
                world.setBlock(chunkX + 4, h + 3, chunkZ + 12, Blocks.stonebrick, 3, 2);
                world.setBlock(chunkX + 5, h + 3, chunkZ + 12, Blocks.stonebrick, 3, 2);
                world.setBlock(chunkX + 6, h + 3, chunkZ + 12, Blocks.stonebrick, 3, 2);
                world.setBlock(chunkX + 7, h + 3, chunkZ + 12, Blocks.stonebrick, 3, 2);
                world.setBlock(chunkX + 8, h + 3, chunkZ + 12, Blocks.stonebrick, 3, 2);
                world.setBlock(chunkX + 9, h + 3, chunkZ + 12, Blocks.stonebrick, 3, 2);
                world.setBlock(chunkX + 10, h + 3, chunkZ + 12, Blocks.air, 0, 2);
                world.setBlock(chunkX + 0, h + 3, chunkZ + 13, Blocks.air, 0, 2);
                world.setBlock(chunkX + 1, h + 3, chunkZ + 13, Blocks.air, 0, 2);
                world.setBlock(chunkX + 2, h + 3, chunkZ + 13, Blocks.air, 0, 2);
                world.setBlock(chunkX + 3, h + 3, chunkZ + 13, Blocks.air, 0, 2);
                world.setBlock(chunkX + 4, h + 3, chunkZ + 13, Blocks.air, 0, 2);
                world.setBlock(chunkX + 5, h + 3, chunkZ + 13, Blocks.air, 0, 2);
                world.setBlock(chunkX + 6, h + 3, chunkZ + 13, Blocks.air, 0, 2);
                world.setBlock(chunkX + 7, h + 3, chunkZ + 13, Blocks.air, 0, 2);
                world.setBlock(chunkX + 8, h + 3, chunkZ + 13, Blocks.air, 0, 2);
                world.setBlock(chunkX + 9, h + 3, chunkZ + 13, Blocks.air, 0, 2);
                world.setBlock(chunkX + 10, h + 3, chunkZ + 13, Blocks.air, 0, 2);
                world.setBlock(chunkX + 0, h + 4, chunkZ + 0, Blocks.air, 0, 2);
                world.setBlock(chunkX + 1, h + 4, chunkZ + 0, Blocks.air, 0, 2);
                world.setBlock(chunkX + 2, h + 4, chunkZ + 0, Blocks.air, 0, 2);
                world.setBlock(chunkX + 3, h + 4, chunkZ + 0, Blocks.air, 0, 2);
                world.setBlock(chunkX + 4, h + 4, chunkZ + 0, Blocks.air, 0, 2);
                world.setBlock(chunkX + 5, h + 4, chunkZ + 0, Blocks.air, 0, 2);
                world.setBlock(chunkX + 6, h + 4, chunkZ + 0, Blocks.air, 0, 2);
                world.setBlock(chunkX + 7, h + 4, chunkZ + 0, Blocks.air, 0, 2);
                world.setBlock(chunkX + 8, h + 4, chunkZ + 0, Blocks.air, 0, 2);
                world.setBlock(chunkX + 9, h + 4, chunkZ + 0, Blocks.air, 0, 2);
                world.setBlock(chunkX + 10, h + 4, chunkZ + 0, Blocks.air, 0, 2);
                world.setBlock(chunkX + 0, h + 4, chunkZ + 1, Blocks.air, 0, 2);
                world.setBlock(chunkX + 1, h + 4, chunkZ + 1, Blocks.stonebrick, 3, 2);
                world.setBlock(chunkX + 2, h + 4, chunkZ + 1, Blocks.stonebrick, 3, 2);
                world.setBlock(chunkX + 3, h + 4, chunkZ + 1, Blocks.stonebrick, 3, 2);
                world.setBlock(chunkX + 4, h + 4, chunkZ + 1, Blocks.stonebrick, 3, 2);
                world.setBlock(chunkX + 5, h + 4, chunkZ + 1, Blocks.stonebrick, 3, 2);
                world.setBlock(chunkX + 6, h + 4, chunkZ + 1, Blocks.stonebrick, 3, 2);
                world.setBlock(chunkX + 7, h + 4, chunkZ + 1, Blocks.stonebrick, 3, 2);
                world.setBlock(chunkX + 8, h + 4, chunkZ + 1, Blocks.stonebrick, 3, 2);
                world.setBlock(chunkX + 9, h + 4, chunkZ + 1, Blocks.stonebrick, 3, 2);
                world.setBlock(chunkX + 10, h + 4, chunkZ + 1, Blocks.air, 0, 2);
                world.setBlock(chunkX + 0, h + 4, chunkZ + 2, Blocks.air, 0, 2);
                world.setBlock(chunkX + 1, h + 4, chunkZ + 2, Blocks.stonebrick, 3, 2);
                world.setBlock(chunkX + 2, h + 4, chunkZ + 2, Blocks.air, 0, 2);
                world.setBlock(chunkX + 3, h + 4, chunkZ + 2, Blocks.air, 0, 2);
                world.setBlock(chunkX + 4, h + 4, chunkZ + 2, Blocks.air, 0, 2);
                world.setBlock(chunkX + 5, h + 4, chunkZ + 2, (Block)Blocks.chest, 3, 2);
                final int x = chunkX + 5;
                final int y = h + 4;
                final int z = chunkZ + 2;
                final TileEntityChest tileentitychest = (TileEntityChest)world.getTileEntity(x, y, z);
                if (tileentitychest != null) {
                    WeightedRandomChestContent.generateChestContents(random, ChestGenHooks.getItems("strongholdLibrary", random), (IInventory)tileentitychest, ChestGenHooks.getCount("strongholdLibrary", random));
                }
                world.setBlock(chunkX + 6, h + 4, chunkZ + 2, Blocks.air, 0, 2);
                world.setBlock(chunkX + 7, h + 4, chunkZ + 2, Blocks.air, 0, 2);
                world.setBlock(chunkX + 8, h + 4, chunkZ + 2, Blocks.air, 0, 2);
                world.setBlock(chunkX + 9, h + 4, chunkZ + 2, Blocks.stonebrick, 3, 2);
                world.setBlock(chunkX + 10, h + 4, chunkZ + 2, Blocks.air, 0, 2);
                world.setBlock(chunkX + 0, h + 4, chunkZ + 3, Blocks.air, 0, 2);
                world.setBlock(chunkX + 1, h + 4, chunkZ + 3, Blocks.stonebrick, 3, 2);
                world.setBlock(chunkX + 2, h + 4, chunkZ + 3, Blocks.air, 0, 2);
                world.setBlock(chunkX + 3, h + 4, chunkZ + 3, Blocks.air, 0, 2);
                world.setBlock(chunkX + 4, h + 4, chunkZ + 3, Blocks.air, 0, 2);
                world.setBlock(chunkX + 5, h + 4, chunkZ + 3, Blocks.air, 0, 2);
                world.setBlock(chunkX + 6, h + 4, chunkZ + 3, Blocks.air, 0, 2);
                world.setBlock(chunkX + 7, h + 4, chunkZ + 3, Blocks.air, 0, 2);
                world.setBlock(chunkX + 8, h + 4, chunkZ + 3, Blocks.air, 0, 2);
                world.setBlock(chunkX + 9, h + 4, chunkZ + 3, Blocks.stonebrick, 3, 2);
                world.setBlock(chunkX + 10, h + 4, chunkZ + 3, Blocks.air, 0, 2);
                world.setBlock(chunkX + 0, h + 4, chunkZ + 4, Blocks.air, 0, 2);
                world.setBlock(chunkX + 1, h + 4, chunkZ + 4, Blocks.stonebrick, 3, 2);
                world.setBlock(chunkX + 2, h + 4, chunkZ + 4, Blocks.air, 0, 2);
                world.setBlock(chunkX + 3, h + 4, chunkZ + 4, Blocks.air, 0, 2);
                world.setBlock(chunkX + 4, h + 4, chunkZ + 4, Blocks.air, 0, 2);
                world.setBlock(chunkX + 5, h + 4, chunkZ + 4, Blocks.air, 0, 2);
                world.setBlock(chunkX + 6, h + 4, chunkZ + 4, Blocks.air, 0, 2);
                world.setBlock(chunkX + 7, h + 4, chunkZ + 4, Blocks.air, 0, 2);
                world.setBlock(chunkX + 8, h + 4, chunkZ + 4, Blocks.air, 0, 2);
                world.setBlock(chunkX + 9, h + 4, chunkZ + 4, Blocks.stonebrick, 3, 2);
                world.setBlock(chunkX + 10, h + 4, chunkZ + 4, Blocks.air, 0, 2);
                world.setBlock(chunkX + 0, h + 4, chunkZ + 5, Blocks.air, 0, 2);
                world.setBlock(chunkX + 1, h + 4, chunkZ + 5, Blocks.stonebrick, 3, 2);
                world.setBlock(chunkX + 2, h + 4, chunkZ + 5, Blocks.air, 0, 2);
                world.setBlock(chunkX + 3, h + 4, chunkZ + 5, Blocks.air, 0, 2);
                world.setBlock(chunkX + 4, h + 4, chunkZ + 5, Blocks.air, 0, 2);
                world.setBlock(chunkX + 5, h + 4, chunkZ + 5, Blocks.air, 0, 2);
                world.setBlock(chunkX + 6, h + 4, chunkZ + 5, Blocks.air, 0, 2);
                world.setBlock(chunkX + 7, h + 4, chunkZ + 5, Blocks.air, 0, 2);
                world.setBlock(chunkX + 8, h + 4, chunkZ + 5, Blocks.air, 0, 2);
                world.setBlock(chunkX + 9, h + 4, chunkZ + 5, Blocks.stonebrick, 3, 2);
                world.setBlock(chunkX + 10, h + 4, chunkZ + 5, Blocks.air, 0, 2);
                world.setBlock(chunkX + 0, h + 4, chunkZ + 6, Blocks.air, 0, 2);
                world.setBlock(chunkX + 1, h + 4, chunkZ + 6, Blocks.stonebrick, 3, 2);
                world.setBlock(chunkX + 2, h + 4, chunkZ + 6, Blocks.air, 0, 2);
                world.setBlock(chunkX + 3, h + 4, chunkZ + 6, Blocks.air, 0, 2);
                world.setBlock(chunkX + 4, h + 4, chunkZ + 6, Blocks.air, 0, 2);
                world.setBlock(chunkX + 5, h + 4, chunkZ + 6, Blocks.air, 0, 2);
                world.setBlock(chunkX + 6, h + 4, chunkZ + 6, Blocks.air, 0, 2);
                world.setBlock(chunkX + 7, h + 4, chunkZ + 6, Blocks.air, 0, 2);
                world.setBlock(chunkX + 8, h + 4, chunkZ + 6, Blocks.air, 0, 2);
                world.setBlock(chunkX + 9, h + 4, chunkZ + 6, Blocks.stonebrick, 3, 2);
                world.setBlock(chunkX + 10, h + 4, chunkZ + 6, Blocks.air, 0, 2);
                world.setBlock(chunkX + 0, h + 4, chunkZ + 7, Blocks.air, 0, 2);
                world.setBlock(chunkX + 1, h + 4, chunkZ + 7, Blocks.stonebrick, 3, 2);
                world.setBlock(chunkX + 2, h + 4, chunkZ + 7, Blocks.air, 0, 2);
                world.setBlock(chunkX + 3, h + 4, chunkZ + 7, Blocks.air, 0, 2);
                world.setBlock(chunkX + 4, h + 4, chunkZ + 7, Blocks.air, 0, 2);
                world.setBlock(chunkX + 5, h + 4, chunkZ + 7, Blocks.air, 0, 2);
                world.setBlock(chunkX + 6, h + 4, chunkZ + 7, Blocks.air, 0, 2);
                world.setBlock(chunkX + 7, h + 4, chunkZ + 7, Blocks.air, 0, 2);
                world.setBlock(chunkX + 8, h + 4, chunkZ + 7, Blocks.air, 0, 2);
                world.setBlock(chunkX + 9, h + 4, chunkZ + 7, Blocks.stonebrick, 3, 2);
                world.setBlock(chunkX + 10, h + 4, chunkZ + 7, Blocks.air, 0, 2);
                world.setBlock(chunkX + 0, h + 4, chunkZ + 8, Blocks.air, 0, 2);
                world.setBlock(chunkX + 1, h + 4, chunkZ + 8, Blocks.stonebrick, 3, 2);
                world.setBlock(chunkX + 2, h + 4, chunkZ + 8, Blocks.air, 0, 2);
                world.setBlock(chunkX + 3, h + 4, chunkZ + 8, Blocks.air, 0, 2);
                world.setBlock(chunkX + 4, h + 4, chunkZ + 8, Blocks.air, 0, 2);
                world.setBlock(chunkX + 5, h + 4, chunkZ + 8, Blocks.air, 0, 2);
                world.setBlock(chunkX + 6, h + 4, chunkZ + 8, Blocks.air, 0, 2);
                world.setBlock(chunkX + 7, h + 4, chunkZ + 8, Blocks.air, 0, 2);
                world.setBlock(chunkX + 8, h + 4, chunkZ + 8, Blocks.air, 0, 2);
                world.setBlock(chunkX + 9, h + 4, chunkZ + 8, Blocks.stonebrick, 3, 2);
                world.setBlock(chunkX + 10, h + 4, chunkZ + 8, Blocks.air, 0, 2);
                world.setBlock(chunkX + 0, h + 4, chunkZ + 9, Blocks.air, 0, 2);
                world.setBlock(chunkX + 1, h + 4, chunkZ + 9, Blocks.stonebrick, 3, 2);
                world.setBlock(chunkX + 2, h + 4, chunkZ + 9, Blocks.air, 0, 2);
                world.setBlock(chunkX + 3, h + 4, chunkZ + 9, Blocks.air, 0, 2);
                world.setBlock(chunkX + 4, h + 4, chunkZ + 9, Blocks.air, 0, 2);
                world.setBlock(chunkX + 5, h + 4, chunkZ + 9, Blocks.air, 0, 2);
                world.setBlock(chunkX + 6, h + 4, chunkZ + 9, Blocks.air, 0, 2);
                world.setBlock(chunkX + 7, h + 4, chunkZ + 9, Blocks.air, 0, 2);
                world.setBlock(chunkX + 8, h + 4, chunkZ + 9, Blocks.air, 0, 2);
                world.setBlock(chunkX + 9, h + 4, chunkZ + 9, Blocks.stonebrick, 3, 2);
                world.setBlock(chunkX + 10, h + 4, chunkZ + 9, Blocks.air, 0, 2);
                world.setBlock(chunkX + 0, h + 4, chunkZ + 10, Blocks.air, 0, 2);
                world.setBlock(chunkX + 1, h + 4, chunkZ + 10, Blocks.stonebrick, 3, 2);
                world.setBlock(chunkX + 2, h + 4, chunkZ + 10, Blocks.air, 0, 2);
                world.setBlock(chunkX + 3, h + 4, chunkZ + 10, Blocks.air, 0, 2);
                world.setBlock(chunkX + 4, h + 4, chunkZ + 10, Blocks.air, 0, 2);
                world.setBlock(chunkX + 5, h + 4, chunkZ + 10, Blocks.air, 0, 2);
                world.setBlock(chunkX + 6, h + 4, chunkZ + 10, Blocks.air, 0, 2);
                world.setBlock(chunkX + 7, h + 4, chunkZ + 10, Blocks.air, 0, 2);
                world.setBlock(chunkX + 8, h + 4, chunkZ + 10, Blocks.air, 0, 2);
                world.setBlock(chunkX + 9, h + 4, chunkZ + 10, Blocks.stonebrick, 3, 2);
                world.setBlock(chunkX + 10, h + 4, chunkZ + 10, Blocks.air, 0, 2);
                world.setBlock(chunkX + 0, h + 4, chunkZ + 11, Blocks.air, 0, 2);
                world.setBlock(chunkX + 1, h + 4, chunkZ + 11, Blocks.stonebrick, 3, 2);
                world.setBlock(chunkX + 2, h + 4, chunkZ + 11, Blocks.air, 0, 2);
                world.setBlock(chunkX + 3, h + 4, chunkZ + 11, Blocks.air, 0, 2);
                world.setBlock(chunkX + 4, h + 4, chunkZ + 11, Blocks.air, 0, 2);
                world.setBlock(chunkX + 5, h + 4, chunkZ + 11, Blocks.air, 0, 2);
                world.setBlock(chunkX + 6, h + 4, chunkZ + 11, Blocks.air, 0, 2);
                world.setBlock(chunkX + 7, h + 4, chunkZ + 11, Blocks.air, 0, 2);
                world.setBlock(chunkX + 8, h + 4, chunkZ + 11, Blocks.air, 0, 2);
                world.setBlock(chunkX + 9, h + 4, chunkZ + 11, Blocks.stonebrick, 3, 2);
                world.setBlock(chunkX + 10, h + 4, chunkZ + 11, Blocks.air, 0, 2);
                world.setBlock(chunkX + 0, h + 4, chunkZ + 12, Blocks.air, 0, 2);
                world.setBlock(chunkX + 1, h + 4, chunkZ + 12, Blocks.stonebrick, 3, 2);
                world.setBlock(chunkX + 2, h + 4, chunkZ + 12, Blocks.stonebrick, 3, 2);
                world.setBlock(chunkX + 3, h + 4, chunkZ + 12, Blocks.stonebrick, 3, 2);
                world.setBlock(chunkX + 4, h + 4, chunkZ + 12, Blocks.stonebrick, 3, 2);
                world.setBlock(chunkX + 5, h + 4, chunkZ + 12, Blocks.stonebrick, 3, 2);
                world.setBlock(chunkX + 6, h + 4, chunkZ + 12, Blocks.stonebrick, 3, 2);
                world.setBlock(chunkX + 7, h + 4, chunkZ + 12, Blocks.stonebrick, 3, 2);
                world.setBlock(chunkX + 8, h + 4, chunkZ + 12, Blocks.stonebrick, 3, 2);
                world.setBlock(chunkX + 9, h + 4, chunkZ + 12, Blocks.stonebrick, 3, 2);
                world.setBlock(chunkX + 10, h + 4, chunkZ + 12, Blocks.air, 0, 2);
                world.setBlock(chunkX + 0, h + 4, chunkZ + 13, Blocks.air, 0, 2);
                world.setBlock(chunkX + 1, h + 4, chunkZ + 13, Blocks.air, 0, 2);
                world.setBlock(chunkX + 2, h + 4, chunkZ + 13, Blocks.air, 0, 2);
                world.setBlock(chunkX + 3, h + 4, chunkZ + 13, Blocks.air, 0, 2);
                world.setBlock(chunkX + 4, h + 4, chunkZ + 13, Blocks.air, 0, 2);
                world.setBlock(chunkX + 5, h + 4, chunkZ + 13, Blocks.air, 0, 2);
                world.setBlock(chunkX + 6, h + 4, chunkZ + 13, Blocks.air, 0, 2);
                world.setBlock(chunkX + 7, h + 4, chunkZ + 13, Blocks.air, 0, 2);
                world.setBlock(chunkX + 8, h + 4, chunkZ + 13, Blocks.air, 0, 2);
                world.setBlock(chunkX + 9, h + 4, chunkZ + 13, Blocks.air, 0, 2);
                world.setBlock(chunkX + 10, h + 4, chunkZ + 13, Blocks.air, 0, 2);
                world.setBlock(chunkX + 0, h + 5, chunkZ + 0, Blocks.air, 0, 2);
                world.setBlock(chunkX + 1, h + 5, chunkZ + 0, Blocks.air, 0, 2);
                world.setBlock(chunkX + 2, h + 5, chunkZ + 0, Blocks.air, 0, 2);
                world.setBlock(chunkX + 3, h + 5, chunkZ + 0, Blocks.air, 0, 2);
                world.setBlock(chunkX + 4, h + 5, chunkZ + 0, Blocks.air, 0, 2);
                world.setBlock(chunkX + 5, h + 5, chunkZ + 0, Blocks.air, 0, 2);
                world.setBlock(chunkX + 6, h + 5, chunkZ + 0, Blocks.air, 0, 2);
                world.setBlock(chunkX + 7, h + 5, chunkZ + 0, Blocks.air, 0, 2);
                world.setBlock(chunkX + 8, h + 5, chunkZ + 0, Blocks.air, 0, 2);
                world.setBlock(chunkX + 9, h + 5, chunkZ + 0, Blocks.air, 0, 2);
                world.setBlock(chunkX + 10, h + 5, chunkZ + 0, Blocks.air, 0, 2);
                world.setBlock(chunkX + 0, h + 5, chunkZ + 1, Blocks.air, 0, 2);
                world.setBlock(chunkX + 1, h + 5, chunkZ + 1, Blocks.stonebrick, 3, 2);
                world.setBlock(chunkX + 2, h + 5, chunkZ + 1, Blocks.stonebrick, 3, 2);
                world.setBlock(chunkX + 3, h + 5, chunkZ + 1, Blocks.stonebrick, 3, 2);
                world.setBlock(chunkX + 4, h + 5, chunkZ + 1, Blocks.stonebrick, 3, 2);
                world.setBlock(chunkX + 5, h + 5, chunkZ + 1, Blocks.stonebrick, 3, 2);
                world.setBlock(chunkX + 6, h + 5, chunkZ + 1, Blocks.stonebrick, 3, 2);
                world.setBlock(chunkX + 7, h + 5, chunkZ + 1, Blocks.stonebrick, 3, 2);
                world.setBlock(chunkX + 8, h + 5, chunkZ + 1, Blocks.stonebrick, 3, 2);
                world.setBlock(chunkX + 9, h + 5, chunkZ + 1, Blocks.stonebrick, 3, 2);
                world.setBlock(chunkX + 10, h + 5, chunkZ + 1, Blocks.air, 0, 2);
                world.setBlock(chunkX + 0, h + 5, chunkZ + 2, Blocks.air, 0, 2);
                world.setBlock(chunkX + 1, h + 5, chunkZ + 2, Blocks.stonebrick, 3, 2);
                world.setBlock(chunkX + 2, h + 5, chunkZ + 2, Blocks.air, 0, 2);
                world.setBlock(chunkX + 3, h + 5, chunkZ + 2, Blocks.air, 0, 2);
                world.setBlock(chunkX + 4, h + 5, chunkZ + 2, Blocks.air, 0, 2);
                world.setBlock(chunkX + 5, h + 5, chunkZ + 2, Blocks.air, 0, 2);
                world.setBlock(chunkX + 6, h + 5, chunkZ + 2, Blocks.air, 0, 2);
                world.setBlock(chunkX + 7, h + 5, chunkZ + 2, Blocks.air, 0, 2);
                world.setBlock(chunkX + 8, h + 5, chunkZ + 2, Blocks.air, 0, 2);
                world.setBlock(chunkX + 9, h + 5, chunkZ + 2, Blocks.stonebrick, 3, 2);
                world.setBlock(chunkX + 10, h + 5, chunkZ + 2, Blocks.air, 0, 2);
                world.setBlock(chunkX + 0, h + 5, chunkZ + 3, Blocks.air, 0, 2);
                world.setBlock(chunkX + 1, h + 5, chunkZ + 3, Blocks.stonebrick, 3, 2);
                world.setBlock(chunkX + 2, h + 5, chunkZ + 3, Blocks.air, 0, 2);
                world.setBlock(chunkX + 3, h + 5, chunkZ + 3, Blocks.air, 0, 2);
                world.setBlock(chunkX + 4, h + 5, chunkZ + 3, Blocks.air, 0, 2);
                world.setBlock(chunkX + 5, h + 5, chunkZ + 3, Blocks.air, 0, 2);
                world.setBlock(chunkX + 6, h + 5, chunkZ + 3, Blocks.air, 0, 2);
                world.setBlock(chunkX + 7, h + 5, chunkZ + 3, Blocks.air, 0, 2);
                world.setBlock(chunkX + 8, h + 5, chunkZ + 3, Blocks.air, 0, 2);
                world.setBlock(chunkX + 9, h + 5, chunkZ + 3, Blocks.stonebrick, 3, 2);
                world.setBlock(chunkX + 10, h + 5, chunkZ + 3, Blocks.air, 0, 2);
                world.setBlock(chunkX + 0, h + 5, chunkZ + 4, Blocks.air, 0, 2);
                world.setBlock(chunkX + 1, h + 5, chunkZ + 4, Blocks.stonebrick, 3, 2);
                world.setBlock(chunkX + 2, h + 5, chunkZ + 4, Blocks.air, 0, 2);
                world.setBlock(chunkX + 3, h + 5, chunkZ + 4, Blocks.air, 0, 2);
                world.setBlock(chunkX + 4, h + 5, chunkZ + 4, Blocks.air, 0, 2);
                world.setBlock(chunkX + 5, h + 5, chunkZ + 4, Blocks.air, 0, 2);
                world.setBlock(chunkX + 6, h + 5, chunkZ + 4, Blocks.air, 0, 2);
                world.setBlock(chunkX + 7, h + 5, chunkZ + 4, Blocks.air, 0, 2);
                world.setBlock(chunkX + 8, h + 5, chunkZ + 4, Blocks.air, 0, 2);
                world.setBlock(chunkX + 9, h + 5, chunkZ + 4, Blocks.stonebrick, 3, 2);
                world.setBlock(chunkX + 10, h + 5, chunkZ + 4, Blocks.air, 0, 2);
                world.setBlock(chunkX + 0, h + 5, chunkZ + 5, Blocks.air, 0, 2);
                world.setBlock(chunkX + 1, h + 5, chunkZ + 5, Blocks.stonebrick, 3, 2);
                world.setBlock(chunkX + 2, h + 5, chunkZ + 5, Blocks.air, 0, 2);
                world.setBlock(chunkX + 3, h + 5, chunkZ + 5, Blocks.air, 0, 2);
                world.setBlock(chunkX + 4, h + 5, chunkZ + 5, Blocks.air, 0, 2);
                world.setBlock(chunkX + 5, h + 5, chunkZ + 5, Blocks.air, 0, 2);
                world.setBlock(chunkX + 6, h + 5, chunkZ + 5, Blocks.air, 0, 2);
                world.setBlock(chunkX + 7, h + 5, chunkZ + 5, Blocks.air, 0, 2);
                world.setBlock(chunkX + 8, h + 5, chunkZ + 5, Blocks.air, 0, 2);
                world.setBlock(chunkX + 9, h + 5, chunkZ + 5, Blocks.stonebrick, 3, 2);
                world.setBlock(chunkX + 10, h + 5, chunkZ + 5, Blocks.air, 0, 2);
                world.setBlock(chunkX + 0, h + 5, chunkZ + 6, Blocks.air, 0, 2);
                world.setBlock(chunkX + 1, h + 5, chunkZ + 6, Blocks.stonebrick, 3, 2);
                world.setBlock(chunkX + 2, h + 5, chunkZ + 6, Blocks.air, 0, 2);
                world.setBlock(chunkX + 3, h + 5, chunkZ + 6, Blocks.air, 0, 2);
                world.setBlock(chunkX + 4, h + 5, chunkZ + 6, Blocks.air, 0, 2);
                world.setBlock(chunkX + 5, h + 5, chunkZ + 6, Blocks.air, 0, 2);
                world.setBlock(chunkX + 6, h + 5, chunkZ + 6, Blocks.air, 0, 2);
                world.setBlock(chunkX + 7, h + 5, chunkZ + 6, Blocks.air, 0, 2);
                world.setBlock(chunkX + 8, h + 5, chunkZ + 6, Blocks.air, 0, 2);
                world.setBlock(chunkX + 9, h + 5, chunkZ + 6, Blocks.stonebrick, 3, 2);
                world.setBlock(chunkX + 10, h + 5, chunkZ + 6, Blocks.air, 0, 2);
                world.setBlock(chunkX + 0, h + 5, chunkZ + 7, Blocks.air, 0, 2);
                world.setBlock(chunkX + 1, h + 5, chunkZ + 7, Blocks.stonebrick, 3, 2);
                world.setBlock(chunkX + 2, h + 5, chunkZ + 7, Blocks.air, 0, 2);
                world.setBlock(chunkX + 3, h + 5, chunkZ + 7, Blocks.air, 0, 2);
                world.setBlock(chunkX + 4, h + 5, chunkZ + 7, Blocks.air, 0, 2);
                world.setBlock(chunkX + 5, h + 5, chunkZ + 7, Blocks.air, 0, 2);
                world.setBlock(chunkX + 6, h + 5, chunkZ + 7, Blocks.air, 0, 2);
                world.setBlock(chunkX + 7, h + 5, chunkZ + 7, Blocks.air, 0, 2);
                world.setBlock(chunkX + 8, h + 5, chunkZ + 7, Blocks.air, 0, 2);
                world.setBlock(chunkX + 9, h + 5, chunkZ + 7, Blocks.stonebrick, 3, 2);
                world.setBlock(chunkX + 10, h + 5, chunkZ + 7, Blocks.air, 0, 2);
                world.setBlock(chunkX + 0, h + 5, chunkZ + 8, Blocks.air, 0, 2);
                world.setBlock(chunkX + 1, h + 5, chunkZ + 8, Blocks.stonebrick, 3, 2);
                world.setBlock(chunkX + 2, h + 5, chunkZ + 8, Blocks.air, 0, 2);
                world.setBlock(chunkX + 3, h + 5, chunkZ + 8, Blocks.air, 0, 2);
                world.setBlock(chunkX + 4, h + 5, chunkZ + 8, Blocks.air, 0, 2);
                world.setBlock(chunkX + 5, h + 5, chunkZ + 8, Blocks.air, 0, 2);
                world.setBlock(chunkX + 6, h + 5, chunkZ + 8, Blocks.air, 0, 2);
                world.setBlock(chunkX + 7, h + 5, chunkZ + 8, Blocks.air, 0, 2);
                world.setBlock(chunkX + 8, h + 5, chunkZ + 8, Blocks.air, 0, 2);
                world.setBlock(chunkX + 9, h + 5, chunkZ + 8, Blocks.stonebrick, 3, 2);
                world.setBlock(chunkX + 10, h + 5, chunkZ + 8, Blocks.air, 0, 2);
                world.setBlock(chunkX + 0, h + 5, chunkZ + 9, Blocks.air, 0, 2);
                world.setBlock(chunkX + 1, h + 5, chunkZ + 9, Blocks.stonebrick, 3, 2);
                world.setBlock(chunkX + 2, h + 5, chunkZ + 9, Blocks.air, 0, 2);
                world.setBlock(chunkX + 3, h + 5, chunkZ + 9, Blocks.air, 0, 2);
                world.setBlock(chunkX + 4, h + 5, chunkZ + 9, Blocks.air, 0, 2);
                world.setBlock(chunkX + 5, h + 5, chunkZ + 9, Blocks.air, 0, 2);
                world.setBlock(chunkX + 6, h + 5, chunkZ + 9, Blocks.air, 0, 2);
                world.setBlock(chunkX + 7, h + 5, chunkZ + 9, Blocks.air, 0, 2);
                world.setBlock(chunkX + 8, h + 5, chunkZ + 9, Blocks.air, 0, 2);
                world.setBlock(chunkX + 9, h + 5, chunkZ + 9, Blocks.stonebrick, 3, 2);
                world.setBlock(chunkX + 10, h + 5, chunkZ + 9, Blocks.air, 0, 2);
                world.setBlock(chunkX + 0, h + 5, chunkZ + 10, Blocks.air, 0, 2);
                world.setBlock(chunkX + 1, h + 5, chunkZ + 10, Blocks.stonebrick, 3, 2);
                world.setBlock(chunkX + 2, h + 5, chunkZ + 10, Blocks.air, 0, 2);
                world.setBlock(chunkX + 3, h + 5, chunkZ + 10, Blocks.air, 0, 2);
                world.setBlock(chunkX + 4, h + 5, chunkZ + 10, Blocks.air, 0, 2);
                world.setBlock(chunkX + 5, h + 5, chunkZ + 10, Blocks.air, 0, 2);
                world.setBlock(chunkX + 6, h + 5, chunkZ + 10, Blocks.air, 0, 2);
                world.setBlock(chunkX + 7, h + 5, chunkZ + 10, Blocks.air, 0, 2);
                world.setBlock(chunkX + 8, h + 5, chunkZ + 10, Blocks.air, 0, 2);
                world.setBlock(chunkX + 9, h + 5, chunkZ + 10, Blocks.stonebrick, 3, 2);
                world.setBlock(chunkX + 10, h + 5, chunkZ + 10, Blocks.air, 0, 2);
                world.setBlock(chunkX + 0, h + 5, chunkZ + 11, Blocks.air, 0, 2);
                world.setBlock(chunkX + 1, h + 5, chunkZ + 11, Blocks.stonebrick, 3, 2);
                world.setBlock(chunkX + 2, h + 5, chunkZ + 11, Blocks.air, 0, 2);
                world.setBlock(chunkX + 3, h + 5, chunkZ + 11, Blocks.air, 0, 2);
                world.setBlock(chunkX + 4, h + 5, chunkZ + 11, Blocks.air, 0, 2);
                world.setBlock(chunkX + 5, h + 5, chunkZ + 11, Blocks.air, 0, 2);
                world.setBlock(chunkX + 6, h + 5, chunkZ + 11, Blocks.air, 0, 2);
                world.setBlock(chunkX + 7, h + 5, chunkZ + 11, Blocks.air, 0, 2);
                world.setBlock(chunkX + 8, h + 5, chunkZ + 11, Blocks.air, 0, 2);
                world.setBlock(chunkX + 9, h + 5, chunkZ + 11, Blocks.stonebrick, 3, 2);
                world.setBlock(chunkX + 10, h + 5, chunkZ + 11, Blocks.air, 0, 2);
                world.setBlock(chunkX + 0, h + 5, chunkZ + 12, Blocks.air, 0, 2);
                world.setBlock(chunkX + 1, h + 5, chunkZ + 12, Blocks.stonebrick, 3, 2);
                world.setBlock(chunkX + 2, h + 5, chunkZ + 12, Blocks.stonebrick, 3, 2);
                world.setBlock(chunkX + 3, h + 5, chunkZ + 12, Blocks.stonebrick, 3, 2);
                world.setBlock(chunkX + 4, h + 5, chunkZ + 12, Blocks.stonebrick, 3, 2);
                world.setBlock(chunkX + 5, h + 5, chunkZ + 12, Blocks.stonebrick, 3, 2);
                world.setBlock(chunkX + 6, h + 5, chunkZ + 12, Blocks.stonebrick, 3, 2);
                world.setBlock(chunkX + 7, h + 5, chunkZ + 12, Blocks.stonebrick, 3, 2);
                world.setBlock(chunkX + 8, h + 5, chunkZ + 12, Blocks.stonebrick, 3, 2);
                world.setBlock(chunkX + 9, h + 5, chunkZ + 12, Blocks.stonebrick, 3, 2);
                world.setBlock(chunkX + 10, h + 5, chunkZ + 12, Blocks.air, 0, 2);
                world.setBlock(chunkX + 0, h + 5, chunkZ + 13, Blocks.air, 0, 2);
                world.setBlock(chunkX + 1, h + 5, chunkZ + 13, Blocks.air, 0, 2);
                world.setBlock(chunkX + 2, h + 5, chunkZ + 13, Blocks.air, 0, 2);
                world.setBlock(chunkX + 3, h + 5, chunkZ + 13, Blocks.air, 0, 2);
                world.setBlock(chunkX + 4, h + 5, chunkZ + 13, Blocks.air, 0, 2);
                world.setBlock(chunkX + 5, h + 5, chunkZ + 13, Blocks.air, 0, 2);
                world.setBlock(chunkX + 6, h + 5, chunkZ + 13, Blocks.air, 0, 2);
                world.setBlock(chunkX + 7, h + 5, chunkZ + 13, Blocks.air, 0, 2);
                world.setBlock(chunkX + 8, h + 5, chunkZ + 13, Blocks.air, 0, 2);
                world.setBlock(chunkX + 9, h + 5, chunkZ + 13, Blocks.air, 0, 2);
                world.setBlock(chunkX + 10, h + 5, chunkZ + 13, Blocks.air, 0, 2);
                world.setBlock(chunkX + 4, h + 6, chunkZ + 0, Blocks.stonebrick, 3, 2);
                world.setBlock(chunkX + 5, h + 6, chunkZ + 0, Blocks.stonebrick, 3, 2);
                world.setBlock(chunkX + 6, h + 6, chunkZ + 0, Blocks.stonebrick, 3, 2);
                world.setBlock(chunkX + 1, h + 6, chunkZ + 1, Blocks.stonebrick, 3, 2);
                world.setBlock(chunkX + 2, h + 6, chunkZ + 1, Blocks.stonebrick, 3, 2);
                world.setBlock(chunkX + 3, h + 6, chunkZ + 1, Blocks.stonebrick, 3, 2);
                world.setBlock(chunkX + 4, h + 6, chunkZ + 1, Blocks.stonebrick, 3, 2);
                world.setBlock(chunkX + 5, h + 6, chunkZ + 1, Blocks.quartz_block, 0, 2);
                world.setBlock(chunkX + 6, h + 6, chunkZ + 1, Blocks.stonebrick, 3, 2);
                world.setBlock(chunkX + 7, h + 6, chunkZ + 1, Blocks.stonebrick, 3, 2);
                world.setBlock(chunkX + 8, h + 6, chunkZ + 1, Blocks.stonebrick, 3, 2);
                world.setBlock(chunkX + 9, h + 6, chunkZ + 1, Blocks.stonebrick, 3, 2);
                world.setBlock(chunkX + 1, h + 6, chunkZ + 2, Blocks.stonebrick, 3, 2);
                world.setBlock(chunkX + 2, h + 6, chunkZ + 2, Blocks.quartz_block, 0, 2);
                world.setBlock(chunkX + 3, h + 6, chunkZ + 2, Blocks.quartz_block, 0, 2);
                world.setBlock(chunkX + 4, h + 6, chunkZ + 2, Blocks.quartz_block, 0, 2);
                world.setBlock(chunkX + 5, h + 6, chunkZ + 2, Blocks.quartz_block, 0, 2);
                world.setBlock(chunkX + 6, h + 6, chunkZ + 2, Blocks.quartz_block, 0, 2);
                world.setBlock(chunkX + 7, h + 6, chunkZ + 2, Blocks.quartz_block, 0, 2);
                world.setBlock(chunkX + 8, h + 6, chunkZ + 2, Blocks.quartz_block, 0, 2);
                world.setBlock(chunkX + 9, h + 6, chunkZ + 2, Blocks.stonebrick, 3, 2);
                world.setBlock(chunkX + 1, h + 6, chunkZ + 3, Blocks.stonebrick, 3, 2);
                world.setBlock(chunkX + 2, h + 6, chunkZ + 3, Blocks.quartz_block, 0, 2);
                world.setBlock(chunkX + 3, h + 6, chunkZ + 3, Blocks.quartz_block, 0, 2);
                world.setBlock(chunkX + 4, h + 6, chunkZ + 3, Blocks.quartz_block, 0, 2);
                world.setBlock(chunkX + 5, h + 6, chunkZ + 3, Blocks.quartz_block, 0, 2);
                world.setBlock(chunkX + 6, h + 6, chunkZ + 3, Blocks.quartz_block, 0, 2);
                world.setBlock(chunkX + 7, h + 6, chunkZ + 3, Blocks.quartz_block, 0, 2);
                world.setBlock(chunkX + 8, h + 6, chunkZ + 3, Blocks.quartz_block, 0, 2);
                world.setBlock(chunkX + 9, h + 6, chunkZ + 3, Blocks.stonebrick, 3, 2);
                world.setBlock(chunkX + 1, h + 6, chunkZ + 4, Blocks.stonebrick, 3, 2);
                world.setBlock(chunkX + 2, h + 6, chunkZ + 4, Blocks.quartz_block, 0, 2);
                world.setBlock(chunkX + 3, h + 6, chunkZ + 4, Blocks.quartz_block, 0, 2);
                world.setBlock(chunkX + 4, h + 6, chunkZ + 4, Blocks.quartz_block, 0, 2);
                world.setBlock(chunkX + 5, h + 6, chunkZ + 4, Blocks.quartz_block, 0, 2);
                world.setBlock(chunkX + 6, h + 6, chunkZ + 4, Blocks.quartz_block, 0, 2);
                world.setBlock(chunkX + 7, h + 6, chunkZ + 4, Blocks.quartz_block, 0, 2);
                world.setBlock(chunkX + 8, h + 6, chunkZ + 4, Blocks.quartz_block, 0, 2);
                world.setBlock(chunkX + 9, h + 6, chunkZ + 4, Blocks.stonebrick, 3, 2);
                world.setBlock(chunkX + 1, h + 6, chunkZ + 5, Blocks.stonebrick, 3, 2);
                world.setBlock(chunkX + 2, h + 6, chunkZ + 5, Blocks.quartz_block, 0, 2);
                world.setBlock(chunkX + 3, h + 6, chunkZ + 5, Blocks.quartz_block, 0, 2);
                world.setBlock(chunkX + 4, h + 6, chunkZ + 5, Blocks.quartz_block, 0, 2);
                world.setBlock(chunkX + 5, h + 6, chunkZ + 5, Blocks.quartz_block, 0, 2);
                world.setBlock(chunkX + 6, h + 6, chunkZ + 5, Blocks.quartz_block, 0, 2);
                world.setBlock(chunkX + 7, h + 6, chunkZ + 5, Blocks.quartz_block, 0, 2);
                world.setBlock(chunkX + 8, h + 6, chunkZ + 5, Blocks.quartz_block, 0, 2);
                world.setBlock(chunkX + 9, h + 6, chunkZ + 5, Blocks.stonebrick, 3, 2);
                world.setBlock(chunkX + 1, h + 6, chunkZ + 6, Blocks.stonebrick, 3, 2);
                world.setBlock(chunkX + 2, h + 6, chunkZ + 6, Blocks.quartz_block, 0, 2);
                world.setBlock(chunkX + 3, h + 6, chunkZ + 6, Blocks.quartz_block, 0, 2);
                world.setBlock(chunkX + 4, h + 6, chunkZ + 6, Blocks.quartz_block, 0, 2);
                world.setBlock(chunkX + 5, h + 6, chunkZ + 6, Blocks.quartz_block, 0, 2);
                world.setBlock(chunkX + 6, h + 6, chunkZ + 6, Blocks.quartz_block, 0, 2);
                world.setBlock(chunkX + 7, h + 6, chunkZ + 6, Blocks.quartz_block, 0, 2);
                world.setBlock(chunkX + 8, h + 6, chunkZ + 6, Blocks.quartz_block, 0, 2);
                world.setBlock(chunkX + 9, h + 6, chunkZ + 6, Blocks.stonebrick, 3, 2);
                world.setBlock(chunkX + 1, h + 6, chunkZ + 7, Blocks.stonebrick, 3, 2);
                world.setBlock(chunkX + 2, h + 6, chunkZ + 7, Blocks.quartz_block, 0, 2);
                world.setBlock(chunkX + 3, h + 6, chunkZ + 7, Blocks.quartz_block, 0, 2);
                world.setBlock(chunkX + 4, h + 6, chunkZ + 7, Blocks.air, 0, 2);
                world.setBlock(chunkX + 5, h + 6, chunkZ + 7, Blocks.air, 0, 2);
                world.setBlock(chunkX + 6, h + 6, chunkZ + 7, Blocks.air, 0, 2);
                world.setBlock(chunkX + 7, h + 6, chunkZ + 7, Blocks.quartz_block, 0, 2);
                world.setBlock(chunkX + 8, h + 6, chunkZ + 7, Blocks.quartz_block, 0, 2);
                world.setBlock(chunkX + 9, h + 6, chunkZ + 7, Blocks.stonebrick, 3, 2);
                world.setBlock(chunkX + 1, h + 6, chunkZ + 8, Blocks.stonebrick, 3, 2);
                world.setBlock(chunkX + 2, h + 6, chunkZ + 8, Blocks.quartz_block, 0, 2);
                world.setBlock(chunkX + 3, h + 6, chunkZ + 8, Blocks.quartz_block, 0, 2);
                world.setBlock(chunkX + 4, h + 6, chunkZ + 8, Blocks.quartz_block, 0, 2);
                world.setBlock(chunkX + 5, h + 6, chunkZ + 8, Blocks.quartz_block, 0, 2);
                world.setBlock(chunkX + 6, h + 6, chunkZ + 8, Blocks.quartz_block, 0, 2);
                world.setBlock(chunkX + 7, h + 6, chunkZ + 8, Blocks.quartz_block, 0, 2);
                world.setBlock(chunkX + 8, h + 6, chunkZ + 8, Blocks.quartz_block, 0, 2);
                world.setBlock(chunkX + 9, h + 6, chunkZ + 8, Blocks.stonebrick, 3, 2);
                world.setBlock(chunkX + 1, h + 6, chunkZ + 9, Blocks.stonebrick, 3, 2);
                world.setBlock(chunkX + 2, h + 6, chunkZ + 9, Blocks.quartz_block, 0, 2);
                world.setBlock(chunkX + 3, h + 6, chunkZ + 9, Blocks.quartz_block, 0, 2);
                world.setBlock(chunkX + 4, h + 6, chunkZ + 9, Blocks.quartz_block, 0, 2);
                world.setBlock(chunkX + 5, h + 6, chunkZ + 9, Blocks.quartz_block, 0, 2);
                world.setBlock(chunkX + 6, h + 6, chunkZ + 9, Blocks.quartz_block, 0, 2);
                world.setBlock(chunkX + 7, h + 6, chunkZ + 9, Blocks.quartz_block, 0, 2);
                world.setBlock(chunkX + 8, h + 6, chunkZ + 9, Blocks.quartz_block, 0, 2);
                world.setBlock(chunkX + 9, h + 6, chunkZ + 9, Blocks.stonebrick, 3, 2);
                world.setBlock(chunkX + 1, h + 6, chunkZ + 10, Blocks.stonebrick, 3, 2);
                world.setBlock(chunkX + 2, h + 6, chunkZ + 10, Blocks.quartz_block, 0, 2);
                world.setBlock(chunkX + 3, h + 6, chunkZ + 10, Blocks.quartz_block, 0, 2);
                world.setBlock(chunkX + 4, h + 6, chunkZ + 10, Blocks.quartz_block, 0, 2);
                world.setBlock(chunkX + 5, h + 6, chunkZ + 10, Blocks.quartz_block, 0, 2);
                world.setBlock(chunkX + 6, h + 6, chunkZ + 10, Blocks.quartz_block, 0, 2);
                world.setBlock(chunkX + 7, h + 6, chunkZ + 10, Blocks.quartz_block, 0, 2);
                world.setBlock(chunkX + 8, h + 6, chunkZ + 10, Blocks.quartz_block, 0, 2);
                world.setBlock(chunkX + 9, h + 6, chunkZ + 10, Blocks.stonebrick, 3, 2);
                world.setBlock(chunkX + 1, h + 6, chunkZ + 11, Blocks.stonebrick, 3, 2);
                world.setBlock(chunkX + 2, h + 6, chunkZ + 11, Blocks.quartz_block, 0, 2);
                world.setBlock(chunkX + 3, h + 6, chunkZ + 11, Blocks.quartz_block, 0, 2);
                world.setBlock(chunkX + 4, h + 6, chunkZ + 11, Blocks.quartz_block, 0, 2);
                world.setBlock(chunkX + 5, h + 6, chunkZ + 11, Blocks.quartz_block, 0, 2);
                world.setBlock(chunkX + 6, h + 6, chunkZ + 11, Blocks.quartz_block, 0, 2);
                world.setBlock(chunkX + 7, h + 6, chunkZ + 11, Blocks.quartz_block, 0, 2);
                world.setBlock(chunkX + 8, h + 6, chunkZ + 11, Blocks.quartz_block, 0, 2);
                world.setBlock(chunkX + 9, h + 6, chunkZ + 11, Blocks.stonebrick, 3, 2);
                world.setBlock(chunkX + 1, h + 6, chunkZ + 12, Blocks.stonebrick, 3, 2);
                world.setBlock(chunkX + 2, h + 6, chunkZ + 12, Blocks.stonebrick, 3, 2);
                world.setBlock(chunkX + 3, h + 6, chunkZ + 12, Blocks.stonebrick, 3, 2);
                world.setBlock(chunkX + 4, h + 6, chunkZ + 12, Blocks.stonebrick, 3, 2);
                world.setBlock(chunkX + 5, h + 6, chunkZ + 12, Blocks.stonebrick, 3, 2);
                world.setBlock(chunkX + 6, h + 6, chunkZ + 12, Blocks.stonebrick, 3, 2);
                world.setBlock(chunkX + 7, h + 6, chunkZ + 12, Blocks.stonebrick, 3, 2);
                world.setBlock(chunkX + 8, h + 6, chunkZ + 12, Blocks.stonebrick, 3, 2);
                world.setBlock(chunkX + 9, h + 6, chunkZ + 12, Blocks.stonebrick, 3, 2);
                world.setBlock(chunkX + 0, h + 7, chunkZ + 0, Blocks.air, 0, 2);
                world.setBlock(chunkX + 1, h + 7, chunkZ + 0, Blocks.air, 0, 2);
                world.setBlock(chunkX + 2, h + 7, chunkZ + 0, Blocks.air, 0, 2);
                world.setBlock(chunkX + 3, h + 7, chunkZ + 0, Blocks.air, 0, 2);
                world.setBlock(chunkX + 4, h + 7, chunkZ + 0, Blocks.cobblestone_wall, 0, 2);
                world.setBlock(chunkX + 5, h + 7, chunkZ + 0, Blocks.air, 0, 2);
                world.setBlock(chunkX + 6, h + 7, chunkZ + 0, Blocks.cobblestone_wall, 0, 2);
                world.setBlock(chunkX + 7, h + 7, chunkZ + 0, Blocks.air, 0, 2);
                world.setBlock(chunkX + 8, h + 7, chunkZ + 0, Blocks.air, 0, 2);
                world.setBlock(chunkX + 9, h + 7, chunkZ + 0, Blocks.air, 0, 2);
                world.setBlock(chunkX + 10, h + 7, chunkZ + 0, Blocks.air, 0, 2);
                world.setBlock(chunkX + 0, h + 7, chunkZ + 1, Blocks.air, 0, 2);
                world.setBlock(chunkX + 1, h + 7, chunkZ + 1, Blocks.stonebrick, 0, 2);
                world.setBlock(chunkX + 2, h + 7, chunkZ + 1, Blocks.stonebrick, 0, 2);
                world.setBlock(chunkX + 3, h + 7, chunkZ + 1, Blocks.stonebrick, 0, 2);
                world.setBlock(chunkX + 4, h + 7, chunkZ + 1, Blocks.stonebrick, 0, 2);
                world.setBlock(chunkX + 5, h + 7, chunkZ + 1, Blocks.air, 0, 2);
                world.setBlock(chunkX + 6, h + 7, chunkZ + 1, Blocks.stonebrick, 0, 2);
                world.setBlock(chunkX + 7, h + 7, chunkZ + 1, Blocks.stonebrick, 0, 2);
                world.setBlock(chunkX + 8, h + 7, chunkZ + 1, Blocks.stonebrick, 0, 2);
                world.setBlock(chunkX + 9, h + 7, chunkZ + 1, Blocks.stonebrick, 0, 2);
                world.setBlock(chunkX + 10, h + 7, chunkZ + 1, Blocks.air, 0, 2);
                world.setBlock(chunkX + 0, h + 7, chunkZ + 2, Blocks.air, 0, 2);
                world.setBlock(chunkX + 1, h + 7, chunkZ + 2, Blocks.stonebrick, 0, 2);
                world.setBlock(chunkX + 2, h + 7, chunkZ + 2, Blocks.air, 0, 2);
                world.setBlock(chunkX + 3, h + 7, chunkZ + 2, Blocks.air, 0, 2);
                world.setBlock(chunkX + 4, h + 7, chunkZ + 2, Blocks.air, 0, 2);
                world.setBlock(chunkX + 5, h + 7, chunkZ + 2, Blocks.air, 0, 2);
                world.setBlock(chunkX + 6, h + 7, chunkZ + 2, Blocks.air, 0, 2);
                world.setBlock(chunkX + 7, h + 7, chunkZ + 2, Blocks.air, 0, 2);
                world.setBlock(chunkX + 8, h + 7, chunkZ + 2, Blocks.air, 0, 2);
                world.setBlock(chunkX + 9, h + 7, chunkZ + 2, Blocks.stonebrick, 0, 2);
                world.setBlock(chunkX + 10, h + 7, chunkZ + 2, Blocks.air, 0, 2);
                world.setBlock(chunkX + 0, h + 7, chunkZ + 3, Blocks.air, 0, 2);
                world.setBlock(chunkX + 1, h + 7, chunkZ + 3, Blocks.stonebrick, 0, 2);
                world.setBlock(chunkX + 2, h + 7, chunkZ + 3, Blocks.air, 0, 2);
                world.setBlock(chunkX + 3, h + 7, chunkZ + 3, Blocks.air, 0, 2);
                world.setBlock(chunkX + 4, h + 7, chunkZ + 3, Blocks.air, 0, 2);
                world.setBlock(chunkX + 5, h + 7, chunkZ + 3, Blocks.air, 0, 2);
                world.setBlock(chunkX + 6, h + 7, chunkZ + 3, Blocks.air, 0, 2);
                world.setBlock(chunkX + 7, h + 7, chunkZ + 3, Blocks.air, 0, 2);
                world.setBlock(chunkX + 8, h + 7, chunkZ + 3, Blocks.air, 0, 2);
                world.setBlock(chunkX + 9, h + 7, chunkZ + 3, Blocks.stonebrick, 0, 2);
                world.setBlock(chunkX + 10, h + 7, chunkZ + 3, Blocks.air, 0, 2);
                world.setBlock(chunkX + 0, h + 7, chunkZ + 4, Blocks.air, 0, 2);
                world.setBlock(chunkX + 1, h + 7, chunkZ + 4, Blocks.stonebrick, 0, 2);
                world.setBlock(chunkX + 2, h + 7, chunkZ + 4, Blocks.air, 0, 2);
                world.setBlock(chunkX + 3, h + 7, chunkZ + 4, Blocks.air, 0, 2);
                world.setBlock(chunkX + 4, h + 7, chunkZ + 4, Blocks.air, 0, 2);
                world.setBlock(chunkX + 5, h + 7, chunkZ + 4, Blocks.air, 0, 2);
                world.setBlock(chunkX + 6, h + 7, chunkZ + 4, Blocks.air, 0, 2);
                world.setBlock(chunkX + 7, h + 7, chunkZ + 4, Blocks.air, 0, 2);
                world.setBlock(chunkX + 8, h + 7, chunkZ + 4, Blocks.air, 0, 2);
                world.setBlock(chunkX + 9, h + 7, chunkZ + 4, Blocks.stonebrick, 0, 2);
                world.setBlock(chunkX + 10, h + 7, chunkZ + 4, Blocks.air, 0, 2);
                world.setBlock(chunkX + 0, h + 7, chunkZ + 5, Blocks.air, 0, 2);
                world.setBlock(chunkX + 1, h + 7, chunkZ + 5, Blocks.stonebrick, 0, 2);
                world.setBlock(chunkX + 2, h + 7, chunkZ + 5, Blocks.air, 0, 2);
                world.setBlock(chunkX + 3, h + 7, chunkZ + 5, Blocks.air, 0, 2);
                world.setBlock(chunkX + 4, h + 7, chunkZ + 5, Blocks.air, 0, 2);
                world.setBlock(chunkX + 5, h + 7, chunkZ + 5, Blocks.air, 0, 2);
                world.setBlock(chunkX + 6, h + 7, chunkZ + 5, Blocks.air, 0, 2);
                world.setBlock(chunkX + 7, h + 7, chunkZ + 5, Blocks.air, 0, 2);
                world.setBlock(chunkX + 8, h + 7, chunkZ + 5, Blocks.air, 0, 2);
                world.setBlock(chunkX + 9, h + 7, chunkZ + 5, Blocks.stonebrick, 0, 2);
                world.setBlock(chunkX + 10, h + 7, chunkZ + 5, Blocks.air, 0, 2);
                world.setBlock(chunkX + 0, h + 7, chunkZ + 6, Blocks.air, 0, 2);
                world.setBlock(chunkX + 1, h + 7, chunkZ + 6, Blocks.stonebrick, 0, 2);
                world.setBlock(chunkX + 2, h + 7, chunkZ + 6, Blocks.air, 0, 2);
                world.setBlock(chunkX + 3, h + 7, chunkZ + 6, (Block)Blocks.double_stone_slab, 0, 2);
                world.setBlock(chunkX + 4, h + 7, chunkZ + 6, (Block)Blocks.double_stone_slab, 0, 2);
                world.setBlock(chunkX + 5, h + 7, chunkZ + 6, (Block)Blocks.double_stone_slab, 0, 2);
                world.setBlock(chunkX + 6, h + 7, chunkZ + 6, (Block)Blocks.double_stone_slab, 0, 2);
                world.setBlock(chunkX + 7, h + 7, chunkZ + 6, (Block)Blocks.double_stone_slab, 0, 2);
                world.setBlock(chunkX + 8, h + 7, chunkZ + 6, Blocks.air, 0, 2);
                world.setBlock(chunkX + 9, h + 7, chunkZ + 6, Blocks.stonebrick, 0, 2);
                world.setBlock(chunkX + 10, h + 7, chunkZ + 6, Blocks.air, 0, 2);
                world.setBlock(chunkX + 0, h + 7, chunkZ + 7, Blocks.air, 0, 2);
                world.setBlock(chunkX + 1, h + 7, chunkZ + 7, Blocks.stonebrick, 0, 2);
                world.setBlock(chunkX + 2, h + 7, chunkZ + 7, Blocks.air, 0, 2);
                world.setBlock(chunkX + 3, h + 7, chunkZ + 7, (Block)Blocks.double_stone_slab, 0, 2);
                world.setBlock(chunkX + 4, h + 7, chunkZ + 7, Blocks.air, 0, 2);
                world.setBlock(chunkX + 5, h + 7, chunkZ + 7, Blocks.air, 0, 2);
                world.setBlock(chunkX + 6, h + 7, chunkZ + 7, Blocks.air, 0, 2);
                world.setBlock(chunkX + 7, h + 7, chunkZ + 7, (Block)Blocks.double_stone_slab, 0, 2);
                world.setBlock(chunkX + 8, h + 7, chunkZ + 7, Blocks.air, 0, 2);
                world.setBlock(chunkX + 9, h + 7, chunkZ + 7, Blocks.stonebrick, 0, 2);
                world.setBlock(chunkX + 10, h + 7, chunkZ + 7, Blocks.air, 0, 2);
                world.setBlock(chunkX + 0, h + 7, chunkZ + 8, Blocks.air, 0, 2);
                world.setBlock(chunkX + 1, h + 7, chunkZ + 8, Blocks.stonebrick, 0, 2);
                world.setBlock(chunkX + 2, h + 7, chunkZ + 8, Blocks.air, 0, 2);
                world.setBlock(chunkX + 3, h + 7, chunkZ + 8, (Block)Blocks.double_stone_slab, 0, 2);
                world.setBlock(chunkX + 4, h + 7, chunkZ + 8, (Block)Blocks.double_stone_slab, 0, 2);
                world.setBlock(chunkX + 5, h + 7, chunkZ + 8, (Block)Blocks.double_stone_slab, 0, 2);
                world.setBlock(chunkX + 6, h + 7, chunkZ + 8, (Block)Blocks.double_stone_slab, 0, 2);
                world.setBlock(chunkX + 7, h + 7, chunkZ + 8, (Block)Blocks.double_stone_slab, 0, 2);
                world.setBlock(chunkX + 8, h + 7, chunkZ + 8, Blocks.air, 0, 2);
                world.setBlock(chunkX + 9, h + 7, chunkZ + 8, Blocks.stonebrick, 0, 2);
                world.setBlock(chunkX + 10, h + 7, chunkZ + 8, Blocks.air, 0, 2);
                world.setBlock(chunkX + 0, h + 7, chunkZ + 9, Blocks.air, 0, 2);
                world.setBlock(chunkX + 1, h + 7, chunkZ + 9, Blocks.stonebrick, 0, 2);
                world.setBlock(chunkX + 2, h + 7, chunkZ + 9, Blocks.air, 0, 2);
                world.setBlock(chunkX + 3, h + 7, chunkZ + 9, Blocks.air, 0, 2);
                world.setBlock(chunkX + 4, h + 7, chunkZ + 9, Blocks.air, 0, 2);
                world.setBlock(chunkX + 5, h + 7, chunkZ + 9, Blocks.air, 0, 2);
                world.setBlock(chunkX + 6, h + 7, chunkZ + 9, Blocks.air, 0, 2);
                world.setBlock(chunkX + 7, h + 7, chunkZ + 9, Blocks.air, 0, 2);
                world.setBlock(chunkX + 8, h + 7, chunkZ + 9, Blocks.air, 0, 2);
                world.setBlock(chunkX + 9, h + 7, chunkZ + 9, Blocks.stonebrick, 0, 2);
                world.setBlock(chunkX + 10, h + 7, chunkZ + 9, Blocks.air, 0, 2);
                world.setBlock(chunkX + 0, h + 7, chunkZ + 10, Blocks.air, 0, 2);
                world.setBlock(chunkX + 1, h + 7, chunkZ + 10, Blocks.stonebrick, 0, 2);
                world.setBlock(chunkX + 2, h + 7, chunkZ + 10, Blocks.stonebrick, 0, 2);
                world.setBlock(chunkX + 3, h + 7, chunkZ + 10, Blocks.stonebrick, 0, 2);
                world.setBlock(chunkX + 4, h + 7, chunkZ + 10, Blocks.stonebrick, 0, 2);
                world.setBlock(chunkX + 5, h + 7, chunkZ + 10, Blocks.stonebrick, 0, 2);
                world.setBlock(chunkX + 6, h + 7, chunkZ + 10, Blocks.stonebrick, 0, 2);
                world.setBlock(chunkX + 7, h + 7, chunkZ + 10, Blocks.stonebrick, 0, 2);
                world.setBlock(chunkX + 8, h + 7, chunkZ + 10, Blocks.stonebrick, 0, 2);
                world.setBlock(chunkX + 9, h + 7, chunkZ + 10, Blocks.stonebrick, 0, 2);
                world.setBlock(chunkX + 10, h + 7, chunkZ + 10, Blocks.air, 0, 2);
                world.setBlock(chunkX + 0, h + 7, chunkZ + 11, Blocks.air, 0, 2);
                world.setBlock(chunkX + 1, h + 7, chunkZ + 11, Blocks.stonebrick, 0, 2);
                world.setBlock(chunkX + 2, h + 7, chunkZ + 11, Blocks.stonebrick, 0, 2);
                world.setBlock(chunkX + 3, h + 7, chunkZ + 11, Blocks.stonebrick, 0, 2);
                world.setBlock(chunkX + 4, h + 7, chunkZ + 11, Blocks.stonebrick, 0, 2);
                world.setBlock(chunkX + 5, h + 7, chunkZ + 11, Blocks.stonebrick, 0, 2);
                world.setBlock(chunkX + 6, h + 7, chunkZ + 11, Blocks.stonebrick, 0, 2);
                world.setBlock(chunkX + 7, h + 7, chunkZ + 11, Blocks.stonebrick, 0, 2);
                world.setBlock(chunkX + 8, h + 7, chunkZ + 11, Blocks.stonebrick, 0, 2);
                world.setBlock(chunkX + 9, h + 7, chunkZ + 11, Blocks.stonebrick, 0, 2);
                world.setBlock(chunkX + 10, h + 7, chunkZ + 11, Blocks.air, 0, 2);
                world.setBlock(chunkX + 0, h + 7, chunkZ + 12, Blocks.air, 0, 2);
                world.setBlock(chunkX + 1, h + 7, chunkZ + 12, Blocks.stonebrick, 0, 2);
                world.setBlock(chunkX + 2, h + 7, chunkZ + 12, Blocks.stonebrick, 0, 2);
                world.setBlock(chunkX + 3, h + 7, chunkZ + 12, Blocks.stonebrick, 0, 2);
                world.setBlock(chunkX + 4, h + 7, chunkZ + 12, Blocks.stonebrick, 0, 2);
                world.setBlock(chunkX + 5, h + 7, chunkZ + 12, Blocks.stonebrick, 0, 2);
                world.setBlock(chunkX + 6, h + 7, chunkZ + 12, Blocks.stonebrick, 0, 2);
                world.setBlock(chunkX + 7, h + 7, chunkZ + 12, Blocks.stonebrick, 0, 2);
                world.setBlock(chunkX + 8, h + 7, chunkZ + 12, Blocks.stonebrick, 0, 2);
                world.setBlock(chunkX + 9, h + 7, chunkZ + 12, Blocks.stonebrick, 0, 2);
                world.setBlock(chunkX + 10, h + 7, chunkZ + 12, Blocks.air, 0, 2);
                world.setBlock(chunkX + 0, h + 7, chunkZ + 13, Blocks.air, 0, 2);
                world.setBlock(chunkX + 1, h + 7, chunkZ + 13, Blocks.air, 0, 2);
                world.setBlock(chunkX + 2, h + 7, chunkZ + 13, Blocks.air, 0, 2);
                world.setBlock(chunkX + 3, h + 7, chunkZ + 13, Blocks.air, 0, 2);
                world.setBlock(chunkX + 4, h + 7, chunkZ + 13, Blocks.air, 0, 2);
                world.setBlock(chunkX + 5, h + 7, chunkZ + 13, Blocks.air, 0, 2);
                world.setBlock(chunkX + 6, h + 7, chunkZ + 13, Blocks.air, 0, 2);
                world.setBlock(chunkX + 7, h + 7, chunkZ + 13, Blocks.air, 0, 2);
                world.setBlock(chunkX + 8, h + 7, chunkZ + 13, Blocks.air, 0, 2);
                world.setBlock(chunkX + 9, h + 7, chunkZ + 13, Blocks.air, 0, 2);
                world.setBlock(chunkX + 10, h + 7, chunkZ + 13, Blocks.air, 0, 2);
                world.setBlock(chunkX + 0, h + 8, chunkZ + 0, Blocks.air, 0, 2);
                world.setBlock(chunkX + 1, h + 8, chunkZ + 0, Blocks.air, 0, 2);
                world.setBlock(chunkX + 2, h + 8, chunkZ + 0, Blocks.air, 0, 2);
                world.setBlock(chunkX + 3, h + 8, chunkZ + 0, Blocks.air, 0, 2);
                world.setBlock(chunkX + 4, h + 8, chunkZ + 0, Blocks.cobblestone_wall, 0, 2);
                world.setBlock(chunkX + 5, h + 8, chunkZ + 0, Blocks.air, 0, 2);
                world.setBlock(chunkX + 6, h + 8, chunkZ + 0, Blocks.cobblestone_wall, 0, 2);
                world.setBlock(chunkX + 7, h + 8, chunkZ + 0, Blocks.air, 0, 2);
                world.setBlock(chunkX + 8, h + 8, chunkZ + 0, Blocks.air, 0, 2);
                world.setBlock(chunkX + 9, h + 8, chunkZ + 0, Blocks.air, 0, 2);
                world.setBlock(chunkX + 10, h + 8, chunkZ + 0, Blocks.air, 0, 2);
                world.setBlock(chunkX + 0, h + 8, chunkZ + 1, Blocks.air, 0, 2);
                world.setBlock(chunkX + 1, h + 8, chunkZ + 1, Blocks.stonebrick, 0, 2);
                world.setBlock(chunkX + 2, h + 8, chunkZ + 1, Blocks.stonebrick, 0, 2);
                world.setBlock(chunkX + 3, h + 8, chunkZ + 1, Blocks.air, 0, 2);
