package apocalypse.fandomcraft.structures;

import net.minecraft.world.*;
import java.util.*;
import net.minecraft.world.biome.*;
import net.minecraft.init.*;
import apocalypse.fandomcraft.main.*;
import net.minecraft.block.*;
import net.minecraft.tileentity.*;
import net.minecraftforge.common.*;
import net.minecraft.util.*;
import net.minecraft.inventory.*;
import net.minecraft.world.gen.structure.*;
import net.minecraft.nbt.*;

public class DungeonRoyalHall extends StructureComponent
{
    public boolean place;
    
    public void generateSurface(final World world, final Random random, final int chunkX, final int chunkY, final int chunkZ) {
        final int h = 20 + random.nextInt(30);
        final int y = world.getHeightValue(chunkX, chunkZ) - h;
        if (this.place = true) {
            if (!world.getBiomeGenForCoords(chunkX, chunkZ).biomeName.equals(BiomeGenBase.extremeHills.biomeName)) {
                if (!world.getBiomeGenForCoords(chunkX, chunkZ).biomeName.equals(BiomeGenBase.extremeHillsPlus.biomeName)) {
                    return;
                }
            }
            world.setBlock(chunkX + 0, y + 0, chunkZ + 0, Blocks.air, 0, 2);
            world.setBlock(chunkX + 1, y + 0, chunkZ + 0, Blocks.air, 0, 2);
            world.setBlock(chunkX + 2, y + 0, chunkZ + 0, Blocks.air, 0, 2);
            world.setBlock(chunkX + 3, y + 0, chunkZ + 0, Blocks.air, 0, 2);
            world.setBlock(chunkX + 4, y + 0, chunkZ + 0, Blocks.air, 0, 2);
            world.setBlock(chunkX + 5, y + 0, chunkZ + 0, Blocks.air, 0, 2);
            world.setBlock(chunkX + 6, y + 0, chunkZ + 0, Blocks.air, 0, 2);
            world.setBlock(chunkX + 7, y + 0, chunkZ + 0, Main.sepiaBrick, 0, 2);
            world.setBlock(chunkX + 8, y + 0, chunkZ + 0, Main.sepiaBrick, 0, 2);
            world.setBlock(chunkX + 9, y + 0, chunkZ + 0, Main.sepiaBrick, 0, 2);
            world.setBlock(chunkX + 10, y + 0, chunkZ + 0, Blocks.air, 0, 2);
            world.setBlock(chunkX + 11, y + 0, chunkZ + 0, Blocks.air, 0, 2);
            world.setBlock(chunkX + 12, y + 0, chunkZ + 0, Blocks.air, 0, 2);
            world.setBlock(chunkX + 13, y + 0, chunkZ + 0, Blocks.air, 0, 2);
            world.setBlock(chunkX + 14, y + 0, chunkZ + 0, Blocks.air, 0, 2);
            world.setBlock(chunkX + 15, y + 0, chunkZ + 0, Blocks.air, 0, 2);
            world.setBlock(chunkX + 16, y + 0, chunkZ + 0, Blocks.air, 0, 2);
            world.setBlock(chunkX + 0, y + 0, chunkZ + 1, Blocks.air, 0, 2);
            world.setBlock(chunkX + 1, y + 0, chunkZ + 1, Blocks.air, 0, 2);
            world.setBlock(chunkX + 2, y + 0, chunkZ + 1, Blocks.air, 0, 2);
            world.setBlock(chunkX + 3, y + 0, chunkZ + 1, Blocks.air, 0, 2);
            world.setBlock(chunkX + 4, y + 0, chunkZ + 1, Blocks.air, 0, 2);
            world.setBlock(chunkX + 5, y + 0, chunkZ + 1, Main.sepiaBrick, 0, 2);
            world.setBlock(chunkX + 6, y + 0, chunkZ + 1, Main.sepiaBrick, 0, 2);
            world.setBlock(chunkX + 7, y + 0, chunkZ + 1, Blocks.stone, 0, 2);
            world.setBlock(chunkX + 8, y + 0, chunkZ + 1, Blocks.stone, 0, 2);
            world.setBlock(chunkX + 9, y + 0, chunkZ + 1, Blocks.stone, 0, 2);
            world.setBlock(chunkX + 10, y + 0, chunkZ + 1, Main.sepiaBrick, 0, 2);
            world.setBlock(chunkX + 11, y + 0, chunkZ + 1, Main.sepiaBrick, 0, 2);
            world.setBlock(chunkX + 12, y + 0, chunkZ + 1, Blocks.air, 0, 2);
            world.setBlock(chunkX + 13, y + 0, chunkZ + 1, Blocks.air, 0, 2);
            world.setBlock(chunkX + 14, y + 0, chunkZ + 1, Blocks.air, 0, 2);
            world.setBlock(chunkX + 15, y + 0, chunkZ + 1, Blocks.air, 0, 2);
            world.setBlock(chunkX + 16, y + 0, chunkZ + 1, Blocks.air, 0, 2);
            world.setBlock(chunkX + 0, y + 0, chunkZ + 2, Blocks.air, 0, 2);
            world.setBlock(chunkX + 1, y + 0, chunkZ + 2, Blocks.air, 0, 2);
            world.setBlock(chunkX + 2, y + 0, chunkZ + 2, Blocks.air, 0, 2);
            world.setBlock(chunkX + 3, y + 0, chunkZ + 2, Blocks.air, 0, 2);
            world.setBlock(chunkX + 4, y + 0, chunkZ + 2, Main.sepiaBrick, 0, 2);
            world.setBlock(chunkX + 5, y + 0, chunkZ + 2, Blocks.stone, 0, 2);
            world.setBlock(chunkX + 6, y + 0, chunkZ + 2, Blocks.stone, 0, 2);
            world.setBlock(chunkX + 7, y + 0, chunkZ + 2, Main.sepiaBlock, 0, 2);
            world.setBlock(chunkX + 8, y + 0, chunkZ + 2, Main.sepiaBlock, 0, 2);
            world.setBlock(chunkX + 9, y + 0, chunkZ + 2, Main.sepiaBlock, 0, 2);
            world.setBlock(chunkX + 10, y + 0, chunkZ + 2, Blocks.stone, 0, 2);
            world.setBlock(chunkX + 11, y + 0, chunkZ + 2, Blocks.stone, 0, 2);
            world.setBlock(chunkX + 12, y + 0, chunkZ + 2, Main.sepiaBrick, 0, 2);
            world.setBlock(chunkX + 13, y + 0, chunkZ + 2, Blocks.air, 0, 2);
            world.setBlock(chunkX + 14, y + 0, chunkZ + 2, Blocks.air, 0, 2);
            world.setBlock(chunkX + 15, y + 0, chunkZ + 2, Blocks.air, 0, 2);
            world.setBlock(chunkX + 16, y + 0, chunkZ + 2, Blocks.air, 0, 2);
            world.setBlock(chunkX + 0, y + 0, chunkZ + 3, Blocks.air, 0, 2);
            world.setBlock(chunkX + 1, y + 0, chunkZ + 3, Blocks.air, 0, 2);
            world.setBlock(chunkX + 2, y + 0, chunkZ + 3, Blocks.air, 0, 2);
            world.setBlock(chunkX + 3, y + 0, chunkZ + 3, Main.sepiaBrick, 0, 2);
            world.setBlock(chunkX + 4, y + 0, chunkZ + 3, Blocks.stone, 0, 2);
            world.setBlock(chunkX + 5, y + 0, chunkZ + 3, Main.sepiaBlock, 0, 2);
            world.setBlock(chunkX + 6, y + 0, chunkZ + 3, Blocks.stone, 0, 2);
            world.setBlock(chunkX + 7, y + 0, chunkZ + 3, Main.sepiaBlock, 0, 2);
            world.setBlock(chunkX + 8, y + 0, chunkZ + 3, Main.sepiaBlock, 0, 2);
            world.setBlock(chunkX + 9, y + 0, chunkZ + 3, Main.sepiaBlock, 0, 2);
            world.setBlock(chunkX + 10, y + 0, chunkZ + 3, Blocks.stone, 0, 2);
            world.setBlock(chunkX + 11, y + 0, chunkZ + 3, Main.sepiaBlock, 0, 2);
            world.setBlock(chunkX + 12, y + 0, chunkZ + 3, Blocks.stone, 0, 2);
            world.setBlock(chunkX + 13, y + 0, chunkZ + 3, Main.sepiaBrick, 0, 2);
            world.setBlock(chunkX + 14, y + 0, chunkZ + 3, Blocks.air, 0, 2);
            world.setBlock(chunkX + 15, y + 0, chunkZ + 3, Blocks.air, 0, 2);
            world.setBlock(chunkX + 16, y + 0, chunkZ + 3, Blocks.air, 0, 2);
            world.setBlock(chunkX + 0, y + 0, chunkZ + 4, Blocks.air, 0, 2);
            world.setBlock(chunkX + 1, y + 0, chunkZ + 4, Blocks.air, 0, 2);
            world.setBlock(chunkX + 2, y + 0, chunkZ + 4, Main.sepiaBrick, 0, 2);
            world.setBlock(chunkX + 3, y + 0, chunkZ + 4, Blocks.stone, 0, 2);
            world.setBlock(chunkX + 4, y + 0, chunkZ + 4, Main.sepiaBlock, 0, 2);
            world.setBlock(chunkX + 5, y + 0, chunkZ + 4, Main.sepiaBlock, 0, 2);
            world.setBlock(chunkX + 6, y + 0, chunkZ + 4, Blocks.wool, 3, 2);
            world.setBlock(chunkX + 7, y + 0, chunkZ + 4, Blocks.wool, 3, 2);
            world.setBlock(chunkX + 8, y + 0, chunkZ + 4, Blocks.wool, 3, 2);
            world.setBlock(chunkX + 9, y + 0, chunkZ + 4, Blocks.wool, 3, 2);
            world.setBlock(chunkX + 10, y + 0, chunkZ + 4, Blocks.wool, 3, 2);
            world.setBlock(chunkX + 11, y + 0, chunkZ + 4, Main.sepiaBlock, 0, 2);
            world.setBlock(chunkX + 12, y + 0, chunkZ + 4, Main.sepiaBlock, 0, 2);
            world.setBlock(chunkX + 13, y + 0, chunkZ + 4, Blocks.stone, 0, 2);
            world.setBlock(chunkX + 14, y + 0, chunkZ + 4, Main.sepiaBrick, 0, 2);
            world.setBlock(chunkX + 15, y + 0, chunkZ + 4, Blocks.air, 0, 2);
            world.setBlock(chunkX + 16, y + 0, chunkZ + 4, Blocks.air, 0, 2);
            world.setBlock(chunkX + 0, y + 0, chunkZ + 5, Blocks.air, 0, 2);
            world.setBlock(chunkX + 1, y + 0, chunkZ + 5, Main.sepiaBrick, 0, 2);
            world.setBlock(chunkX + 2, y + 0, chunkZ + 5, Blocks.stone, 0, 2);
            world.setBlock(chunkX + 3, y + 0, chunkZ + 5, Main.sepiaBlock, 0, 2);
            world.setBlock(chunkX + 4, y + 0, chunkZ + 5, Main.sepiaBlock, 0, 2);
            world.setBlock(chunkX + 5, y + 0, chunkZ + 5, Blocks.wool, 3, 2);
            world.setBlock(chunkX + 6, y + 0, chunkZ + 5, Blocks.wool, 3, 2);
            world.setBlock(chunkX + 7, y + 0, chunkZ + 5, Blocks.wool, 15, 2);
            world.setBlock(chunkX + 8, y + 0, chunkZ + 5, Blocks.wool, 15, 2);
            world.setBlock(chunkX + 9, y + 0, chunkZ + 5, Blocks.wool, 15, 2);
            world.setBlock(chunkX + 10, y + 0, chunkZ + 5, Blocks.wool, 3, 2);
            world.setBlock(chunkX + 11, y + 0, chunkZ + 5, Blocks.wool, 3, 2);
            world.setBlock(chunkX + 12, y + 0, chunkZ + 5, Main.sepiaBlock, 0, 2);
            world.setBlock(chunkX + 13, y + 0, chunkZ + 5, Main.sepiaBlock, 0, 2);
            world.setBlock(chunkX + 14, y + 0, chunkZ + 5, Blocks.stone, 0, 2);
            world.setBlock(chunkX + 15, y + 0, chunkZ + 5, Main.sepiaBrick, 0, 2);
            world.setBlock(chunkX + 16, y + 0, chunkZ + 5, Blocks.air, 0, 2);
            world.setBlock(chunkX + 0, y + 0, chunkZ + 6, Main.sepiaBrick, 0, 2);
            world.setBlock(chunkX + 1, y + 0, chunkZ + 6, Blocks.stone, 0, 2);
            world.setBlock(chunkX + 2, y + 0, chunkZ + 6, Main.sepiaBlock, 0, 2);
            world.setBlock(chunkX + 3, y + 0, chunkZ + 6, Main.sepiaBlock, 0, 2);
            world.setBlock(chunkX + 4, y + 0, chunkZ + 6, Blocks.wool, 3, 2);
            world.setBlock(chunkX + 5, y + 0, chunkZ + 6, Blocks.wool, 3, 2);
            world.setBlock(chunkX + 6, y + 0, chunkZ + 6, Blocks.wool, 15, 2);
            world.setBlock(chunkX + 7, y + 0, chunkZ + 6, Blocks.wool, 15, 2);
            world.setBlock(chunkX + 8, y + 0, chunkZ + 6, Blocks.wool, 4, 2);
            world.setBlock(chunkX + 9, y + 0, chunkZ + 6, Blocks.wool, 15, 2);
            world.setBlock(chunkX + 10, y + 0, chunkZ + 6, Blocks.wool, 15, 2);
            world.setBlock(chunkX + 11, y + 0, chunkZ + 6, Blocks.wool, 3, 2);
            world.setBlock(chunkX + 12, y + 0, chunkZ + 6, Blocks.wool, 3, 2);
            world.setBlock(chunkX + 13, y + 0, chunkZ + 6, Main.sepiaBlock, 0, 2);
            world.setBlock(chunkX + 14, y + 0, chunkZ + 6, Main.sepiaBlock, 0, 2);
            world.setBlock(chunkX + 15, y + 0, chunkZ + 6, Blocks.stone, 0, 2);
            world.setBlock(chunkX + 16, y + 0, chunkZ + 6, Main.sepiaBrick, 0, 2);
            world.setBlock(chunkX + 0, y + 0, chunkZ + 7, Main.sepiaBrick, 0, 2);
            world.setBlock(chunkX + 1, y + 0, chunkZ + 7, Blocks.stone, 0, 2);
            world.setBlock(chunkX + 2, y + 0, chunkZ + 7, Main.sepiaBlock, 0, 2);
            world.setBlock(chunkX + 3, y + 0, chunkZ + 7, Blocks.wool, 3, 2);
            world.setBlock(chunkX + 4, y + 0, chunkZ + 7, Blocks.wool, 3, 2);
            world.setBlock(chunkX + 5, y + 0, chunkZ + 7, Blocks.wool, 15, 2);
            world.setBlock(chunkX + 6, y + 0, chunkZ + 7, Blocks.wool, 15, 2);
            world.setBlock(chunkX + 7, y + 0, chunkZ + 7, Blocks.wool, 4, 2);
            world.setBlock(chunkX + 8, y + 0, chunkZ + 7, Blocks.wool, 4, 2);
            world.setBlock(chunkX + 9, y + 0, chunkZ + 7, Blocks.wool, 4, 2);
            world.setBlock(chunkX + 10, y + 0, chunkZ + 7, Blocks.wool, 15, 2);
            world.setBlock(chunkX + 11, y + 0, chunkZ + 7, Blocks.wool, 15, 2);
            world.setBlock(chunkX + 12, y + 0, chunkZ + 7, Blocks.wool, 3, 2);
            world.setBlock(chunkX + 13, y + 0, chunkZ + 7, Blocks.wool, 3, 2);
            world.setBlock(chunkX + 14, y + 0, chunkZ + 7, Main.sepiaBlock, 0, 2);
            world.setBlock(chunkX + 15, y + 0, chunkZ + 7, Blocks.stone, 0, 2);
            world.setBlock(chunkX + 16, y + 0, chunkZ + 7, Main.sepiaBrick, 0, 2);
            world.setBlock(chunkX + 0, y + 0, chunkZ + 8, Main.sepiaBrick, 0, 2);
            world.setBlock(chunkX + 1, y + 0, chunkZ + 8, Blocks.stone, 0, 2);
            world.setBlock(chunkX + 2, y + 0, chunkZ + 8, Main.sepiaBlock, 0, 2);
            world.setBlock(chunkX + 3, y + 0, chunkZ + 8, Blocks.wool, 3, 2);
            world.setBlock(chunkX + 4, y + 0, chunkZ + 8, Blocks.wool, 15, 2);
            world.setBlock(chunkX + 5, y + 0, chunkZ + 8, Blocks.wool, 15, 2);
            world.setBlock(chunkX + 6, y + 0, chunkZ + 8, Blocks.wool, 4, 2);
            world.setBlock(chunkX + 7, y + 0, chunkZ + 8, Blocks.wool, 15, 2);
            world.setBlock(chunkX + 8, y + 0, chunkZ + 8, Blocks.wool, 15, 2);
            world.setBlock(chunkX + 9, y + 0, chunkZ + 8, Blocks.wool, 15, 2);
            world.setBlock(chunkX + 10, y + 0, chunkZ + 8, Blocks.wool, 4, 2);
            world.setBlock(chunkX + 11, y + 0, chunkZ + 8, Blocks.wool, 15, 2);
            world.setBlock(chunkX + 12, y + 0, chunkZ + 8, Blocks.wool, 15, 2);
            world.setBlock(chunkX + 13, y + 0, chunkZ + 8, Blocks.wool, 3, 2);
            world.setBlock(chunkX + 14, y + 0, chunkZ + 8, Main.sepiaBlock, 0, 2);
            world.setBlock(chunkX + 15, y + 0, chunkZ + 8, Blocks.stone, 0, 2);
            world.setBlock(chunkX + 16, y + 0, chunkZ + 8, Main.sepiaBrick, 0, 2);
            world.setBlock(chunkX + 0, y + 0, chunkZ + 9, Main.sepiaBrick, 0, 2);
            world.setBlock(chunkX + 1, y + 0, chunkZ + 9, Blocks.stone, 0, 2);
            world.setBlock(chunkX + 2, y + 0, chunkZ + 9, Main.sepiaBlock, 0, 2);
            world.setBlock(chunkX + 3, y + 0, chunkZ + 9, Blocks.wool, 3, 2);
            world.setBlock(chunkX + 4, y + 0, chunkZ + 9, Blocks.wool, 15, 2);
            world.setBlock(chunkX + 5, y + 0, chunkZ + 9, Blocks.wool, 4, 2);
            world.setBlock(chunkX + 6, y + 0, chunkZ + 9, Blocks.wool, 4, 2);
            world.setBlock(chunkX + 7, y + 0, chunkZ + 9, Blocks.wool, 4, 2);
            world.setBlock(chunkX + 8, y + 0, chunkZ + 9, Blocks.wool, 15, 2);
            world.setBlock(chunkX + 9, y + 0, chunkZ + 9, Blocks.wool, 4, 2);
            world.setBlock(chunkX + 10, y + 0, chunkZ + 9, Blocks.wool, 4, 2);
            world.setBlock(chunkX + 11, y + 0, chunkZ + 9, Blocks.wool, 4, 2);
            world.setBlock(chunkX + 12, y + 0, chunkZ + 9, Blocks.wool, 15, 2);
            world.setBlock(chunkX + 13, y + 0, chunkZ + 9, Blocks.wool, 3, 2);
            world.setBlock(chunkX + 14, y + 0, chunkZ + 9, Main.sepiaBlock, 0, 2);
            world.setBlock(chunkX + 15, y + 0, chunkZ + 9, Blocks.stone, 0, 2);
            world.setBlock(chunkX + 16, y + 0, chunkZ + 9, Main.sepiaBrick, 0, 2);
            world.setBlock(chunkX + 0, y + 0, chunkZ + 10, Main.sepiaBrick, 0, 2);
            world.setBlock(chunkX + 1, y + 0, chunkZ + 10, Blocks.stone, 0, 2);
            world.setBlock(chunkX + 2, y + 0, chunkZ + 10, Main.sepiaBlock, 0, 2);
            world.setBlock(chunkX + 3, y + 0, chunkZ + 10, Blocks.wool, 3, 2);
            world.setBlock(chunkX + 4, y + 0, chunkZ + 10, Blocks.wool, 15, 2);
            world.setBlock(chunkX + 5, y + 0, chunkZ + 10, Blocks.wool, 15, 2);
            world.setBlock(chunkX + 6, y + 0, chunkZ + 10, Blocks.wool, 15, 2);
            world.setBlock(chunkX + 7, y + 0, chunkZ + 10, Blocks.wool, 15, 2);
            world.setBlock(chunkX + 8, y + 0, chunkZ + 10, Blocks.wool, 15, 2);
            world.setBlock(chunkX + 9, y + 0, chunkZ + 10, Blocks.wool, 15, 2);
            world.setBlock(chunkX + 10, y + 0, chunkZ + 10, Blocks.wool, 15, 2);
            world.setBlock(chunkX + 11, y + 0, chunkZ + 10, Blocks.wool, 15, 2);
            world.setBlock(chunkX + 12, y + 0, chunkZ + 10, Blocks.wool, 15, 2);
            world.setBlock(chunkX + 13, y + 0, chunkZ + 10, Blocks.wool, 3, 2);
            world.setBlock(chunkX + 14, y + 0, chunkZ + 10, Main.sepiaBlock, 0, 2);
            world.setBlock(chunkX + 15, y + 0, chunkZ + 10, Blocks.stone, 0, 2);
            world.setBlock(chunkX + 16, y + 0, chunkZ + 10, Main.sepiaBrick, 0, 2);
            world.setBlock(chunkX + 0, y + 0, chunkZ + 11, Main.sepiaBrick, 0, 2);
            world.setBlock(chunkX + 1, y + 0, chunkZ + 11, Blocks.stone, 0, 2);
            world.setBlock(chunkX + 2, y + 0, chunkZ + 11, Main.sepiaBlock, 0, 2);
            world.setBlock(chunkX + 3, y + 0, chunkZ + 11, Main.sepiaBlock, 0, 2);
            world.setBlock(chunkX + 4, y + 0, chunkZ + 11, Blocks.wool, 3, 2);
            world.setBlock(chunkX + 5, y + 0, chunkZ + 11, Blocks.wool, 3, 2);
            world.setBlock(chunkX + 6, y + 0, chunkZ + 11, Blocks.wool, 3, 2);
            world.setBlock(chunkX + 7, y + 0, chunkZ + 11, Blocks.wool, 3, 2);
            world.setBlock(chunkX + 8, y + 0, chunkZ + 11, Blocks.wool, 3, 2);
            world.setBlock(chunkX + 9, y + 0, chunkZ + 11, Blocks.wool, 3, 2);
            world.setBlock(chunkX + 10, y + 0, chunkZ + 11, Blocks.wool, 3, 2);
            world.setBlock(chunkX + 11, y + 0, chunkZ + 11, Blocks.wool, 3, 2);
            world.setBlock(chunkX + 12, y + 0, chunkZ + 11, Blocks.wool, 3, 2);
            world.setBlock(chunkX + 13, y + 0, chunkZ + 11, Main.sepiaBlock, 0, 2);
            world.setBlock(chunkX + 14, y + 0, chunkZ + 11, Main.sepiaBlock, 0, 2);
            world.setBlock(chunkX + 15, y + 0, chunkZ + 11, Blocks.stone, 0, 2);
            world.setBlock(chunkX + 16, y + 0, chunkZ + 11, Main.sepiaBrick, 0, 2);
            world.setBlock(chunkX + 0, y + 0, chunkZ + 12, Blocks.air, 0, 2);
            world.setBlock(chunkX + 1, y + 0, chunkZ + 12, Main.sepiaBrick, 0, 2);
            world.setBlock(chunkX + 2, y + 0, chunkZ + 12, Blocks.stone, 0, 2);
            world.setBlock(chunkX + 3, y + 0, chunkZ + 12, Main.sepiaBlock, 0, 2);
            world.setBlock(chunkX + 4, y + 0, chunkZ + 12, Main.sepiaBlock, 0, 2);
            world.setBlock(chunkX + 5, y + 0, chunkZ + 12, Main.sepiaBlock, 0, 2);
            world.setBlock(chunkX + 6, y + 0, chunkZ + 12, Main.sepiaBlock, 0, 2);
            world.setBlock(chunkX + 7, y + 0, chunkZ + 12, Main.sepiaBlock, 0, 2);
            world.setBlock(chunkX + 8, y + 0, chunkZ + 12, Main.sepiaBlock, 0, 2);
            world.setBlock(chunkX + 9, y + 0, chunkZ + 12, Main.sepiaBlock, 0, 2);
            world.setBlock(chunkX + 10, y + 0, chunkZ + 12, Main.sepiaBlock, 0, 2);
            world.setBlock(chunkX + 11, y + 0, chunkZ + 12, Main.sepiaBlock, 0, 2);
            world.setBlock(chunkX + 12, y + 0, chunkZ + 12, Main.sepiaBlock, 0, 2);
            world.setBlock(chunkX + 13, y + 0, chunkZ + 12, Main.sepiaBlock, 0, 2);
            world.setBlock(chunkX + 14, y + 0, chunkZ + 12, Blocks.stone, 0, 2);
            world.setBlock(chunkX + 15, y + 0, chunkZ + 12, Main.sepiaBrick, 0, 2);
            world.setBlock(chunkX + 16, y + 0, chunkZ + 12, Blocks.air, 0, 2);
            world.setBlock(chunkX + 0, y + 0, chunkZ + 13, Blocks.air, 0, 2);
            world.setBlock(chunkX + 1, y + 0, chunkZ + 13, Blocks.air, 0, 2);
            world.setBlock(chunkX + 2, y + 0, chunkZ + 13, Main.sepiaBrick, 0, 2);
            world.setBlock(chunkX + 3, y + 0, chunkZ + 13, Blocks.stone, 0, 2);
            world.setBlock(chunkX + 4, y + 0, chunkZ + 13, Blocks.stone, 0, 2);
            world.setBlock(chunkX + 5, y + 0, chunkZ + 13, Blocks.stone, 0, 2);
            world.setBlock(chunkX + 6, y + 0, chunkZ + 13, Main.fairyTowerChiseled, 0, 2);
            world.setBlock(chunkX + 7, y + 0, chunkZ + 13, Blocks.air, 3, 2);
            world.setBlock(chunkX + 8, y + 0, chunkZ + 13, Blocks.air, 3, 2);
            world.setBlock(chunkX + 9, y + 0, chunkZ + 13, Blocks.air, 3, 2);
            world.setBlock(chunkX + 10, y + 0, chunkZ + 13, Main.fairyTowerChiseled, 0, 2);
            world.setBlock(chunkX + 11, y + 0, chunkZ + 13, Blocks.stone, 0, 2);
            world.setBlock(chunkX + 12, y + 0, chunkZ + 13, Blocks.stone, 0, 2);
            world.setBlock(chunkX + 13, y + 0, chunkZ + 13, Blocks.stone, 0, 2);
            world.setBlock(chunkX + 14, y + 0, chunkZ + 13, Main.sepiaBrick, 0, 2);
            world.setBlock(chunkX + 15, y + 0, chunkZ + 13, Blocks.air, 0, 2);
            world.setBlock(chunkX + 16, y + 0, chunkZ + 13, Blocks.air, 0, 2);
            world.setBlock(chunkX + 0, y + 0, chunkZ + 14, Blocks.air, 0, 2);
            world.setBlock(chunkX + 1, y + 0, chunkZ + 14, Blocks.air, 0, 2);
            world.setBlock(chunkX + 2, y + 0, chunkZ + 14, Blocks.air, 0, 2);
            world.setBlock(chunkX + 3, y + 0, chunkZ + 14, Main.sepiaBrick, 0, 2);
            world.setBlock(chunkX + 4, y + 0, chunkZ + 14, Main.sepiaBrick, 0, 2);
            world.setBlock(chunkX + 5, y + 0, chunkZ + 14, Main.sepiaBrick, 0, 2);
            world.setBlock(chunkX + 6, y + 0, chunkZ + 14, Main.fairyTowerChiseled, 0, 2);
            world.setBlock(chunkX + 7, y + 0, chunkZ + 14, Blocks.air, 0, 2);
            world.setBlock(chunkX + 8, y + 0, chunkZ + 14, Blocks.air, 0, 2);
            world.setBlock(chunkX + 9, y + 0, chunkZ + 14, Blocks.air, 0, 2);
            world.setBlock(chunkX + 10, y + 0, chunkZ + 14, Main.fairyTowerChiseled, 0, 2);
            world.setBlock(chunkX + 11, y + 0, chunkZ + 14, Main.sepiaBrick, 0, 2);
            world.setBlock(chunkX + 12, y + 0, chunkZ + 14, Main.sepiaBrick, 0, 2);
            world.setBlock(chunkX + 13, y + 0, chunkZ + 14, Main.sepiaBrick, 0, 2);
            world.setBlock(chunkX + 14, y + 0, chunkZ + 14, Blocks.air, 0, 2);
            world.setBlock(chunkX + 15, y + 0, chunkZ + 14, Blocks.air, 0, 2);
            world.setBlock(chunkX + 16, y + 0, chunkZ + 14, Blocks.air, 0, 2);
            world.setBlock(chunkX + 0, y + 1, chunkZ + 0, Blocks.air, 0, 2);
            world.setBlock(chunkX + 1, y + 1, chunkZ + 0, Blocks.air, 0, 2);
            world.setBlock(chunkX + 2, y + 1, chunkZ + 0, Blocks.air, 0, 2);
            world.setBlock(chunkX + 3, y + 1, chunkZ + 0, Blocks.air, 0, 2);
            world.setBlock(chunkX + 4, y + 1, chunkZ + 0, Blocks.air, 0, 2);
            world.setBlock(chunkX + 5, y + 1, chunkZ + 0, Blocks.air, 0, 2);
            world.setBlock(chunkX + 6, y + 1, chunkZ + 0, Blocks.air, 0, 2);
            world.setBlock(chunkX + 7, y + 1, chunkZ + 0, Main.sepiaBrick, 0, 2);
            world.setBlock(chunkX + 8, y + 1, chunkZ + 0, Main.sepiaBrick, 0, 2);
            world.setBlock(chunkX + 9, y + 1, chunkZ + 0, Main.sepiaBrick, 0, 2);
            world.setBlock(chunkX + 10, y + 1, chunkZ + 0, Blocks.air, 0, 2);
            world.setBlock(chunkX + 11, y + 1, chunkZ + 0, Blocks.air, 0, 2);
            world.setBlock(chunkX + 12, y + 1, chunkZ + 0, Blocks.air, 0, 2);
            world.setBlock(chunkX + 13, y + 1, chunkZ + 0, Blocks.air, 0, 2);
            world.setBlock(chunkX + 14, y + 1, chunkZ + 0, Blocks.air, 0, 2);
            world.setBlock(chunkX + 15, y + 1, chunkZ + 0, Blocks.air, 0, 2);
            world.setBlock(chunkX + 16, y + 1, chunkZ + 0, Blocks.air, 0, 2);
            world.setBlock(chunkX + 0, y + 1, chunkZ + 1, Blocks.air, 0, 2);
            world.setBlock(chunkX + 1, y + 1, chunkZ + 1, Blocks.air, 0, 2);
            world.setBlock(chunkX + 2, y + 1, chunkZ + 1, Blocks.air, 0, 2);
            world.setBlock(chunkX + 3, y + 1, chunkZ + 1, Blocks.air, 0, 2);
            world.setBlock(chunkX + 4, y + 1, chunkZ + 1, Blocks.air, 0, 2);
            world.setBlock(chunkX + 5, y + 1, chunkZ + 1, Main.sepiaBrick, 0, 2);
            world.setBlock(chunkX + 6, y + 1, chunkZ + 1, Main.sepiaBrick, 0, 2);
            world.setBlock(chunkX + 7, y + 1, chunkZ + 1, Main.sepiaBlock, 0, 2);
            world.setBlock(chunkX + 8, y + 1, chunkZ + 1, Main.sepiaBlock, 0, 2);
            world.setBlock(chunkX + 9, y + 1, chunkZ + 1, Main.sepiaBlock, 0, 2);
            world.setBlock(chunkX + 10, y + 1, chunkZ + 1, Main.sepiaBrick, 0, 2);
            world.setBlock(chunkX + 11, y + 1, chunkZ + 1, Main.sepiaBrick, 0, 2);
            world.setBlock(chunkX + 12, y + 1, chunkZ + 1, Blocks.air, 0, 2);
            world.setBlock(chunkX + 13, y + 1, chunkZ + 1, Blocks.air, 0, 2);
            world.setBlock(chunkX + 14, y + 1, chunkZ + 1, Blocks.air, 0, 2);
            world.setBlock(chunkX + 15, y + 1, chunkZ + 1, Blocks.air, 0, 2);
            world.setBlock(chunkX + 16, y + 1, chunkZ + 1, Blocks.air, 0, 2);
            world.setBlock(chunkX + 0, y + 1, chunkZ + 2, Blocks.air, 0, 2);
            world.setBlock(chunkX + 1, y + 1, chunkZ + 2, Blocks.air, 0, 2);
            world.setBlock(chunkX + 2, y + 1, chunkZ + 2, Blocks.air, 0, 2);
            world.setBlock(chunkX + 3, y + 1, chunkZ + 2, Blocks.air, 0, 2);
            world.setBlock(chunkX + 4, y + 1, chunkZ + 2, Main.sepiaBrick, 0, 2);
            world.setBlock(chunkX + 5, y + 1, chunkZ + 2, Blocks.stone, 0, 2);
            world.setBlock(chunkX + 6, y + 1, chunkZ + 2, Main.sepiaBlock, 0, 2);
            world.setBlock(chunkX + 7, y + 1, chunkZ + 2, Blocks.air, 7, 2);
            world.setBlock(chunkX + 8, y + 1, chunkZ + 2, Blocks.air, 7, 2);
            world.setBlock(chunkX + 9, y + 1, chunkZ + 2, Blocks.air, 7, 2);
            world.setBlock(chunkX + 10, y + 1, chunkZ + 2, Main.sepiaBlock, 0, 2);
            world.setBlock(chunkX + 11, y + 1, chunkZ + 2, Blocks.stone, 0, 2);
            world.setBlock(chunkX + 12, y + 1, chunkZ + 2, Main.sepiaBrick, 0, 2);
            world.setBlock(chunkX + 13, y + 1, chunkZ + 2, Blocks.air, 0, 2);
            world.setBlock(chunkX + 14, y + 1, chunkZ + 2, Blocks.air, 0, 2);
            world.setBlock(chunkX + 15, y + 1, chunkZ + 2, Blocks.air, 0, 2);
            world.setBlock(chunkX + 16, y + 1, chunkZ + 2, Blocks.air, 0, 2);
            world.setBlock(chunkX + 0, y + 1, chunkZ + 3, Blocks.air, 0, 2);
            world.setBlock(chunkX + 1, y + 1, chunkZ + 3, Blocks.air, 0, 2);
            world.setBlock(chunkX + 2, y + 1, chunkZ + 3, Blocks.air, 0, 2);
            world.setBlock(chunkX + 3, y + 1, chunkZ + 3, Main.sepiaBrick, 0, 2);
            world.setBlock(chunkX + 4, y + 1, chunkZ + 3, Blocks.stone, 0, 2);
            world.setBlock(chunkX + 5, y + 1, chunkZ + 3, Blocks.air, 0, 2);
            world.setBlock(chunkX + 6, y + 1, chunkZ + 3, Main.fairyTowerChiseled, 0, 2);
            world.setBlock(chunkX + 7, y + 1, chunkZ + 3, Blocks.air, 0, 2);
            world.setBlock(chunkX + 8, y + 1, chunkZ + 3, Blocks.air, 0, 2);
            world.setBlock(chunkX + 9, y + 1, chunkZ + 3, Blocks.air, 0, 2);
            world.setBlock(chunkX + 10, y + 1, chunkZ + 3, Main.fairyTowerChiseled, 0, 2);
            world.setBlock(chunkX + 11, y + 1, chunkZ + 3, Blocks.air, 0, 2);
            world.setBlock(chunkX + 12, y + 1, chunkZ + 3, Blocks.stone, 0, 2);
            world.setBlock(chunkX + 13, y + 1, chunkZ + 3, Main.sepiaBrick, 0, 2);
            world.setBlock(chunkX + 14, y + 1, chunkZ + 3, Blocks.air, 0, 2);
            world.setBlock(chunkX + 15, y + 1, chunkZ + 3, Blocks.air, 0, 2);
            world.setBlock(chunkX + 16, y + 1, chunkZ + 3, Blocks.air, 0, 2);
            world.setBlock(chunkX + 0, y + 1, chunkZ + 4, Blocks.air, 0, 2);
            world.setBlock(chunkX + 1, y + 1, chunkZ + 4, Blocks.air, 0, 2);
            world.setBlock(chunkX + 2, y + 1, chunkZ + 4, Main.sepiaBrick, 0, 2);
            world.setBlock(chunkX + 3, y + 1, chunkZ + 4, Blocks.stone, 0, 2);
            world.setBlock(chunkX + 4, y + 1, chunkZ + 4, Main.bluePot, 0, 2);
            world.setBlock(chunkX + 5, y + 1, chunkZ + 4, Blocks.air, 0, 2);
            world.setBlock(chunkX + 6, y + 1, chunkZ + 4, Blocks.air, 0, 2);
            world.setBlock(chunkX + 7, y + 1, chunkZ + 4, Blocks.air, 0, 2);
            world.setBlock(chunkX + 8, y + 1, chunkZ + 4, Blocks.air, 0, 2);
            world.setBlock(chunkX + 9, y + 1, chunkZ + 4, Blocks.air, 0, 2);
            world.setBlock(chunkX + 10, y + 1, chunkZ + 4, Blocks.air, 0, 2);
            world.setBlock(chunkX + 11, y + 1, chunkZ + 4, Blocks.air, 0, 2);
            world.setBlock(chunkX + 12, y + 1, chunkZ + 4, Main.bluePot, 0, 2);
            world.setBlock(chunkX + 13, y + 1, chunkZ + 4, Blocks.stone, 0, 2);
            world.setBlock(chunkX + 14, y + 1, chunkZ + 4, Main.sepiaBrick, 0, 2);
            world.setBlock(chunkX + 15, y + 1, chunkZ + 4, Blocks.air, 0, 2);
            world.setBlock(chunkX + 16, y + 1, chunkZ + 4, Blocks.air, 0, 2);
            world.setBlock(chunkX + 0, y + 1, chunkZ + 5, Blocks.air, 0, 2);
            world.setBlock(chunkX + 1, y + 1, chunkZ + 5, Main.sepiaBrick, 0, 2);
            world.setBlock(chunkX + 2, y + 1, chunkZ + 5, Blocks.stone, 0, 2);
            world.setBlock(chunkX + 3, y + 1, chunkZ + 5, Blocks.air, 0, 2);
            world.setBlock(chunkX + 4, y + 1, chunkZ + 5, Blocks.air, 0, 2);
            world.setBlock(chunkX + 5, y + 1, chunkZ + 5, Blocks.air, 0, 2);
            world.setBlock(chunkX + 6, y + 1, chunkZ + 5, Blocks.air, 0, 2);
            world.setBlock(chunkX + 7, y + 1, chunkZ + 5, Blocks.air, 0, 2);
            world.setBlock(chunkX + 8, y + 1, chunkZ + 5, Blocks.air, 0, 2);
            world.setBlock(chunkX + 9, y + 1, chunkZ + 5, Blocks.air, 0, 2);
            world.setBlock(chunkX + 10, y + 1, chunkZ + 5, Blocks.air, 0, 2);
            world.setBlock(chunkX + 11, y + 1, chunkZ + 5, Blocks.air, 0, 2);
            world.setBlock(chunkX + 12, y + 1, chunkZ + 5, Blocks.air, 0, 2);
            world.setBlock(chunkX + 13, y + 1, chunkZ + 5, Blocks.air, 0, 2);
            world.setBlock(chunkX + 14, y + 1, chunkZ + 5, Blocks.stone, 0, 2);
            world.setBlock(chunkX + 15, y + 1, chunkZ + 5, Main.sepiaBrick, 0, 2);
            world.setBlock(chunkX + 16, y + 1, chunkZ + 5, Blocks.air, 0, 2);
            world.setBlock(chunkX + 0, y + 1, chunkZ + 6, Main.sepiaBrick, 0, 2);
            world.setBlock(chunkX + 1, y + 1, chunkZ + 6, Blocks.stone, 0, 2);
            world.setBlock(chunkX + 2, y + 1, chunkZ + 6, Blocks.air, 0, 2);
            world.setBlock(chunkX + 3, y + 1, chunkZ + 6, Blocks.air, 0, 2);
            world.setBlock(chunkX + 4, y + 1, chunkZ + 6, Blocks.air, 0, 2);
            world.setBlock(chunkX + 5, y + 1, chunkZ + 6, Blocks.air, 0, 2);
            world.setBlock(chunkX + 6, y + 1, chunkZ + 6, Blocks.air, 0, 2);
            world.setBlock(chunkX + 7, y + 1, chunkZ + 6, Blocks.air, 0, 2);
            world.setBlock(chunkX + 8, y + 1, chunkZ + 6, Blocks.air, 0, 2);
            world.setBlock(chunkX + 9, y + 1, chunkZ + 6, Blocks.air, 0, 2);
            world.setBlock(chunkX + 10, y + 1, chunkZ + 6, Blocks.air, 0, 2);
            world.setBlock(chunkX + 11, y + 1, chunkZ + 6, Blocks.air, 0, 2);
            world.setBlock(chunkX + 12, y + 1, chunkZ + 6, Blocks.air, 0, 2);
            world.setBlock(chunkX + 13, y + 1, chunkZ + 6, Blocks.air, 0, 2);
            world.setBlock(chunkX + 14, y + 1, chunkZ + 6, Blocks.air, 0, 2);
            world.setBlock(chunkX + 15, y + 1, chunkZ + 6, Blocks.stone, 0, 2);
            world.setBlock(chunkX + 16, y + 1, chunkZ + 6, Main.sepiaBrick, 0, 2);
            world.setBlock(chunkX + 0, y + 1, chunkZ + 7, Main.sepiaBrick, 0, 2);
            world.setBlock(chunkX + 1, y + 1, chunkZ + 7, Blocks.stone, 0, 2);
            world.setBlock(chunkX + 2, y + 1, chunkZ + 7, Blocks.air, 0, 2);
            world.setBlock(chunkX + 3, y + 1, chunkZ + 7, Blocks.air, 0, 2);
            world.setBlock(chunkX + 4, y + 1, chunkZ + 7, Blocks.air, 0, 2);
            world.setBlock(chunkX + 5, y + 1, chunkZ + 7, Blocks.air, 0, 2);
            world.setBlock(chunkX + 6, y + 1, chunkZ + 7, Blocks.air, 0, 2);
            world.setBlock(chunkX + 7, y + 1, chunkZ + 7, Blocks.air, 0, 2);
            world.setBlock(chunkX + 8, y + 1, chunkZ + 7, Blocks.air, 0, 2);
            world.setBlock(chunkX + 9, y + 1, chunkZ + 7, Blocks.air, 0, 2);
            world.setBlock(chunkX + 10, y + 1, chunkZ + 7, Blocks.air, 0, 2);
            world.setBlock(chunkX + 11, y + 1, chunkZ + 7, Blocks.air, 0, 2);
            world.setBlock(chunkX + 12, y + 1, chunkZ + 7, Blocks.air, 0, 2);
            world.setBlock(chunkX + 13, y + 1, chunkZ + 7, Blocks.air, 0, 2);
            world.setBlock(chunkX + 14, y + 1, chunkZ + 7, Blocks.air, 0, 2);
            world.setBlock(chunkX + 15, y + 1, chunkZ + 7, Blocks.stone, 0, 2);
            world.setBlock(chunkX + 16, y + 1, chunkZ + 7, Main.sepiaBrick, 0, 2);
            world.setBlock(chunkX + 0, y + 1, chunkZ + 8, Main.sepiaBrick, 0, 2);
            world.setBlock(chunkX + 1, y + 1, chunkZ + 8, Blocks.stone, 0, 2);
            world.setBlock(chunkX + 2, y + 1, chunkZ + 8, Blocks.air, 0, 2);
            world.setBlock(chunkX + 3, y + 1, chunkZ + 8, Blocks.air, 0, 2);
            world.setBlock(chunkX + 4, y + 1, chunkZ + 8, Blocks.air, 0, 2);
            world.setBlock(chunkX + 5, y + 1, chunkZ + 8, Blocks.air, 0, 2);
            world.setBlock(chunkX + 6, y + 1, chunkZ + 8, Blocks.air, 0, 2);
            world.setBlock(chunkX + 7, y + 1, chunkZ + 8, Blocks.air, 0, 2);
            world.setBlock(chunkX + 8, y + 1, chunkZ + 8, Blocks.mob_spawner, 0, 2);
            final int x1 = chunkX + 8;
            final int y2 = y + 1;
            final int z1 = chunkZ + 8;
            final TileEntityMobSpawner tileentitymobspawner1 = (TileEntityMobSpawner)world.getTileEntity(x1, y2, z1);
            if (tileentitymobspawner1 == null) {
                System.err.println("Failed to fetch mob spawner entity at (" + x1 + ", " + y2 + ", " + z1 + ")");
            }
            else {
                tileentitymobspawner1.func_145881_a().setEntityName("MightyDarknut");
            }
            world.setBlock(chunkX + 9, y + 1, chunkZ + 8, Blocks.air, 0, 2);
            world.setBlock(chunkX + 10, y + 1, chunkZ + 8, Blocks.air, 0, 2);
            world.setBlock(chunkX + 11, y + 1, chunkZ + 8, Blocks.air, 0, 2);
            world.setBlock(chunkX + 12, y + 1, chunkZ + 8, Blocks.air, 0, 2);
            world.setBlock(chunkX + 13, y + 1, chunkZ + 8, Blocks.air, 0, 2);
            world.setBlock(chunkX + 14, y + 1, chunkZ + 8, Blocks.air, 0, 2);
            world.setBlock(chunkX + 15, y + 1, chunkZ + 8, Blocks.stone, 0, 2);
            world.setBlock(chunkX + 16, y + 1, chunkZ + 8, Main.sepiaBrick, 0, 2);
            world.setBlock(chunkX + 0, y + 1, chunkZ + 9, Main.sepiaBrick, 0, 2);
            world.setBlock(chunkX + 1, y + 1, chunkZ + 9, Blocks.stone, 0, 2);
            world.setBlock(chunkX + 2, y + 1, chunkZ + 9, Blocks.air, 0, 2);
            world.setBlock(chunkX + 3, y + 1, chunkZ + 9, Blocks.air, 0, 2);
            world.setBlock(chunkX + 4, y + 1, chunkZ + 9, Blocks.air, 0, 2);
            world.setBlock(chunkX + 5, y + 1, chunkZ + 9, Blocks.air, 0, 2);
            world.setBlock(chunkX + 6, y + 1, chunkZ + 9, Blocks.air, 0, 2);
            world.setBlock(chunkX + 7, y + 1, chunkZ + 9, Blocks.air, 0, 2);
            world.setBlock(chunkX + 8, y + 1, chunkZ + 9, Blocks.air, 0, 2);
            world.setBlock(chunkX + 9, y + 1, chunkZ + 9, Blocks.air, 0, 2);
            world.setBlock(chunkX + 10, y + 1, chunkZ + 9, Blocks.air, 0, 2);
            world.setBlock(chunkX + 11, y + 1, chunkZ + 9, Blocks.air, 0, 2);
            world.setBlock(chunkX + 12, y + 1, chunkZ + 9, Blocks.air, 0, 2);
            world.setBlock(chunkX + 13, y + 1, chunkZ + 9, Blocks.air, 0, 2);
            world.setBlock(chunkX + 14, y + 1, chunkZ + 9, Blocks.air, 0, 2);
            world.setBlock(chunkX + 15, y + 1, chunkZ + 9, Blocks.stone, 0, 2);
            world.setBlock(chunkX + 16, y + 1, chunkZ + 9, Main.sepiaBrick, 0, 2);
            world.setBlock(chunkX + 0, y + 1, chunkZ + 10, Main.sepiaBrick, 0, 2);
            world.setBlock(chunkX + 1, y + 1, chunkZ + 10, Blocks.stone, 0, 2);
            world.setBlock(chunkX + 2, y + 1, chunkZ + 10, Blocks.air, 0, 2);
            world.setBlock(chunkX + 3, y + 1, chunkZ + 10, Blocks.air, 0, 2);
            world.setBlock(chunkX + 4, y + 1, chunkZ + 10, Blocks.air, 0, 2);
            world.setBlock(chunkX + 5, y + 1, chunkZ + 10, Blocks.air, 0, 2);
            world.setBlock(chunkX + 6, y + 1, chunkZ + 10, Blocks.air, 0, 2);
            world.setBlock(chunkX + 7, y + 1, chunkZ + 10, Blocks.air, 0, 2);
            world.setBlock(chunkX + 8, y + 1, chunkZ + 10, Blocks.air, 0, 2);
            world.setBlock(chunkX + 9, y + 1, chunkZ + 10, Blocks.air, 0, 2);
            world.setBlock(chunkX + 10, y + 1, chunkZ + 10, Blocks.air, 0, 2);
            world.setBlock(chunkX + 11, y + 1, chunkZ + 10, Blocks.air, 0, 2);
            world.setBlock(chunkX + 12, y + 1, chunkZ + 10, Blocks.air, 0, 2);
            world.setBlock(chunkX + 13, y + 1, chunkZ + 10, Blocks.air, 0, 2);
            world.setBlock(chunkX + 14, y + 1, chunkZ + 10, Blocks.air, 0, 2);
            world.setBlock(chunkX + 15, y + 1, chunkZ + 10, Blocks.stone, 0, 2);
            world.setBlock(chunkX + 16, y + 1, chunkZ + 10, Main.sepiaBrick, 0, 2);
            world.setBlock(chunkX + 0, y + 1, chunkZ + 11, Main.sepiaBrick, 0, 2);
            world.setBlock(chunkX + 1, y + 1, chunkZ + 11, Blocks.stone, 0, 2);
            world.setBlock(chunkX + 2, y + 1, chunkZ + 11, Main.bluePot, 0, 2);
            world.setBlock(chunkX + 3, y + 1, chunkZ + 11, Blocks.air, 0, 2);
            world.setBlock(chunkX + 4, y + 1, chunkZ + 11, Blocks.air, 0, 2);
            world.setBlock(chunkX + 5, y + 1, chunkZ + 11, Blocks.air, 0, 2);
            world.setBlock(chunkX + 6, y + 1, chunkZ + 11, Blocks.air, 0, 2);
            world.setBlock(chunkX + 7, y + 1, chunkZ + 11, Blocks.air, 0, 2);
            world.setBlock(chunkX + 8, y + 1, chunkZ + 11, Blocks.air, 0, 2);
            world.setBlock(chunkX + 9, y + 1, chunkZ + 11, Blocks.air, 0, 2);
            world.setBlock(chunkX + 10, y + 1, chunkZ + 11, Blocks.air, 0, 2);
            world.setBlock(chunkX + 11, y + 1, chunkZ + 11, Blocks.air, 0, 2);
            world.setBlock(chunkX + 12, y + 1, chunkZ + 11, Blocks.air, 0, 2);
            world.setBlock(chunkX + 13, y + 1, chunkZ + 11, Blocks.air, 0, 2);
            world.setBlock(chunkX + 14, y + 1, chunkZ + 11, Main.bluePot, 0, 2);
            world.setBlock(chunkX + 15, y + 1, chunkZ + 11, Blocks.stone, 0, 2);
            world.setBlock(chunkX + 16, y + 1, chunkZ + 11, Main.sepiaBrick, 0, 2);
            world.setBlock(chunkX + 0, y + 1, chunkZ + 12, Blocks.air, 0, 2);
            world.setBlock(chunkX + 1, y + 1, chunkZ + 12, Main.sepiaBrick, 0, 2);
            world.setBlock(chunkX + 2, y + 1, chunkZ + 12, Blocks.stone, 0, 2);
            world.setBlock(chunkX + 3, y + 1, chunkZ + 12, Main.bluePot, 0, 2);
            world.setBlock(chunkX + 4, y + 1, chunkZ + 12, Blocks.air, 0, 2);
            world.setBlock(chunkX + 5, y + 1, chunkZ + 12, Blocks.air, 0, 2);
            world.setBlock(chunkX + 6, y + 1, chunkZ + 12, Blocks.air, 0, 2);
            world.setBlock(chunkX + 7, y + 1, chunkZ + 12, Blocks.air, 0, 2);
            world.setBlock(chunkX + 8, y + 1, chunkZ + 12, Blocks.air, 0, 2);
            world.setBlock(chunkX + 9, y + 1, chunkZ + 12, Blocks.air, 0, 2);
            world.setBlock(chunkX + 10, y + 1, chunkZ + 12, Blocks.air, 0, 2);
            world.setBlock(chunkX + 11, y + 1, chunkZ + 12, Blocks.air, 0, 2);
            world.setBlock(chunkX + 12, y + 1, chunkZ + 12, Blocks.air, 0, 2);
            world.setBlock(chunkX + 13, y + 1, chunkZ + 12, Main.bluePot, 0, 2);
            world.setBlock(chunkX + 14, y + 1, chunkZ + 12, Blocks.stone, 0, 2);
            world.setBlock(chunkX + 15, y + 1, chunkZ + 12, Main.sepiaBrick, 0, 2);
            world.setBlock(chunkX + 16, y + 1, chunkZ + 12, Blocks.air, 0, 2);
            world.setBlock(chunkX + 0, y + 1, chunkZ + 13, Blocks.air, 0, 2);
            world.setBlock(chunkX + 1, y + 1, chunkZ + 13, Blocks.air, 0, 2);
            world.setBlock(chunkX + 2, y + 1, chunkZ + 13, Main.sepiaBrick, 0, 2);
            world.setBlock(chunkX + 3, y + 1, chunkZ + 13, Blocks.stone, 0, 2);
            world.setBlock(chunkX + 4, y + 1, chunkZ + 13, Blocks.stone, 0, 2);
            world.setBlock(chunkX + 5, y + 1, chunkZ + 13, Blocks.stone, 0, 2);
            world.setBlock(chunkX + 6, y + 1, chunkZ + 13, Main.fairyTowerChiseled, 0, 2);
            world.setBlock(chunkX + 7, y + 1, chunkZ + 13, Blocks.air, 0, 2);
            world.setBlock(chunkX + 8, y + 1, chunkZ + 13, Blocks.air, 0, 2);
            world.setBlock(chunkX + 9, y + 1, chunkZ + 13, Blocks.air, 0, 2);
            world.setBlock(chunkX + 10, y + 1, chunkZ + 13, Main.fairyTowerChiseled, 0, 2);
            world.setBlock(chunkX + 11, y + 1, chunkZ + 13, Blocks.stone, 0, 2);
            world.setBlock(chunkX + 12, y + 1, chunkZ + 13, Blocks.stone, 0, 2);
            world.setBlock(chunkX + 13, y + 1, chunkZ + 13, Blocks.stone, 0, 2);
            world.setBlock(chunkX + 14, y + 1, chunkZ + 13, Main.sepiaBrick, 0, 2);
            world.setBlock(chunkX + 15, y + 1, chunkZ + 13, Blocks.air, 0, 2);
            world.setBlock(chunkX + 16, y + 1, chunkZ + 13, Blocks.air, 0, 2);
            world.setBlock(chunkX + 0, y + 1, chunkZ + 14, Blocks.air, 0, 2);
            world.setBlock(chunkX + 1, y + 1, chunkZ + 14, Blocks.air, 0, 2);
            world.setBlock(chunkX + 2, y + 1, chunkZ + 14, Blocks.air, 0, 2);
            world.setBlock(chunkX + 3, y + 1, chunkZ + 14, Main.sepiaBrick, 0, 2);
            world.setBlock(chunkX + 4, y + 1, chunkZ + 14, Main.sepiaBrick, 0, 2);
            world.setBlock(chunkX + 5, y + 1, chunkZ + 14, Main.sepiaBrick, 0, 2);
            world.setBlock(chunkX + 6, y + 1, chunkZ + 14, Main.fairyTowerChiseled, 0, 2);
            world.setBlock(chunkX + 7, y + 1, chunkZ + 14, Blocks.air, 0, 2);
            world.setBlock(chunkX + 8, y + 1, chunkZ + 14, Blocks.air, 0, 2);
            world.setBlock(chunkX + 9, y + 1, chunkZ + 14, Blocks.air, 0, 2);
            world.setBlock(chunkX + 10, y + 1, chunkZ + 14, Main.fairyTowerChiseled, 0, 2);
            world.setBlock(chunkX + 11, y + 1, chunkZ + 14, Main.sepiaBrick, 0, 2);
            world.setBlock(chunkX + 12, y + 1, chunkZ + 14, Main.sepiaBrick, 0, 2);
            world.setBlock(chunkX + 13, y + 1, chunkZ + 14, Main.sepiaBrick, 0, 2);
            world.setBlock(chunkX + 14, y + 1, chunkZ + 14, Blocks.air, 0, 2);
            world.setBlock(chunkX + 15, y + 1, chunkZ + 14, Blocks.air, 0, 2);
            world.setBlock(chunkX + 16, y + 1, chunkZ + 14, Blocks.air, 0, 2);
            world.setBlock(chunkX + 0, y + 2, chunkZ + 0, Blocks.air, 0, 2);
            world.setBlock(chunkX + 1, y + 2, chunkZ + 0, Blocks.air, 0, 2);
            world.setBlock(chunkX + 2, y + 2, chunkZ + 0, Blocks.air, 0, 2);
            world.setBlock(chunkX + 3, y + 2, chunkZ + 0, Blocks.air, 0, 2);
            world.setBlock(chunkX + 4, y + 2, chunkZ + 0, Blocks.air, 0, 2);
            world.setBlock(chunkX + 5, y + 2, chunkZ + 0, Blocks.air, 0, 2);
            world.setBlock(chunkX + 6, y + 2, chunkZ + 0, Blocks.air, 0, 2);
            world.setBlock(chunkX + 7, y + 2, chunkZ + 0, Main.sepiaBrick, 0, 2);
            world.setBlock(chunkX + 8, y + 2, chunkZ + 0, Main.sepiaBrick, 0, 2);
            world.setBlock(chunkX + 9, y + 2, chunkZ + 0, Main.sepiaBrick, 0, 2);
            world.setBlock(chunkX + 10, y + 2, chunkZ + 0, Blocks.air, 0, 2);
            world.setBlock(chunkX + 11, y + 2, chunkZ + 0, Blocks.air, 0, 2);
            world.setBlock(chunkX + 12, y + 2, chunkZ + 0, Blocks.air, 0, 2);
            world.setBlock(chunkX + 13, y + 2, chunkZ + 0, Blocks.air, 0, 2);
            world.setBlock(chunkX + 14, y + 2, chunkZ + 0, Blocks.air, 0, 2);
            world.setBlock(chunkX + 15, y + 2, chunkZ + 0, Blocks.air, 0, 2);
            world.setBlock(chunkX + 16, y + 2, chunkZ + 0, Blocks.air, 0, 2);
            world.setBlock(chunkX + 0, y + 2, chunkZ + 1, Blocks.air, 0, 2);
            world.setBlock(chunkX + 1, y + 2, chunkZ + 1, Blocks.air, 0, 2);
            world.setBlock(chunkX + 2, y + 2, chunkZ + 1, Blocks.air, 0, 2);
            world.setBlock(chunkX + 3, y + 2, chunkZ + 1, Blocks.air, 0, 2);
            world.setBlock(chunkX + 4, y + 2, chunkZ + 1, Blocks.air, 0, 2);
            world.setBlock(chunkX + 5, y + 2, chunkZ + 1, Main.sepiaBrick, 0, 2);
            world.setBlock(chunkX + 6, y + 2, chunkZ + 1, Main.sepiaBrick, 0, 2);
            world.setBlock(chunkX + 7, y + 2, chunkZ + 1, Main.sepiaBlock, 0, 2);
            world.setBlock(chunkX + 8, y + 2, chunkZ + 1, Main.sepiaBlock, 0, 2);
            world.setBlock(chunkX + 9, y + 2, chunkZ + 1, Main.sepiaBlock, 0, 2);
            world.setBlock(chunkX + 10, y + 2, chunkZ + 1, Main.sepiaBrick, 0, 2);
            world.setBlock(chunkX + 11, y + 2, chunkZ + 1, Main.sepiaBrick, 0, 2);
            world.setBlock(chunkX + 12, y + 2, chunkZ + 1, Blocks.air, 0, 2);
            world.setBlock(chunkX + 13, y + 2, chunkZ + 1, Blocks.air, 0, 2);
            world.setBlock(chunkX + 14, y + 2, chunkZ + 1, Blocks.air, 0, 2);
            world.setBlock(chunkX + 15, y + 2, chunkZ + 1, Blocks.air, 0, 2);
            world.setBlock(chunkX + 16, y + 2, chunkZ + 1, Blocks.air, 0, 2);
            world.setBlock(chunkX + 0, y + 2, chunkZ + 2, Blocks.air, 0, 2);
            world.setBlock(chunkX + 1, y + 2, chunkZ + 2, Blocks.air, 0, 2);
            world.setBlock(chunkX + 2, y + 2, chunkZ + 2, Blocks.air, 0, 2);
            world.setBlock(chunkX + 3, y + 2, chunkZ + 2, Blocks.air, 0, 2);
            world.setBlock(chunkX + 4, y + 2, chunkZ + 2, Main.sepiaBrick, 0, 2);
            world.setBlock(chunkX + 5, y + 2, chunkZ + 2, Blocks.stone, 0, 2);
            world.setBlock(chunkX + 6, y + 2, chunkZ + 2, Main.sepiaBlock, 0, 2);
            world.setBlock(chunkX + 7, y + 2, chunkZ + 2, Blocks.air, 0, 2);
            world.setBlock(chunkX + 8, y + 2, chunkZ + 2, (Block)Blocks.chest, 3, 2);
            final int xx = chunkX + 8;
            final int yy = y + 2;
            final int zz = chunkZ + 2;
            final TileEntityChest tileentitychest = (TileEntityChest)world.getTileEntity(xx, yy, zz);
            if (tileentitychest != null) {
                WeightedRandomChestContent.generateChestContents(random, ChestGenHooks.getItems("dungeonChest", random), (IInventory)tileentitychest, ChestGenHooks.getCount("dungeonChest", random));
            }
            world.setBlock(chunkX + 9, y + 2, chunkZ + 2, Blocks.air, 0, 2);
            world.setBlock(chunkX + 10, y + 2, chunkZ + 2, Main.sepiaBlock, 0, 2);
            world.setBlock(chunkX + 11, y + 2, chunkZ + 2, Blocks.stone, 0, 2);
            world.setBlock(chunkX + 12, y + 2, chunkZ + 2, Main.sepiaBrick, 0, 2);
            world.setBlock(chunkX + 13, y + 2, chunkZ + 2, Blocks.air, 0, 2);
            world.setBlock(chunkX + 14, y + 2, chunkZ + 2, Blocks.air, 0, 2);
            world.setBlock(chunkX + 15, y + 2, chunkZ + 2, Blocks.air, 0, 2);
            world.setBlock(chunkX + 16, y + 2, chunkZ + 2, Blocks.air, 0, 2);
            world.setBlock(chunkX + 0, y + 2, chunkZ + 3, Blocks.air, 0, 2);
            world.setBlock(chunkX + 1, y + 2, chunkZ + 3, Blocks.air, 0, 2);
            world.setBlock(chunkX + 2, y + 2, chunkZ + 3, Blocks.air, 0, 2);
            world.setBlock(chunkX + 3, y + 2, chunkZ + 3, Main.sepiaBrick, 0, 2);
            world.setBlock(chunkX + 4, y + 2, chunkZ + 3, Blocks.stone, 0, 2);
            world.setBlock(chunkX + 5, y + 2, chunkZ + 3, Blocks.air, 0, 2);
            world.setBlock(chunkX + 6, y + 2, chunkZ + 3, Main.fairyTowerChiseled, 0, 2);
            world.setBlock(chunkX + 7, y + 2, chunkZ + 3, Blocks.air, 0, 2);
            world.setBlock(chunkX + 8, y + 2, chunkZ + 3, Blocks.air, 0, 2);
            world.setBlock(chunkX + 9, y + 2, chunkZ + 3, Blocks.air, 0, 2);
            world.setBlock(chunkX + 10, y + 2, chunkZ + 3, Main.fairyTowerChiseled, 0, 2);
            world.setBlock(chunkX + 11, y + 2, chunkZ + 3, Blocks.air, 0, 2);
            world.setBlock(chunkX + 12, y + 2, chunkZ + 3, Blocks.stone, 0, 2);
            world.setBlock(chunkX + 13, y + 2, chunkZ + 3, Main.sepiaBrick, 0, 2);
            world.setBlock(chunkX + 14, y + 2, chunkZ + 3, Blocks.air, 0, 2);
            world.setBlock(chunkX + 15, y + 2, chunkZ + 3, Blocks.air, 0, 2);
            world.setBlock(chunkX + 16, y + 2, chunkZ + 3, Blocks.air, 0, 2);
            world.setBlock(chunkX + 0, y + 2, chunkZ + 4, Blocks.air, 0, 2);
            world.setBlock(chunkX + 1, y + 2, chunkZ + 4, Blocks.air, 0, 2);
            world.setBlock(chunkX + 2, y + 2, chunkZ + 4, Main.sepiaBrick, 0, 2);
            world.setBlock(chunkX + 3, y + 2, chunkZ + 4, Blocks.stone, 0, 2);
            world.setBlock(chunkX + 4, y + 2, chunkZ + 4, Blocks.air, 0, 2);
            world.setBlock(chunkX + 5, y + 2, chunkZ + 4, Blocks.air, 0, 2);
            world.setBlock(chunkX + 6, y + 2, chunkZ + 4, Blocks.air, 0, 2);
            world.setBlock(chunkX + 7, y + 2, chunkZ + 4, Blocks.air, 0, 2);
            world.setBlock(chunkX + 8, y + 2, chunkZ + 4, Blocks.air, 0, 2);
            world.setBlock(chunkX + 9, y + 2, chunkZ + 4, Blocks.air, 0, 2);
            world.setBlock(chunkX + 10, y + 2, chunkZ + 4, Blocks.air, 0, 2);
            world.setBlock(chunkX + 11, y + 2, chunkZ + 4, Blocks.air, 0, 2);
            world.setBlock(chunkX + 12, y + 2, chunkZ + 4, Blocks.air, 0, 2);
            world.setBlock(chunkX + 13, y + 2, chunkZ + 4, Blocks.stone, 0, 2);
            world.setBlock(chunkX + 14, y + 2, chunkZ + 4, Main.sepiaBrick, 0, 2);
            world.setBlock(chunkX + 15, y + 2, chunkZ + 4, Blocks.air, 0, 2);
            world.setBlock(chunkX + 16, y + 2, chunkZ + 4, Blocks.air, 0, 2);
            world.setBlock(chunkX + 0, y + 2, chunkZ + 5, Blocks.air, 0, 2);
            world.setBlock(chunkX + 1, y + 2, chunkZ + 5, Main.sepiaBrick, 0, 2);
            world.setBlock(chunkX + 2, y + 2, chunkZ + 5, Blocks.stone, 0, 2);
            world.setBlock(chunkX + 3, y + 2, chunkZ + 5, Blocks.air, 0, 2);
            world.setBlock(chunkX + 4, y + 2, chunkZ + 5, Blocks.air, 0, 2);
            world.setBlock(chunkX + 5, y + 2, chunkZ + 5, Blocks.air, 0, 2);
            world.setBlock(chunkX + 6, y + 2, chunkZ + 5, Blocks.air, 0, 2);
            world.setBlock(chunkX + 7, y + 2, chunkZ + 5, Blocks.air, 0, 2);
            world.setBlock(chunkX + 8, y + 2, chunkZ + 5, Blocks.air, 0, 2);
            world.setBlock(chunkX + 9, y + 2, chunkZ + 5, Blocks.air, 0, 2);
            world.setBlock(chunkX + 10, y + 2, chunkZ + 5, Blocks.air, 0, 2);
            world.setBlock(chunkX + 11, y + 2, chunkZ + 5, Blocks.air, 0, 2);
            world.setBlock(chunkX + 12, y + 2, chunkZ + 5, Blocks.air, 0, 2);
            world.setBlock(chunkX + 13, y + 2, chunkZ + 5, Blocks.air, 0, 2);
            world.setBlock(chunkX + 14, y + 2, chunkZ + 5, Blocks.stone, 0, 2);
            world.setBlock(chunkX + 15, y + 2, chunkZ + 5, Main.sepiaBrick, 0, 2);
            world.setBlock(chunkX + 16, y + 2, chunkZ + 5, Blocks.air, 0, 2);
            world.setBlock(chunkX + 0, y + 2, chunkZ + 6, Main.sepiaBrick, 0, 2);
            world.setBlock(chunkX + 1, y + 2, chunkZ + 6, Blocks.stone, 0, 2);
            world.setBlock(chunkX + 2, y + 2, chunkZ + 6, Blocks.air, 0, 2);
            world.setBlock(chunkX + 3, y + 2, chunkZ + 6, Blocks.air, 0, 2);
            world.setBlock(chunkX + 4, y + 2, chunkZ + 6, Blocks.air, 0, 2);
            world.setBlock(chunkX + 5, y + 2, chunkZ + 6, Blocks.air, 0, 2);
            world.setBlock(chunkX + 6, y + 2, chunkZ + 6, Blocks.air, 0, 2);
            world.setBlock(chunkX + 7, y + 2, chunkZ + 6, Blocks.air, 0, 2);
            world.setBlock(chunkX + 8, y + 2, chunkZ + 6, Blocks.air, 0, 2);
            world.setBlock(chunkX + 9, y + 2, chunkZ + 6, Blocks.air, 0, 2);
            world.setBlock(chunkX + 10, y + 2, chunkZ + 6, Blocks.air, 0, 2);
            world.setBlock(chunkX + 11, y + 2, chunkZ + 6, Blocks.air, 0, 2);
            world.setBlock(chunkX + 12, y + 2, chunkZ + 6, Blocks.air, 0, 2);
            world.setBlock(chunkX + 13, y + 2, chunkZ + 6, Blocks.air, 0, 2);
            world.setBlock(chunkX + 14, y + 2, chunkZ + 6, Blocks.air, 0, 2);
            world.setBlock(chunkX + 15, y + 2, chunkZ + 6, Blocks.stone, 0, 2);
            world.setBlock(chunkX + 16, y + 2, chunkZ + 6, Main.sepiaBrick, 0, 2);
            world.setBlock(chunkX + 0, y + 2, chunkZ + 7, Main.sepiaBrick, 0, 2);
            world.setBlock(chunkX + 1, y + 2, chunkZ + 7, Blocks.stone, 0, 2);
            world.setBlock(chunkX + 2, y + 2, chunkZ + 7, Blocks.air, 0, 2);
            world.setBlock(chunkX + 3, y + 2, chunkZ + 7, Blocks.air, 0, 2);
            world.setBlock(chunkX + 4, y + 2, chunkZ + 7, Blocks.air, 0, 2);
            world.setBlock(chunkX + 5, y + 2, chunkZ + 7, Blocks.air, 0, 2);
            world.setBlock(chunkX + 6, y + 2, chunkZ + 7, Blocks.air, 0, 2);
            world.setBlock(chunkX + 7, y + 2, chunkZ + 7, Blocks.air, 0, 2);
            world.setBlock(chunkX + 8, y + 2, chunkZ + 7, Blocks.air, 0, 2);
            world.setBlock(chunkX + 9, y + 2, chunkZ + 7, Blocks.air, 0, 2);
            world.setBlock(chunkX + 10, y + 2, chunkZ + 7, Blocks.air, 0, 2);
            world.setBlock(chunkX + 11, y + 2, chunkZ + 7, Blocks.air, 0, 2);
            world.setBlock(chunkX + 12, y + 2, chunkZ + 7, Blocks.air, 0, 2);
            world.setBlock(chunkX + 13, y + 2, chunkZ + 7, Blocks.air, 0, 2);
            world.setBlock(chunkX + 14, y + 2, chunkZ + 7, Blocks.air, 0, 2);
            world.setBlock(chunkX + 15, y + 2, chunkZ + 7, Blocks.stone, 0, 2);
            world.setBlock(chunkX + 16, y + 2, chunkZ + 7, Main.sepiaBrick, 0, 2);
            world.setBlock(chunkX + 0, y + 2, chunkZ + 8, Main.sepiaBrick, 0, 2);
            world.setBlock(chunkX + 1, y + 2, chunkZ + 8, Blocks.stone, 0, 2);
            world.setBlock(chunkX + 2, y + 2, chunkZ + 8, Blocks.air, 0, 2);
            world.setBlock(chunkX + 3, y + 2, chunkZ + 8, Blocks.air, 0, 2);
            world.setBlock(chunkX + 4, y + 2, chunkZ + 8, Blocks.air, 0, 2);
            world.setBlock(chunkX + 5, y + 2, chunkZ + 8, Blocks.air, 0, 2);
            world.setBlock(chunkX + 6, y + 2, chunkZ + 8, Blocks.air, 0, 2);
            world.setBlock(chunkX + 7, y + 2, chunkZ + 8, Blocks.air, 0, 2);
            world.setBlock(chunkX + 8, y + 2, chunkZ + 8, Blocks.air, 0, 2);
            world.setBlock(chunkX + 9, y + 2, chunkZ + 8, Blocks.air, 0, 2);
            world.setBlock(chunkX + 10, y + 2, chunkZ + 8, Blocks.air, 0, 2);
            world.setBlock(chunkX + 11, y + 2, chunkZ + 8, Blocks.air, 0, 2);
            world.setBlock(chunkX + 12, y + 2, chunkZ + 8, Blocks.air, 0, 2);
            world.setBlock(chunkX + 13, y + 2, chunkZ + 8, Blocks.air, 0, 2);
            world.setBlock(chunkX + 14, y + 2, chunkZ + 8, Blocks.air, 0, 2);
            world.setBlock(chunkX + 15, y + 2, chunkZ + 8, Blocks.stone, 0, 2);
            world.setBlock(chunkX + 16, y + 2, chunkZ + 8, Main.sepiaBrick, 0, 2);
            world.setBlock(chunkX + 0, y + 2, chunkZ + 9, Main.sepiaBrick, 0, 2);
            world.setBlock(chunkX + 1, y + 2, chunkZ + 9, Blocks.stone, 0, 2);
            world.setBlock(chunkX + 2, y + 2, chunkZ + 9, Blocks.air, 0, 2);
            world.setBlock(chunkX + 3, y + 2, chunkZ + 9, Blocks.air, 0, 2);
            world.setBlock(chunkX + 4, y + 2, chunkZ + 9, Blocks.air, 0, 2);
            world.setBlock(chunkX + 5, y + 2, chunkZ + 9, Blocks.air, 0, 2);
            world.setBlock(chunkX + 6, y + 2, chunkZ + 9, Blocks.air, 0, 2);
            world.setBlock(chunkX + 7, y + 2, chunkZ + 9, Blocks.air, 0, 2);
            world.setBlock(chunkX + 8, y + 2, chunkZ + 9, Blocks.air, 0, 2);
            world.setBlock(chunkX + 9, y + 2, chunkZ + 9, Blocks.air, 0, 2);
            world.setBlock(chunkX + 10, y + 2, chunkZ + 9, Blocks.air, 0, 2);
            world.setBlock(chunkX + 11, y + 2, chunkZ + 9, Blocks.air, 0, 2);
            world.setBlock(chunkX + 12, y + 2, chunkZ + 9, Blocks.air, 0, 2);
            world.setBlock(chunkX + 13, y + 2, chunkZ + 9, Blocks.air, 0, 2);
            world.setBlock(chunkX + 14, y + 2, chunkZ + 9, Blocks.air, 0, 2);
            world.setBlock(chunkX + 15, y + 2, chunkZ + 9, Blocks.stone, 0, 2);
            world.setBlock(chunkX + 16, y + 2, chunkZ + 9, Main.sepiaBrick, 0, 2);
            world.setBlock(chunkX + 0, y + 2, chunkZ + 10, Main.sepiaBrick, 0, 2);
            world.setBlock(chunkX + 1, y + 2, chunkZ + 10, Blocks.stone, 0, 2);
            world.setBlock(chunkX + 2, y + 2, chunkZ + 10, Blocks.air, 0, 2);
            world.setBlock(chunkX + 3, y + 2, chunkZ + 10, Blocks.air, 0, 2);
            world.setBlock(chunkX + 4, y + 2, chunkZ + 10, Blocks.air, 0, 2);
            world.setBlock(chunkX + 5, y + 2, chunkZ + 10, Blocks.air, 0, 2);
            world.setBlock(chunkX + 6, y + 2, chunkZ + 10, Blocks.air, 0, 2);
            world.setBlock(chunkX + 7, y + 2, chunkZ + 10, Blocks.air, 0, 2);
            world.setBlock(chunkX + 8, y + 2, chunkZ + 10, Blocks.air, 0, 2);
            world.setBlock(chunkX + 9, y + 2, chunkZ + 10, Blocks.air, 0, 2);
            world.setBlock(chunkX + 10, y + 2, chunkZ + 10, Blocks.air, 0, 2);
            world.setBlock(chunkX + 11, y + 2, chunkZ + 10, Blocks.air, 0, 2);
            world.setBlock(chunkX + 12, y + 2, chunkZ + 10, Blocks.air, 0, 2);
            world.setBlock(chunkX + 13, y + 2, chunkZ + 10, Blocks.air, 0, 2);
            world.setBlock(chunkX + 14, y + 2, chunkZ + 10, Blocks.air, 0, 2);
            world.setBlock(chunkX + 15, y + 2, chunkZ + 10, Blocks.stone, 0, 2);
            world.setBlock(chunkX + 16, y + 2, chunkZ + 10, Main.sepiaBrick, 0, 2);
            world.setBlock(chunkX + 0, y + 2, chunkZ + 11, Main.sepiaBrick, 0, 2);
            world.setBlock(chunkX + 1, y + 2, chunkZ + 11, Blocks.stone, 0, 2);
            world.setBlock(chunkX + 2, y + 2, chunkZ + 11, Blocks.air, 0, 2);
            world.setBlock(chunkX + 3, y + 2, chunkZ + 11, Blocks.air, 0, 2);
            world.setBlock(chunkX + 4, y + 2, chunkZ + 11, Blocks.air, 0, 2);
            world.setBlock(chunkX + 5, y + 2, chunkZ + 11, Blocks.air, 0, 2);
            world.setBlock(chunkX + 6, y + 2, chunkZ + 11, Blocks.air, 0, 2);
            world.setBlock(chunkX + 7, y + 2, chunkZ + 11, Blocks.air, 0, 2);
            world.setBlock(chunkX + 8, y + 2, chunkZ + 11, Blocks.air, 0, 2);
            world.setBlock(chunkX + 9, y + 2, chunkZ + 11, Blocks.air, 0, 2);
            world.setBlock(chunkX + 10, y + 2, chunkZ + 11, Blocks.air, 0, 2);
            world.setBlock(chunkX + 11, y + 2, chunkZ + 11, Blocks.air, 0, 2);
            world.setBlock(chunkX + 12, y + 2, chunkZ + 11, Blocks.air, 0, 2);
            world.setBlock(chunkX + 13, y + 2, chunkZ + 11, Blocks.air, 0, 2);
            world.setBlock(chunkX + 14, y + 2, chunkZ + 11, Blocks.air, 0, 2);
            world.setBlock(chunkX + 15, y + 2, chunkZ + 11, Blocks.stone, 0, 2);
            world.setBlock(chunkX + 16, y + 2, chunkZ + 11, Main.sepiaBrick, 0, 2);
            world.setBlock(chunkX + 0, y + 2, chunkZ + 12, Blocks.air, 0, 2);
            world.setBlock(chunkX + 1, y + 2, chunkZ + 12, Main.sepiaBrick, 0, 2);
            world.setBlock(chunkX + 2, y + 2, chunkZ + 12, Blocks.stone, 0, 2);
            world.setBlock(chunkX + 3, y + 2, chunkZ + 12, Blocks.air, 0, 2);
            world.setBlock(chunkX + 4, y + 2, chunkZ + 12, Blocks.air, 0, 2);
            world.setBlock(chunkX + 5, y + 2, chunkZ + 12, Blocks.air, 0, 2);
            world.setBlock(chunkX + 6, y + 2, chunkZ + 12, Blocks.air, 0, 2);
            world.setBlock(chunkX + 7, y + 2, chunkZ + 12, Blocks.air, 0, 2);
            world.setBlock(chunkX + 8, y + 2, chunkZ + 12, Blocks.air, 0, 2);
            world.setBlock(chunkX + 9, y + 2, chunkZ + 12, Blocks.air, 0, 2);
            world.setBlock(chunkX + 10, y + 2, chunkZ + 12, Blocks.air, 0, 2);
            world.setBlock(chunkX + 11, y + 2, chunkZ + 12, Blocks.air, 0, 2);
            world.setBlock(chunkX + 12, y + 2, chunkZ + 12, Blocks.air, 0, 2);
            world.setBlock(chunkX + 13, y + 2, chunkZ + 12, Blocks.air, 0, 2);
            world.setBlock(chunkX + 14, y + 2, chunkZ + 12, Blocks.stone, 0, 2);
            world.setBlock(chunkX + 15, y + 2, chunkZ + 12, Main.sepiaBrick, 0, 2);
            world.setBlock(chunkX + 16, y + 2, chunkZ + 12, Blocks.air, 0, 2);
            world.setBlock(chunkX + 0, y + 2, chunkZ + 13, Blocks.air, 0, 2);
            world.setBlock(chunkX + 1, y + 2, chunkZ + 13, Blocks.air, 0, 2);
            world.setBlock(chunkX + 2, y + 2, chunkZ + 13, Main.sepiaBrick, 0, 2);
            world.setBlock(chunkX + 3, y + 2, chunkZ + 13, Blocks.stone, 0, 2);
            world.setBlock(chunkX + 4, y + 2, chunkZ + 13, Blocks.stone, 0, 2);
            world.setBlock(chunkX + 5, y + 2, chunkZ + 13, Blocks.stone, 0, 2);
            world.setBlock(chunkX + 6, y + 2, chunkZ + 13, Main.fairyTowerChiseled, 0, 2);
            world.setBlock(chunkX + 7, y + 2, chunkZ + 13, Blocks.air, 0, 2);
            world.setBlock(chunkX + 8, y + 2, chunkZ + 13, Blocks.air, 0, 2);
            world.setBlock(chunkX + 9, y + 2, chunkZ + 13, Blocks.air, 0, 2);
            world.setBlock(chunkX + 10, y + 2, chunkZ + 13, Main.fairyTowerChiseled, 0, 2);
            world.setBlock(chunkX + 11, y + 2, chunkZ + 13, Blocks.stone, 0, 2);
            world.setBlock(chunkX + 12, y + 2, chunkZ + 13, Blocks.stone, 0, 2);
            world.setBlock(chunkX + 13, y + 2, chunkZ + 13, Blocks.stone, 0, 2);
            world.setBlock(chunkX + 14, y + 2, chunkZ + 13, Main.sepiaBrick, 0, 2);
            world.setBlock(chunkX + 15, y + 2, chunkZ + 13, Blocks.air, 0, 2);
            world.setBlock(chunkX + 16, y + 2, chunkZ + 13, Blocks.air, 0, 2);
            world.setBlock(chunkX + 0, y + 2, chunkZ + 14, Blocks.air, 0, 2);
            world.setBlock(chunkX + 1, y + 2, chunkZ + 14, Blocks.air, 0, 2);
            world.setBlock(chunkX + 2, y + 2, chunkZ + 14, Blocks.air, 0, 2);
            world.setBlock(chunkX + 3, y + 2, chunkZ + 14, Main.sepiaBrick, 0, 2);
            world.setBlock(chunkX + 4, y + 2, chunkZ + 14, Main.sepiaBrick, 0, 2);
            world.setBlock(chunkX + 5, y + 2, chunkZ + 14, Main.sepiaBrick, 0, 2);
            world.setBlock(chunkX + 6, y + 2, chunkZ + 14, Main.fairyTowerChiseled, 0, 2);
            world.setBlock(chunkX + 7, y + 2, chunkZ + 14, Blocks.air, 0, 2);
            world.setBlock(chunkX + 8, y + 2, chunkZ + 14, Blocks.air, 0, 2);
            world.setBlock(chunkX + 9, y + 2, chunkZ + 14, Blocks.air, 0, 2);
            world.setBlock(chunkX + 10, y + 2, chunkZ + 14, Main.fairyTowerChiseled, 0, 2);
            world.setBlock(chunkX + 11, y + 2, chunkZ + 14, Main.sepiaBrick, 0, 2);
            world.setBlock(chunkX + 12, y + 2, chunkZ + 14, Main.sepiaBrick, 0, 2);
            world.setBlock(chunkX + 13, y + 2, chunkZ + 14, Main.sepiaBrick, 0, 2);
            world.setBlock(chunkX + 14, y + 2, chunkZ + 14, Blocks.air, 0, 2);
            world.setBlock(chunkX + 15, y + 2, chunkZ + 14, Blocks.air, 0, 2);
            world.setBlock(chunkX + 16, y + 2, chunkZ + 14, Blocks.air, 0, 2);
            world.setBlock(chunkX + 0, y + 3, chunkZ + 0, Blocks.air, 0, 2);
            world.setBlock(chunkX + 1, y + 3, chunkZ + 0, Blocks.air, 0, 2);
            world.setBlock(chunkX + 2, y + 3, chunkZ + 0, Blocks.air, 0, 2);
            world.setBlock(chunkX + 3, y + 3, chunkZ + 0, Blocks.air, 0, 2);
            world.setBlock(chunkX + 4, y + 3, chunkZ + 0, Blocks.air, 0, 2);
            world.setBlock(chunkX + 5, y + 3, chunkZ + 0, Blocks.air, 0, 2);
            world.setBlock(chunkX + 6, y + 3, chunkZ + 0, Blocks.air, 0, 2);
            world.setBlock(chunkX + 7, y + 3, chunkZ + 0, Main.sepiaBrick, 0, 2);
            world.setBlock(chunkX + 8, y + 3, chunkZ + 0, Main.sepiaBrick, 0, 2);
            world.setBlock(chunkX + 9, y + 3, chunkZ + 0, Main.sepiaBrick, 0, 2);
            world.setBlock(chunkX + 10, y + 3, chunkZ + 0, Blocks.air, 0, 2);
            world.setBlock(chunkX + 11, y + 3, chunkZ + 0, Blocks.air, 0, 2);
            world.setBlock(chunkX + 12, y + 3, chunkZ + 0, Blocks.air, 0, 2);
            world.setBlock(chunkX + 13, y + 3, chunkZ + 0, Blocks.air, 0, 2);
            world.setBlock(chunkX + 14, y + 3, chunkZ + 0, Blocks.air, 0, 2);
            world.setBlock(chunkX + 15, y + 3, chunkZ + 0, Blocks.air, 0, 2);
            world.setBlock(chunkX + 16, y + 3, chunkZ + 0, Blocks.air, 0, 2);
            world.setBlock(chunkX + 0, y + 3, chunkZ + 1, Blocks.air, 0, 2);
            world.setBlock(chunkX + 1, y + 3, chunkZ + 1, Blocks.air, 0, 2);
            world.setBlock(chunkX + 2, y + 3, chunkZ + 1, Blocks.air, 0, 2);
            world.setBlock(chunkX + 3, y + 3, chunkZ + 1, Blocks.air, 0, 2);
            world.setBlock(chunkX + 4, y + 3, chunkZ + 1, Blocks.air, 0, 2);
            world.setBlock(chunkX + 5, y + 3, chunkZ + 1, Main.sepiaBrick, 0, 2);
            world.setBlock(chunkX + 6, y + 3, chunkZ + 1, Main.sepiaBrick, 0, 2);
            world.setBlock(chunkX + 7, y + 3, chunkZ + 1, Main.sepiaBlock, 0, 2);
            world.setBlock(chunkX + 8, y + 3, chunkZ + 1, Main.sepiaBlock, 0, 2);
            world.setBlock(chunkX + 9, y + 3, chunkZ + 1, Main.sepiaBlock, 0, 2);
            world.setBlock(chunkX + 10, y + 3, chunkZ + 1, Main.sepiaBrick, 0, 2);
            world.setBlock(chunkX + 11, y + 3, chunkZ + 1, Main.sepiaBrick, 0, 2);
            world.setBlock(chunkX + 12, y + 3, chunkZ + 1, Blocks.air, 0, 2);
            world.setBlock(chunkX + 13, y + 3, chunkZ + 1, Blocks.air, 0, 2);
            world.setBlock(chunkX + 14, y + 3, chunkZ + 1, Blocks.air, 0, 2);
            world.setBlock(chunkX + 15, y + 3, chunkZ + 1, Blocks.air, 0, 2);
            world.setBlock(chunkX + 16, y + 3, chunkZ + 1, Blocks.air, 0, 2);
            world.setBlock(chunkX + 0, y + 3, chunkZ + 2, Blocks.air, 0, 2);
            world.setBlock(chunkX + 1, y + 3, chunkZ + 2, Blocks.air, 0, 2);
            world.setBlock(chunkX + 2, y + 3, chunkZ + 2, Blocks.air, 0, 2);
            world.setBlock(chunkX + 3, y + 3, chunkZ + 2, Blocks.air, 0, 2);
            world.setBlock(chunkX + 4, y + 3, chunkZ + 2, Main.sepiaBrick, 0, 2);
            world.setBlock(chunkX + 5, y + 3, chunkZ + 2, Blocks.stone, 0, 2);
            world.setBlock(chunkX + 6, y + 3, chunkZ + 2, Main.sepiaBlock, 0, 2);
            world.setBlock(chunkX + 7, y + 3, chunkZ + 2, Blocks.air, 0, 2);
            world.setBlock(chunkX + 8, y + 3, chunkZ + 2, Blocks.air, 0, 2);
            world.setBlock(chunkX + 9, y + 3, chunkZ + 2, Blocks.air, 0, 2);
            world.setBlock(chunkX + 10, y + 3, chunkZ + 2, Main.sepiaBlock, 0, 2);
            world.setBlock(chunkX + 11, y + 3, chunkZ + 2, Blocks.stone, 0, 2);
            world.setBlock(chunkX + 12, y + 3, chunkZ + 2, Main.sepiaBrick, 0, 2);
            world.setBlock(chunkX + 13, y + 3, chunkZ + 2, Blocks.air, 0, 2);
            world.setBlock(chunkX + 14, y + 3, chunkZ + 2, Blocks.air, 0, 2);
            world.setBlock(chunkX + 15, y + 3, chunkZ + 2, Blocks.air, 0, 2);
            world.setBlock(chunkX + 16, y + 3, chunkZ + 2, Blocks.air, 0, 2);
            world.setBlock(chunkX + 0, y + 3, chunkZ + 3, Blocks.air, 0, 2);
            world.setBlock(chunkX + 1, y + 3, chunkZ + 3, Blocks.air, 0, 2);
            world.setBlock(chunkX + 2, y + 3, chunkZ + 3, Blocks.air, 0, 2);
            world.setBlock(chunkX + 3, y + 3, chunkZ + 3, Main.sepiaBrick, 0, 2);
            world.setBlock(chunkX + 4, y + 3, chunkZ + 3, Blocks.stone, 0, 2);
            world.setBlock(chunkX + 5, y + 3, chunkZ + 3, Blocks.air, 0, 2);
            world.setBlock(chunkX + 6, y + 3, chunkZ + 3, Main.fairyTowerChiseled, 0, 2);
            world.setBlock(chunkX + 7, y + 3, chunkZ + 3, Blocks.air, 0, 2);
            world.setBlock(chunkX + 8, y + 3, chunkZ + 3, Blocks.air, 0, 2);
            world.setBlock(chunkX + 9, y + 3, chunkZ + 3, Blocks.air, 0, 2);
            world.setBlock(chunkX + 10, y + 3, chunkZ + 3, Main.fairyTowerChiseled, 0, 2);
            world.setBlock(chunkX + 11, y + 3, chunkZ + 3, Blocks.air, 0, 2);
            world.setBlock(chunkX + 12, y + 3, chunkZ + 3, Blocks.stone, 0, 2);
            world.setBlock(chunkX + 13, y + 3, chunkZ + 3, Main.sepiaBrick, 0, 2);
            world.setBlock(chunkX + 14, y + 3, chunkZ + 3, Blocks.air, 0, 2);
            world.setBlock(chunkX + 15, y + 3, chunkZ + 3, Blocks.air, 0, 2);
            world.setBlock(chunkX + 16, y + 3, chunkZ + 3, Blocks.air, 0, 2);
            world.setBlock(chunkX + 0, y + 3, chunkZ + 4, Blocks.air, 0, 2);
            world.setBlock(chunkX + 1, y + 3, chunkZ + 4, Blocks.air, 0, 2);
            world.setBlock(chunkX + 2, y + 3, chunkZ + 4, Main.sepiaBrick, 0, 2);
            world.setBlock(chunkX + 3, y + 3, chunkZ + 4, Blocks.stone, 0, 2);
            world.setBlock(chunkX + 4, y + 3, chunkZ + 4, Blocks.air, 0, 2);
            world.setBlock(chunkX + 5, y + 3, chunkZ + 4, Blocks.air, 0, 2);
            world.setBlock(chunkX + 6, y + 3, chunkZ + 4, Blocks.air, 0, 2);
            world.setBlock(chunkX + 7, y + 3, chunkZ + 4, Blocks.air, 0, 2);
            world.setBlock(chunkX + 8, y + 3, chunkZ + 4, Blocks.air, 0, 2);
            world.setBlock(chunkX + 9, y + 3, chunkZ + 4, Blocks.air, 0, 2);
            world.setBlock(chunkX + 10, y + 3, chunkZ + 4, Blocks.air, 0, 2);
            world.setBlock(chunkX + 11, y + 3, chunkZ + 4, Blocks.air, 0, 2);
            world.setBlock(chunkX + 12, y + 3, chunkZ + 4, Blocks.air, 0, 2);
            world.setBlock(chunkX + 13, y + 3, chunkZ + 4, Blocks.stone, 0, 2);
            world.setBlock(chunkX + 14, y + 3, chunkZ + 4, Main.sepiaBrick, 0, 2);
            world.setBlock(chunkX + 15, y + 3, chunkZ + 4, Blocks.air, 0, 2);
            world.setBlock(chunkX + 16, y + 3, chunkZ + 4, Blocks.air, 0, 2);
            world.setBlock(chunkX + 0, y + 3, chunkZ + 5, Blocks.air, 0, 2);
            world.setBlock(chunkX + 1, y + 3, chunkZ + 5, Main.sepiaBrick, 0, 2);
            world.setBlock(chunkX + 2, y + 3, chunkZ + 5, Blocks.stone, 0, 2);
            world.setBlock(chunkX + 3, y + 3, chunkZ + 5, Blocks.air, 0, 2);
            world.setBlock(chunkX + 4, y + 3, chunkZ + 5, Blocks.air, 0, 2);
            world.setBlock(chunkX + 5, y + 3, chunkZ + 5, Blocks.air, 0, 2);
            world.setBlock(chunkX + 6, y + 3, chunkZ + 5, Blocks.air, 0, 2);
            world.setBlock(chunkX + 7, y + 3, chunkZ + 5, Blocks.air, 0, 2);
            world.setBlock(chunkX + 8, y + 3, chunkZ + 5, Blocks.air, 0, 2);
            world.setBlock(chunkX + 9, y + 3, chunkZ + 5, Blocks.air, 0, 2);
            world.setBlock(chunkX + 10, y + 3, chunkZ + 5, Blocks.air, 0, 2);
            world.setBlock(chunkX + 11, y + 3, chunkZ + 5, Blocks.air, 0, 2);
            world.setBlock(chunkX + 12, y + 3, chunkZ + 5, Blocks.air, 0, 2);
            world.setBlock(chunkX + 13, y + 3, chunkZ + 5, Blocks.air, 0, 2);
            world.setBlock(chunkX + 14, y + 3, chunkZ + 5, Blocks.stone, 0, 2);
            world.setBlock(chunkX + 15, y + 3, chunkZ + 5, Main.sepiaBrick, 0, 2);
            world.setBlock(chunkX + 16, y + 3, chunkZ + 5, Blocks.air, 0, 2);
            world.setBlock(chunkX + 0, y + 3, chunkZ + 6, Main.sepiaBrick, 0, 2);
            world.setBlock(chunkX + 1, y + 3, chunkZ + 6, Blocks.stone, 0, 2);
            world.setBlock(chunkX + 2, y + 3, chunkZ + 6, Blocks.air, 0, 2);
            world.setBlock(chunkX + 3, y + 3, chunkZ + 6, Blocks.air, 0, 2);
            world.setBlock(chunkX + 4, y + 3, chunkZ + 6, Blocks.air, 0, 2);
            world.setBlock(chunkX + 5, y + 3, chunkZ + 6, Blocks.air, 0, 2);
            world.setBlock(chunkX + 6, y + 3, chunkZ + 6, Blocks.air, 0, 2);
            world.setBlock(chunkX + 7, y + 3, chunkZ + 6, Blocks.air, 0, 2);
            world.setBlock(chunkX + 8, y + 3, chunkZ + 6, Blocks.air, 0, 2);
            world.setBlock(chunkX + 9, y + 3, chunkZ + 6, Blocks.air, 0, 2);
            world.setBlock(chunkX + 10, y + 3, chunkZ + 6, Blocks.air, 0, 2);
            world.setBlock(chunkX + 11, y + 3, chunkZ + 6, Blocks.air, 0, 2);
            world.setBlock(chunkX + 12, y + 3, chunkZ + 6, Blocks.air, 0, 2);
            world.setBlock(chunkX + 13, y + 3, chunkZ + 6, Blocks.air, 0, 2);
            world.setBlock(chunkX + 14, y + 3, chunkZ + 6, Blocks.air, 0, 2);
            world.setBlock(chunkX + 15, y + 3, chunkZ + 6, Blocks.stone, 0, 2);
            world.setBlock(chunkX + 16, y + 3, chunkZ + 6, Main.sepiaBrick, 0, 2);
            world.setBlock(chunkX + 0, y + 3, chunkZ + 7, Main.sepiaBrick, 0, 2);
            world.setBlock(chunkX + 1, y + 3, chunkZ + 7, Blocks.stone, 0, 2);
            world.setBlock(chunkX + 2, y + 3, chunkZ + 7, Blocks.air, 0, 2);
            world.setBlock(chunkX + 3, y + 3, chunkZ + 7, Blocks.air, 0, 2);
            world.setBlock(chunkX + 4, y + 3, chunkZ + 7, Blocks.air, 0, 2);
            world.setBlock(chunkX + 5, y + 3, chunkZ + 7, Blocks.air, 0, 2);
            world.setBlock(chunkX + 6, y + 3, chunkZ + 7, Blocks.air, 0, 2);
            world.setBlock(chunkX + 7, y + 3, chunkZ + 7, Blocks.air, 0, 2);
            world.setBlock(chunkX + 8, y + 3, chunkZ + 7, Blocks.air, 0, 2);
            world.setBlock(chunkX + 9, y + 3, chunkZ + 7, Blocks.air, 0, 2);
            world.setBlock(chunkX + 10, y + 3, chunkZ + 7, Blocks.air, 0, 2);
            world.setBlock(chunkX + 11, y + 3, chunkZ + 7, Blocks.air, 0, 2);
            world.setBlock(chunkX + 12, y + 3, chunkZ + 7, Blocks.air, 0, 2);
            world.setBlock(chunkX + 13, y + 3, chunkZ + 7, Blocks.air, 0, 2);
            world.setBlock(chunkX + 14, y + 3, chunkZ + 7, Blocks.air, 0, 2);
            world.setBlock(chunkX + 15, y + 3, chunkZ + 7, Blocks.stone, 0, 2);
            world.setBlock(chunkX + 16, y + 3, chunkZ + 7, Main.sepiaBrick, 0, 2);
            world.setBlock(chunkX + 0, y + 3, chunkZ + 8, Main.sepiaBrick, 0, 2);
            world.setBlock(chunkX + 1, y + 3, chunkZ + 8, Blocks.stone, 0, 2);
            world.setBlock(chunkX + 2, y + 3, chunkZ + 8, Blocks.air, 0, 2);
            world.setBlock(chunkX + 3, y + 3, chunkZ + 8, Blocks.air, 0, 2);
            world.setBlock(chunkX + 4, y + 3, chunkZ + 8, Blocks.air, 0, 2);
            world.setBlock(chunkX + 5, y + 3, chunkZ + 8, Blocks.air, 0, 2);
            world.setBlock(chunkX + 6, y + 3, chunkZ + 8, Blocks.air, 0, 2);
            world.setBlock(chunkX + 7, y + 3, chunkZ + 8, Blocks.air, 0, 2);
            world.setBlock(chunkX + 8, y + 3, chunkZ + 8, Blocks.air, 0, 2);
            world.setBlock(chunkX + 9, y + 3, chunkZ + 8, Blocks.air, 0, 2);
            world.setBlock(chunkX + 10, y + 3, chunkZ + 8, Blocks.air, 0, 2);
            world.setBlock(chunkX + 11, y + 3, chunkZ + 8, Blocks.air, 0, 2);
            world.setBlock(chunkX + 12, y + 3, chunkZ + 8, Blocks.air, 0, 2);
            world.setBlock(chunkX + 13, y + 3, chunkZ + 8, Blocks.air, 0, 2);
            world.setBlock(chunkX + 14, y + 3, chunkZ + 8, Blocks.air, 0, 2);
            world.setBlock(chunkX + 15, y + 3, chunkZ + 8, Blocks.stone, 0, 2);
            world.setBlock(chunkX + 16, y + 3, chunkZ + 8, Main.sepiaBrick, 0, 2);
            world.setBlock(chunkX + 0, y + 3, chunkZ + 9, Main.sepiaBrick, 0, 2);
            world.setBlock(chunkX + 1, y + 3, chunkZ + 9, Blocks.stone, 0, 2);
            world.setBlock(chunkX + 2, y + 3, chunkZ + 9, Blocks.air, 0, 2);
            world.setBlock(chunkX + 3, y + 3, chunkZ + 9, Blocks.air, 0, 2);
            world.setBlock(chunkX + 4, y + 3, chunkZ + 9, Blocks.air, 0, 2);
            world.setBlock(chunkX + 5, y + 3, chunkZ + 9, Blocks.air, 0, 2);
            world.setBlock(chunkX + 6, y + 3, chunkZ + 9, Blocks.air, 0, 2);
            world.setBlock(chunkX + 7, y + 3, chunkZ + 9, Blocks.air, 0, 2);
            world.setBlock(chunkX + 8, y + 3, chunkZ + 9, Blocks.air, 0, 2);
            world.setBlock(chunkX + 9, y + 3, chunkZ + 9, Blocks.air, 0, 2);
            world.setBlock(chunkX + 10, y + 3, chunkZ + 9, Blocks.air, 0, 2);
            world.setBlock(chunkX + 11, y + 3, chunkZ + 9, Blocks.air, 0, 2);
            world.setBlock(chunkX + 12, y + 3, chunkZ + 9, Blocks.air, 0, 2);
            world.setBlock(chunkX + 13, y + 3, chunkZ + 9, Blocks.air, 0, 2);
            world.setBlock(chunkX + 14, y + 3, chunkZ + 9, Blocks.air, 0, 2);
            world.setBlock(chunkX + 15, y + 3, chunkZ + 9, Blocks.stone, 0, 2);
            world.setBlock(chunkX + 16, y + 3, chunkZ + 9, Main.sepiaBrick, 0, 2);
            world.setBlock(chunkX + 0, y + 3, chunkZ + 10, Main.sepiaBrick, 0, 2);
            world.setBlock(chunkX + 1, y + 3, chunkZ + 10, Blocks.stone, 0, 2);
            world.setBlock(chunkX + 2, y + 3, chunkZ + 10, Blocks.air, 0, 2);
            world.setBlock(chunkX + 3, y + 3, chunkZ + 10, Blocks.air, 0, 2);
            world.setBlock(chunkX + 4, y + 3, chunkZ + 10, Blocks.air, 0, 2);
            world.setBlock(chunkX + 5, y + 3, chunkZ + 10, Blocks.air, 0, 2);
            world.setBlock(chunkX + 6, y + 3, chunkZ + 10, Blocks.air, 0, 2);
            world.setBlock(chunkX + 7, y + 3, chunkZ + 10, Blocks.air, 0, 2);
            world.setBlock(chunkX + 8, y + 3, chunkZ + 10, Blocks.air, 0, 2);
            world.setBlock(chunkX + 9, y + 3, chunkZ + 10, Blocks.air, 0, 2);
            world.setBlock(chunkX + 10, y + 3, chunkZ + 10, Blocks.air, 0, 2);
            world.setBlock(chunkX + 11, y + 3, chunkZ + 10, Blocks.air, 0, 2);
            world.setBlock(chunkX + 12, y + 3, chunkZ + 10, Blocks.air, 0, 2);
            world.setBlock(chunkX + 13, y + 3, chunkZ + 10, Blocks.air, 0, 2);
            world.setBlock(chunkX + 14, y + 3, chunkZ + 10, Blocks.air, 0, 2);
            world.setBlock(chunkX + 15, y + 3, chunkZ + 10, Blocks.stone, 0, 2);
            world.setBlock(chunkX + 16, y + 3, chunkZ + 10, Main.sepiaBrick, 0, 2);
            world.setBlock(chunkX + 0, y + 3, chunkZ + 11, Main.sepiaBrick, 0, 2);
            world.setBlock(chunkX + 1, y + 3, chunkZ + 11, Blocks.stone, 0, 2);
            world.setBlock(chunkX + 2, y + 3, chunkZ + 11, Blocks.air, 0, 2);
            world.setBlock(chunkX + 3, y + 3, chunkZ + 11, Blocks.air, 0, 2);
            world.setBlock(chunkX + 4, y + 3, chunkZ + 11, Blocks.air, 0, 2);
            world.setBlock(chunkX + 5, y + 3, chunkZ + 11, Blocks.air, 0, 2);
            world.setBlock(chunkX + 6, y + 3, chunkZ + 11, Blocks.air, 0, 2);
            world.setBlock(chunkX + 7, y + 3, chunkZ + 11, Blocks.air, 0, 2);
            world.setBlock(chunkX + 8, y + 3, chunkZ + 11, Blocks.air, 0, 2);
            world.setBlock(chunkX + 9, y + 3, chunkZ + 11, Blocks.air, 0, 2);
            world.setBlock(chunkX + 10, y + 3, chunkZ + 11, Blocks.air, 0, 2);
            world.setBlock(chunkX + 11, y + 3, chunkZ + 11, Blocks.air, 0, 2);
            world.setBlock(chunkX + 12, y + 3, chunkZ + 11, Blocks.air, 0, 2);
            world.setBlock(chunkX + 13, y + 3, chunkZ + 11, Blocks.air, 0, 2);
            world.setBlock(chunkX + 14, y + 3, chunkZ + 11, Blocks.air, 0, 2);
            world.setBlock(chunkX + 15, y + 3, chunkZ + 11, Blocks.stone, 0, 2);
            world.setBlock(chunkX + 16, y + 3, chunkZ + 11, Main.sepiaBrick, 0, 2);
            world.setBlock(chunkX + 0, y + 3, chunkZ + 12, Blocks.air, 0, 2);
            world.setBlock(chunkX + 1, y + 3, chunkZ + 12, Main.sepiaBrick, 0, 2);
            world.setBlock(chunkX + 2, y + 3, chunkZ + 12, Blocks.stone, 0, 2);
            world.setBlock(chunkX + 3, y + 3, chunkZ + 12, Blocks.air, 0, 2);
            world.setBlock(chunkX + 4, y + 3, chunkZ + 12, Blocks.air, 0, 2);
            world.setBlock(chunkX + 5, y + 3, chunkZ + 12, Blocks.air, 0, 2);
            world.setBlock(chunkX + 6, y + 3, chunkZ + 12, Blocks.air, 0, 2);
            world.setBlock(chunkX + 7, y + 3, chunkZ + 12, Blocks.air, 0, 2);
            world.setBlock(chunkX + 8, y + 3, chunkZ + 12, Blocks.air, 0, 2);
            world.setBlock(chunkX + 9, y + 3, chunkZ + 12, Blocks.air, 0, 2);
            world.setBlock(chunkX + 10, y + 3, chunkZ + 12, Blocks.air, 0, 2);
            world.setBlock(chunkX + 11, y + 3, chunkZ + 12, Blocks.air, 0, 2);
            world.setBlock(chunkX + 12, y + 3, chunkZ + 12, Blocks.air, 0, 2);
            world.setBlock(chunkX + 13, y + 3, chunkZ + 12, Blocks.air, 0, 2);
            world.setBlock(chunkX + 14, y + 3, chunkZ + 12, Blocks.stone, 0, 2);
            world.setBlock(chunkX + 15, y + 3, chunkZ + 12, Main.sepiaBrick, 0, 2);
            world.setBlock(chunkX + 16, y + 3, chunkZ + 12, Blocks.air, 0, 2);
            world.setBlock(chunkX + 0, y + 3, chunkZ + 13, Blocks.air, 0, 2);
            world.setBlock(chunkX + 1, y + 3, chunkZ + 13, Blocks.air, 0, 2);
            world.setBlock(chunkX + 2, y + 3, chunkZ + 13, Main.sepiaBrick, 0, 2);
            world.setBlock(chunkX + 3, y + 3, chunkZ + 13, Blocks.stone, 0, 2);
            world.setBlock(chunkX + 4, y + 3, chunkZ + 13, Blocks.stone, 0, 2);
            world.setBlock(chunkX + 5, y + 3, chunkZ + 13, Blocks.stone, 0, 2);
            world.setBlock(chunkX + 6, y + 3, chunkZ + 13, Main.sepiaThinBrick, 0, 2);
            world.setBlock(chunkX + 7, y + 3, chunkZ + 13, Main.sepiaBrick, 0, 2);
            world.setBlock(chunkX + 8, y + 3, chunkZ + 13, Main.sepiaBrick, 0, 2);
            world.setBlock(chunkX + 9, y + 3, chunkZ + 13, Main.sepiaBrick, 0, 2);
            world.setBlock(chunkX + 10, y + 3, chunkZ + 13, Main.sepiaThinBrick, 0, 2);
            world.setBlock(chunkX + 11, y + 3, chunkZ + 13, Blocks.stone, 0, 2);
            world.setBlock(chunkX + 12, y + 3, chunkZ + 13, Blocks.stone, 0, 2);
            world.setBlock(chunkX + 13, y + 3, chunkZ + 13, Blocks.stone, 0, 2);
            world.setBlock(chunkX + 14, y + 3, chunkZ + 13, Main.sepiaBrick, 0, 2);
            world.setBlock(chunkX + 15, y + 3, chunkZ + 13, Blocks.air, 0, 2);
            world.setBlock(chunkX + 16, y + 3, chunkZ + 13, Blocks.air, 0, 2);
            world.setBlock(chunkX + 0, y + 3, chunkZ + 14, Blocks.air, 0, 2);
            world.setBlock(chunkX + 1, y + 3, chunkZ + 14, Blocks.air, 0, 2);
            world.setBlock(chunkX + 2, y + 3, chunkZ + 14, Blocks.air, 0, 2);
            world.setBlock(chunkX + 3, y + 3, chunkZ + 14, Main.sepiaBrick, 0, 2);
            world.setBlock(chunkX + 4, y + 3, chunkZ + 14, Main.sepiaBrick, 0, 2);
            world.setBlock(chunkX + 5, y + 3, chunkZ + 14, Main.sepiaBrick, 0, 2);
            world.setBlock(chunkX + 6, y + 3, chunkZ + 14, Main.sepiaThinBrick, 0, 2);
            world.setBlock(chunkX + 7, y + 3, chunkZ + 14, Main.sepiaBrick, 0, 2);
            world.setBlock(chunkX + 8, y + 3, chunkZ + 14, Main.sepiaBrick, 0, 2);
            world.setBlock(chunkX + 9, y + 3, chunkZ + 14, Main.sepiaBrick, 0, 2);
            world.setBlock(chunkX + 10, y + 3, chunkZ + 14, Main.sepiaThinBrick, 0, 2);
            world.setBlock(chunkX + 11, y + 3, chunkZ + 14, Main.sepiaBrick, 0, 2);
            world.setBlock(chunkX + 12, y + 3, chunkZ + 14, Main.sepiaBrick, 0, 2);
            world.setBlock(chunkX + 13, y + 3, chunkZ + 14, Main.sepiaBrick, 0, 2);
            world.setBlock(chunkX + 14, y + 3, chunkZ + 14, Blocks.air, 0, 2);
            world.setBlock(chunkX + 15, y + 3, chunkZ + 14, Blocks.air, 0, 2);
            world.setBlock(chunkX + 16, y + 3, chunkZ + 14, Blocks.air, 0, 2);
            world.setBlock(chunkX + 0, y + 4, chunkZ + 0, Blocks.air, 0, 2);
            world.setBlock(chunkX + 1, y + 4, chunkZ + 0, Blocks.air, 0, 2);
            world.setBlock(chunkX + 2, y + 4, chunkZ + 0, Blocks.air, 0, 2);
            world.setBlock(chunkX + 3, y + 4, chunkZ + 0, Blocks.air, 0, 2);
            world.setBlock(chunkX + 4, y + 4, chunkZ + 0, Blocks.air, 0, 2);
            world.setBlock(chunkX + 5, y + 4, chunkZ + 0, Blocks.air, 0, 2);
            world.setBlock(chunkX + 6, y + 4, chunkZ + 0, Blocks.air, 0, 2);
            world.setBlock(chunkX + 7, y + 4, chunkZ + 0, Main.sepiaBrick, 0, 2);
            world.setBlock(chunkX + 8, y + 4, chunkZ + 0, Main.sepiaBrick, 0, 2);
            world.setBlock(chunkX + 9, y + 4, chunkZ + 0, Main.sepiaBrick, 0, 2);
            world.setBlock(chunkX + 10, y + 4, chunkZ + 0, Blocks.air, 0, 2);
            world.setBlock(chunkX + 11, y + 4, chunkZ + 0, Blocks.air, 0, 2);
            world.setBlock(chunkX + 12, y + 4, chunkZ + 0, Blocks.air, 0, 2);
            world.setBlock(chunkX + 13, y + 4, chunkZ + 0, Blocks.air, 0, 2);
            world.setBlock(chunkX + 14, y + 4, chunkZ + 0, Blocks.air, 0, 2);
            world.setBlock(chunkX + 15, y + 4, chunkZ + 0, Blocks.air, 0, 2);
            world.setBlock(chunkX + 16, y + 4, chunkZ + 0, Blocks.air, 0, 2);
            world.setBlock(chunkX + 0, y + 4, chunkZ + 1, Blocks.air, 0, 2);
            world.setBlock(chunkX + 1, y + 4, chunkZ + 1, Blocks.air, 0, 2);
            world.setBlock(chunkX + 2, y + 4, chunkZ + 1, Blocks.air, 0, 2);
            world.setBlock(chunkX + 3, y + 4, chunkZ + 1, Blocks.air, 0, 2);
            world.setBlock(chunkX + 4, y + 4, chunkZ + 1, Blocks.air, 0, 2);
            world.setBlock(chunkX + 5, y + 4, chunkZ + 1, Main.sepiaBrick, 0, 2);
            world.setBlock(chunkX + 6, y + 4, chunkZ + 1, Main.sepiaBrick, 0, 2);
            world.setBlock(chunkX + 7, y + 4, chunkZ + 1, Blocks.stone, 0, 2);
            world.setBlock(chunkX + 8, y + 4, chunkZ + 1, Blocks.stone, 0, 2);
            world.setBlock(chunkX + 9, y + 4, chunkZ + 1, Blocks.stone, 0, 2);
            world.setBlock(chunkX + 10, y + 4, chunkZ + 1, Main.sepiaBrick, 0, 2);
            world.setBlock(chunkX + 11, y + 4, chunkZ + 1, Main.sepiaBrick, 0, 2);
            world.setBlock(chunkX + 12, y + 4, chunkZ + 1, Blocks.air, 0, 2);
            world.setBlock(chunkX + 13, y + 4, chunkZ + 1, Blocks.air, 0, 2);
            world.setBlock(chunkX + 14, y + 4, chunkZ + 1, Blocks.air, 0, 2);
            world.setBlock(chunkX + 15, y + 4, chunkZ + 1, Blocks.air, 0, 2);
            world.setBlock(chunkX + 16, y + 4, chunkZ + 1, Blocks.air, 0, 2);
            world.setBlock(chunkX + 0, y + 4, chunkZ + 2, Blocks.air, 0, 2);
            world.setBlock(chunkX + 1, y + 4, chunkZ + 2, Blocks.air, 0, 2);
            world.setBlock(chunkX + 2, y + 4, chunkZ + 2, Blocks.air, 0, 2);
            world.setBlock(chunkX + 3, y + 4, chunkZ + 2, Blocks.air, 0, 2);
            world.setBlock(chunkX + 4, y + 4, chunkZ + 2, Main.sepiaBrick, 0, 2);
            world.setBlock(chunkX + 5, y + 4, chunkZ + 2, Blocks.stone, 0, 2);
            world.setBlock(chunkX + 6, y + 4, chunkZ + 2, Blocks.stone, 0, 2);
            world.setBlock(chunkX + 7, y + 4, chunkZ + 2, Main.sepiaBlock, 0, 2);
            world.setBlock(chunkX + 8, y + 4, chunkZ + 2, Main.sepiaBlock, 0, 2);
            world.setBlock(chunkX + 9, y + 4, chunkZ + 2, Main.sepiaBlock, 0, 2);
            world.setBlock(chunkX + 10, y + 4, chunkZ + 2, Blocks.stone, 0, 2);
            world.setBlock(chunkX + 11, y + 4, chunkZ + 2, Blocks.stone, 0, 2);
            world.setBlock(chunkX + 12, y + 4, chunkZ + 2, Main.sepiaBrick, 0, 2);
            world.setBlock(chunkX + 13, y + 4, chunkZ + 2, Blocks.air, 0, 2);
            world.setBlock(chunkX + 14, y + 4, chunkZ + 2, Blocks.air, 0, 2);
            world.setBlock(chunkX + 15, y + 4, chunkZ + 2, Blocks.air, 0, 2);
            world.setBlock(chunkX + 16, y + 4, chunkZ + 2, Blocks.air, 0, 2);
            world.setBlock(chunkX + 0, y + 4, chunkZ + 3, Blocks.air, 0, 2);
            world.setBlock(chunkX + 1, y + 4, chunkZ + 3, Blocks.air, 0, 2);
            world.setBlock(chunkX + 2, y + 4, chunkZ + 3, Blocks.air, 0, 2);
            world.setBlock(chunkX + 3, y + 4, chunkZ + 3, Main.sepiaBrick, 0, 2);
            world.setBlock(chunkX + 4, y + 4, chunkZ + 3, Blocks.stone, 0, 2);
            world.setBlock(chunkX + 5, y + 4, chunkZ + 3, Blocks.air, 0, 2);
            world.setBlock(chunkX + 6, y + 4, chunkZ + 3, Blocks.air, 0, 2);
            world.setBlock(chunkX + 7, y + 4, chunkZ + 3, Main.sepiaBrick, 0, 2);
            world.setBlock(chunkX + 8, y + 4, chunkZ + 3, Main.sepiaBrick, 0, 2);
            world.setBlock(chunkX + 9, y + 4, chunkZ + 3, Main.sepiaBrick, 0, 2);
            world.setBlock(chunkX + 10, y + 4, chunkZ + 3, Blocks.air, 1, 2);
            world.setBlock(chunkX + 11, y + 4, chunkZ + 3, Blocks.air, 0, 2);
            world.setBlock(chunkX + 12, y + 4, chunkZ + 3, Blocks.stone, 0, 2);
            world.setBlock(chunkX + 13, y + 4, chunkZ + 3, Main.sepiaBrick, 0, 2);
            world.setBlock(chunkX + 14, y + 4, chunkZ + 3, Blocks.air, 0, 2);
            world.setBlock(chunkX + 15, y + 4, chunkZ + 3, Blocks.air, 0, 2);
            world.setBlock(chunkX + 16, y + 4, chunkZ + 3, Blocks.air, 0, 2);
            world.setBlock(chunkX + 0, y + 4, chunkZ + 4, Blocks.air, 0, 2);
            world.setBlock(chunkX + 1, y + 4, chunkZ + 4, Blocks.air, 0, 2);
            world.setBlock(chunkX + 2, y + 4, chunkZ + 4, Main.sepiaBrick, 0, 2);
            world.setBlock(chunkX + 3, y + 4, chunkZ + 4, Blocks.stone, 0, 2);
            world.setBlock(chunkX + 4, y + 4, chunkZ + 4, Blocks.air, 0, 2);
            world.setBlock(chunkX + 5, y + 4, chunkZ + 4, Blocks.air, 0, 2);
            world.setBlock(chunkX + 6, y + 4, chunkZ + 4, Blocks.air, 0, 2);
            world.setBlock(chunkX + 7, y + 4, chunkZ + 4, Blocks.air, 0, 2);
            world.setBlock(chunkX + 8, y + 4, chunkZ + 4, Blocks.air, 0, 2);
            world.setBlock(chunkX + 9, y + 4, chunkZ + 4, Blocks.air, 0, 2);
            world.setBlock(chunkX + 10, y + 4, chunkZ + 4, Blocks.air, 0, 2);
            world.setBlock(chunkX + 11, y + 4, chunkZ + 4, Blocks.air, 0, 2);
            world.setBlock(chunkX + 12, y + 4, chunkZ + 4, Blocks.air, 0, 2);
            world.setBlock(chunkX + 13, y + 4, chunkZ + 4, Blocks.stone, 0, 2);
            world.setBlock(chunkX + 14, y + 4, chunkZ + 4, Main.sepiaBrick, 0, 2);
            world.setBlock(chunkX + 15, y + 4, chunkZ + 4, Blocks.air, 0, 2);
            world.setBlock(chunkX + 16, y + 4, chunkZ + 4, Blocks.air, 0, 2);
            world.setBlock(chunkX + 0, y + 4, chunkZ + 5, Blocks.air, 0, 2);
            world.setBlock(chunkX + 1, y + 4, chunkZ + 5, Main.sepiaBrick, 0, 2);
            world.setBlock(chunkX + 2, y + 4, chunkZ + 5, Blocks.stone, 0, 2);
            world.setBlock(chunkX + 3, y + 4, chunkZ + 5, Blocks.air, 0, 2);
            world.setBlock(chunkX + 4, y + 4, chunkZ + 5, Blocks.air, 0, 2);
            world.setBlock(chunkX + 5, y + 4, chunkZ + 5, Blocks.air, 0, 2);
            world.setBlock(chunkX + 6, y + 4, chunkZ + 5, Blocks.air, 0, 2);
            world.setBlock(chunkX + 7, y + 4, chunkZ + 5, Blocks.air, 0, 2);
            world.setBlock(chunkX + 8, y + 4, chunkZ + 5, Blocks.air, 0, 2);
            world.setBlock(chunkX + 9, y + 4, chunkZ + 5, Blocks.air, 0, 2);
            world.setBlock(chunkX + 10, y + 4, chunkZ + 5, Blocks.air, 0, 2);
            world.setBlock(chunkX + 11, y + 4, chunkZ + 5, Blocks.air, 0, 2);
            world.setBlock(chunkX + 12, y + 4, chunkZ + 5, Blocks.air, 0, 2);
            world.setBlock(chunkX + 13, y + 4, chunkZ + 5, Blocks.air, 0, 2);
            world.setBlock(chunkX + 14, y + 4, chunkZ + 5, Blocks.stone, 0, 2);
            world.setBlock(chunkX + 15, y + 4, chunkZ + 5, Main.sepiaBrick, 0, 2);
            world.setBlock(chunkX + 16, y + 4, chunkZ + 5, Blocks.air, 0, 2);
            world.setBlock(chunkX + 0, y + 4, chunkZ + 6, Main.sepiaBrick, 0, 2);
            world.setBlock(chunkX + 1, y + 4, chunkZ + 6, Blocks.stone, 0, 2);
            world.setBlock(chunkX + 2, y + 4, chunkZ + 6, Blocks.air, 0, 2);
            world.setBlock(chunkX + 3, y + 4, chunkZ + 6, Blocks.air, 0, 2);
            world.setBlock(chunkX + 4, y + 4, chunkZ + 6, Blocks.air, 0, 2);
            world.setBlock(chunkX + 5, y + 4, chunkZ + 6, Blocks.air, 0, 2);
            world.setBlock(chunkX + 6, y + 4, chunkZ + 6, Blocks.air, 0, 2);
            world.setBlock(chunkX + 7, y + 4, chunkZ + 6, Blocks.air, 0, 2);
            world.setBlock(chunkX + 8, y + 4, chunkZ + 6, Blocks.air, 0, 2);
            world.setBlock(chunkX + 9, y + 4, chunkZ + 6, Blocks.air, 0, 2);
            world.setBlock(chunkX + 10, y + 4, chunkZ + 6, Blocks.air, 0, 2);
            world.setBlock(chunkX + 11, y + 4, chunkZ + 6, Blocks.air, 0, 2);
            world.setBlock(chunkX + 12, y + 4, chunkZ + 6, Blocks.air, 0, 2);
            world.setBlock(chunkX + 13, y + 4, chunkZ + 6, Blocks.air, 0, 2);
            world.setBlock(chunkX + 14, y + 4, chunkZ + 6, Blocks.air, 0, 2);
            world.setBlock(chunkX + 15, y + 4, chunkZ + 6, Blocks.stone, 0, 2);
            world.setBlock(chunkX + 16, y + 4, chunkZ + 6, Main.sepiaBrick, 0, 2);
            world.setBlock(chunkX + 0, y + 4, chunkZ + 7, Main.sepiaBrick, 0, 2);
            world.setBlock(chunkX + 1, y + 4, chunkZ + 7, Blocks.stone, 0, 2);
            world.setBlock(chunkX + 2, y + 4, chunkZ + 7, Blocks.air, 0, 2);
            world.setBlock(chunkX + 3, y + 4, chunkZ + 7, Blocks.air, 0, 2);
            world.setBlock(chunkX + 4, y + 4, chunkZ + 7, Blocks.air, 0, 2);
            world.setBlock(chunkX + 5, y + 4, chunkZ + 7, Blocks.air, 0, 2);
            world.setBlock(chunkX + 6, y + 4, chunkZ + 7, Blocks.air, 0, 2);
            world.setBlock(chunkX + 7, y + 4, chunkZ + 7, Blocks.air, 0, 2);
            world.setBlock(chunkX + 8, y + 4, chunkZ + 7, Blocks.air, 0, 2);
            world.setBlock(chunkX + 9, y + 4, chunkZ + 7, Blocks.air, 0, 2);
            world.setBlock(chunkX + 10, y + 4, chunkZ + 7, Blocks.air, 0, 2);
            world.setBlock(chunkX + 11, y + 4, chunkZ + 7, Blocks.air, 0, 2);
            world.setBlock(chunkX + 12, y + 4, chunkZ + 7, Blocks.air, 0, 2);
            world.setBlock(chunkX + 13, y + 4, chunkZ + 7, Blocks.air, 0, 2);
            world.setBlock(chunkX + 14, y + 4, chunkZ + 7, Blocks.air, 0, 2);
            world.setBlock(chunkX + 15, y + 4, chunkZ + 7, Blocks.stone, 0, 2);
            world.setBlock(chunkX + 16, y + 4, chunkZ + 7, Main.sepiaBrick, 0, 2);
            world.setBlock(chunkX + 0, y + 4, chunkZ + 8, Main.sepiaBrick, 0, 2);
            world.setBlock(chunkX + 1, y + 4, chunkZ + 8, Blocks.stone, 0, 2);
            world.setBlock(chunkX + 2, y + 4, chunkZ + 8, Blocks.air, 0, 2);
            world.setBlock(chunkX + 3, y + 4, chunkZ + 8, Blocks.air, 0, 2);
            world.setBlock(chunkX + 4, y + 4, chunkZ + 8, Blocks.air, 0, 2);
            world.setBlock(chunkX + 5, y + 4, chunkZ + 8, Blocks.air, 0, 2);
            world.setBlock(chunkX + 6, y + 4, chunkZ + 8, Blocks.air, 0, 2);
            world.setBlock(chunkX + 7, y + 4, chunkZ + 8, Blocks.air, 0, 2);
            world.setBlock(chunkX + 8, y + 4, chunkZ + 8, Blocks.air, 0, 2);
            world.setBlock(chunkX + 9, y + 4, chunkZ + 8, Blocks.air, 0, 2);
            world.setBlock(chunkX + 10, y + 4, chunkZ + 8, Blocks.air, 0, 2);
            world.setBlock(chunkX + 11, y + 4, chunkZ + 8, Blocks.air, 0, 2);
            world.setBlock(chunkX + 12, y + 4, chunkZ + 8, Blocks.air, 0, 2);
            world.setBlock(chunkX + 13, y + 4, chunkZ + 8, Blocks.air, 0, 2);
            world.setBlock(chunkX + 14, y + 4, chunkZ + 8, Blocks.air, 0, 2);
            world.setBlock(chunkX + 15, y + 4, chunkZ + 8, Blocks.stone, 0, 2);
            world.setBlock(chunkX + 16, y + 4, chunkZ + 8, Main.sepiaBrick, 0, 2);
            world.setBlock(chunkX + 0, y + 4, chunkZ + 9, Main.sepiaBrick, 0, 2);
            world.setBlock(chunkX + 1, y + 4, chunkZ + 9, Blocks.stone, 0, 2);
            world.setBlock(chunkX + 2, y + 4, chunkZ + 9, Blocks.air, 0, 2);
            world.setBlock(chunkX + 3, y + 4, chunkZ + 9, Blocks.air, 0, 2);
            world.setBlock(chunkX + 4, y + 4, chunkZ + 9, Blocks.air, 0, 2);
            world.setBlock(chunkX + 5, y + 4, chunkZ + 9, Blocks.air, 0, 2);
            world.setBlock(chunkX + 6, y + 4, chunkZ + 9, Blocks.air, 0, 2);
            world.setBlock(chunkX + 7, y + 4, chunkZ + 9, Blocks.air, 0, 2);
            world.setBlock(chunkX + 8, y + 4, chunkZ + 9, Blocks.air, 0, 2);
            world.setBlock(chunkX + 9, y + 4, chunkZ + 9, Blocks.air, 0, 2);
            world.setBlock(chunkX + 10, y + 4, chunkZ + 9, Blocks.air, 0, 2);
            world.setBlock(chunkX + 11, y + 4, chunkZ + 9, Blocks.air, 0, 2);
            world.setBlock(chunkX + 12, y + 4, chunkZ + 9, Blocks.air, 0, 2);
            world.setBlock(chunkX + 13, y + 4, chunkZ + 9, Blocks.air, 0, 2);
            world.setBlock(chunkX + 14, y + 4, chunkZ + 9, Blocks.air, 0, 2);
            world.setBlock(chunkX + 15, y + 4, chunkZ + 9, Blocks.stone, 0, 2);
            world.setBlock(chunkX + 16, y + 4, chunkZ + 9, Main.sepiaBrick, 0, 2);
            world.setBlock(chunkX + 0, y + 4, chunkZ + 10, Main.sepiaBrick, 0, 2);
            world.setBlock(chunkX + 1, y + 4, chunkZ + 10, Blocks.stone, 0, 2);
            world.setBlock(chunkX + 2, y + 4, chunkZ + 10, Blocks.air, 0, 2);
            world.setBlock(chunkX + 3, y + 4, chunkZ + 10, Blocks.air, 0, 2);
            world.setBlock(chunkX + 4, y + 4, chunkZ + 10, Blocks.air, 0, 2);
            world.setBlock(chunkX + 5, y + 4, chunkZ + 10, Blocks.air, 0, 2);
            world.setBlock(chunkX + 6, y + 4, chunkZ + 10, Blocks.air, 0, 2);
            world.setBlock(chunkX + 7, y + 4, chunkZ + 10, Blocks.air, 0, 2);
            world.setBlock(chunkX + 8, y + 4, chunkZ + 10, Blocks.air, 0, 2);
            world.setBlock(chunkX + 9, y + 4, chunkZ + 10, Blocks.air, 0, 2);
            world.setBlock(chunkX + 10, y + 4, chunkZ + 10, Blocks.air, 0, 2);
            world.setBlock(chunkX + 11, y + 4, chunkZ + 10, Blocks.air, 0, 2);
            world.setBlock(chunkX + 12, y + 4, chunkZ + 10, Blocks.air, 0, 2);
            world.setBlock(chunkX + 13, y + 4, chunkZ + 10, Blocks.air, 0, 2);
            world.setBlock(chunkX + 14, y + 4, chunkZ + 10, Blocks.air, 0, 2);
            world.setBlock(chunkX + 15, y + 4, chunkZ + 10, Blocks.stone, 0, 2);
            world.setBlock(chunkX + 16, y + 4, chunkZ + 10, Main.sepiaBrick, 0, 2);
            world.setBlock(chunkX + 0, y + 4, chunkZ + 11, Main.sepiaBrick, 0, 2);
            world.setBlock(chunkX + 1, y + 4, chunkZ + 11, Blocks.stone, 0, 2);
            world.setBlock(chunkX + 2, y + 4, chunkZ + 11, Blocks.air, 0, 2);
            world.setBlock(chunkX + 3, y + 4, chunkZ + 11, Blocks.air, 0, 2);
            world.setBlock(chunkX + 4, y + 4, chunkZ + 11, Blocks.air, 0, 2);
            world.setBlock(chunkX + 5, y + 4, chunkZ + 11, Blocks.air, 0, 2);
            world.setBlock(chunkX + 6, y + 4, chunkZ + 11, Blocks.air, 0, 2);
            world.setBlock(chunkX + 7, y + 4, chunkZ + 11, Blocks.air, 0, 2);
            world.setBlock(chunkX + 8, y + 4, chunkZ + 11, Blocks.air, 0, 2);
            world.setBlock(chunkX + 9, y + 4, chunkZ + 11, Blocks.air, 0, 2);
            world.setBlock(chunkX + 10, y + 4, chunkZ + 11, Blocks.air, 0, 2);
            world.setBlock(chunkX + 11, y + 4, chunkZ + 11, Blocks.air, 0, 2);
            world.setBlock(chunkX + 12, y + 4, chunkZ + 11, Blocks.air, 0, 2);
            world.setBlock(chunkX + 13, y + 4, chunkZ + 11, Blocks.air, 0, 2);
            world.setBlock(chunkX + 14, y + 4, chunkZ + 11, Blocks.air, 0, 2);
            world.setBlock(chunkX + 15, y + 4, chunkZ + 11, Blocks.stone, 0, 2);
            world.setBlock(chunkX + 16, y + 4, chunkZ + 11, Main.sepiaBrick, 0, 2);
            world.setBlock(chunkX + 0, y + 4, chunkZ + 12, Blocks.air, 0, 2);
            world.setBlock(chunkX + 1, y + 4, chunkZ + 12, Main.sepiaBrick, 0, 2);
            world.setBlock(chunkX + 2, y + 4, chunkZ + 12, Blocks.stone, 0, 2);
            world.setBlock(chunkX + 3, y + 4, chunkZ + 12, Blocks.air, 0, 2);
            world.setBlock(chunkX + 4, y + 4, chunkZ + 12, Blocks.air, 0, 2);
            world.setBlock(chunkX + 5, y + 4, chunkZ + 12, Blocks.air, 0, 2);
            world.setBlock(chunkX + 6, y + 4, chunkZ + 12, Blocks.air, 0, 2);
            world.setBlock(chunkX + 7, y + 4, chunkZ + 12, Blocks.air, 0, 2);
            world.setBlock(chunkX + 8, y + 4, chunkZ + 12, Blocks.air, 0, 2);
            world.setBlock(chunkX + 9, y + 4, chunkZ + 12, Blocks.air, 0, 2);
