package apocalypse.fandomcraft.structures;

import net.minecraft.world.*;
import java.util.*;
import net.minecraft.world.biome.*;
import net.minecraft.init.*;
import apocalypse.fandomcraft.main.*;
import net.minecraft.tileentity.*;
import net.minecraftforge.common.*;
import net.minecraft.util.*;
import net.minecraft.inventory.*;
import net.minecraft.world.gen.structure.*;
import net.minecraft.nbt.*;

public class DungeonDekuTree extends StructureComponent
{
    public void generateSurface(final World world, final Random random, final int chunkX, final int chunkZ, final int chunkY) {
        final int j = world.getHeightValue(chunkX, chunkZ) - 3;
        if ((world.getBiomeGenForCoords(chunkX, chunkZ).biomeName.equals(BiomeGenBase.plains.biomeName) || world.getBiomeGenForCoords(chunkX, chunkZ).biomeName.equals(BiomeGenBase.savanna.biomeName)) && random.nextInt(10) + 1 <= 9) {
            boolean place = true;
            for (int y = 0; y < 11; ++y) {
                for (int z = 0; z < 13; ++z) {
                    for (int x = 0; x < 9; ++x) {
                        place = (world.getBlock(chunkX + x, j + y + 1, chunkZ + z) == Blocks.air || world.getBlock(chunkX + x, j + y + 1, chunkZ + z) == Blocks.tallgrass);
                    }
                }
            }
            if (place) {
                world.setBlock(chunkX + 6, j - 5, chunkZ + 6, Blocks.log, 1, 2);
                world.setBlock(chunkX + 7, j - 5, chunkZ + 6, Blocks.log, 1, 2);
                world.setBlock(chunkX + 8, j - 5, chunkZ + 6, Blocks.log, 1, 2);
                world.setBlock(chunkX + 5, j - 5, chunkZ + 7, Blocks.log, 1, 2);
                world.setBlock(chunkX + 6, j - 5, chunkZ + 7, Main.RockStone, 0, 2);
                world.setBlock(chunkX + 7, j - 5, chunkZ + 7, Main.RockStone, 0, 2);
                world.setBlock(chunkX + 8, j - 5, chunkZ + 7, Main.RockStone, 0, 2);
                world.setBlock(chunkX + 9, j - 5, chunkZ + 7, Blocks.log, 1, 2);
                world.setBlock(chunkX + 4, j - 5, chunkZ + 8, Blocks.log, 1, 2);
                world.setBlock(chunkX + 5, j - 5, chunkZ + 8, Main.RockStone, 0, 2);
                world.setBlock(chunkX + 6, j - 5, chunkZ + 8, Main.RockStone, 0, 2);
                world.setBlock(chunkX + 7, j - 5, chunkZ + 8, Main.RockStone, 0, 2);
                world.setBlock(chunkX + 8, j - 5, chunkZ + 8, Main.RockStone, 0, 2);
                world.setBlock(chunkX + 9, j - 5, chunkZ + 8, Main.RockStone, 0, 2);
                world.setBlock(chunkX + 10, j - 5, chunkZ + 8, Blocks.log, 1, 2);
                world.setBlock(chunkX + 3, j - 5, chunkZ + 9, Blocks.log, 1, 2);
                world.setBlock(chunkX + 4, j - 5, chunkZ + 9, Main.RockStone, 0, 2);
                world.setBlock(chunkX + 5, j - 5, chunkZ + 9, Main.RockStone, 0, 2);
                world.setBlock(chunkX + 6, j - 5, chunkZ + 9, Main.RockStone, 0, 2);
                world.setBlock(chunkX + 7, j - 5, chunkZ + 9, Main.RockStone, 0, 2);
                world.setBlock(chunkX + 8, j - 5, chunkZ + 9, Main.RockStone, 0, 2);
                world.setBlock(chunkX + 9, j - 5, chunkZ + 9, Main.RockStone, 0, 2);
                world.setBlock(chunkX + 10, j - 5, chunkZ + 9, Main.RockStone, 0, 2);
                world.setBlock(chunkX + 11, j - 5, chunkZ + 9, Blocks.log, 1, 2);
                world.setBlock(chunkX + 3, j - 5, chunkZ + 10, Blocks.log, 1, 2);
                world.setBlock(chunkX + 4, j - 5, chunkZ + 10, Main.RockStone, 0, 2);
                world.setBlock(chunkX + 5, j - 5, chunkZ + 10, Main.RockStone, 0, 2);
                world.setBlock(chunkX + 6, j - 5, chunkZ + 10, Main.RockStone, 0, 2);
                world.setBlock(chunkX + 6, j - 4, chunkZ + 6, Blocks.log, 1, 2);
                world.setBlock(chunkX + 7, j - 4, chunkZ + 6, Blocks.log, 1, 2);
                world.setBlock(chunkX + 8, j - 4, chunkZ + 6, Blocks.log, 1, 2);
                world.setBlock(chunkX + 5, j - 4, chunkZ + 7, Blocks.log, 1, 2);
                world.setBlock(chunkX + 6, j - 4, chunkZ + 7, Main.RockStone, 0, 2);
                world.setBlock(chunkX + 7, j - 4, chunkZ + 7, Main.RockStone, 0, 2);
                world.setBlock(chunkX + 8, j - 4, chunkZ + 7, Main.RockStone, 0, 2);
                world.setBlock(chunkX + 9, j - 4, chunkZ + 7, Blocks.log, 1, 2);
                world.setBlock(chunkX + 4, j - 4, chunkZ + 8, Blocks.log, 1, 2);
                world.setBlock(chunkX + 5, j - 4, chunkZ + 8, Main.RockStone, 0, 2);
                world.setBlock(chunkX + 6, j - 4, chunkZ + 8, Main.RockStone, 0, 2);
                world.setBlock(chunkX + 7, j - 4, chunkZ + 8, Main.RockStone, 0, 2);
                world.setBlock(chunkX + 8, j - 4, chunkZ + 8, Main.RockStone, 0, 2);
                world.setBlock(chunkX + 9, j - 4, chunkZ + 8, Main.RockStone, 0, 2);
                world.setBlock(chunkX + 10, j - 4, chunkZ + 8, Blocks.log, 1, 2);
                world.setBlock(chunkX + 3, j - 4, chunkZ + 9, Blocks.log, 1, 2);
                world.setBlock(chunkX + 4, j - 4, chunkZ + 9, Main.RockStone, 0, 2);
                world.setBlock(chunkX + 5, j - 4, chunkZ + 9, Main.RockStone, 0, 2);
                world.setBlock(chunkX + 6, j - 4, chunkZ + 9, Main.RockStone, 0, 2);
                world.setBlock(chunkX + 7, j - 4, chunkZ + 9, Main.RockStone, 0, 2);
                world.setBlock(chunkX + 8, j - 4, chunkZ + 9, Main.RockStone, 0, 2);
                world.setBlock(chunkX + 9, j - 4, chunkZ + 9, Main.RockStone, 0, 2);
                world.setBlock(chunkX + 10, j - 4, chunkZ + 9, Main.RockStone, 0, 2);
                world.setBlock(chunkX + 11, j - 4, chunkZ + 9, Blocks.log, 1, 2);
                world.setBlock(chunkX + 3, j - 4, chunkZ + 10, Blocks.log, 1, 2);
                world.setBlock(chunkX + 4, j - 4, chunkZ + 10, Main.RockStone, 0, 2);
                world.setBlock(chunkX + 5, j - 4, chunkZ + 10, Main.RockStone, 0, 2);
                world.setBlock(chunkX + 6, j - 4, chunkZ + 10, Main.RockStone, 0, 2);
                world.setBlock(chunkX + 6, j - 3, chunkZ + 6, Blocks.log, 1, 2);
                world.setBlock(chunkX + 7, j - 3, chunkZ + 6, Blocks.log, 1, 2);
                world.setBlock(chunkX + 8, j - 3, chunkZ + 6, Blocks.log, 1, 2);
                world.setBlock(chunkX + 5, j - 3, chunkZ + 7, Blocks.log, 1, 2);
                world.setBlock(chunkX + 6, j - 3, chunkZ + 7, Main.RockStone, 0, 2);
                world.setBlock(chunkX + 7, j - 3, chunkZ + 7, Main.RockStone, 0, 2);
                world.setBlock(chunkX + 8, j - 3, chunkZ + 7, Main.RockStone, 0, 2);
                world.setBlock(chunkX + 9, j - 3, chunkZ + 7, Blocks.log, 1, 2);
                world.setBlock(chunkX + 4, j - 3, chunkZ + 8, Blocks.log, 1, 2);
                world.setBlock(chunkX + 5, j - 3, chunkZ + 8, Main.RockStone, 0, 2);
                world.setBlock(chunkX + 6, j - 3, chunkZ + 8, Main.RockStone, 0, 2);
                world.setBlock(chunkX + 7, j - 3, chunkZ + 8, Main.RockStone, 0, 2);
                world.setBlock(chunkX + 8, j - 3, chunkZ + 8, Main.RockStone, 0, 2);
                world.setBlock(chunkX + 9, j - 3, chunkZ + 8, Main.RockStone, 0, 2);
                world.setBlock(chunkX + 10, j - 3, chunkZ + 8, Blocks.log, 1, 2);
                world.setBlock(chunkX + 3, j - 3, chunkZ + 9, Blocks.log, 1, 2);
                world.setBlock(chunkX + 4, j - 3, chunkZ + 9, Main.RockStone, 0, 2);
                world.setBlock(chunkX + 5, j - 3, chunkZ + 9, Main.RockStone, 0, 2);
                world.setBlock(chunkX + 6, j - 3, chunkZ + 9, Main.RockStone, 0, 2);
                world.setBlock(chunkX + 7, j - 3, chunkZ + 9, Main.RockStone, 0, 2);
                world.setBlock(chunkX + 8, j - 3, chunkZ + 9, Main.RockStone, 0, 2);
                world.setBlock(chunkX + 9, j - 3, chunkZ + 9, Main.RockStone, 0, 2);
                world.setBlock(chunkX + 10, j - 3, chunkZ + 9, Main.RockStone, 0, 2);
                world.setBlock(chunkX + 11, j - 3, chunkZ + 9, Blocks.log, 1, 2);
                world.setBlock(chunkX + 3, j - 3, chunkZ + 10, Blocks.log, 1, 2);
                world.setBlock(chunkX + 4, j - 3, chunkZ + 10, Main.RockStone, 0, 2);
                world.setBlock(chunkX + 5, j - 3, chunkZ + 10, Main.RockStone, 0, 2);
                world.setBlock(chunkX + 6, j - 3, chunkZ + 10, Main.RockStone, 0, 2);
                world.setBlock(chunkX + 6, j - 2, chunkZ + 6, Blocks.log, 1, 2);
                world.setBlock(chunkX + 7, j - 2, chunkZ + 6, Blocks.log, 1, 2);
                world.setBlock(chunkX + 8, j - 2, chunkZ + 6, Blocks.log, 1, 2);
                world.setBlock(chunkX + 5, j - 2, chunkZ + 7, Blocks.log, 1, 2);
                world.setBlock(chunkX + 6, j - 2, chunkZ + 7, Main.RockStone, 0, 2);
                world.setBlock(chunkX + 7, j - 2, chunkZ + 7, Main.RockStone, 0, 2);
                world.setBlock(chunkX + 8, j - 2, chunkZ + 7, Main.RockStone, 0, 2);
                world.setBlock(chunkX + 9, j - 2, chunkZ + 7, Blocks.log, 1, 2);
                world.setBlock(chunkX + 4, j - 2, chunkZ + 8, Blocks.log, 1, 2);
                world.setBlock(chunkX + 5, j - 2, chunkZ + 8, Main.RockStone, 0, 2);
                world.setBlock(chunkX + 6, j - 2, chunkZ + 8, Main.RockStone, 0, 2);
                world.setBlock(chunkX + 7, j - 2, chunkZ + 8, Main.RockStone, 0, 2);
                world.setBlock(chunkX + 8, j - 2, chunkZ + 8, Main.RockStone, 0, 2);
                world.setBlock(chunkX + 9, j - 2, chunkZ + 8, Main.RockStone, 0, 2);
                world.setBlock(chunkX + 10, j - 2, chunkZ + 8, Blocks.log, 1, 2);
                world.setBlock(chunkX + 3, j - 2, chunkZ + 9, Blocks.log, 1, 2);
                world.setBlock(chunkX + 4, j - 2, chunkZ + 9, Main.RockStone, 0, 2);
                world.setBlock(chunkX + 5, j - 2, chunkZ + 9, Main.RockStone, 0, 2);
                world.setBlock(chunkX + 6, j - 2, chunkZ + 9, Main.RockStone, 0, 2);
                world.setBlock(chunkX + 7, j - 2, chunkZ + 9, Main.RockStone, 0, 2);
                world.setBlock(chunkX + 8, j - 2, chunkZ + 9, Main.RockStone, 0, 2);
                world.setBlock(chunkX + 9, j - 2, chunkZ + 9, Main.RockStone, 0, 2);
                world.setBlock(chunkX + 10, j - 2, chunkZ + 9, Main.RockStone, 0, 2);
                world.setBlock(chunkX + 11, j - 2, chunkZ + 9, Blocks.log, 1, 2);
                world.setBlock(chunkX + 3, j - 2, chunkZ + 10, Blocks.log, 1, 2);
                world.setBlock(chunkX + 4, j - 2, chunkZ + 10, Main.RockStone, 0, 2);
                world.setBlock(chunkX + 5, j - 2, chunkZ + 10, Main.RockStone, 0, 2);
                world.setBlock(chunkX + 6, j - 2, chunkZ + 10, Main.RockStone, 0, 2);
                world.setBlock(chunkX + 6, j - 1, chunkZ + 6, Blocks.log, 1, 2);
                world.setBlock(chunkX + 7, j - 1, chunkZ + 6, Blocks.log, 1, 2);
                world.setBlock(chunkX + 8, j - 1, chunkZ + 6, Blocks.log, 1, 2);
                world.setBlock(chunkX + 5, j - 1, chunkZ + 7, Blocks.log, 1, 2);
                world.setBlock(chunkX + 6, j - 1, chunkZ + 7, Main.RockStone, 0, 2);
                world.setBlock(chunkX + 7, j - 1, chunkZ + 7, Main.RockStone, 0, 2);
                world.setBlock(chunkX + 8, j - 1, chunkZ + 7, Main.RockStone, 0, 2);
                world.setBlock(chunkX + 9, j - 1, chunkZ + 7, Blocks.log, 1, 2);
                world.setBlock(chunkX + 4, j - 1, chunkZ + 8, Blocks.log, 1, 2);
                world.setBlock(chunkX + 5, j - 1, chunkZ + 8, Main.RockStone, 0, 2);
                world.setBlock(chunkX + 6, j - 1, chunkZ + 8, Main.RockStone, 0, 2);
                world.setBlock(chunkX + 7, j - 1, chunkZ + 8, Main.RockStone, 0, 2);
                world.setBlock(chunkX + 8, j - 1, chunkZ + 8, Main.RockStone, 0, 2);
                world.setBlock(chunkX + 9, j - 1, chunkZ + 8, Main.RockStone, 0, 2);
                world.setBlock(chunkX + 10, j - 1, chunkZ + 8, Blocks.log, 1, 2);
                world.setBlock(chunkX + 3, j - 1, chunkZ + 9, Blocks.log, 1, 2);
                world.setBlock(chunkX + 4, j - 1, chunkZ + 9, Main.RockStone, 0, 2);
                world.setBlock(chunkX + 5, j - 1, chunkZ + 9, Main.RockStone, 0, 2);
                world.setBlock(chunkX + 6, j - 1, chunkZ + 9, Main.RockStone, 0, 2);
                world.setBlock(chunkX + 7, j - 1, chunkZ + 9, Main.RockStone, 0, 2);
                world.setBlock(chunkX + 8, j - 1, chunkZ + 9, Main.RockStone, 0, 2);
                world.setBlock(chunkX + 9, j - 1, chunkZ + 9, Main.RockStone, 0, 2);
                world.setBlock(chunkX + 10, j - 1, chunkZ + 9, Main.RockStone, 0, 2);
                world.setBlock(chunkX + 11, j - 1, chunkZ + 9, Blocks.log, 1, 2);
                world.setBlock(chunkX + 3, j - 1, chunkZ + 10, Blocks.log, 1, 2);
                world.setBlock(chunkX + 4, j - 1, chunkZ + 10, Main.RockStone, 0, 2);
                world.setBlock(chunkX + 5, j - 1, chunkZ + 10, Main.RockStone, 0, 2);
                world.setBlock(chunkX + 6, j - 1, chunkZ + 10, Main.RockStone, 0, 2);
                world.setBlock(chunkX + 6, j + 0, chunkZ + 6, Blocks.log, 1, 2);
                world.setBlock(chunkX + 7, j + 0, chunkZ + 6, Blocks.log, 1, 2);
                world.setBlock(chunkX + 8, j + 0, chunkZ + 6, Blocks.log, 1, 2);
                world.setBlock(chunkX + 5, j + 0, chunkZ + 7, Blocks.log, 1, 2);
                world.setBlock(chunkX + 6, j + 0, chunkZ + 7, Main.RockStone, 0, 2);
                world.setBlock(chunkX + 7, j + 0, chunkZ + 7, Main.RockStone, 0, 2);
                world.setBlock(chunkX + 8, j + 0, chunkZ + 7, Main.RockStone, 0, 2);
                world.setBlock(chunkX + 9, j + 0, chunkZ + 7, Blocks.log, 1, 2);
                world.setBlock(chunkX + 4, j + 0, chunkZ + 8, Blocks.log, 1, 2);
                world.setBlock(chunkX + 5, j + 0, chunkZ + 8, Main.RockStone, 0, 2);
                world.setBlock(chunkX + 6, j + 0, chunkZ + 8, Main.RockStone, 0, 2);
                world.setBlock(chunkX + 7, j + 0, chunkZ + 8, Main.RockStone, 0, 2);
                world.setBlock(chunkX + 8, j + 0, chunkZ + 8, Main.RockStone, 0, 2);
                world.setBlock(chunkX + 9, j + 0, chunkZ + 8, Main.RockStone, 0, 2);
                world.setBlock(chunkX + 10, j + 0, chunkZ + 8, Blocks.log, 1, 2);
                world.setBlock(chunkX + 3, j + 0, chunkZ + 9, Blocks.log, 1, 2);
                world.setBlock(chunkX + 4, j + 0, chunkZ + 9, Main.RockStone, 0, 2);
                world.setBlock(chunkX + 5, j + 0, chunkZ + 9, Main.RockStone, 0, 2);
                world.setBlock(chunkX + 6, j + 0, chunkZ + 9, Main.RockStone, 0, 2);
                world.setBlock(chunkX + 7, j + 0, chunkZ + 9, Main.RockStone, 0, 2);
                world.setBlock(chunkX + 8, j + 0, chunkZ + 9, Main.RockStone, 0, 2);
                world.setBlock(chunkX + 9, j + 0, chunkZ + 9, Main.RockStone, 0, 2);
                world.setBlock(chunkX + 10, j + 0, chunkZ + 9, Main.RockStone, 0, 2);
                world.setBlock(chunkX + 11, j + 0, chunkZ + 9, Blocks.log, 1, 2);
                world.setBlock(chunkX + 3, j + 0, chunkZ + 10, Blocks.log, 1, 2);
                world.setBlock(chunkX + 4, j + 0, chunkZ + 10, Main.RockStone, 0, 2);
                world.setBlock(chunkX + 5, j + 0, chunkZ + 10, Main.RockStone, 0, 2);
                world.setBlock(chunkX + 6, j + 0, chunkZ + 10, Main.RockStone, 0, 2);
                world.setBlock(chunkX + 7, j + 0, chunkZ + 10, Blocks.mob_spawner, 0, 2);
                final int x2 = chunkX + 7;
                final int y2 = j + 0;
                final int z2 = chunkZ + 10;
                final TileEntityMobSpawner tileentitymobspawner = (TileEntityMobSpawner)world.getTileEntity(x2, y2, z2);
                if (tileentitymobspawner != null) {
                    tileentitymobspawner.func_145881_a().setEntityName("Spider");
                }
                else {
                    System.err.println("Failed to fetch mob spawner entity at (" + x2 + ", " + y2 + ", " + z2 + ")");
                }
                world.setBlock(chunkX + 8, j - 5, chunkZ + 10, Main.RockStone, 0, 2);
                world.setBlock(chunkX + 9, j - 5, chunkZ + 10, Main.RockStone, 0, 2);
                world.setBlock(chunkX + 10, j - 5, chunkZ + 10, Main.RockStone, 0, 2);
                world.setBlock(chunkX + 11, j - 5, chunkZ + 10, Blocks.log, 1, 2);
                world.setBlock(chunkX + 3, j - 5, chunkZ + 11, Blocks.log, 1, 2);
                world.setBlock(chunkX + 4, j - 5, chunkZ + 11, Main.RockStone, 0, 2);
                world.setBlock(chunkX + 5, j - 5, chunkZ + 11, Main.RockStone, 0, 2);
                world.setBlock(chunkX + 6, j - 5, chunkZ + 11, Main.RockStone, 0, 2);
                world.setBlock(chunkX + 7, j - 5, chunkZ + 11, Main.RockStone, 0, 2);
                world.setBlock(chunkX + 8, j - 5, chunkZ + 11, Main.RockStone, 0, 2);
                world.setBlock(chunkX + 9, j - 5, chunkZ + 11, Main.RockStone, 0, 2);
                world.setBlock(chunkX + 10, j - 5, chunkZ + 11, Main.RockStone, 0, 2);
                world.setBlock(chunkX + 11, j - 5, chunkZ + 11, Blocks.log, 1, 2);
                world.setBlock(chunkX + 4, j - 5, chunkZ + 12, Blocks.log, 1, 2);
                world.setBlock(chunkX + 5, j - 5, chunkZ + 12, Main.RockStone, 0, 2);
                world.setBlock(chunkX + 6, j - 5, chunkZ + 12, Main.RockStone, 0, 2);
                world.setBlock(chunkX + 7, j - 5, chunkZ + 12, Main.RockStone, 0, 2);
                world.setBlock(chunkX + 8, j - 5, chunkZ + 12, Main.RockStone, 0, 2);
                world.setBlock(chunkX + 9, j - 5, chunkZ + 12, Main.RockStone, 0, 2);
                world.setBlock(chunkX + 10, j - 5, chunkZ + 12, Blocks.log, 1, 2);
                world.setBlock(chunkX + 5, j - 5, chunkZ + 13, Blocks.log, 1, 2);
                world.setBlock(chunkX + 6, j - 5, chunkZ + 13, Main.RockStone, 0, 2);
                world.setBlock(chunkX + 7, j - 5, chunkZ + 13, Main.RockStone, 0, 2);
                world.setBlock(chunkX + 8, j - 5, chunkZ + 13, Main.RockStone, 0, 2);
                world.setBlock(chunkX + 9, j - 5, chunkZ + 13, Blocks.log, 1, 2);
                world.setBlock(chunkX + 6, j - 5, chunkZ + 14, Blocks.log, 1, 2);
                world.setBlock(chunkX + 7, j - 5, chunkZ + 14, Blocks.log, 1, 2);
                world.setBlock(chunkX + 8, j - 5, chunkZ + 14, Blocks.log, 1, 2);
                world.setBlock(chunkX + 8, j - 4, chunkZ + 10, Main.RockStone, 0, 2);
                world.setBlock(chunkX + 9, j - 4, chunkZ + 10, Main.RockStone, 0, 2);
                world.setBlock(chunkX + 10, j - 4, chunkZ + 10, Main.RockStone, 0, 2);
                world.setBlock(chunkX + 11, j - 4, chunkZ + 10, Blocks.log, 1, 2);
                world.setBlock(chunkX + 3, j - 4, chunkZ + 11, Blocks.log, 1, 2);
                world.setBlock(chunkX + 4, j - 4, chunkZ + 11, Main.RockStone, 0, 2);
                world.setBlock(chunkX + 5, j - 4, chunkZ + 11, Main.RockStone, 0, 2);
                world.setBlock(chunkX + 6, j - 4, chunkZ + 11, Main.RockStone, 0, 2);
                world.setBlock(chunkX + 7, j - 4, chunkZ + 11, Main.RockStone, 0, 2);
                world.setBlock(chunkX + 8, j - 4, chunkZ + 11, Main.RockStone, 0, 2);
                world.setBlock(chunkX + 9, j - 4, chunkZ + 11, Main.RockStone, 0, 2);
                world.setBlock(chunkX + 10, j - 4, chunkZ + 11, Main.RockStone, 0, 2);
                world.setBlock(chunkX + 11, j - 4, chunkZ + 11, Blocks.log, 1, 2);
                world.setBlock(chunkX + 4, j - 4, chunkZ + 12, Blocks.log, 1, 2);
                world.setBlock(chunkX + 5, j - 4, chunkZ + 12, Main.RockStone, 0, 2);
                world.setBlock(chunkX + 6, j - 4, chunkZ + 12, Main.RockStone, 0, 2);
                world.setBlock(chunkX + 7, j - 4, chunkZ + 12, Main.RockStone, 0, 2);
                world.setBlock(chunkX + 8, j - 4, chunkZ + 12, Main.RockStone, 0, 2);
                world.setBlock(chunkX + 9, j - 4, chunkZ + 12, Main.RockStone, 0, 2);
                world.setBlock(chunkX + 10, j - 4, chunkZ + 12, Blocks.log, 1, 2);
                world.setBlock(chunkX + 5, j - 4, chunkZ + 13, Blocks.log, 1, 2);
                world.setBlock(chunkX + 6, j - 4, chunkZ + 13, Main.RockStone, 0, 2);
                world.setBlock(chunkX + 7, j - 4, chunkZ + 13, Main.RockStone, 0, 2);
                world.setBlock(chunkX + 8, j - 4, chunkZ + 13, Main.RockStone, 0, 2);
                world.setBlock(chunkX + 9, j - 4, chunkZ + 13, Blocks.log, 1, 2);
                world.setBlock(chunkX + 6, j - 4, chunkZ + 14, Blocks.log, 1, 2);
                world.setBlock(chunkX + 7, j - 4, chunkZ + 14, Blocks.log, 1, 2);
                world.setBlock(chunkX + 8, j - 4, chunkZ + 14, Blocks.log, 1, 2);
                world.setBlock(chunkX + 8, j - 3, chunkZ + 10, Main.RockStone, 0, 2);
                world.setBlock(chunkX + 9, j - 3, chunkZ + 10, Main.RockStone, 0, 2);
                world.setBlock(chunkX + 10, j - 3, chunkZ + 10, Main.RockStone, 0, 2);
                world.setBlock(chunkX + 11, j - 3, chunkZ + 10, Blocks.log, 1, 2);
                world.setBlock(chunkX + 3, j - 3, chunkZ + 11, Blocks.log, 1, 2);
                world.setBlock(chunkX + 4, j - 3, chunkZ + 11, Main.RockStone, 0, 2);
                world.setBlock(chunkX + 5, j - 3, chunkZ + 11, Main.RockStone, 0, 2);
                world.setBlock(chunkX + 6, j - 3, chunkZ + 11, Main.RockStone, 0, 2);
                world.setBlock(chunkX + 7, j - 3, chunkZ + 11, Main.RockStone, 0, 2);
                world.setBlock(chunkX + 8, j - 3, chunkZ + 11, Main.RockStone, 0, 2);
                world.setBlock(chunkX + 9, j - 3, chunkZ + 11, Main.RockStone, 0, 2);
                world.setBlock(chunkX + 10, j - 3, chunkZ + 11, Main.RockStone, 0, 2);
                world.setBlock(chunkX + 11, j - 3, chunkZ + 11, Blocks.log, 1, 2);
                world.setBlock(chunkX + 4, j - 3, chunkZ + 12, Blocks.log, 1, 2);
                world.setBlock(chunkX + 5, j - 3, chunkZ + 12, Main.RockStone, 0, 2);
                world.setBlock(chunkX + 6, j - 3, chunkZ + 12, Main.RockStone, 0, 2);
                world.setBlock(chunkX + 7, j - 3, chunkZ + 12, Main.RockStone, 0, 2);
                world.setBlock(chunkX + 8, j - 3, chunkZ + 12, Main.RockStone, 0, 2);
                world.setBlock(chunkX + 9, j - 3, chunkZ + 12, Main.RockStone, 0, 2);
                world.setBlock(chunkX + 10, j - 3, chunkZ + 12, Blocks.log, 1, 2);
                world.setBlock(chunkX + 5, j - 3, chunkZ + 13, Blocks.log, 1, 2);
                world.setBlock(chunkX + 6, j - 3, chunkZ + 13, Main.RockStone, 0, 2);
                world.setBlock(chunkX + 7, j - 3, chunkZ + 13, Main.RockStone, 0, 2);
                world.setBlock(chunkX + 8, j - 3, chunkZ + 13, Main.RockStone, 0, 2);
                world.setBlock(chunkX + 9, j - 3, chunkZ + 13, Blocks.log, 1, 2);
                world.setBlock(chunkX + 6, j - 3, chunkZ + 14, Blocks.log, 1, 2);
                world.setBlock(chunkX + 7, j - 3, chunkZ + 14, Blocks.log, 1, 2);
                world.setBlock(chunkX + 8, j - 3, chunkZ + 14, Blocks.log, 1, 2);
                world.setBlock(chunkX + 8, j - 2, chunkZ + 10, Main.RockStone, 0, 2);
                world.setBlock(chunkX + 9, j - 2, chunkZ + 10, Main.RockStone, 0, 2);
                world.setBlock(chunkX + 10, j - 2, chunkZ + 10, Main.RockStone, 0, 2);
                world.setBlock(chunkX + 11, j - 2, chunkZ + 10, Blocks.log, 1, 2);
                world.setBlock(chunkX + 3, j - 2, chunkZ + 11, Blocks.log, 1, 2);
                world.setBlock(chunkX + 4, j - 2, chunkZ + 11, Main.RockStone, 0, 2);
                world.setBlock(chunkX + 5, j - 2, chunkZ + 11, Main.RockStone, 0, 2);
                world.setBlock(chunkX + 6, j - 2, chunkZ + 11, Main.RockStone, 0, 2);
                world.setBlock(chunkX + 7, j - 2, chunkZ + 11, Main.RockStone, 0, 2);
                world.setBlock(chunkX + 8, j - 2, chunkZ + 11, Main.RockStone, 0, 2);
                world.setBlock(chunkX + 9, j - 2, chunkZ + 11, Main.RockStone, 0, 2);
                world.setBlock(chunkX + 10, j - 2, chunkZ + 11, Main.RockStone, 0, 2);
                world.setBlock(chunkX + 11, j - 2, chunkZ + 11, Blocks.log, 1, 2);
                world.setBlock(chunkX + 4, j - 2, chunkZ + 12, Blocks.log, 1, 2);
                world.setBlock(chunkX + 5, j - 2, chunkZ + 12, Main.RockStone, 0, 2);
                world.setBlock(chunkX + 6, j - 2, chunkZ + 12, Main.RockStone, 0, 2);
                world.setBlock(chunkX + 7, j - 2, chunkZ + 12, Main.RockStone, 0, 2);
                world.setBlock(chunkX + 8, j - 2, chunkZ + 12, Main.RockStone, 0, 2);
                world.setBlock(chunkX + 9, j - 2, chunkZ + 12, Main.RockStone, 0, 2);
                world.setBlock(chunkX + 10, j - 2, chunkZ + 12, Blocks.log, 1, 2);
                world.setBlock(chunkX + 5, j - 2, chunkZ + 13, Blocks.log, 1, 2);
                world.setBlock(chunkX + 6, j - 2, chunkZ + 13, Main.RockStone, 0, 2);
                world.setBlock(chunkX + 7, j - 2, chunkZ + 13, Main.RockStone, 0, 2);
                world.setBlock(chunkX + 8, j - 2, chunkZ + 13, Main.RockStone, 0, 2);
                world.setBlock(chunkX + 9, j - 2, chunkZ + 13, Blocks.log, 1, 2);
                world.setBlock(chunkX + 6, j - 2, chunkZ + 14, Blocks.log, 1, 2);
                world.setBlock(chunkX + 7, j - 2, chunkZ + 14, Blocks.log, 1, 2);
                world.setBlock(chunkX + 8, j - 2, chunkZ + 14, Blocks.log, 1, 2);
                world.setBlock(chunkX + 8, j - 1, chunkZ + 10, Main.RockStone, 0, 2);
                world.setBlock(chunkX + 9, j - 1, chunkZ + 10, Main.RockStone, 0, 2);
                world.setBlock(chunkX + 10, j - 1, chunkZ + 10, Main.RockStone, 0, 2);
                world.setBlock(chunkX + 11, j - 1, chunkZ + 10, Blocks.log, 1, 2);
                world.setBlock(chunkX + 3, j - 1, chunkZ + 11, Blocks.log, 1, 2);
                world.setBlock(chunkX + 4, j - 1, chunkZ + 11, Main.RockStone, 0, 2);
                world.setBlock(chunkX + 5, j - 1, chunkZ + 11, Main.RockStone, 0, 2);
                world.setBlock(chunkX + 6, j - 1, chunkZ + 11, Main.RockStone, 0, 2);
                world.setBlock(chunkX + 7, j - 1, chunkZ + 11, Main.RockStone, 0, 2);
                world.setBlock(chunkX + 8, j - 1, chunkZ + 11, Main.RockStone, 0, 2);
                world.setBlock(chunkX + 9, j - 1, chunkZ + 11, Main.RockStone, 0, 2);
                world.setBlock(chunkX + 10, j - 1, chunkZ + 11, Main.RockStone, 0, 2);
                world.setBlock(chunkX + 11, j - 1, chunkZ + 11, Blocks.log, 1, 2);
                world.setBlock(chunkX + 4, j - 1, chunkZ + 12, Blocks.log, 1, 2);
                world.setBlock(chunkX + 5, j - 1, chunkZ + 12, Main.RockStone, 0, 2);
                world.setBlock(chunkX + 6, j - 1, chunkZ + 12, Main.RockStone, 0, 2);
                world.setBlock(chunkX + 7, j - 1, chunkZ + 12, Main.RockStone, 0, 2);
                world.setBlock(chunkX + 8, j - 1, chunkZ + 12, Main.RockStone, 0, 2);
                world.setBlock(chunkX + 9, j - 1, chunkZ + 12, Main.RockStone, 0, 2);
                world.setBlock(chunkX + 10, j - 1, chunkZ + 12, Blocks.log, 1, 2);
                world.setBlock(chunkX + 5, j - 1, chunkZ + 13, Blocks.log, 1, 2);
                world.setBlock(chunkX + 6, j - 1, chunkZ + 13, Main.RockStone, 0, 2);
                world.setBlock(chunkX + 7, j - 1, chunkZ + 13, Main.RockStone, 0, 2);
                world.setBlock(chunkX + 8, j - 1, chunkZ + 13, Main.RockStone, 0, 2);
                world.setBlock(chunkX + 9, j - 1, chunkZ + 13, Blocks.log, 1, 2);
                world.setBlock(chunkX + 6, j - 1, chunkZ + 14, Blocks.log, 1, 2);
                world.setBlock(chunkX + 7, j - 1, chunkZ + 14, Blocks.log, 1, 2);
                world.setBlock(chunkX + 8, j - 1, chunkZ + 14, Blocks.log, 1, 2);
                world.setBlock(chunkX + 8, j + 0, chunkZ + 10, Main.RockStone, 0, 2);
                world.setBlock(chunkX + 9, j + 0, chunkZ + 10, Main.RockStone, 0, 2);
                world.setBlock(chunkX + 10, j + 0, chunkZ + 10, Main.RockStone, 0, 2);
                world.setBlock(chunkX + 11, j + 0, chunkZ + 10, Blocks.log, 1, 2);
                world.setBlock(chunkX + 3, j + 0, chunkZ + 11, Blocks.log, 1, 2);
                world.setBlock(chunkX + 4, j + 0, chunkZ + 11, Main.RockStone, 0, 2);
                world.setBlock(chunkX + 5, j + 0, chunkZ + 11, Main.RockStone, 0, 2);
                world.setBlock(chunkX + 6, j + 0, chunkZ + 11, Main.RockStone, 0, 2);
                world.setBlock(chunkX + 7, j + 0, chunkZ + 11, Main.RockStone, 0, 2);
                world.setBlock(chunkX + 8, j + 0, chunkZ + 11, Main.RockStone, 0, 2);
                world.setBlock(chunkX + 9, j + 0, chunkZ + 11, Main.RockStone, 0, 2);
                world.setBlock(chunkX + 10, j + 0, chunkZ + 11, Main.RockStone, 0, 2);
                world.setBlock(chunkX + 11, j + 0, chunkZ + 11, Blocks.log, 1, 2);
                world.setBlock(chunkX + 4, j + 0, chunkZ + 12, Blocks.log, 1, 2);
                world.setBlock(chunkX + 5, j + 0, chunkZ + 12, Main.RockStone, 0, 2);
                world.setBlock(chunkX + 6, j + 0, chunkZ + 12, Main.RockStone, 0, 2);
                world.setBlock(chunkX + 7, j + 0, chunkZ + 12, Main.RockStone, 0, 2);
                world.setBlock(chunkX + 8, j + 0, chunkZ + 12, Main.RockStone, 0, 2);
                world.setBlock(chunkX + 9, j + 0, chunkZ + 12, Main.RockStone, 0, 2);
                world.setBlock(chunkX + 10, j + 0, chunkZ + 12, Blocks.log, 1, 2);
                world.setBlock(chunkX + 5, j + 0, chunkZ + 13, Blocks.log, 1, 2);
                world.setBlock(chunkX + 6, j + 0, chunkZ + 13, Main.RockStone, 0, 2);
                world.setBlock(chunkX + 7, j + 0, chunkZ + 13, Main.RockStone, 0, 2);
                world.setBlock(chunkX + 8, j + 0, chunkZ + 13, Main.RockStone, 0, 2);
                world.setBlock(chunkX + 9, j + 0, chunkZ + 13, Blocks.log, 1, 2);
                world.setBlock(chunkX + 6, j + 0, chunkZ + 14, Blocks.log, 1, 2);
                world.setBlock(chunkX + 7, j + 0, chunkZ + 14, Blocks.log, 1, 2);
                world.setBlock(chunkX + 8, j + 0, chunkZ + 14, Blocks.log, 1, 2);
                world.setBlock(chunkX + 6, j + 1, chunkZ + 6, Blocks.log, 1, 2);
                world.setBlock(chunkX + 7, j + 1, chunkZ + 6, Blocks.log, 1, 2);
                world.setBlock(chunkX + 8, j + 1, chunkZ + 6, Blocks.log, 1, 2);
                world.setBlock(chunkX + 5, j + 1, chunkZ + 7, Blocks.log, 1, 2);
                world.setBlock(chunkX + 6, j + 1, chunkZ + 7, Blocks.web, 0, 2);
                world.setBlock(chunkX + 9, j + 1, chunkZ + 7, Blocks.log, 1, 2);
                world.setBlock(chunkX + 4, j + 1, chunkZ + 8, Blocks.log, 1, 2);
                world.setBlock(chunkX + 10, j + 1, chunkZ + 8, Blocks.log, 1, 2);
                world.setBlock(chunkX + 3, j + 1, chunkZ + 9, Blocks.log, 1, 2);
                world.setBlock(chunkX + 11, j + 1, chunkZ + 9, Blocks.log, 1, 2);
                world.setBlock(chunkX + 3, j + 1, chunkZ + 10, Blocks.log, 1, 2);
                world.setBlock(chunkX + 10, j + 1, chunkZ + 10, Blocks.trapped_chest, 4, 2);
                final int xx = chunkX + 10;
                final int yy = j + 1;
                final int zz = chunkZ + 10;
                final TileEntityChest tileentitychest = (TileEntityChest)world.getTileEntity(xx, yy, zz);
                if (tileentitychest != null) {
                    WeightedRandomChestContent.generateChestContents(random, ChestGenHooks.getItems("dungeonChest", random), (IInventory)tileentitychest, ChestGenHooks.getCount("dungeonChest", random));
                }
                world.setBlock(chunkX + 11, j + 1, chunkZ + 10, Blocks.log, 1, 2);
                world.setBlock(chunkX + 3, j + 1, chunkZ + 11, Blocks.log, 1, 2);
                world.setBlock(chunkX + 10, j + 1, chunkZ + 11, Blocks.web, 0, 2);
                world.setBlock(chunkX + 11, j + 1, chunkZ + 11, Blocks.log, 1, 2);
                world.setBlock(chunkX + 4, j + 1, chunkZ + 12, Blocks.log, 1, 2);
                world.setBlock(chunkX + 5, j + 1, chunkZ + 12, Blocks.web, 0, 2);
                world.setBlock(chunkX + 10, j + 1, chunkZ + 12, Blocks.log, 1, 2);
                world.setBlock(chunkX + 5, j + 1, chunkZ + 13, Blocks.log, 1, 2);
                world.setBlock(chunkX + 9, j + 1, chunkZ + 13, Blocks.log, 1, 2);
                world.setBlock(chunkX + 6, j + 1, chunkZ + 14, Blocks.log, 1, 2);
                world.setBlock(chunkX + 7, j + 1, chunkZ + 14, Blocks.log, 1, 2);
                world.setBlock(chunkX + 8, j + 1, chunkZ + 14, Blocks.log, 1, 2);
                world.setBlock(chunkX + 0, j + 2, chunkZ + 3, Blocks.log, 1, 2);
                world.setBlock(chunkX + 1, j + 2, chunkZ + 3, Blocks.log, 1, 2);
                world.setBlock(chunkX + 6, j + 2, chunkZ + 3, Blocks.log, 1, 2);
                world.setBlock(chunkX + 0, j + 2, chunkZ + 4, Blocks.log, 1, 2);
                world.setBlock(chunkX + 3, j + 2, chunkZ + 4, Blocks.log, 1, 2);
                world.setBlock(chunkX + 5, j + 2, chunkZ + 4, Blocks.log, 1, 2);
                world.setBlock(chunkX + 5, j + 2, chunkZ + 5, Blocks.log, 1, 2);
                world.setBlock(chunkX + 9, j + 2, chunkZ + 5, Blocks.log, 1, 2);
                world.setBlock(chunkX + 1, j + 2, chunkZ + 6, Blocks.log, 1, 2);
                world.setBlock(chunkX + 6, j + 2, chunkZ + 6, Blocks.log, 1, 2);
                world.setBlock(chunkX + 7, j + 2, chunkZ + 6, Blocks.log, 1, 2);
                world.setBlock(chunkX + 8, j + 2, chunkZ + 6, Blocks.log, 1, 2);
                world.setBlock(chunkX + 10, j + 2, chunkZ + 6, Blocks.log, 1, 2);
                world.setBlock(chunkX + 5, j + 2, chunkZ + 7, Blocks.log, 1, 2);
                world.setBlock(chunkX + 9, j + 2, chunkZ + 7, Blocks.log, 1, 2);
                world.setBlock(chunkX + 4, j + 2, chunkZ + 8, Blocks.log, 1, 2);
                world.setBlock(chunkX + 10, j + 2, chunkZ + 8, Blocks.log, 1, 2);
                world.setBlock(chunkX + 3, j + 2, chunkZ + 9, Blocks.log, 1, 2);
                world.setBlock(chunkX + 11, j + 2, chunkZ + 9, Blocks.log, 1, 2);
                world.setBlock(chunkX + 3, j + 2, chunkZ + 10, Blocks.log, 1, 2);
                world.setBlock(chunkX + 11, j + 2, chunkZ + 10, Blocks.log, 1, 2);
                world.setBlock(chunkX + 1, j + 2, chunkZ + 11, Blocks.log, 1, 2);
                world.setBlock(chunkX + 3, j + 2, chunkZ + 11, Blocks.log, 1, 2);
                world.setBlock(chunkX + 11, j + 2, chunkZ + 11, Blocks.log, 1, 2);
                world.setBlock(chunkX + 2, j + 2, chunkZ + 12, Blocks.log, 1, 2);
                world.setBlock(chunkX + 4, j + 2, chunkZ + 12, Blocks.log, 1, 2);
                world.setBlock(chunkX + 10, j + 2, chunkZ + 12, Blocks.log, 1, 2);
                world.setBlock(chunkX + 2, j + 2, chunkZ + 13, Blocks.log, 1, 2);
                world.setBlock(chunkX + 3, j + 2, chunkZ + 13, Blocks.log, 1, 2);
                world.setBlock(chunkX + 5, j + 2, chunkZ + 13, Blocks.log, 1, 2);
                world.setBlock(chunkX + 9, j + 2, chunkZ + 13, Blocks.log, 1, 2);
                world.setBlock(chunkX + 12, j + 2, chunkZ + 13, Blocks.log, 1, 2);
                world.setBlock(chunkX + 3, j + 2, chunkZ + 14, Blocks.log, 1, 2);
                world.setBlock(chunkX + 6, j + 2, chunkZ + 14, Blocks.log, 1, 2);
                world.setBlock(chunkX + 7, j + 2, chunkZ + 14, Blocks.log, 1, 2);
                world.setBlock(chunkX + 8, j + 2, chunkZ + 14, Blocks.log, 1, 2);
                world.setBlock(chunkX + 12, j + 2, chunkZ + 14, Blocks.log, 1, 2);
                world.setBlock(chunkX + 13, j + 2, chunkZ + 14, Blocks.log, 1, 2);
                world.setBlock(chunkX + 13, j + 2, chunkZ + 15, Blocks.log, 1, 2);
                world.setBlock(chunkX + 12, j + 2, chunkZ + 16, Blocks.log, 1, 2);
                world.setBlock(chunkX + 13, j + 2, chunkZ + 16, Blocks.log, 1, 2);
                world.setBlock(chunkX + 13, j + 2, chunkZ + 17, Blocks.log, 1, 2);
                world.setBlock(chunkX + 2, j + 2, chunkZ + 18, Blocks.log, 1, 2);
                world.setBlock(chunkX + 7, j + 3, chunkZ + 1, Blocks.log, 1, 2);
                world.setBlock(chunkX + 7, j + 3, chunkZ + 2, Blocks.log, 1, 2);
                world.setBlock(chunkX + 7, j + 3, chunkZ + 3, Blocks.log, 1, 2);
                world.setBlock(chunkX + 8, j + 3, chunkZ + 3, Blocks.log, 1, 2);
                world.setBlock(chunkX + 1, j + 3, chunkZ + 4, Blocks.log, 1, 2);
                world.setBlock(chunkX + 2, j + 3, chunkZ + 4, Blocks.log, 1, 2);
                world.setBlock(chunkX + 6, j + 3, chunkZ + 4, Blocks.log, 1, 2);
                world.setBlock(chunkX + 7, j + 3, chunkZ + 4, Blocks.log, 1, 2);
                world.setBlock(chunkX + 8, j + 3, chunkZ + 4, Blocks.log, 1, 2);
                world.setBlock(chunkX + 1, j + 3, chunkZ + 5, Blocks.log, 1, 2);
                world.setBlock(chunkX + 2, j + 3, chunkZ + 5, Blocks.log, 1, 2);
                world.setBlock(chunkX + 3, j + 3, chunkZ + 5, Blocks.log, 1, 2);
                world.setBlock(chunkX + 4, j + 3, chunkZ + 5, Blocks.log, 1, 2);
                world.setBlock(chunkX + 6, j + 3, chunkZ + 5, Blocks.log, 1, 2);
                world.setBlock(chunkX + 7, j + 3, chunkZ + 5, Blocks.log, 1, 2);
                world.setBlock(chunkX + 8, j + 3, chunkZ + 5, Blocks.log, 1, 2);
                world.setBlock(chunkX + 9, j + 3, chunkZ + 5, Blocks.log, 1, 2);
                world.setBlock(chunkX + 2, j + 3, chunkZ + 6, Blocks.log, 1, 2);
                world.setBlock(chunkX + 3, j + 3, chunkZ + 6, Blocks.log, 1, 2);
                world.setBlock(chunkX + 4, j + 3, chunkZ + 6, Blocks.log, 1, 2);
                world.setBlock(chunkX + 5, j + 3, chunkZ + 6, Blocks.log, 1, 2);
                world.setBlock(chunkX + 6, j + 3, chunkZ + 6, Blocks.log, 1, 2);
                world.setBlock(chunkX + 7, j + 3, chunkZ + 6, Blocks.log, 1, 2);
                world.setBlock(chunkX + 8, j + 3, chunkZ + 6, Blocks.log, 1, 2);
                world.setBlock(chunkX + 9, j + 3, chunkZ + 6, Blocks.log, 1, 2);
                world.setBlock(chunkX + 10, j + 3, chunkZ + 6, Blocks.log, 1, 2);
                world.setBlock(chunkX + 11, j + 3, chunkZ + 6, Blocks.log, 1, 2);
                world.setBlock(chunkX + 3, j + 3, chunkZ + 7, Blocks.log, 1, 2);
                world.setBlock(chunkX + 4, j + 3, chunkZ + 7, Blocks.log, 1, 2);
                world.setBlock(chunkX + 5, j + 3, chunkZ + 7, Blocks.log, 1, 2);
                world.setBlock(chunkX + 6, j + 3, chunkZ + 7, Blocks.web, 0, 2);
                world.setBlock(chunkX + 8, j + 3, chunkZ + 7, Blocks.web, 0, 2);
                world.setBlock(chunkX + 9, j + 3, chunkZ + 7, Blocks.log, 1, 2);
                world.setBlock(chunkX + 10, j + 3, chunkZ + 7, Blocks.log, 1, 2);
                world.setBlock(chunkX + 11, j + 3, chunkZ + 7, Blocks.log, 1, 2);
                world.setBlock(chunkX + 12, j + 3, chunkZ + 7, Blocks.log, 1, 2);
                world.setBlock(chunkX + 3, j + 3, chunkZ + 8, Blocks.log, 1, 2);
                world.setBlock(chunkX + 4, j + 3, chunkZ + 8, Blocks.log, 1, 2);
                world.setBlock(chunkX + 10, j + 3, chunkZ + 8, Blocks.log, 1, 2);
                world.setBlock(chunkX + 11, j + 3, chunkZ + 8, Blocks.log, 1, 2);
                world.setBlock(chunkX + 12, j + 3, chunkZ + 8, Blocks.log, 1, 2);
                world.setBlock(chunkX + 2, j + 3, chunkZ + 9, Blocks.log, 1, 2);
                world.setBlock(chunkX + 3, j + 3, chunkZ + 9, Blocks.log, 1, 2);
                world.setBlock(chunkX + 10, j + 3, chunkZ + 9, Blocks.web, 0, 2);
                world.setBlock(chunkX + 11, j + 3, chunkZ + 9, Blocks.log, 1, 2);
                world.setBlock(chunkX + 12, j + 3, chunkZ + 9, Blocks.log, 1, 2);
                world.setBlock(chunkX + 13, j + 3, chunkZ + 9, Blocks.log, 1, 2);
                world.setBlock(chunkX + 0, j + 3, chunkZ + 10, Blocks.log, 1, 2);
                world.setBlock(chunkX + 1, j + 3, chunkZ + 10, Blocks.log, 1, 2);
                world.setBlock(chunkX + 2, j + 3, chunkZ + 10, Blocks.log, 1, 2);
                world.setBlock(chunkX + 3, j + 3, chunkZ + 10, Blocks.log, 1, 2);
                world.setBlock(chunkX + 11, j + 3, chunkZ + 10, Blocks.log, 1, 2);
                world.setBlock(chunkX + 12, j + 3, chunkZ + 10, Blocks.log, 1, 2);
                world.setBlock(chunkX + 13, j + 3, chunkZ + 10, Blocks.log, 1, 2);
                world.setBlock(chunkX + 2, j + 3, chunkZ + 11, Blocks.log, 1, 2);
                world.setBlock(chunkX + 3, j + 3, chunkZ + 11, Blocks.log, 1, 2);
                world.setBlock(chunkX + 11, j + 3, chunkZ + 11, Blocks.log, 1, 2);
                world.setBlock(chunkX + 12, j + 3, chunkZ + 11, Blocks.log, 1, 2);
                world.setBlock(chunkX + 13, j + 3, chunkZ + 11, Blocks.log, 1, 2);
                world.setBlock(chunkX + 3, j + 3, chunkZ + 12, Blocks.log, 1, 2);
                world.setBlock(chunkX + 4, j + 3, chunkZ + 12, Blocks.log, 1, 2);
                world.setBlock(chunkX + 5, j + 3, chunkZ + 12, Blocks.web, 0, 2);
                world.setBlock(chunkX + 9, j + 3, chunkZ + 12, Blocks.web, 0, 2);
                world.setBlock(chunkX + 10, j + 3, chunkZ + 12, Blocks.log, 1, 2);
                world.setBlock(chunkX + 11, j + 3, chunkZ + 12, Blocks.log, 1, 2);
                world.setBlock(chunkX + 12, j + 3, chunkZ + 12, Blocks.log, 1, 2);
                world.setBlock(chunkX + 3, j + 3, chunkZ + 13, Blocks.log, 1, 2);
                world.setBlock(chunkX + 4, j + 3, chunkZ + 13, Blocks.log, 1, 2);
                world.setBlock(chunkX + 5, j + 3, chunkZ + 13, Blocks.log, 1, 2);
                world.setBlock(chunkX + 8, j + 3, chunkZ + 13, Blocks.web, 0, 2);
                world.setBlock(chunkX + 9, j + 3, chunkZ + 13, Blocks.log, 1, 2);
                world.setBlock(chunkX + 10, j + 3, chunkZ + 13, Blocks.log, 1, 2);
                world.setBlock(chunkX + 11, j + 3, chunkZ + 13, Blocks.log, 1, 2);
                world.setBlock(chunkX + 4, j + 3, chunkZ + 14, Blocks.log, 1, 2);
                world.setBlock(chunkX + 5, j + 3, chunkZ + 14, Blocks.log, 1, 2);
                world.setBlock(chunkX + 6, j + 3, chunkZ + 14, Blocks.log, 1, 2);
                world.setBlock(chunkX + 7, j + 3, chunkZ + 14, Blocks.log, 1, 2);
                world.setBlock(chunkX + 8, j + 3, chunkZ + 14, Blocks.log, 1, 2);
                world.setBlock(chunkX + 9, j + 3, chunkZ + 14, Blocks.log, 1, 2);
                world.setBlock(chunkX + 10, j + 3, chunkZ + 14, Blocks.log, 1, 2);
                world.setBlock(chunkX + 11, j + 3, chunkZ + 14, Blocks.log, 1, 2);
                world.setBlock(chunkX + 12, j + 3, chunkZ + 14, Blocks.log, 1, 2);
                world.setBlock(chunkX + 3, j + 3, chunkZ + 15, Blocks.log, 1, 2);
                world.setBlock(chunkX + 4, j + 3, chunkZ + 15, Blocks.log, 1, 2);
                world.setBlock(chunkX + 5, j + 3, chunkZ + 15, Blocks.log, 1, 2);
                world.setBlock(chunkX + 6, j + 3, chunkZ + 15, Blocks.log, 1, 2);
                world.setBlock(chunkX + 7, j + 3, chunkZ + 15, Blocks.log, 1, 2);
                world.setBlock(chunkX + 8, j + 3, chunkZ + 15, Blocks.log, 1, 2);
                world.setBlock(chunkX + 10, j + 3, chunkZ + 15, Blocks.log, 1, 2);
                world.setBlock(chunkX + 11, j + 3, chunkZ + 15, Blocks.log, 1, 2);
                world.setBlock(chunkX + 12, j + 3, chunkZ + 15, Blocks.log, 1, 2);
                world.setBlock(chunkX + 3, j + 3, chunkZ + 16, Blocks.log, 1, 2);
                world.setBlock(chunkX + 4, j + 3, chunkZ + 16, Blocks.log, 1, 2);
                world.setBlock(chunkX + 11, j + 3, chunkZ + 16, Blocks.log, 1, 2);
                world.setBlock(chunkX + 3, j + 3, chunkZ + 17, Blocks.log, 1, 2);
                world.setBlock(chunkX + 7, j + 4, chunkZ + 3, Blocks.log, 1, 2);
                world.setBlock(chunkX + 7, j + 4, chunkZ + 4, Blocks.log, 1, 2);
                world.setBlock(chunkX + 2, j + 4, chunkZ + 5, Blocks.log, 1, 2);
                world.setBlock(chunkX + 3, j + 4, chunkZ + 5, Blocks.log, 1, 2);
                world.setBlock(chunkX + 6, j + 4, chunkZ + 5, Blocks.log, 1, 2);
                world.setBlock(chunkX + 7, j + 4, chunkZ + 5, Blocks.log, 1, 2);
                world.setBlock(chunkX + 8, j + 4, chunkZ + 5, Blocks.log, 1, 2);
                world.setBlock(chunkX + 3, j + 4, chunkZ + 6, Blocks.log, 1, 2);
                world.setBlock(chunkX + 4, j + 4, chunkZ + 6, Blocks.log, 1, 2);
                world.setBlock(chunkX + 5, j + 4, chunkZ + 6, Blocks.log, 1, 2);
                world.setBlock(chunkX + 6, j + 4, chunkZ + 6, Blocks.log, 1, 2);
                world.setBlock(chunkX + 7, j + 4, chunkZ + 6, Blocks.log, 1, 2);
                world.setBlock(chunkX + 8, j + 4, chunkZ + 6, Blocks.log, 1, 2);
                world.setBlock(chunkX + 9, j + 4, chunkZ + 6, Blocks.log, 1, 2);
                world.setBlock(chunkX + 10, j + 4, chunkZ + 6, Blocks.log, 1, 2);
                world.setBlock(chunkX + 3, j + 4, chunkZ + 7, Blocks.log, 1, 2);
                world.setBlock(chunkX + 4, j + 4, chunkZ + 7, Blocks.log, 1, 2);
                world.setBlock(chunkX + 5, j + 4, chunkZ + 7, Blocks.log, 1, 2);
                world.setBlock(chunkX + 6, j + 4, chunkZ + 7, Main.RockStone, 0, 2);
                world.setBlock(chunkX + 7, j + 4, chunkZ + 7, Main.RockStone, 0, 2);
                world.setBlock(chunkX + 8, j + 4, chunkZ + 7, Main.RockStone, 0, 2);
                world.setBlock(chunkX + 9, j + 4, chunkZ + 7, Blocks.log, 1, 2);
                world.setBlock(chunkX + 10, j + 4, chunkZ + 7, Blocks.log, 1, 2);
                world.setBlock(chunkX + 11, j + 4, chunkZ + 7, Blocks.log, 1, 2);
                world.setBlock(chunkX + 3, j + 4, chunkZ + 8, Blocks.log, 1, 2);
                world.setBlock(chunkX + 4, j + 4, chunkZ + 8, Blocks.log, 1, 2);
                world.setBlock(chunkX + 5, j + 4, chunkZ + 8, Main.RockStone, 0, 2);
                world.setBlock(chunkX + 6, j + 4, chunkZ + 8, Main.RockStone, 0, 2);
                world.setBlock(chunkX + 7, j + 4, chunkZ + 8, Main.RockStone, 0, 2);
                world.setBlock(chunkX + 8, j + 4, chunkZ + 8, Main.RockStone, 0, 2);
                world.setBlock(chunkX + 9, j + 4, chunkZ + 8, Main.RockStone, 0, 2);
                world.setBlock(chunkX + 10, j + 4, chunkZ + 8, Blocks.log, 1, 2);
                world.setBlock(chunkX + 11, j + 4, chunkZ + 8, Blocks.log, 1, 2);
                world.setBlock(chunkX + 2, j + 4, chunkZ + 9, Blocks.log, 1, 2);
                world.setBlock(chunkX + 3, j + 4, chunkZ + 9, Blocks.log, 1, 2);
                world.setBlock(chunkX + 4, j + 4, chunkZ + 9, Blocks.web, 0, 2);
                world.setBlock(chunkX + 5, j + 4, chunkZ + 9, Main.RockStone, 0, 2);
                world.setBlock(chunkX + 6, j + 4, chunkZ + 9, Main.RockStone, 0, 2);
                world.setBlock(chunkX + 7, j + 4, chunkZ + 9, Main.RockStone, 0, 2);
                world.setBlock(chunkX + 8, j + 4, chunkZ + 9, Main.RockStone, 0, 2);
                world.setBlock(chunkX + 9, j + 4, chunkZ + 9, Main.RockStone, 0, 2);
                world.setBlock(chunkX + 10, j + 4, chunkZ + 9, Main.RockStone, 0, 2);
                world.setBlock(chunkX + 11, j + 4, chunkZ + 9, Blocks.log, 1, 2);
                world.setBlock(chunkX + 12, j + 4, chunkZ + 9, Blocks.log, 1, 2);
                world.setBlock(chunkX + 1, j + 4, chunkZ + 10, Blocks.log, 1, 2);
                world.setBlock(chunkX + 2, j + 4, chunkZ + 10, Blocks.log, 1, 2);
                world.setBlock(chunkX + 3, j + 4, chunkZ + 10, Blocks.log, 1, 2);
                world.setBlock(chunkX + 4, j + 4, chunkZ + 10, Blocks.web, 0, 2);
                world.setBlock(chunkX + 5, j + 4, chunkZ + 10, Main.RockStone, 0, 2);
                world.setBlock(chunkX + 6, j + 4, chunkZ + 10, Main.RockStone, 0, 2);
                world.setBlock(chunkX + 7, j + 4, chunkZ + 10, Main.RockStone, 0, 2);
                world.setBlock(chunkX + 8, j + 4, chunkZ + 10, Main.RockStone, 0, 2);
                world.setBlock(chunkX + 9, j + 4, chunkZ + 10, Main.RockStone, 0, 2);
                world.setBlock(chunkX + 10, j + 4, chunkZ + 10, Main.RockStone, 0, 2);
                world.setBlock(chunkX + 11, j + 4, chunkZ + 10, Main.RockStone, 0, 2);
                world.setBlock(chunkX + 12, j + 4, chunkZ + 10, Blocks.log, 1, 2);
                world.setBlock(chunkX + 3, j + 4, chunkZ + 11, Blocks.log, 1, 2);
                world.setBlock(chunkX + 4, j + 4, chunkZ + 11, Blocks.web, 0, 2);
                world.setBlock(chunkX + 5, j + 4, chunkZ + 11, Main.RockStone, 0, 2);
                world.setBlock(chunkX + 6, j + 4, chunkZ + 11, Main.RockStone, 0, 2);
                world.setBlock(chunkX + 7, j + 4, chunkZ + 11, Main.RockStone, 0, 2);
                world.setBlock(chunkX + 8, j + 4, chunkZ + 11, Main.RockStone, 0, 2);
                world.setBlock(chunkX + 9, j + 4, chunkZ + 11, Main.RockStone, 0, 2);
                world.setBlock(chunkX + 10, j + 4, chunkZ + 11, Main.RockStone, 0, 2);
                world.setBlock(chunkX + 11, j + 4, chunkZ + 11, Blocks.log, 1, 2);
                world.setBlock(chunkX + 12, j + 4, chunkZ + 11, Blocks.log, 1, 2);
                world.setBlock(chunkX + 3, j + 4, chunkZ + 12, Blocks.log, 1, 2);
                world.setBlock(chunkX + 4, j + 4, chunkZ + 12, Blocks.log, 1, 2);
                world.setBlock(chunkX + 5, j + 4, chunkZ + 12, Main.RockStone, 0, 2);
                world.setBlock(chunkX + 6, j + 4, chunkZ + 12, Main.RockStone, 0, 2);
                world.setBlock(chunkX + 7, j + 4, chunkZ + 12, Main.RockStone, 0, 2);
                world.setBlock(chunkX + 8, j + 4, chunkZ + 12, Main.RockStone, 0, 2);
                world.setBlock(chunkX + 9, j + 4, chunkZ + 12, Main.RockStone, 0, 2);
                world.setBlock(chunkX + 10, j + 4, chunkZ + 12, Blocks.log, 1, 2);
                world.setBlock(chunkX + 11, j + 4, chunkZ + 12, Blocks.log, 1, 2);
                world.setBlock(chunkX + 4, j + 4, chunkZ + 13, Blocks.log, 1, 2);
                world.setBlock(chunkX + 5, j + 4, chunkZ + 13, Blocks.log, 1, 2);
                world.setBlock(chunkX + 6, j + 4, chunkZ + 13, Main.RockStone, 0, 2);
                world.setBlock(chunkX + 7, j + 4, chunkZ + 13, Main.RockStone, 0, 2);
                world.setBlock(chunkX + 8, j + 4, chunkZ + 13, Main.RockStone, 0, 2);
                world.setBlock(chunkX + 9, j + 4, chunkZ + 13, Blocks.log, 1, 2);
                world.setBlock(chunkX + 10, j + 4, chunkZ + 13, Blocks.log, 1, 2);
                world.setBlock(chunkX + 4, j + 4, chunkZ + 14, Blocks.log, 1, 2);
                world.setBlock(chunkX + 5, j + 4, chunkZ + 14, Blocks.log, 1, 2);
                world.setBlock(chunkX + 6, j + 4, chunkZ + 14, Blocks.log, 1, 2);
                world.setBlock(chunkX + 7, j + 4, chunkZ + 14, Blocks.log, 1, 2);
                world.setBlock(chunkX + 8, j + 4, chunkZ + 14, Blocks.log, 1, 2);
                world.setBlock(chunkX + 9, j + 4, chunkZ + 14, Blocks.log, 1, 2);
                world.setBlock(chunkX + 10, j + 4, chunkZ + 14, Blocks.log, 1, 2);
                world.setBlock(chunkX + 11, j + 4, chunkZ + 14, Blocks.log, 1, 2);
                world.setBlock(chunkX + 3, j + 4, chunkZ + 15, Blocks.log, 1, 2);
                world.setBlock(chunkX + 4, j + 4, chunkZ + 15, Blocks.log, 1, 2);
                world.setBlock(chunkX + 5, j + 4, chunkZ + 15, Blocks.log, 1, 2);
                world.setBlock(chunkX + 6, j + 4, chunkZ + 15, Blocks.log, 1, 2);
                world.setBlock(chunkX + 7, j + 4, chunkZ + 15, Blocks.log, 1, 2);
                world.setBlock(chunkX + 8, j + 4, chunkZ + 15, Blocks.log, 1, 2);
                world.setBlock(chunkX + 11, j + 4, chunkZ + 15, Blocks.log, 1, 2);
                world.setBlock(chunkX + 4, j + 4, chunkZ + 16, Blocks.log, 1, 2);
                world.setBlock(chunkX + 7, j + 5, chunkZ + 5, Blocks.log, 1, 2);
                world.setBlock(chunkX + 5, j + 5, chunkZ + 6, Blocks.log, 1, 2);
                world.setBlock(chunkX + 6, j + 5, chunkZ + 6, Blocks.log, 1, 2);
                world.setBlock(chunkX + 7, j + 5, chunkZ + 6, Blocks.log, 1, 2);
                world.setBlock(chunkX + 8, j + 5, chunkZ + 6, Blocks.log, 1, 2);
                world.setBlock(chunkX + 9, j + 5, chunkZ + 6, Blocks.log, 1, 2);
                world.setBlock(chunkX + 4, j + 5, chunkZ + 7, Blocks.log, 1, 2);
                world.setBlock(chunkX + 5, j + 5, chunkZ + 7, Blocks.log, 1, 2);
                world.setBlock(chunkX + 9, j + 5, chunkZ + 7, Blocks.log, 1, 2);
                world.setBlock(chunkX + 10, j + 5, chunkZ + 7, Blocks.log, 1, 2);
                world.setBlock(chunkX + 3, j + 5, chunkZ + 8, Blocks.log, 1, 2);
                world.setBlock(chunkX + 4, j + 5, chunkZ + 8, Blocks.log, 1, 2);
                world.setBlock(chunkX + 9, j + 5, chunkZ + 8, Blocks.log, 1, 2);
                world.setBlock(chunkX + 10, j + 5, chunkZ + 8, Blocks.log, 1, 2);
                world.setBlock(chunkX + 11, j + 5, chunkZ + 8, Blocks.log, 1, 2);
                world.setBlock(chunkX + 3, j + 5, chunkZ + 9, Blocks.log, 1, 2);
                world.setBlock(chunkX + 11, j + 5, chunkZ + 9, Blocks.log, 1, 2);
                world.setBlock(chunkX + 2, j + 5, chunkZ + 10, Blocks.log, 1, 2);
                world.setBlock(chunkX + 3, j + 5, chunkZ + 10, Blocks.log, 1, 2);
                world.setBlock(chunkX + 7, j + 5, chunkZ + 10, Blocks.mob_spawner, 0, 2);
                final int x3 = chunkX + 7;
                final int y3 = j + 5;
                final int z3 = chunkZ + 10;
                final TileEntityMobSpawner tileentitymobspawner2 = (TileEntityMobSpawner)world.getTileEntity(x3, y3, z3);
                if (tileentitymobspawner2 != null) {
                    tileentitymobspawner2.func_145881_a().setEntityName("Tektite");
                }
                else {
                    System.err.println("Failed to fetch mob spawner entity at (" + x3 + ", " + y3 + ", " + z3 + ")");
                }
                world.setBlock(chunkX + 3, j + 5, chunkZ + 11, Blocks.log, 1, 2);
                world.setBlock(chunkX + 11, j + 5, chunkZ + 11, Blocks.log, 1, 2);
                world.setBlock(chunkX + 3, j + 5, chunkZ + 12, Blocks.log, 1, 2);
                world.setBlock(chunkX + 4, j + 5, chunkZ + 12, Blocks.log, 1, 2);
                world.setBlock(chunkX + 10, j + 5, chunkZ + 12, Blocks.log, 1, 2);
                world.setBlock(chunkX + 11, j + 5, chunkZ + 12, Blocks.log, 1, 2);
                world.setBlock(chunkX + 5, j + 5, chunkZ + 13, Blocks.log, 1, 2);
                world.setBlock(chunkX + 9, j + 5, chunkZ + 13, Blocks.log, 1, 2);
                world.setBlock(chunkX + 10, j + 5, chunkZ + 13, Blocks.log, 1, 2);
                world.setBlock(chunkX + 5, j + 5, chunkZ + 14, Blocks.log, 1, 2);
                world.setBlock(chunkX + 6, j + 5, chunkZ + 14, Blocks.log, 1, 2);
                world.setBlock(chunkX + 7, j + 5, chunkZ + 14, Blocks.log, 1, 2);
                world.setBlock(chunkX + 8, j + 5, chunkZ + 14, Blocks.log, 1, 2);
                world.setBlock(chunkX + 9, j + 5, chunkZ + 14, Blocks.log, 1, 2);
                world.setBlock(chunkX + 10, j + 5, chunkZ + 14, Blocks.log, 1, 2);
                world.setBlock(chunkX + 7, j + 5, chunkZ + 15, Blocks.log, 1, 2);
                world.setBlock(chunkX + 5, j + 6, chunkZ + 6, Blocks.log, 1, 2);
                world.setBlock(chunkX + 6, j + 6, chunkZ + 6, Blocks.log, 1, 2);
                world.setBlock(chunkX + 7, j + 6, chunkZ + 6, Blocks.log, 1, 2);
                world.setBlock(chunkX + 8, j + 6, chunkZ + 6, Blocks.log, 1, 2);
                world.setBlock(chunkX + 5, j + 6, chunkZ + 7, Blocks.log, 1, 2);
                world.setBlock(chunkX + 6, j + 6, chunkZ + 7, Blocks.log, 9, 2);
                world.setBlock(chunkX + 9, j + 6, chunkZ + 7, Blocks.log, 1, 2);
                world.setBlock(chunkX + 10, j + 6, chunkZ + 7, Blocks.log, 1, 2);
                world.setBlock(chunkX + 4, j + 6, chunkZ + 8, Blocks.log, 1, 2);
                world.setBlock(chunkX + 6, j + 6, chunkZ + 8, Blocks.log, 9, 2);
                world.setBlock(chunkX + 10, j + 6, chunkZ + 8, Blocks.log, 1, 2);
                world.setBlock(chunkX + 3, j + 6, chunkZ + 9, Blocks.log, 1, 2);
                world.setBlock(chunkX + 11, j + 6, chunkZ + 9, Blocks.log, 1, 2);
                world.setBlock(chunkX + 3, j + 6, chunkZ + 10, Blocks.log, 1, 2);
                world.setBlock(chunkX + 3, j + 6, chunkZ + 11, Blocks.log, 1, 2);
                world.setBlock(chunkX + 11, j + 6, chunkZ + 11, Blocks.log, 1, 2);
                world.setBlock(chunkX + 4, j + 6, chunkZ + 12, Blocks.log, 1, 2);
                world.setBlock(chunkX + 10, j + 6, chunkZ + 12, Blocks.log, 1, 2);
                world.setBlock(chunkX + 5, j + 6, chunkZ + 13, Blocks.log, 1, 2);
                world.setBlock(chunkX + 9, j + 6, chunkZ + 13, Blocks.log, 1, 2);
                world.setBlock(chunkX + 10, j + 6, chunkZ + 13, Blocks.log, 1, 2);
                world.setBlock(chunkX + 6, j + 6, chunkZ + 14, Blocks.log, 1, 2);
                world.setBlock(chunkX + 7, j + 6, chunkZ + 14, Blocks.log, 1, 2);
                world.setBlock(chunkX + 8, j + 6, chunkZ + 14, Blocks.log, 1, 2);
                world.setBlock(chunkX + 9, j + 6, chunkZ + 14, Blocks.log, 1, 2);
                world.setBlock(chunkX + 6, j + 7, chunkZ + 6, Blocks.log, 1, 2);
                world.setBlock(chunkX + 7, j + 7, chunkZ + 6, Blocks.log, 1, 2);
                world.setBlock(chunkX + 8, j + 7, chunkZ + 6, Blocks.log, 1, 2);
                world.setBlock(chunkX + 5, j + 7, chunkZ + 7, Blocks.log, 1, 2);
                world.setBlock(chunkX + 9, j + 7, chunkZ + 7, Blocks.log, 1, 2);
                world.setBlock(chunkX + 4, j + 7, chunkZ + 8, Blocks.log, 1, 2);
                world.setBlock(chunkX + 10, j + 7, chunkZ + 8, Blocks.log, 1, 2);
                world.setBlock(chunkX + 3, j + 7, chunkZ + 9, Blocks.log, 1, 2);
                world.setBlock(chunkX + 4, j + 7, chunkZ + 9, Blocks.log, 5, 2);
                world.setBlock(chunkX + 10, j + 7, chunkZ + 9, Blocks.web, 0, 2);
                world.setBlock(chunkX + 11, j + 7, chunkZ + 9, Blocks.log, 1, 2);
                world.setBlock(chunkX + 3, j + 7, chunkZ + 10, Blocks.log, 1, 2);
                world.setBlock(chunkX + 11, j + 7, chunkZ + 10, Blocks.log, 1, 2);
                world.setBlock(chunkX + 3, j + 7, chunkZ + 11, Blocks.log, 1, 2);
                world.setBlock(chunkX + 11, j + 7, chunkZ + 11, Blocks.log, 1, 2);
                world.setBlock(chunkX + 4, j + 7, chunkZ + 12, Blocks.log, 1, 2);
                world.setBlock(chunkX + 10, j + 7, chunkZ + 12, Blocks.log, 1, 2);
                world.setBlock(chunkX + 5, j + 7, chunkZ + 13, Blocks.log, 1, 2);
                world.setBlock(chunkX + 9, j + 7, chunkZ + 13, Blocks.log, 1, 2);
                world.setBlock(chunkX + 10, j + 7, chunkZ + 13, Blocks.log, 1, 2);
                world.setBlock(chunkX + 6, j + 7, chunkZ + 14, Blocks.log, 1, 2);
                world.setBlock(chunkX + 7, j + 7, chunkZ + 14, Blocks.log, 1, 2);
                world.setBlock(chunkX + 8, j + 7, chunkZ + 14, Blocks.log, 1, 2);
                world.setBlock(chunkX + 6, j + 8, chunkZ + 6, Blocks.log, 1, 2);
                world.setBlock(chunkX + 7, j + 8, chunkZ + 6, Blocks.log, 1, 2);
                world.setBlock(chunkX + 8, j + 8, chunkZ + 6, Blocks.log, 1, 2);
                world.setBlock(chunkX + 5, j + 8, chunkZ + 7, Blocks.log, 1, 2);
                world.setBlock(chunkX + 9, j + 8, chunkZ + 7, Blocks.log, 1, 2);
                world.setBlock(chunkX + 4, j + 8, chunkZ + 8, Blocks.log, 1, 2);
                world.setBlock(chunkX + 10, j + 8, chunkZ + 8, Blocks.log, 1, 2);
                world.setBlock(chunkX + 3, j + 8, chunkZ + 9, Blocks.log, 1, 2);
                world.setBlock(chunkX + 11, j + 8, chunkZ + 9, Blocks.log, 1, 2);
                world.setBlock(chunkX + 3, j + 8, chunkZ + 10, Blocks.log, 1, 2);
                world.setBlock(chunkX + 11, j + 8, chunkZ + 10, Blocks.log, 1, 2);
                world.setBlock(chunkX + 3, j + 8, chunkZ + 11, Blocks.log, 1, 2);
                world.setBlock(chunkX + 11, j + 8, chunkZ + 11, Blocks.log, 1, 2);
                world.setBlock(chunkX + 4, j + 8, chunkZ + 12, Blocks.log, 1, 2);
                world.setBlock(chunkX + 5, j + 8, chunkZ + 12, Blocks.log, 9, 2);
                world.setBlock(chunkX + 10, j + 8, chunkZ + 12, Blocks.log, 1, 2);
                world.setBlock(chunkX + 5, j + 8, chunkZ + 13, Blocks.log, 1, 2);
                world.setBlock(chunkX + 7, j + 8, chunkZ + 13, Blocks.web, 0, 2);
                world.setBlock(chunkX + 9, j + 8, chunkZ + 13, Blocks.log, 1, 2);
                world.setBlock(chunkX + 6, j + 8, chunkZ + 14, Blocks.log, 1, 2);
                world.setBlock(chunkX + 7, j + 8, chunkZ + 14, Blocks.log, 1, 2);
                world.setBlock(chunkX + 8, j + 8, chunkZ + 14, Blocks.log, 1, 2);
                world.setBlock(chunkX + 6, j + 9, chunkZ + 6, Blocks.log, 1, 2);
                world.setBlock(chunkX + 7, j + 9, chunkZ + 6, Blocks.log, 1, 2);
                world.setBlock(chunkX + 8, j + 9, chunkZ + 6, Blocks.log, 1, 2);
                world.setBlock(chunkX + 5, j + 9, chunkZ + 7, Blocks.log, 1, 2);
                world.setBlock(chunkX + 9, j + 9, chunkZ + 7, Blocks.log, 1, 2);
                world.setBlock(chunkX + 4, j + 9, chunkZ + 8, Blocks.log, 1, 2);
                world.setBlock(chunkX + 10, j + 9, chunkZ + 8, Blocks.log, 1, 2);
                world.setBlock(chunkX + 3, j + 9, chunkZ + 9, Blocks.log, 1, 2);
                world.setBlock(chunkX + 11, j + 9, chunkZ + 9, Blocks.log, 1, 2);
                world.setBlock(chunkX + 3, j + 9, chunkZ + 10, Blocks.log, 1, 2);
                world.setBlock(chunkX + 11, j + 9, chunkZ + 10, Blocks.log, 1, 2);
                world.setBlock(chunkX + 3, j + 9, chunkZ + 11, Blocks.log, 1, 2);
                world.setBlock(chunkX + 10, j + 9, chunkZ + 11, Blocks.web, 0, 2);
                world.setBlock(chunkX + 11, j + 9, chunkZ + 11, Blocks.log, 1, 2);
                world.setBlock(chunkX + 4, j + 9, chunkZ + 12, Blocks.log, 1, 2);
                world.setBlock(chunkX + 8, j + 9, chunkZ + 12, Blocks.log, 5, 2);
                world.setBlock(chunkX + 9, j + 9, chunkZ + 12, Blocks.log, 5, 2);
                world.setBlock(chunkX + 10, j + 9, chunkZ + 12, Blocks.log, 1, 2);
                world.setBlock(chunkX + 5, j + 9, chunkZ + 13, Blocks.log, 1, 2);
                world.setBlock(chunkX + 6, j + 9, chunkZ + 13, Blocks.web, 0, 2);
                world.setBlock(chunkX + 9, j + 9, chunkZ + 13, Blocks.log, 1, 2);
                world.setBlock(chunkX + 6, j + 9, chunkZ + 14, Blocks.log, 1, 2);
                world.setBlock(chunkX + 8, j + 9, chunkZ + 14, Blocks.log, 1, 2);
                world.setBlock(chunkX + 7, j + 9, chunkZ + 15, Blocks.log, 9, 2);
                world.setBlock(chunkX + 7, j + 9, chunkZ + 16, Blocks.log, 9, 2);
                world.setBlock(chunkX + 7, j + 9, chunkZ + 17, Blocks.log, 9, 2);
                world.setBlock(chunkX + 6, j + 10, chunkZ + 6, Blocks.log, 1, 2);
                world.setBlock(chunkX + 7, j + 10, chunkZ + 6, Blocks.log, 1, 2);
                world.setBlock(chunkX + 8, j + 10, chunkZ + 6, Blocks.log, 1, 2);
                world.setBlock(chunkX + 5, j + 10, chunkZ + 7, Blocks.log, 1, 2);
                world.setBlock(chunkX + 9, j + 10, chunkZ + 7, Blocks.log, 1, 2);
                world.setBlock(chunkX + 4, j + 10, chunkZ + 8, Blocks.log, 1, 2);
                world.setBlock(chunkX + 10, j + 10, chunkZ + 8, Blocks.log, 1, 2);
                world.setBlock(chunkX + 3, j + 10, chunkZ + 9, Blocks.log, 1, 2);
                world.setBlock(chunkX + 6, j + 10, chunkZ + 9, Blocks.log, 1, 2);
                world.setBlock(chunkX + 7, j + 10, chunkZ + 9, Blocks.log, 5, 2);
                world.setBlock(chunkX + 8, j + 10, chunkZ + 9, Blocks.log, 5, 2);
                world.setBlock(chunkX + 9, j + 10, chunkZ + 9, Blocks.log, 5, 2);
                world.setBlock(chunkX + 10, j + 10, chunkZ + 9, Blocks.log, 5, 2);
                world.setBlock(chunkX + 11, j + 10, chunkZ + 9, Blocks.log, 1, 2);
                world.setBlock(chunkX + 3, j + 10, chunkZ + 10, Blocks.log, 1, 2);
                world.setBlock(chunkX + 11, j + 10, chunkZ + 10, Blocks.log, 1, 2);
                world.setBlock(chunkX + 3, j + 10, chunkZ + 11, Blocks.log, 1, 2);
                world.setBlock(chunkX + 11, j + 10, chunkZ + 11, Blocks.log, 1, 2);
                world.setBlock(chunkX + 4, j + 10, chunkZ + 12, Blocks.log, 1, 2);
                world.setBlock(chunkX + 10, j + 10, chunkZ + 12, Blocks.log, 1, 2);
                world.setBlock(chunkX + 5, j + 10, chunkZ + 13, Blocks.log, 1, 2);
                world.setBlock(chunkX + 9, j + 10, chunkZ + 13, Blocks.log, 1, 2);
                world.setBlock(chunkX + 6, j + 10, chunkZ + 14, Blocks.log, 1, 2);
                world.setBlock(chunkX + 8, j + 10, chunkZ + 14, Blocks.log, 1, 2);
                world.setBlock(chunkX + 6, j + 10, chunkZ + 15, Blocks.log, 9, 2);
                world.setBlock(chunkX + 8, j + 10, chunkZ + 15, Blocks.log, 9, 2);
                world.setBlock(chunkX + 6, j + 10, chunkZ + 16, Blocks.log, 9, 2);
                world.setBlock(chunkX + 8, j + 10, chunkZ + 16, Blocks.log, 9, 2);
                world.setBlock(chunkX + 6, j + 10, chunkZ + 17, Blocks.log, 9, 2);
                world.setBlock(chunkX + 8, j + 10, chunkZ + 17, Blocks.log, 9, 2);
                world.setBlock(chunkX + 7, j + 10, chunkZ + 18, Blocks.log, 9, 2);
                world.setBlock(chunkX + 6, j + 11, chunkZ + 6, Blocks.log, 1, 2);
                world.setBlock(chunkX + 7, j + 11, chunkZ + 6, Blocks.log, 1, 2);
                world.setBlock(chunkX + 8, j + 11, chunkZ + 6, Blocks.log, 1, 2);
                world.setBlock(chunkX + 5, j + 11, chunkZ + 7, Blocks.log, 1, 2);
                world.setBlock(chunkX + 8, j + 11, chunkZ + 7, Blocks.web, 0, 2);
                world.setBlock(chunkX + 9, j + 11, chunkZ + 7, Blocks.log, 1, 2);
                world.setBlock(chunkX + 4, j + 11, chunkZ + 8, Blocks.log, 1, 2);
                world.setBlock(chunkX + 10, j + 11, chunkZ + 8, Blocks.log, 1, 2);
                world.setBlock(chunkX + 3, j + 11, chunkZ + 9, Blocks.log, 1, 2);
                world.setBlock(chunkX + 4, j + 11, chunkZ + 9, Blocks.log, 5, 2);
                world.setBlock(chunkX + 5, j + 11, chunkZ + 9, Blocks.log, 5, 2);
                world.setBlock(chunkX + 6, j + 11, chunkZ + 9, Blocks.log, 5, 2);
                world.setBlock(chunkX + 11, j + 11, chunkZ + 9, Blocks.log, 1, 2);
                world.setBlock(chunkX + 3, j + 11, chunkZ + 10, Blocks.log, 1, 2);
                world.setBlock(chunkX + 11, j + 11, chunkZ + 10, Blocks.log, 1, 2);
                world.setBlock(chunkX + 3, j + 11, chunkZ + 11, Blocks.log, 1, 2);
                world.setBlock(chunkX + 4, j + 11, chunkZ + 11, Blocks.web, 0, 2);
                world.setBlock(chunkX + 11, j + 11, chunkZ + 11, Blocks.log, 1, 2);
                world.setBlock(chunkX + 4, j + 11, chunkZ + 12, Blocks.log, 1, 2);
                world.setBlock(chunkX + 10, j + 11, chunkZ + 12, Blocks.log, 1, 2);
                world.setBlock(chunkX + 5, j + 11, chunkZ + 13, Blocks.log, 1, 2);
                world.setBlock(chunkX + 9, j + 11, chunkZ + 13, Blocks.log, 1, 2);
                world.setBlock(chunkX + 6, j + 11, chunkZ + 14, Blocks.log, 1, 2);
                world.setBlock(chunkX + 8, j + 11, chunkZ + 14, Blocks.log, 1, 2);
                world.setBlock(chunkX + 6, j + 11, chunkZ + 15, Blocks.log, 9, 2);
                world.setBlock(chunkX + 8, j + 11, chunkZ + 15, Blocks.log, 9, 2);
                world.setBlock(chunkX + 6, j + 11, chunkZ + 16, Blocks.log, 9, 2);
                world.setBlock(chunkX + 8, j + 11, chunkZ + 16, Blocks.log, 9, 2);
                world.setBlock(chunkX + 6, j + 11, chunkZ + 17, Blocks.log, 9, 2);
                world.setBlock(chunkX + 8, j + 11, chunkZ + 17, Blocks.log, 9, 2);
                world.setBlock(chunkX + 6, j + 11, chunkZ + 18, Blocks.log, 9, 2);
                world.setBlock(chunkX + 7, j + 11, chunkZ + 18, Blocks.trapped_chest, 2, 2);
                final int xx2 = chunkX + 7;
                final int yy2 = j + 11;
                final int zz2 = chunkZ + 18;
                final TileEntityChest tileentitychest2 = (TileEntityChest)world.getTileEntity(xx, yy, zz);
                if (tileentitychest2 != null) {
                    WeightedRandomChestContent.generateChestContents(random, ChestGenHooks.getItems("dungeonChest", random), (IInventory)tileentitychest2, ChestGenHooks.getCount("dungeonChest", random));
                }
                world.setBlock(chunkX + 8, j + 11, chunkZ + 18, Blocks.log, 9, 2);
                world.setBlock(chunkX + 7, j + 11, chunkZ + 19, Blocks.log, 9, 2);
                world.setBlock(chunkX + 7, j + 11, chunkZ + 20, Blocks.log, 9, 2);
                world.setBlock(chunkX + 6, j + 12, chunkZ + 7, Blocks.log, 1, 2);
                world.setBlock(chunkX + 7, j + 12, chunkZ + 7, Blocks.log, 1, 2);
                world.setBlock(chunkX + 8, j + 12, chunkZ + 7, Blocks.log, 1, 2);
                world.setBlock(chunkX + 5, j + 12, chunkZ + 8, Blocks.log, 1, 2);
                world.setBlock(chunkX + 9, j + 12, chunkZ + 8, Blocks.log, 1, 2);
                world.setBlock(chunkX + 4, j + 12, chunkZ + 9, Blocks.log, 1, 2);
                world.setBlock(chunkX + 10, j + 12, chunkZ + 9, Blocks.log, 1, 2);
                world.setBlock(chunkX + 4, j + 12, chunkZ + 10, Blocks.log, 1, 2);
                world.setBlock(chunkX + 10, j + 12, chunkZ + 10, Blocks.log, 1, 2);
                world.setBlock(chunkX + 4, j + 12, chunkZ + 11, Blocks.log, 1, 2);
                world.setBlock(chunkX + 7, j + 12, chunkZ + 11, Blocks.log, 9, 2);
                world.setBlock(chunkX + 10, j + 12, chunkZ + 11, Blocks.log, 1, 2);
                world.setBlock(chunkX + 5, j + 12, chunkZ + 12, Blocks.log, 1, 2);
                world.setBlock(chunkX + 9, j + 12, chunkZ + 12, Blocks.log, 1, 2);
                world.setBlock(chunkX + 6, j + 12, chunkZ + 13, Blocks.log, 1, 2);
                world.setBlock(chunkX + 7, j + 12, chunkZ + 13, Blocks.log, 1, 2);
                world.setBlock(chunkX + 8, j + 12, chunkZ + 13, Blocks.log, 1, 2);
                world.setBlock(chunkX + 7, j + 12, chunkZ + 14, Blocks.log, 9, 2);
                world.setBlock(chunkX + 7, j + 12, chunkZ + 15, Blocks.log, 9, 2);
                world.setBlock(chunkX + 7, j + 12, chunkZ + 16, Blocks.log, 9, 2);
                world.setBlock(chunkX + 6, j + 12, chunkZ + 17, Blocks.log, 9, 2);
                world.setBlock(chunkX + 8, j + 12, chunkZ + 17, Blocks.log, 9, 2);
                world.setBlock(chunkX + 6, j + 12, chunkZ + 18, Blocks.log, 9, 2);
                world.setBlock(chunkX + 8, j + 12, chunkZ + 18, Blocks.log, 9, 2);
                world.setBlock(chunkX + 6, j + 12, chunkZ + 19, Blocks.log, 9, 2);
                world.setBlock(chunkX + 8, j + 12, chunkZ + 19, Blocks.log, 9, 2);
                world.setBlock(chunkX + 7, j + 12, chunkZ + 20, Blocks.log, 9, 2);
                world.setBlock(chunkX + 7, j + 12, chunkZ + 21, Blocks.log, 9, 2);
                world.setBlock(chunkX + 7, j + 12, chunkZ + 22, Blocks.log, 9, 2);
                world.setBlock(chunkX + 7, j + 13, chunkZ + 6, Blocks.log, 9, 2);
                world.setBlock(chunkX + 6, j + 13, chunkZ + 7, Blocks.log, 1, 2);
                world.setBlock(chunkX + 7, j + 13, chunkZ + 7, Blocks.log, 9, 2);
                world.setBlock(chunkX + 8, j + 13, chunkZ + 7, Blocks.log, 1, 2);
                world.setBlock(chunkX + 5, j + 13, chunkZ + 8, Blocks.log, 1, 2);
                world.setBlock(chunkX + 7, j + 13, chunkZ + 8, Blocks.log, 9, 2);
                world.setBlock(chunkX + 9, j + 13, chunkZ + 8, Blocks.log, 1, 2);
                world.setBlock(chunkX + 4, j + 13, chunkZ + 9, Blocks.log, 1, 2);
                world.setBlock(chunkX + 10, j + 13, chunkZ + 9, Blocks.log, 1, 2);
                world.setBlock(chunkX + 4, j + 13, chunkZ + 10, Blocks.log, 1, 2);
                world.setBlock(chunkX + 10, j + 13, chunkZ + 10, Blocks.log, 1, 2);
                world.setBlock(chunkX + 4, j + 13, chunkZ + 11, Blocks.log, 1, 2);
                world.setBlock(chunkX + 10, j + 13, chunkZ + 11, Blocks.log, 1, 2);
                world.setBlock(chunkX + 5, j + 13, chunkZ + 12, Blocks.log, 1, 2);
                world.setBlock(chunkX + 7, j + 13, chunkZ + 12, Blocks.log, 9, 2);
                world.setBlock(chunkX + 9, j + 13, chunkZ + 12, Blocks.log, 1, 2);
                world.setBlock(chunkX + 6, j + 13, chunkZ + 13, Blocks.log, 1, 2);
                world.setBlock(chunkX + 7, j + 13, chunkZ + 13, Blocks.log, 1, 2);
                world.setBlock(chunkX + 8, j + 13, chunkZ + 13, Blocks.log, 1, 2);
                world.setBlock(chunkX + 7, j + 13, chunkZ + 17, Blocks.log, 9, 2);
                world.setBlock(chunkX + 7, j + 13, chunkZ + 18, Blocks.log, 9, 2);
                world.setBlock(chunkX + 7, j + 13, chunkZ + 19, Blocks.log, 9, 2);
                world.setBlock(chunkX + 7, j + 14, chunkZ + 5, Blocks.log, 9, 2);
                world.setBlock(chunkX + 7, j + 14, chunkZ + 6, Blocks.log, 9, 2);
                world.setBlock(chunkX + 6, j + 14, chunkZ + 7, Blocks.log, 1, 2);
                world.setBlock(chunkX + 8, j + 14, chunkZ + 7, Blocks.log, 1, 2);
                world.setBlock(chunkX + 5, j + 14, chunkZ + 8, Blocks.log, 1, 2);
                world.setBlock(chunkX + 9, j + 14, chunkZ + 8, Blocks.log, 1, 2);
                world.setBlock(chunkX + 4, j + 14, chunkZ + 9, Blocks.log, 1, 2);
                world.setBlock(chunkX + 10, j + 14, chunkZ + 9, Blocks.log, 1, 2);
                world.setBlock(chunkX + 4, j + 14, chunkZ + 10, Blocks.log, 1, 2);
                world.setBlock(chunkX + 10, j + 14, chunkZ + 10, Blocks.log, 1, 2);
                world.setBlock(chunkX + 4, j + 14, chunkZ + 11, Blocks.log, 1, 2);
                world.setBlock(chunkX + 10, j + 14, chunkZ + 11, Blocks.log, 1, 2);
                world.setBlock(chunkX + 5, j + 14, chunkZ + 12, Blocks.log, 1, 2);
                world.setBlock(chunkX + 9, j + 14, chunkZ + 12, Blocks.log, 1, 2);
                world.setBlock(chunkX + 6, j + 14, chunkZ + 13, Blocks.log, 1, 2);
                world.setBlock(chunkX + 7, j + 14, chunkZ + 13, Blocks.log, 1, 2);
                world.setBlock(chunkX + 8, j + 14, chunkZ + 13, Blocks.log, 1, 2);
                world.setBlock(chunkX + 7, j + 15, chunkZ + 3, Blocks.log, 9, 2);
                world.setBlock(chunkX + 7, j + 15, chunkZ + 4, Blocks.log, 9, 2);
                world.setBlock(chunkX + 6, j + 15, chunkZ + 5, Blocks.log, 9, 2);
                world.setBlock(chunkX + 8, j + 15, chunkZ + 5, Blocks.log, 9, 2);
                world.setBlock(chunkX + 6, j + 15, chunkZ + 6, Blocks.log, 9, 2);
                world.setBlock(chunkX + 8, j + 15, chunkZ + 6, Blocks.log, 9, 2);
                world.setBlock(chunkX + 6, j + 15, chunkZ + 7, Blocks.log, 9, 2);
                world.setBlock(chunkX + 8, j + 15, chunkZ + 7, Blocks.log, 9, 2);
                world.setBlock(chunkX + 5, j + 15, chunkZ + 8, Blocks.log, 1, 2);
                world.setBlock(chunkX + 9, j + 15, chunkZ + 8, Blocks.log, 1, 2);
                world.setBlock(chunkX + 4, j + 15, chunkZ + 9, Blocks.log, 1, 2);
                world.setBlock(chunkX + 9, j + 15, chunkZ + 9, Blocks.log, 1, 2);
                world.setBlock(chunkX + 4, j + 15, chunkZ + 10, Blocks.log, 1, 2);
                world.setBlock(chunkX + 10, j + 15, chunkZ + 10, Blocks.log, 1, 2);
                world.setBlock(chunkX + 4, j + 15, chunkZ + 11, Blocks.log, 1, 2);
                world.setBlock(chunkX + 9, j + 15, chunkZ + 11, Blocks.log, 1, 2);
                world.setBlock(chunkX + 10, j + 15, chunkZ + 11, Blocks.log, 1, 2);
                world.setBlock(chunkX + 5, j + 15, chunkZ + 12, Blocks.log, 1, 2);
                world.setBlock(chunkX + 6, j + 15, chunkZ + 12, Blocks.web, 0, 2);
                world.setBlock(chunkX + 8, j + 15, chunkZ + 12, Blocks.log, 1, 2);
                world.setBlock(chunkX + 6, j + 15, chunkZ + 13, Blocks.log, 1, 2);
                world.setBlock(chunkX + 7, j + 15, chunkZ + 13, Blocks.log, 1, 2);
                world.setBlock(chunkX + 8, j + 15, chunkZ + 13, Blocks.log, 1, 2);
                world.setBlock(chunkX + 7, j + 16, chunkZ + 0, Blocks.log, 9, 2);
                world.setBlock(chunkX + 7, j + 16, chunkZ + 1, Blocks.log, 9, 2);
                world.setBlock(chunkX + 6, j + 16, chunkZ + 2, Blocks.log, 9, 2);
                world.setBlock(chunkX + 7, j + 16, chunkZ + 2, Blocks.log, 9, 2);
                world.setBlock(chunkX + 6, j + 16, chunkZ + 3, Blocks.log, 9, 2);
                world.setBlock(chunkX + 7, j + 16, chunkZ + 3, Blocks.log, 9, 2);
                world.setBlock(chunkX + 6, j + 16, chunkZ + 4, Blocks.log, 9, 2);
                world.setBlock(chunkX + 7, j + 16, chunkZ + 4, Blocks.trapped_chest, 3, 2);
                final int xx3 = chunkX + 7;
                final int yy3 = j + 16;
                final int zz3 = chunkZ + 4;
                final TileEntityChest tileentitychest3 = (TileEntityChest)world.getTileEntity(xx, yy, zz);
                if (tileentitychest3 != null) {
                    WeightedRandomChestContent.generateChestContents(random, ChestGenHooks.getItems("dungeonChest", random), (IInventory)tileentitychest3, ChestGenHooks.getCount("dungeonChest", random));
                }
                world.setBlock(chunkX + 8, j + 16, chunkZ + 4, Blocks.log, 9, 2);
                world.setBlock(chunkX + 6, j + 16, chunkZ + 5, Blocks.log, 9, 2);
                world.setBlock(chunkX + 8, j + 16, chunkZ + 5, Blocks.log, 9, 2);
                world.setBlock(chunkX + 6, j + 16, chunkZ + 6, Blocks.log, 9, 2);
                world.setBlock(chunkX + 8, j + 16, chunkZ + 6, Blocks.log, 9, 2);
                world.setBlock(chunkX + 6, j + 16, chunkZ + 7, Blocks.log, 9, 2);
                world.setBlock(chunkX + 8, j + 16, chunkZ + 7, Blocks.log, 9, 2);
                world.setBlock(chunkX + 5, j + 16, chunkZ + 8, Blocks.log, 1, 2);
                world.setBlock(chunkX + 6, j + 16, chunkZ + 8, Blocks.log, 1, 2);
                world.setBlock(chunkX + 8, j + 16, chunkZ + 8, Blocks.log, 1, 2);
                world.setBlock(chunkX + 9, j + 16, chunkZ + 8, Blocks.log, 1, 2);
                world.setBlock(chunkX + 4, j + 16, chunkZ + 9, Blocks.log, 1, 2);
                world.setBlock(chunkX + 5, j + 16, chunkZ + 9, Blocks.log, 1, 2);
                world.setBlock(chunkX + 9, j + 16, chunkZ + 9, Blocks.log, 1, 2);
                world.setBlock(chunkX + 4, j + 16, chunkZ + 10, Blocks.log, 1, 2);
                world.setBlock(chunkX + 9, j + 16, chunkZ + 10, Blocks.log, 1, 2);
                world.setBlock(chunkX + 10, j + 16, chunkZ + 10, Blocks.log, 1, 2);
                world.setBlock(chunkX + 4, j + 16, chunkZ + 11, Blocks.log, 1, 2);
                world.setBlock(chunkX + 5, j + 16, chunkZ + 11, Blocks.log, 1, 2);
                world.setBlock(chunkX + 8, j + 16, chunkZ + 11, Blocks.log, 1, 2);
                world.setBlock(chunkX + 9, j + 16, chunkZ + 11, Blocks.log, 1, 2);
                world.setBlock(chunkX + 5, j + 16, chunkZ + 12, Blocks.log, 1, 2);
                world.setBlock(chunkX + 6, j + 16, chunkZ + 12, Blocks.log, 1, 2);
                world.setBlock(chunkX + 7, j + 16, chunkZ + 12, Blocks.log, 1, 2);
                world.setBlock(chunkX + 8, j + 16, chunkZ + 12, Blocks.log, 1, 2);
                world.setBlock(chunkX + 6, j + 16, chunkZ + 13, Blocks.log, 1, 2);
                world.setBlock(chunkX + 7, j + 16, chunkZ + 13, Blocks.log, 1, 2);
                world.setBlock(chunkX + 7, j + 17, chunkZ + 2, Blocks.log, 9, 2);
                world.setBlock(chunkX + 7, j + 17, chunkZ + 3, Blocks.log, 9, 2);
                world.setBlock(chunkX + 8, j + 17, chunkZ + 3, Blocks.log, 9, 2);
                world.setBlock(chunkX + 6, j + 17, chunkZ + 4, Blocks.log, 9, 2);
                world.setBlock(chunkX + 8, j + 17, chunkZ + 4, Blocks.log, 9, 2);
                world.setBlock(chunkX + 6, j + 17, chunkZ + 5, Blocks.log, 9, 2);
                world.setBlock(chunkX + 7, j + 17, chunkZ + 5, Blocks.log, 9, 2);
                world.setBlock(chunkX + 8, j + 17, chunkZ + 5, Blocks.log, 9, 2);
                world.setBlock(chunkX + 7, j + 17, chunkZ + 6, Blocks.log, 9, 2);
                world.setBlock(chunkX + 7, j + 17, chunkZ + 7, Blocks.log, 9, 2);
                world.setBlock(chunkX + 6, j + 17, chunkZ + 8, Blocks.log, 1, 2);
                world.setBlock(chunkX + 7, j + 17, chunkZ + 8, Blocks.log, 1, 2);
                world.setBlock(chunkX + 8, j + 17, chunkZ + 8, Blocks.log, 1, 2);
                world.setBlock(chunkX + 5, j + 17, chunkZ + 9, Blocks.log, 1, 2);
                world.setBlock(chunkX + 6, j + 17, chunkZ + 9, Blocks.log, 1, 2);
                world.setBlock(chunkX + 7, j + 17, chunkZ + 9, Blocks.log, 1, 2);
                world.setBlock(chunkX + 8, j + 17, chunkZ + 9, Blocks.log, 1, 2);
                world.setBlock(chunkX + 9, j + 17, chunkZ + 9, Blocks.log, 1, 2);
                world.setBlock(chunkX + 5, j + 17, chunkZ + 10, Blocks.log, 1, 2);
                world.setBlock(chunkX + 6, j + 17, chunkZ + 10, Blocks.log, 1, 2);
                world.setBlock(chunkX + 7, j + 17, chunkZ + 10, Blocks.web, 0, 2);
                world.setBlock(chunkX + 8, j + 17, chunkZ + 10, Blocks.log, 1, 2);
                world.setBlock(chunkX + 9, j + 17, chunkZ + 10, Blocks.log, 1, 2);
                world.setBlock(chunkX + 5, j + 17, chunkZ + 11, Blocks.log, 1, 2);
                world.setBlock(chunkX + 6, j + 17, chunkZ + 11, Blocks.log, 1, 2);
                world.setBlock(chunkX + 7, j + 17, chunkZ + 11, Blocks.log, 1, 2);
                world.setBlock(chunkX + 8, j + 17, chunkZ + 11, Blocks.log, 1, 2);
                world.setBlock(chunkX + 9, j + 17, chunkZ + 11, Blocks.log, 1, 2);
                world.setBlock(chunkX + 6, j + 17, chunkZ + 12, Blocks.log, 1, 2);
                world.setBlock(chunkX + 7, j + 17, chunkZ + 12, Blocks.log, 1, 2);
                world.setBlock(chunkX + 8, j + 17, chunkZ + 12, Blocks.log, 1, 2);
                world.setBlock(chunkX + 7, j + 18, chunkZ + 4, Blocks.log, 9, 2);
                world.setBlock(chunkX + 7, j + 18, chunkZ + 5, Blocks.log, 9, 2);
                world.setBlock(chunkX + 7, j + 18, chunkZ + 6, Blocks.log, 9, 2);
                world.setBlock(chunkX + 7, j + 18, chunkZ + 8, Blocks.log, 1, 2);
                world.setBlock(chunkX + 8, j + 18, chunkZ + 8, Blocks.log, 1, 2);
                world.setBlock(chunkX + 6, j + 18, chunkZ + 9, Blocks.log, 1, 2);
                world.setBlock(chunkX + 7, j + 18, chunkZ + 9, Blocks.log, 1, 2);
                world.setBlock(chunkX + 8, j + 18, chunkZ + 9, Blocks.log, 1, 2);
                world.setBlock(chunkX + 5, j + 18, chunkZ + 10, Blocks.log, 1, 2);
                world.setBlock(chunkX + 6, j + 18, chunkZ + 10, Blocks.log, 1, 2);
                world.setBlock(chunkX + 7, j + 18, chunkZ + 10, Blocks.web, 0, 2);
                world.setBlock(chunkX + 8, j + 18, chunkZ + 10, Blocks.log, 1, 2);
                world.setBlock(chunkX + 5, j + 18, chunkZ + 11, Blocks.log, 1, 2);
                world.setBlock(chunkX + 6, j + 18, chunkZ + 11, Blocks.log, 1, 2);
                world.setBlock(chunkX + 7, j + 18, chunkZ + 11, Blocks.log, 1, 2);
                world.setBlock(chunkX + 8, j + 18, chunkZ + 11, Blocks.log, 1, 2);
                world.setBlock(chunkX + 9, j + 18, chunkZ + 11, Blocks.log, 1, 2);
                world.setBlock(chunkX + 6, j + 18, chunkZ + 12, Blocks.log, 1, 2);
                world.setBlock(chunkX + 7, j + 18, chunkZ + 12, Blocks.log, 1, 2);
                world.setBlock(chunkX + 8, j + 19, chunkZ + 8, Blocks.log, 1, 2);
                world.setBlock(chunkX + 7, j + 19, chunkZ + 9, Blocks.log, 1, 2);
                world.setBlock(chunkX + 6, j + 19, chunkZ + 10, Blocks.log, 1, 2);
                world.setBlock(chunkX + 7, j + 19, chunkZ + 10, Blocks.web, 0, 2);
                world.setBlock(chunkX + 8, j + 19, chunkZ + 10, Blocks.log, 1, 2);
                world.setBlock(chunkX + 5, j + 19, chunkZ + 11, Blocks.log, 1, 2);
                world.setBlock(chunkX + 6, j + 19, chunkZ + 11, Blocks.log, 1, 2);
                world.setBlock(chunkX + 7, j + 19, chunkZ + 11, Blocks.log, 1, 2);
                world.setBlock(chunkX + 8, j + 19, chunkZ + 11, Blocks.log, 1, 2);
                world.setBlock(chunkX + 6, j + 19, chunkZ + 12, Blocks.log, 1, 2);
                world.setBlock(chunkX + 7, j + 19, chunkZ + 12, Blocks.log, 1, 2);
                world.setBlock(chunkX + 5, j + 20, chunkZ + 11, Blocks.log, 1, 2);
                world.setBlock(chunkX + 6, j + 20, chunkZ + 11, Blocks.log, 1, 2);
                world.setBlock(chunkX + 7, j + 20, chunkZ + 11, Blocks.log, 1, 2);
                world.setBlock(chunkX + 8, j + 20, chunkZ + 11, Blocks.log, 1, 2);
                world.setBlock(chunkX + 6, j + 20, chunkZ + 12, Blocks.log, 1, 2);
                world.setBlock(chunkX + 6, j + 21, chunkZ + 11, Blocks.log, 1, 2);
                world.setBlock(chunkX + 6, j + 22, chunkZ + 11, Blocks.log, 1, 2);
                System.out.println("Successfully built a forest dungeon at (" + x3 + ", " + y3 + ", " + z3 + ")");
            }
        }
    }

    @Override
    protected void func_143012_a(NBTTagCompound p_143012_1_) {

    }

    @Override
    protected void func_143011_b(NBTTagCompound p_143011_1_) {

    }

    public boolean addComponentParts(final World world, final Random r, final StructureBoundingBox box) {
        this.generateSurface(world, r, this.coordBaseMode, this.coordBaseMode, this.coordBaseMode);
        return true;
    }
    
    protected void writeStructureToNBT(final NBTTagCompound p_143012_1_) {
    }
    
    protected void readStructureFromNBT(final NBTTagCompound p_143011_1_) {
    }
}
