package apocalypse.fandomcraft.structures;

import net.minecraft.world.*;
import java.util.*;
import net.minecraft.init.*;
import net.minecraft.block.*;
import net.minecraftforge.common.*;
import net.minecraft.util.*;
import net.minecraft.inventory.*;
import apocalypse.fandomcraft.main.*;
import net.minecraft.tileentity.*;
import net.minecraft.world.gen.structure.*;
import net.minecraft.nbt.*;

public class DungeonSky extends StructureComponent
{
    public boolean place;
    
    public void generateStart(final World world, final Random random, final int chunkX, final int chunkY, final int chunkZ) {
        final int h = world.getHeightValue(chunkX, chunkZ) + 20;
        final int r = random.nextInt(50);
        final int y = 200 - r;
        this.place = true;
        if (this.place && y < 200 && y > h) {
            world.setBlock(chunkX + 4, y + 1, chunkZ + 5, Blocks.vine, 8, 2);
            world.setBlock(chunkX + 5, y + 1, chunkZ + 8, Blocks.vine, 8, 2);
            world.setBlock(chunkX + 6, y + 1, chunkZ + 9, Blocks.vine, 4, 2);
            world.setBlock(chunkX + 4, y + 2, chunkZ + 5, Blocks.vine, 8, 2);
            world.setBlock(chunkX + 6, y + 2, chunkZ + 6, Blocks.stone, 0, 2);
            world.setBlock(chunkX + 7, y + 2, chunkZ + 6, Blocks.stone, 0, 2);
            world.setBlock(chunkX + 8, y + 2, chunkZ + 6, Blocks.stone, 0, 2);
            world.setBlock(chunkX + 6, y + 2, chunkZ + 7, Blocks.stone, 0, 2);
            world.setBlock(chunkX + 7, y + 2, chunkZ + 7, Blocks.stone, 0, 2);
            world.setBlock(chunkX + 8, y + 2, chunkZ + 7, Blocks.stone, 0, 2);
            world.setBlock(chunkX + 5, y + 2, chunkZ + 8, Blocks.vine, 8, 2);
            world.setBlock(chunkX + 6, y + 2, chunkZ + 8, Blocks.stone, 0, 2);
            world.setBlock(chunkX + 7, y + 2, chunkZ + 8, Blocks.stone, 0, 2);
            world.setBlock(chunkX + 8, y + 2, chunkZ + 8, Blocks.stone, 0, 2);
            world.setBlock(chunkX + 6, y + 2, chunkZ + 9, Blocks.vine, 4, 2);
            world.setBlock(chunkX + 9, y + 2, chunkZ + 10, Blocks.vine, 2, 2);
            world.setBlock(chunkX + 6, y + 3, chunkZ + 4, Blocks.stone, 0, 2);
            world.setBlock(chunkX + 7, y + 3, chunkZ + 4, Blocks.stone, 0, 2);
            world.setBlock(chunkX + 8, y + 3, chunkZ + 4, Blocks.stone, 0, 2);
            world.setBlock(chunkX + 4, y + 3, chunkZ + 5, Blocks.vine, 8, 2);
            world.setBlock(chunkX + 5, y + 3, chunkZ + 5, Blocks.stone, 0, 2);
            world.setBlock(chunkX + 6, y + 3, chunkZ + 5, Blocks.stone, 0, 2);
            world.setBlock(chunkX + 7, y + 3, chunkZ + 5, Blocks.stone, 0, 2);
            world.setBlock(chunkX + 8, y + 3, chunkZ + 5, Blocks.stone, 0, 2);
            world.setBlock(chunkX + 9, y + 3, chunkZ + 5, Blocks.stone, 0, 2);
            world.setBlock(chunkX + 4, y + 3, chunkZ + 6, Blocks.stone, 0, 2);
            world.setBlock(chunkX + 5, y + 3, chunkZ + 6, Blocks.stone, 0, 2);
            world.setBlock(chunkX + 6, y + 3, chunkZ + 6, Blocks.stone, 0, 2);
            world.setBlock(chunkX + 7, y + 3, chunkZ + 6, Blocks.stone, 0, 2);
            world.setBlock(chunkX + 8, y + 3, chunkZ + 6, Blocks.stone, 0, 2);
            world.setBlock(chunkX + 9, y + 3, chunkZ + 6, Blocks.stone, 0, 2);
            world.setBlock(chunkX + 10, y + 3, chunkZ + 6, Blocks.stone, 0, 2);
            world.setBlock(chunkX + 4, y + 3, chunkZ + 7, Blocks.stone, 0, 2);
            world.setBlock(chunkX + 5, y + 3, chunkZ + 7, Blocks.stone, 0, 2);
            world.setBlock(chunkX + 6, y + 3, chunkZ + 7, Blocks.stone, 0, 2);
            world.setBlock(chunkX + 7, y + 3, chunkZ + 7, Blocks.stone, 0, 2);
            world.setBlock(chunkX + 8, y + 3, chunkZ + 7, Blocks.stone, 0, 2);
            world.setBlock(chunkX + 9, y + 3, chunkZ + 7, Blocks.stone, 0, 2);
            world.setBlock(chunkX + 10, y + 3, chunkZ + 7, Blocks.stone, 0, 2);
            world.setBlock(chunkX + 4, y + 3, chunkZ + 8, Blocks.stone, 0, 2);
            world.setBlock(chunkX + 5, y + 3, chunkZ + 8, Blocks.stone, 0, 2);
            world.setBlock(chunkX + 6, y + 3, chunkZ + 8, Blocks.stone, 0, 2);
            world.setBlock(chunkX + 7, y + 3, chunkZ + 8, Blocks.stone, 0, 2);
            world.setBlock(chunkX + 8, y + 3, chunkZ + 8, Blocks.stone, 0, 2);
            world.setBlock(chunkX + 9, y + 3, chunkZ + 8, Blocks.stone, 0, 2);
            world.setBlock(chunkX + 10, y + 3, chunkZ + 8, Blocks.stone, 0, 2);
            world.setBlock(chunkX + 5, y + 3, chunkZ + 9, Blocks.stone, 0, 2);
            world.setBlock(chunkX + 6, y + 3, chunkZ + 9, Blocks.stone, 0, 2);
            world.setBlock(chunkX + 7, y + 3, chunkZ + 9, Blocks.stone, 0, 2);
            world.setBlock(chunkX + 8, y + 3, chunkZ + 9, Blocks.stone, 0, 2);
            world.setBlock(chunkX + 9, y + 3, chunkZ + 9, Blocks.stone, 0, 2);
            world.setBlock(chunkX + 10, y + 3, chunkZ + 9, Blocks.vine, 2, 2);
            world.setBlock(chunkX + 11, y + 3, chunkZ + 9, Blocks.vine, 2, 2);
            world.setBlock(chunkX + 6, y + 3, chunkZ + 10, Blocks.stone, 0, 2);
            world.setBlock(chunkX + 7, y + 3, chunkZ + 10, Blocks.stone, 0, 2);
            world.setBlock(chunkX + 8, y + 3, chunkZ + 10, Blocks.stone, 0, 2);
            world.setBlock(chunkX + 9, y + 3, chunkZ + 10, Blocks.vine, 2, 2);
            world.setBlock(chunkX + 6, y + 3, chunkZ + 11, Blocks.vine, 4, 2);
            world.setBlock(chunkX + 6, y + 4, chunkZ + 3, Blocks.stone, 0, 2);
            world.setBlock(chunkX + 7, y + 4, chunkZ + 3, Blocks.stone, 0, 2);
            world.setBlock(chunkX + 8, y + 4, chunkZ + 3, Blocks.stone, 0, 2);
            world.setBlock(chunkX + 4, y + 4, chunkZ + 4, Blocks.stone, 0, 2);
            world.setBlock(chunkX + 5, y + 4, chunkZ + 4, Blocks.stone, 0, 2);
            world.setBlock(chunkX + 6, y + 4, chunkZ + 4, Blocks.stone, 0, 2);
            world.setBlock(chunkX + 7, y + 4, chunkZ + 4, Blocks.stone, 0, 2);
            world.setBlock(chunkX + 8, y + 4, chunkZ + 4, Blocks.stone, 0, 2);
            world.setBlock(chunkX + 9, y + 4, chunkZ + 4, Blocks.stone, 0, 2);
            world.setBlock(chunkX + 10, y + 4, chunkZ + 4, Blocks.stone, 0, 2);
            world.setBlock(chunkX + 4, y + 4, chunkZ + 5, Blocks.stone, 0, 2);
            world.setBlock(chunkX + 5, y + 4, chunkZ + 5, Blocks.stone, 0, 2);
            world.setBlock(chunkX + 6, y + 4, chunkZ + 5, Blocks.stone, 0, 2);
            world.setBlock(chunkX + 7, y + 4, chunkZ + 5, Blocks.stone, 0, 2);
            world.setBlock(chunkX + 8, y + 4, chunkZ + 5, Blocks.stone, 0, 2);
            world.setBlock(chunkX + 9, y + 4, chunkZ + 5, Blocks.stone, 0, 2);
            world.setBlock(chunkX + 10, y + 4, chunkZ + 5, Blocks.stone, 0, 2);
            world.setBlock(chunkX + 11, y + 4, chunkZ + 5, Blocks.vine, 1, 2);
            world.setBlock(chunkX + 3, y + 4, chunkZ + 6, Blocks.stone, 0, 2);
            world.setBlock(chunkX + 4, y + 4, chunkZ + 6, Blocks.stone, 0, 2);
            world.setBlock(chunkX + 5, y + 4, chunkZ + 6, Blocks.stone, 0, 2);
            world.setBlock(chunkX + 6, y + 4, chunkZ + 6, Blocks.stone, 0, 2);
            world.setBlock(chunkX + 7, y + 4, chunkZ + 6, Blocks.stone, 0, 2);
            world.setBlock(chunkX + 8, y + 4, chunkZ + 6, Blocks.stone, 0, 2);
            world.setBlock(chunkX + 9, y + 4, chunkZ + 6, Blocks.stone, 0, 2);
            world.setBlock(chunkX + 10, y + 4, chunkZ + 6, Blocks.stone, 0, 2);
            world.setBlock(chunkX + 11, y + 4, chunkZ + 6, Blocks.stone, 0, 2);
            world.setBlock(chunkX + 12, y + 4, chunkZ + 6, Blocks.vine, 2, 2);
            world.setBlock(chunkX + 3, y + 4, chunkZ + 7, Blocks.stone, 0, 2);
            world.setBlock(chunkX + 4, y + 4, chunkZ + 7, Blocks.stone, 0, 2);
            world.setBlock(chunkX + 5, y + 4, chunkZ + 7, Blocks.stone, 0, 2);
            world.setBlock(chunkX + 6, y + 4, chunkZ + 7, Blocks.stone, 0, 2);
            world.setBlock(chunkX + 7, y + 4, chunkZ + 7, Blocks.stone, 0, 2);
            world.setBlock(chunkX + 8, y + 4, chunkZ + 7, Blocks.stone, 0, 2);
            world.setBlock(chunkX + 9, y + 4, chunkZ + 7, Blocks.stone, 0, 2);
            world.setBlock(chunkX + 10, y + 4, chunkZ + 7, Blocks.stone, 0, 2);
            world.setBlock(chunkX + 11, y + 4, chunkZ + 7, Blocks.stone, 0, 2);
            world.setBlock(chunkX + 3, y + 4, chunkZ + 8, Blocks.stone, 0, 2);
            world.setBlock(chunkX + 4, y + 4, chunkZ + 8, Blocks.stone, 0, 2);
            world.setBlock(chunkX + 5, y + 4, chunkZ + 8, Blocks.stone, 0, 2);
            world.setBlock(chunkX + 6, y + 4, chunkZ + 8, Blocks.stone, 0, 2);
            world.setBlock(chunkX + 7, y + 4, chunkZ + 8, Blocks.stone, 0, 2);
            world.setBlock(chunkX + 8, y + 4, chunkZ + 8, Blocks.stone, 0, 2);
            world.setBlock(chunkX + 9, y + 4, chunkZ + 8, Blocks.stone, 0, 2);
            world.setBlock(chunkX + 10, y + 4, chunkZ + 8, Blocks.stone, 0, 2);
            world.setBlock(chunkX + 11, y + 4, chunkZ + 8, Blocks.stone, 0, 2);
            world.setBlock(chunkX + 3, y + 4, chunkZ + 9, Blocks.vine, 4, 2);
            world.setBlock(chunkX + 4, y + 4, chunkZ + 9, Blocks.stone, 0, 2);
            world.setBlock(chunkX + 5, y + 4, chunkZ + 9, Blocks.stone, 0, 2);
            world.setBlock(chunkX + 6, y + 4, chunkZ + 9, Blocks.stone, 0, 2);
            world.setBlock(chunkX + 7, y + 4, chunkZ + 9, Blocks.stone, 0, 2);
            world.setBlock(chunkX + 8, y + 4, chunkZ + 9, Blocks.stone, 0, 2);
            world.setBlock(chunkX + 9, y + 4, chunkZ + 9, Blocks.stone, 0, 2);
            world.setBlock(chunkX + 10, y + 4, chunkZ + 9, Blocks.stone, 0, 2);
            world.setBlock(chunkX + 11, y + 4, chunkZ + 9, Blocks.vine, 2, 2);
            world.setBlock(chunkX + 4, y + 4, chunkZ + 10, Blocks.stone, 0, 2);
            world.setBlock(chunkX + 5, y + 4, chunkZ + 10, Blocks.stone, 0, 2);
            world.setBlock(chunkX + 6, y + 4, chunkZ + 10, Blocks.stone, 0, 2);
            world.setBlock(chunkX + 7, y + 4, chunkZ + 10, Blocks.stone, 0, 2);
            world.setBlock(chunkX + 8, y + 4, chunkZ + 10, Blocks.stone, 0, 2);
            world.setBlock(chunkX + 9, y + 4, chunkZ + 10, Blocks.stone, 0, 2);
            world.setBlock(chunkX + 10, y + 4, chunkZ + 10, Blocks.stone, 0, 2);
            world.setBlock(chunkX + 6, y + 4, chunkZ + 11, Blocks.stone, 0, 2);
            world.setBlock(chunkX + 7, y + 4, chunkZ + 11, Blocks.stone, 0, 2);
            world.setBlock(chunkX + 8, y + 4, chunkZ + 11, Blocks.stone, 0, 2);
            world.setBlock(chunkX + 12, y + 4, chunkZ + 12, Blocks.vine, 2, 2);
            world.setBlock(chunkX + 2, y + 5, chunkZ + 3, Blocks.vine, 8, 2);
            world.setBlock(chunkX + 5, y + 5, chunkZ + 3, Blocks.stone, 0, 2);
            world.setBlock(chunkX + 6, y + 5, chunkZ + 3, Blocks.stone, 0, 2);
            world.setBlock(chunkX + 7, y + 5, chunkZ + 3, Blocks.stone, 0, 2);
            world.setBlock(chunkX + 8, y + 5, chunkZ + 3, Blocks.stone, 0, 2);
            world.setBlock(chunkX + 9, y + 5, chunkZ + 3, Blocks.stone, 0, 2);
            world.setBlock(chunkX + 4, y + 5, chunkZ + 4, Blocks.stone, 0, 2);
            world.setBlock(chunkX + 5, y + 5, chunkZ + 4, Blocks.stone, 0, 2);
            world.setBlock(chunkX + 6, y + 5, chunkZ + 4, Blocks.stone, 0, 2);
            world.setBlock(chunkX + 7, y + 5, chunkZ + 4, Blocks.stone, 0, 2);
            world.setBlock(chunkX + 8, y + 5, chunkZ + 4, Blocks.stone, 0, 2);
            world.setBlock(chunkX + 9, y + 5, chunkZ + 4, Blocks.stone, 0, 2);
            world.setBlock(chunkX + 10, y + 5, chunkZ + 4, Blocks.stone, 0, 2);
            world.setBlock(chunkX + 3, y + 5, chunkZ + 5, Blocks.stone, 0, 2);
            world.setBlock(chunkX + 4, y + 5, chunkZ + 5, Blocks.stone, 0, 2);
            world.setBlock(chunkX + 5, y + 5, chunkZ + 5, Blocks.stone, 0, 2);
            world.setBlock(chunkX + 6, y + 5, chunkZ + 5, Blocks.stone, 0, 2);
            world.setBlock(chunkX + 7, y + 5, chunkZ + 5, Blocks.stone, 0, 2);
            world.setBlock(chunkX + 8, y + 5, chunkZ + 5, Blocks.stone, 0, 2);
            world.setBlock(chunkX + 9, y + 5, chunkZ + 5, Blocks.stone, 0, 2);
            world.setBlock(chunkX + 10, y + 5, chunkZ + 5, Blocks.stone, 0, 2);
            world.setBlock(chunkX + 11, y + 5, chunkZ + 5, Blocks.stone, 0, 2);
            world.setBlock(chunkX + 3, y + 5, chunkZ + 6, Blocks.stone, 0, 2);
            world.setBlock(chunkX + 4, y + 5, chunkZ + 6, Blocks.stone, 0, 2);
            world.setBlock(chunkX + 5, y + 5, chunkZ + 6, Blocks.stone, 0, 2);
            world.setBlock(chunkX + 6, y + 5, chunkZ + 6, Blocks.stone, 0, 2);
            world.setBlock(chunkX + 7, y + 5, chunkZ + 6, Blocks.stone, 0, 2);
            world.setBlock(chunkX + 8, y + 5, chunkZ + 6, Blocks.stone, 0, 2);
            world.setBlock(chunkX + 9, y + 5, chunkZ + 6, Blocks.stone, 0, 2);
            world.setBlock(chunkX + 10, y + 5, chunkZ + 6, Blocks.stone, 0, 2);
            world.setBlock(chunkX + 11, y + 5, chunkZ + 6, Blocks.stone, 0, 2);
            world.setBlock(chunkX + 3, y + 5, chunkZ + 7, Blocks.stone, 0, 2);
            world.setBlock(chunkX + 4, y + 5, chunkZ + 7, Blocks.stone, 0, 2);
            world.setBlock(chunkX + 5, y + 5, chunkZ + 7, Blocks.stone, 0, 2);
            world.setBlock(chunkX + 6, y + 5, chunkZ + 7, Blocks.stone, 0, 2);
            world.setBlock(chunkX + 7, y + 5, chunkZ + 7, Blocks.stone, 0, 2);
            world.setBlock(chunkX + 8, y + 5, chunkZ + 7, Blocks.stone, 0, 2);
            world.setBlock(chunkX + 9, y + 5, chunkZ + 7, Blocks.stone, 0, 2);
            world.setBlock(chunkX + 10, y + 5, chunkZ + 7, Blocks.stone, 0, 2);
            world.setBlock(chunkX + 11, y + 5, chunkZ + 7, Blocks.stone, 0, 2);
            world.setBlock(chunkX + 3, y + 5, chunkZ + 8, Blocks.stone, 0, 2);
            world.setBlock(chunkX + 4, y + 5, chunkZ + 8, Blocks.stone, 0, 2);
            world.setBlock(chunkX + 5, y + 5, chunkZ + 8, Blocks.stone, 0, 2);
            world.setBlock(chunkX + 6, y + 5, chunkZ + 8, Blocks.stone, 0, 2);
            world.setBlock(chunkX + 7, y + 5, chunkZ + 8, Blocks.stone, 0, 2);
            world.setBlock(chunkX + 8, y + 5, chunkZ + 8, Blocks.stone, 0, 2);
            world.setBlock(chunkX + 9, y + 5, chunkZ + 8, Blocks.stone, 0, 2);
            world.setBlock(chunkX + 10, y + 5, chunkZ + 8, Blocks.stone, 0, 2);
            world.setBlock(chunkX + 11, y + 5, chunkZ + 8, Blocks.stone, 0, 2);
            world.setBlock(chunkX + 3, y + 5, chunkZ + 9, Blocks.stone, 0, 2);
            world.setBlock(chunkX + 4, y + 5, chunkZ + 9, Blocks.stone, 0, 2);
            world.setBlock(chunkX + 5, y + 5, chunkZ + 9, Blocks.stone, 0, 2);
            world.setBlock(chunkX + 6, y + 5, chunkZ + 9, Blocks.stone, 0, 2);
            world.setBlock(chunkX + 7, y + 5, chunkZ + 9, Blocks.stone, 0, 2);
            world.setBlock(chunkX + 8, y + 5, chunkZ + 9, Blocks.stone, 0, 2);
            world.setBlock(chunkX + 9, y + 5, chunkZ + 9, Blocks.stone, 0, 2);
            world.setBlock(chunkX + 10, y + 5, chunkZ + 9, Blocks.stone, 0, 2);
            world.setBlock(chunkX + 11, y + 5, chunkZ + 9, Blocks.stone, 0, 2);
            world.setBlock(chunkX + 4, y + 5, chunkZ + 10, Blocks.stone, 0, 2);
            world.setBlock(chunkX + 5, y + 5, chunkZ + 10, Blocks.stone, 0, 2);
            world.setBlock(chunkX + 6, y + 5, chunkZ + 10, Blocks.stone, 0, 2);
            world.setBlock(chunkX + 7, y + 5, chunkZ + 10, Blocks.stone, 0, 2);
            world.setBlock(chunkX + 8, y + 5, chunkZ + 10, Blocks.stone, 0, 2);
            world.setBlock(chunkX + 9, y + 5, chunkZ + 10, Blocks.stone, 0, 2);
            world.setBlock(chunkX + 10, y + 5, chunkZ + 10, Blocks.stone, 0, 2);
            world.setBlock(chunkX + 5, y + 5, chunkZ + 11, Blocks.stone, 0, 2);
            world.setBlock(chunkX + 6, y + 5, chunkZ + 11, Blocks.stone, 0, 2);
            world.setBlock(chunkX + 7, y + 5, chunkZ + 11, Blocks.stone, 0, 2);
            world.setBlock(chunkX + 8, y + 5, chunkZ + 11, Blocks.stone, 0, 2);
            world.setBlock(chunkX + 9, y + 5, chunkZ + 11, Blocks.stone, 0, 2);
            world.setBlock(chunkX + 10, y + 5, chunkZ + 11, Blocks.stone, 0, 2);
            world.setBlock(chunkX + 12, y + 5, chunkZ + 12, Blocks.vine, 2, 2);
            world.setBlock(chunkX + 7, y + 6, chunkZ + 0, Blocks.vine, 1, 2);
            world.setBlock(chunkX + 5, y + 6, chunkZ + 2, Blocks.stone, 0, 2);
            world.setBlock(chunkX + 6, y + 6, chunkZ + 2, Blocks.stone, 0, 2);
            world.setBlock(chunkX + 7, y + 6, chunkZ + 2, Blocks.stone, 0, 2);
            world.setBlock(chunkX + 8, y + 6, chunkZ + 2, Blocks.stone, 0, 2);
            world.setBlock(chunkX + 9, y + 6, chunkZ + 2, Blocks.stone, 0, 2);
            world.setBlock(chunkX + 2, y + 6, chunkZ + 3, Blocks.vine, 8, 2);
            world.setBlock(chunkX + 4, y + 6, chunkZ + 3, Blocks.stone, 0, 2);
            world.setBlock(chunkX + 5, y + 6, chunkZ + 3, Blocks.stone, 0, 2);
            world.setBlock(chunkX + 6, y + 6, chunkZ + 3, Blocks.stone, 0, 2);
            world.setBlock(chunkX + 7, y + 6, chunkZ + 3, Blocks.stone, 0, 2);
            world.setBlock(chunkX + 8, y + 6, chunkZ + 3, Blocks.stone, 0, 2);
            world.setBlock(chunkX + 9, y + 6, chunkZ + 3, Blocks.stone, 0, 2);
            world.setBlock(chunkX + 10, y + 6, chunkZ + 3, Blocks.stone, 0, 2);
            world.setBlock(chunkX + 3, y + 6, chunkZ + 4, Blocks.stone, 0, 2);
            world.setBlock(chunkX + 4, y + 6, chunkZ + 4, Blocks.stone, 0, 2);
            world.setBlock(chunkX + 5, y + 6, chunkZ + 4, Blocks.stone, 0, 2);
            world.setBlock(chunkX + 6, y + 6, chunkZ + 4, Blocks.stone, 0, 2);
            world.setBlock(chunkX + 7, y + 6, chunkZ + 4, Blocks.stone, 0, 2);
            world.setBlock(chunkX + 8, y + 6, chunkZ + 4, Blocks.stone, 0, 2);
            world.setBlock(chunkX + 9, y + 6, chunkZ + 4, Blocks.stone, 0, 2);
            world.setBlock(chunkX + 10, y + 6, chunkZ + 4, Blocks.stone, 0, 2);
            world.setBlock(chunkX + 11, y + 6, chunkZ + 4, Blocks.stone, 0, 2);
            world.setBlock(chunkX + 2, y + 6, chunkZ + 5, Blocks.stone, 0, 2);
            world.setBlock(chunkX + 3, y + 6, chunkZ + 5, Blocks.stone, 0, 2);
            world.setBlock(chunkX + 4, y + 6, chunkZ + 5, Blocks.stone, 0, 2);
            world.setBlock(chunkX + 5, y + 6, chunkZ + 5, Blocks.stone, 0, 2);
            world.setBlock(chunkX + 6, y + 6, chunkZ + 5, Blocks.stone, 0, 2);
            world.setBlock(chunkX + 7, y + 6, chunkZ + 5, Blocks.stone, 0, 2);
            world.setBlock(chunkX + 8, y + 6, chunkZ + 5, Blocks.stone, 0, 2);
            world.setBlock(chunkX + 9, y + 6, chunkZ + 5, Blocks.stone, 0, 2);
            world.setBlock(chunkX + 10, y + 6, chunkZ + 5, Blocks.stone, 0, 2);
            world.setBlock(chunkX + 11, y + 6, chunkZ + 5, Blocks.stone, 0, 2);
            world.setBlock(chunkX + 12, y + 6, chunkZ + 5, Blocks.stone, 0, 2);
            world.setBlock(chunkX + 2, y + 6, chunkZ + 6, Blocks.stone, 0, 2);
            world.setBlock(chunkX + 3, y + 6, chunkZ + 6, Blocks.stone, 0, 2);
            world.setBlock(chunkX + 4, y + 6, chunkZ + 6, Blocks.stone, 0, 2);
            world.setBlock(chunkX + 5, y + 6, chunkZ + 6, Blocks.stone, 0, 2);
            world.setBlock(chunkX + 6, y + 6, chunkZ + 6, Blocks.stone, 0, 2);
            world.setBlock(chunkX + 7, y + 6, chunkZ + 6, Blocks.stone, 0, 2);
            world.setBlock(chunkX + 8, y + 6, chunkZ + 6, Blocks.stone, 0, 2);
            world.setBlock(chunkX + 9, y + 6, chunkZ + 6, Blocks.stone, 0, 2);
            world.setBlock(chunkX + 10, y + 6, chunkZ + 6, Blocks.stone, 0, 2);
            world.setBlock(chunkX + 11, y + 6, chunkZ + 6, Blocks.stone, 0, 2);
            world.setBlock(chunkX + 12, y + 6, chunkZ + 6, Blocks.stone, 0, 2);
            world.setBlock(chunkX + 2, y + 6, chunkZ + 7, Blocks.stone, 0, 2);
            world.setBlock(chunkX + 3, y + 6, chunkZ + 7, Blocks.stone, 0, 2);
            world.setBlock(chunkX + 4, y + 6, chunkZ + 7, Blocks.stone, 0, 2);
            world.setBlock(chunkX + 5, y + 6, chunkZ + 7, Blocks.stone, 0, 2);
            world.setBlock(chunkX + 6, y + 6, chunkZ + 7, Blocks.stone, 0, 2);
            world.setBlock(chunkX + 7, y + 6, chunkZ + 7, Blocks.stone, 0, 2);
            world.setBlock(chunkX + 8, y + 6, chunkZ + 7, Blocks.stone, 0, 2);
            world.setBlock(chunkX + 9, y + 6, chunkZ + 7, Blocks.stone, 0, 2);
            world.setBlock(chunkX + 10, y + 6, chunkZ + 7, Blocks.stone, 0, 2);
            world.setBlock(chunkX + 11, y + 6, chunkZ + 7, Blocks.stone, 0, 2);
            world.setBlock(chunkX + 12, y + 6, chunkZ + 7, Blocks.stone, 0, 2);
            world.setBlock(chunkX + 2, y + 6, chunkZ + 8, Blocks.stone, 0, 2);
            world.setBlock(chunkX + 3, y + 6, chunkZ + 8, Blocks.stone, 0, 2);
            world.setBlock(chunkX + 4, y + 6, chunkZ + 8, Blocks.stone, 0, 2);
            world.setBlock(chunkX + 5, y + 6, chunkZ + 8, Blocks.stone, 0, 2);
            world.setBlock(chunkX + 6, y + 6, chunkZ + 8, Blocks.stone, 0, 2);
            world.setBlock(chunkX + 7, y + 6, chunkZ + 8, Blocks.stone, 0, 2);
            world.setBlock(chunkX + 8, y + 6, chunkZ + 8, Blocks.stone, 0, 2);
            world.setBlock(chunkX + 9, y + 6, chunkZ + 8, Blocks.stone, 0, 2);
            world.setBlock(chunkX + 10, y + 6, chunkZ + 8, Blocks.stone, 0, 2);
            world.setBlock(chunkX + 11, y + 6, chunkZ + 8, Blocks.stone, 0, 2);
            world.setBlock(chunkX + 12, y + 6, chunkZ + 8, Blocks.stone, 0, 2);
            world.setBlock(chunkX + 2, y + 6, chunkZ + 9, Blocks.stone, 0, 2);
            world.setBlock(chunkX + 3, y + 6, chunkZ + 9, Blocks.stone, 0, 2);
            world.setBlock(chunkX + 4, y + 6, chunkZ + 9, Blocks.stone, 0, 2);
            world.setBlock(chunkX + 5, y + 6, chunkZ + 9, Blocks.stone, 0, 2);
            world.setBlock(chunkX + 6, y + 6, chunkZ + 9, Blocks.stone, 0, 2);
            world.setBlock(chunkX + 7, y + 6, chunkZ + 9, Blocks.stone, 0, 2);
            world.setBlock(chunkX + 8, y + 6, chunkZ + 9, Blocks.stone, 0, 2);
            world.setBlock(chunkX + 9, y + 6, chunkZ + 9, Blocks.stone, 0, 2);
            world.setBlock(chunkX + 10, y + 6, chunkZ + 9, Blocks.stone, 0, 2);
            world.setBlock(chunkX + 11, y + 6, chunkZ + 9, Blocks.stone, 0, 2);
            world.setBlock(chunkX + 12, y + 6, chunkZ + 9, Blocks.stone, 0, 2);
            world.setBlock(chunkX + 3, y + 6, chunkZ + 10, Blocks.stone, 0, 2);
            world.setBlock(chunkX + 4, y + 6, chunkZ + 10, Blocks.stone, 0, 2);
            world.setBlock(chunkX + 5, y + 6, chunkZ + 10, Blocks.stone, 0, 2);
            world.setBlock(chunkX + 6, y + 6, chunkZ + 10, Blocks.stone, 0, 2);
            world.setBlock(chunkX + 7, y + 6, chunkZ + 10, Blocks.stone, 0, 2);
            world.setBlock(chunkX + 8, y + 6, chunkZ + 10, Blocks.stone, 0, 2);
            world.setBlock(chunkX + 9, y + 6, chunkZ + 10, Blocks.stone, 0, 2);
            world.setBlock(chunkX + 10, y + 6, chunkZ + 10, Blocks.stone, 0, 2);
            world.setBlock(chunkX + 11, y + 6, chunkZ + 10, Blocks.stone, 0, 2);
            world.setBlock(chunkX + 12, y + 6, chunkZ + 10, Blocks.stone, 0, 2);
            world.setBlock(chunkX + 2, y + 6, chunkZ + 11, Blocks.vine, 4, 2);
            world.setBlock(chunkX + 4, y + 6, chunkZ + 11, Blocks.stone, 0, 2);
            world.setBlock(chunkX + 5, y + 6, chunkZ + 11, Blocks.stone, 0, 2);
            world.setBlock(chunkX + 6, y + 6, chunkZ + 11, Blocks.stone, 0, 2);
            world.setBlock(chunkX + 7, y + 6, chunkZ + 11, Blocks.stone, 0, 2);
            world.setBlock(chunkX + 8, y + 6, chunkZ + 11, Blocks.stone, 0, 2);
            world.setBlock(chunkX + 9, y + 6, chunkZ + 11, Blocks.stone, 0, 2);
            world.setBlock(chunkX + 10, y + 6, chunkZ + 11, Blocks.stone, 0, 2);
            world.setBlock(chunkX + 5, y + 6, chunkZ + 12, Blocks.stone, 0, 2);
            world.setBlock(chunkX + 6, y + 6, chunkZ + 12, Blocks.stone, 0, 2);
            world.setBlock(chunkX + 7, y + 6, chunkZ + 12, Blocks.stone, 0, 2);
            world.setBlock(chunkX + 8, y + 6, chunkZ + 12, Blocks.stone, 0, 2);
            world.setBlock(chunkX + 9, y + 6, chunkZ + 12, Blocks.stone, 0, 2);
            world.setBlock(chunkX + 12, y + 6, chunkZ + 12, Blocks.vine, 2, 2);
            world.setBlock(chunkX + 7, y + 7, chunkZ + 0, Blocks.vine, 1, 2);
            world.setBlock(chunkX + 10, y + 7, chunkZ + 0, Blocks.vine, 1, 2);
            world.setBlock(chunkX + 4, y + 7, chunkZ + 2, Blocks.stone, 0, 2);
            world.setBlock(chunkX + 5, y + 7, chunkZ + 2, Blocks.stone, 0, 2);
            world.setBlock(chunkX + 6, y + 7, chunkZ + 2, Blocks.stone, 0, 2);
            world.setBlock(chunkX + 7, y + 7, chunkZ + 2, Blocks.stone, 0, 2);
            world.setBlock(chunkX + 8, y + 7, chunkZ + 2, Blocks.stone, 0, 2);
            world.setBlock(chunkX + 9, y + 7, chunkZ + 2, Blocks.stone, 0, 2);
            world.setBlock(chunkX + 10, y + 7, chunkZ + 2, Blocks.stone, 0, 2);
            world.setBlock(chunkX + 2, y + 7, chunkZ + 3, Blocks.vine, 8, 2);
            world.setBlock(chunkX + 3, y + 7, chunkZ + 3, Blocks.stone, 0, 2);
            world.setBlock(chunkX + 4, y + 7, chunkZ + 3, Blocks.stone, 0, 2);
            world.setBlock(chunkX + 5, y + 7, chunkZ + 3, Blocks.dirt, 0, 2);
            world.setBlock(chunkX + 6, y + 7, chunkZ + 3, Blocks.dirt, 0, 2);
            world.setBlock(chunkX + 7, y + 7, chunkZ + 3, Blocks.stone, 0, 2);
            world.setBlock(chunkX + 8, y + 7, chunkZ + 3, Blocks.dirt, 0, 2);
            world.setBlock(chunkX + 9, y + 7, chunkZ + 3, Blocks.dirt, 0, 2);
            world.setBlock(chunkX + 10, y + 7, chunkZ + 3, Blocks.stone, 0, 2);
            world.setBlock(chunkX + 11, y + 7, chunkZ + 3, Blocks.stone, 0, 2);
            world.setBlock(chunkX + 2, y + 7, chunkZ + 4, Blocks.stone, 0, 2);
            world.setBlock(chunkX + 3, y + 7, chunkZ + 4, Blocks.stone, 0, 2);
            world.setBlock(chunkX + 4, y + 7, chunkZ + 4, Blocks.dirt, 0, 2);
            world.setBlock(chunkX + 5, y + 7, chunkZ + 4, Blocks.dirt, 0, 2);
            world.setBlock(chunkX + 6, y + 7, chunkZ + 4, Blocks.dirt, 0, 2);
            world.setBlock(chunkX + 7, y + 7, chunkZ + 4, Blocks.dirt, 0, 2);
            world.setBlock(chunkX + 8, y + 7, chunkZ + 4, Blocks.dirt, 0, 2);
            world.setBlock(chunkX + 9, y + 7, chunkZ + 4, Blocks.dirt, 0, 2);
            world.setBlock(chunkX + 10, y + 7, chunkZ + 4, Blocks.dirt, 0, 2);
            world.setBlock(chunkX + 11, y + 7, chunkZ + 4, Blocks.stone, 0, 2);
            world.setBlock(chunkX + 12, y + 7, chunkZ + 4, Blocks.stone, 0, 2);
            world.setBlock(chunkX + 13, y + 7, chunkZ + 4, Blocks.vine, 2, 2);
            world.setBlock(chunkX + 2, y + 7, chunkZ + 5, Blocks.stone, 0, 2);
            world.setBlock(chunkX + 3, y + 7, chunkZ + 5, Blocks.stone, 0, 2);
            world.setBlock(chunkX + 4, y + 7, chunkZ + 5, Blocks.stone, 0, 2);
            world.setBlock(chunkX + 5, y + 7, chunkZ + 5, Blocks.dirt, 0, 2);
            world.setBlock(chunkX + 6, y + 7, chunkZ + 5, Blocks.dirt, 0, 2);
            world.setBlock(chunkX + 7, y + 7, chunkZ + 5, Blocks.stone, 0, 2);
            world.setBlock(chunkX + 8, y + 7, chunkZ + 5, Blocks.dirt, 0, 2);
            world.setBlock(chunkX + 9, y + 7, chunkZ + 5, Blocks.dirt, 0, 2);
            world.setBlock(chunkX + 10, y + 7, chunkZ + 5, Blocks.stone, 0, 2);
            world.setBlock(chunkX + 11, y + 7, chunkZ + 5, Blocks.stone, 0, 2);
            world.setBlock(chunkX + 12, y + 7, chunkZ + 5, Blocks.stone, 0, 2);
            world.setBlock(chunkX + 13, y + 7, chunkZ + 5, Blocks.vine, 2, 2);
            world.setBlock(chunkX + 2, y + 7, chunkZ + 6, Blocks.stone, 0, 2);
            world.setBlock(chunkX + 3, y + 7, chunkZ + 6, Blocks.stone, 0, 2);
            world.setBlock(chunkX + 4, y + 7, chunkZ + 6, Blocks.dirt, 0, 2);
            world.setBlock(chunkX + 5, y + 7, chunkZ + 6, Blocks.dirt, 0, 2);
            world.setBlock(chunkX + 6, y + 7, chunkZ + 6, Blocks.stone, 0, 2);
            world.setBlock(chunkX + 7, y + 7, chunkZ + 6, Blocks.stone, 0, 2);
            world.setBlock(chunkX + 8, y + 7, chunkZ + 6, Blocks.dirt, 0, 2);
            world.setBlock(chunkX + 9, y + 7, chunkZ + 6, Blocks.dirt, 0, 2);
            world.setBlock(chunkX + 10, y + 7, chunkZ + 6, Blocks.dirt, 0, 2);
            world.setBlock(chunkX + 11, y + 7, chunkZ + 6, Blocks.stone, 0, 2);
            world.setBlock(chunkX + 12, y + 7, chunkZ + 6, Blocks.stone, 0, 2);
            world.setBlock(chunkX + 2, y + 7, chunkZ + 7, Blocks.stone, 0, 2);
            world.setBlock(chunkX + 3, y + 7, chunkZ + 7, Blocks.stone, 0, 2);
            world.setBlock(chunkX + 4, y + 7, chunkZ + 7, Blocks.dirt, 0, 2);
            world.setBlock(chunkX + 5, y + 7, chunkZ + 7, Blocks.dirt, 0, 2);
            world.setBlock(chunkX + 6, y + 7, chunkZ + 7, Blocks.dirt, 0, 2);
            world.setBlock(chunkX + 7, y + 7, chunkZ + 7, Blocks.dirt, 0, 2);
            world.setBlock(chunkX + 8, y + 7, chunkZ + 7, Blocks.dirt, 0, 2);
            world.setBlock(chunkX + 9, y + 7, chunkZ + 7, Blocks.dirt, 0, 2);
            world.setBlock(chunkX + 10, y + 7, chunkZ + 7, Blocks.stone, 0, 2);
            world.setBlock(chunkX + 11, y + 7, chunkZ + 7, Blocks.stone, 0, 2);
            world.setBlock(chunkX + 12, y + 7, chunkZ + 7, Blocks.stone, 0, 2);
            world.setBlock(chunkX + 14, y + 7, chunkZ + 7, Blocks.vine, 2, 2);
            world.setBlock(chunkX + 2, y + 7, chunkZ + 8, Blocks.stone, 0, 2);
            world.setBlock(chunkX + 3, y + 7, chunkZ + 8, Blocks.stone, 0, 2);
            world.setBlock(chunkX + 4, y + 7, chunkZ + 8, Blocks.dirt, 0, 2);
            world.setBlock(chunkX + 5, y + 7, chunkZ + 8, Blocks.stone, 0, 2);
            world.setBlock(chunkX + 6, y + 7, chunkZ + 8, Blocks.dirt, 0, 2);
            world.setBlock(chunkX + 7, y + 7, chunkZ + 8, Blocks.dirt, 0, 2);
            world.setBlock(chunkX + 8, y + 7, chunkZ + 8, Blocks.stone, 0, 2);
            world.setBlock(chunkX + 9, y + 7, chunkZ + 8, Blocks.dirt, 0, 2);
            world.setBlock(chunkX + 10, y + 7, chunkZ + 8, Blocks.dirt, 0, 2);
            world.setBlock(chunkX + 11, y + 7, chunkZ + 8, Blocks.stone, 0, 2);
            world.setBlock(chunkX + 12, y + 7, chunkZ + 8, Blocks.stone, 0, 2);
            world.setBlock(chunkX + 2, y + 7, chunkZ + 9, Blocks.stone, 0, 2);
            world.setBlock(chunkX + 3, y + 7, chunkZ + 9, Blocks.stone, 0, 2);
            world.setBlock(chunkX + 4, y + 7, chunkZ + 9, Blocks.stone, 0, 2);
            world.setBlock(chunkX + 5, y + 7, chunkZ + 9, Blocks.stone, 0, 2);
            world.setBlock(chunkX + 6, y + 7, chunkZ + 9, Blocks.stone, 0, 2);
            world.setBlock(chunkX + 7, y + 7, chunkZ + 9, Blocks.dirt, 0, 2);
            world.setBlock(chunkX + 8, y + 7, chunkZ + 9, Blocks.dirt, 0, 2);
            world.setBlock(chunkX + 9, y + 7, chunkZ + 9, Blocks.dirt, 0, 2);
            world.setBlock(chunkX + 10, y + 7, chunkZ + 9, Blocks.stone, 0, 2);
            world.setBlock(chunkX + 11, y + 7, chunkZ + 9, Blocks.stone, 0, 2);
            world.setBlock(chunkX + 12, y + 7, chunkZ + 9, Blocks.stone, 0, 2);
            world.setBlock(chunkX + 1, y + 7, chunkZ + 10, Blocks.vine, 8, 2);
            world.setBlock(chunkX + 2, y + 7, chunkZ + 10, Blocks.stone, 0, 2);
            world.setBlock(chunkX + 3, y + 7, chunkZ + 10, Blocks.stone, 0, 2);
            world.setBlock(chunkX + 4, y + 7, chunkZ + 10, Blocks.stone, 0, 2);
            world.setBlock(chunkX + 5, y + 7, chunkZ + 10, Blocks.stone, 0, 2);
            world.setBlock(chunkX + 6, y + 7, chunkZ + 10, Blocks.stone, 0, 2);
            world.setBlock(chunkX + 7, y + 7, chunkZ + 10, Blocks.stone, 0, 2);
            world.setBlock(chunkX + 8, y + 7, chunkZ + 10, Blocks.stone, 0, 2);
            world.setBlock(chunkX + 9, y + 7, chunkZ + 10, Blocks.stone, 0, 2);
            world.setBlock(chunkX + 10, y + 7, chunkZ + 10, Blocks.stone, 0, 2);
            world.setBlock(chunkX + 11, y + 7, chunkZ + 10, Blocks.stone, 0, 2);
            world.setBlock(chunkX + 12, y + 7, chunkZ + 10, Blocks.stone, 0, 2);
            world.setBlock(chunkX + 2, y + 7, chunkZ + 11, Blocks.vine, 12, 2);
            world.setBlock(chunkX + 3, y + 7, chunkZ + 11, Blocks.stone, 0, 2);
            world.setBlock(chunkX + 4, y + 7, chunkZ + 11, Blocks.stone, 0, 2);
            world.setBlock(chunkX + 5, y + 7, chunkZ + 11, Blocks.stone, 0, 2);
            world.setBlock(chunkX + 6, y + 7, chunkZ + 11, Blocks.stone, 0, 2);
            world.setBlock(chunkX + 7, y + 7, chunkZ + 11, Blocks.stone, 0, 2);
            world.setBlock(chunkX + 8, y + 7, chunkZ + 11, Blocks.stone, 0, 2);
            world.setBlock(chunkX + 9, y + 7, chunkZ + 11, Blocks.stone, 0, 2);
            world.setBlock(chunkX + 10, y + 7, chunkZ + 11, Blocks.stone, 0, 2);
            world.setBlock(chunkX + 11, y + 7, chunkZ + 11, Blocks.stone, 0, 2);
            world.setBlock(chunkX + 12, y + 7, chunkZ + 11, Blocks.vine, 2, 2);
            world.setBlock(chunkX + 4, y + 7, chunkZ + 12, Blocks.stone, 0, 2);
            world.setBlock(chunkX + 5, y + 7, chunkZ + 12, Blocks.stone, 0, 2);
            world.setBlock(chunkX + 6, y + 7, chunkZ + 12, Blocks.stone, 0, 2);
            world.setBlock(chunkX + 7, y + 7, chunkZ + 12, Blocks.stone, 0, 2);
            world.setBlock(chunkX + 8, y + 7, chunkZ + 12, Blocks.stone, 0, 2);
            world.setBlock(chunkX + 9, y + 7, chunkZ + 12, Blocks.stone, 0, 2);
            world.setBlock(chunkX + 10, y + 7, chunkZ + 12, Blocks.stone, 0, 2);
            world.setBlock(chunkX + 11, y + 7, chunkZ + 12, Blocks.stone, 0, 2);
            world.setBlock(chunkX + 12, y + 7, chunkZ + 12, Blocks.vine, 2, 2);
            world.setBlock(chunkX + 7, y + 7, chunkZ + 14, Blocks.vine, 4, 2);
            world.setBlock(chunkX + 7, y + 8, chunkZ + 0, Blocks.vine, 1, 2);
            world.setBlock(chunkX + 10, y + 8, chunkZ + 0, Blocks.vine, 1, 2);
            world.setBlock(chunkX + 5, y + 8, chunkZ + 1, Blocks.dirt, 0, 2);
            world.setBlock(chunkX + 6, y + 8, chunkZ + 1, Blocks.dirt, 0, 2);
            world.setBlock(chunkX + 7, y + 8, chunkZ + 1, Blocks.dirt, 0, 2);
            world.setBlock(chunkX + 8, y + 8, chunkZ + 1, Blocks.dirt, 0, 2);
            world.setBlock(chunkX + 9, y + 8, chunkZ + 1, Blocks.stone, 0, 2);
            world.setBlock(chunkX + 4, y + 8, chunkZ + 2, Blocks.stone, 0, 2);
            world.setBlock(chunkX + 5, y + 8, chunkZ + 2, Blocks.dirt, 0, 2);
            world.setBlock(chunkX + 6, y + 8, chunkZ + 2, Blocks.dirt, 0, 2);
            world.setBlock(chunkX + 7, y + 8, chunkZ + 2, Blocks.dirt, 0, 2);
            world.setBlock(chunkX + 8, y + 8, chunkZ + 2, Blocks.stone, 0, 2);
            world.setBlock(chunkX + 9, y + 8, chunkZ + 2, Blocks.stone, 0, 2);
            world.setBlock(chunkX + 10, y + 8, chunkZ + 2, Blocks.dirt, 0, 2);
            world.setBlock(chunkX + 3, y + 8, chunkZ + 3, Blocks.stone, 0, 2);
            world.setBlock(chunkX + 4, y + 8, chunkZ + 3, Blocks.dirt, 0, 2);
            world.setBlock(chunkX + 5, y + 8, chunkZ + 3, Blocks.dirt, 0, 2);
            world.setBlock(chunkX + 6, y + 8, chunkZ + 3, Blocks.dirt, 0, 2);
            world.setBlock(chunkX + 7, y + 8, chunkZ + 3, Blocks.dirt, 0, 2);
            world.setBlock(chunkX + 8, y + 8, chunkZ + 3, Blocks.dirt, 0, 2);
            world.setBlock(chunkX + 9, y + 8, chunkZ + 3, Blocks.dirt, 0, 2);
            world.setBlock(chunkX + 10, y + 8, chunkZ + 3, Blocks.stone, 0, 2);
            world.setBlock(chunkX + 11, y + 8, chunkZ + 3, Blocks.stone, 0, 2);
            world.setBlock(chunkX + 12, y + 8, chunkZ + 3, Blocks.dirt, 0, 2);
            world.setBlock(chunkX + 2, y + 8, chunkZ + 4, Blocks.stone, 0, 2);
            world.setBlock(chunkX + 3, y + 8, chunkZ + 4, Blocks.stone, 0, 2);
            world.setBlock(chunkX + 4, y + 8, chunkZ + 4, Blocks.dirt, 0, 2);
            world.setBlock(chunkX + 5, y + 8, chunkZ + 4, Blocks.dirt, 0, 2);
            world.setBlock(chunkX + 6, y + 8, chunkZ + 4, Blocks.dirt, 0, 2);
            world.setBlock(chunkX + 7, y + 8, chunkZ + 4, Blocks.dirt, 0, 2);
            world.setBlock(chunkX + 8, y + 8, chunkZ + 4, Blocks.dirt, 0, 2);
            world.setBlock(chunkX + 9, y + 8, chunkZ + 4, Blocks.dirt, 0, 2);
            world.setBlock(chunkX + 10, y + 8, chunkZ + 4, Blocks.dirt, 0, 2);
            world.setBlock(chunkX + 11, y + 8, chunkZ + 4, Blocks.dirt, 0, 2);
            world.setBlock(chunkX + 12, y + 8, chunkZ + 4, Blocks.dirt, 0, 2);
            world.setBlock(chunkX + 1, y + 8, chunkZ + 5, Blocks.stone, 0, 2);
            world.setBlock(chunkX + 2, y + 8, chunkZ + 5, Blocks.stone, 0, 2);
            world.setBlock(chunkX + 3, y + 8, chunkZ + 5, Blocks.stone, 0, 2);
            world.setBlock(chunkX + 4, y + 8, chunkZ + 5, Blocks.dirt, 0, 2);
            world.setBlock(chunkX + 5, y + 8, chunkZ + 5, Blocks.dirt, 0, 2);
            world.setBlock(chunkX + 6, y + 8, chunkZ + 5, Blocks.dirt, 0, 2);
            world.setBlock(chunkX + 7, y + 8, chunkZ + 5, Blocks.dirt, 0, 2);
            world.setBlock(chunkX + 8, y + 8, chunkZ + 5, Blocks.dirt, 0, 2);
            world.setBlock(chunkX + 9, y + 8, chunkZ + 5, Blocks.dirt, 0, 2);
            world.setBlock(chunkX + 10, y + 8, chunkZ + 5, Blocks.dirt, 0, 2);
            world.setBlock(chunkX + 11, y + 8, chunkZ + 5, Blocks.dirt, 0, 2);
            world.setBlock(chunkX + 12, y + 8, chunkZ + 5, Blocks.dirt, 0, 2);
            world.setBlock(chunkX + 13, y + 8, chunkZ + 5, Blocks.dirt, 0, 2);
            world.setBlock(chunkX + 0, y + 8, chunkZ + 6, Blocks.vine, 8, 2);
            world.setBlock(chunkX + 1, y + 8, chunkZ + 6, Blocks.stone, 0, 2);
            world.setBlock(chunkX + 2, y + 8, chunkZ + 6, Blocks.stone, 0, 2);
            world.setBlock(chunkX + 3, y + 8, chunkZ + 6, Blocks.dirt, 0, 2);
            world.setBlock(chunkX + 4, y + 8, chunkZ + 6, Blocks.dirt, 0, 2);
            world.setBlock(chunkX + 5, y + 8, chunkZ + 6, Blocks.dirt, 0, 2);
            world.setBlock(chunkX + 6, y + 8, chunkZ + 6, Blocks.dirt, 0, 2);
            world.setBlock(chunkX + 7, y + 8, chunkZ + 6, Blocks.dirt, 0, 2);
            world.setBlock(chunkX + 8, y + 8, chunkZ + 6, Blocks.dirt, 0, 2);
            world.setBlock(chunkX + 9, y + 8, chunkZ + 6, Blocks.dirt, 0, 2);
            world.setBlock(chunkX + 10, y + 8, chunkZ + 6, Blocks.dirt, 0, 2);
            world.setBlock(chunkX + 11, y + 8, chunkZ + 6, Blocks.dirt, 0, 2);
            world.setBlock(chunkX + 12, y + 8, chunkZ + 6, Blocks.dirt, 0, 2);
            world.setBlock(chunkX + 13, y + 8, chunkZ + 6, Blocks.stone, 0, 2);
            world.setBlock(chunkX + 1, y + 8, chunkZ + 7, Blocks.dirt, 0, 2);
            world.setBlock(chunkX + 2, y + 8, chunkZ + 7, Blocks.dirt, 0, 2);
            world.setBlock(chunkX + 3, y + 8, chunkZ + 7, Blocks.dirt, 0, 2);
            world.setBlock(chunkX + 4, y + 8, chunkZ + 7, Blocks.dirt, 0, 2);
            world.setBlock(chunkX + 5, y + 8, chunkZ + 7, Blocks.dirt, 0, 2);
            world.setBlock(chunkX + 6, y + 8, chunkZ + 7, Blocks.dirt, 0, 2);
            world.setBlock(chunkX + 7, y + 8, chunkZ + 7, Blocks.dirt, 0, 2);
            world.setBlock(chunkX + 8, y + 8, chunkZ + 7, Blocks.dirt, 0, 2);
            world.setBlock(chunkX + 9, y + 8, chunkZ + 7, Blocks.dirt, 0, 2);
            world.setBlock(chunkX + 10, y + 8, chunkZ + 7, Blocks.dirt, 0, 2);
            world.setBlock(chunkX + 11, y + 8, chunkZ + 7, Blocks.dirt, 0, 2);
            world.setBlock(chunkX + 12, y + 8, chunkZ + 7, Blocks.dirt, 0, 2);
            world.setBlock(chunkX + 13, y + 8, chunkZ + 7, Blocks.dirt, 0, 2);
            world.setBlock(chunkX + 14, y + 8, chunkZ + 7, Blocks.vine, 2, 2);
            world.setBlock(chunkX + 1, y + 8, chunkZ + 8, Blocks.stone, 0, 2);
            world.setBlock(chunkX + 2, y + 8, chunkZ + 8, Blocks.dirt, 0, 2);
            world.setBlock(chunkX + 3, y + 8, chunkZ + 8, Blocks.dirt, 0, 2);
            world.setBlock(chunkX + 4, y + 8, chunkZ + 8, Blocks.dirt, 0, 2);
            world.setBlock(chunkX + 5, y + 8, chunkZ + 8, Blocks.dirt, 0, 2);
            world.setBlock(chunkX + 6, y + 8, chunkZ + 8, Blocks.dirt, 0, 2);
            world.setBlock(chunkX + 7, y + 8, chunkZ + 8, Blocks.dirt, 0, 2);
            world.setBlock(chunkX + 8, y + 8, chunkZ + 8, Blocks.dirt, 0, 2);
            world.setBlock(chunkX + 9, y + 8, chunkZ + 8, Blocks.dirt, 0, 2);
            world.setBlock(chunkX + 10, y + 8, chunkZ + 8, Blocks.dirt, 0, 2);
            world.setBlock(chunkX + 11, y + 8, chunkZ + 8, Blocks.stone, 0, 2);
            world.setBlock(chunkX + 12, y + 8, chunkZ + 8, Blocks.dirt, 0, 2);
            world.setBlock(chunkX + 13, y + 8, chunkZ + 8, Blocks.stone, 0, 2);
            world.setBlock(chunkX + 1, y + 8, chunkZ + 9, Blocks.stone, 0, 2);
            world.setBlock(chunkX + 2, y + 8, chunkZ + 9, Blocks.dirt, 0, 2);
            world.setBlock(chunkX + 3, y + 8, chunkZ + 9, Blocks.dirt, 0, 2);
            world.setBlock(chunkX + 4, y + 8, chunkZ + 9, Blocks.dirt, 0, 2);
            world.setBlock(chunkX + 5, y + 8, chunkZ + 9, Blocks.dirt, 0, 2);
            world.setBlock(chunkX + 6, y + 8, chunkZ + 9, Blocks.dirt, 0, 2);
            world.setBlock(chunkX + 7, y + 8, chunkZ + 9, Blocks.dirt, 0, 2);
            world.setBlock(chunkX + 8, y + 8, chunkZ + 9, Blocks.dirt, 0, 2);
            world.setBlock(chunkX + 9, y + 8, chunkZ + 9, Blocks.dirt, 0, 2);
            world.setBlock(chunkX + 10, y + 8, chunkZ + 9, Blocks.dirt, 0, 2);
            world.setBlock(chunkX + 11, y + 8, chunkZ + 9, Blocks.dirt, 0, 2);
            world.setBlock(chunkX + 12, y + 8, chunkZ + 9, Blocks.dirt, 0, 2);
            world.setBlock(chunkX + 13, y + 8, chunkZ + 9, Blocks.stone, 0, 2);
            world.setBlock(chunkX + 2, y + 8, chunkZ + 10, Blocks.stone, 0, 2);
            world.setBlock(chunkX + 3, y + 8, chunkZ + 10, Blocks.stone, 0, 2);
            world.setBlock(chunkX + 4, y + 8, chunkZ + 10, Blocks.dirt, 0, 2);
            world.setBlock(chunkX + 5, y + 8, chunkZ + 10, Blocks.dirt, 0, 2);
            world.setBlock(chunkX + 6, y + 8, chunkZ + 10, Blocks.dirt, 0, 2);
            world.setBlock(chunkX + 7, y + 8, chunkZ + 10, Blocks.stone, 0, 2);
            world.setBlock(chunkX + 8, y + 8, chunkZ + 10, Blocks.dirt, 0, 2);
            world.setBlock(chunkX + 9, y + 8, chunkZ + 10, Blocks.dirt, 0, 2);
            world.setBlock(chunkX + 10, y + 8, chunkZ + 10, Blocks.dirt, 0, 2);
            world.setBlock(chunkX + 11, y + 8, chunkZ + 10, Blocks.dirt, 0, 2);
            world.setBlock(chunkX + 12, y + 8, chunkZ + 10, Blocks.stone, 0, 2);
            world.setBlock(chunkX + 13, y + 8, chunkZ + 10, Blocks.stone, 0, 2);
            world.setBlock(chunkX + 3, y + 8, chunkZ + 11, Blocks.stone, 0, 2);
            world.setBlock(chunkX + 4, y + 8, chunkZ + 11, Blocks.dirt, 0, 2);
            world.setBlock(chunkX + 5, y + 8, chunkZ + 11, Blocks.stone, 0, 2);
            world.setBlock(chunkX + 6, y + 8, chunkZ + 11, Blocks.dirt, 0, 2);
            world.setBlock(chunkX + 7, y + 8, chunkZ + 11, Blocks.stone, 0, 2);
            world.setBlock(chunkX + 8, y + 8, chunkZ + 11, Blocks.dirt, 0, 2);
            world.setBlock(chunkX + 9, y + 8, chunkZ + 11, Blocks.dirt, 0, 2);
            world.setBlock(chunkX + 10, y + 8, chunkZ + 11, Blocks.stone, 0, 2);
            world.setBlock(chunkX + 11, y + 8, chunkZ + 11, Blocks.stone, 0, 2);
            world.setBlock(chunkX + 12, y + 8, chunkZ + 11, Blocks.stone, 0, 2);
            world.setBlock(chunkX + 13, y + 8, chunkZ + 11, Blocks.stone, 0, 2);
            world.setBlock(chunkX + 4, y + 8, chunkZ + 12, Blocks.stone, 0, 2);
            world.setBlock(chunkX + 5, y + 8, chunkZ + 12, Blocks.stone, 0, 2);
            world.setBlock(chunkX + 6, y + 8, chunkZ + 12, Blocks.dirt, 0, 2);
            world.setBlock(chunkX + 7, y + 8, chunkZ + 12, Blocks.dirt, 0, 2);
            world.setBlock(chunkX + 8, y + 8, chunkZ + 12, Blocks.dirt, 0, 2);
            world.setBlock(chunkX + 9, y + 8, chunkZ + 12, Blocks.stone, 0, 2);
            world.setBlock(chunkX + 10, y + 8, chunkZ + 12, Blocks.stone, 0, 2);
            world.setBlock(chunkX + 11, y + 8, chunkZ + 12, Blocks.stone, 0, 2);
            world.setBlock(chunkX + 12, y + 8, chunkZ + 12, Blocks.stone, 0, 2);
            world.setBlock(chunkX + 13, y + 8, chunkZ + 12, Blocks.stone, 0, 2);
            world.setBlock(chunkX + 3, y + 8, chunkZ + 13, Blocks.vine, 4, 2);
            world.setBlock(chunkX + 5, y + 8, chunkZ + 13, Blocks.stone, 0, 2);
            world.setBlock(chunkX + 6, y + 8, chunkZ + 13, Blocks.stone, 0, 2);
            world.setBlock(chunkX + 7, y + 8, chunkZ + 13, Blocks.stone, 0, 2);
            world.setBlock(chunkX + 8, y + 8, chunkZ + 13, Blocks.stone, 0, 2);
            world.setBlock(chunkX + 9, y + 8, chunkZ + 13, Blocks.stone, 0, 2);
            world.setBlock(chunkX + 5, y + 8, chunkZ + 14, Blocks.vine, 4, 2);
            world.setBlock(chunkX + 7, y + 8, chunkZ + 14, Blocks.vine, 4, 2);
            world.setBlock(chunkX + 8, y + 8, chunkZ + 14, Blocks.vine, 4, 2);
            world.setBlock(chunkX + 3, y + 9, chunkZ + 0, Blocks.vine, 1, 2);
            world.setBlock(chunkX + 7, y + 9, chunkZ + 0, Blocks.vine, 1, 2);
            world.setBlock(chunkX + 9, y + 9, chunkZ + 0, Blocks.vine, 1, 2);
            world.setBlock(chunkX + 10, y + 9, chunkZ + 0, Blocks.vine, 1, 2);
            world.setBlock(chunkX + 3, y + 9, chunkZ + 1, Blocks.dirt, 0, 2);
            world.setBlock(chunkX + 4, y + 9, chunkZ + 1, Blocks.dirt, 0, 2);
            world.setBlock(chunkX + 5, y + 9, chunkZ + 1, Blocks.dirt, 0, 2);
            world.setBlock(chunkX + 6, y + 9, chunkZ + 1, Blocks.dirt, 0, 2);
            world.setBlock(chunkX + 7, y + 9, chunkZ + 1, Blocks.dirt, 0, 2);
            world.setBlock(chunkX + 8, y + 9, chunkZ + 1, Blocks.dirt, 0, 2);
            world.setBlock(chunkX + 9, y + 9, chunkZ + 1, Blocks.dirt, 0, 2);
            world.setBlock(chunkX + 10, y + 9, chunkZ + 1, Blocks.dirt, 0, 2);
            world.setBlock(chunkX + 2, y + 9, chunkZ + 2, Blocks.dirt, 0, 2);
            world.setBlock(chunkX + 3, y + 9, chunkZ + 2, Blocks.dirt, 0, 2);
            world.setBlock(chunkX + 4, y + 9, chunkZ + 2, Blocks.dirt, 0, 2);
            world.setBlock(chunkX + 5, y + 9, chunkZ + 2, Blocks.dirt, 0, 2);
            world.setBlock(chunkX + 6, y + 9, chunkZ + 2, Blocks.dirt, 0, 2);
            world.setBlock(chunkX + 7, y + 9, chunkZ + 2, Blocks.dirt, 0, 2);
            world.setBlock(chunkX + 9, y + 9, chunkZ + 2, Blocks.dirt, 0, 2);
            world.setBlock(chunkX + 10, y + 9, chunkZ + 2, Blocks.dirt, 0, 2);
            world.setBlock(chunkX + 11, y + 9, chunkZ + 2, Blocks.dirt, 0, 2);
            world.setBlock(chunkX + 1, y + 9, chunkZ + 3, Blocks.dirt, 0, 2);
            world.setBlock(chunkX + 2, y + 9, chunkZ + 3, Blocks.dirt, 0, 2);
            world.setBlock(chunkX + 3, y + 9, chunkZ + 3, Blocks.dirt, 0, 2);
            world.setBlock(chunkX + 4, y + 9, chunkZ + 3, Blocks.dirt, 0, 2);
            world.setBlock(chunkX + 11, y + 9, chunkZ + 3, Blocks.dirt, 0, 2);
            world.setBlock(chunkX + 12, y + 9, chunkZ + 3, Blocks.dirt, 0, 2);
            world.setBlock(chunkX + 13, y + 9, chunkZ + 3, Blocks.dirt, 0, 2);
            world.setBlock(chunkX + 0, y + 9, chunkZ + 4, Blocks.vine, 8, 2);
            world.setBlock(chunkX + 1, y + 9, chunkZ + 4, Blocks.dirt, 0, 2);
            world.setBlock(chunkX + 6, y + 9, chunkZ + 4, Blocks.dirt, 0, 2);
            world.setBlock(chunkX + 7, y + 9, chunkZ + 4, Blocks.dirt, 0, 2);
            world.setBlock(chunkX + 8, y + 9, chunkZ + 4, Blocks.dirt, 0, 2);
            world.setBlock(chunkX + 9, y + 9, chunkZ + 4, Blocks.dirt, 0, 2);
            world.setBlock(chunkX + 11, y + 9, chunkZ + 4, Blocks.dirt, 0, 2);
            world.setBlock(chunkX + 12, y + 9, chunkZ + 4, Blocks.dirt, 0, 2);
            world.setBlock(chunkX + 13, y + 9, chunkZ + 4, Blocks.dirt, 0, 2);
            world.setBlock(chunkX + 0, y + 9, chunkZ + 5, Blocks.vine, 8, 2);
            world.setBlock(chunkX + 1, y + 9, chunkZ + 5, Blocks.dirt, 0, 2);
            world.setBlock(chunkX + 3, y + 9, chunkZ + 5, Blocks.dirt, 0, 2);
            world.setBlock(chunkX + 4, y + 9, chunkZ + 5, Blocks.dirt, 0, 2);
            world.setBlock(chunkX + 5, y + 9, chunkZ + 5, Blocks.dirt, 0, 2);
            world.setBlock(chunkX + 6, y + 9, chunkZ + 5, Blocks.dirt, 0, 2);
            world.setBlock(chunkX + 7, y + 9, chunkZ + 5, Blocks.dirt, 0, 2);
            world.setBlock(chunkX + 8, y + 9, chunkZ + 5, Blocks.dirt, 0, 2);
            world.setBlock(chunkX + 9, y + 9, chunkZ + 5, Blocks.dirt, 0, 2);
            world.setBlock(chunkX + 11, y + 9, chunkZ + 5, Blocks.dirt, 0, 2);
            world.setBlock(chunkX + 12, y + 9, chunkZ + 5, Blocks.dirt, 0, 2);
            world.setBlock(chunkX + 13, y + 9, chunkZ + 5, Blocks.dirt, 0, 2);
            world.setBlock(chunkX + 0, y + 9, chunkZ + 6, Blocks.vine, 8, 2);
            world.setBlock(chunkX + 1, y + 9, chunkZ + 6, Blocks.dirt, 0, 2);
            world.setBlock(chunkX + 3, y + 9, chunkZ + 6, Blocks.dirt, 0, 2);
            world.setBlock(chunkX + 4, y + 9, chunkZ + 6, Blocks.dirt, 0, 2);
            world.setBlock(chunkX + 6, y + 9, chunkZ + 6, Blocks.dirt, 0, 2);
            world.setBlock(chunkX + 7, y + 9, chunkZ + 6, Blocks.dirt, 0, 2);
            world.setBlock(chunkX + 8, y + 9, chunkZ + 6, Blocks.dirt, 0, 2);
            world.setBlock(chunkX + 11, y + 9, chunkZ + 6, Blocks.dirt, 0, 2);
            world.setBlock(chunkX + 12, y + 9, chunkZ + 6, Blocks.dirt, 0, 2);
            world.setBlock(chunkX + 13, y + 9, chunkZ + 6, Blocks.dirt, 0, 2);
            world.setBlock(chunkX + 0, y + 9, chunkZ + 7, Blocks.vine, 4, 2);
            world.setBlock(chunkX + 1, y + 9, chunkZ + 7, Blocks.dirt, 0, 2);
            world.setBlock(chunkX + 3, y + 9, chunkZ + 7, Blocks.dirt, 0, 2);
            world.setBlock(chunkX + 4, y + 9, chunkZ + 7, Blocks.dirt, 0, 2);
            world.setBlock(chunkX + 8, y + 9, chunkZ + 7, Blocks.dirt, 0, 2);
            world.setBlock(chunkX + 10, y + 9, chunkZ + 7, Blocks.dirt, 0, 2);
            world.setBlock(chunkX + 11, y + 9, chunkZ + 7, Blocks.dirt, 0, 2);
            world.setBlock(chunkX + 12, y + 9, chunkZ + 7, Blocks.dirt, 0, 2);
            world.setBlock(chunkX + 13, y + 9, chunkZ + 7, Blocks.dirt, 0, 2);
            world.setBlock(chunkX + 1, y + 9, chunkZ + 8, Blocks.dirt, 0, 2);
            world.setBlock(chunkX + 3, y + 9, chunkZ + 8, Blocks.dirt, 0, 2);
            world.setBlock(chunkX + 4, y + 9, chunkZ + 8, Blocks.dirt, 0, 2);
            world.setBlock(chunkX + 6, y + 9, chunkZ + 8, Blocks.dirt, 0, 2);
            world.setBlock(chunkX + 11, y + 9, chunkZ + 8, Blocks.dirt, 0, 2);
            world.setBlock(chunkX + 12, y + 9, chunkZ + 8, Blocks.dirt, 0, 2);
            world.setBlock(chunkX + 13, y + 9, chunkZ + 8, Blocks.dirt, 0, 2);
            world.setBlock(chunkX + 1, y + 9, chunkZ + 9, Blocks.dirt, 0, 2);
            world.setBlock(chunkX + 3, y + 9, chunkZ + 9, (Block)Blocks.chest, 4, 2);
            final int x = chunkX + 3;
            final int y2 = chunkY + 9;
            final int z = chunkZ + 9;
            final TileEntityChest tileentitychest = (TileEntityChest)world.getTileEntity(x, y2, z);
            if (tileentitychest != null) {
                WeightedRandomChestContent.generateChestContents(random, ChestGenHooks.getItems("dungeonChest", random), (IInventory)tileentitychest, ChestGenHooks.getCount("dungeonChest", random));
            }
            world.setBlock(chunkX + 4, y + 9, chunkZ + 9, Blocks.dirt, 0, 2);
            world.setBlock(chunkX + 6, y + 9, chunkZ + 9, Blocks.dirt, 0, 2);
            world.setBlock(chunkX + 7, y + 9, chunkZ + 9, Blocks.dirt, 0, 2);
            world.setBlock(chunkX + 8, y + 9, chunkZ + 9, Blocks.dirt, 0, 2);
            world.setBlock(chunkX + 12, y + 9, chunkZ + 9, Blocks.dirt, 0, 2);
            world.setBlock(chunkX + 13, y + 9, chunkZ + 9, Blocks.stone, 0, 2);
            world.setBlock(chunkX + 2, y + 9, chunkZ + 10, Blocks.dirt, 0, 2);
            world.setBlock(chunkX + 3, y + 9, chunkZ + 10, Blocks.dirt, 0, 2);
            world.setBlock(chunkX + 4, y + 9, chunkZ + 10, Blocks.dirt, 0, 2);
            world.setBlock(chunkX + 6, y + 9, chunkZ + 10, Blocks.dirt, 0, 2);
            world.setBlock(chunkX + 7, y + 9, chunkZ + 10, Blocks.dirt, 0, 2);
            world.setBlock(chunkX + 8, y + 9, chunkZ + 10, Blocks.dirt, 0, 2);
            world.setBlock(chunkX + 9, y + 9, chunkZ + 10, Blocks.dirt, 0, 2);
            world.setBlock(chunkX + 13, y + 9, chunkZ + 10, Blocks.stone, 0, 2);
            world.setBlock(chunkX + 2, y + 9, chunkZ + 11, Blocks.dirt, 0, 2);
            world.setBlock(chunkX + 3, y + 9, chunkZ + 11, Blocks.dirt, 0, 2);
            world.setBlock(chunkX + 4, y + 9, chunkZ + 11, Blocks.dirt, 0, 2);
            world.setBlock(chunkX + 9, y + 9, chunkZ + 11, Blocks.dirt, 0, 2);
            world.setBlock(chunkX + 10, y + 9, chunkZ + 11, Blocks.dirt, 0, 2);
            world.setBlock(chunkX + 3, y + 9, chunkZ + 12, Blocks.stone, 0, 2);
            world.setBlock(chunkX + 4, y + 9, chunkZ + 12, Blocks.dirt, 0, 2);
            world.setBlock(chunkX + 5, y + 9, chunkZ + 12, Blocks.dirt, 0, 2);
            world.setBlock(chunkX + 6, y + 9, chunkZ + 12, Blocks.dirt, 0, 2);
            world.setBlock(chunkX + 7, y + 9, chunkZ + 12, Blocks.dirt, 0, 2);
            world.setBlock(chunkX + 8, y + 9, chunkZ + 12, Blocks.dirt, 0, 2);
            world.setBlock(chunkX + 9, y + 9, chunkZ + 12, Blocks.dirt, 0, 2);
            world.setBlock(chunkX + 10, y + 9, chunkZ + 12, Blocks.dirt, 0, 2);
            world.setBlock(chunkX + 11, y + 9, chunkZ + 12, Blocks.stone, 0, 2);
            world.setBlock(chunkX + 3, y + 9, chunkZ + 13, Blocks.vine, 4, 2);
            world.setBlock(chunkX + 5, y + 9, chunkZ + 13, Blocks.stone, 0, 2);
            world.setBlock(chunkX + 6, y + 9, chunkZ + 13, Blocks.dirt, 0, 2);
            world.setBlock(chunkX + 7, y + 9, chunkZ + 13, Blocks.dirt, 0, 2);
            world.setBlock(chunkX + 8, y + 9, chunkZ + 13, Blocks.dirt, 0, 2);
            world.setBlock(chunkX + 9, y + 9, chunkZ + 13, Blocks.stone, 0, 2);
            world.setBlock(chunkX + 10, y + 9, chunkZ + 13, Blocks.vine, 4, 2);
            world.setBlock(chunkX + 6, y + 10, chunkZ + 0, Blocks.dirt, 0, 2);
            world.setBlock(chunkX + 7, y + 10, chunkZ + 0, Blocks.dirt, 0, 2);
            world.setBlock(chunkX + 9, y + 10, chunkZ + 0, Blocks.vine, 1, 2);
            world.setBlock(chunkX + 3, y + 10, chunkZ + 1, Blocks.dirt, 0, 2);
            world.setBlock(chunkX + 4, y + 10, chunkZ + 1, Blocks.dirt, 0, 2);
            world.setBlock(chunkX + 5, y + 10, chunkZ + 1, Blocks.dirt, 0, 2);
            world.setBlock(chunkX + 6, y + 10, chunkZ + 1, Blocks.dirt, 0, 2);
            world.setBlock(chunkX + 7, y + 10, chunkZ + 1, Blocks.dirt, 0, 2);
            world.setBlock(chunkX + 8, y + 10, chunkZ + 1, Blocks.dirt, 0, 2);
            world.setBlock(chunkX + 9, y + 10, chunkZ + 1, Blocks.dirt, 0, 2);
            world.setBlock(chunkX + 10, y + 10, chunkZ + 1, Blocks.dirt, 0, 2);
            world.setBlock(chunkX + 11, y + 10, chunkZ + 1, Blocks.dirt, 0, 2);
            world.setBlock(chunkX + 2, y + 10, chunkZ + 2, Blocks.dirt, 0, 2);
            world.setBlock(chunkX + 3, y + 10, chunkZ + 2, Blocks.dirt, 0, 2);
            world.setBlock(chunkX + 4, y + 10, chunkZ + 2, Blocks.dirt, 0, 2);
            world.setBlock(chunkX + 5, y + 10, chunkZ + 2, Blocks.dirt, 0, 2);
            world.setBlock(chunkX + 6, y + 10, chunkZ + 2, Blocks.dirt, 0, 2);
            world.setBlock(chunkX + 7, y + 10, chunkZ + 2, Blocks.dirt, 0, 2);
            world.setBlock(chunkX + 9, y + 10, chunkZ + 2, Blocks.dirt, 0, 2);
            world.setBlock(chunkX + 10, y + 10, chunkZ + 2, Blocks.dirt, 0, 2);
            world.setBlock(chunkX + 11, y + 10, chunkZ + 2, Blocks.dirt, 0, 2);
            world.setBlock(chunkX + 12, y + 10, chunkZ + 2, Blocks.dirt, 0, 2);
            world.setBlock(chunkX + 1, y + 10, chunkZ + 3, Blocks.dirt, 0, 2);
            world.setBlock(chunkX + 2, y + 10, chunkZ + 3, Blocks.dirt, 0, 2);
            world.setBlock(chunkX + 3, y + 10, chunkZ + 3, Blocks.dirt, 0, 2);
            world.setBlock(chunkX + 4, y + 10, chunkZ + 3, Blocks.dirt, 0, 2);
            world.setBlock(chunkX + 11, y + 10, chunkZ + 3, Blocks.dirt, 0, 2);
            world.setBlock(chunkX + 12, y + 10, chunkZ + 3, Blocks.dirt, 0, 2);
            world.setBlock(chunkX + 13, y + 10, chunkZ + 3, Blocks.dirt, 0, 2);
            world.setBlock(chunkX + 1, y + 10, chunkZ + 4, Blocks.dirt, 0, 2);
            world.setBlock(chunkX + 6, y + 10, chunkZ + 4, Blocks.dirt, 0, 2);
            world.setBlock(chunkX + 7, y + 10, chunkZ + 4, Blocks.dirt, 0, 2);
            world.setBlock(chunkX + 8, y + 10, chunkZ + 4, Blocks.dirt, 0, 2);
            world.setBlock(chunkX + 9, y + 10, chunkZ + 4, Blocks.dirt, 0, 2);
            world.setBlock(chunkX + 11, y + 10, chunkZ + 4, Blocks.dirt, 0, 2);
            world.setBlock(chunkX + 12, y + 10, chunkZ + 4, Blocks.dirt, 0, 2);
            world.setBlock(chunkX + 13, y + 10, chunkZ + 4, Blocks.dirt, 0, 2);
            world.setBlock(chunkX + 1, y + 10, chunkZ + 5, Blocks.dirt, 0, 2);
            world.setBlock(chunkX + 3, y + 10, chunkZ + 5, Blocks.dirt, 0, 2);
            world.setBlock(chunkX + 4, y + 10, chunkZ + 5, Blocks.dirt, 0, 2);
            world.setBlock(chunkX + 5, y + 10, chunkZ + 5, Blocks.dirt, 0, 2);
            world.setBlock(chunkX + 6, y + 10, chunkZ + 5, Blocks.dirt, 0, 2);
            world.setBlock(chunkX + 7, y + 10, chunkZ + 5, Blocks.dirt, 0, 2);
            world.setBlock(chunkX + 8, y + 10, chunkZ + 5, Blocks.dirt, 0, 2);
            world.setBlock(chunkX + 9, y + 10, chunkZ + 5, Blocks.dirt, 0, 2);
            world.setBlock(chunkX + 11, y + 10, chunkZ + 5, Blocks.dirt, 0, 2);
            world.setBlock(chunkX + 12, y + 10, chunkZ + 5, Blocks.dirt, 0, 2);
            world.setBlock(chunkX + 13, y + 10, chunkZ + 5, Blocks.dirt, 0, 2);
            world.setBlock(chunkX + 0, y + 10, chunkZ + 6, Blocks.dirt, 0, 2);
            world.setBlock(chunkX + 1, y + 10, chunkZ + 6, Blocks.dirt, 0, 2);
            world.setBlock(chunkX + 3, y + 10, chunkZ + 6, Blocks.dirt, 0, 2);
            world.setBlock(chunkX + 4, y + 10, chunkZ + 6, Blocks.dirt, 0, 2);
            world.setBlock(chunkX + 6, y + 10, chunkZ + 6, Blocks.dirt, 0, 2);
            world.setBlock(chunkX + 7, y + 10, chunkZ + 6, Blocks.dirt, 0, 2);
            world.setBlock(chunkX + 8, y + 10, chunkZ + 6, Blocks.dirt, 0, 2);
            world.setBlock(chunkX + 11, y + 10, chunkZ + 6, Blocks.dirt, 0, 2);
            world.setBlock(chunkX + 12, y + 10, chunkZ + 6, Blocks.dirt, 0, 2);
            world.setBlock(chunkX + 13, y + 10, chunkZ + 6, Blocks.dirt, 0, 2);
            world.setBlock(chunkX + 0, y + 10, chunkZ + 7, Blocks.vine, 4, 2);
            world.setBlock(chunkX + 1, y + 10, chunkZ + 7, Blocks.dirt, 0, 2);
            world.setBlock(chunkX + 3, y + 10, chunkZ + 7, Blocks.dirt, 0, 2);
            world.setBlock(chunkX + 4, y + 10, chunkZ + 7, Blocks.dirt, 0, 2);
            world.setBlock(chunkX + 8, y + 10, chunkZ + 7, Blocks.dirt, 0, 2);
            world.setBlock(chunkX + 10, y + 10, chunkZ + 7, Blocks.dirt, 0, 2);
            world.setBlock(chunkX + 11, y + 10, chunkZ + 7, Blocks.dirt, 0, 2);
            world.setBlock(chunkX + 12, y + 10, chunkZ + 7, Blocks.dirt, 0, 2);
            world.setBlock(chunkX + 13, y + 10, chunkZ + 7, Blocks.dirt, 0, 2);
            world.setBlock(chunkX + 14, y + 10, chunkZ + 7, Blocks.dirt, 0, 2);
            world.setBlock(chunkX + 1, y + 10, chunkZ + 8, Blocks.dirt, 0, 2);
            world.setBlock(chunkX + 3, y + 10, chunkZ + 8, Blocks.dirt, 0, 2);
            world.setBlock(chunkX + 4, y + 10, chunkZ + 8, Blocks.dirt, 0, 2);
            world.setBlock(chunkX + 6, y + 10, chunkZ + 8, Blocks.dirt, 0, 2);
            world.setBlock(chunkX + 11, y + 10, chunkZ + 8, Blocks.dirt, 0, 2);
            world.setBlock(chunkX + 12, y + 10, chunkZ + 8, Blocks.dirt, 0, 2);
            world.setBlock(chunkX + 13, y + 10, chunkZ + 8, Blocks.dirt, 0, 2);
            world.setBlock(chunkX + 14, y + 10, chunkZ + 8, Blocks.dirt, 0, 2);
            world.setBlock(chunkX + 1, y + 10, chunkZ + 9, Blocks.stone, 0, 2);
            world.setBlock(chunkX + 4, y + 10, chunkZ + 9, Blocks.dirt, 0, 2);
            world.setBlock(chunkX + 6, y + 10, chunkZ + 9, Blocks.dirt, 0, 2);
            world.setBlock(chunkX + 7, y + 10, chunkZ + 9, Blocks.dirt, 0, 2);
            world.setBlock(chunkX + 8, y + 10, chunkZ + 9, Blocks.dirt, 0, 2);
            world.setBlock(chunkX + 12, y + 10, chunkZ + 9, Blocks.dirt, 0, 2);
            world.setBlock(chunkX + 13, y + 10, chunkZ + 9, Blocks.dirt, 0, 2);
            world.setBlock(chunkX + 1, y + 10, chunkZ + 10, Blocks.dirt, 0, 2);
            world.setBlock(chunkX + 2, y + 10, chunkZ + 10, Blocks.dirt, 0, 2);
            world.setBlock(chunkX + 3, y + 10, chunkZ + 10, Blocks.dirt, 0, 2);
            world.setBlock(chunkX + 4, y + 10, chunkZ + 10, Blocks.dirt, 0, 2);
            world.setBlock(chunkX + 6, y + 10, chunkZ + 10, Blocks.dirt, 0, 2);
            world.setBlock(chunkX + 7, y + 10, chunkZ + 10, Blocks.dirt, 0, 2);
            world.setBlock(chunkX + 8, y + 10, chunkZ + 10, Blocks.dirt, 0, 2);
            world.setBlock(chunkX + 9, y + 10, chunkZ + 10, Blocks.dirt, 0, 2);
            world.setBlock(chunkX + 13, y + 10, chunkZ + 10, Blocks.stone, 0, 2);
            world.setBlock(chunkX + 2, y + 10, chunkZ + 11, Blocks.stone, 0, 2);
            world.setBlock(chunkX + 3, y + 10, chunkZ + 11, Blocks.dirt, 0, 2);
            world.setBlock(chunkX + 4, y + 10, chunkZ + 11, Blocks.dirt, 0, 2);
            world.setBlock(chunkX + 9, y + 10, chunkZ + 11, Blocks.dirt, 0, 2);
            world.setBlock(chunkX + 10, y + 10, chunkZ + 11, Blocks.dirt, 0, 2);
            world.setBlock(chunkX + 2, y + 10, chunkZ + 12, Blocks.vine, 8, 2);
            world.setBlock(chunkX + 3, y + 10, chunkZ + 12, Blocks.dirt, 0, 2);
            world.setBlock(chunkX + 4, y + 10, chunkZ + 12, Blocks.stone, 0, 2);
            world.setBlock(chunkX + 5, y + 10, chunkZ + 12, Blocks.dirt, 0, 2);
            world.setBlock(chunkX + 6, y + 10, chunkZ + 12, Blocks.dirt, 0, 2);
            world.setBlock(chunkX + 7, y + 10, chunkZ + 12, Blocks.dirt, 0, 2);
            world.setBlock(chunkX + 8, y + 10, chunkZ + 12, Blocks.dirt, 0, 2);
            world.setBlock(chunkX + 9, y + 10, chunkZ + 12, Blocks.dirt, 0, 2);
            world.setBlock(chunkX + 10, y + 10, chunkZ + 12, Blocks.dirt, 0, 2);
            world.setBlock(chunkX + 11, y + 10, chunkZ + 12, Blocks.stone, 0, 2);
            world.setBlock(chunkX + 3, y + 10, chunkZ + 13, Blocks.vine, 4, 2);
            world.setBlock(chunkX + 4, y + 10, chunkZ + 13, Blocks.stone, 0, 2);
            world.setBlock(chunkX + 5, y + 10, chunkZ + 13, Blocks.stone, 0, 2);
            world.setBlock(chunkX + 6, y + 10, chunkZ + 13, Blocks.dirt, 0, 2);
            world.setBlock(chunkX + 7, y + 10, chunkZ + 13, Blocks.stone, 0, 2);
            world.setBlock(chunkX + 8, y + 10, chunkZ + 13, Blocks.stone, 0, 2);
            world.setBlock(chunkX + 9, y + 10, chunkZ + 13, Blocks.stone, 0, 2);
            world.setBlock(chunkX + 10, y + 10, chunkZ + 13, Blocks.stone, 0, 2);
            world.setBlock(chunkX + 6, y + 11, chunkZ + 0, Blocks.dirt, 0, 2);
            world.setBlock(chunkX + 7, y + 11, chunkZ + 0, Blocks.dirt, 0, 2);
            world.setBlock(chunkX + 8, y + 11, chunkZ + 0, Blocks.dirt, 0, 2);
            world.setBlock(chunkX + 3, y + 11, chunkZ + 1, Blocks.dirt, 0, 2);
            world.setBlock(chunkX + 4, y + 11, chunkZ + 1, Blocks.dirt, 0, 2);
            world.setBlock(chunkX + 5, y + 11, chunkZ + 1, Blocks.dirt, 0, 2);
            world.setBlock(chunkX + 6, y + 11, chunkZ + 1, Blocks.dirt, 0, 2);
            world.setBlock(chunkX + 7, y + 11, chunkZ + 1, Blocks.dirt, 0, 2);
            world.setBlock(chunkX + 8, y + 11, chunkZ + 1, Blocks.dirt, 0, 2);
            world.setBlock(chunkX + 9, y + 11, chunkZ + 1, Blocks.dirt, 0, 2);
            world.setBlock(chunkX + 10, y + 11, chunkZ + 1, Blocks.dirt, 0, 2);
            world.setBlock(chunkX + 11, y + 11, chunkZ + 1, Blocks.dirt, 0, 2);
            world.setBlock(chunkX + 2, y + 11, chunkZ + 2, Blocks.stone, 0, 2);
            world.setBlock(chunkX + 3, y + 11, chunkZ + 2, Blocks.dirt, 0, 2);
            world.setBlock(chunkX + 4, y + 11, chunkZ + 2, Blocks.dirt, 0, 2);
            world.setBlock(chunkX + 5, y + 11, chunkZ + 2, Blocks.dirt, 0, 2);
            world.setBlock(chunkX + 6, y + 11, chunkZ + 2, Blocks.dirt, 0, 2);
            world.setBlock(chunkX + 7, y + 11, chunkZ + 2, Blocks.dirt, 0, 2);
            world.setBlock(chunkX + 8, y + 11, chunkZ + 2, Blocks.dirt, 0, 2);
            world.setBlock(chunkX + 9, y + 11, chunkZ + 2, Blocks.dirt, 0, 2);
            world.setBlock(chunkX + 10, y + 11, chunkZ + 2, Blocks.dirt, 0, 2);
            world.setBlock(chunkX + 11, y + 11, chunkZ + 2, Blocks.dirt, 0, 2);
            world.setBlock(chunkX + 12, y + 11, chunkZ + 2, Blocks.stone, 0, 2);
            world.setBlock(chunkX + 1, y + 11, chunkZ + 3, Blocks.dirt, 0, 2);
            world.setBlock(chunkX + 2, y + 11, chunkZ + 3, Blocks.dirt, 0, 2);
            world.setBlock(chunkX + 3, y + 11, chunkZ + 3, Blocks.dirt, 0, 2);
            world.setBlock(chunkX + 4, y + 11, chunkZ + 3, Blocks.dirt, 0, 2);
            world.setBlock(chunkX + 5, y + 11, chunkZ + 3, Blocks.dirt, 0, 2);
            world.setBlock(chunkX + 6, y + 11, chunkZ + 3, Blocks.dirt, 0, 2);
            world.setBlock(chunkX + 7, y + 11, chunkZ + 3, Blocks.dirt, 0, 2);
            world.setBlock(chunkX + 8, y + 11, chunkZ + 3, Blocks.dirt, 0, 2);
            world.setBlock(chunkX + 9, y + 11, chunkZ + 3, Blocks.dirt, 0, 2);
            world.setBlock(chunkX + 10, y + 11, chunkZ + 3, Blocks.dirt, 0, 2);
            world.setBlock(chunkX + 11, y + 11, chunkZ + 3, Blocks.dirt, 0, 2);
            world.setBlock(chunkX + 12, y + 11, chunkZ + 3, Blocks.dirt, 0, 2);
            world.setBlock(chunkX + 13, y + 11, chunkZ + 3, Blocks.dirt, 0, 2);
            world.setBlock(chunkX + 1, y + 11, chunkZ + 4, Blocks.dirt, 0, 2);
            world.setBlock(chunkX + 2, y + 11, chunkZ + 4, Blocks.dirt, 0, 2);
            world.setBlock(chunkX + 3, y + 11, chunkZ + 4, Blocks.dirt, 0, 2);
            world.setBlock(chunkX + 4, y + 11, chunkZ + 4, Blocks.dirt, 0, 2);
            world.setBlock(chunkX + 5, y + 11, chunkZ + 4, Blocks.dirt, 0, 2);
            world.setBlock(chunkX + 6, y + 11, chunkZ + 4, Blocks.dirt, 0, 2);
            world.setBlock(chunkX + 7, y + 11, chunkZ + 4, Blocks.dirt, 0, 2);
            world.setBlock(chunkX + 8, y + 11, chunkZ + 4, Blocks.dirt, 0, 2);
            world.setBlock(chunkX + 9, y + 11, chunkZ + 4, Blocks.dirt, 0, 2);
            world.setBlock(chunkX + 10, y + 11, chunkZ + 4, Blocks.dirt, 0, 2);
            world.setBlock(chunkX + 11, y + 11, chunkZ + 4, Blocks.dirt, 0, 2);
            world.setBlock(chunkX + 12, y + 11, chunkZ + 4, Blocks.dirt, 0, 2);
            world.setBlock(chunkX + 13, y + 11, chunkZ + 4, Blocks.stone, 0, 2);
            world.setBlock(chunkX + 1, y + 11, chunkZ + 5, Blocks.dirt, 0, 2);
            world.setBlock(chunkX + 2, y + 11, chunkZ + 5, Blocks.dirt, 0, 2);
            world.setBlock(chunkX + 3, y + 11, chunkZ + 5, Blocks.dirt, 0, 2);
            world.setBlock(chunkX + 4, y + 11, chunkZ + 5, Blocks.dirt, 0, 2);
            world.setBlock(chunkX + 5, y + 11, chunkZ + 5, Blocks.dirt, 0, 2);
            world.setBlock(chunkX + 6, y + 11, chunkZ + 5, Blocks.dirt, 0, 2);
            world.setBlock(chunkX + 7, y + 11, chunkZ + 5, Blocks.dirt, 0, 2);
            world.setBlock(chunkX + 8, y + 11, chunkZ + 5, Blocks.dirt, 0, 2);
            world.setBlock(chunkX + 9, y + 11, chunkZ + 5, Blocks.dirt, 0, 2);
            world.setBlock(chunkX + 10, y + 11, chunkZ + 5, Blocks.dirt, 0, 2);
            world.setBlock(chunkX + 11, y + 11, chunkZ + 5, Blocks.dirt, 0, 2);
            world.setBlock(chunkX + 12, y + 11, chunkZ + 5, Blocks.dirt, 0, 2);
            world.setBlock(chunkX + 13, y + 11, chunkZ + 5, Blocks.dirt, 0, 2);
            world.setBlock(chunkX + 0, y + 11, chunkZ + 6, Blocks.dirt, 0, 2);
            world.setBlock(chunkX + 1, y + 11, chunkZ + 6, Blocks.dirt, 0, 2);
            world.setBlock(chunkX + 2, y + 11, chunkZ + 6, Blocks.dirt, 0, 2);
            world.setBlock(chunkX + 3, y + 11, chunkZ + 6, Blocks.dirt, 0, 2);
            world.setBlock(chunkX + 4, y + 11, chunkZ + 6, Blocks.dirt, 0, 2);
            world.setBlock(chunkX + 5, y + 11, chunkZ + 6, Blocks.dirt, 0, 2);
            world.setBlock(chunkX + 6, y + 11, chunkZ + 6, Blocks.dirt, 0, 2);
            world.setBlock(chunkX + 7, y + 11, chunkZ + 6, Blocks.dirt, 0, 2);
            world.setBlock(chunkX + 8, y + 11, chunkZ + 6, Blocks.dirt, 0, 2);
            world.setBlock(chunkX + 9, y + 11, chunkZ + 6, Blocks.dirt, 0, 2);
            world.setBlock(chunkX + 10, y + 11, chunkZ + 6, Blocks.dirt, 0, 2);
            world.setBlock(chunkX + 11, y + 11, chunkZ + 6, Blocks.dirt, 0, 2);
            world.setBlock(chunkX + 12, y + 11, chunkZ + 6, Blocks.dirt, 0, 2);
            world.setBlock(chunkX + 13, y + 11, chunkZ + 6, Blocks.dirt, 0, 2);
            world.setBlock(chunkX + 14, y + 11, chunkZ + 6, Blocks.dirt, 0, 2);
            world.setBlock(chunkX + 0, y + 11, chunkZ + 7, Blocks.dirt, 0, 2);
            world.setBlock(chunkX + 1, y + 11, chunkZ + 7, Blocks.dirt, 0, 2);
            world.setBlock(chunkX + 2, y + 11, chunkZ + 7, Blocks.dirt, 0, 2);
            world.setBlock(chunkX + 3, y + 11, chunkZ + 7, Blocks.dirt, 0, 2);
            world.setBlock(chunkX + 4, y + 11, chunkZ + 7, Blocks.dirt, 0, 2);
            world.setBlock(chunkX + 5, y + 11, chunkZ + 7, Blocks.dirt, 0, 2);
            world.setBlock(chunkX + 6, y + 11, chunkZ + 7, Blocks.dirt, 0, 2);
            world.setBlock(chunkX + 7, y + 11, chunkZ + 7, Blocks.dirt, 0, 2);
            world.setBlock(chunkX + 8, y + 11, chunkZ + 7, Blocks.dirt, 0, 2);
            world.setBlock(chunkX + 9, y + 11, chunkZ + 7, Blocks.dirt, 0, 2);
            world.setBlock(chunkX + 10, y + 11, chunkZ + 7, Blocks.dirt, 0, 2);
            world.setBlock(chunkX + 11, y + 11, chunkZ + 7, Blocks.dirt, 0, 2);
            world.setBlock(chunkX + 12, y + 11, chunkZ + 7, Blocks.dirt, 0, 2);
            world.setBlock(chunkX + 13, y + 11, chunkZ + 7, Blocks.dirt, 0, 2);
            world.setBlock(chunkX + 14, y + 11, chunkZ + 7, Blocks.dirt, 0, 2);
            world.setBlock(chunkX + 0, y + 11, chunkZ + 8, Blocks.stone, 0, 2);
            world.setBlock(chunkX + 1, y + 11, chunkZ + 8, Blocks.dirt, 0, 2);
            world.setBlock(chunkX + 2, y + 11, chunkZ + 8, Blocks.dirt, 0, 2);
            world.setBlock(chunkX + 3, y + 11, chunkZ + 8, Blocks.dirt, 0, 2);
            world.setBlock(chunkX + 4, y + 11, chunkZ + 8, Blocks.dirt, 0, 2);
            world.setBlock(chunkX + 5, y + 11, chunkZ + 8, Blocks.dirt, 0, 2);
            world.setBlock(chunkX + 6, y + 11, chunkZ + 8, Blocks.dirt, 0, 2);
            world.setBlock(chunkX + 7, y + 11, chunkZ + 8, Blocks.dirt, 0, 2);
            world.setBlock(chunkX + 8, y + 11, chunkZ + 8, Blocks.dirt, 0, 2);
            world.setBlock(chunkX + 9, y + 11, chunkZ + 8, Blocks.dirt, 0, 2);
            world.setBlock(chunkX + 10, y + 11, chunkZ + 8, Blocks.dirt, 0, 2);
            world.setBlock(chunkX + 11, y + 11, chunkZ + 8, Blocks.dirt, 0, 2);
            world.setBlock(chunkX + 12, y + 11, chunkZ + 8, Blocks.dirt, 0, 2);
            world.setBlock(chunkX + 13, y + 11, chunkZ + 8, Blocks.dirt, 0, 2);
            world.setBlock(chunkX + 14, y + 11, chunkZ + 8, Blocks.stone, 0, 2);
            world.setBlock(chunkX + 0, y + 11, chunkZ + 9, Blocks.vine, 4, 2);
            world.setBlock(chunkX + 1, y + 11, chunkZ + 9, Blocks.dirt, 0, 2);
            world.setBlock(chunkX + 2, y + 11, chunkZ + 9, Blocks.dirt, 0, 2);
            world.setBlock(chunkX + 3, y + 11, chunkZ + 9, Blocks.dirt, 0, 2);
            world.setBlock(chunkX + 4, y + 11, chunkZ + 9, Blocks.dirt, 0, 2);
            world.setBlock(chunkX + 5, y + 11, chunkZ + 9, Blocks.dirt, 0, 2);
            world.setBlock(chunkX + 6, y + 11, chunkZ + 9, Blocks.dirt, 0, 2);
            world.setBlock(chunkX + 7, y + 11, chunkZ + 9, Blocks.dirt, 0, 2);
            world.setBlock(chunkX + 8, y + 11, chunkZ + 9, Blocks.dirt, 0, 2);
            world.setBlock(chunkX + 9, y + 11, chunkZ + 9, Blocks.dirt, 0, 2);
            world.setBlock(chunkX + 10, y + 11, chunkZ + 9, Blocks.dirt, 0, 2);
            world.setBlock(chunkX + 11, y + 11, chunkZ + 9, Blocks.dirt, 0, 2);
            world.setBlock(chunkX + 12, y + 11, chunkZ + 9, Blocks.dirt, 0, 2);
            world.setBlock(chunkX + 13, y + 11, chunkZ + 9, Blocks.dirt, 0, 2);
            world.setBlock(chunkX + 1, y + 11, chunkZ + 10, Blocks.stone, 0, 2);
            world.setBlock(chunkX + 2, y + 11, chunkZ + 10, Blocks.stone, 0, 2);
            world.setBlock(chunkX + 3, y + 11, chunkZ + 10, Blocks.dirt, 0, 2);
            world.setBlock(chunkX + 4, y + 11, chunkZ + 10, Blocks.dirt, 0, 2);
            world.setBlock(chunkX + 5, y + 11, chunkZ + 10, Blocks.dirt, 0, 2);
            world.setBlock(chunkX + 6, y + 11, chunkZ + 10, Blocks.dirt, 0, 2);
            world.setBlock(chunkX + 7, y + 11, chunkZ + 10, Blocks.dirt, 0, 2);
            world.setBlock(chunkX + 8, y + 11, chunkZ + 10, Blocks.dirt, 0, 2);
            world.setBlock(chunkX + 9, y + 11, chunkZ + 10, Blocks.dirt, 0, 2);
            world.setBlock(chunkX + 10, y + 11, chunkZ + 10, Blocks.dirt, 0, 2);
            world.setBlock(chunkX + 11, y + 11, chunkZ + 10, Blocks.dirt, 0, 2);
            world.setBlock(chunkX + 12, y + 11, chunkZ + 10, Blocks.dirt, 0, 2);
            world.setBlock(chunkX + 13, y + 11, chunkZ + 10, Blocks.stone, 0, 2);
            world.setBlock(chunkX + 2, y + 11, chunkZ + 11, Blocks.dirt, 0, 2);
            world.setBlock(chunkX + 3, y + 11, chunkZ + 11, Blocks.stone, 0, 2);
            world.setBlock(chunkX + 4, y + 11, chunkZ + 11, Blocks.dirt, 0, 2);
            world.setBlock(chunkX + 5, y + 11, chunkZ + 11, Blocks.dirt, 0, 2);
            world.setBlock(chunkX + 6, y + 11, chunkZ + 11, Blocks.dirt, 0, 2);
            world.setBlock(chunkX + 7, y + 11, chunkZ + 11, Blocks.dirt, 0, 2);
            world.setBlock(chunkX + 8, y + 11, chunkZ + 11, Blocks.dirt, 0, 2);
            world.setBlock(chunkX + 9, y + 11, chunkZ + 11, Blocks.dirt, 0, 2);
            world.setBlock(chunkX + 10, y + 11, chunkZ + 11, Blocks.dirt, 0, 2);
            world.setBlock(chunkX + 11, y + 11, chunkZ + 11, Blocks.dirt, 0, 2);
            world.setBlock(chunkX + 12, y + 11, chunkZ + 11, Blocks.dirt, 0, 2);
            world.setBlock(chunkX + 13, y + 11, chunkZ + 11, Blocks.stone, 0, 2);
            world.setBlock(chunkX + 2, y + 11, chunkZ + 12, Blocks.stone, 0, 2);
            world.setBlock(chunkX + 3, y + 11, chunkZ + 12, Blocks.stone, 0, 2);
            world.setBlock(chunkX + 4, y + 11, chunkZ + 12, Blocks.dirt, 0, 2);
            world.setBlock(chunkX + 5, y + 11, chunkZ + 12, Blocks.dirt, 0, 2);
            world.setBlock(chunkX + 6, y + 11, chunkZ + 12, Blocks.dirt, 0, 2);
            world.setBlock(chunkX + 7, y + 11, chunkZ + 12, Blocks.dirt, 0, 2);
            world.setBlock(chunkX + 8, y + 11, chunkZ + 12, Blocks.dirt, 0, 2);
            world.setBlock(chunkX + 9, y + 11, chunkZ + 12, Blocks.dirt, 0, 2);
            world.setBlock(chunkX + 10, y + 11, chunkZ + 12, Blocks.stone, 0, 2);
            world.setBlock(chunkX + 11, y + 11, chunkZ + 12, Blocks.stone, 0, 2);
            world.setBlock(chunkX + 12, y + 11, chunkZ + 12, Blocks.stone, 0, 2);
            world.setBlock(chunkX + 4, y + 11, chunkZ + 13, Blocks.stone, 0, 2);
            world.setBlock(chunkX + 5, y + 11, chunkZ + 13, Blocks.stone, 0, 2);
            world.setBlock(chunkX + 6, y + 11, chunkZ + 13, Blocks.stone, 0, 2);
            world.setBlock(chunkX + 7, y + 11, chunkZ + 13, Blocks.dirt, 0, 2);
            world.setBlock(chunkX + 8, y + 11, chunkZ + 13, Blocks.stone, 0, 2);
            world.setBlock(chunkX + 9, y + 11, chunkZ + 13, Blocks.stone, 0, 2);
            world.setBlock(chunkX + 10, y + 11, chunkZ + 13, Blocks.stone, 0, 2);
            world.setBlock(chunkX + 6, y + 11, chunkZ + 14, Blocks.stone, 0, 2);
            world.setBlock(chunkX + 7, y + 11, chunkZ + 14, Blocks.stone, 0, 2);
            world.setBlock(chunkX + 8, y + 11, chunkZ + 14, Blocks.stone, 0, 2);
            world.setBlock(chunkX + 6, y + 12, chunkZ + 0, Blocks.dirt, 0, 2);
            world.setBlock(chunkX + 7, y + 12, chunkZ + 0, Blocks.dirt, 0, 2);
            world.setBlock(chunkX + 8, y + 12, chunkZ + 0, Blocks.dirt, 0, 2);
            world.setBlock(chunkX + 3, y + 12, chunkZ + 1, Blocks.stone, 0, 2);
            world.setBlock(chunkX + 4, y + 12, chunkZ + 1, Blocks.dirt, 0, 2);
            world.setBlock(chunkX + 5, y + 12, chunkZ + 1, Blocks.dirt, 0, 2);
            world.setBlock(chunkX + 6, y + 12, chunkZ + 1, Blocks.dirt, 0, 2);
            world.setBlock(chunkX + 7, y + 12, chunkZ + 1, Blocks.dirt, 0, 2);
            world.setBlock(chunkX + 8, y + 12, chunkZ + 1, Blocks.dirt, 0, 2);
            world.setBlock(chunkX + 9, y + 12, chunkZ + 1, Blocks.dirt, 0, 2);
            world.setBlock(chunkX + 10, y + 12, chunkZ + 1, Blocks.stone, 0, 2);
            world.setBlock(chunkX + 11, y + 12, chunkZ + 1, Blocks.stone, 0, 2);
            world.setBlock(chunkX + 2, y + 12, chunkZ + 2, Blocks.stone, 0, 2);
            world.setBlock(chunkX + 3, y + 12, chunkZ + 2, Blocks.dirt, 0, 2);
            world.setBlock(chunkX + 4, y + 12, chunkZ + 2, Blocks.dirt, 0, 2);
            world.setBlock(chunkX + 5, y + 12, chunkZ + 2, Blocks.dirt, 0, 2);
            world.setBlock(chunkX + 6, y + 12, chunkZ + 2, Blocks.dirt, 0, 2);
            world.setBlock(chunkX + 7, y + 12, chunkZ + 2, Blocks.dirt, 0, 2);
            world.setBlock(chunkX + 8, y + 12, chunkZ + 2, Blocks.dirt, 0, 2);
            world.setBlock(chunkX + 9, y + 12, chunkZ + 2, Blocks.dirt, 0, 2);
            world.setBlock(chunkX + 10, y + 12, chunkZ + 2, Blocks.dirt, 0, 2);
            world.setBlock(chunkX + 11, y + 12, chunkZ + 2, Blocks.dirt, 0, 2);
            world.setBlock(chunkX + 12, y + 12, chunkZ + 2, Blocks.stone, 0, 2);
            world.setBlock(chunkX + 1, y + 12, chunkZ + 3, Blocks.stone, 0, 2);
            world.setBlock(chunkX + 2, y + 12, chunkZ + 3, Blocks.dirt, 0, 2);
            world.setBlock(chunkX + 3, y + 12, chunkZ + 3, Blocks.dirt, 0, 2);
            world.setBlock(chunkX + 4, y + 12, chunkZ + 3, Blocks.dirt, 0, 2);
            world.setBlock(chunkX + 5, y + 12, chunkZ + 3, Blocks.dirt, 0, 2);
            world.setBlock(chunkX + 6, y + 12, chunkZ + 3, Blocks.dirt, 0, 2);
            world.setBlock(chunkX + 7, y + 12, chunkZ + 3, Blocks.dirt, 0, 2);
            world.setBlock(chunkX + 8, y + 12, chunkZ + 3, Blocks.dirt, 0, 2);
            world.setBlock(chunkX + 9, y + 12, chunkZ + 3, Blocks.dirt, 0, 2);
            world.setBlock(chunkX + 10, y + 12, chunkZ + 3, Blocks.dirt, 0, 2);
            world.setBlock(chunkX + 11, y + 12, chunkZ + 3, Blocks.dirt, 0, 2);
            world.setBlock(chunkX + 12, y + 12, chunkZ + 3, Blocks.stone, 0, 2);
            world.setBlock(chunkX + 13, y + 12, chunkZ + 3, Blocks.stone, 0, 2);
            world.setBlock(chunkX + 1, y + 12, chunkZ + 4, Blocks.dirt, 0, 2);
            world.setBlock(chunkX + 2, y + 12, chunkZ + 4, Blocks.dirt, 0, 2);
            world.setBlock(chunkX + 3, y + 12, chunkZ + 4, Blocks.dirt, 0, 2);
            world.setBlock(chunkX + 4, y + 12, chunkZ + 4, Blocks.dirt, 0, 2);
            world.setBlock(chunkX + 5, y + 12, chunkZ + 4, Blocks.dirt, 0, 2);
            world.setBlock(chunkX + 6, y + 12, chunkZ + 4, Blocks.dirt, 0, 2);
            world.setBlock(chunkX + 7, y + 12, chunkZ + 4, Blocks.dirt, 0, 2);
            world.setBlock(chunkX + 8, y + 12, chunkZ + 4, Blocks.dirt, 0, 2);
            world.setBlock(chunkX + 9, y + 12, chunkZ + 4, Blocks.dirt, 0, 2);
            world.setBlock(chunkX + 10, y + 12, chunkZ + 4, Blocks.dirt, 0, 2);
            world.setBlock(chunkX + 11, y + 12, chunkZ + 4, Blocks.dirt, 0, 2);
            world.setBlock(chunkX + 12, y + 12, chunkZ + 4, Blocks.dirt, 0, 2);
            world.setBlock(chunkX + 13, y + 12, chunkZ + 4, Blocks.dirt, 0, 2);
            world.setBlock(chunkX + 1, y + 12, chunkZ + 5, Blocks.dirt, 0, 2);
            world.setBlock(chunkX + 2, y + 12, chunkZ + 5, Blocks.dirt, 0, 2);
            world.setBlock(chunkX + 3, y + 12, chunkZ + 5, Blocks.dirt, 0, 2);
            world.setBlock(chunkX + 4, y + 12, chunkZ + 5, Blocks.dirt, 0, 2);
            world.setBlock(chunkX + 5, y + 12, chunkZ + 5, Blocks.dirt, 0, 2);
            world.setBlock(chunkX + 6, y + 12, chunkZ + 5, Blocks.dirt, 0, 2);
            world.setBlock(chunkX + 7, y + 12, chunkZ + 5, Blocks.dirt, 0, 2);
            world.setBlock(chunkX + 8, y + 12, chunkZ + 5, Blocks.dirt, 0, 2);
            world.setBlock(chunkX + 9, y + 12, chunkZ + 5, Blocks.dirt, 0, 2);
            world.setBlock(chunkX + 10, y + 12, chunkZ + 5, Blocks.dirt, 0, 2);
            world.setBlock(chunkX + 11, y + 12, chunkZ + 5, Blocks.dirt, 0, 2);
            world.setBlock(chunkX + 12, y + 12, chunkZ + 5, Blocks.dirt, 0, 2);
            world.setBlock(chunkX + 13, y + 12, chunkZ + 5, Blocks.dirt, 0, 2);
            world.setBlock(chunkX + 0, y + 12, chunkZ + 6, Blocks.dirt, 0, 2);
            world.setBlock(chunkX + 1, y + 12, chunkZ + 6, Blocks.dirt, 0, 2);
            world.setBlock(chunkX + 2, y + 12, chunkZ + 6, Blocks.dirt, 0, 2);
            world.setBlock(chunkX + 3, y + 12, chunkZ + 6, Blocks.dirt, 0, 2);
            world.setBlock(chunkX + 4, y + 12, chunkZ + 6, Blocks.dirt, 0, 2);
            world.setBlock(chunkX + 5, y + 12, chunkZ + 6, Blocks.dirt, 0, 2);
            world.setBlock(chunkX + 6, y + 12, chunkZ + 6, Blocks.dirt, 0, 2);
            world.setBlock(chunkX + 7, y + 12, chunkZ + 6, Blocks.dirt, 0, 2);
            world.setBlock(chunkX + 8, y + 12, chunkZ + 6, Blocks.dirt, 0, 2);
            world.setBlock(chunkX + 9, y + 12, chunkZ + 6, Blocks.dirt, 0, 2);
            world.setBlock(chunkX + 10, y + 12, chunkZ + 6, Blocks.dirt, 0, 2);
            world.setBlock(chunkX + 11, y + 12, chunkZ + 6, Blocks.dirt, 0, 2);
            world.setBlock(chunkX + 12, y + 12, chunkZ + 6, Blocks.dirt, 0, 2);
            world.setBlock(chunkX + 13, y + 12, chunkZ + 6, Blocks.dirt, 0, 2);
            world.setBlock(chunkX + 14, y + 12, chunkZ + 6, Blocks.dirt, 0, 2);
            world.setBlock(chunkX + 0, y + 12, chunkZ + 7, Blocks.dirt, 0, 2);
            world.setBlock(chunkX + 1, y + 12, chunkZ + 7, Blocks.dirt, 0, 2);
            world.setBlock(chunkX + 2, y + 12, chunkZ + 7, Blocks.dirt, 0, 2);
            world.setBlock(chunkX + 3, y + 12, chunkZ + 7, Blocks.dirt, 0, 2);
            world.setBlock(chunkX + 4, y + 12, chunkZ + 7, Blocks.dirt, 0, 2);
            world.setBlock(chunkX + 5, y + 12, chunkZ + 7, Blocks.dirt, 0, 2);
            world.setBlock(chunkX + 6, y + 12, chunkZ + 7, Blocks.dirt, 0, 2);
            world.setBlock(chunkX + 7, y + 12, chunkZ + 7, Blocks.dirt, 0, 2);
            world.setBlock(chunkX + 8, y + 12, chunkZ + 7, Blocks.dirt, 0, 2);
            world.setBlock(chunkX + 9, y + 12, chunkZ + 7, Blocks.dirt, 0, 2);
            world.setBlock(chunkX + 10, y + 12, chunkZ + 7, Blocks.dirt, 0, 2);
            world.setBlock(chunkX + 11, y + 12, chunkZ + 7, Blocks.dirt, 0, 2);
            world.setBlock(chunkX + 12, y + 12, chunkZ + 7, Blocks.dirt, 0, 2);
            world.setBlock(chunkX + 13, y + 12, chunkZ + 7, Blocks.stone, 0, 2);
            world.setBlock(chunkX + 14, y + 12, chunkZ + 7, Blocks.dirt, 0, 2);
            world.setBlock(chunkX + 15, y + 12, chunkZ + 7, Blocks.dirt, 0, 2);
            world.setBlock(chunkX + 0, y + 12, chunkZ + 8, Blocks.dirt, 0, 2);
            world.setBlock(chunkX + 1, y + 12, chunkZ + 8, Blocks.stone, 0, 2);
            world.setBlock(chunkX + 2, y + 12, chunkZ + 8, Blocks.stone, 0, 2);
            world.setBlock(chunkX + 3, y + 12, chunkZ + 8, Blocks.dirt, 0, 2);
            world.setBlock(chunkX + 4, y + 12, chunkZ + 8, Blocks.dirt, 0, 2);
            world.setBlock(chunkX + 5, y + 12, chunkZ + 8, Blocks.dirt, 0, 2);
            world.setBlock(chunkX + 6, y + 12, chunkZ + 8, Blocks.dirt, 0, 2);
            world.setBlock(chunkX + 7, y + 12, chunkZ + 8, Blocks.dirt, 0, 2);
            world.setBlock(chunkX + 8, y + 12, chunkZ + 8, Blocks.dirt, 0, 2);
            world.setBlock(chunkX + 9, y + 12, chunkZ + 8, Blocks.dirt, 0, 2);
            world.setBlock(chunkX + 10, y + 12, chunkZ + 8, Blocks.dirt, 0, 2);
            world.setBlock(chunkX + 11, y + 12, chunkZ + 8, Blocks.dirt, 0, 2);
            world.setBlock(chunkX + 12, y + 12, chunkZ + 8, Blocks.dirt, 0, 2);
            world.setBlock(chunkX + 13, y + 12, chunkZ + 8, Blocks.stone, 0, 2);
            world.setBlock(chunkX + 14, y + 12, chunkZ + 8, Blocks.dirt, 0, 2);
            world.setBlock(chunkX + 1, y + 12, chunkZ + 9, Blocks.dirt, 0, 2);
            world.setBlock(chunkX + 2, y + 12, chunkZ + 9, Blocks.dirt, 0, 2);
            world.setBlock(chunkX + 3, y + 12, chunkZ + 9, Blocks.dirt, 0, 2);
            world.setBlock(chunkX + 4, y + 12, chunkZ + 9, Blocks.dirt, 0, 2);
            world.setBlock(chunkX + 5, y + 12, chunkZ + 9, Blocks.dirt, 0, 2);
            world.setBlock(chunkX + 6, y + 12, chunkZ + 9, Blocks.dirt, 0, 2);
            world.setBlock(chunkX + 7, y + 12, chunkZ + 9, Blocks.dirt, 0, 2);
            world.setBlock(chunkX + 8, y + 12, chunkZ + 9, Blocks.dirt, 0, 2);
            world.setBlock(chunkX + 9, y + 12, chunkZ + 9, Blocks.dirt, 0, 2);
            world.setBlock(chunkX + 10, y + 12, chunkZ + 9, Blocks.dirt, 0, 2);
            world.setBlock(chunkX + 11, y + 12, chunkZ + 9, Blocks.dirt, 0, 2);
            world.setBlock(chunkX + 12, y + 12, chunkZ + 9, Blocks.stone, 0, 2);
            world.setBlock(chunkX + 13, y + 12, chunkZ + 9, Blocks.stone, 0, 2);
            world.setBlock(chunkX + 1, y + 12, chunkZ + 10, Blocks.dirt, 0, 2);
            world.setBlock(chunkX + 2, y + 12, chunkZ + 10, Blocks.dirt, 0, 2);
            world.setBlock(chunkX + 3, y + 12, chunkZ + 10, Blocks.dirt, 0, 2);
            world.setBlock(chunkX + 4, y + 12, chunkZ + 10, Blocks.dirt, 0, 2);
            world.setBlock(chunkX + 5, y + 12, chunkZ + 10, Blocks.dirt, 0, 2);
            world.setBlock(chunkX + 6, y + 12, chunkZ + 10, Blocks.dirt, 0, 2);
            world.setBlock(chunkX + 7, y + 12, chunkZ + 10, Blocks.dirt, 0, 2);
            world.setBlock(chunkX + 8, y + 12, chunkZ + 10, Blocks.dirt, 0, 2);
            world.setBlock(chunkX + 9, y + 12, chunkZ + 10, Blocks.dirt, 0, 2);
            world.setBlock(chunkX + 10, y + 12, chunkZ + 10, Blocks.dirt, 0, 2);
            world.setBlock(chunkX + 11, y + 12, chunkZ + 10, Blocks.dirt, 0, 2);
            world.setBlock(chunkX + 12, y + 12, chunkZ + 10, Blocks.stone, 0, 2);
            world.setBlock(chunkX + 13, y + 12, chunkZ + 10, Blocks.dirt, 0, 2);
            world.setBlock(chunkX + 1, y + 12, chunkZ + 11, Blocks.stone, 0, 2);
            world.setBlock(chunkX + 2, y + 12, chunkZ + 11, Blocks.dirt, 0, 2);
            world.setBlock(chunkX + 3, y + 12, chunkZ + 11, Blocks.dirt, 0, 2);
            world.setBlock(chunkX + 4, y + 12, chunkZ + 11, Blocks.dirt, 0, 2);
            world.setBlock(chunkX + 5, y + 12, chunkZ + 11, Blocks.dirt, 0, 2);
            world.setBlock(chunkX + 6, y + 12, chunkZ + 11, Blocks.dirt, 0, 2);
            world.setBlock(chunkX + 7, y + 12, chunkZ + 11, Blocks.dirt, 0, 2);
            world.setBlock(chunkX + 8, y + 12, chunkZ + 11, Blocks.dirt, 0, 2);
            world.setBlock(chunkX + 9, y + 12, chunkZ + 11, Blocks.dirt, 0, 2);
            world.setBlock(chunkX + 10, y + 12, chunkZ + 11, Blocks.dirt, 0, 2);
            world.setBlock(chunkX + 11, y + 12, chunkZ + 11, Blocks.stone, 0, 2);
            world.setBlock(chunkX + 12, y + 12, chunkZ + 11, Blocks.stone, 0, 2);
            world.setBlock(chunkX + 13, y + 12, chunkZ + 11, Blocks.stone, 0, 2);
            world.setBlock(chunkX + 2, y + 12, chunkZ + 12, Blocks.stone, 0, 2);
            world.setBlock(chunkX + 3, y + 12, chunkZ + 12, Blocks.dirt, 0, 2);
            world.setBlock(chunkX + 4, y + 12, chunkZ + 12, Blocks.dirt, 0, 2);
            world.setBlock(chunkX + 5, y + 12, chunkZ + 12, Blocks.dirt, 0, 2);
            world.setBlock(chunkX + 6, y + 12, chunkZ + 12, Blocks.dirt, 0, 2);
            world.setBlock(chunkX + 7, y + 12, chunkZ + 12, Blocks.dirt, 0, 2);
            world.setBlock(chunkX + 8, y + 12, chunkZ + 12, Blocks.dirt, 0, 2);
            world.setBlock(chunkX + 9, y + 12, chunkZ + 12, Blocks.dirt, 0, 2);
            world.setBlock(chunkX + 10, y + 12, chunkZ + 12, Blocks.dirt, 0, 2);
            world.setBlock(chunkX + 11, y + 12, chunkZ + 12, Blocks.dirt, 0, 2);
            world.setBlock(chunkX + 12, y + 12, chunkZ + 12, Blocks.stone, 0, 2);
            world.setBlock(chunkX + 3, y + 12, chunkZ + 13, Blocks.stone, 0, 2);
            world.setBlock(chunkX + 4, y + 12, chunkZ + 13, Blocks.stone, 0, 2);
            world.setBlock(chunkX + 5, y + 12, chunkZ + 13, Blocks.dirt, 0, 2);
            world.setBlock(chunkX + 6, y + 12, chunkZ + 13, Blocks.stone, 0, 2);
            world.setBlock(chunkX + 7, y + 12, chunkZ + 13, Blocks.stone, 0, 2);
            world.setBlock(chunkX + 8, y + 12, chunkZ + 13, Blocks.dirt, 0, 2);
            world.setBlock(chunkX + 9, y + 12, chunkZ + 13, Blocks.dirt, 0, 2);
            world.setBlock(chunkX + 10, y + 12, chunkZ + 13, Blocks.stone, 0, 2);
            world.setBlock(chunkX + 11, y + 12, chunkZ + 13, Blocks.stone, 0, 2);
            world.setBlock(chunkX + 6, y + 12, chunkZ + 14, Blocks.stone, 0, 2);
            world.setBlock(chunkX + 7, y + 12, chunkZ + 14, Blocks.stone, 0, 2);
            world.setBlock(chunkX + 8, y + 12, chunkZ + 14, Blocks.stone, 0, 2);
            world.setBlock(chunkX + 5, y + 13, chunkZ + 0, Blocks.dirt, 0, 2);
            world.setBlock(chunkX + 6, y + 13, chunkZ + 0, Blocks.dirt, 0, 2);
            world.setBlock(chunkX + 7, y + 13, chunkZ + 0, Blocks.dirt, 0, 2);
            world.setBlock(chunkX + 8, y + 13, chunkZ + 0, Blocks.dirt, 0, 2);
            world.setBlock(chunkX + 9, y + 13, chunkZ + 0, Blocks.dirt, 0, 2);
            world.setBlock(chunkX + 3, y + 13, chunkZ + 1, Blocks.dirt, 0, 2);
            world.setBlock(chunkX + 4, y + 13, chunkZ + 1, Blocks.dirt, 0, 2);
            world.setBlock(chunkX + 5, y + 13, chunkZ + 1, Blocks.dirt, 0, 2);
            world.setBlock(chunkX + 6, y + 13, chunkZ + 1, Blocks.dirt, 0, 2);
            world.setBlock(chunkX + 7, y + 13, chunkZ + 1, Blocks.dirt, 0, 2);
            world.setBlock(chunkX + 8, y + 13, chunkZ + 1, Blocks.dirt, 0, 2);
            world.setBlock(chunkX + 9, y + 13, chunkZ + 1, Blocks.dirt, 0, 2);
            world.setBlock(chunkX + 10, y + 13, chunkZ + 1, Blocks.stone, 0, 2);
            world.setBlock(chunkX + 11, y + 13, chunkZ + 1, Blocks.dirt, 0, 2);
            world.setBlock(chunkX + 2, y + 13, chunkZ + 2, Blocks.dirt, 0, 2);
            world.setBlock(chunkX + 3, y + 13, chunkZ + 2, Blocks.dirt, 0, 2);
            world.setBlock(chunkX + 4, y + 13, chunkZ + 2, Blocks.dirt, 0, 2);
            world.setBlock(chunkX + 5, y + 13, chunkZ + 2, Blocks.dirt, 0, 2);
            world.setBlock(chunkX + 6, y + 13, chunkZ + 2, Blocks.dirt, 0, 2);
            world.setBlock(chunkX + 7, y + 13, chunkZ + 2, Blocks.dirt, 0, 2);
            world.setBlock(chunkX + 8, y + 13, chunkZ + 2, Blocks.dirt, 0, 2);
            world.setBlock(chunkX + 9, y + 13, chunkZ + 2, Blocks.dirt, 0, 2);
            world.setBlock(chunkX + 10, y + 13, chunkZ + 2, Blocks.dirt, 0, 2);
            world.setBlock(chunkX + 11, y + 13, chunkZ + 2, Blocks.dirt, 0, 2);
            world.setBlock(chunkX + 12, y + 13, chunkZ + 2, Blocks.dirt, 0, 2);
            world.setBlock(chunkX + 13, y + 13, chunkZ + 2, Blocks.dirt, 0, 2);
            world.setBlock(chunkX + 1, y + 13, chunkZ + 3, Blocks.dirt, 0, 2);
            world.setBlock(chunkX + 2, y + 13, chunkZ + 3, Blocks.dirt, 0, 2);
            world.setBlock(chunkX + 3, y + 13, chunkZ + 3, Blocks.dirt, 0, 2);
            world.setBlock(chunkX + 4, y + 13, chunkZ + 3, Blocks.dirt, 0, 2);
            world.setBlock(chunkX + 5, y + 13, chunkZ + 3, Blocks.dirt, 0, 2);
            world.setBlock(chunkX + 6, y + 13, chunkZ + 3, Blocks.dirt, 0, 2);
            world.setBlock(chunkX + 7, y + 13, chunkZ + 3, Blocks.dirt, 0, 2);
            world.setBlock(chunkX + 8, y + 13, chunkZ + 3, Blocks.dirt, 0, 2);
            world.setBlock(chunkX + 9, y + 13, chunkZ + 3, Blocks.dirt, 0, 2);
            world.setBlock(chunkX + 10, y + 13, chunkZ + 3, Blocks.dirt, 0, 2);
            world.setBlock(chunkX + 11, y + 13, chunkZ + 3, Blocks.dirt, 0, 2);
            world.setBlock(chunkX + 12, y + 13, chunkZ + 3, Blocks.dirt, 0, 2);
            world.setBlock(chunkX + 13, y + 13, chunkZ + 3, Blocks.stone, 0, 2);
            world.setBlock(chunkX + 1, y + 13, chunkZ + 4, Blocks.dirt, 0, 2);
            world.setBlock(chunkX + 2, y + 13, chunkZ + 4, Blocks.dirt, 0, 2);
            world.setBlock(chunkX + 3, y + 13, chunkZ + 4, Blocks.dirt, 0, 2);
            world.setBlock(chunkX + 4, y + 13, chunkZ + 4, Blocks.dirt, 0, 2);
            world.setBlock(chunkX + 5, y + 13, chunkZ + 4, Blocks.dirt, 0, 2);
            world.setBlock(chunkX + 6, y + 13, chunkZ + 4, Blocks.dirt, 0, 2);
            world.setBlock(chunkX + 7, y + 13, chunkZ + 4, Blocks.dirt, 0, 2);
            world.setBlock(chunkX + 8, y + 13, chunkZ + 4, Blocks.dirt, 0, 2);
            world.setBlock(chunkX + 9, y + 13, chunkZ + 4, Blocks.dirt, 0, 2);
            world.setBlock(chunkX + 10, y + 13, chunkZ + 4, Blocks.dirt, 0, 2);
            world.setBlock(chunkX + 11, y + 13, chunkZ + 4, Blocks.dirt, 0, 2);
            world.setBlock(chunkX + 12, y + 13, chunkZ + 4, Blocks.dirt, 0, 2);
            world.setBlock(chunkX + 13, y + 13, chunkZ + 4, Blocks.dirt, 0, 2);
            world.setBlock(chunkX + 0, y + 13, chunkZ + 5, Blocks.stone, 0, 2);
            world.setBlock(chunkX + 1, y + 13, chunkZ + 5, Blocks.dirt, 0, 2);
            world.setBlock(chunkX + 2, y + 13, chunkZ + 5, Blocks.dirt, 0, 2);
            world.setBlock(chunkX + 3, y + 13, chunkZ + 5, Blocks.dirt, 0, 2);
            world.setBlock(chunkX + 4, y + 13, chunkZ + 5, Blocks.dirt, 0, 2);
            world.setBlock(chunkX + 5, y + 13, chunkZ + 5, Blocks.dirt, 0, 2);
            world.setBlock(chunkX + 6, y + 13, chunkZ + 5, Blocks.dirt, 0, 2);
            world.setBlock(chunkX + 7, y + 13, chunkZ + 5, Blocks.dirt, 0, 2);
            world.setBlock(chunkX + 8, y + 13, chunkZ + 5, Blocks.dirt, 0, 2);
            world.setBlock(chunkX + 9, y + 13, chunkZ + 5, Blocks.dirt, 0, 2);
            world.setBlock(chunkX + 10, y + 13, chunkZ + 5, Blocks.dirt, 0, 2);
            world.setBlock(chunkX + 11, y + 13, chunkZ + 5, Blocks.dirt, 0, 2);
            world.setBlock(chunkX + 12, y + 13, chunkZ + 5, Blocks.dirt, 0, 2);
            world.setBlock(chunkX + 13, y + 13, chunkZ + 5, Blocks.dirt, 0, 2);
            world.setBlock(chunkX + 14, y + 13, chunkZ + 5, Blocks.dirt, 0, 2);
            world.setBlock(chunkX + 0, y + 13, chunkZ + 6, Blocks.dirt, 0, 2);
            world.setBlock(chunkX + 1, y + 13, chunkZ + 6, Blocks.dirt, 0, 2);
            world.setBlock(chunkX + 2, y + 13, chunkZ + 6, Blocks.dirt, 0, 2);
            world.setBlock(chunkX + 3, y + 13, chunkZ + 6, Blocks.dirt, 0, 2);
            world.setBlock(chunkX + 4, y + 13, chunkZ + 6, Blocks.dirt, 0, 2);
            world.setBlock(chunkX + 5, y + 13, chunkZ + 6, Blocks.dirt, 0, 2);
            world.setBlock(chunkX + 6, y + 13, chunkZ + 6, Blocks.dirt, 0, 2);
            world.setBlock(chunkX + 7, y + 13, chunkZ + 6, Blocks.dirt, 0, 2);
            world.setBlock(chunkX + 8, y + 13, chunkZ + 6, Blocks.dirt, 0, 2);
            world.setBlock(chunkX + 9, y + 13, chunkZ + 6, Blocks.dirt, 0, 2);
            world.setBlock(chunkX + 10, y + 13, chunkZ + 6, Blocks.dirt, 0, 2);
            world.setBlock(chunkX + 11, y + 13, chunkZ + 6, Blocks.dirt, 0, 2);
            world.setBlock(chunkX + 12, y + 13, chunkZ + 6, Blocks.dirt, 0, 2);
            world.setBlock(chunkX + 13, y + 13, chunkZ + 6, Blocks.dirt, 0, 2);
            world.setBlock(chunkX + 14, y + 13, chunkZ + 6, Blocks.dirt, 0, 2);
            world.setBlock(chunkX + 15, y + 13, chunkZ + 6, Blocks.dirt, 0, 2);
            world.setBlock(chunkX + 0, y + 13, chunkZ + 7, Blocks.dirt, 0, 2);
            world.setBlock(chunkX + 1, y + 13, chunkZ + 7, Blocks.dirt, 0, 2);
            world.setBlock(chunkX + 2, y + 13, chunkZ + 7, Blocks.dirt, 0, 2);
            world.setBlock(chunkX + 3, y + 13, chunkZ + 7, Blocks.dirt, 0, 2);
            world.setBlock(chunkX + 4, y + 13, chunkZ + 7, Blocks.dirt, 0, 2);
            world.setBlock(chunkX + 5, y + 13, chunkZ + 7, Blocks.dirt, 0, 2);
            world.setBlock(chunkX + 6, y + 13, chunkZ + 7, Blocks.dirt, 0, 2);
            world.setBlock(chunkX + 7, y + 13, chunkZ + 7, Blocks.dirt, 0, 2);
            world.setBlock(chunkX + 8, y + 13, chunkZ + 7, Blocks.dirt, 0, 2);
            world.setBlock(chunkX + 9, y + 13, chunkZ + 7, Blocks.dirt, 0, 2);
            world.setBlock(chunkX + 10, y + 13, chunkZ + 7, Blocks.dirt, 0, 2);
            world.setBlock(chunkX + 11, y + 13, chunkZ + 7, Blocks.dirt, 0, 2);
            world.setBlock(chunkX + 12, y + 13, chunkZ + 7, Blocks.dirt, 0, 2);
            world.setBlock(chunkX + 13, y + 13, chunkZ + 7, Blocks.dirt, 0, 2);
            world.setBlock(chunkX + 14, y + 13, chunkZ + 7, Blocks.dirt, 0, 2);
            world.setBlock(chunkX + 15, y + 13, chunkZ + 7, Blocks.dirt, 0, 2);
            world.setBlock(chunkX + 0, y + 13, chunkZ + 8, Blocks.dirt, 0, 2);
            world.setBlock(chunkX + 1, y + 13, chunkZ + 8, Blocks.dirt, 0, 2);
            world.setBlock(chunkX + 2, y + 13, chunkZ + 8, Blocks.dirt, 0, 2);
            world.setBlock(chunkX + 3, y + 13, chunkZ + 8, Blocks.dirt, 0, 2);
            world.setBlock(chunkX + 4, y + 13, chunkZ + 8, Blocks.dirt, 0, 2);
            world.setBlock(chunkX + 5, y + 13, chunkZ + 8, Blocks.dirt, 0, 2);
            world.setBlock(chunkX + 6, y + 13, chunkZ + 8, Blocks.dirt, 0, 2);
            world.setBlock(chunkX + 7, y + 13, chunkZ + 8, Blocks.dirt, 0, 2);
            world.setBlock(chunkX + 8, y + 13, chunkZ + 8, Blocks.dirt, 0, 2);
            world.setBlock(chunkX + 9, y + 13, chunkZ + 8, Blocks.dirt, 0, 2);
            world.setBlock(chunkX + 10, y + 13, chunkZ + 8, Blocks.dirt, 0, 2);
            world.setBlock(chunkX + 11, y + 13, chunkZ + 8, Blocks.dirt, 0, 2);
            world.setBlock(chunkX + 12, y + 13, chunkZ + 8, Blocks.dirt, 0, 2);
            world.setBlock(chunkX + 13, y + 13, chunkZ + 8, Blocks.dirt, 0, 2);
            world.setBlock(chunkX + 14, y + 13, chunkZ + 8, Blocks.dirt, 0, 2);
            world.setBlock(chunkX + 15, y + 13, chunkZ + 8, Blocks.dirt, 0, 2);
            this.generateCont(world, random, chunkX, y, chunkZ);
        }
    }
    
