package apocalypse.fandomcraft.structures;

import net.minecraft.world.*;
import java.util.*;
import apocalypse.fandomcraft.fable.*;
import net.minecraft.init.*;
import net.minecraft.block.*;
import net.minecraft.tileentity.*;
import net.minecraftforge.common.*;
import net.minecraft.util.*;
import net.minecraft.inventory.*;
import apocalypse.fandomcraft.main.*;
import net.minecraft.world.gen.structure.*;
import net.minecraft.nbt.*;

public class DungeonFairyIsland extends StructureComponent
{
    public void generateStart(final World world, final Random random, final int chunkX, final int chunkY, final int chunkZ) {
        final int j = world.getHeightValue(chunkX, chunkZ) - 10;
        final boolean place = true;
        if (place) {
            if (!world.getBiomeGenForCoords(chunkX, chunkZ).biomeName.equals(BiomeGen.ocean.biomeName)) {
                if (!world.getBiomeGenForCoords(chunkX, chunkZ).biomeName.equals(BiomeGen.deepOcean.biomeName)) {
                    return;
                }
            }
            world.setBlock(chunkX + 9, j + 0, chunkZ + 1, Blocks.dirt, 0, 2);
            world.setBlock(chunkX + 10, j + 0, chunkZ + 1, Blocks.dirt, 0, 2);
            world.setBlock(chunkX + 11, j + 0, chunkZ + 1, Blocks.dirt, 0, 2);
            world.setBlock(chunkX + 12, j + 0, chunkZ + 1, Blocks.dirt, 0, 2);
            world.setBlock(chunkX + 13, j + 0, chunkZ + 1, Blocks.dirt, 0, 2);
            world.setBlock(chunkX + 7, j + 0, chunkZ + 2, Blocks.dirt, 0, 2);
            world.setBlock(chunkX + 8, j + 0, chunkZ + 2, Blocks.dirt, 0, 2);
            world.setBlock(chunkX + 9, j + 0, chunkZ + 2, Blocks.dirt, 0, 2);
            world.setBlock(chunkX + 10, j + 0, chunkZ + 2, Blocks.dirt, 0, 2);
            world.setBlock(chunkX + 11, j + 0, chunkZ + 2, Blocks.dirt, 0, 2);
            world.setBlock(chunkX + 12, j + 0, chunkZ + 2, Blocks.dirt, 0, 2);
            world.setBlock(chunkX + 13, j + 0, chunkZ + 2, Blocks.dirt, 0, 2);
            world.setBlock(chunkX + 14, j + 0, chunkZ + 2, Blocks.dirt, 0, 2);
            world.setBlock(chunkX + 15, j + 0, chunkZ + 2, Blocks.dirt, 0, 2);
            world.setBlock(chunkX + 5, j + 0, chunkZ + 3, Blocks.dirt, 0, 2);
            world.setBlock(chunkX + 6, j + 0, chunkZ + 3, Blocks.dirt, 0, 2);
            world.setBlock(chunkX + 7, j + 0, chunkZ + 3, Blocks.dirt, 0, 2);
            world.setBlock(chunkX + 8, j + 0, chunkZ + 3, Blocks.dirt, 0, 2);
            world.setBlock(chunkX + 9, j + 0, chunkZ + 3, Blocks.dirt, 0, 2);
            world.setBlock(chunkX + 10, j + 0, chunkZ + 3, Blocks.dirt, 0, 2);
            world.setBlock(chunkX + 11, j + 0, chunkZ + 3, Blocks.dirt, 0, 2);
            world.setBlock(chunkX + 12, j + 0, chunkZ + 3, Blocks.dirt, 0, 2);
            world.setBlock(chunkX + 13, j + 0, chunkZ + 3, Blocks.dirt, 0, 2);
            world.setBlock(chunkX + 14, j + 0, chunkZ + 3, Blocks.dirt, 0, 2);
            world.setBlock(chunkX + 15, j + 0, chunkZ + 3, Blocks.dirt, 0, 2);
            world.setBlock(chunkX + 16, j + 0, chunkZ + 3, Blocks.dirt, 0, 2);
            world.setBlock(chunkX + 17, j + 0, chunkZ + 3, Blocks.dirt, 0, 2);
            world.setBlock(chunkX + 4, j + 0, chunkZ + 4, Blocks.dirt, 0, 2);
            world.setBlock(chunkX + 5, j + 0, chunkZ + 4, Blocks.dirt, 0, 2);
            world.setBlock(chunkX + 6, j + 0, chunkZ + 4, Blocks.dirt, 0, 2);
            world.setBlock(chunkX + 7, j + 0, chunkZ + 4, Blocks.dirt, 0, 2);
            world.setBlock(chunkX + 8, j + 0, chunkZ + 4, Blocks.dirt, 0, 2);
            world.setBlock(chunkX + 9, j + 0, chunkZ + 4, Blocks.dirt, 0, 2);
            world.setBlock(chunkX + 10, j + 0, chunkZ + 4, Blocks.dirt, 0, 2);
            world.setBlock(chunkX + 11, j + 0, chunkZ + 4, Blocks.dirt, 0, 2);
            world.setBlock(chunkX + 12, j + 0, chunkZ + 4, Blocks.dirt, 0, 2);
            world.setBlock(chunkX + 13, j + 0, chunkZ + 4, Blocks.dirt, 0, 2);
            world.setBlock(chunkX + 14, j + 0, chunkZ + 4, Blocks.dirt, 0, 2);
            world.setBlock(chunkX + 15, j + 0, chunkZ + 4, Blocks.dirt, 0, 2);
            world.setBlock(chunkX + 16, j + 0, chunkZ + 4, Blocks.dirt, 0, 2);
            world.setBlock(chunkX + 17, j + 0, chunkZ + 4, Blocks.dirt, 0, 2);
            world.setBlock(chunkX + 18, j + 0, chunkZ + 4, Blocks.dirt, 0, 2);
            world.setBlock(chunkX + 4, j + 0, chunkZ + 5, Blocks.dirt, 0, 2);
            world.setBlock(chunkX + 5, j + 0, chunkZ + 5, Blocks.dirt, 0, 2);
            world.setBlock(chunkX + 6, j + 0, chunkZ + 5, Blocks.dirt, 0, 2);
            world.setBlock(chunkX + 7, j + 0, chunkZ + 5, Blocks.dirt, 0, 2);
            world.setBlock(chunkX + 8, j + 0, chunkZ + 5, Blocks.dirt, 0, 2);
            world.setBlock(chunkX + 9, j + 0, chunkZ + 5, Blocks.dirt, 0, 2);
            world.setBlock(chunkX + 10, j + 0, chunkZ + 5, Blocks.dirt, 0, 2);
            world.setBlock(chunkX + 11, j + 0, chunkZ + 5, Blocks.dirt, 0, 2);
            world.setBlock(chunkX + 12, j + 0, chunkZ + 5, Blocks.dirt, 0, 2);
            world.setBlock(chunkX + 13, j + 0, chunkZ + 5, Blocks.dirt, 0, 2);
            world.setBlock(chunkX + 14, j + 0, chunkZ + 5, Blocks.dirt, 0, 2);
            world.setBlock(chunkX + 15, j + 0, chunkZ + 5, Blocks.dirt, 0, 2);
            world.setBlock(chunkX + 16, j + 0, chunkZ + 5, Blocks.dirt, 0, 2);
            world.setBlock(chunkX + 17, j + 0, chunkZ + 5, Blocks.dirt, 0, 2);
            world.setBlock(chunkX + 18, j + 0, chunkZ + 5, Blocks.dirt, 0, 2);
            world.setBlock(chunkX + 3, j + 0, chunkZ + 6, Blocks.dirt, 0, 2);
            world.setBlock(chunkX + 4, j + 0, chunkZ + 6, Blocks.dirt, 0, 2);
            world.setBlock(chunkX + 5, j + 0, chunkZ + 6, Blocks.dirt, 0, 2);
            world.setBlock(chunkX + 6, j + 0, chunkZ + 6, Blocks.dirt, 0, 2);
            world.setBlock(chunkX + 7, j + 0, chunkZ + 6, Blocks.dirt, 0, 2);
            world.setBlock(chunkX + 8, j + 0, chunkZ + 6, Blocks.dirt, 0, 2);
            world.setBlock(chunkX + 9, j + 0, chunkZ + 6, Blocks.dirt, 0, 2);
            world.setBlock(chunkX + 10, j + 0, chunkZ + 6, Blocks.dirt, 0, 2);
            world.setBlock(chunkX + 11, j + 0, chunkZ + 6, Blocks.dirt, 0, 2);
            world.setBlock(chunkX + 12, j + 0, chunkZ + 6, Blocks.dirt, 0, 2);
            world.setBlock(chunkX + 13, j + 0, chunkZ + 6, Blocks.dirt, 0, 2);
            world.setBlock(chunkX + 14, j + 0, chunkZ + 6, Blocks.dirt, 0, 2);
            world.setBlock(chunkX + 15, j + 0, chunkZ + 6, Blocks.dirt, 0, 2);
            world.setBlock(chunkX + 16, j + 0, chunkZ + 6, Blocks.dirt, 0, 2);
            world.setBlock(chunkX + 17, j + 0, chunkZ + 6, Blocks.dirt, 0, 2);
            world.setBlock(chunkX + 18, j + 0, chunkZ + 6, Blocks.dirt, 0, 2);
            world.setBlock(chunkX + 19, j + 0, chunkZ + 6, Blocks.dirt, 0, 2);
            world.setBlock(chunkX + 3, j + 0, chunkZ + 7, Blocks.dirt, 0, 2);
            world.setBlock(chunkX + 4, j + 0, chunkZ + 7, Blocks.dirt, 0, 2);
            world.setBlock(chunkX + 5, j + 0, chunkZ + 7, Blocks.dirt, 0, 2);
            world.setBlock(chunkX + 6, j + 0, chunkZ + 7, Blocks.dirt, 0, 2);
            world.setBlock(chunkX + 7, j + 0, chunkZ + 7, Blocks.dirt, 0, 2);
            world.setBlock(chunkX + 8, j + 0, chunkZ + 7, Blocks.dirt, 0, 2);
            world.setBlock(chunkX + 9, j + 0, chunkZ + 7, Blocks.dirt, 0, 2);
            world.setBlock(chunkX + 10, j + 0, chunkZ + 7, Blocks.dirt, 0, 2);
            world.setBlock(chunkX + 11, j + 0, chunkZ + 7, Blocks.dirt, 0, 2);
            world.setBlock(chunkX + 12, j + 0, chunkZ + 7, Blocks.dirt, 0, 2);
            world.setBlock(chunkX + 13, j + 0, chunkZ + 7, Blocks.dirt, 0, 2);
            world.setBlock(chunkX + 14, j + 0, chunkZ + 7, Blocks.dirt, 0, 2);
            world.setBlock(chunkX + 15, j + 0, chunkZ + 7, Blocks.dirt, 0, 2);
            world.setBlock(chunkX + 16, j + 0, chunkZ + 7, Blocks.dirt, 0, 2);
            world.setBlock(chunkX + 17, j + 0, chunkZ + 7, Blocks.dirt, 0, 2);
            world.setBlock(chunkX + 18, j + 0, chunkZ + 7, Blocks.dirt, 0, 2);
            world.setBlock(chunkX + 19, j + 0, chunkZ + 7, Blocks.dirt, 0, 2);
            world.setBlock(chunkX + 2, j + 0, chunkZ + 8, Blocks.dirt, 0, 2);
            world.setBlock(chunkX + 3, j + 0, chunkZ + 8, Blocks.dirt, 0, 2);
            world.setBlock(chunkX + 4, j + 0, chunkZ + 8, Blocks.dirt, 0, 2);
            world.setBlock(chunkX + 5, j + 0, chunkZ + 8, Blocks.dirt, 0, 2);
            world.setBlock(chunkX + 6, j + 0, chunkZ + 8, Blocks.dirt, 0, 2);
            world.setBlock(chunkX + 7, j + 0, chunkZ + 8, Blocks.dirt, 0, 2);
            world.setBlock(chunkX + 8, j + 0, chunkZ + 8, Blocks.dirt, 0, 2);
            world.setBlock(chunkX + 9, j + 0, chunkZ + 8, Blocks.dirt, 0, 2);
            world.setBlock(chunkX + 10, j + 0, chunkZ + 8, Blocks.dirt, 0, 2);
            world.setBlock(chunkX + 11, j + 0, chunkZ + 8, Blocks.dirt, 0, 2);
            world.setBlock(chunkX + 12, j + 0, chunkZ + 8, Blocks.dirt, 0, 2);
            world.setBlock(chunkX + 13, j + 0, chunkZ + 8, Blocks.dirt, 0, 2);
            world.setBlock(chunkX + 14, j + 0, chunkZ + 8, Blocks.dirt, 0, 2);
            world.setBlock(chunkX + 15, j + 0, chunkZ + 8, Blocks.dirt, 0, 2);
            world.setBlock(chunkX + 16, j + 0, chunkZ + 8, Blocks.dirt, 0, 2);
            world.setBlock(chunkX + 17, j + 0, chunkZ + 8, Blocks.dirt, 0, 2);
            world.setBlock(chunkX + 18, j + 0, chunkZ + 8, Blocks.dirt, 0, 2);
            world.setBlock(chunkX + 19, j + 0, chunkZ + 8, Blocks.dirt, 0, 2);
            world.setBlock(chunkX + 20, j + 0, chunkZ + 8, Blocks.dirt, 0, 2);
            world.setBlock(chunkX + 2, j + 0, chunkZ + 9, Blocks.dirt, 0, 2);
            world.setBlock(chunkX + 3, j + 0, chunkZ + 9, Blocks.dirt, 0, 2);
            world.setBlock(chunkX + 4, j + 0, chunkZ + 9, Blocks.dirt, 0, 2);
            world.setBlock(chunkX + 5, j + 0, chunkZ + 9, Blocks.dirt, 0, 2);
            world.setBlock(chunkX + 6, j + 0, chunkZ + 9, Blocks.dirt, 0, 2);
            world.setBlock(chunkX + 7, j + 0, chunkZ + 9, Blocks.stone, 0, 2);
            world.setBlock(chunkX + 8, j + 0, chunkZ + 9, Blocks.dirt, 0, 2);
            world.setBlock(chunkX + 9, j + 0, chunkZ + 9, Blocks.dirt, 0, 2);
            world.setBlock(chunkX + 10, j + 0, chunkZ + 9, Blocks.dirt, 0, 2);
            world.setBlock(chunkX + 11, j + 0, chunkZ + 9, Blocks.dirt, 0, 2);
            world.setBlock(chunkX + 12, j + 0, chunkZ + 9, Blocks.dirt, 0, 2);
            world.setBlock(chunkX + 13, j + 0, chunkZ + 9, Blocks.dirt, 0, 2);
            world.setBlock(chunkX + 14, j + 0, chunkZ + 9, Blocks.dirt, 0, 2);
            world.setBlock(chunkX + 15, j + 0, chunkZ + 9, Blocks.dirt, 0, 2);
            world.setBlock(chunkX + 16, j + 0, chunkZ + 9, Blocks.dirt, 0, 2);
            world.setBlock(chunkX + 17, j + 0, chunkZ + 9, Blocks.dirt, 0, 2);
            world.setBlock(chunkX + 18, j + 0, chunkZ + 9, Blocks.dirt, 0, 2);
            world.setBlock(chunkX + 19, j + 0, chunkZ + 9, Blocks.dirt, 0, 2);
            world.setBlock(chunkX + 20, j + 0, chunkZ + 9, Blocks.dirt, 0, 2);
            world.setBlock(chunkX + 2, j + 0, chunkZ + 10, Blocks.dirt, 0, 2);
            world.setBlock(chunkX + 3, j + 0, chunkZ + 10, Blocks.dirt, 0, 2);
            world.setBlock(chunkX + 4, j + 0, chunkZ + 10, Blocks.dirt, 0, 2);
            world.setBlock(chunkX + 5, j + 0, chunkZ + 10, Blocks.dirt, 0, 2);
            world.setBlock(chunkX + 6, j + 0, chunkZ + 10, Blocks.stone, 0, 2);
            world.setBlock(chunkX + 7, j + 0, chunkZ + 10, Blocks.stone, 0, 2);
            world.setBlock(chunkX + 8, j + 0, chunkZ + 10, Blocks.stone, 0, 2);
            world.setBlock(chunkX + 9, j + 0, chunkZ + 10, Blocks.dirt, 0, 2);
            world.setBlock(chunkX + 10, j + 0, chunkZ + 10, Blocks.dirt, 0, 2);
            world.setBlock(chunkX + 11, j + 0, chunkZ + 10, Blocks.dirt, 0, 2);
            world.setBlock(chunkX + 12, j + 0, chunkZ + 10, Blocks.dirt, 0, 2);
            world.setBlock(chunkX + 13, j + 0, chunkZ + 10, Blocks.dirt, 0, 2);
            world.setBlock(chunkX + 14, j + 0, chunkZ + 10, Blocks.dirt, 0, 2);
            world.setBlock(chunkX + 15, j + 0, chunkZ + 10, Blocks.dirt, 0, 2);
            world.setBlock(chunkX + 16, j + 0, chunkZ + 10, Blocks.dirt, 0, 2);
            world.setBlock(chunkX + 17, j + 0, chunkZ + 10, Blocks.dirt, 0, 2);
            world.setBlock(chunkX + 18, j + 0, chunkZ + 10, Blocks.dirt, 0, 2);
            world.setBlock(chunkX + 19, j + 0, chunkZ + 10, Blocks.dirt, 0, 2);
            world.setBlock(chunkX + 20, j + 0, chunkZ + 10, Blocks.dirt, 0, 2);
            world.setBlock(chunkX + 2, j + 0, chunkZ + 11, Blocks.dirt, 0, 2);
            world.setBlock(chunkX + 3, j + 0, chunkZ + 11, Blocks.dirt, 0, 2);
            world.setBlock(chunkX + 4, j + 0, chunkZ + 11, Blocks.dirt, 0, 2);
            world.setBlock(chunkX + 5, j + 0, chunkZ + 11, Blocks.dirt, 0, 2);
            world.setBlock(chunkX + 6, j + 0, chunkZ + 11, Blocks.dirt, 0, 2);
            world.setBlock(chunkX + 7, j + 0, chunkZ + 11, Blocks.stone, 0, 2);
            world.setBlock(chunkX + 8, j + 0, chunkZ + 11, Blocks.dirt, 0, 2);
            world.setBlock(chunkX + 9, j + 0, chunkZ + 11, Blocks.dirt, 0, 2);
            world.setBlock(chunkX + 10, j + 0, chunkZ + 11, Blocks.dirt, 0, 2);
            world.setBlock(chunkX + 11, j + 0, chunkZ + 11, Blocks.dirt, 0, 2);
            world.setBlock(chunkX + 12, j + 0, chunkZ + 11, Blocks.dirt, 0, 2);
            world.setBlock(chunkX + 13, j + 0, chunkZ + 11, Blocks.dirt, 0, 2);
            world.setBlock(chunkX + 14, j + 0, chunkZ + 11, Blocks.dirt, 0, 2);
            world.setBlock(chunkX + 15, j + 0, chunkZ + 11, Blocks.dirt, 0, 2);
            world.setBlock(chunkX + 16, j + 0, chunkZ + 11, Blocks.dirt, 0, 2);
            world.setBlock(chunkX + 17, j + 0, chunkZ + 11, Blocks.dirt, 0, 2);
            world.setBlock(chunkX + 18, j + 0, chunkZ + 11, Blocks.dirt, 0, 2);
            world.setBlock(chunkX + 19, j + 0, chunkZ + 11, Blocks.dirt, 0, 2);
            world.setBlock(chunkX + 20, j + 0, chunkZ + 11, Blocks.dirt, 0, 2);
            world.setBlock(chunkX + 3, j + 0, chunkZ + 12, Blocks.dirt, 0, 2);
            world.setBlock(chunkX + 4, j + 0, chunkZ + 12, Blocks.dirt, 0, 2);
            world.setBlock(chunkX + 5, j + 0, chunkZ + 12, Blocks.dirt, 0, 2);
            world.setBlock(chunkX + 6, j + 0, chunkZ + 12, Blocks.dirt, 0, 2);
            world.setBlock(chunkX + 7, j + 0, chunkZ + 12, Blocks.dirt, 0, 2);
            world.setBlock(chunkX + 8, j + 0, chunkZ + 12, Blocks.dirt, 0, 2);
            world.setBlock(chunkX + 9, j + 0, chunkZ + 12, Blocks.dirt, 0, 2);
            world.setBlock(chunkX + 10, j + 0, chunkZ + 12, Blocks.dirt, 0, 2);
            world.setBlock(chunkX + 11, j + 0, chunkZ + 12, Blocks.dirt, 0, 2);
            world.setBlock(chunkX + 12, j + 0, chunkZ + 12, Blocks.dirt, 0, 2);
            world.setBlock(chunkX + 13, j + 0, chunkZ + 12, Blocks.dirt, 0, 2);
            world.setBlock(chunkX + 14, j + 0, chunkZ + 12, Blocks.dirt, 0, 2);
            world.setBlock(chunkX + 15, j + 0, chunkZ + 12, Blocks.dirt, 0, 2);
            world.setBlock(chunkX + 16, j + 0, chunkZ + 12, Blocks.dirt, 0, 2);
            world.setBlock(chunkX + 17, j + 0, chunkZ + 12, Blocks.dirt, 0, 2);
            world.setBlock(chunkX + 18, j + 0, chunkZ + 12, Blocks.dirt, 0, 2);
            world.setBlock(chunkX + 19, j + 0, chunkZ + 12, Blocks.dirt, 0, 2);
            world.setBlock(chunkX + 3, j + 0, chunkZ + 13, Blocks.dirt, 0, 2);
            world.setBlock(chunkX + 4, j + 0, chunkZ + 13, Blocks.dirt, 0, 2);
            world.setBlock(chunkX + 5, j + 0, chunkZ + 13, Blocks.dirt, 0, 2);
            world.setBlock(chunkX + 6, j + 0, chunkZ + 13, Blocks.dirt, 0, 2);
            world.setBlock(chunkX + 7, j + 0, chunkZ + 13, Blocks.dirt, 0, 2);
            world.setBlock(chunkX + 8, j + 0, chunkZ + 13, Blocks.dirt, 0, 2);
            world.setBlock(chunkX + 9, j + 0, chunkZ + 13, Blocks.dirt, 0, 2);
            world.setBlock(chunkX + 10, j + 0, chunkZ + 13, Blocks.dirt, 0, 2);
            world.setBlock(chunkX + 11, j + 0, chunkZ + 13, Blocks.dirt, 0, 2);
            world.setBlock(chunkX + 12, j + 0, chunkZ + 13, Blocks.dirt, 0, 2);
            world.setBlock(chunkX + 13, j + 0, chunkZ + 13, Blocks.dirt, 0, 2);
            world.setBlock(chunkX + 14, j + 0, chunkZ + 13, Blocks.dirt, 0, 2);
            world.setBlock(chunkX + 15, j + 0, chunkZ + 13, Blocks.dirt, 0, 2);
            world.setBlock(chunkX + 16, j + 0, chunkZ + 13, Blocks.dirt, 0, 2);
            world.setBlock(chunkX + 17, j + 0, chunkZ + 13, Blocks.dirt, 0, 2);
            world.setBlock(chunkX + 18, j + 0, chunkZ + 13, Blocks.dirt, 0, 2);
            world.setBlock(chunkX + 19, j + 0, chunkZ + 13, Blocks.dirt, 0, 2);
            world.setBlock(chunkX + 4, j + 0, chunkZ + 14, Blocks.dirt, 0, 2);
            world.setBlock(chunkX + 5, j + 0, chunkZ + 14, Blocks.dirt, 0, 2);
            world.setBlock(chunkX + 6, j + 0, chunkZ + 14, Blocks.dirt, 0, 2);
            world.setBlock(chunkX + 7, j + 0, chunkZ + 14, Blocks.dirt, 0, 2);
            world.setBlock(chunkX + 8, j + 0, chunkZ + 14, Blocks.dirt, 0, 2);
            world.setBlock(chunkX + 9, j + 0, chunkZ + 14, Blocks.dirt, 0, 2);
            world.setBlock(chunkX + 10, j + 0, chunkZ + 14, Blocks.dirt, 0, 2);
            world.setBlock(chunkX + 11, j + 0, chunkZ + 14, Blocks.dirt, 0, 2);
            world.setBlock(chunkX + 12, j + 0, chunkZ + 14, Blocks.dirt, 0, 2);
            world.setBlock(chunkX + 13, j + 0, chunkZ + 14, Blocks.dirt, 0, 2);
            world.setBlock(chunkX + 14, j + 0, chunkZ + 14, Blocks.dirt, 0, 2);
            world.setBlock(chunkX + 15, j + 0, chunkZ + 14, Blocks.dirt, 0, 2);
            world.setBlock(chunkX + 16, j + 0, chunkZ + 14, Blocks.dirt, 0, 2);
            world.setBlock(chunkX + 17, j + 0, chunkZ + 14, Blocks.dirt, 0, 2);
            world.setBlock(chunkX + 18, j + 0, chunkZ + 14, Blocks.dirt, 0, 2);
            world.setBlock(chunkX + 4, j + 0, chunkZ + 15, Blocks.dirt, 0, 2);
            world.setBlock(chunkX + 5, j + 0, chunkZ + 15, Blocks.dirt, 0, 2);
            world.setBlock(chunkX + 6, j + 0, chunkZ + 15, Blocks.dirt, 0, 2);
            world.setBlock(chunkX + 7, j + 0, chunkZ + 15, Blocks.dirt, 0, 2);
            world.setBlock(chunkX + 8, j + 0, chunkZ + 15, Blocks.dirt, 0, 2);
            world.setBlock(chunkX + 9, j + 0, chunkZ + 15, Blocks.dirt, 0, 2);
            world.setBlock(chunkX + 10, j + 0, chunkZ + 15, Blocks.dirt, 0, 2);
            world.setBlock(chunkX + 11, j + 0, chunkZ + 15, Blocks.dirt, 0, 2);
            world.setBlock(chunkX + 12, j + 0, chunkZ + 15, Blocks.dirt, 0, 2);
            world.setBlock(chunkX + 13, j + 0, chunkZ + 15, Blocks.dirt, 0, 2);
            world.setBlock(chunkX + 14, j + 0, chunkZ + 15, Blocks.dirt, 0, 2);
            world.setBlock(chunkX + 15, j + 0, chunkZ + 15, Blocks.dirt, 0, 2);
            world.setBlock(chunkX + 16, j + 0, chunkZ + 15, Blocks.dirt, 0, 2);
            world.setBlock(chunkX + 17, j + 0, chunkZ + 15, Blocks.dirt, 0, 2);
            world.setBlock(chunkX + 18, j + 0, chunkZ + 15, Blocks.dirt, 0, 2);
            world.setBlock(chunkX + 5, j + 0, chunkZ + 16, Blocks.dirt, 0, 2);
            world.setBlock(chunkX + 6, j + 0, chunkZ + 16, Blocks.dirt, 0, 2);
            world.setBlock(chunkX + 7, j + 0, chunkZ + 16, Blocks.dirt, 0, 2);
            world.setBlock(chunkX + 8, j + 0, chunkZ + 16, Blocks.dirt, 0, 2);
            world.setBlock(chunkX + 9, j + 0, chunkZ + 16, Blocks.dirt, 0, 2);
            world.setBlock(chunkX + 10, j + 0, chunkZ + 16, Blocks.dirt, 0, 2);
            world.setBlock(chunkX + 11, j + 0, chunkZ + 16, Blocks.dirt, 0, 2);
            world.setBlock(chunkX + 12, j + 0, chunkZ + 16, Blocks.dirt, 0, 2);
            world.setBlock(chunkX + 13, j + 0, chunkZ + 16, Blocks.dirt, 0, 2);
            world.setBlock(chunkX + 14, j + 0, chunkZ + 16, Blocks.dirt, 0, 2);
            world.setBlock(chunkX + 15, j + 0, chunkZ + 16, Blocks.dirt, 0, 2);
            world.setBlock(chunkX + 16, j + 0, chunkZ + 16, Blocks.dirt, 0, 2);
            world.setBlock(chunkX + 17, j + 0, chunkZ + 16, Blocks.dirt, 0, 2);
            world.setBlock(chunkX + 7, j + 0, chunkZ + 17, Blocks.dirt, 0, 2);
            world.setBlock(chunkX + 8, j + 0, chunkZ + 17, Blocks.dirt, 0, 2);
            world.setBlock(chunkX + 9, j + 0, chunkZ + 17, Blocks.dirt, 0, 2);
            world.setBlock(chunkX + 10, j + 0, chunkZ + 17, Blocks.dirt, 0, 2);
            world.setBlock(chunkX + 11, j + 0, chunkZ + 17, Blocks.dirt, 0, 2);
            world.setBlock(chunkX + 12, j + 0, chunkZ + 17, Blocks.dirt, 0, 2);
            world.setBlock(chunkX + 13, j + 0, chunkZ + 17, Blocks.dirt, 0, 2);
            world.setBlock(chunkX + 14, j + 0, chunkZ + 17, Blocks.dirt, 0, 2);
            world.setBlock(chunkX + 15, j + 0, chunkZ + 17, Blocks.dirt, 0, 2);
            world.setBlock(chunkX + 10, j + 0, chunkZ + 18, Blocks.dirt, 0, 2);
            world.setBlock(chunkX + 11, j + 0, chunkZ + 18, Blocks.dirt, 0, 2);
            world.setBlock(chunkX + 12, j + 0, chunkZ + 18, Blocks.dirt, 0, 2);
            world.setBlock(chunkX + 13, j + 0, chunkZ + 18, Blocks.dirt, 0, 2);
            world.setBlock(chunkX + 9, j + 1, chunkZ + 0, Blocks.dirt, 0, 2);
            world.setBlock(chunkX + 10, j + 1, chunkZ + 0, Blocks.dirt, 0, 2);
            world.setBlock(chunkX + 11, j + 1, chunkZ + 0, Blocks.dirt, 0, 2);
            world.setBlock(chunkX + 12, j + 1, chunkZ + 0, Blocks.dirt, 0, 2);
            world.setBlock(chunkX + 13, j + 1, chunkZ + 0, Blocks.dirt, 0, 2);
            world.setBlock(chunkX + 14, j + 1, chunkZ + 0, Blocks.dirt, 0, 2);
            world.setBlock(chunkX + 7, j + 1, chunkZ + 1, Blocks.dirt, 0, 2);
            world.setBlock(chunkX + 8, j + 1, chunkZ + 1, Blocks.dirt, 0, 2);
            world.setBlock(chunkX + 9, j + 1, chunkZ + 1, Blocks.dirt, 0, 2);
            world.setBlock(chunkX + 10, j + 1, chunkZ + 1, Blocks.dirt, 0, 2);
            world.setBlock(chunkX + 11, j + 1, chunkZ + 1, Blocks.dirt, 0, 2);
            world.setBlock(chunkX + 12, j + 1, chunkZ + 1, Blocks.dirt, 0, 2);
            world.setBlock(chunkX + 13, j + 1, chunkZ + 1, Blocks.dirt, 0, 2);
            world.setBlock(chunkX + 14, j + 1, chunkZ + 1, Blocks.dirt, 0, 2);
            world.setBlock(chunkX + 15, j + 1, chunkZ + 1, Blocks.dirt, 0, 2);
            world.setBlock(chunkX + 16, j + 1, chunkZ + 1, Blocks.dirt, 0, 2);
            world.setBlock(chunkX + 6, j + 1, chunkZ + 2, Blocks.dirt, 0, 2);
            world.setBlock(chunkX + 7, j + 1, chunkZ + 2, Blocks.dirt, 0, 2);
            world.setBlock(chunkX + 8, j + 1, chunkZ + 2, Blocks.dirt, 0, 2);
            world.setBlock(chunkX + 9, j + 1, chunkZ + 2, Blocks.dirt, 0, 2);
            world.setBlock(chunkX + 10, j + 1, chunkZ + 2, Blocks.dirt, 0, 2);
            world.setBlock(chunkX + 11, j + 1, chunkZ + 2, Blocks.dirt, 0, 2);
            world.setBlock(chunkX + 12, j + 1, chunkZ + 2, Blocks.dirt, 0, 2);
            world.setBlock(chunkX + 13, j + 1, chunkZ + 2, Blocks.dirt, 0, 2);
            world.setBlock(chunkX + 14, j + 1, chunkZ + 2, Blocks.dirt, 0, 2);
            world.setBlock(chunkX + 15, j + 1, chunkZ + 2, Blocks.dirt, 0, 2);
            world.setBlock(chunkX + 16, j + 1, chunkZ + 2, Blocks.dirt, 0, 2);
            world.setBlock(chunkX + 17, j + 1, chunkZ + 2, Blocks.dirt, 0, 2);
            world.setBlock(chunkX + 5, j + 1, chunkZ + 3, Blocks.dirt, 0, 2);
            world.setBlock(chunkX + 6, j + 1, chunkZ + 3, Blocks.dirt, 0, 2);
            world.setBlock(chunkX + 7, j + 1, chunkZ + 3, Blocks.dirt, 0, 2);
            world.setBlock(chunkX + 8, j + 1, chunkZ + 3, Blocks.dirt, 0, 2);
            world.setBlock(chunkX + 9, j + 1, chunkZ + 3, Blocks.dirt, 0, 2);
            world.setBlock(chunkX + 10, j + 1, chunkZ + 3, Blocks.dirt, 0, 2);
            world.setBlock(chunkX + 11, j + 1, chunkZ + 3, Blocks.dirt, 0, 2);
            world.setBlock(chunkX + 12, j + 1, chunkZ + 3, Blocks.dirt, 0, 2);
            world.setBlock(chunkX + 13, j + 1, chunkZ + 3, Blocks.dirt, 0, 2);
            world.setBlock(chunkX + 14, j + 1, chunkZ + 3, Blocks.dirt, 0, 2);
            world.setBlock(chunkX + 15, j + 1, chunkZ + 3, Blocks.dirt, 0, 2);
            world.setBlock(chunkX + 16, j + 1, chunkZ + 3, Blocks.dirt, 0, 2);
            world.setBlock(chunkX + 17, j + 1, chunkZ + 3, Blocks.dirt, 0, 2);
            world.setBlock(chunkX + 18, j + 1, chunkZ + 3, Blocks.dirt, 0, 2);
            world.setBlock(chunkX + 4, j + 1, chunkZ + 4, Blocks.dirt, 0, 2);
            world.setBlock(chunkX + 5, j + 1, chunkZ + 4, Blocks.dirt, 0, 2);
            world.setBlock(chunkX + 6, j + 1, chunkZ + 4, Blocks.dirt, 0, 2);
            world.setBlock(chunkX + 7, j + 1, chunkZ + 4, Blocks.dirt, 0, 2);
            world.setBlock(chunkX + 8, j + 1, chunkZ + 4, Blocks.dirt, 0, 2);
            world.setBlock(chunkX + 9, j + 1, chunkZ + 4, Blocks.dirt, 0, 2);
            world.setBlock(chunkX + 10, j + 1, chunkZ + 4, Blocks.dirt, 0, 2);
            world.setBlock(chunkX + 11, j + 1, chunkZ + 4, Blocks.dirt, 0, 2);
            world.setBlock(chunkX + 12, j + 1, chunkZ + 4, Blocks.dirt, 0, 2);
            world.setBlock(chunkX + 13, j + 1, chunkZ + 4, Blocks.dirt, 0, 2);
            world.setBlock(chunkX + 14, j + 1, chunkZ + 4, Blocks.dirt, 0, 2);
            world.setBlock(chunkX + 15, j + 1, chunkZ + 4, Blocks.dirt, 0, 2);
            world.setBlock(chunkX + 16, j + 1, chunkZ + 4, Blocks.dirt, 0, 2);
            world.setBlock(chunkX + 17, j + 1, chunkZ + 4, Blocks.dirt, 0, 2);
            world.setBlock(chunkX + 18, j + 1, chunkZ + 4, Blocks.dirt, 0, 2);
            world.setBlock(chunkX + 19, j + 1, chunkZ + 4, Blocks.dirt, 0, 2);
            world.setBlock(chunkX + 3, j + 1, chunkZ + 5, Blocks.dirt, 0, 2);
            world.setBlock(chunkX + 4, j + 1, chunkZ + 5, Blocks.dirt, 0, 2);
            world.setBlock(chunkX + 5, j + 1, chunkZ + 5, Blocks.dirt, 0, 2);
            world.setBlock(chunkX + 6, j + 1, chunkZ + 5, Blocks.dirt, 0, 2);
            world.setBlock(chunkX + 7, j + 1, chunkZ + 5, Blocks.dirt, 0, 2);
            world.setBlock(chunkX + 8, j + 1, chunkZ + 5, Blocks.dirt, 0, 2);
            world.setBlock(chunkX + 9, j + 1, chunkZ + 5, Blocks.dirt, 0, 2);
            world.setBlock(chunkX + 10, j + 1, chunkZ + 5, Blocks.dirt, 0, 2);
            world.setBlock(chunkX + 11, j + 1, chunkZ + 5, Blocks.dirt, 0, 2);
            world.setBlock(chunkX + 12, j + 1, chunkZ + 5, Blocks.dirt, 0, 2);
            world.setBlock(chunkX + 13, j + 1, chunkZ + 5, Blocks.dirt, 0, 2);
            world.setBlock(chunkX + 14, j + 1, chunkZ + 5, Blocks.dirt, 0, 2);
            world.setBlock(chunkX + 15, j + 1, chunkZ + 5, Blocks.dirt, 0, 2);
            world.setBlock(chunkX + 16, j + 1, chunkZ + 5, Blocks.dirt, 0, 2);
            world.setBlock(chunkX + 17, j + 1, chunkZ + 5, Blocks.dirt, 0, 2);
            world.setBlock(chunkX + 18, j + 1, chunkZ + 5, Blocks.dirt, 0, 2);
            world.setBlock(chunkX + 19, j + 1, chunkZ + 5, Blocks.dirt, 0, 2);
            world.setBlock(chunkX + 20, j + 1, chunkZ + 5, Blocks.dirt, 0, 2);
            world.setBlock(chunkX + 3, j + 1, chunkZ + 6, Blocks.dirt, 0, 2);
            world.setBlock(chunkX + 4, j + 1, chunkZ + 6, Blocks.dirt, 0, 2);
            world.setBlock(chunkX + 5, j + 1, chunkZ + 6, Blocks.dirt, 0, 2);
            world.setBlock(chunkX + 6, j + 1, chunkZ + 6, Blocks.dirt, 0, 2);
            world.setBlock(chunkX + 7, j + 1, chunkZ + 6, Blocks.dirt, 0, 2);
            world.setBlock(chunkX + 8, j + 1, chunkZ + 6, Blocks.dirt, 0, 2);
            world.setBlock(chunkX + 9, j + 1, chunkZ + 6, Blocks.dirt, 0, 2);
            world.setBlock(chunkX + 10, j + 1, chunkZ + 6, Blocks.dirt, 0, 2);
            world.setBlock(chunkX + 11, j + 1, chunkZ + 6, Blocks.dirt, 0, 2);
            world.setBlock(chunkX + 12, j + 1, chunkZ + 6, Blocks.dirt, 0, 2);
            world.setBlock(chunkX + 13, j + 1, chunkZ + 6, Blocks.dirt, 0, 2);
            world.setBlock(chunkX + 14, j + 1, chunkZ + 6, Blocks.dirt, 0, 2);
            world.setBlock(chunkX + 15, j + 1, chunkZ + 6, Blocks.dirt, 0, 2);
            world.setBlock(chunkX + 16, j + 1, chunkZ + 6, Blocks.dirt, 0, 2);
            world.setBlock(chunkX + 17, j + 1, chunkZ + 6, Blocks.dirt, 0, 2);
            world.setBlock(chunkX + 18, j + 1, chunkZ + 6, Blocks.dirt, 0, 2);
            world.setBlock(chunkX + 19, j + 1, chunkZ + 6, Blocks.dirt, 0, 2);
            world.setBlock(chunkX + 20, j + 1, chunkZ + 6, Blocks.dirt, 0, 2);
            world.setBlock(chunkX + 2, j + 1, chunkZ + 7, Blocks.dirt, 0, 2);
            world.setBlock(chunkX + 3, j + 1, chunkZ + 7, Blocks.dirt, 0, 2);
            world.setBlock(chunkX + 4, j + 1, chunkZ + 7, Blocks.dirt, 0, 2);
            world.setBlock(chunkX + 5, j + 1, chunkZ + 7, Blocks.dirt, 0, 2);
            world.setBlock(chunkX + 6, j + 1, chunkZ + 7, Blocks.dirt, 0, 2);
            world.setBlock(chunkX + 7, j + 1, chunkZ + 7, Blocks.dirt, 0, 2);
            world.setBlock(chunkX + 8, j + 1, chunkZ + 7, Blocks.dirt, 0, 2);
            world.setBlock(chunkX + 9, j + 1, chunkZ + 7, Blocks.dirt, 0, 2);
            world.setBlock(chunkX + 10, j + 1, chunkZ + 7, Blocks.dirt, 0, 2);
            world.setBlock(chunkX + 11, j + 1, chunkZ + 7, Blocks.dirt, 0, 2);
            world.setBlock(chunkX + 12, j + 1, chunkZ + 7, Blocks.dirt, 0, 2);
            world.setBlock(chunkX + 13, j + 1, chunkZ + 7, Blocks.dirt, 0, 2);
            world.setBlock(chunkX + 14, j + 1, chunkZ + 7, Blocks.dirt, 0, 2);
            world.setBlock(chunkX + 15, j + 1, chunkZ + 7, Blocks.dirt, 0, 2);
            world.setBlock(chunkX + 16, j + 1, chunkZ + 7, Blocks.dirt, 0, 2);
            world.setBlock(chunkX + 17, j + 1, chunkZ + 7, Blocks.dirt, 0, 2);
            world.setBlock(chunkX + 18, j + 1, chunkZ + 7, Blocks.dirt, 0, 2);
            world.setBlock(chunkX + 19, j + 1, chunkZ + 7, Blocks.dirt, 0, 2);
            world.setBlock(chunkX + 20, j + 1, chunkZ + 7, Blocks.dirt, 0, 2);
            world.setBlock(chunkX + 21, j + 1, chunkZ + 7, Blocks.dirt, 0, 2);
            world.setBlock(chunkX + 2, j + 1, chunkZ + 8, Blocks.dirt, 0, 2);
            world.setBlock(chunkX + 3, j + 1, chunkZ + 8, Blocks.dirt, 0, 2);
            world.setBlock(chunkX + 4, j + 1, chunkZ + 8, Blocks.dirt, 0, 2);
            world.setBlock(chunkX + 5, j + 1, chunkZ + 8, Blocks.dirt, 0, 2);
            world.setBlock(chunkX + 6, j + 1, chunkZ + 8, Blocks.dirt, 0, 2);
            world.setBlock(chunkX + 7, j + 1, chunkZ + 8, Blocks.dirt, 0, 2);
            world.setBlock(chunkX + 8, j + 1, chunkZ + 8, Blocks.dirt, 0, 2);
            world.setBlock(chunkX + 9, j + 1, chunkZ + 8, Blocks.dirt, 0, 2);
            world.setBlock(chunkX + 10, j + 1, chunkZ + 8, Blocks.dirt, 0, 2);
            world.setBlock(chunkX + 11, j + 1, chunkZ + 8, Blocks.dirt, 0, 2);
            world.setBlock(chunkX + 12, j + 1, chunkZ + 8, Blocks.dirt, 0, 2);
            world.setBlock(chunkX + 13, j + 1, chunkZ + 8, Blocks.dirt, 0, 2);
            world.setBlock(chunkX + 14, j + 1, chunkZ + 8, Blocks.dirt, 0, 2);
            world.setBlock(chunkX + 15, j + 1, chunkZ + 8, Blocks.dirt, 0, 2);
            world.setBlock(chunkX + 16, j + 1, chunkZ + 8, Blocks.dirt, 0, 2);
            world.setBlock(chunkX + 17, j + 1, chunkZ + 8, Blocks.dirt, 0, 2);
            world.setBlock(chunkX + 18, j + 1, chunkZ + 8, Blocks.dirt, 0, 2);
            world.setBlock(chunkX + 19, j + 1, chunkZ + 8, Blocks.dirt, 0, 2);
            world.setBlock(chunkX + 20, j + 1, chunkZ + 8, Blocks.dirt, 0, 2);
            world.setBlock(chunkX + 21, j + 1, chunkZ + 8, Blocks.dirt, 0, 2);
            world.setBlock(chunkX + 2, j + 1, chunkZ + 9, Blocks.dirt, 0, 2);
            world.setBlock(chunkX + 3, j + 1, chunkZ + 9, Blocks.dirt, 0, 2);
            world.setBlock(chunkX + 4, j + 1, chunkZ + 9, Blocks.dirt, 0, 2);
            world.setBlock(chunkX + 5, j + 1, chunkZ + 9, Blocks.dirt, 0, 2);
            world.setBlock(chunkX + 6, j + 1, chunkZ + 9, Blocks.dirt, 0, 2);
            world.setBlock(chunkX + 7, j + 1, chunkZ + 9, Blocks.stone, 0, 2);
            world.setBlock(chunkX + 8, j + 1, chunkZ + 9, Blocks.dirt, 0, 2);
            world.setBlock(chunkX + 9, j + 1, chunkZ + 9, Blocks.dirt, 0, 2);
            world.setBlock(chunkX + 10, j + 1, chunkZ + 9, Blocks.dirt, 0, 2);
            world.setBlock(chunkX + 11, j + 1, chunkZ + 9, Blocks.dirt, 0, 2);
            world.setBlock(chunkX + 12, j + 1, chunkZ + 9, Blocks.dirt, 0, 2);
            world.setBlock(chunkX + 13, j + 1, chunkZ + 9, Blocks.dirt, 0, 2);
            world.setBlock(chunkX + 14, j + 1, chunkZ + 9, Blocks.dirt, 0, 2);
            world.setBlock(chunkX + 15, j + 1, chunkZ + 9, Blocks.dirt, 0, 2);
            world.setBlock(chunkX + 16, j + 1, chunkZ + 9, Blocks.dirt, 0, 2);
            world.setBlock(chunkX + 17, j + 1, chunkZ + 9, Blocks.dirt, 0, 2);
            world.setBlock(chunkX + 18, j + 1, chunkZ + 9, Blocks.dirt, 0, 2);
            world.setBlock(chunkX + 19, j + 1, chunkZ + 9, Blocks.dirt, 0, 2);
            world.setBlock(chunkX + 20, j + 1, chunkZ + 9, Blocks.dirt, 0, 2);
            world.setBlock(chunkX + 21, j + 1, chunkZ + 9, Blocks.dirt, 0, 2);
            world.setBlock(chunkX + 2, j + 1, chunkZ + 10, Blocks.dirt, 0, 2);
            world.setBlock(chunkX + 3, j + 1, chunkZ + 10, Blocks.dirt, 0, 2);
            world.setBlock(chunkX + 4, j + 1, chunkZ + 10, Blocks.dirt, 0, 2);
            world.setBlock(chunkX + 5, j + 1, chunkZ + 10, Blocks.dirt, 0, 2);
            world.setBlock(chunkX + 6, j + 1, chunkZ + 10, Blocks.stone, 0, 2);
            world.setBlock(chunkX + 7, j + 1, chunkZ + 10, Blocks.stone, 0, 2);
            world.setBlock(chunkX + 8, j + 1, chunkZ + 10, Blocks.stone, 0, 2);
            world.setBlock(chunkX + 9, j + 1, chunkZ + 10, Blocks.dirt, 0, 2);
            world.setBlock(chunkX + 10, j + 1, chunkZ + 10, Blocks.dirt, 0, 2);
            world.setBlock(chunkX + 11, j + 1, chunkZ + 10, Blocks.dirt, 0, 2);
            world.setBlock(chunkX + 12, j + 1, chunkZ + 10, Blocks.dirt, 0, 2);
            world.setBlock(chunkX + 13, j + 1, chunkZ + 10, Blocks.dirt, 0, 2);
            world.setBlock(chunkX + 14, j + 1, chunkZ + 10, Blocks.dirt, 0, 2);
            world.setBlock(chunkX + 15, j + 1, chunkZ + 10, Blocks.dirt, 0, 2);
            world.setBlock(chunkX + 16, j + 1, chunkZ + 10, Blocks.dirt, 0, 2);
            world.setBlock(chunkX + 17, j + 1, chunkZ + 10, Blocks.dirt, 0, 2);
            world.setBlock(chunkX + 18, j + 1, chunkZ + 10, Blocks.dirt, 0, 2);
            world.setBlock(chunkX + 19, j + 1, chunkZ + 10, Blocks.dirt, 0, 2);
            world.setBlock(chunkX + 20, j + 1, chunkZ + 10, Blocks.dirt, 0, 2);
            world.setBlock(chunkX + 21, j + 1, chunkZ + 10, Blocks.dirt, 0, 2);
            world.setBlock(chunkX + 2, j + 1, chunkZ + 11, Blocks.dirt, 0, 2);
            world.setBlock(chunkX + 3, j + 1, chunkZ + 11, Blocks.dirt, 0, 2);
            world.setBlock(chunkX + 4, j + 1, chunkZ + 11, Blocks.dirt, 0, 2);
            world.setBlock(chunkX + 5, j + 1, chunkZ + 11, Blocks.dirt, 0, 2);
            world.setBlock(chunkX + 6, j + 1, chunkZ + 11, Blocks.dirt, 0, 2);
            world.setBlock(chunkX + 7, j + 1, chunkZ + 11, Blocks.stone, 0, 2);
            world.setBlock(chunkX + 8, j + 1, chunkZ + 11, Blocks.dirt, 0, 2);
            world.setBlock(chunkX + 9, j + 1, chunkZ + 11, Blocks.dirt, 0, 2);
            world.setBlock(chunkX + 10, j + 1, chunkZ + 11, Blocks.dirt, 0, 2);
            world.setBlock(chunkX + 11, j + 1, chunkZ + 11, Blocks.dirt, 0, 2);
            world.setBlock(chunkX + 12, j + 1, chunkZ + 11, Blocks.dirt, 0, 2);
            world.setBlock(chunkX + 13, j + 1, chunkZ + 11, Blocks.dirt, 0, 2);
            world.setBlock(chunkX + 14, j + 1, chunkZ + 11, Blocks.dirt, 0, 2);
            world.setBlock(chunkX + 15, j + 1, chunkZ + 11, Blocks.dirt, 0, 2);
            world.setBlock(chunkX + 16, j + 1, chunkZ + 11, Blocks.dirt, 0, 2);
            world.setBlock(chunkX + 17, j + 1, chunkZ + 11, Blocks.dirt, 0, 2);
            world.setBlock(chunkX + 18, j + 1, chunkZ + 11, Blocks.dirt, 0, 2);
            world.setBlock(chunkX + 19, j + 1, chunkZ + 11, Blocks.dirt, 0, 2);
            world.setBlock(chunkX + 20, j + 1, chunkZ + 11, Blocks.dirt, 0, 2);
            world.setBlock(chunkX + 21, j + 1, chunkZ + 11, Blocks.dirt, 0, 2);
            world.setBlock(chunkX + 2, j + 1, chunkZ + 12, Blocks.dirt, 0, 2);
            world.setBlock(chunkX + 3, j + 1, chunkZ + 12, Blocks.dirt, 0, 2);
            world.setBlock(chunkX + 4, j + 1, chunkZ + 12, Blocks.dirt, 0, 2);
            world.setBlock(chunkX + 5, j + 1, chunkZ + 12, Blocks.dirt, 0, 2);
            world.setBlock(chunkX + 6, j + 1, chunkZ + 12, Blocks.dirt, 0, 2);
            world.setBlock(chunkX + 7, j + 1, chunkZ + 12, Blocks.dirt, 0, 2);
            world.setBlock(chunkX + 8, j + 1, chunkZ + 12, Blocks.dirt, 0, 2);
            world.setBlock(chunkX + 9, j + 1, chunkZ + 12, Blocks.dirt, 0, 2);
            world.setBlock(chunkX + 10, j + 1, chunkZ + 12, Blocks.dirt, 0, 2);
            world.setBlock(chunkX + 11, j + 1, chunkZ + 12, Blocks.dirt, 0, 2);
            world.setBlock(chunkX + 12, j + 1, chunkZ + 12, Blocks.dirt, 0, 2);
            world.setBlock(chunkX + 13, j + 1, chunkZ + 12, Blocks.dirt, 0, 2);
            world.setBlock(chunkX + 14, j + 1, chunkZ + 12, Blocks.dirt, 0, 2);
            world.setBlock(chunkX + 15, j + 1, chunkZ + 12, Blocks.dirt, 0, 2);
            world.setBlock(chunkX + 16, j + 1, chunkZ + 12, Blocks.dirt, 0, 2);
            world.setBlock(chunkX + 17, j + 1, chunkZ + 12, Blocks.dirt, 0, 2);
            world.setBlock(chunkX + 18, j + 1, chunkZ + 12, Blocks.dirt, 0, 2);
            world.setBlock(chunkX + 19, j + 1, chunkZ + 12, Blocks.dirt, 0, 2);
            world.setBlock(chunkX + 20, j + 1, chunkZ + 12, Blocks.dirt, 0, 2);
            world.setBlock(chunkX + 21, j + 1, chunkZ + 12, Blocks.dirt, 0, 2);
            world.setBlock(chunkX + 3, j + 1, chunkZ + 13, Blocks.dirt, 0, 2);
            world.setBlock(chunkX + 4, j + 1, chunkZ + 13, Blocks.dirt, 0, 2);
            world.setBlock(chunkX + 5, j + 1, chunkZ + 13, Blocks.dirt, 0, 2);
            world.setBlock(chunkX + 6, j + 1, chunkZ + 13, Blocks.dirt, 0, 2);
            world.setBlock(chunkX + 7, j + 1, chunkZ + 13, Blocks.dirt, 0, 2);
            world.setBlock(chunkX + 8, j + 1, chunkZ + 13, Blocks.dirt, 0, 2);
            world.setBlock(chunkX + 9, j + 1, chunkZ + 13, Blocks.dirt, 0, 2);
            world.setBlock(chunkX + 10, j + 1, chunkZ + 13, Blocks.dirt, 0, 2);
            world.setBlock(chunkX + 11, j + 1, chunkZ + 13, Blocks.dirt, 0, 2);
            world.setBlock(chunkX + 12, j + 1, chunkZ + 13, Blocks.dirt, 0, 2);
            world.setBlock(chunkX + 13, j + 1, chunkZ + 13, Blocks.dirt, 0, 2);
            world.setBlock(chunkX + 14, j + 1, chunkZ + 13, Blocks.dirt, 0, 2);
            world.setBlock(chunkX + 15, j + 1, chunkZ + 13, Blocks.dirt, 0, 2);
            world.setBlock(chunkX + 16, j + 1, chunkZ + 13, Blocks.dirt, 0, 2);
            world.setBlock(chunkX + 17, j + 1, chunkZ + 13, Blocks.dirt, 0, 2);
            world.setBlock(chunkX + 18, j + 1, chunkZ + 13, Blocks.dirt, 0, 2);
            world.setBlock(chunkX + 19, j + 1, chunkZ + 13, Blocks.dirt, 0, 2);
            world.setBlock(chunkX + 20, j + 1, chunkZ + 13, Blocks.dirt, 0, 2);
            world.setBlock(chunkX + 3, j + 1, chunkZ + 14, Blocks.dirt, 0, 2);
            world.setBlock(chunkX + 4, j + 1, chunkZ + 14, Blocks.dirt, 0, 2);
            world.setBlock(chunkX + 5, j + 1, chunkZ + 14, Blocks.dirt, 0, 2);
            world.setBlock(chunkX + 6, j + 1, chunkZ + 14, Blocks.dirt, 0, 2);
            world.setBlock(chunkX + 7, j + 1, chunkZ + 14, Blocks.dirt, 0, 2);
            world.setBlock(chunkX + 8, j + 1, chunkZ + 14, Blocks.dirt, 0, 2);
            world.setBlock(chunkX + 9, j + 1, chunkZ + 14, Blocks.dirt, 0, 2);
            world.setBlock(chunkX + 10, j + 1, chunkZ + 14, Blocks.dirt, 0, 2);
            world.setBlock(chunkX + 11, j + 1, chunkZ + 14, Blocks.dirt, 0, 2);
            world.setBlock(chunkX + 12, j + 1, chunkZ + 14, Blocks.dirt, 0, 2);
            world.setBlock(chunkX + 13, j + 1, chunkZ + 14, Blocks.dirt, 0, 2);
            world.setBlock(chunkX + 14, j + 1, chunkZ + 14, Blocks.dirt, 0, 2);
            world.setBlock(chunkX + 15, j + 1, chunkZ + 14, Blocks.dirt, 0, 2);
            world.setBlock(chunkX + 16, j + 1, chunkZ + 14, Blocks.dirt, 0, 2);
            world.setBlock(chunkX + 17, j + 1, chunkZ + 14, Blocks.dirt, 0, 2);
            world.setBlock(chunkX + 18, j + 1, chunkZ + 14, Blocks.dirt, 0, 2);
            world.setBlock(chunkX + 19, j + 1, chunkZ + 14, Blocks.dirt, 0, 2);
            world.setBlock(chunkX + 20, j + 1, chunkZ + 14, Blocks.dirt, 0, 2);
            world.setBlock(chunkX + 4, j + 1, chunkZ + 15, Blocks.dirt, 0, 2);
            world.setBlock(chunkX + 5, j + 1, chunkZ + 15, Blocks.dirt, 0, 2);
            world.setBlock(chunkX + 6, j + 1, chunkZ + 15, Blocks.dirt, 0, 2);
            world.setBlock(chunkX + 7, j + 1, chunkZ + 15, Blocks.dirt, 0, 2);
            world.setBlock(chunkX + 8, j + 1, chunkZ + 15, Blocks.dirt, 0, 2);
            world.setBlock(chunkX + 9, j + 1, chunkZ + 15, Blocks.dirt, 0, 2);
            world.setBlock(chunkX + 10, j + 1, chunkZ + 15, Blocks.dirt, 0, 2);
            world.setBlock(chunkX + 11, j + 1, chunkZ + 15, Blocks.dirt, 0, 2);
            world.setBlock(chunkX + 12, j + 1, chunkZ + 15, Blocks.dirt, 0, 2);
            world.setBlock(chunkX + 13, j + 1, chunkZ + 15, Blocks.dirt, 0, 2);
            world.setBlock(chunkX + 14, j + 1, chunkZ + 15, Blocks.dirt, 0, 2);
            world.setBlock(chunkX + 15, j + 1, chunkZ + 15, Blocks.dirt, 0, 2);
            world.setBlock(chunkX + 16, j + 1, chunkZ + 15, Blocks.dirt, 0, 2);
            world.setBlock(chunkX + 17, j + 1, chunkZ + 15, Blocks.dirt, 0, 2);
            world.setBlock(chunkX + 18, j + 1, chunkZ + 15, Blocks.dirt, 0, 2);
            world.setBlock(chunkX + 19, j + 1, chunkZ + 15, Blocks.dirt, 0, 2);
            world.setBlock(chunkX + 5, j + 1, chunkZ + 16, Blocks.dirt, 0, 2);
            world.setBlock(chunkX + 6, j + 1, chunkZ + 16, Blocks.dirt, 0, 2);
            world.setBlock(chunkX + 7, j + 1, chunkZ + 16, Blocks.dirt, 0, 2);
            world.setBlock(chunkX + 8, j + 1, chunkZ + 16, Blocks.dirt, 0, 2);
            world.setBlock(chunkX + 9, j + 1, chunkZ + 16, Blocks.dirt, 0, 2);
            world.setBlock(chunkX + 10, j + 1, chunkZ + 16, Blocks.dirt, 0, 2);
            world.setBlock(chunkX + 11, j + 1, chunkZ + 16, Blocks.dirt, 0, 2);
            world.setBlock(chunkX + 12, j + 1, chunkZ + 16, Blocks.dirt, 0, 2);
            world.setBlock(chunkX + 13, j + 1, chunkZ + 16, Blocks.dirt, 0, 2);
            world.setBlock(chunkX + 14, j + 1, chunkZ + 16, Blocks.dirt, 0, 2);
            world.setBlock(chunkX + 15, j + 1, chunkZ + 16, Blocks.dirt, 0, 2);
            world.setBlock(chunkX + 16, j + 1, chunkZ + 16, Blocks.dirt, 0, 2);
            world.setBlock(chunkX + 17, j + 1, chunkZ + 16, Blocks.dirt, 0, 2);
            world.setBlock(chunkX + 18, j + 1, chunkZ + 16, Blocks.dirt, 0, 2);
            world.setBlock(chunkX + 6, j + 1, chunkZ + 17, Blocks.dirt, 0, 2);
            world.setBlock(chunkX + 7, j + 1, chunkZ + 17, Blocks.dirt, 0, 2);
            world.setBlock(chunkX + 8, j + 1, chunkZ + 17, Blocks.dirt, 0, 2);
            world.setBlock(chunkX + 9, j + 1, chunkZ + 17, Blocks.dirt, 0, 2);
            world.setBlock(chunkX + 10, j + 1, chunkZ + 17, Blocks.dirt, 0, 2);
            world.setBlock(chunkX + 11, j + 1, chunkZ + 17, Blocks.dirt, 0, 2);
            world.setBlock(chunkX + 12, j + 1, chunkZ + 17, Blocks.dirt, 0, 2);
            world.setBlock(chunkX + 13, j + 1, chunkZ + 17, Blocks.dirt, 0, 2);
            world.setBlock(chunkX + 14, j + 1, chunkZ + 17, Blocks.dirt, 0, 2);
            world.setBlock(chunkX + 15, j + 1, chunkZ + 17, Blocks.dirt, 0, 2);
            world.setBlock(chunkX + 16, j + 1, chunkZ + 17, Blocks.dirt, 0, 2);
            world.setBlock(chunkX + 17, j + 1, chunkZ + 17, Blocks.dirt, 0, 2);
            world.setBlock(chunkX + 7, j + 1, chunkZ + 18, Blocks.dirt, 0, 2);
            world.setBlock(chunkX + 8, j + 1, chunkZ + 18, Blocks.dirt, 0, 2);
            world.setBlock(chunkX + 9, j + 1, chunkZ + 18, Blocks.dirt, 0, 2);
            world.setBlock(chunkX + 10, j + 1, chunkZ + 18, Blocks.dirt, 0, 2);
            world.setBlock(chunkX + 11, j + 1, chunkZ + 18, Blocks.dirt, 0, 2);
            world.setBlock(chunkX + 12, j + 1, chunkZ + 18, Blocks.dirt, 0, 2);
            world.setBlock(chunkX + 13, j + 1, chunkZ + 18, Blocks.dirt, 0, 2);
            world.setBlock(chunkX + 14, j + 1, chunkZ + 18, Blocks.dirt, 0, 2);
            world.setBlock(chunkX + 15, j + 1, chunkZ + 18, Blocks.dirt, 0, 2);
            world.setBlock(chunkX + 16, j + 1, chunkZ + 18, Blocks.dirt, 0, 2);
            world.setBlock(chunkX + 9, j + 1, chunkZ + 19, Blocks.dirt, 0, 2);
            world.setBlock(chunkX + 10, j + 1, chunkZ + 19, Blocks.dirt, 0, 2);
            world.setBlock(chunkX + 11, j + 1, chunkZ + 19, Blocks.dirt, 0, 2);
            world.setBlock(chunkX + 12, j + 1, chunkZ + 19, Blocks.dirt, 0, 2);
            world.setBlock(chunkX + 13, j + 1, chunkZ + 19, Blocks.dirt, 0, 2);
            world.setBlock(chunkX + 14, j + 1, chunkZ + 19, Blocks.dirt, 0, 2);
            world.setBlock(chunkX + 9, j + 2, chunkZ + 0, Blocks.dirt, 0, 2);
            world.setBlock(chunkX + 10, j + 2, chunkZ + 0, Blocks.dirt, 0, 2);
            world.setBlock(chunkX + 11, j + 2, chunkZ + 0, Blocks.dirt, 0, 2);
            world.setBlock(chunkX + 12, j + 2, chunkZ + 0, Blocks.dirt, 0, 2);
            world.setBlock(chunkX + 13, j + 2, chunkZ + 0, Blocks.dirt, 0, 2);
            world.setBlock(chunkX + 14, j + 2, chunkZ + 0, Blocks.dirt, 0, 2);
            world.setBlock(chunkX + 7, j + 2, chunkZ + 1, Blocks.dirt, 0, 2);
            world.setBlock(chunkX + 8, j + 2, chunkZ + 1, Blocks.dirt, 0, 2);
            world.setBlock(chunkX + 9, j + 2, chunkZ + 1, Blocks.dirt, 0, 2);
            world.setBlock(chunkX + 10, j + 2, chunkZ + 1, Blocks.dirt, 0, 2);
            world.setBlock(chunkX + 11, j + 2, chunkZ + 1, Blocks.dirt, 0, 2);
            world.setBlock(chunkX + 12, j + 2, chunkZ + 1, Blocks.dirt, 0, 2);
            world.setBlock(chunkX + 13, j + 2, chunkZ + 1, Blocks.dirt, 0, 2);
            world.setBlock(chunkX + 14, j + 2, chunkZ + 1, Blocks.dirt, 0, 2);
            world.setBlock(chunkX + 15, j + 2, chunkZ + 1, Blocks.dirt, 0, 2);
            world.setBlock(chunkX + 16, j + 2, chunkZ + 1, Blocks.dirt, 0, 2);
            world.setBlock(chunkX + 6, j + 2, chunkZ + 2, Blocks.dirt, 0, 2);
            world.setBlock(chunkX + 7, j + 2, chunkZ + 2, Blocks.dirt, 0, 2);
            world.setBlock(chunkX + 8, j + 2, chunkZ + 2, Blocks.dirt, 0, 2);
            world.setBlock(chunkX + 9, j + 2, chunkZ + 2, Blocks.dirt, 0, 2);
            world.setBlock(chunkX + 10, j + 2, chunkZ + 2, Blocks.dirt, 0, 2);
            world.setBlock(chunkX + 11, j + 2, chunkZ + 2, Blocks.dirt, 0, 2);
            world.setBlock(chunkX + 12, j + 2, chunkZ + 2, Blocks.dirt, 0, 2);
            world.setBlock(chunkX + 13, j + 2, chunkZ + 2, Blocks.dirt, 0, 2);
            world.setBlock(chunkX + 14, j + 2, chunkZ + 2, Blocks.dirt, 0, 2);
            world.setBlock(chunkX + 15, j + 2, chunkZ + 2, Blocks.dirt, 0, 2);
            world.setBlock(chunkX + 16, j + 2, chunkZ + 2, Blocks.dirt, 0, 2);
            world.setBlock(chunkX + 17, j + 2, chunkZ + 2, Blocks.dirt, 0, 2);
            world.setBlock(chunkX + 5, j + 2, chunkZ + 3, Blocks.dirt, 0, 2);
            world.setBlock(chunkX + 6, j + 2, chunkZ + 3, Blocks.dirt, 0, 2);
            world.setBlock(chunkX + 7, j + 2, chunkZ + 3, Blocks.dirt, 0, 2);
            world.setBlock(chunkX + 8, j + 2, chunkZ + 3, Blocks.dirt, 0, 2);
            world.setBlock(chunkX + 9, j + 2, chunkZ + 3, Blocks.dirt, 0, 2);
            world.setBlock(chunkX + 10, j + 2, chunkZ + 3, Blocks.dirt, 0, 2);
            world.setBlock(chunkX + 11, j + 2, chunkZ + 3, Blocks.dirt, 0, 2);
            world.setBlock(chunkX + 12, j + 2, chunkZ + 3, Blocks.dirt, 0, 2);
            world.setBlock(chunkX + 13, j + 2, chunkZ + 3, Blocks.dirt, 0, 2);
            world.setBlock(chunkX + 14, j + 2, chunkZ + 3, Blocks.dirt, 0, 2);
            world.setBlock(chunkX + 15, j + 2, chunkZ + 3, Blocks.dirt, 0, 2);
            world.setBlock(chunkX + 16, j + 2, chunkZ + 3, Blocks.dirt, 0, 2);
            world.setBlock(chunkX + 17, j + 2, chunkZ + 3, Blocks.dirt, 0, 2);
            world.setBlock(chunkX + 18, j + 2, chunkZ + 3, Blocks.dirt, 0, 2);
            world.setBlock(chunkX + 4, j + 2, chunkZ + 4, Blocks.dirt, 0, 2);
            world.setBlock(chunkX + 5, j + 2, chunkZ + 4, Blocks.dirt, 0, 2);
            world.setBlock(chunkX + 6, j + 2, chunkZ + 4, Blocks.dirt, 0, 2);
            world.setBlock(chunkX + 7, j + 2, chunkZ + 4, Blocks.dirt, 0, 2);
            world.setBlock(chunkX + 8, j + 2, chunkZ + 4, Blocks.dirt, 0, 2);
            world.setBlock(chunkX + 9, j + 2, chunkZ + 4, Blocks.dirt, 0, 2);
            world.setBlock(chunkX + 10, j + 2, chunkZ + 4, Blocks.dirt, 0, 2);
            world.setBlock(chunkX + 11, j + 2, chunkZ + 4, Blocks.dirt, 0, 2);
            world.setBlock(chunkX + 12, j + 2, chunkZ + 4, Blocks.dirt, 0, 2);
            world.setBlock(chunkX + 13, j + 2, chunkZ + 4, Blocks.dirt, 0, 2);
            world.setBlock(chunkX + 14, j + 2, chunkZ + 4, Blocks.dirt, 0, 2);
            world.setBlock(chunkX + 15, j + 2, chunkZ + 4, Blocks.dirt, 0, 2);
            world.setBlock(chunkX + 16, j + 2, chunkZ + 4, Blocks.dirt, 0, 2);
            world.setBlock(chunkX + 17, j + 2, chunkZ + 4, Blocks.dirt, 0, 2);
            world.setBlock(chunkX + 18, j + 2, chunkZ + 4, Blocks.dirt, 0, 2);
            world.setBlock(chunkX + 19, j + 2, chunkZ + 4, Blocks.dirt, 0, 2);
            world.setBlock(chunkX + 3, j + 2, chunkZ + 5, Blocks.dirt, 0, 2);
            world.setBlock(chunkX + 4, j + 2, chunkZ + 5, Blocks.dirt, 0, 2);
            world.setBlock(chunkX + 5, j + 2, chunkZ + 5, Blocks.dirt, 0, 2);
            world.setBlock(chunkX + 6, j + 2, chunkZ + 5, Blocks.dirt, 0, 2);
            world.setBlock(chunkX + 7, j + 2, chunkZ + 5, Blocks.dirt, 0, 2);
            world.setBlock(chunkX + 8, j + 2, chunkZ + 5, Blocks.dirt, 0, 2);
            world.setBlock(chunkX + 9, j + 2, chunkZ + 5, Blocks.dirt, 0, 2);
            world.setBlock(chunkX + 10, j + 2, chunkZ + 5, Blocks.dirt, 0, 2);
            world.setBlock(chunkX + 11, j + 2, chunkZ + 5, Blocks.dirt, 0, 2);
            world.setBlock(chunkX + 12, j + 2, chunkZ + 5, Blocks.dirt, 0, 2);
            world.setBlock(chunkX + 13, j + 2, chunkZ + 5, Blocks.dirt, 0, 2);
            world.setBlock(chunkX + 14, j + 2, chunkZ + 5, Blocks.dirt, 0, 2);
            world.setBlock(chunkX + 15, j + 2, chunkZ + 5, Blocks.dirt, 0, 2);
            world.setBlock(chunkX + 16, j + 2, chunkZ + 5, Blocks.dirt, 0, 2);
            world.setBlock(chunkX + 17, j + 2, chunkZ + 5, Blocks.dirt, 0, 2);
            world.setBlock(chunkX + 18, j + 2, chunkZ + 5, Blocks.dirt, 0, 2);
            world.setBlock(chunkX + 19, j + 2, chunkZ + 5, Blocks.dirt, 0, 2);
            world.setBlock(chunkX + 20, j + 2, chunkZ + 5, Blocks.dirt, 0, 2);
            world.setBlock(chunkX + 3, j + 2, chunkZ + 6, Blocks.dirt, 0, 2);
            world.setBlock(chunkX + 4, j + 2, chunkZ + 6, Blocks.dirt, 0, 2);
            world.setBlock(chunkX + 5, j + 2, chunkZ + 6, Blocks.dirt, 0, 2);
            world.setBlock(chunkX + 6, j + 2, chunkZ + 6, Blocks.dirt, 0, 2);
            world.setBlock(chunkX + 7, j + 2, chunkZ + 6, Blocks.dirt, 0, 2);
            world.setBlock(chunkX + 8, j + 2, chunkZ + 6, Blocks.dirt, 0, 2);
            world.setBlock(chunkX + 9, j + 2, chunkZ + 6, Blocks.dirt, 0, 2);
            world.setBlock(chunkX + 10, j + 2, chunkZ + 6, Blocks.dirt, 0, 2);
            world.setBlock(chunkX + 11, j + 2, chunkZ + 6, Blocks.dirt, 0, 2);
            world.setBlock(chunkX + 12, j + 2, chunkZ + 6, Blocks.dirt, 0, 2);
            world.setBlock(chunkX + 13, j + 2, chunkZ + 6, Blocks.dirt, 0, 2);
            world.setBlock(chunkX + 14, j + 2, chunkZ + 6, Blocks.dirt, 0, 2);
            world.setBlock(chunkX + 15, j + 2, chunkZ + 6, Blocks.dirt, 0, 2);
            world.setBlock(chunkX + 16, j + 2, chunkZ + 6, Blocks.dirt, 0, 2);
            world.setBlock(chunkX + 17, j + 2, chunkZ + 6, Blocks.dirt, 0, 2);
            world.setBlock(chunkX + 18, j + 2, chunkZ + 6, Blocks.dirt, 0, 2);
            world.setBlock(chunkX + 19, j + 2, chunkZ + 6, Blocks.dirt, 0, 2);
            world.setBlock(chunkX + 20, j + 2, chunkZ + 6, Blocks.dirt, 0, 2);
            world.setBlock(chunkX + 2, j + 2, chunkZ + 7, Blocks.dirt, 0, 2);
            world.setBlock(chunkX + 3, j + 2, chunkZ + 7, Blocks.dirt, 0, 2);
            world.setBlock(chunkX + 4, j + 2, chunkZ + 7, Blocks.dirt, 0, 2);
            world.setBlock(chunkX + 5, j + 2, chunkZ + 7, Blocks.dirt, 0, 2);
            world.setBlock(chunkX + 6, j + 2, chunkZ + 7, Blocks.dirt, 0, 2);
            world.setBlock(chunkX + 7, j + 2, chunkZ + 7, Blocks.dirt, 0, 2);
            world.setBlock(chunkX + 8, j + 2, chunkZ + 7, Blocks.dirt, 0, 2);
            world.setBlock(chunkX + 9, j + 2, chunkZ + 7, Blocks.dirt, 0, 2);
            world.setBlock(chunkX + 10, j + 2, chunkZ + 7, Blocks.dirt, 0, 2);
            world.setBlock(chunkX + 11, j + 2, chunkZ + 7, Blocks.dirt, 0, 2);
            world.setBlock(chunkX + 12, j + 2, chunkZ + 7, Blocks.dirt, 0, 2);
            world.setBlock(chunkX + 13, j + 2, chunkZ + 7, Blocks.dirt, 0, 2);
            world.setBlock(chunkX + 14, j + 2, chunkZ + 7, Blocks.dirt, 0, 2);
            world.setBlock(chunkX + 15, j + 2, chunkZ + 7, Blocks.dirt, 0, 2);
            world.setBlock(chunkX + 16, j + 2, chunkZ + 7, Blocks.dirt, 0, 2);
            world.setBlock(chunkX + 17, j + 2, chunkZ + 7, Blocks.dirt, 0, 2);
            world.setBlock(chunkX + 18, j + 2, chunkZ + 7, Blocks.dirt, 0, 2);
            world.setBlock(chunkX + 19, j + 2, chunkZ + 7, Blocks.dirt, 0, 2);
            world.setBlock(chunkX + 20, j + 2, chunkZ + 7, Blocks.dirt, 0, 2);
            world.setBlock(chunkX + 21, j + 2, chunkZ + 7, Blocks.dirt, 0, 2);
            world.setBlock(chunkX + 2, j + 2, chunkZ + 8, Blocks.dirt, 0, 2);
            world.setBlock(chunkX + 3, j + 2, chunkZ + 8, Blocks.dirt, 0, 2);
            world.setBlock(chunkX + 4, j + 2, chunkZ + 8, Blocks.dirt, 0, 2);
            world.setBlock(chunkX + 5, j + 2, chunkZ + 8, Blocks.dirt, 0, 2);
            world.setBlock(chunkX + 6, j + 2, chunkZ + 8, Blocks.dirt, 0, 2);
            world.setBlock(chunkX + 7, j + 2, chunkZ + 8, Blocks.dirt, 0, 2);
            world.setBlock(chunkX + 8, j + 2, chunkZ + 8, Blocks.dirt, 0, 2);
            world.setBlock(chunkX + 9, j + 2, chunkZ + 8, Blocks.dirt, 0, 2);
            world.setBlock(chunkX + 10, j + 2, chunkZ + 8, Blocks.dirt, 0, 2);
            world.setBlock(chunkX + 11, j + 2, chunkZ + 8, Blocks.dirt, 0, 2);
            world.setBlock(chunkX + 12, j + 2, chunkZ + 8, Blocks.dirt, 0, 2);
            world.setBlock(chunkX + 13, j + 2, chunkZ + 8, Blocks.dirt, 0, 2);
            world.setBlock(chunkX + 14, j + 2, chunkZ + 8, Blocks.dirt, 0, 2);
            world.setBlock(chunkX + 15, j + 2, chunkZ + 8, Blocks.dirt, 0, 2);
            world.setBlock(chunkX + 16, j + 2, chunkZ + 8, Blocks.dirt, 0, 2);
            world.setBlock(chunkX + 17, j + 2, chunkZ + 8, Blocks.dirt, 0, 2);
            world.setBlock(chunkX + 18, j + 2, chunkZ + 8, Blocks.dirt, 0, 2);
            world.setBlock(chunkX + 19, j + 2, chunkZ + 8, Blocks.dirt, 0, 2);
            world.setBlock(chunkX + 20, j + 2, chunkZ + 8, Blocks.dirt, 0, 2);
            world.setBlock(chunkX + 21, j + 2, chunkZ + 8, Blocks.dirt, 0, 2);
            world.setBlock(chunkX + 2, j + 2, chunkZ + 9, Blocks.dirt, 0, 2);
            world.setBlock(chunkX + 3, j + 2, chunkZ + 9, Blocks.dirt, 0, 2);
            world.setBlock(chunkX + 4, j + 2, chunkZ + 9, Blocks.dirt, 0, 2);
            world.setBlock(chunkX + 5, j + 2, chunkZ + 9, Blocks.dirt, 0, 2);
            world.setBlock(chunkX + 6, j + 2, chunkZ + 9, Blocks.stone, 0, 2);
            world.setBlock(chunkX + 7, j + 2, chunkZ + 9, Blocks.stone, 0, 2);
            world.setBlock(chunkX + 8, j + 2, chunkZ + 9, Blocks.stone, 0, 2);
            world.setBlock(chunkX + 9, j + 2, chunkZ + 9, Blocks.dirt, 0, 2);
            world.setBlock(chunkX + 10, j + 2, chunkZ + 9, Blocks.dirt, 0, 2);
            world.setBlock(chunkX + 11, j + 2, chunkZ + 9, Blocks.dirt, 0, 2);
            world.setBlock(chunkX + 12, j + 2, chunkZ + 9, Blocks.dirt, 0, 2);
            world.setBlock(chunkX + 13, j + 2, chunkZ + 9, Blocks.dirt, 0, 2);
            world.setBlock(chunkX + 14, j + 2, chunkZ + 9, Blocks.dirt, 0, 2);
            world.setBlock(chunkX + 15, j + 2, chunkZ + 9, Blocks.dirt, 0, 2);
            world.setBlock(chunkX + 16, j + 2, chunkZ + 9, Blocks.dirt, 0, 2);
            world.setBlock(chunkX + 17, j + 2, chunkZ + 9, Blocks.dirt, 0, 2);
            world.setBlock(chunkX + 18, j + 2, chunkZ + 9, Blocks.dirt, 0, 2);
            world.setBlock(chunkX + 19, j + 2, chunkZ + 9, Blocks.dirt, 0, 2);
            world.setBlock(chunkX + 20, j + 2, chunkZ + 9, Blocks.dirt, 0, 2);
            world.setBlock(chunkX + 21, j + 2, chunkZ + 9, Blocks.dirt, 0, 2);
            world.setBlock(chunkX + 2, j + 2, chunkZ + 10, Blocks.dirt, 0, 2);
            world.setBlock(chunkX + 3, j + 2, chunkZ + 10, Blocks.dirt, 0, 2);
            world.setBlock(chunkX + 4, j + 2, chunkZ + 10, Blocks.dirt, 0, 2);
            world.setBlock(chunkX + 5, j + 2, chunkZ + 10, Blocks.dirt, 0, 2);
            world.setBlock(chunkX + 6, j + 2, chunkZ + 10, Blocks.stone, 0, 2);
            world.setBlock(chunkX + 7, j + 2, chunkZ + 10, (Block)Blocks.chest, 4, 2);
            final int xg = chunkX + 7;
            final int yg = chunkY + 2;
            final int zg = chunkZ + 10;
            final TileEntityChest tileentitychest = (TileEntityChest)world.getTileEntity(xg, yg, zg);
            if (tileentitychest != null) {
                WeightedRandomChestContent.generateChestContents(random, ChestGenHooks.getItems("dungeonChest", random), (IInventory)tileentitychest, ChestGenHooks.getCount("dungeonChest", random));
            }
            world.setBlock(chunkX + 8, j + 2, chunkZ + 10, Blocks.stone, 0, 2);
            world.setBlock(chunkX + 9, j + 2, chunkZ + 10, Blocks.dirt, 0, 2);
            world.setBlock(chunkX + 10, j + 2, chunkZ + 10, Blocks.dirt, 0, 2);
            world.setBlock(chunkX + 11, j + 2, chunkZ + 10, Blocks.dirt, 0, 2);
            world.setBlock(chunkX + 12, j + 2, chunkZ + 10, Blocks.dirt, 0, 2);
            world.setBlock(chunkX + 13, j + 2, chunkZ + 10, Blocks.dirt, 0, 2);
            world.setBlock(chunkX + 14, j + 2, chunkZ + 10, Blocks.dirt, 0, 2);
            world.setBlock(chunkX + 15, j + 2, chunkZ + 10, Blocks.dirt, 0, 2);
            world.setBlock(chunkX + 16, j + 2, chunkZ + 10, Blocks.dirt, 0, 2);
            world.setBlock(chunkX + 17, j + 2, chunkZ + 10, Blocks.dirt, 0, 2);
            world.setBlock(chunkX + 18, j + 2, chunkZ + 10, Blocks.dirt, 0, 2);
            world.setBlock(chunkX + 19, j + 2, chunkZ + 10, Blocks.dirt, 0, 2);
            world.setBlock(chunkX + 20, j + 2, chunkZ + 10, Blocks.dirt, 0, 2);
            world.setBlock(chunkX + 21, j + 2, chunkZ + 10, Blocks.dirt, 0, 2);
            world.setBlock(chunkX + 2, j + 2, chunkZ + 11, Blocks.dirt, 0, 2);
            world.setBlock(chunkX + 3, j + 2, chunkZ + 11, Blocks.dirt, 0, 2);
            world.setBlock(chunkX + 4, j + 2, chunkZ + 11, Blocks.dirt, 0, 2);
            world.setBlock(chunkX + 5, j + 2, chunkZ + 11, Blocks.dirt, 0, 2);
            world.setBlock(chunkX + 6, j + 2, chunkZ + 11, Blocks.stone, 0, 2);
            world.setBlock(chunkX + 7, j + 2, chunkZ + 11, Blocks.stone, 0, 2);
            world.setBlock(chunkX + 8, j + 2, chunkZ + 11, Blocks.stone, 0, 2);
            world.setBlock(chunkX + 9, j + 2, chunkZ + 11, Blocks.dirt, 0, 2);
            world.setBlock(chunkX + 10, j + 2, chunkZ + 11, Blocks.dirt, 0, 2);
            world.setBlock(chunkX + 11, j + 2, chunkZ + 11, Blocks.dirt, 0, 2);
            world.setBlock(chunkX + 12, j + 2, chunkZ + 11, Blocks.dirt, 0, 2);
            world.setBlock(chunkX + 13, j + 2, chunkZ + 11, Blocks.dirt, 0, 2);
            world.setBlock(chunkX + 14, j + 2, chunkZ + 11, Blocks.dirt, 0, 2);
            world.setBlock(chunkX + 15, j + 2, chunkZ + 11, Blocks.dirt, 0, 2);
            world.setBlock(chunkX + 16, j + 2, chunkZ + 11, Blocks.dirt, 0, 2);
            world.setBlock(chunkX + 17, j + 2, chunkZ + 11, Blocks.dirt, 0, 2);
            world.setBlock(chunkX + 18, j + 2, chunkZ + 11, Blocks.dirt, 0, 2);
            world.setBlock(chunkX + 19, j + 2, chunkZ + 11, Blocks.dirt, 0, 2);
            world.setBlock(chunkX + 20, j + 2, chunkZ + 11, Blocks.dirt, 0, 2);
            world.setBlock(chunkX + 21, j + 2, chunkZ + 11, Blocks.dirt, 0, 2);
            world.setBlock(chunkX + 2, j + 2, chunkZ + 12, Blocks.dirt, 0, 2);
            world.setBlock(chunkX + 3, j + 2, chunkZ + 12, Blocks.dirt, 0, 2);
            world.setBlock(chunkX + 4, j + 2, chunkZ + 12, Blocks.dirt, 0, 2);
            world.setBlock(chunkX + 5, j + 2, chunkZ + 12, Blocks.dirt, 0, 2);
            world.setBlock(chunkX + 6, j + 2, chunkZ + 12, Blocks.dirt, 0, 2);
            world.setBlock(chunkX + 7, j + 2, chunkZ + 12, Blocks.dirt, 0, 2);
            world.setBlock(chunkX + 8, j + 2, chunkZ + 12, Blocks.dirt, 0, 2);
            world.setBlock(chunkX + 9, j + 2, chunkZ + 12, Blocks.dirt, 0, 2);
            world.setBlock(chunkX + 10, j + 2, chunkZ + 12, Blocks.dirt, 0, 2);
            world.setBlock(chunkX + 11, j + 2, chunkZ + 12, Blocks.dirt, 0, 2);
            world.setBlock(chunkX + 12, j + 2, chunkZ + 12, Blocks.dirt, 0, 2);
            world.setBlock(chunkX + 13, j + 2, chunkZ + 12, Blocks.dirt, 0, 2);
            world.setBlock(chunkX + 14, j + 2, chunkZ + 12, Blocks.dirt, 0, 2);
            world.setBlock(chunkX + 15, j + 2, chunkZ + 12, Blocks.dirt, 0, 2);
            world.setBlock(chunkX + 16, j + 2, chunkZ + 12, Blocks.dirt, 0, 2);
            world.setBlock(chunkX + 17, j + 2, chunkZ + 12, Blocks.dirt, 0, 2);
            world.setBlock(chunkX + 18, j + 2, chunkZ + 12, Blocks.dirt, 0, 2);
            world.setBlock(chunkX + 19, j + 2, chunkZ + 12, Blocks.dirt, 0, 2);
            world.setBlock(chunkX + 20, j + 2, chunkZ + 12, Blocks.dirt, 0, 2);
            world.setBlock(chunkX + 21, j + 2, chunkZ + 12, Blocks.dirt, 0, 2);
            world.setBlock(chunkX + 3, j + 2, chunkZ + 13, Blocks.dirt, 0, 2);
            world.setBlock(chunkX + 4, j + 2, chunkZ + 13, Blocks.dirt, 0, 2);
            world.setBlock(chunkX + 5, j + 2, chunkZ + 13, Blocks.dirt, 0, 2);
            world.setBlock(chunkX + 6, j + 2, chunkZ + 13, Blocks.dirt, 0, 2);
            world.setBlock(chunkX + 7, j + 2, chunkZ + 13, Blocks.dirt, 0, 2);
            world.setBlock(chunkX + 8, j + 2, chunkZ + 13, Blocks.dirt, 0, 2);
            world.setBlock(chunkX + 9, j + 2, chunkZ + 13, Blocks.dirt, 0, 2);
            world.setBlock(chunkX + 10, j + 2, chunkZ + 13, Blocks.dirt, 0, 2);
            world.setBlock(chunkX + 11, j + 2, chunkZ + 13, Blocks.dirt, 0, 2);
            world.setBlock(chunkX + 12, j + 2, chunkZ + 13, Blocks.dirt, 0, 2);
            world.setBlock(chunkX + 13, j + 2, chunkZ + 13, Blocks.dirt, 0, 2);
            world.setBlock(chunkX + 14, j + 2, chunkZ + 13, Blocks.dirt, 0, 2);
            world.setBlock(chunkX + 15, j + 2, chunkZ + 13, Blocks.dirt, 0, 2);
            world.setBlock(chunkX + 16, j + 2, chunkZ + 13, Blocks.dirt, 0, 2);
            world.setBlock(chunkX + 17, j + 2, chunkZ + 13, Blocks.dirt, 0, 2);
            world.setBlock(chunkX + 18, j + 2, chunkZ + 13, Blocks.dirt, 0, 2);
            world.setBlock(chunkX + 19, j + 2, chunkZ + 13, Blocks.dirt, 0, 2);
            world.setBlock(chunkX + 20, j + 2, chunkZ + 13, Blocks.dirt, 0, 2);
            world.setBlock(chunkX + 3, j + 2, chunkZ + 14, Blocks.dirt, 0, 2);
            world.setBlock(chunkX + 4, j + 2, chunkZ + 14, Blocks.dirt, 0, 2);
            world.setBlock(chunkX + 5, j + 2, chunkZ + 14, Blocks.dirt, 0, 2);
            world.setBlock(chunkX + 6, j + 2, chunkZ + 14, Blocks.dirt, 0, 2);
            world.setBlock(chunkX + 7, j + 2, chunkZ + 14, Blocks.dirt, 0, 2);
            world.setBlock(chunkX + 8, j + 2, chunkZ + 14, Blocks.dirt, 0, 2);
            world.setBlock(chunkX + 9, j + 2, chunkZ + 14, Blocks.dirt, 0, 2);
            world.setBlock(chunkX + 10, j + 2, chunkZ + 14, Blocks.dirt, 0, 2);
            world.setBlock(chunkX + 11, j + 2, chunkZ + 14, Blocks.dirt, 0, 2);
            world.setBlock(chunkX + 12, j + 2, chunkZ + 14, Blocks.dirt, 0, 2);
            world.setBlock(chunkX + 13, j + 2, chunkZ + 14, Blocks.dirt, 0, 2);
            world.setBlock(chunkX + 14, j + 2, chunkZ + 14, Blocks.dirt, 0, 2);
            world.setBlock(chunkX + 15, j + 2, chunkZ + 14, Blocks.dirt, 0, 2);
            world.setBlock(chunkX + 16, j + 2, chunkZ + 14, Blocks.dirt, 0, 2);
            world.setBlock(chunkX + 17, j + 2, chunkZ + 14, Blocks.dirt, 0, 2);
            world.setBlock(chunkX + 18, j + 2, chunkZ + 14, Blocks.dirt, 0, 2);
            world.setBlock(chunkX + 19, j + 2, chunkZ + 14, Blocks.dirt, 0, 2);
            world.setBlock(chunkX + 20, j + 2, chunkZ + 14, Blocks.dirt, 0, 2);
            world.setBlock(chunkX + 4, j + 2, chunkZ + 15, Blocks.dirt, 0, 2);
            world.setBlock(chunkX + 5, j + 2, chunkZ + 15, Blocks.dirt, 0, 2);
            world.setBlock(chunkX + 6, j + 2, chunkZ + 15, Blocks.dirt, 0, 2);
            world.setBlock(chunkX + 7, j + 2, chunkZ + 15, Blocks.dirt, 0, 2);
            world.setBlock(chunkX + 8, j + 2, chunkZ + 15, Blocks.dirt, 0, 2);
            world.setBlock(chunkX + 9, j + 2, chunkZ + 15, Blocks.dirt, 0, 2);
            world.setBlock(chunkX + 10, j + 2, chunkZ + 15, Blocks.dirt, 0, 2);
            world.setBlock(chunkX + 11, j + 2, chunkZ + 15, Blocks.dirt, 0, 2);
            world.setBlock(chunkX + 12, j + 2, chunkZ + 15, Blocks.dirt, 0, 2);
            world.setBlock(chunkX + 13, j + 2, chunkZ + 15, Blocks.dirt, 0, 2);
            world.setBlock(chunkX + 14, j + 2, chunkZ + 15, Blocks.dirt, 0, 2);
            world.setBlock(chunkX + 15, j + 2, chunkZ + 15, Blocks.dirt, 0, 2);
            world.setBlock(chunkX + 16, j + 2, chunkZ + 15, Blocks.dirt, 0, 2);
            world.setBlock(chunkX + 17, j + 2, chunkZ + 15, Blocks.dirt, 0, 2);
            world.setBlock(chunkX + 18, j + 2, chunkZ + 15, Blocks.dirt, 0, 2);
            world.setBlock(chunkX + 19, j + 2, chunkZ + 15, Blocks.dirt, 0, 2);
            world.setBlock(chunkX + 5, j + 2, chunkZ + 16, Blocks.dirt, 0, 2);
            world.setBlock(chunkX + 6, j + 2, chunkZ + 16, Blocks.dirt, 0, 2);
            world.setBlock(chunkX + 7, j + 2, chunkZ + 16, Blocks.dirt, 0, 2);
            world.setBlock(chunkX + 8, j + 2, chunkZ + 16, Blocks.dirt, 0, 2);
            world.setBlock(chunkX + 9, j + 2, chunkZ + 16, Blocks.dirt, 0, 2);
            world.setBlock(chunkX + 10, j + 2, chunkZ + 16, Blocks.dirt, 0, 2);
            world.setBlock(chunkX + 11, j + 2, chunkZ + 16, Blocks.dirt, 0, 2);
            world.setBlock(chunkX + 12, j + 2, chunkZ + 16, Blocks.dirt, 0, 2);
            world.setBlock(chunkX + 13, j + 2, chunkZ + 16, Blocks.dirt, 0, 2);
            world.setBlock(chunkX + 14, j + 2, chunkZ + 16, Blocks.dirt, 0, 2);
            world.setBlock(chunkX + 15, j + 2, chunkZ + 16, Blocks.dirt, 0, 2);
            world.setBlock(chunkX + 16, j + 2, chunkZ + 16, Blocks.dirt, 0, 2);
            world.setBlock(chunkX + 17, j + 2, chunkZ + 16, Blocks.dirt, 0, 2);
            world.setBlock(chunkX + 18, j + 2, chunkZ + 16, Blocks.dirt, 0, 2);
            world.setBlock(chunkX + 6, j + 2, chunkZ + 17, Blocks.dirt, 0, 2);
            world.setBlock(chunkX + 7, j + 2, chunkZ + 17, Blocks.dirt, 0, 2);
            world.setBlock(chunkX + 8, j + 2, chunkZ + 17, Blocks.dirt, 0, 2);
            world.setBlock(chunkX + 9, j + 2, chunkZ + 17, Blocks.dirt, 0, 2);
            world.setBlock(chunkX + 10, j + 2, chunkZ + 17, Blocks.dirt, 0, 2);
            world.setBlock(chunkX + 11, j + 2, chunkZ + 17, Blocks.dirt, 0, 2);
            world.setBlock(chunkX + 12, j + 2, chunkZ + 17, Blocks.dirt, 0, 2);
            world.setBlock(chunkX + 13, j + 2, chunkZ + 17, Blocks.dirt, 0, 2);
            world.setBlock(chunkX + 14, j + 2, chunkZ + 17, Blocks.dirt, 0, 2);
            world.setBlock(chunkX + 15, j + 2, chunkZ + 17, Blocks.dirt, 0, 2);
            world.setBlock(chunkX + 16, j + 2, chunkZ + 17, Blocks.dirt, 0, 2);
            world.setBlock(chunkX + 17, j + 2, chunkZ + 17, Blocks.dirt, 0, 2);
            world.setBlock(chunkX + 7, j + 2, chunkZ + 18, Blocks.dirt, 0, 2);
            world.setBlock(chunkX + 8, j + 2, chunkZ + 18, Blocks.dirt, 0, 2);
            world.setBlock(chunkX + 9, j + 2, chunkZ + 18, Blocks.dirt, 0, 2);
            world.setBlock(chunkX + 10, j + 2, chunkZ + 18, Blocks.dirt, 0, 2);
            world.setBlock(chunkX + 11, j + 2, chunkZ + 18, Blocks.dirt, 0, 2);
            world.setBlock(chunkX + 12, j + 2, chunkZ + 18, Blocks.dirt, 0, 2);
            world.setBlock(chunkX + 13, j + 2, chunkZ + 18, Blocks.dirt, 0, 2);
            world.setBlock(chunkX + 14, j + 2, chunkZ + 18, Blocks.dirt, 0, 2);
            world.setBlock(chunkX + 15, j + 2, chunkZ + 18, Blocks.dirt, 0, 2);
            world.setBlock(chunkX + 16, j + 2, chunkZ + 18, Blocks.dirt, 0, 2);
            world.setBlock(chunkX + 9, j + 2, chunkZ + 19, Blocks.dirt, 0, 2);
            world.setBlock(chunkX + 10, j + 2, chunkZ + 19, Blocks.dirt, 0, 2);
            world.setBlock(chunkX + 11, j + 2, chunkZ + 19, Blocks.dirt, 0, 2);
            world.setBlock(chunkX + 12, j + 2, chunkZ + 19, Blocks.dirt, 0, 2);
            world.setBlock(chunkX + 13, j + 2, chunkZ + 19, Blocks.dirt, 0, 2);
            world.setBlock(chunkX + 14, j + 2, chunkZ + 19, Blocks.dirt, 0, 2);
            world.setBlock(chunkX + 13, j + 3, chunkZ + 0, (Block)Blocks.sand, 0, 2);
            world.setBlock(chunkX + 14, j + 3, chunkZ + 0, (Block)Blocks.sand, 0, 2);
            world.setBlock(chunkX + 8, j + 3, chunkZ + 1, Blocks.dirt, 0, 2);
            world.setBlock(chunkX + 9, j + 3, chunkZ + 1, Blocks.dirt, 0, 2);
            world.setBlock(chunkX + 10, j + 3, chunkZ + 1, Blocks.dirt, 0, 2);
            world.setBlock(chunkX + 11, j + 3, chunkZ + 1, Blocks.dirt, 0, 2);
            world.setBlock(chunkX + 12, j + 3, chunkZ + 1, Blocks.dirt, 0, 2);
            world.setBlock(chunkX + 13, j + 3, chunkZ + 1, Blocks.dirt, 0, 2);
            world.setBlock(chunkX + 15, j + 3, chunkZ + 1, (Block)Blocks.sand, 0, 2);
            world.setBlock(chunkX + 16, j + 3, chunkZ + 1, (Block)Blocks.sand, 0, 2);
            world.setBlock(chunkX + 6, j + 3, chunkZ + 2, Blocks.dirt, 0, 2);
            world.setBlock(chunkX + 7, j + 3, chunkZ + 2, Blocks.dirt, 0, 2);
            world.setBlock(chunkX + 8, j + 3, chunkZ + 2, Blocks.dirt, 0, 2);
            world.setBlock(chunkX + 9, j + 3, chunkZ + 2, Blocks.dirt, 0, 2);
            world.setBlock(chunkX + 10, j + 3, chunkZ + 2, Blocks.dirt, 0, 2);
            world.setBlock(chunkX + 11, j + 3, chunkZ + 2, Blocks.dirt, 0, 2);
            world.setBlock(chunkX + 12, j + 3, chunkZ + 2, Blocks.dirt, 0, 2);
            world.setBlock(chunkX + 13, j + 3, chunkZ + 2, Blocks.dirt, 0, 2);
            world.setBlock(chunkX + 14, j + 3, chunkZ + 2, Blocks.dirt, 0, 2);
            world.setBlock(chunkX + 15, j + 3, chunkZ + 2, Blocks.dirt, 0, 2);
            world.setBlock(chunkX + 16, j + 3, chunkZ + 2, (Block)Blocks.sand, 0, 2);
            world.setBlock(chunkX + 17, j + 3, chunkZ + 2, (Block)Blocks.sand, 0, 2);
            world.setBlock(chunkX + 4, j + 3, chunkZ + 3, Blocks.dirt, 0, 2);
            world.setBlock(chunkX + 5, j + 3, chunkZ + 3, Blocks.dirt, 0, 2);
            world.setBlock(chunkX + 6, j + 3, chunkZ + 3, Blocks.dirt, 0, 2);
            world.setBlock(chunkX + 7, j + 3, chunkZ + 3, Blocks.dirt, 0, 2);
            world.setBlock(chunkX + 8, j + 3, chunkZ + 3, Blocks.dirt, 0, 2);
            world.setBlock(chunkX + 9, j + 3, chunkZ + 3, Blocks.dirt, 0, 2);
            world.setBlock(chunkX + 10, j + 3, chunkZ + 3, Blocks.dirt, 0, 2);
            world.setBlock(chunkX + 11, j + 3, chunkZ + 3, Blocks.dirt, 0, 2);
            world.setBlock(chunkX + 12, j + 3, chunkZ + 3, Blocks.dirt, 0, 2);
            world.setBlock(chunkX + 13, j + 3, chunkZ + 3, Blocks.dirt, 0, 2);
            world.setBlock(chunkX + 14, j + 3, chunkZ + 3, Blocks.dirt, 0, 2);
            world.setBlock(chunkX + 15, j + 3, chunkZ + 3, Blocks.dirt, 0, 2);
            world.setBlock(chunkX + 16, j + 3, chunkZ + 3, Blocks.dirt, 0, 2);
            world.setBlock(chunkX + 17, j + 3, chunkZ + 3, Blocks.dirt, 0, 2);
            world.setBlock(chunkX + 3, j + 3, chunkZ + 4, Blocks.dirt, 0, 2);
            world.setBlock(chunkX + 4, j + 3, chunkZ + 4, Blocks.dirt, 0, 2);
            world.setBlock(chunkX + 5, j + 3, chunkZ + 4, Blocks.dirt, 0, 2);
            world.setBlock(chunkX + 6, j + 3, chunkZ + 4, Blocks.dirt, 0, 2);
            world.setBlock(chunkX + 7, j + 3, chunkZ + 4, Blocks.dirt, 0, 2);
            world.setBlock(chunkX + 8, j + 3, chunkZ + 4, Blocks.dirt, 0, 2);
            world.setBlock(chunkX + 9, j + 3, chunkZ + 4, Blocks.dirt, 0, 2);
            world.setBlock(chunkX + 10, j + 3, chunkZ + 4, Blocks.dirt, 0, 2);
            world.setBlock(chunkX + 11, j + 3, chunkZ + 4, Blocks.dirt, 0, 2);
            world.setBlock(chunkX + 12, j + 3, chunkZ + 4, Blocks.dirt, 0, 2);
            world.setBlock(chunkX + 13, j + 3, chunkZ + 4, Blocks.dirt, 0, 2);
            world.setBlock(chunkX + 14, j + 3, chunkZ + 4, Blocks.dirt, 0, 2);
            world.setBlock(chunkX + 15, j + 3, chunkZ + 4, Blocks.dirt, 0, 2);
            world.setBlock(chunkX + 16, j + 3, chunkZ + 4, Blocks.dirt, 0, 2);
            world.setBlock(chunkX + 17, j + 3, chunkZ + 4, Blocks.dirt, 0, 2);
            world.setBlock(chunkX + 18, j + 3, chunkZ + 4, Blocks.dirt, 0, 2);
            world.setBlock(chunkX + 3, j + 3, chunkZ + 5, Blocks.dirt, 0, 2);
            world.setBlock(chunkX + 4, j + 3, chunkZ + 5, Blocks.dirt, 0, 2);
            world.setBlock(chunkX + 5, j + 3, chunkZ + 5, Blocks.dirt, 0, 2);
            world.setBlock(chunkX + 6, j + 3, chunkZ + 5, Blocks.dirt, 0, 2);
            world.setBlock(chunkX + 7, j + 3, chunkZ + 5, Blocks.dirt, 0, 2);
            world.setBlock(chunkX + 8, j + 3, chunkZ + 5, Blocks.dirt, 0, 2);
            world.setBlock(chunkX + 9, j + 3, chunkZ + 5, Blocks.dirt, 0, 2);
            world.setBlock(chunkX + 10, j + 3, chunkZ + 5, Blocks.dirt, 0, 2);
            world.setBlock(chunkX + 11, j + 3, chunkZ + 5, Blocks.dirt, 0, 2);
            world.setBlock(chunkX + 12, j + 3, chunkZ + 5, Blocks.dirt, 0, 2);
            world.setBlock(chunkX + 13, j + 3, chunkZ + 5, Blocks.dirt, 0, 2);
            world.setBlock(chunkX + 14, j + 3, chunkZ + 5, Blocks.dirt, 0, 2);
            world.setBlock(chunkX + 15, j + 3, chunkZ + 5, Blocks.dirt, 0, 2);
            world.setBlock(chunkX + 16, j + 3, chunkZ + 5, Blocks.dirt, 0, 2);
            world.setBlock(chunkX + 17, j + 3, chunkZ + 5, Blocks.dirt, 0, 2);
            world.setBlock(chunkX + 18, j + 3, chunkZ + 5, Blocks.dirt, 0, 2);
            world.setBlock(chunkX + 2, j + 3, chunkZ + 6, Blocks.dirt, 0, 2);
            world.setBlock(chunkX + 3, j + 3, chunkZ + 6, Blocks.dirt, 0, 2);
            world.setBlock(chunkX + 4, j + 3, chunkZ + 6, Blocks.dirt, 0, 2);
            world.setBlock(chunkX + 5, j + 3, chunkZ + 6, Blocks.dirt, 0, 2);
            world.setBlock(chunkX + 6, j + 3, chunkZ + 6, Blocks.dirt, 0, 2);
            world.setBlock(chunkX + 7, j + 3, chunkZ + 6, Blocks.dirt, 0, 2);
            world.setBlock(chunkX + 8, j + 3, chunkZ + 6, Blocks.dirt, 0, 2);
            world.setBlock(chunkX + 9, j + 3, chunkZ + 6, Blocks.dirt, 0, 2);
            world.setBlock(chunkX + 10, j + 3, chunkZ + 6, Blocks.dirt, 0, 2);
            world.setBlock(chunkX + 11, j + 3, chunkZ + 6, Blocks.dirt, 0, 2);
            world.setBlock(chunkX + 12, j + 3, chunkZ + 6, Blocks.dirt, 0, 2);
            world.setBlock(chunkX + 13, j + 3, chunkZ + 6, Blocks.dirt, 0, 2);
            world.setBlock(chunkX + 14, j + 3, chunkZ + 6, Blocks.dirt, 0, 2);
            world.setBlock(chunkX + 15, j + 3, chunkZ + 6, Blocks.dirt, 0, 2);
            world.setBlock(chunkX + 16, j + 3, chunkZ + 6, Blocks.dirt, 0, 2);
            world.setBlock(chunkX + 17, j + 3, chunkZ + 6, Blocks.dirt, 0, 2);
            world.setBlock(chunkX + 18, j + 3, chunkZ + 6, Blocks.dirt, 0, 2);
            world.setBlock(chunkX + 19, j + 3, chunkZ + 6, Blocks.dirt, 0, 2);
            world.setBlock(chunkX + 2, j + 3, chunkZ + 7, Blocks.dirt, 0, 2);
            world.setBlock(chunkX + 3, j + 3, chunkZ + 7, Blocks.dirt, 0, 2);
            world.setBlock(chunkX + 4, j + 3, chunkZ + 7, Blocks.dirt, 0, 2);
            world.setBlock(chunkX + 5, j + 3, chunkZ + 7, Blocks.dirt, 0, 2);
            world.setBlock(chunkX + 6, j + 3, chunkZ + 7, Blocks.dirt, 0, 2);
            world.setBlock(chunkX + 7, j + 3, chunkZ + 7, Blocks.dirt, 0, 2);
            world.setBlock(chunkX + 8, j + 3, chunkZ + 7, Blocks.dirt, 0, 2);
            world.setBlock(chunkX + 9, j + 3, chunkZ + 7, Blocks.dirt, 0, 2);
            world.setBlock(chunkX + 10, j + 3, chunkZ + 7, Blocks.dirt, 0, 2);
            world.setBlock(chunkX + 11, j + 3, chunkZ + 7, Blocks.dirt, 0, 2);
            world.setBlock(chunkX + 12, j + 3, chunkZ + 7, Blocks.dirt, 0, 2);
            world.setBlock(chunkX + 13, j + 3, chunkZ + 7, Blocks.dirt, 0, 2);
            world.setBlock(chunkX + 14, j + 3, chunkZ + 7, Blocks.dirt, 0, 2);
            world.setBlock(chunkX + 15, j + 3, chunkZ + 7, Blocks.dirt, 0, 2);
            world.setBlock(chunkX + 16, j + 3, chunkZ + 7, Blocks.dirt, 0, 2);
            world.setBlock(chunkX + 17, j + 3, chunkZ + 7, Blocks.dirt, 0, 2);
            world.setBlock(chunkX + 18, j + 3, chunkZ + 7, Blocks.dirt, 0, 2);
            world.setBlock(chunkX + 19, j + 3, chunkZ + 7, Blocks.dirt, 0, 2);
            world.setBlock(chunkX + 20, j + 3, chunkZ + 7, (Block)Blocks.sand, 0, 2);
            world.setBlock(chunkX + 1, j + 3, chunkZ + 8, Blocks.dirt, 0, 2);
            world.setBlock(chunkX + 2, j + 3, chunkZ + 8, Blocks.dirt, 0, 2);
            world.setBlock(chunkX + 3, j + 3, chunkZ + 8, Blocks.dirt, 0, 2);
            world.setBlock(chunkX + 4, j + 3, chunkZ + 8, Blocks.dirt, 0, 2);
            world.setBlock(chunkX + 5, j + 3, chunkZ + 8, Blocks.dirt, 0, 2);
            world.setBlock(chunkX + 6, j + 3, chunkZ + 8, Blocks.stone, 0, 2);
            world.setBlock(chunkX + 7, j + 3, chunkZ + 8, Blocks.stone, 0, 2);
            world.setBlock(chunkX + 8, j + 3, chunkZ + 8, Blocks.stone, 0, 2);
            world.setBlock(chunkX + 9, j + 3, chunkZ + 8, Blocks.dirt, 0, 2);
            world.setBlock(chunkX + 10, j + 3, chunkZ + 8, Blocks.dirt, 0, 2);
            world.setBlock(chunkX + 11, j + 3, chunkZ + 8, Blocks.dirt, 0, 2);
            world.setBlock(chunkX + 12, j + 3, chunkZ + 8, Blocks.dirt, 0, 2);
            world.setBlock(chunkX + 13, j + 3, chunkZ + 8, Blocks.dirt, 0, 2);
            world.setBlock(chunkX + 14, j + 3, chunkZ + 8, Blocks.dirt, 0, 2);
            world.setBlock(chunkX + 15, j + 3, chunkZ + 8, Blocks.dirt, 0, 2);
            world.setBlock(chunkX + 16, j + 3, chunkZ + 8, Blocks.dirt, 0, 2);
            world.setBlock(chunkX + 17, j + 3, chunkZ + 8, Blocks.dirt, 0, 2);
            world.setBlock(chunkX + 18, j + 3, chunkZ + 8, Blocks.dirt, 0, 2);
            world.setBlock(chunkX + 19, j + 3, chunkZ + 8, Blocks.dirt, 0, 2);
            world.setBlock(chunkX + 20, j + 3, chunkZ + 8, Blocks.dirt, 0, 2);
            world.setBlock(chunkX + 21, j + 3, chunkZ + 8, (Block)Blocks.sand, 0, 2);
            world.setBlock(chunkX + 1, j + 3, chunkZ + 9, Blocks.dirt, 0, 2);
            world.setBlock(chunkX + 2, j + 3, chunkZ + 9, Blocks.dirt, 0, 2);
            world.setBlock(chunkX + 3, j + 3, chunkZ + 9, Blocks.dirt, 0, 2);
            world.setBlock(chunkX + 4, j + 3, chunkZ + 9, Blocks.dirt, 0, 2);
            world.setBlock(chunkX + 5, j + 3, chunkZ + 9, Blocks.stone, 0, 2);
            world.setBlock(chunkX + 9, j + 3, chunkZ + 9, Blocks.stone, 0, 2);
            world.setBlock(chunkX + 10, j + 3, chunkZ + 9, Blocks.dirt, 0, 2);
            world.setBlock(chunkX + 11, j + 3, chunkZ + 9, Blocks.dirt, 0, 2);
            world.setBlock(chunkX + 12, j + 3, chunkZ + 9, Blocks.dirt, 0, 2);
            world.setBlock(chunkX + 13, j + 3, chunkZ + 9, Blocks.dirt, 0, 2);
            world.setBlock(chunkX + 14, j + 3, chunkZ + 9, Blocks.dirt, 0, 2);
            world.setBlock(chunkX + 15, j + 3, chunkZ + 9, Blocks.dirt, 0, 2);
            world.setBlock(chunkX + 16, j + 3, chunkZ + 9, Blocks.dirt, 0, 2);
            world.setBlock(chunkX + 17, j + 3, chunkZ + 9, Blocks.dirt, 0, 2);
            world.setBlock(chunkX + 18, j + 3, chunkZ + 9, Blocks.dirt, 0, 2);
            world.setBlock(chunkX + 19, j + 3, chunkZ + 9, Blocks.dirt, 0, 2);
            world.setBlock(chunkX + 20, j + 3, chunkZ + 9, Blocks.dirt, 0, 2);
            world.setBlock(chunkX + 21, j + 3, chunkZ + 9, (Block)Blocks.sand, 0, 2);
            world.setBlock(chunkX + 1, j + 3, chunkZ + 10, Blocks.dirt, 0, 2);
            world.setBlock(chunkX + 2, j + 3, chunkZ + 10, Blocks.dirt, 0, 2);
            world.setBlock(chunkX + 3, j + 3, chunkZ + 10, Blocks.dirt, 0, 2);
            world.setBlock(chunkX + 4, j + 3, chunkZ + 10, Blocks.dirt, 0, 2);
            world.setBlock(chunkX + 5, j + 3, chunkZ + 10, Blocks.stone, 0, 2);
            world.setBlock(chunkX + 9, j + 3, chunkZ + 10, Blocks.stone, 0, 2);
            world.setBlock(chunkX + 10, j + 3, chunkZ + 10, Blocks.dirt, 0, 2);
            world.setBlock(chunkX + 11, j + 3, chunkZ + 10, Blocks.dirt, 0, 2);
            world.setBlock(chunkX + 12, j + 3, chunkZ + 10, Blocks.dirt, 0, 2);
            world.setBlock(chunkX + 13, j + 3, chunkZ + 10, Blocks.dirt, 0, 2);
            world.setBlock(chunkX + 14, j + 3, chunkZ + 10, Blocks.dirt, 0, 2);
            world.setBlock(chunkX + 15, j + 3, chunkZ + 10, Blocks.dirt, 0, 2);
            world.setBlock(chunkX + 16, j + 3, chunkZ + 10, Blocks.dirt, 0, 2);
            world.setBlock(chunkX + 17, j + 3, chunkZ + 10, Blocks.dirt, 0, 2);
            world.setBlock(chunkX + 18, j + 3, chunkZ + 10, Blocks.dirt, 0, 2);
            world.setBlock(chunkX + 19, j + 3, chunkZ + 10, Blocks.dirt, 0, 2);
            world.setBlock(chunkX + 20, j + 3, chunkZ + 10, Blocks.dirt, 0, 2);
            world.setBlock(chunkX + 21, j + 3, chunkZ + 10, (Block)Blocks.sand, 0, 2);
            world.setBlock(chunkX + 1, j + 3, chunkZ + 11, Blocks.dirt, 0, 2);
            world.setBlock(chunkX + 2, j + 3, chunkZ + 11, Blocks.dirt, 0, 2);
            world.setBlock(chunkX + 3, j + 3, chunkZ + 11, Blocks.dirt, 0, 2);
            world.setBlock(chunkX + 4, j + 3, chunkZ + 11, Blocks.dirt, 0, 2);
            world.setBlock(chunkX + 5, j + 3, chunkZ + 11, Blocks.stone, 0, 2);
            world.setBlock(chunkX + 9, j + 3, chunkZ + 11, Blocks.stone, 0, 2);
            world.setBlock(chunkX + 10, j + 3, chunkZ + 11, Blocks.dirt, 0, 2);
            world.setBlock(chunkX + 11, j + 3, chunkZ + 11, Blocks.dirt, 0, 2);
            world.setBlock(chunkX + 12, j + 3, chunkZ + 11, Blocks.dirt, 0, 2);
            world.setBlock(chunkX + 13, j + 3, chunkZ + 11, Blocks.dirt, 0, 2);
            world.setBlock(chunkX + 14, j + 3, chunkZ + 11, Blocks.dirt, 0, 2);
            world.setBlock(chunkX + 15, j + 3, chunkZ + 11, Blocks.dirt, 0, 2);
            world.setBlock(chunkX + 16, j + 3, chunkZ + 11, Blocks.dirt, 0, 2);
            world.setBlock(chunkX + 17, j + 3, chunkZ + 11, Blocks.dirt, 0, 2);
            world.setBlock(chunkX + 18, j + 3, chunkZ + 11, Blocks.dirt, 0, 2);
            world.setBlock(chunkX + 19, j + 3, chunkZ + 11, Blocks.dirt, 0, 2);
            world.setBlock(chunkX + 20, j + 3, chunkZ + 11, Blocks.dirt, 0, 2);
            world.setBlock(chunkX + 21, j + 3, chunkZ + 11, (Block)Blocks.sand, 0, 2);
            world.setBlock(chunkX + 2, j + 3, chunkZ + 12, Blocks.dirt, 0, 2);
            world.setBlock(chunkX + 3, j + 3, chunkZ + 12, Blocks.dirt, 0, 2);
            world.setBlock(chunkX + 4, j + 3, chunkZ + 12, Blocks.dirt, 0, 2);
            world.setBlock(chunkX + 5, j + 3, chunkZ + 12, Blocks.dirt, 0, 2);
            world.setBlock(chunkX + 6, j + 3, chunkZ + 12, Blocks.stone, 0, 2);
            world.setBlock(chunkX + 7, j + 3, chunkZ + 12, Blocks.stone, 0, 2);
            world.setBlock(chunkX + 8, j + 3, chunkZ + 12, Blocks.stone, 0, 2);
            world.setBlock(chunkX + 9, j + 3, chunkZ + 12, Blocks.dirt, 0, 2);
            world.setBlock(chunkX + 10, j + 3, chunkZ + 12, Blocks.dirt, 0, 2);
            world.setBlock(chunkX + 11, j + 3, chunkZ + 12, Blocks.dirt, 0, 2);
            world.setBlock(chunkX + 12, j + 3, chunkZ + 12, Blocks.dirt, 0, 2);
            world.setBlock(chunkX + 13, j + 3, chunkZ + 12, Blocks.dirt, 0, 2);
            world.setBlock(chunkX + 14, j + 3, chunkZ + 12, Blocks.dirt, 0, 2);
            world.setBlock(chunkX + 15, j + 3, chunkZ + 12, Blocks.dirt, 0, 2);
            world.setBlock(chunkX + 16, j + 3, chunkZ + 12, Blocks.dirt, 0, 2);
            world.setBlock(chunkX + 17, j + 3, chunkZ + 12, Blocks.dirt, 0, 2);
            world.setBlock(chunkX + 18, j + 3, chunkZ + 12, Blocks.dirt, 0, 2);
            world.setBlock(chunkX + 19, j + 3, chunkZ + 12, Blocks.dirt, 0, 2);
            world.setBlock(chunkX + 20, j + 3, chunkZ + 12, (Block)Blocks.sand, 0, 2);
            world.setBlock(chunkX + 21, j + 3, chunkZ + 12, (Block)Blocks.sand, 0, 2);
            world.setBlock(chunkX + 2, j + 3, chunkZ + 13, Blocks.dirt, 0, 2);
            world.setBlock(chunkX + 3, j + 3, chunkZ + 13, Blocks.dirt, 0, 2);
            world.setBlock(chunkX + 4, j + 3, chunkZ + 13, Blocks.dirt, 0, 2);
            world.setBlock(chunkX + 5, j + 3, chunkZ + 13, Blocks.dirt, 0, 2);
            world.setBlock(chunkX + 6, j + 3, chunkZ + 13, Blocks.dirt, 0, 2);
            world.setBlock(chunkX + 7, j + 3, chunkZ + 13, Blocks.dirt, 0, 2);
            world.setBlock(chunkX + 8, j + 3, chunkZ + 13, Blocks.dirt, 0, 2);
            world.setBlock(chunkX + 9, j + 3, chunkZ + 13, Blocks.dirt, 0, 2);
            world.setBlock(chunkX + 10, j + 3, chunkZ + 13, Blocks.dirt, 0, 2);
            world.setBlock(chunkX + 11, j + 3, chunkZ + 13, Blocks.dirt, 0, 2);
            world.setBlock(chunkX + 12, j + 3, chunkZ + 13, Blocks.dirt, 0, 2);
            world.setBlock(chunkX + 13, j + 3, chunkZ + 13, Blocks.dirt, 0, 2);
            world.setBlock(chunkX + 14, j + 3, chunkZ + 13, Blocks.dirt, 0, 2);
            world.setBlock(chunkX + 15, j + 3, chunkZ + 13, Blocks.dirt, 0, 2);
            world.setBlock(chunkX + 16, j + 3, chunkZ + 13, Blocks.dirt, 0, 2);
            world.setBlock(chunkX + 17, j + 3, chunkZ + 13, Blocks.dirt, 0, 2);
            world.setBlock(chunkX + 18, j + 3, chunkZ + 13, Blocks.dirt, 0, 2);
            world.setBlock(chunkX + 19, j + 3, chunkZ + 13, Blocks.dirt, 0, 2);
            world.setBlock(chunkX + 20, j + 3, chunkZ + 13, (Block)Blocks.sand, 0, 2);
            world.setBlock(chunkX + 3, j + 3, chunkZ + 14, Blocks.dirt, 0, 2);
            world.setBlock(chunkX + 4, j + 3, chunkZ + 14, Blocks.dirt, 0, 2);
            world.setBlock(chunkX + 5, j + 3, chunkZ + 14, Blocks.dirt, 0, 2);
            world.setBlock(chunkX + 6, j + 3, chunkZ + 14, Blocks.dirt, 0, 2);
            world.setBlock(chunkX + 7, j + 3, chunkZ + 14, Blocks.dirt, 0, 2);
            world.setBlock(chunkX + 8, j + 3, chunkZ + 14, Blocks.dirt, 0, 2);
            world.setBlock(chunkX + 9, j + 3, chunkZ + 14, Blocks.dirt, 0, 2);
            world.setBlock(chunkX + 10, j + 3, chunkZ + 14, Blocks.dirt, 0, 2);
            world.setBlock(chunkX + 11, j + 3, chunkZ + 14, Blocks.dirt, 0, 2);
            world.setBlock(chunkX + 12, j + 3, chunkZ + 14, Blocks.dirt, 0, 2);
            world.setBlock(chunkX + 13, j + 3, chunkZ + 14, Blocks.dirt, 0, 2);
            world.setBlock(chunkX + 14, j + 3, chunkZ + 14, Blocks.dirt, 0, 2);
            world.setBlock(chunkX + 15, j + 3, chunkZ + 14, Blocks.dirt, 0, 2);
            world.setBlock(chunkX + 16, j + 3, chunkZ + 14, Blocks.dirt, 0, 2);
            world.setBlock(chunkX + 17, j + 3, chunkZ + 14, Blocks.dirt, 0, 2);
            world.setBlock(chunkX + 18, j + 3, chunkZ + 14, Blocks.dirt, 0, 2);
            world.setBlock(chunkX + 19, j + 3, chunkZ + 14, (Block)Blocks.sand, 0, 2);
            world.setBlock(chunkX + 20, j + 3, chunkZ + 14, (Block)Blocks.sand, 0, 2);
            world.setBlock(chunkX + 3, j + 3, chunkZ + 15, Blocks.dirt, 0, 2);
            world.setBlock(chunkX + 4, j + 3, chunkZ + 15, Blocks.dirt, 0, 2);
            world.setBlock(chunkX + 5, j + 3, chunkZ + 15, Blocks.dirt, 0, 2);
            world.setBlock(chunkX + 6, j + 3, chunkZ + 15, Blocks.dirt, 0, 2);
            world.setBlock(chunkX + 7, j + 3, chunkZ + 15, Blocks.dirt, 0, 2);
            world.setBlock(chunkX + 8, j + 3, chunkZ + 15, Blocks.dirt, 0, 2);
            world.setBlock(chunkX + 9, j + 3, chunkZ + 15, Blocks.dirt, 0, 2);
            world.setBlock(chunkX + 10, j + 3, chunkZ + 15, Blocks.dirt, 0, 2);
            world.setBlock(chunkX + 11, j + 3, chunkZ + 15, Blocks.dirt, 0, 2);
            world.setBlock(chunkX + 12, j + 3, chunkZ + 15, Blocks.dirt, 0, 2);
            world.setBlock(chunkX + 13, j + 3, chunkZ + 15, Blocks.dirt, 0, 2);
            world.setBlock(chunkX + 14, j + 3, chunkZ + 15, Blocks.dirt, 0, 2);
            world.setBlock(chunkX + 15, j + 3, chunkZ + 15, Blocks.dirt, 0, 2);
            world.setBlock(chunkX + 16, j + 3, chunkZ + 15, Blocks.dirt, 0, 2);
            world.setBlock(chunkX + 17, j + 3, chunkZ + 15, Blocks.dirt, 0, 2);
            world.setBlock(chunkX + 18, j + 3, chunkZ + 15, Blocks.dirt, 0, 2);
            world.setBlock(chunkX + 19, j + 3, chunkZ + 15, (Block)Blocks.sand, 0, 2);
            world.setBlock(chunkX + 4, j + 3, chunkZ + 16, Blocks.dirt, 0, 2);
            world.setBlock(chunkX + 5, j + 3, chunkZ + 16, Blocks.dirt, 0, 2);
            world.setBlock(chunkX + 6, j + 3, chunkZ + 16, Blocks.dirt, 0, 2);
            world.setBlock(chunkX + 7, j + 3, chunkZ + 16, Blocks.dirt, 0, 2);
            world.setBlock(chunkX + 8, j + 3, chunkZ + 16, Blocks.dirt, 0, 2);
            world.setBlock(chunkX + 9, j + 3, chunkZ + 16, Blocks.dirt, 0, 2);
            world.setBlock(chunkX + 10, j + 3, chunkZ + 16, Blocks.dirt, 0, 2);
            world.setBlock(chunkX + 11, j + 3, chunkZ + 16, Blocks.dirt, 0, 2);
            world.setBlock(chunkX + 12, j + 3, chunkZ + 16, Blocks.dirt, 0, 2);
            world.setBlock(chunkX + 13, j + 3, chunkZ + 16, Blocks.dirt, 0, 2);
            world.setBlock(chunkX + 14, j + 3, chunkZ + 16, Blocks.dirt, 0, 2);
            world.setBlock(chunkX + 15, j + 3, chunkZ + 16, Blocks.dirt, 0, 2);
            world.setBlock(chunkX + 16, j + 3, chunkZ + 16, Blocks.dirt, 0, 2);
            world.setBlock(chunkX + 17, j + 3, chunkZ + 16, Blocks.dirt, 0, 2);
            world.setBlock(chunkX + 18, j + 3, chunkZ + 16, (Block)Blocks.sand, 0, 2);
            world.setBlock(chunkX + 6, j + 3, chunkZ + 17, Blocks.dirt, 0, 2);
            world.setBlock(chunkX + 7, j + 3, chunkZ + 17, Blocks.dirt, 0, 2);
            world.setBlock(chunkX + 8, j + 3, chunkZ + 17, Blocks.dirt, 0, 2);
            world.setBlock(chunkX + 9, j + 3, chunkZ + 17, Blocks.dirt, 0, 2);
            world.setBlock(chunkX + 10, j + 3, chunkZ + 17, Blocks.dirt, 0, 2);
            world.setBlock(chunkX + 11, j + 3, chunkZ + 17, Blocks.dirt, 0, 2);
            world.setBlock(chunkX + 12, j + 3, chunkZ + 17, Blocks.dirt, 0, 2);
            world.setBlock(chunkX + 13, j + 3, chunkZ + 17, Blocks.dirt, 0, 2);
            world.setBlock(chunkX + 14, j + 3, chunkZ + 17, Blocks.dirt, 0, 2);
            world.setBlock(chunkX + 15, j + 3, chunkZ + 17, Blocks.dirt, 0, 2);
            world.setBlock(chunkX + 16, j + 3, chunkZ + 17, (Block)Blocks.sand, 0, 2);
            world.setBlock(chunkX + 17, j + 3, chunkZ + 17, (Block)Blocks.sand, 0, 2);
            world.setBlock(chunkX + 8, j + 3, chunkZ + 18, Blocks.dirt, 0, 2);
            world.setBlock(chunkX + 9, j + 3, chunkZ + 18, Blocks.dirt, 0, 2);
            world.setBlock(chunkX + 10, j + 3, chunkZ + 18, Blocks.dirt, 0, 2);
            world.setBlock(chunkX + 11, j + 3, chunkZ + 18, Blocks.dirt, 0, 2);
            world.setBlock(chunkX + 12, j + 3, chunkZ + 18, Blocks.dirt, 0, 2);
            world.setBlock(chunkX + 13, j + 3, chunkZ + 18, Blocks.dirt, 0, 2);
            world.setBlock(chunkX + 15, j + 3, chunkZ + 18, (Block)Blocks.sand, 0, 2);
            world.setBlock(chunkX + 16, j + 3, chunkZ + 18, (Block)Blocks.sand, 0, 2);
            world.setBlock(chunkX + 13, j + 3, chunkZ + 19, (Block)Blocks.sand, 0, 2);
            world.setBlock(chunkX + 14, j + 3, chunkZ + 19, (Block)Blocks.sand, 0, 2);
            world.setBlock(chunkX + 7, j + 4, chunkZ + 0, Blocks.dirt, 0, 2);
            world.setBlock(chunkX + 8, j + 4, chunkZ + 0, Blocks.dirt, 0, 2);
            world.setBlock(chunkX + 9, j + 4, chunkZ + 0, Blocks.dirt, 0, 2);
            world.setBlock(chunkX + 10, j + 4, chunkZ + 0, Blocks.dirt, 0, 2);
            world.setBlock(chunkX + 11, j + 4, chunkZ + 0, Blocks.dirt, 0, 2);
            world.setBlock(chunkX + 12, j + 4, chunkZ + 0, Blocks.dirt, 0, 2);
            world.setBlock(chunkX + 13, j + 4, chunkZ + 0, (Block)Blocks.sand, 0, 2);
            world.setBlock(chunkX + 14, j + 4, chunkZ + 0, (Block)Blocks.sand, 0, 2);
            world.setBlock(chunkX + 5, j + 4, chunkZ + 1, Blocks.dirt, 0, 2);
            world.setBlock(chunkX + 6, j + 4, chunkZ + 1, Blocks.dirt, 0, 2);
            world.setBlock(chunkX + 7, j + 4, chunkZ + 1, Blocks.dirt, 0, 2);
            world.setBlock(chunkX + 8, j + 4, chunkZ + 1, Blocks.dirt, 0, 2);
            world.setBlock(chunkX + 9, j + 4, chunkZ + 1, Blocks.dirt, 0, 2);
            world.setBlock(chunkX + 10, j + 4, chunkZ + 1, Blocks.dirt, 0, 2);
            world.setBlock(chunkX + 11, j + 4, chunkZ + 1, Blocks.dirt, 0, 2);
            world.setBlock(chunkX + 12, j + 4, chunkZ + 1, Blocks.dirt, 0, 2);
            world.setBlock(chunkX + 13, j + 4, chunkZ + 1, Blocks.dirt, 0, 2);
            world.setBlock(chunkX + 14, j + 4, chunkZ + 1, Blocks.dirt, 0, 2);
            world.setBlock(chunkX + 15, j + 4, chunkZ + 1, (Block)Blocks.sand, 0, 2);
            world.setBlock(chunkX + 16, j + 4, chunkZ + 1, (Block)Blocks.sand, 0, 2);
            world.setBlock(chunkX + 4, j + 4, chunkZ + 2, Blocks.dirt, 0, 2);
            world.setBlock(chunkX + 5, j + 4, chunkZ + 2, Blocks.dirt, 0, 2);
            world.setBlock(chunkX + 6, j + 4, chunkZ + 2, Blocks.dirt, 0, 2);
            world.setBlock(chunkX + 7, j + 4, chunkZ + 2, Blocks.dirt, 0, 2);
            world.setBlock(chunkX + 8, j + 4, chunkZ + 2, Blocks.dirt, 0, 2);
            world.setBlock(chunkX + 9, j + 4, chunkZ + 2, Blocks.dirt, 0, 2);
            world.setBlock(chunkX + 10, j + 4, chunkZ + 2, Blocks.dirt, 0, 2);
            world.setBlock(chunkX + 11, j + 4, chunkZ + 2, Blocks.dirt, 0, 2);
            world.setBlock(chunkX + 12, j + 4, chunkZ + 2, Blocks.dirt, 0, 2);
            world.setBlock(chunkX + 13, j + 4, chunkZ + 2, Blocks.dirt, 0, 2);
            world.setBlock(chunkX + 14, j + 4, chunkZ + 2, Blocks.dirt, 0, 2);
            world.setBlock(chunkX + 15, j + 4, chunkZ + 2, Blocks.dirt, 0, 2);
            world.setBlock(chunkX + 16, j + 4, chunkZ + 2, (Block)Blocks.sand, 0, 2);
            world.setBlock(chunkX + 17, j + 4, chunkZ + 2, (Block)Blocks.sand, 0, 2);
            world.setBlock(chunkX + 3, j + 4, chunkZ + 3, Blocks.dirt, 0, 2);
            world.setBlock(chunkX + 4, j + 4, chunkZ + 3, Blocks.dirt, 0, 2);
            world.setBlock(chunkX + 5, j + 4, chunkZ + 3, Blocks.dirt, 0, 2);
            world.setBlock(chunkX + 6, j + 4, chunkZ + 3, Blocks.dirt, 0, 2);
            world.setBlock(chunkX + 7, j + 4, chunkZ + 3, Blocks.dirt, 0, 2);
            world.setBlock(chunkX + 8, j + 4, chunkZ + 3, Blocks.dirt, 0, 2);
            world.setBlock(chunkX + 9, j + 4, chunkZ + 3, Blocks.dirt, 0, 2);
            world.setBlock(chunkX + 10, j + 4, chunkZ + 3, Blocks.dirt, 0, 2);
            world.setBlock(chunkX + 11, j + 4, chunkZ + 3, Blocks.dirt, 0, 2);
            world.setBlock(chunkX + 12, j + 4, chunkZ + 3, Blocks.dirt, 0, 2);
            world.setBlock(chunkX + 13, j + 4, chunkZ + 3, Blocks.dirt, 0, 2);
            world.setBlock(chunkX + 14, j + 4, chunkZ + 3, Blocks.dirt, 0, 2);
            world.setBlock(chunkX + 15, j + 4, chunkZ + 3, Blocks.dirt, 0, 2);
            world.setBlock(chunkX + 16, j + 4, chunkZ + 3, Blocks.dirt, 0, 2);
            world.setBlock(chunkX + 17, j + 4, chunkZ + 3, (Block)Blocks.sand, 0, 2);
            world.setBlock(chunkX + 2, j + 4, chunkZ + 4, Blocks.dirt, 0, 2);
            world.setBlock(chunkX + 3, j + 4, chunkZ + 4, Blocks.dirt, 0, 2);
            world.setBlock(chunkX + 4, j + 4, chunkZ + 4, Blocks.dirt, 0, 2);
            world.setBlock(chunkX + 5, j + 4, chunkZ + 4, Blocks.dirt, 0, 2);
            world.setBlock(chunkX + 6, j + 4, chunkZ + 4, Blocks.dirt, 0, 2);
            world.setBlock(chunkX + 7, j + 4, chunkZ + 4, Blocks.dirt, 0, 2);
            world.setBlock(chunkX + 8, j + 4, chunkZ + 4, Blocks.dirt, 0, 2);
            world.setBlock(chunkX + 9, j + 4, chunkZ + 4, Blocks.dirt, 0, 2);
            world.setBlock(chunkX + 10, j + 4, chunkZ + 4, Blocks.dirt, 0, 2);
            world.setBlock(chunkX + 11, j + 4, chunkZ + 4, Blocks.dirt, 0, 2);
            world.setBlock(chunkX + 12, j + 4, chunkZ + 4, Blocks.dirt, 0, 2);
            world.setBlock(chunkX + 13, j + 4, chunkZ + 4, Blocks.dirt, 0, 2);
            world.setBlock(chunkX + 14, j + 4, chunkZ + 4, Blocks.dirt, 0, 2);
            world.setBlock(chunkX + 15, j + 4, chunkZ + 4, Blocks.dirt, 0, 2);
            world.setBlock(chunkX + 16, j + 4, chunkZ + 4, Blocks.dirt, 0, 2);
            world.setBlock(chunkX + 17, j + 4, chunkZ + 4, Blocks.dirt, 0, 2);
            world.setBlock(chunkX + 18, j + 4, chunkZ + 4, (Block)Blocks.sand, 0, 2);
            world.setBlock(chunkX + 1, j + 4, chunkZ + 5, Blocks.dirt, 0, 2);
            world.setBlock(chunkX + 2, j + 4, chunkZ + 5, Blocks.dirt, 0, 2);
            world.setBlock(chunkX + 3, j + 4, chunkZ + 5, Blocks.dirt, 0, 2);
            world.setBlock(chunkX + 4, j + 4, chunkZ + 5, Blocks.dirt, 0, 2);
            world.setBlock(chunkX + 5, j + 4, chunkZ + 5, Blocks.dirt, 0, 2);
            world.setBlock(chunkX + 6, j + 4, chunkZ + 5, Blocks.dirt, 0, 2);
            world.setBlock(chunkX + 7, j + 4, chunkZ + 5, Blocks.dirt, 0, 2);
            world.setBlock(chunkX + 8, j + 4, chunkZ + 5, Blocks.dirt, 0, 2);
            world.setBlock(chunkX + 9, j + 4, chunkZ + 5, Blocks.dirt, 0, 2);
            world.setBlock(chunkX + 10, j + 4, chunkZ + 5, Blocks.dirt, 0, 2);
            world.setBlock(chunkX + 11, j + 4, chunkZ + 5, Blocks.dirt, 0, 2);
            world.setBlock(chunkX + 12, j + 4, chunkZ + 5, Blocks.dirt, 0, 2);
