package apocalypse.fandomcraft.structures;

import net.minecraft.world.*;
import java.util.*;
import net.minecraft.world.biome.*;
import net.minecraft.init.*;
import net.minecraft.block.*;
import apocalypse.fandomcraft.main.*;
import net.minecraft.tileentity.*;
import net.minecraftforge.common.*;
import net.minecraft.util.*;
import net.minecraft.inventory.*;
import net.minecraft.world.gen.structure.*;
import net.minecraft.nbt.*;

public class DungeonCrypt extends StructureComponent
{
    public void generateStart(final World world, final Random random, final int chunkX, final int chunkY, final int chunkZ) {
        final int j = world.getHeightValue(chunkX, chunkZ) - 14;
        final boolean place = true;
        if (place && (world.getBiomeGenForCoords(chunkX, chunkZ).biomeName.equals(BiomeGenBase.plains.biomeName) || world.getBiomeGenForCoords(chunkX, chunkZ).biomeName.equals(BiomeGenBase.taiga.biomeName) || world.getBiomeGenForCoords(chunkX, chunkZ).biomeName.equals(BiomeGenBase.megaTaiga.biomeName) || world.getBiomeGenForCoords(chunkX, chunkZ).biomeName.equals(BiomeGenBase.savanna.biomeName))) {
            world.setBlock(chunkX + 0, j + 0, chunkZ + 0, Blocks.dirt, 0, 2);
            world.setBlock(chunkX + 1, j + 0, chunkZ + 0, Blocks.dirt, 0, 2);
            world.setBlock(chunkX + 2, j + 0, chunkZ + 0, Blocks.dirt, 0, 2);
            world.setBlock(chunkX + 3, j + 0, chunkZ + 0, Blocks.dirt, 0, 2);
            world.setBlock(chunkX + 4, j + 0, chunkZ + 0, Blocks.dirt, 0, 2);
            world.setBlock(chunkX + 5, j + 0, chunkZ + 0, Blocks.dirt, 0, 2);
            world.setBlock(chunkX + 6, j + 0, chunkZ + 0, Blocks.dirt, 0, 2);
            world.setBlock(chunkX + 7, j + 0, chunkZ + 0, Blocks.dirt, 0, 2);
            world.setBlock(chunkX + 8, j + 0, chunkZ + 0, Blocks.dirt, 0, 2);
            world.setBlock(chunkX + 9, j + 0, chunkZ + 0, Blocks.dirt, 0, 2);
            world.setBlock(chunkX + 10, j + 0, chunkZ + 0, Blocks.dirt, 0, 2);
            world.setBlock(chunkX + 11, j + 0, chunkZ + 0, Blocks.dirt, 0, 2);
            world.setBlock(chunkX + 12, j + 0, chunkZ + 0, Blocks.dirt, 0, 2);
            world.setBlock(chunkX + 13, j + 0, chunkZ + 0, Blocks.dirt, 0, 2);
            world.setBlock(chunkX + 14, j + 0, chunkZ + 0, Blocks.dirt, 0, 2);
            world.setBlock(chunkX + 0, j + 0, chunkZ + 1, Blocks.dirt, 0, 2);
            world.setBlock(chunkX + 1, j + 0, chunkZ + 1, (Block)Blocks.grass, 0, 2);
            world.setBlock(chunkX + 2, j + 0, chunkZ + 1, (Block)Blocks.grass, 0, 2);
            world.setBlock(chunkX + 3, j + 0, chunkZ + 1, (Block)Blocks.grass, 0, 2);
            world.setBlock(chunkX + 4, j + 0, chunkZ + 1, (Block)Blocks.grass, 0, 2);
            world.setBlock(chunkX + 5, j + 0, chunkZ + 1, (Block)Blocks.grass, 0, 2);
            world.setBlock(chunkX + 6, j + 0, chunkZ + 1, (Block)Blocks.grass, 0, 2);
            world.setBlock(chunkX + 7, j + 0, chunkZ + 1, (Block)Blocks.grass, 0, 2);
            world.setBlock(chunkX + 8, j + 0, chunkZ + 1, (Block)Blocks.grass, 0, 2);
            world.setBlock(chunkX + 9, j + 0, chunkZ + 1, (Block)Blocks.grass, 0, 2);
            world.setBlock(chunkX + 10, j + 0, chunkZ + 1, (Block)Blocks.grass, 0, 2);
            world.setBlock(chunkX + 11, j + 0, chunkZ + 1, (Block)Blocks.grass, 0, 2);
            world.setBlock(chunkX + 12, j + 0, chunkZ + 1, (Block)Blocks.grass, 0, 2);
            world.setBlock(chunkX + 13, j + 0, chunkZ + 1, (Block)Blocks.grass, 0, 2);
            world.setBlock(chunkX + 14, j + 0, chunkZ + 1, Blocks.dirt, 0, 2);
            world.setBlock(chunkX + 0, j + 0, chunkZ + 2, Blocks.dirt, 0, 2);
            world.setBlock(chunkX + 1, j + 0, chunkZ + 2, (Block)Blocks.grass, 0, 2);
            world.setBlock(chunkX + 2, j + 0, chunkZ + 2, (Block)Blocks.grass, 0, 2);
            world.setBlock(chunkX + 3, j + 0, chunkZ + 2, (Block)Blocks.grass, 0, 2);
            world.setBlock(chunkX + 4, j + 0, chunkZ + 2, (Block)Blocks.grass, 0, 2);
            world.setBlock(chunkX + 5, j + 0, chunkZ + 2, (Block)Blocks.grass, 0, 2);
            world.setBlock(chunkX + 6, j + 0, chunkZ + 2, (Block)Blocks.grass, 0, 2);
            world.setBlock(chunkX + 7, j + 0, chunkZ + 2, Main.boulder, 0, 2);
            world.setBlock(chunkX + 8, j + 0, chunkZ + 2, (Block)Blocks.grass, 0, 2);
            world.setBlock(chunkX + 9, j + 0, chunkZ + 2, (Block)Blocks.grass, 0, 2);
            world.setBlock(chunkX + 10, j + 0, chunkZ + 2, (Block)Blocks.grass, 0, 2);
            world.setBlock(chunkX + 11, j + 0, chunkZ + 2, (Block)Blocks.grass, 0, 2);
            world.setBlock(chunkX + 12, j + 0, chunkZ + 2, (Block)Blocks.grass, 0, 2);
            world.setBlock(chunkX + 13, j + 0, chunkZ + 2, (Block)Blocks.grass, 0, 2);
            world.setBlock(chunkX + 14, j + 0, chunkZ + 2, Blocks.dirt, 0, 2);
            world.setBlock(chunkX + 0, j + 0, chunkZ + 3, Blocks.dirt, 0, 2);
            world.setBlock(chunkX + 1, j + 0, chunkZ + 3, Main.infestedDirt, 0, 2);
            world.setBlock(chunkX + 2, j + 0, chunkZ + 3, Main.infestedDirt, 0, 2);
            world.setBlock(chunkX + 3, j + 0, chunkZ + 3, Main.infestedDirt, 0, 2);
            world.setBlock(chunkX + 4, j + 0, chunkZ + 3, Main.infestedDirt, 0, 2);
            world.setBlock(chunkX + 5, j + 0, chunkZ + 3, (Block)Blocks.grass, 0, 2);
            world.setBlock(chunkX + 6, j + 0, chunkZ + 3, (Block)Blocks.grass, 0, 2);
            world.setBlock(chunkX + 7, j + 0, chunkZ + 3, (Block)Blocks.grass, 0, 2);
            world.setBlock(chunkX + 8, j + 0, chunkZ + 3, (Block)Blocks.grass, 0, 2);
            world.setBlock(chunkX + 9, j + 0, chunkZ + 3, (Block)Blocks.grass, 0, 2);
            world.setBlock(chunkX + 10, j + 0, chunkZ + 3, (Block)Blocks.grass, 0, 2);
            world.setBlock(chunkX + 11, j + 0, chunkZ + 3, (Block)Blocks.grass, 0, 2);
            world.setBlock(chunkX + 12, j + 0, chunkZ + 3, (Block)Blocks.grass, 0, 2);
            world.setBlock(chunkX + 13, j + 0, chunkZ + 3, (Block)Blocks.grass, 0, 2);
            world.setBlock(chunkX + 14, j + 0, chunkZ + 3, Blocks.dirt, 0, 2);
            world.setBlock(chunkX + 0, j + 0, chunkZ + 4, Blocks.dirt, 0, 2);
            world.setBlock(chunkX + 1, j + 0, chunkZ + 4, Main.infestedDirt, 0, 2);
            world.setBlock(chunkX + 2, j + 0, chunkZ + 4, Blocks.water, 0, 2);
            world.setBlock(chunkX + 3, j + 0, chunkZ + 4, Blocks.water, 0, 2);
            world.setBlock(chunkX + 4, j + 0, chunkZ + 4, Main.infestedDirt, 0, 2);
            world.setBlock(chunkX + 5, j + 0, chunkZ + 4, Main.infestedDirt, 0, 2);
            world.setBlock(chunkX + 6, j + 0, chunkZ + 4, (Block)Blocks.grass, 0, 2);
            world.setBlock(chunkX + 7, j + 0, chunkZ + 4, (Block)Blocks.grass, 0, 2);
            world.setBlock(chunkX + 8, j + 0, chunkZ + 4, (Block)Blocks.grass, 0, 2);
            world.setBlock(chunkX + 9, j + 0, chunkZ + 4, (Block)Blocks.grass, 0, 2);
            world.setBlock(chunkX + 10, j + 0, chunkZ + 4, (Block)Blocks.grass, 0, 2);
            world.setBlock(chunkX + 11, j + 0, chunkZ + 4, (Block)Blocks.grass, 0, 2);
            world.setBlock(chunkX + 12, j + 0, chunkZ + 4, Blocks.dirt, 0, 2);
            world.setBlock(chunkX + 13, j + 0, chunkZ + 4, (Block)Blocks.grass, 0, 2);
            world.setBlock(chunkX + 14, j + 0, chunkZ + 4, Blocks.dirt, 0, 2);
            world.setBlock(chunkX + 0, j + 0, chunkZ + 5, Blocks.dirt, 0, 2);
            world.setBlock(chunkX + 1, j + 0, chunkZ + 5, Blocks.water, 0, 2);
            world.setBlock(chunkX + 2, j + 0, chunkZ + 5, Blocks.water, 0, 2);
            world.setBlock(chunkX + 3, j + 0, chunkZ + 5, Blocks.water, 0, 2);
            world.setBlock(chunkX + 4, j + 0, chunkZ + 5, Blocks.water, 0, 2);
            world.setBlock(chunkX + 5, j + 0, chunkZ + 5, Main.infestedDirt, 0, 2);
            world.setBlock(chunkX + 6, j + 0, chunkZ + 5, (Block)Blocks.grass, 0, 2);
            world.setBlock(chunkX + 7, j + 0, chunkZ + 5, (Block)Blocks.grass, 0, 2);
            world.setBlock(chunkX + 8, j + 0, chunkZ + 5, (Block)Blocks.grass, 0, 2);
            world.setBlock(chunkX + 9, j + 0, chunkZ + 5, (Block)Blocks.grass, 0, 2);
            world.setBlock(chunkX + 10, j + 0, chunkZ + 5, (Block)Blocks.grass, 0, 2);
            world.setBlock(chunkX + 11, j + 0, chunkZ + 5, (Block)Blocks.grass, 0, 2);
            world.setBlock(chunkX + 12, j + 0, chunkZ + 5, (Block)Blocks.grass, 0, 2);
            world.setBlock(chunkX + 13, j + 0, chunkZ + 5, (Block)Blocks.grass, 0, 2);
            world.setBlock(chunkX + 14, j + 0, chunkZ + 5, Blocks.dirt, 0, 2);
            world.setBlock(chunkX + 0, j + 0, chunkZ + 6, Blocks.dirt, 0, 2);
            world.setBlock(chunkX + 1, j + 0, chunkZ + 6, Blocks.water, 0, 2);
            world.setBlock(chunkX + 2, j + 0, chunkZ + 6, Blocks.water, 0, 2);
            world.setBlock(chunkX + 3, j + 0, chunkZ + 6, Blocks.water, 0, 2);
            world.setBlock(chunkX + 4, j + 0, chunkZ + 6, Blocks.water, 0, 2);
            world.setBlock(chunkX + 5, j + 0, chunkZ + 6, Main.infestedDirt, 0, 2);
            world.setBlock(chunkX + 6, j + 0, chunkZ + 6, (Block)Blocks.grass, 0, 2);
            world.setBlock(chunkX + 7, j + 0, chunkZ + 6, (Block)Blocks.grass, 0, 2);
            world.setBlock(chunkX + 8, j + 0, chunkZ + 6, (Block)Blocks.grass, 0, 2);
            world.setBlock(chunkX + 9, j + 0, chunkZ + 6, (Block)Blocks.grass, 0, 2);
            world.setBlock(chunkX + 10, j + 0, chunkZ + 6, (Block)Blocks.grass, 0, 2);
            world.setBlock(chunkX + 11, j + 0, chunkZ + 6, (Block)Blocks.grass, 0, 2);
            world.setBlock(chunkX + 12, j + 0, chunkZ + 6, (Block)Blocks.grass, 0, 2);
            world.setBlock(chunkX + 13, j + 0, chunkZ + 6, (Block)Blocks.grass, 0, 2);
            world.setBlock(chunkX + 14, j + 0, chunkZ + 6, Blocks.dirt, 0, 2);
            world.setBlock(chunkX + 0, j + 0, chunkZ + 7, Blocks.dirt, 0, 2);
            world.setBlock(chunkX + 1, j + 0, chunkZ + 7, Blocks.water, 0, 2);
            world.setBlock(chunkX + 2, j + 0, chunkZ + 7, Blocks.water, 0, 2);
            world.setBlock(chunkX + 3, j + 0, chunkZ + 7, Blocks.water, 0, 2);
            world.setBlock(chunkX + 4, j + 0, chunkZ + 7, Blocks.water, 0, 2);
            world.setBlock(chunkX + 5, j + 0, chunkZ + 7, Main.infestedDirt, 0, 2);
            world.setBlock(chunkX + 6, j + 0, chunkZ + 7, (Block)Blocks.grass, 0, 2);
            world.setBlock(chunkX + 7, j + 0, chunkZ + 7, (Block)Blocks.grass, 0, 2);
            world.setBlock(chunkX + 8, j + 0, chunkZ + 7, (Block)Blocks.grass, 0, 2);
            world.setBlock(chunkX + 9, j + 0, chunkZ + 7, Main.boulder, 0, 2);
            world.setBlock(chunkX + 10, j + 0, chunkZ + 7, (Block)Blocks.grass, 0, 2);
            world.setBlock(chunkX + 11, j + 0, chunkZ + 7, (Block)Blocks.grass, 0, 2);
            world.setBlock(chunkX + 12, j + 0, chunkZ + 7, (Block)Blocks.grass, 0, 2);
            world.setBlock(chunkX + 13, j + 0, chunkZ + 7, (Block)Blocks.grass, 0, 2);
            world.setBlock(chunkX + 14, j + 0, chunkZ + 7, Blocks.dirt, 0, 2);
            world.setBlock(chunkX + 0, j + 0, chunkZ + 8, Blocks.dirt, 0, 2);
            world.setBlock(chunkX + 1, j + 0, chunkZ + 8, Blocks.dirt, 0, 2);
            world.setBlock(chunkX + 2, j + 0, chunkZ + 8, Blocks.dirt, 0, 2);
            world.setBlock(chunkX + 3, j + 0, chunkZ + 8, Blocks.dirt, 0, 2);
            world.setBlock(chunkX + 4, j + 0, chunkZ + 8, Blocks.dirt, 0, 2);
            world.setBlock(chunkX + 5, j + 0, chunkZ + 8, Blocks.dirt, 0, 2);
            world.setBlock(chunkX + 6, j + 0, chunkZ + 8, Blocks.dirt, 0, 2);
            world.setBlock(chunkX + 7, j + 0, chunkZ + 8, Blocks.dirt, 0, 2);
            world.setBlock(chunkX + 8, j + 0, chunkZ + 8, Blocks.dirt, 0, 2);
            world.setBlock(chunkX + 9, j + 0, chunkZ + 8, Blocks.dirt, 0, 2);
            world.setBlock(chunkX + 10, j + 0, chunkZ + 8, Blocks.dirt, 0, 2);
            world.setBlock(chunkX + 11, j + 0, chunkZ + 8, Blocks.dirt, 0, 2);
            world.setBlock(chunkX + 12, j + 0, chunkZ + 8, Blocks.dirt, 0, 2);
            world.setBlock(chunkX + 13, j + 0, chunkZ + 8, Blocks.dirt, 0, 2);
            world.setBlock(chunkX + 14, j + 0, chunkZ + 8, Blocks.dirt, 0, 2);
            world.setBlock(chunkX + 0, j + 0, chunkZ + 9, (Block)Blocks.grass, 0, 2);
            world.setBlock(chunkX + 1, j + 0, chunkZ + 9, (Block)Blocks.grass, 0, 2);
            world.setBlock(chunkX + 2, j + 0, chunkZ + 9, (Block)Blocks.grass, 0, 2);
            world.setBlock(chunkX + 3, j + 0, chunkZ + 9, (Block)Blocks.grass, 0, 2);
            world.setBlock(chunkX + 4, j + 0, chunkZ + 9, (Block)Blocks.grass, 0, 2);
            world.setBlock(chunkX + 5, j + 0, chunkZ + 9, (Block)Blocks.grass, 0, 2);
            world.setBlock(chunkX + 6, j + 0, chunkZ + 9, (Block)Blocks.grass, 0, 2);
            world.setBlock(chunkX + 7, j + 0, chunkZ + 9, (Block)Blocks.grass, 0, 2);
            world.setBlock(chunkX + 8, j + 0, chunkZ + 9, (Block)Blocks.grass, 0, 2);
            world.setBlock(chunkX + 9, j + 0, chunkZ + 9, (Block)Blocks.grass, 0, 2);
            world.setBlock(chunkX + 10, j + 0, chunkZ + 9, (Block)Blocks.grass, 0, 2);
            world.setBlock(chunkX + 11, j + 0, chunkZ + 9, (Block)Blocks.grass, 0, 2);
            world.setBlock(chunkX + 12, j + 0, chunkZ + 9, (Block)Blocks.grass, 0, 2);
            world.setBlock(chunkX + 13, j + 0, chunkZ + 9, (Block)Blocks.grass, 0, 2);
            world.setBlock(chunkX + 14, j + 0, chunkZ + 9, (Block)Blocks.grass, 0, 2);
            world.setBlock(chunkX + 0, j + 1, chunkZ + 0, Blocks.stonebrick, 0, 2);
            world.setBlock(chunkX + 1, j + 1, chunkZ + 0, Blocks.stonebrick, 0, 2);
            world.setBlock(chunkX + 2, j + 1, chunkZ + 0, Blocks.stonebrick, 0, 2);
            world.setBlock(chunkX + 3, j + 1, chunkZ + 0, Blocks.stonebrick, 0, 2);
            world.setBlock(chunkX + 4, j + 1, chunkZ + 0, Blocks.stonebrick, 1, 2);
            world.setBlock(chunkX + 5, j + 1, chunkZ + 0, Blocks.stonebrick, 0, 2);
            world.setBlock(chunkX + 6, j + 1, chunkZ + 0, Blocks.stonebrick, 0, 2);
            world.setBlock(chunkX + 7, j + 1, chunkZ + 0, Blocks.stonebrick, 0, 2);
            world.setBlock(chunkX + 8, j + 1, chunkZ + 0, Blocks.stonebrick, 0, 2);
            world.setBlock(chunkX + 9, j + 1, chunkZ + 0, Blocks.stonebrick, 0, 2);
            world.setBlock(chunkX + 10, j + 1, chunkZ + 0, Blocks.stonebrick, 0, 2);
            world.setBlock(chunkX + 11, j + 1, chunkZ + 0, Blocks.stonebrick, 0, 2);
            world.setBlock(chunkX + 12, j + 1, chunkZ + 0, Blocks.stonebrick, 0, 2);
            world.setBlock(chunkX + 13, j + 1, chunkZ + 0, Blocks.stonebrick, 0, 2);
            world.setBlock(chunkX + 14, j + 1, chunkZ + 0, Blocks.stonebrick, 0, 2);
            world.setBlock(chunkX + 0, j + 1, chunkZ + 1, Blocks.stonebrick, 0, 2);
            world.setBlock(chunkX + 1, j + 1, chunkZ + 1, Main.bluePot, 0, 2);
            world.setBlock(chunkX + 2, j + 1, chunkZ + 1, Blocks.air, 0, 2);
            world.setBlock(chunkX + 3, j + 1, chunkZ + 1, (Block)Blocks.tallgrass, 1, 2);
            world.setBlock(chunkX + 4, j + 1, chunkZ + 1, (Block)Blocks.tallgrass, 1, 2);
            world.setBlock(chunkX + 5, j + 1, chunkZ + 1, (Block)Blocks.tallgrass, 1, 2);
            world.setBlock(chunkX + 6, j + 1, chunkZ + 1, Blocks.air, 0, 2);
            world.setBlock(chunkX + 7, j + 1, chunkZ + 1, Blocks.air, 0, 2);
            world.setBlock(chunkX + 8, j + 1, chunkZ + 1, Blocks.air, 0, 2);
            world.setBlock(chunkX + 9, j + 1, chunkZ + 1, Blocks.air, 0, 2);
            world.setBlock(chunkX + 10, j + 1, chunkZ + 1, Blocks.air, 0, 2);
            world.setBlock(chunkX + 11, j + 1, chunkZ + 1, Main.boulder, 0, 2);
            world.setBlock(chunkX + 12, j + 1, chunkZ + 1, (Block)Blocks.tallgrass, 1, 2);
            world.setBlock(chunkX + 13, j + 1, chunkZ + 1, (Block)Blocks.tallgrass, 1, 2);
            world.setBlock(chunkX + 14, j + 1, chunkZ + 1, Blocks.stonebrick, 0, 2);
            world.setBlock(chunkX + 0, j + 1, chunkZ + 2, Blocks.stonebrick, 0, 2);
            world.setBlock(chunkX + 1, j + 1, chunkZ + 2, Blocks.air, 0, 2);
            world.setBlock(chunkX + 2, j + 1, chunkZ + 2, (Block)Blocks.tallgrass, 1, 2);
            world.setBlock(chunkX + 3, j + 1, chunkZ + 2, (Block)Blocks.red_flower, 0, 2);
            world.setBlock(chunkX + 4, j + 1, chunkZ + 2, (Block)Blocks.tallgrass, 1, 2);
            world.setBlock(chunkX + 5, j + 1, chunkZ + 2, (Block)Blocks.tallgrass, 1, 2);
            world.setBlock(chunkX + 6, j + 1, chunkZ + 2, (Block)Blocks.tallgrass, 1, 2);
            world.setBlock(chunkX + 7, j + 1, chunkZ + 2, Blocks.air, 0, 2);
            world.setBlock(chunkX + 8, j + 1, chunkZ + 2, (Block)Blocks.tallgrass, 1, 2);
            world.setBlock(chunkX + 9, j + 1, chunkZ + 2, (Block)Blocks.tallgrass, 1, 2);
            world.setBlock(chunkX + 10, j + 1, chunkZ + 2, Blocks.air, 0, 2);
            world.setBlock(chunkX + 11, j + 1, chunkZ + 2, (Block)Blocks.tallgrass, 1, 2);
            world.setBlock(chunkX + 12, j + 1, chunkZ + 2, (Block)Blocks.tallgrass, 1, 2);
            world.setBlock(chunkX + 13, j + 1, chunkZ + 2, (Block)Blocks.tallgrass, 1, 2);
            world.setBlock(chunkX + 14, j + 1, chunkZ + 2, Blocks.stonebrick, 0, 2);
            world.setBlock(chunkX + 0, j + 1, chunkZ + 3, Blocks.stonebrick, 0, 2);
            world.setBlock(chunkX + 1, j + 1, chunkZ + 3, Blocks.air, 0, 2);
            world.setBlock(chunkX + 2, j + 1, chunkZ + 3, Blocks.air, 0, 2);
            world.setBlock(chunkX + 3, j + 1, chunkZ + 3, Blocks.air, 0, 2);
            world.setBlock(chunkX + 4, j + 1, chunkZ + 3, Blocks.air, 0, 2);
            world.setBlock(chunkX + 5, j + 1, chunkZ + 3, (Block)Blocks.tallgrass, 1, 2);
            world.setBlock(chunkX + 6, j + 1, chunkZ + 3, Blocks.air, 0, 2);
            world.setBlock(chunkX + 7, j + 1, chunkZ + 3, (Block)Blocks.yellow_flower, 0, 2);
            world.setBlock(chunkX + 8, j + 1, chunkZ + 3, (Block)Blocks.tallgrass, 1, 2);
            world.setBlock(chunkX + 9, j + 1, chunkZ + 3, (Block)Blocks.tallgrass, 1, 2);
            world.setBlock(chunkX + 10, j + 1, chunkZ + 3, (Block)Blocks.red_flower, 3, 2);
            world.setBlock(chunkX + 11, j + 1, chunkZ + 3, (Block)Blocks.tallgrass, 1, 2);
            world.setBlock(chunkX + 12, j + 1, chunkZ + 3, (Block)Blocks.tallgrass, 1, 2);
            world.setBlock(chunkX + 13, j + 1, chunkZ + 3, Main.bluePot, 0, 2);
            world.setBlock(chunkX + 14, j + 1, chunkZ + 3, Blocks.stonebrick, 1, 2);
            world.setBlock(chunkX + 0, j + 1, chunkZ + 4, Blocks.stonebrick, 0, 2);
            world.setBlock(chunkX + 1, j + 1, chunkZ + 4, Blocks.air, 0, 2);
            world.setBlock(chunkX + 2, j + 1, chunkZ + 4, Blocks.air, 0, 2);
            world.setBlock(chunkX + 3, j + 1, chunkZ + 4, Blocks.air, 0, 2);
            world.setBlock(chunkX + 4, j + 1, chunkZ + 4, Blocks.air, 0, 2);
            world.setBlock(chunkX + 5, j + 1, chunkZ + 4, Blocks.air, 0, 2);
            world.setBlock(chunkX + 6, j + 1, chunkZ + 4, (Block)Blocks.tallgrass, 1, 2);
            world.setBlock(chunkX + 7, j + 1, chunkZ + 4, (Block)Blocks.tallgrass, 1, 2);
            world.setBlock(chunkX + 8, j + 1, chunkZ + 4, (Block)Blocks.tallgrass, 1, 2);
            world.setBlock(chunkX + 9, j + 1, chunkZ + 4, (Block)Blocks.tallgrass, 1, 2);
            world.setBlock(chunkX + 10, j + 1, chunkZ + 4, (Block)Blocks.tallgrass, 1, 2);
            world.setBlock(chunkX + 11, j + 1, chunkZ + 4, (Block)Blocks.tallgrass, 1, 2);
            world.setBlock(chunkX + 12, j + 1, chunkZ + 4, Blocks.mob_spawner, 0, 2);
            final int x = chunkX + 12;
            final int y = j + 1;
            final int z = chunkZ + 4;
            final TileEntityMobSpawner tileentitymobspawner = (TileEntityMobSpawner)world.getTileEntity(x, y, z);
            if (tileentitymobspawner != null) {
                tileentitymobspawner.func_145881_a().setEntityName("Redead");
            }
            else {
                System.err.println("Failed to fetch mob spawner entity at (" + x + ", " + y + ", " + z + ")");
            }
            world.setBlock(chunkX + 13, j + 1, chunkZ + 4, (Block)Blocks.chest, 4, 2);
            final int x2 = chunkX + 13;
            final int y2 = chunkY + 1;
            final int z2 = chunkZ + 4;
            final TileEntityChest tileentitychest = (TileEntityChest)world.getTileEntity(x2, y2, z2);
            if (tileentitychest != null) {
                WeightedRandomChestContent.generateChestContents(random, ChestGenHooks.getItems("strongholdCorridor", random), (IInventory)tileentitychest, ChestGenHooks.getCount("strongholdCorridor", random));
            }
            world.setBlock(chunkX + 14, j + 1, chunkZ + 4, Blocks.stonebrick, 1, 2);
            world.setBlock(chunkX + 0, j + 1, chunkZ + 5, Blocks.stonebrick, 1, 2);
            world.setBlock(chunkX + 1, j + 1, chunkZ + 5, Blocks.air, 0, 2);
            world.setBlock(chunkX + 2, j + 1, chunkZ + 5, Blocks.air, 0, 2);
            world.setBlock(chunkX + 3, j + 1, chunkZ + 5, Blocks.air, 0, 2);
            world.setBlock(chunkX + 4, j + 1, chunkZ + 5, Blocks.air, 0, 2);
            world.setBlock(chunkX + 5, j + 1, chunkZ + 5, Blocks.air, 0, 2);
            world.setBlock(chunkX + 6, j + 1, chunkZ + 5, (Block)Blocks.tallgrass, 1, 2);
            world.setBlock(chunkX + 7, j + 1, chunkZ + 5, (Block)Blocks.tallgrass, 1, 2);
            world.setBlock(chunkX + 8, j + 1, chunkZ + 5, (Block)Blocks.tallgrass, 1, 2);
            world.setBlock(chunkX + 9, j + 1, chunkZ + 5, (Block)Blocks.tallgrass, 1, 2);
            world.setBlock(chunkX + 10, j + 1, chunkZ + 5, (Block)Blocks.tallgrass, 1, 2);
            world.setBlock(chunkX + 11, j + 1, chunkZ + 5, (Block)Blocks.tallgrass, 1, 2);
            world.setBlock(chunkX + 12, j + 1, chunkZ + 5, (Block)Blocks.tallgrass, 1, 2);
            world.setBlock(chunkX + 13, j + 1, chunkZ + 5, Main.bluePot, 0, 2);
            world.setBlock(chunkX + 14, j + 1, chunkZ + 5, Blocks.stonebrick, 0, 2);
            world.setBlock(chunkX + 0, j + 1, chunkZ + 6, Blocks.stonebrick, 0, 2);
            world.setBlock(chunkX + 1, j + 1, chunkZ + 6, Blocks.air, 0, 2);
            world.setBlock(chunkX + 2, j + 1, chunkZ + 6, Blocks.air, 0, 2);
            world.setBlock(chunkX + 3, j + 1, chunkZ + 6, Blocks.air, 0, 2);
            world.setBlock(chunkX + 4, j + 1, chunkZ + 6, Blocks.air, 0, 2);
            world.setBlock(chunkX + 5, j + 1, chunkZ + 6, Blocks.air, 0, 2);
            world.setBlock(chunkX + 6, j + 1, chunkZ + 6, (Block)Blocks.tallgrass, 1, 2);
            world.setBlock(chunkX + 7, j + 1, chunkZ + 6, (Block)Blocks.red_flower, 8, 2);
            world.setBlock(chunkX + 8, j + 1, chunkZ + 6, (Block)Blocks.tallgrass, 1, 2);
            world.setBlock(chunkX + 9, j + 1, chunkZ + 6, (Block)Blocks.yellow_flower, 0, 2);
            world.setBlock(chunkX + 10, j + 1, chunkZ + 6, (Block)Blocks.tallgrass, 1, 2);
            world.setBlock(chunkX + 11, j + 1, chunkZ + 6, Blocks.air, 0, 2);
            world.setBlock(chunkX + 12, j + 1, chunkZ + 6, (Block)Blocks.tallgrass, 1, 2);
            world.setBlock(chunkX + 13, j + 1, chunkZ + 6, (Block)Blocks.tallgrass, 1, 2);
            world.setBlock(chunkX + 14, j + 1, chunkZ + 6, Blocks.stonebrick, 0, 2);
            world.setBlock(chunkX + 0, j + 1, chunkZ + 7, Blocks.stonebrick, 0, 2);
            world.setBlock(chunkX + 1, j + 1, chunkZ + 7, Blocks.air, 0, 2);
            world.setBlock(chunkX + 2, j + 1, chunkZ + 7, Blocks.air, 0, 2);
            world.setBlock(chunkX + 3, j + 1, chunkZ + 7, Blocks.air, 0, 2);
            world.setBlock(chunkX + 4, j + 1, chunkZ + 7, Blocks.air, 0, 2);
            world.setBlock(chunkX + 5, j + 1, chunkZ + 7, Blocks.air, 0, 2);
            world.setBlock(chunkX + 6, j + 1, chunkZ + 7, (Block)Blocks.tallgrass, 1, 2);
            world.setBlock(chunkX + 7, j + 1, chunkZ + 7, Main.bluePot, 0, 2);
            world.setBlock(chunkX + 8, j + 1, chunkZ + 7, Blocks.air, 0, 2);
            world.setBlock(chunkX + 9, j + 1, chunkZ + 7, Blocks.air, 0, 2);
            world.setBlock(chunkX + 10, j + 1, chunkZ + 7, (Block)Blocks.red_flower, 8, 2);
            world.setBlock(chunkX + 11, j + 1, chunkZ + 7, (Block)Blocks.tallgrass, 1, 2);
            world.setBlock(chunkX + 12, j + 1, chunkZ + 7, (Block)Blocks.yellow_flower, 0, 2);
            world.setBlock(chunkX + 13, j + 1, chunkZ + 7, (Block)Blocks.tallgrass, 1, 2);
            world.setBlock(chunkX + 14, j + 1, chunkZ + 7, Blocks.stonebrick, 0, 2);
            world.setBlock(chunkX + 0, j + 1, chunkZ + 8, Blocks.stonebrick, 0, 2);
            world.setBlock(chunkX + 1, j + 1, chunkZ + 8, Blocks.stonebrick, 0, 2);
            world.setBlock(chunkX + 2, j + 1, chunkZ + 8, Blocks.stonebrick, 0, 2);
            world.setBlock(chunkX + 3, j + 1, chunkZ + 8, Blocks.stonebrick, 0, 2);
            world.setBlock(chunkX + 4, j + 1, chunkZ + 8, Blocks.stonebrick, 0, 2);
            world.setBlock(chunkX + 5, j + 1, chunkZ + 8, Blocks.stonebrick, 0, 2);
            world.setBlock(chunkX + 6, j + 1, chunkZ + 8, Blocks.stonebrick, 0, 2);
            world.setBlock(chunkX + 7, j + 1, chunkZ + 8, Blocks.stonebrick, 0, 2);
            world.setBlock(chunkX + 8, j + 1, chunkZ + 8, Blocks.stonebrick, 0, 2);
            world.setBlock(chunkX + 9, j + 1, chunkZ + 8, Blocks.stonebrick, 0, 2);
            world.setBlock(chunkX + 10, j + 1, chunkZ + 8, Blocks.stonebrick, 1, 2);
            world.setBlock(chunkX + 11, j + 1, chunkZ + 8, Blocks.stonebrick, 0, 2);
            world.setBlock(chunkX + 12, j + 1, chunkZ + 8, Blocks.stonebrick, 0, 2);
            world.setBlock(chunkX + 13, j + 1, chunkZ + 8, Blocks.stonebrick, 0, 2);
            world.setBlock(chunkX + 14, j + 1, chunkZ + 8, Blocks.stonebrick, 0, 2);
            world.setBlock(chunkX + 0, j + 1, chunkZ + 9, Blocks.air, 0, 2);
            world.setBlock(chunkX + 1, j + 1, chunkZ + 9, Blocks.air, 0, 2);
            world.setBlock(chunkX + 2, j + 1, chunkZ + 9, Blocks.air, 0, 2);
            world.setBlock(chunkX + 3, j + 1, chunkZ + 9, Blocks.air, 0, 2);
            world.setBlock(chunkX + 4, j + 1, chunkZ + 9, Blocks.air, 0, 2);
            world.setBlock(chunkX + 5, j + 1, chunkZ + 9, Blocks.air, 0, 2);
            world.setBlock(chunkX + 6, j + 1, chunkZ + 9, Blocks.air, 0, 2);
            world.setBlock(chunkX + 7, j + 1, chunkZ + 9, Blocks.air, 0, 2);
            world.setBlock(chunkX + 8, j + 1, chunkZ + 9, Blocks.air, 0, 2);
            world.setBlock(chunkX + 9, j + 1, chunkZ + 9, Blocks.air, 0, 2);
            world.setBlock(chunkX + 10, j + 1, chunkZ + 9, Blocks.air, 0, 2);
            world.setBlock(chunkX + 11, j + 1, chunkZ + 9, Blocks.air, 0, 2);
            world.setBlock(chunkX + 12, j + 1, chunkZ + 9, Blocks.air, 0, 2);
            world.setBlock(chunkX + 13, j + 1, chunkZ + 9, Blocks.air, 0, 2);
            world.setBlock(chunkX + 14, j + 1, chunkZ + 9, Blocks.air, 0, 2);
            world.setBlock(chunkX + 0, j + 2, chunkZ + 0, Blocks.stonebrick, 0, 2);
            world.setBlock(chunkX + 1, j + 2, chunkZ + 0, Blocks.stonebrick, 0, 2);
            world.setBlock(chunkX + 2, j + 2, chunkZ + 0, Blocks.stonebrick, 1, 2);
            world.setBlock(chunkX + 3, j + 2, chunkZ + 0, Blocks.stonebrick, 0, 2);
            world.setBlock(chunkX + 4, j + 2, chunkZ + 0, Blocks.stonebrick, 0, 2);
            world.setBlock(chunkX + 5, j + 2, chunkZ + 0, Blocks.stonebrick, 0, 2);
            world.setBlock(chunkX + 6, j + 2, chunkZ + 0, Blocks.stonebrick, 1, 2);
            world.setBlock(chunkX + 7, j + 2, chunkZ + 0, Blocks.stonebrick, 1, 2);
            world.setBlock(chunkX + 8, j + 2, chunkZ + 0, Blocks.stonebrick, 0, 2);
            world.setBlock(chunkX + 9, j + 2, chunkZ + 0, Blocks.stonebrick, 0, 2);
            world.setBlock(chunkX + 10, j + 2, chunkZ + 0, Blocks.stonebrick, 0, 2);
            world.setBlock(chunkX + 11, j + 2, chunkZ + 0, Blocks.stonebrick, 1, 2);
            world.setBlock(chunkX + 12, j + 2, chunkZ + 0, Blocks.stonebrick, 0, 2);
            world.setBlock(chunkX + 13, j + 2, chunkZ + 0, Blocks.stonebrick, 0, 2);
            world.setBlock(chunkX + 14, j + 2, chunkZ + 0, Blocks.stonebrick, 0, 2);
            world.setBlock(chunkX + 0, j + 2, chunkZ + 1, Blocks.stonebrick, 0, 2);
            world.setBlock(chunkX + 1, j + 2, chunkZ + 1, Blocks.air, 0, 2);
            world.setBlock(chunkX + 2, j + 2, chunkZ + 1, Blocks.air, 0, 2);
            world.setBlock(chunkX + 3, j + 2, chunkZ + 1, Blocks.air, 0, 2);
            world.setBlock(chunkX + 4, j + 2, chunkZ + 1, Blocks.air, 0, 2);
            world.setBlock(chunkX + 5, j + 2, chunkZ + 1, Blocks.air, 0, 2);
            world.setBlock(chunkX + 6, j + 2, chunkZ + 1, Blocks.air, 0, 2);
            world.setBlock(chunkX + 7, j + 2, chunkZ + 1, Blocks.air, 0, 2);
            world.setBlock(chunkX + 8, j + 2, chunkZ + 1, Blocks.air, 0, 2);
            world.setBlock(chunkX + 9, j + 2, chunkZ + 1, Blocks.air, 0, 2);
            world.setBlock(chunkX + 10, j + 2, chunkZ + 1, Blocks.air, 0, 2);
            world.setBlock(chunkX + 11, j + 2, chunkZ + 1, Blocks.air, 0, 2);
            world.setBlock(chunkX + 12, j + 2, chunkZ + 1, Blocks.air, 0, 2);
            world.setBlock(chunkX + 13, j + 2, chunkZ + 1, Blocks.air, 0, 2);
            world.setBlock(chunkX + 14, j + 2, chunkZ + 1, Blocks.stonebrick, 1, 2);
            world.setBlock(chunkX + 0, j + 2, chunkZ + 2, Blocks.stonebrick, 0, 2);
            world.setBlock(chunkX + 1, j + 2, chunkZ + 2, Blocks.air, 0, 2);
            world.setBlock(chunkX + 2, j + 2, chunkZ + 2, Blocks.air, 0, 2);
            world.setBlock(chunkX + 3, j + 2, chunkZ + 2, Blocks.air, 0, 2);
            world.setBlock(chunkX + 4, j + 2, chunkZ + 2, Blocks.air, 0, 2);
            world.setBlock(chunkX + 5, j + 2, chunkZ + 2, Blocks.air, 0, 2);
            world.setBlock(chunkX + 6, j + 2, chunkZ + 2, Blocks.air, 0, 2);
            world.setBlock(chunkX + 7, j + 2, chunkZ + 2, Blocks.air, 0, 2);
            world.setBlock(chunkX + 8, j + 2, chunkZ + 2, Blocks.air, 0, 2);
            world.setBlock(chunkX + 9, j + 2, chunkZ + 2, Blocks.air, 0, 2);
            world.setBlock(chunkX + 10, j + 2, chunkZ + 2, Blocks.air, 0, 2);
            world.setBlock(chunkX + 11, j + 2, chunkZ + 2, Blocks.air, 0, 2);
            world.setBlock(chunkX + 12, j + 2, chunkZ + 2, Blocks.air, 0, 2);
            world.setBlock(chunkX + 13, j + 2, chunkZ + 2, Blocks.air, 0, 2);
            world.setBlock(chunkX + 14, j + 2, chunkZ + 2, Blocks.stonebrick, 0, 2);
            world.setBlock(chunkX + 0, j + 2, chunkZ + 3, Blocks.stonebrick, 1, 2);
            world.setBlock(chunkX + 1, j + 2, chunkZ + 3, Blocks.air, 0, 2);
            world.setBlock(chunkX + 2, j + 2, chunkZ + 3, Blocks.air, 0, 2);
            world.setBlock(chunkX + 3, j + 2, chunkZ + 3, Blocks.air, 0, 2);
            world.setBlock(chunkX + 4, j + 2, chunkZ + 3, Blocks.air, 0, 2);
            world.setBlock(chunkX + 5, j + 2, chunkZ + 3, Blocks.air, 0, 2);
            world.setBlock(chunkX + 6, j + 2, chunkZ + 3, Blocks.air, 0, 2);
            world.setBlock(chunkX + 7, j + 2, chunkZ + 3, Blocks.air, 0, 2);
            world.setBlock(chunkX + 8, j + 2, chunkZ + 3, Blocks.air, 0, 2);
            world.setBlock(chunkX + 9, j + 2, chunkZ + 3, Blocks.air, 0, 2);
            world.setBlock(chunkX + 10, j + 2, chunkZ + 3, Blocks.air, 0, 2);
            world.setBlock(chunkX + 11, j + 2, chunkZ + 3, Blocks.air, 0, 2);
            world.setBlock(chunkX + 12, j + 2, chunkZ + 3, Blocks.air, 0, 2);
            world.setBlock(chunkX + 13, j + 2, chunkZ + 3, Blocks.air, 0, 2);
            world.setBlock(chunkX + 14, j + 2, chunkZ + 3, Blocks.stonebrick, 0, 2);
            world.setBlock(chunkX + 0, j + 2, chunkZ + 4, Blocks.stonebrick, 1, 2);
            world.setBlock(chunkX + 1, j + 2, chunkZ + 4, Blocks.air, 0, 2);
            world.setBlock(chunkX + 2, j + 2, chunkZ + 4, Blocks.air, 0, 2);
            world.setBlock(chunkX + 3, j + 2, chunkZ + 4, Blocks.air, 0, 2);
            world.setBlock(chunkX + 4, j + 2, chunkZ + 4, Blocks.air, 0, 2);
            world.setBlock(chunkX + 5, j + 2, chunkZ + 4, Blocks.air, 0, 2);
            world.setBlock(chunkX + 6, j + 2, chunkZ + 4, Blocks.air, 0, 2);
            world.setBlock(chunkX + 7, j + 2, chunkZ + 4, Blocks.air, 0, 2);
            world.setBlock(chunkX + 8, j + 2, chunkZ + 4, Blocks.air, 0, 2);
            world.setBlock(chunkX + 9, j + 2, chunkZ + 4, Blocks.air, 0, 2);
            world.setBlock(chunkX + 10, j + 2, chunkZ + 4, Blocks.air, 0, 2);
            world.setBlock(chunkX + 11, j + 2, chunkZ + 4, Blocks.air, 0, 2);
            world.setBlock(chunkX + 12, j + 2, chunkZ + 4, Blocks.air, 0, 2);
            world.setBlock(chunkX + 13, j + 2, chunkZ + 4, Blocks.air, 0, 2);
            world.setBlock(chunkX + 14, j + 2, chunkZ + 4, Blocks.stonebrick, 0, 2);
            world.setBlock(chunkX + 0, j + 2, chunkZ + 5, Blocks.stonebrick, 0, 2);
            world.setBlock(chunkX + 1, j + 2, chunkZ + 5, Blocks.air, 0, 2);
            world.setBlock(chunkX + 2, j + 2, chunkZ + 5, Blocks.air, 0, 2);
            world.setBlock(chunkX + 3, j + 2, chunkZ + 5, Blocks.air, 0, 2);
            world.setBlock(chunkX + 4, j + 2, chunkZ + 5, Blocks.air, 0, 2);
            world.setBlock(chunkX + 5, j + 2, chunkZ + 5, Blocks.air, 0, 2);
            world.setBlock(chunkX + 6, j + 2, chunkZ + 5, Blocks.air, 0, 2);
            world.setBlock(chunkX + 7, j + 2, chunkZ + 5, Blocks.air, 0, 2);
            world.setBlock(chunkX + 8, j + 2, chunkZ + 5, Blocks.air, 0, 2);
            world.setBlock(chunkX + 9, j + 2, chunkZ + 5, Blocks.air, 0, 2);
            world.setBlock(chunkX + 10, j + 2, chunkZ + 5, Blocks.air, 0, 2);
            world.setBlock(chunkX + 11, j + 2, chunkZ + 5, Blocks.air, 0, 2);
            world.setBlock(chunkX + 12, j + 2, chunkZ + 5, Blocks.air, 0, 2);
            world.setBlock(chunkX + 13, j + 2, chunkZ + 5, Blocks.air, 0, 2);
            world.setBlock(chunkX + 14, j + 2, chunkZ + 5, Blocks.stonebrick, 0, 2);
            world.setBlock(chunkX + 0, j + 2, chunkZ + 6, Blocks.stonebrick, 0, 2);
            world.setBlock(chunkX + 1, j + 2, chunkZ + 6, Blocks.air, 0, 2);
            world.setBlock(chunkX + 2, j + 2, chunkZ + 6, Blocks.air, 0, 2);
            world.setBlock(chunkX + 3, j + 2, chunkZ + 6, Blocks.air, 0, 2);
            world.setBlock(chunkX + 4, j + 2, chunkZ + 6, Blocks.air, 0, 2);
            world.setBlock(chunkX + 5, j + 2, chunkZ + 6, Blocks.air, 0, 2);
            world.setBlock(chunkX + 6, j + 2, chunkZ + 6, Blocks.air, 0, 2);
            world.setBlock(chunkX + 7, j + 2, chunkZ + 6, Blocks.air, 0, 2);
            world.setBlock(chunkX + 8, j + 2, chunkZ + 6, Blocks.air, 0, 2);
            world.setBlock(chunkX + 9, j + 2, chunkZ + 6, Blocks.air, 0, 2);
            world.setBlock(chunkX + 10, j + 2, chunkZ + 6, Blocks.air, 0, 2);
            world.setBlock(chunkX + 11, j + 2, chunkZ + 6, Blocks.air, 0, 2);
            world.setBlock(chunkX + 12, j + 2, chunkZ + 6, Blocks.air, 0, 2);
            world.setBlock(chunkX + 13, j + 2, chunkZ + 6, Blocks.air, 0, 2);
            world.setBlock(chunkX + 14, j + 2, chunkZ + 6, Blocks.stonebrick, 0, 2);
            world.setBlock(chunkX + 0, j + 2, chunkZ + 7, Blocks.stonebrick, 0, 2);
            world.setBlock(chunkX + 1, j + 2, chunkZ + 7, Blocks.air, 0, 2);
            world.setBlock(chunkX + 2, j + 2, chunkZ + 7, Blocks.air, 0, 2);
            world.setBlock(chunkX + 3, j + 2, chunkZ + 7, Blocks.air, 0, 2);
            world.setBlock(chunkX + 4, j + 2, chunkZ + 7, Blocks.air, 0, 2);
            world.setBlock(chunkX + 5, j + 2, chunkZ + 7, Blocks.air, 0, 2);
            world.setBlock(chunkX + 6, j + 2, chunkZ + 7, Blocks.air, 0, 2);
            world.setBlock(chunkX + 7, j + 2, chunkZ + 7, Blocks.air, 0, 2);
            world.setBlock(chunkX + 8, j + 2, chunkZ + 7, Blocks.air, 0, 2);
            world.setBlock(chunkX + 9, j + 2, chunkZ + 7, Blocks.air, 0, 2);
            world.setBlock(chunkX + 10, j + 2, chunkZ + 7, Blocks.air, 0, 2);
            world.setBlock(chunkX + 11, j + 2, chunkZ + 7, Blocks.air, 0, 2);
            world.setBlock(chunkX + 12, j + 2, chunkZ + 7, Blocks.air, 0, 2);
            world.setBlock(chunkX + 13, j + 2, chunkZ + 7, Blocks.air, 0, 2);
            world.setBlock(chunkX + 14, j + 2, chunkZ + 7, Blocks.stonebrick, 1, 2);
            world.setBlock(chunkX + 0, j + 2, chunkZ + 8, Blocks.stonebrick, 0, 2);
            world.setBlock(chunkX + 1, j + 2, chunkZ + 8, Blocks.stonebrick, 0, 2);
            world.setBlock(chunkX + 2, j + 2, chunkZ + 8, Blocks.stonebrick, 1, 2);
            world.setBlock(chunkX + 3, j + 2, chunkZ + 8, Blocks.stonebrick, 0, 2);
            world.setBlock(chunkX + 4, j + 2, chunkZ + 8, Blocks.stonebrick, 1, 2);
            world.setBlock(chunkX + 5, j + 2, chunkZ + 8, Blocks.stonebrick, 0, 2);
            world.setBlock(chunkX + 6, j + 2, chunkZ + 8, Blocks.stonebrick, 0, 2);
            world.setBlock(chunkX + 7, j + 2, chunkZ + 8, Blocks.stonebrick, 1, 2);
            world.setBlock(chunkX + 8, j + 2, chunkZ + 8, Blocks.stonebrick, 1, 2);
            world.setBlock(chunkX + 9, j + 2, chunkZ + 8, Blocks.stonebrick, 0, 2);
            world.setBlock(chunkX + 10, j + 2, chunkZ + 8, Blocks.stonebrick, 0, 2);
            world.setBlock(chunkX + 11, j + 2, chunkZ + 8, Blocks.stonebrick, 0, 2);
            world.setBlock(chunkX + 12, j + 2, chunkZ + 8, Blocks.stonebrick, 0, 2);
            world.setBlock(chunkX + 13, j + 2, chunkZ + 8, Blocks.stonebrick, 0, 2);
            world.setBlock(chunkX + 14, j + 2, chunkZ + 8, Blocks.stonebrick, 0, 2);
            world.setBlock(chunkX + 0, j + 2, chunkZ + 9, Blocks.air, 0, 2);
            world.setBlock(chunkX + 1, j + 2, chunkZ + 9, Blocks.air, 0, 2);
            world.setBlock(chunkX + 2, j + 2, chunkZ + 9, Blocks.air, 0, 2);
            world.setBlock(chunkX + 3, j + 2, chunkZ + 9, Blocks.air, 0, 2);
            world.setBlock(chunkX + 4, j + 2, chunkZ + 9, Blocks.air, 0, 2);
            world.setBlock(chunkX + 5, j + 2, chunkZ + 9, Blocks.air, 0, 2);
            world.setBlock(chunkX + 6, j + 2, chunkZ + 9, Blocks.air, 0, 2);
            world.setBlock(chunkX + 7, j + 2, chunkZ + 9, Blocks.air, 0, 2);
            world.setBlock(chunkX + 8, j + 2, chunkZ + 9, Blocks.air, 0, 2);
            world.setBlock(chunkX + 9, j + 2, chunkZ + 9, Blocks.air, 0, 2);
            world.setBlock(chunkX + 10, j + 2, chunkZ + 9, Blocks.air, 0, 2);
            world.setBlock(chunkX + 11, j + 2, chunkZ + 9, Blocks.air, 0, 2);
            world.setBlock(chunkX + 12, j + 2, chunkZ + 9, Blocks.air, 0, 2);
            world.setBlock(chunkX + 13, j + 2, chunkZ + 9, Blocks.air, 0, 2);
            world.setBlock(chunkX + 14, j + 2, chunkZ + 9, Blocks.air, 0, 2);
            world.setBlock(chunkX + 0, j + 3, chunkZ + 0, Blocks.stonebrick, 0, 2);
            world.setBlock(chunkX + 1, j + 3, chunkZ + 0, Blocks.stonebrick, 0, 2);
            world.setBlock(chunkX + 2, j + 3, chunkZ + 0, Blocks.stonebrick, 0, 2);
            world.setBlock(chunkX + 3, j + 3, chunkZ + 0, Blocks.stonebrick, 0, 2);
            world.setBlock(chunkX + 4, j + 3, chunkZ + 0, Blocks.stonebrick, 1, 2);
            world.setBlock(chunkX + 5, j + 3, chunkZ + 0, Blocks.stonebrick, 0, 2);
            world.setBlock(chunkX + 6, j + 3, chunkZ + 0, Blocks.stonebrick, 1, 2);
            world.setBlock(chunkX + 7, j + 3, chunkZ + 0, Blocks.stonebrick, 0, 2);
            world.setBlock(chunkX + 8, j + 3, chunkZ + 0, Blocks.stonebrick, 0, 2);
            world.setBlock(chunkX + 9, j + 3, chunkZ + 0, Blocks.stonebrick, 1, 2);
            world.setBlock(chunkX + 10, j + 3, chunkZ + 0, Blocks.stonebrick, 1, 2);
            world.setBlock(chunkX + 11, j + 3, chunkZ + 0, Blocks.stonebrick, 1, 2);
            world.setBlock(chunkX + 12, j + 3, chunkZ + 0, Blocks.stonebrick, 0, 2);
            world.setBlock(chunkX + 13, j + 3, chunkZ + 0, Blocks.stonebrick, 0, 2);
            world.setBlock(chunkX + 14, j + 3, chunkZ + 0, Blocks.stonebrick, 0, 2);
            world.setBlock(chunkX + 0, j + 3, chunkZ + 1, Blocks.stonebrick, 0, 2);
            world.setBlock(chunkX + 1, j + 3, chunkZ + 1, Blocks.air, 0, 2);
            world.setBlock(chunkX + 2, j + 3, chunkZ + 1, Blocks.air, 0, 2);
            world.setBlock(chunkX + 3, j + 3, chunkZ + 1, Blocks.air, 0, 2);
            world.setBlock(chunkX + 4, j + 3, chunkZ + 1, Blocks.air, 0, 2);
            world.setBlock(chunkX + 5, j + 3, chunkZ + 1, Blocks.air, 0, 2);
            world.setBlock(chunkX + 6, j + 3, chunkZ + 1, Blocks.air, 0, 2);
            world.setBlock(chunkX + 7, j + 3, chunkZ + 1, Blocks.air, 0, 2);
            world.setBlock(chunkX + 8, j + 3, chunkZ + 1, Blocks.air, 0, 2);
            world.setBlock(chunkX + 9, j + 3, chunkZ + 1, Blocks.air, 0, 2);
            world.setBlock(chunkX + 10, j + 3, chunkZ + 1, Blocks.air, 0, 2);
            world.setBlock(chunkX + 11, j + 3, chunkZ + 1, Blocks.air, 0, 2);
            world.setBlock(chunkX + 12, j + 3, chunkZ + 1, Blocks.air, 0, 2);
            world.setBlock(chunkX + 13, j + 3, chunkZ + 1, Blocks.air, 0, 2);
            world.setBlock(chunkX + 14, j + 3, chunkZ + 1, Blocks.stonebrick, 0, 2);
            world.setBlock(chunkX + 0, j + 3, chunkZ + 2, Blocks.stonebrick, 0, 2);
            world.setBlock(chunkX + 1, j + 3, chunkZ + 2, Blocks.air, 0, 2);
            world.setBlock(chunkX + 2, j + 3, chunkZ + 2, Blocks.air, 0, 2);
            world.setBlock(chunkX + 3, j + 3, chunkZ + 2, Blocks.air, 0, 2);
            world.setBlock(chunkX + 4, j + 3, chunkZ + 2, Blocks.air, 0, 2);
            world.setBlock(chunkX + 5, j + 3, chunkZ + 2, Blocks.air, 0, 2);
            world.setBlock(chunkX + 6, j + 3, chunkZ + 2, Blocks.air, 0, 2);
            world.setBlock(chunkX + 7, j + 3, chunkZ + 2, Blocks.air, 0, 2);
            world.setBlock(chunkX + 8, j + 3, chunkZ + 2, Blocks.air, 0, 2);
            world.setBlock(chunkX + 9, j + 3, chunkZ + 2, Blocks.air, 0, 2);
            world.setBlock(chunkX + 10, j + 3, chunkZ + 2, Blocks.air, 0, 2);
            world.setBlock(chunkX + 11, j + 3, chunkZ + 2, Blocks.air, 0, 2);
            world.setBlock(chunkX + 12, j + 3, chunkZ + 2, Blocks.air, 0, 2);
            world.setBlock(chunkX + 13, j + 3, chunkZ + 2, Blocks.air, 0, 2);
            world.setBlock(chunkX + 14, j + 3, chunkZ + 2, Blocks.stonebrick, 0, 2);
            world.setBlock(chunkX + 0, j + 3, chunkZ + 3, Blocks.stonebrick, 0, 2);
            world.setBlock(chunkX + 1, j + 3, chunkZ + 3, Blocks.air, 0, 2);
            world.setBlock(chunkX + 2, j + 3, chunkZ + 3, Blocks.air, 0, 2);
            world.setBlock(chunkX + 3, j + 3, chunkZ + 3, Blocks.air, 0, 2);
            world.setBlock(chunkX + 4, j + 3, chunkZ + 3, Blocks.air, 0, 2);
            world.setBlock(chunkX + 5, j + 3, chunkZ + 3, Blocks.air, 0, 2);
            world.setBlock(chunkX + 6, j + 3, chunkZ + 3, Blocks.air, 0, 2);
            world.setBlock(chunkX + 7, j + 3, chunkZ + 3, Blocks.air, 0, 2);
            world.setBlock(chunkX + 8, j + 3, chunkZ + 3, Blocks.air, 0, 2);
            world.setBlock(chunkX + 9, j + 3, chunkZ + 3, Blocks.air, 0, 2);
            world.setBlock(chunkX + 10, j + 3, chunkZ + 3, Blocks.air, 0, 2);
            world.setBlock(chunkX + 11, j + 3, chunkZ + 3, Blocks.air, 0, 2);
            world.setBlock(chunkX + 12, j + 3, chunkZ + 3, Blocks.air, 0, 2);
            world.setBlock(chunkX + 13, j + 3, chunkZ + 3, Blocks.air, 0, 2);
            world.setBlock(chunkX + 14, j + 3, chunkZ + 3, Blocks.stonebrick, 0, 2);
            world.setBlock(chunkX + 0, j + 3, chunkZ + 4, Blocks.stonebrick, 0, 2);
            world.setBlock(chunkX + 1, j + 3, chunkZ + 4, Blocks.air, 0, 2);
            world.setBlock(chunkX + 2, j + 3, chunkZ + 4, Blocks.air, 0, 2);
            world.setBlock(chunkX + 3, j + 3, chunkZ + 4, Blocks.air, 0, 2);
            world.setBlock(chunkX + 4, j + 3, chunkZ + 4, Blocks.air, 0, 2);
            world.setBlock(chunkX + 5, j + 3, chunkZ + 4, Blocks.air, 0, 2);
            world.setBlock(chunkX + 6, j + 3, chunkZ + 4, Blocks.air, 0, 2);
            world.setBlock(chunkX + 7, j + 3, chunkZ + 4, Blocks.air, 0, 2);
            world.setBlock(chunkX + 8, j + 3, chunkZ + 4, Blocks.air, 0, 2);
            world.setBlock(chunkX + 9, j + 3, chunkZ + 4, Blocks.air, 0, 2);
            world.setBlock(chunkX + 10, j + 3, chunkZ + 4, Blocks.air, 0, 2);
            world.setBlock(chunkX + 11, j + 3, chunkZ + 4, Blocks.air, 0, 2);
            world.setBlock(chunkX + 12, j + 3, chunkZ + 4, Blocks.air, 0, 2);
            world.setBlock(chunkX + 13, j + 3, chunkZ + 4, Blocks.air, 0, 2);
            world.setBlock(chunkX + 14, j + 3, chunkZ + 4, Blocks.stonebrick, 1, 2);
            world.setBlock(chunkX + 0, j + 3, chunkZ + 5, Blocks.stonebrick, 0, 2);
            world.setBlock(chunkX + 1, j + 3, chunkZ + 5, Blocks.air, 0, 2);
            world.setBlock(chunkX + 2, j + 3, chunkZ + 5, Blocks.air, 0, 2);
            world.setBlock(chunkX + 3, j + 3, chunkZ + 5, Blocks.air, 0, 2);
            world.setBlock(chunkX + 4, j + 3, chunkZ + 5, Blocks.air, 0, 2);
            world.setBlock(chunkX + 5, j + 3, chunkZ + 5, Blocks.air, 0, 2);
            world.setBlock(chunkX + 6, j + 3, chunkZ + 5, Blocks.air, 0, 2);
            world.setBlock(chunkX + 7, j + 3, chunkZ + 5, Blocks.air, 0, 2);
            world.setBlock(chunkX + 8, j + 3, chunkZ + 5, Blocks.air, 0, 2);
            world.setBlock(chunkX + 9, j + 3, chunkZ + 5, Blocks.air, 0, 2);
            world.setBlock(chunkX + 10, j + 3, chunkZ + 5, Blocks.air, 0, 2);
            world.setBlock(chunkX + 11, j + 3, chunkZ + 5, Blocks.air, 0, 2);
            world.setBlock(chunkX + 12, j + 3, chunkZ + 5, Blocks.air, 0, 2);
            world.setBlock(chunkX + 13, j + 3, chunkZ + 5, Blocks.air, 0, 2);
            world.setBlock(chunkX + 14, j + 3, chunkZ + 5, Blocks.stonebrick, 0, 2);
            world.setBlock(chunkX + 0, j + 3, chunkZ + 6, Blocks.stonebrick, 1, 2);
            world.setBlock(chunkX + 1, j + 3, chunkZ + 6, Blocks.air, 0, 2);
            world.setBlock(chunkX + 2, j + 3, chunkZ + 6, Blocks.air, 0, 2);
            world.setBlock(chunkX + 3, j + 3, chunkZ + 6, Blocks.air, 0, 2);
            world.setBlock(chunkX + 4, j + 3, chunkZ + 6, Blocks.air, 0, 2);
            world.setBlock(chunkX + 5, j + 3, chunkZ + 6, Blocks.air, 0, 2);
            world.setBlock(chunkX + 6, j + 3, chunkZ + 6, Blocks.air, 0, 2);
            world.setBlock(chunkX + 7, j + 3, chunkZ + 6, Blocks.air, 0, 2);
            world.setBlock(chunkX + 8, j + 3, chunkZ + 6, Blocks.air, 0, 2);
            world.setBlock(chunkX + 9, j + 3, chunkZ + 6, Blocks.air, 0, 2);
            world.setBlock(chunkX + 10, j + 3, chunkZ + 6, Blocks.air, 0, 2);
            world.setBlock(chunkX + 11, j + 3, chunkZ + 6, Blocks.air, 0, 2);
            world.setBlock(chunkX + 12, j + 3, chunkZ + 6, Blocks.air, 0, 2);
            world.setBlock(chunkX + 13, j + 3, chunkZ + 6, Blocks.air, 0, 2);
            world.setBlock(chunkX + 14, j + 3, chunkZ + 6, Blocks.stonebrick, 0, 2);
            world.setBlock(chunkX + 0, j + 3, chunkZ + 7, Blocks.stonebrick, 1, 2);
            world.setBlock(chunkX + 1, j + 3, chunkZ + 7, Blocks.air, 0, 2);
            world.setBlock(chunkX + 2, j + 3, chunkZ + 7, Blocks.air, 0, 2);
            world.setBlock(chunkX + 3, j + 3, chunkZ + 7, Blocks.air, 0, 2);
            world.setBlock(chunkX + 4, j + 3, chunkZ + 7, Blocks.air, 0, 2);
            world.setBlock(chunkX + 5, j + 3, chunkZ + 7, Blocks.air, 0, 2);
            world.setBlock(chunkX + 6, j + 3, chunkZ + 7, Blocks.air, 0, 2);
            world.setBlock(chunkX + 7, j + 3, chunkZ + 7, Blocks.air, 0, 2);
            world.setBlock(chunkX + 8, j + 3, chunkZ + 7, Blocks.air, 0, 2);
            world.setBlock(chunkX + 9, j + 3, chunkZ + 7, Blocks.air, 0, 2);
            world.setBlock(chunkX + 10, j + 3, chunkZ + 7, Blocks.air, 0, 2);
            world.setBlock(chunkX + 11, j + 3, chunkZ + 7, Blocks.air, 0, 2);
            world.setBlock(chunkX + 12, j + 3, chunkZ + 7, Blocks.air, 0, 2);
            world.setBlock(chunkX + 13, j + 3, chunkZ + 7, Blocks.air, 0, 2);
            world.setBlock(chunkX + 14, j + 3, chunkZ + 7, Blocks.stonebrick, 0, 2);
            world.setBlock(chunkX + 0, j + 3, chunkZ + 8, Blocks.stonebrick, 0, 2);
            world.setBlock(chunkX + 1, j + 3, chunkZ + 8, Blocks.stonebrick, 0, 2);
            world.setBlock(chunkX + 2, j + 3, chunkZ + 8, Blocks.stonebrick, 0, 2);
            world.setBlock(chunkX + 3, j + 3, chunkZ + 8, Blocks.stonebrick, 0, 2);
            world.setBlock(chunkX + 4, j + 3, chunkZ + 8, Blocks.stonebrick, 0, 2);
            world.setBlock(chunkX + 5, j + 3, chunkZ + 8, Blocks.stonebrick, 1, 2);
            world.setBlock(chunkX + 6, j + 3, chunkZ + 8, Blocks.stonebrick, 0, 2);
            world.setBlock(chunkX + 7, j + 3, chunkZ + 8, Blocks.stonebrick, 0, 2);
            world.setBlock(chunkX + 8, j + 3, chunkZ + 8, Blocks.stonebrick, 0, 2);
            world.setBlock(chunkX + 9, j + 3, chunkZ + 8, Blocks.stonebrick, 1, 2);
            world.setBlock(chunkX + 10, j + 3, chunkZ + 8, Blocks.stonebrick, 0, 2);
            world.setBlock(chunkX + 11, j + 3, chunkZ + 8, Blocks.stonebrick, 0, 2);
            world.setBlock(chunkX + 12, j + 3, chunkZ + 8, Blocks.stonebrick, 0, 2);
            world.setBlock(chunkX + 13, j + 3, chunkZ + 8, Blocks.stonebrick, 0, 2);
            world.setBlock(chunkX + 14, j + 3, chunkZ + 8, Blocks.stonebrick, 0, 2);
            world.setBlock(chunkX + 0, j + 3, chunkZ + 9, Blocks.air, 0, 2);
            world.setBlock(chunkX + 1, j + 3, chunkZ + 9, Blocks.air, 0, 2);
            world.setBlock(chunkX + 2, j + 3, chunkZ + 9, Blocks.air, 0, 2);
            world.setBlock(chunkX + 3, j + 3, chunkZ + 9, Blocks.air, 0, 2);
            world.setBlock(chunkX + 4, j + 3, chunkZ + 9, Blocks.air, 0, 2);
            world.setBlock(chunkX + 5, j + 3, chunkZ + 9, Blocks.air, 0, 2);
            world.setBlock(chunkX + 6, j + 3, chunkZ + 9, Blocks.air, 0, 2);
            world.setBlock(chunkX + 7, j + 3, chunkZ + 9, Blocks.air, 0, 2);
            world.setBlock(chunkX + 8, j + 3, chunkZ + 9, Blocks.air, 0, 2);
            world.setBlock(chunkX + 9, j + 3, chunkZ + 9, Blocks.air, 0, 2);
            world.setBlock(chunkX + 10, j + 3, chunkZ + 9, Blocks.air, 0, 2);
            world.setBlock(chunkX + 11, j + 3, chunkZ + 9, Blocks.air, 0, 2);
            world.setBlock(chunkX + 12, j + 3, chunkZ + 9, Blocks.air, 0, 2);
            world.setBlock(chunkX + 13, j + 3, chunkZ + 9, Blocks.air, 0, 2);
            world.setBlock(chunkX + 14, j + 3, chunkZ + 9, Blocks.air, 0, 2);
            world.setBlock(chunkX + 0, j + 4, chunkZ + 0, Blocks.stonebrick, 0, 2);
            world.setBlock(chunkX + 1, j + 4, chunkZ + 0, Blocks.stonebrick, 0, 2);
            world.setBlock(chunkX + 2, j + 4, chunkZ + 0, Blocks.stonebrick, 1, 2);
            world.setBlock(chunkX + 3, j + 4, chunkZ + 0, Blocks.stonebrick, 0, 2);
            world.setBlock(chunkX + 4, j + 4, chunkZ + 0, Blocks.stonebrick, 0, 2);
            world.setBlock(chunkX + 5, j + 4, chunkZ + 0, Blocks.stonebrick, 0, 2);
            world.setBlock(chunkX + 6, j + 4, chunkZ + 0, Blocks.stonebrick, 0, 2);
            world.setBlock(chunkX + 7, j + 4, chunkZ + 0, Blocks.stonebrick, 1, 2);
            world.setBlock(chunkX + 8, j + 4, chunkZ + 0, Blocks.stonebrick, 0, 2);
            world.setBlock(chunkX + 9, j + 4, chunkZ + 0, Blocks.stonebrick, 0, 2);
            world.setBlock(chunkX + 10, j + 4, chunkZ + 0, Blocks.stonebrick, 0, 2);
            world.setBlock(chunkX + 11, j + 4, chunkZ + 0, Blocks.stonebrick, 1, 2);
            world.setBlock(chunkX + 12, j + 4, chunkZ + 0, Blocks.stonebrick, 0, 2);
            world.setBlock(chunkX + 13, j + 4, chunkZ + 0, Blocks.stonebrick, 0, 2);
            world.setBlock(chunkX + 14, j + 4, chunkZ + 0, Blocks.stonebrick, 0, 2);
            world.setBlock(chunkX + 0, j + 4, chunkZ + 1, Blocks.stonebrick, 0, 2);
            world.setBlock(chunkX + 1, j + 4, chunkZ + 1, Blocks.stonebrick, 0, 2);
            world.setBlock(chunkX + 2, j + 4, chunkZ + 1, Blocks.stonebrick, 0, 2);
            world.setBlock(chunkX + 3, j + 4, chunkZ + 1, Blocks.stonebrick, 1, 2);
            world.setBlock(chunkX + 4, j + 4, chunkZ + 1, Blocks.stonebrick, 0, 2);
            world.setBlock(chunkX + 5, j + 4, chunkZ + 1, Blocks.stonebrick, 1, 2);
            world.setBlock(chunkX + 6, j + 4, chunkZ + 1, Blocks.stonebrick, 0, 2);
            world.setBlock(chunkX + 7, j + 4, chunkZ + 1, Blocks.stonebrick, 1, 2);
            world.setBlock(chunkX + 8, j + 4, chunkZ + 1, Blocks.stonebrick, 0, 2);
            world.setBlock(chunkX + 9, j + 4, chunkZ + 1, Blocks.stonebrick, 0, 2);
            world.setBlock(chunkX + 10, j + 4, chunkZ + 1, Blocks.stonebrick, 1, 2);
            world.setBlock(chunkX + 11, j + 4, chunkZ + 1, Blocks.stonebrick, 0, 2);
            world.setBlock(chunkX + 12, j + 4, chunkZ + 1, Blocks.stonebrick, 0, 2);
            world.setBlock(chunkX + 13, j + 4, chunkZ + 1, Blocks.stonebrick, 0, 2);
            world.setBlock(chunkX + 14, j + 4, chunkZ + 1, Blocks.stonebrick, 0, 2);
            world.setBlock(chunkX + 0, j + 4, chunkZ + 2, Blocks.stonebrick, 0, 2);
            world.setBlock(chunkX + 1, j + 4, chunkZ + 2, Blocks.stonebrick, 0, 2);
            world.setBlock(chunkX + 2, j + 4, chunkZ + 2, Blocks.stonebrick, 1, 2);
            world.setBlock(chunkX + 3, j + 4, chunkZ + 2, Blocks.stonebrick, 0, 2);
            world.setBlock(chunkX + 4, j + 4, chunkZ + 2, Blocks.stonebrick, 0, 2);
            world.setBlock(chunkX + 5, j + 4, chunkZ + 2, Blocks.stonebrick, 0, 2);
            world.setBlock(chunkX + 6, j + 4, chunkZ + 2, Blocks.stonebrick, 0, 2);
            world.setBlock(chunkX + 7, j + 4, chunkZ + 2, Blocks.stonebrick, 0, 2);
            world.setBlock(chunkX + 8, j + 4, chunkZ + 2, Blocks.stonebrick, 0, 2);
            world.setBlock(chunkX + 9, j + 4, chunkZ + 2, Blocks.stonebrick, 1, 2);
            world.setBlock(chunkX + 10, j + 4, chunkZ + 2, Blocks.stonebrick, 0, 2);
            world.setBlock(chunkX + 11, j + 4, chunkZ + 2, Blocks.stonebrick, 0, 2);
            world.setBlock(chunkX + 12, j + 4, chunkZ + 2, Blocks.stonebrick, 0, 2);
            world.setBlock(chunkX + 13, j + 4, chunkZ + 2, Blocks.stonebrick, 1, 2);
            world.setBlock(chunkX + 14, j + 4, chunkZ + 2, Blocks.stonebrick, 0, 2);
            world.setBlock(chunkX + 0, j + 4, chunkZ + 3, Blocks.stonebrick, 1, 2);
            world.setBlock(chunkX + 1, j + 4, chunkZ + 3, Blocks.stonebrick, 0, 2);
            world.setBlock(chunkX + 2, j + 4, chunkZ + 3, Blocks.stonebrick, 0, 2);
            world.setBlock(chunkX + 3, j + 4, chunkZ + 3, Blocks.stonebrick, 0, 2);
            world.setBlock(chunkX + 4, j + 4, chunkZ + 3, Blocks.stonebrick, 0, 2);
            world.setBlock(chunkX + 5, j + 4, chunkZ + 3, Blocks.stonebrick, 0, 2);
            world.setBlock(chunkX + 6, j + 4, chunkZ + 3, Blocks.stonebrick, 0, 2);
            world.setBlock(chunkX + 7, j + 4, chunkZ + 3, Blocks.stonebrick, 0, 2);
            world.setBlock(chunkX + 8, j + 4, chunkZ + 3, Blocks.stonebrick, 0, 2);
            world.setBlock(chunkX + 9, j + 4, chunkZ + 3, Blocks.stonebrick, 0, 2);
            world.setBlock(chunkX + 10, j + 4, chunkZ + 3, Blocks.stonebrick, 0, 2);
            world.setBlock(chunkX + 11, j + 4, chunkZ + 3, Blocks.stonebrick, 1, 2);
            world.setBlock(chunkX + 12, j + 4, chunkZ + 3, Blocks.stonebrick, 0, 2);
            world.setBlock(chunkX + 13, j + 4, chunkZ + 3, Blocks.stonebrick, 0, 2);
            world.setBlock(chunkX + 14, j + 4, chunkZ + 3, Blocks.stonebrick, 0, 2);
            world.setBlock(chunkX + 0, j + 4, chunkZ + 4, Blocks.stonebrick, 0, 2);
            world.setBlock(chunkX + 1, j + 4, chunkZ + 4, Blocks.stonebrick, 1, 2);
            world.setBlock(chunkX + 2, j + 4, chunkZ + 4, Blocks.stonebrick, 1, 2);
            world.setBlock(chunkX + 3, j + 4, chunkZ + 4, Blocks.stonebrick, 0, 2);
            world.setBlock(chunkX + 4, j + 4, chunkZ + 4, Blocks.stonebrick, 1, 2);
            world.setBlock(chunkX + 5, j + 4, chunkZ + 4, Blocks.stonebrick, 0, 2);
            world.setBlock(chunkX + 6, j + 4, chunkZ + 4, Blocks.stonebrick, 0, 2);
            world.setBlock(chunkX + 7, j + 4, chunkZ + 4, Blocks.stonebrick, 1, 2);
            world.setBlock(chunkX + 8, j + 4, chunkZ + 4, Blocks.stonebrick, 1, 2);
            world.setBlock(chunkX + 9, j + 4, chunkZ + 4, Blocks.stonebrick, 0, 2);
            world.setBlock(chunkX + 10, j + 4, chunkZ + 4, Blocks.stonebrick, 0, 2);
            world.setBlock(chunkX + 11, j + 4, chunkZ + 4, Blocks.stonebrick, 0, 2);
            world.setBlock(chunkX + 12, j + 4, chunkZ + 4, Blocks.stonebrick, 0, 2);
            world.setBlock(chunkX + 13, j + 4, chunkZ + 4, Blocks.stonebrick, 0, 2);
            world.setBlock(chunkX + 14, j + 4, chunkZ + 4, Blocks.stonebrick, 0, 2);
            world.setBlock(chunkX + 0, j + 4, chunkZ + 5, Blocks.stonebrick, 0, 2);
            world.setBlock(chunkX + 1, j + 4, chunkZ + 5, Blocks.stonebrick, 0, 2);
            world.setBlock(chunkX + 2, j + 4, chunkZ + 5, Blocks.air, 0, 2);
            world.setBlock(chunkX + 3, j + 4, chunkZ + 5, Blocks.stonebrick, 0, 2);
            world.setBlock(chunkX + 4, j + 4, chunkZ + 5, Blocks.stonebrick, 0, 2);
            world.setBlock(chunkX + 5, j + 4, chunkZ + 5, Blocks.stonebrick, 0, 2);
            world.setBlock(chunkX + 6, j + 4, chunkZ + 5, Blocks.stonebrick, 1, 2);
            world.setBlock(chunkX + 7, j + 4, chunkZ + 5, Blocks.stonebrick, 0, 2);
            world.setBlock(chunkX + 8, j + 4, chunkZ + 5, Blocks.stonebrick, 0, 2);
            world.setBlock(chunkX + 9, j + 4, chunkZ + 5, Blocks.stonebrick, 0, 2);
            world.setBlock(chunkX + 10, j + 4, chunkZ + 5, Blocks.stonebrick, 0, 2);
            world.setBlock(chunkX + 11, j + 4, chunkZ + 5, Blocks.stonebrick, 1, 2);
            world.setBlock(chunkX + 12, j + 4, chunkZ + 5, Blocks.stonebrick, 0, 2);
            world.setBlock(chunkX + 13, j + 4, chunkZ + 5, Blocks.stonebrick, 0, 2);
            world.setBlock(chunkX + 14, j + 4, chunkZ + 5, Blocks.stonebrick, 1, 2);
            world.setBlock(chunkX + 0, j + 4, chunkZ + 6, Blocks.stonebrick, 0, 2);
            world.setBlock(chunkX + 1, j + 4, chunkZ + 6, Blocks.stonebrick, 0, 2);
            world.setBlock(chunkX + 2, j + 4, chunkZ + 6, Blocks.stonebrick, 0, 2);
            world.setBlock(chunkX + 3, j + 4, chunkZ + 6, Blocks.stonebrick, 0, 2);
            world.setBlock(chunkX + 4, j + 4, chunkZ + 6, Blocks.stonebrick, 1, 2);
            world.setBlock(chunkX + 5, j + 4, chunkZ + 6, Blocks.stonebrick, 0, 2);
            world.setBlock(chunkX + 6, j + 4, chunkZ + 6, Blocks.stonebrick, 0, 2);
            world.setBlock(chunkX + 7, j + 4, chunkZ + 6, Blocks.stonebrick, 0, 2);
            world.setBlock(chunkX + 8, j + 4, chunkZ + 6, Blocks.stonebrick, 0, 2);
            world.setBlock(chunkX + 9, j + 4, chunkZ + 6, Blocks.stonebrick, 0, 2);
            world.setBlock(chunkX + 10, j + 4, chunkZ + 6, Blocks.stonebrick, 0, 2);
            world.setBlock(chunkX + 11, j + 4, chunkZ + 6, Blocks.stonebrick, 0, 2);
            world.setBlock(chunkX + 12, j + 4, chunkZ + 6, Blocks.stonebrick, 0, 2);
            world.setBlock(chunkX + 13, j + 4, chunkZ + 6, Blocks.stonebrick, 0, 2);
            world.setBlock(chunkX + 14, j + 4, chunkZ + 6, Blocks.stonebrick, 0, 2);
            world.setBlock(chunkX + 0, j + 4, chunkZ + 7, Blocks.stonebrick, 0, 2);
            world.setBlock(chunkX + 1, j + 4, chunkZ + 7, Blocks.stonebrick, 0, 2);
            world.setBlock(chunkX + 2, j + 4, chunkZ + 7, Blocks.stonebrick, 0, 2);
            world.setBlock(chunkX + 3, j + 4, chunkZ + 7, Blocks.stonebrick, 1, 2);
            world.setBlock(chunkX + 4, j + 4, chunkZ + 7, Blocks.stonebrick, 0, 2);
            world.setBlock(chunkX + 5, j + 4, chunkZ + 7, Blocks.stonebrick, 0, 2);
            world.setBlock(chunkX + 6, j + 4, chunkZ + 7, Blocks.stonebrick, 0, 2);
            world.setBlock(chunkX + 7, j + 4, chunkZ + 7, Blocks.stonebrick, 0, 2);
            world.setBlock(chunkX + 8, j + 4, chunkZ + 7, Blocks.stonebrick, 1, 2);
            world.setBlock(chunkX + 9, j + 4, chunkZ + 7, Blocks.stonebrick, 0, 2);
            world.setBlock(chunkX + 10, j + 4, chunkZ + 7, Blocks.stonebrick, 0, 2);
            world.setBlock(chunkX + 11, j + 4, chunkZ + 7, Blocks.stonebrick, 1, 2);
            world.setBlock(chunkX + 12, j + 4, chunkZ + 7, Blocks.stonebrick, 1, 2);
            world.setBlock(chunkX + 13, j + 4, chunkZ + 7, Blocks.stonebrick, 1, 2);
            world.setBlock(chunkX + 14, j + 4, chunkZ + 7, Blocks.stonebrick, 0, 2);
            world.setBlock(chunkX + 0, j + 4, chunkZ + 8, Blocks.stonebrick, 0, 2);
            world.setBlock(chunkX + 1, j + 4, chunkZ + 8, Blocks.stonebrick, 0, 2);
            world.setBlock(chunkX + 2, j + 4, chunkZ + 8, Blocks.stonebrick, 1, 2);
            world.setBlock(chunkX + 3, j + 4, chunkZ + 8, Blocks.stonebrick, 0, 2);
            world.setBlock(chunkX + 4, j + 4, chunkZ + 8, Blocks.stonebrick, 0, 2);
            world.setBlock(chunkX + 5, j + 4, chunkZ + 8, Blocks.stonebrick, 0, 2);
            world.setBlock(chunkX + 6, j + 4, chunkZ + 8, Blocks.stonebrick, 0, 2);
            world.setBlock(chunkX + 7, j + 4, chunkZ + 8, Blocks.stonebrick, 0, 2);
            world.setBlock(chunkX + 8, j + 4, chunkZ + 8, Blocks.stonebrick, 0, 2);
            world.setBlock(chunkX + 9, j + 4, chunkZ + 8, Blocks.stonebrick, 0, 2);
            world.setBlock(chunkX + 10, j + 4, chunkZ + 8, Blocks.stonebrick, 1, 2);
            world.setBlock(chunkX + 11, j + 4, chunkZ + 8, Blocks.stonebrick, 0, 2);
            world.setBlock(chunkX + 12, j + 4, chunkZ + 8, Blocks.stonebrick, 0, 2);
            world.setBlock(chunkX + 13, j + 4, chunkZ + 8, Blocks.stonebrick, 0, 2);
            world.setBlock(chunkX + 14, j + 4, chunkZ + 8, Blocks.stonebrick, 0, 2);
            world.setBlock(chunkX + 0, j + 4, chunkZ + 9, Blocks.air, 0, 2);
            world.setBlock(chunkX + 1, j + 4, chunkZ + 9, Blocks.air, 0, 2);
            world.setBlock(chunkX + 2, j + 4, chunkZ + 9, Blocks.air, 0, 2);
            world.setBlock(chunkX + 3, j + 4, chunkZ + 9, Blocks.air, 0, 2);
            world.setBlock(chunkX + 4, j + 4, chunkZ + 9, Blocks.air, 0, 2);
            world.setBlock(chunkX + 5, j + 4, chunkZ + 9, Blocks.air, 0, 2);
            world.setBlock(chunkX + 6, j + 4, chunkZ + 9, Blocks.air, 0, 2);
            world.setBlock(chunkX + 7, j + 4, chunkZ + 9, Blocks.air, 0, 2);
            world.setBlock(chunkX + 8, j + 4, chunkZ + 9, Blocks.air, 0, 2);
            world.setBlock(chunkX + 9, j + 4, chunkZ + 9, Blocks.air, 0, 2);
            world.setBlock(chunkX + 10, j + 4, chunkZ + 9, Blocks.air, 0, 2);
            world.setBlock(chunkX + 11, j + 4, chunkZ + 9, Blocks.air, 0, 2);
            world.setBlock(chunkX + 12, j + 4, chunkZ + 9, Blocks.air, 0, 2);
            world.setBlock(chunkX + 13, j + 4, chunkZ + 9, Blocks.air, 0, 2);
            world.setBlock(chunkX + 14, j + 4, chunkZ + 9, Blocks.air, 0, 2);
            world.setBlock(chunkX + 0, j + 5, chunkZ + 0, Blocks.air, 0, 2);
            world.setBlock(chunkX + 1, j + 5, chunkZ + 0, Blocks.air, 0, 2);
            world.setBlock(chunkX + 2, j + 5, chunkZ + 0, Blocks.air, 0, 2);
            world.setBlock(chunkX + 3, j + 5, chunkZ + 0, Blocks.air, 0, 2);
            world.setBlock(chunkX + 4, j + 5, chunkZ + 0, Blocks.air, 0, 2);
            world.setBlock(chunkX + 5, j + 5, chunkZ + 0, Blocks.air, 0, 2);
            world.setBlock(chunkX + 6, j + 5, chunkZ + 0, Blocks.air, 0, 2);
            world.setBlock(chunkX + 7, j + 5, chunkZ + 0, Blocks.air, 0, 2);
            world.setBlock(chunkX + 8, j + 5, chunkZ + 0, Blocks.air, 0, 2);
            world.setBlock(chunkX + 9, j + 5, chunkZ + 0, Blocks.air, 0, 2);
            world.setBlock(chunkX + 10, j + 5, chunkZ + 0, Blocks.air, 0, 2);
            world.setBlock(chunkX + 11, j + 5, chunkZ + 0, Blocks.air, 0, 2);
            world.setBlock(chunkX + 12, j + 5, chunkZ + 0, Blocks.air, 0, 2);
            world.setBlock(chunkX + 13, j + 5, chunkZ + 0, Blocks.air, 0, 2);
            world.setBlock(chunkX + 14, j + 5, chunkZ + 0, Blocks.air, 0, 2);
            world.setBlock(chunkX + 0, j + 5, chunkZ + 1, Blocks.air, 0, 2);
            world.setBlock(chunkX + 1, j + 5, chunkZ + 1, Blocks.air, 0, 2);
            world.setBlock(chunkX + 2, j + 5, chunkZ + 1, Blocks.air, 0, 2);
            world.setBlock(chunkX + 3, j + 5, chunkZ + 1, Blocks.air, 0, 2);
            world.setBlock(chunkX + 4, j + 5, chunkZ + 1, Blocks.air, 0, 2);
            world.setBlock(chunkX + 5, j + 5, chunkZ + 1, Blocks.air, 0, 2);
            world.setBlock(chunkX + 6, j + 5, chunkZ + 1, Blocks.air, 0, 2);
            world.setBlock(chunkX + 7, j + 5, chunkZ + 1, Blocks.air, 0, 2);
            world.setBlock(chunkX + 8, j + 5, chunkZ + 1, Blocks.air, 0, 2);
            world.setBlock(chunkX + 9, j + 5, chunkZ + 1, Blocks.air, 0, 2);
            world.setBlock(chunkX + 10, j + 5, chunkZ + 1, Blocks.air, 0, 2);
            world.setBlock(chunkX + 11, j + 5, chunkZ + 1, Blocks.air, 0, 2);
            world.setBlock(chunkX + 12, j + 5, chunkZ + 1, Blocks.air, 0, 2);
            world.setBlock(chunkX + 13, j + 5, chunkZ + 1, Blocks.air, 0, 2);
            world.setBlock(chunkX + 14, j + 5, chunkZ + 1, Blocks.air, 0, 2);
            world.setBlock(chunkX + 0, j + 5, chunkZ + 2, Blocks.air, 0, 2);
            world.setBlock(chunkX + 1, j + 5, chunkZ + 2, Blocks.air, 0, 2);
            world.setBlock(chunkX + 2, j + 5, chunkZ + 2, Blocks.air, 0, 2);
            world.setBlock(chunkX + 3, j + 5, chunkZ + 2, Blocks.air, 0, 2);
            world.setBlock(chunkX + 4, j + 5, chunkZ + 2, Blocks.air, 0, 2);
            world.setBlock(chunkX + 5, j + 5, chunkZ + 2, Blocks.air, 0, 2);
            world.setBlock(chunkX + 6, j + 5, chunkZ + 2, Blocks.air, 0, 2);
            world.setBlock(chunkX + 7, j + 5, chunkZ + 2, Blocks.air, 0, 2);
            world.setBlock(chunkX + 8, j + 5, chunkZ + 2, Blocks.air, 0, 2);
            world.setBlock(chunkX + 9, j + 5, chunkZ + 2, Blocks.air, 0, 2);
            world.setBlock(chunkX + 10, j + 5, chunkZ + 2, Blocks.air, 0, 2);
            world.setBlock(chunkX + 11, j + 5, chunkZ + 2, Blocks.air, 0, 2);
            world.setBlock(chunkX + 12, j + 5, chunkZ + 2, Blocks.air, 0, 2);
            world.setBlock(chunkX + 13, j + 5, chunkZ + 2, Blocks.air, 0, 2);
            world.setBlock(chunkX + 14, j + 5, chunkZ + 2, Blocks.air, 0, 2);
            world.setBlock(chunkX + 0, j + 5, chunkZ + 3, Blocks.air, 0, 2);
            world.setBlock(chunkX + 1, j + 5, chunkZ + 3, Blocks.air, 0, 2);
            world.setBlock(chunkX + 2, j + 5, chunkZ + 3, Blocks.air, 0, 2);
            world.setBlock(chunkX + 3, j + 5, chunkZ + 3, Blocks.air, 0, 2);
            world.setBlock(chunkX + 4, j + 5, chunkZ + 3, Blocks.air, 0, 2);
            world.setBlock(chunkX + 5, j + 5, chunkZ + 3, Blocks.air, 0, 2);
            world.setBlock(chunkX + 6, j + 5, chunkZ + 3, Blocks.air, 0, 2);
            world.setBlock(chunkX + 7, j + 5, chunkZ + 3, Blocks.air, 0, 2);
            world.setBlock(chunkX + 8, j + 5, chunkZ + 3, Blocks.air, 0, 2);
            world.setBlock(chunkX + 9, j + 5, chunkZ + 3, Blocks.air, 0, 2);
            world.setBlock(chunkX + 10, j + 5, chunkZ + 3, Blocks.air, 0, 2);
            world.setBlock(chunkX + 11, j + 5, chunkZ + 3, Blocks.air, 0, 2);
            world.setBlock(chunkX + 12, j + 5, chunkZ + 3, Blocks.air, 0, 2);
            world.setBlock(chunkX + 13, j + 5, chunkZ + 3, Blocks.air, 0, 2);
            world.setBlock(chunkX + 14, j + 5, chunkZ + 3, Blocks.air, 0, 2);
            world.setBlock(chunkX + 0, j + 5, chunkZ + 4, Blocks.air, 0, 2);
            world.setBlock(chunkX + 1, j + 5, chunkZ + 4, Blocks.air, 0, 2);
            world.setBlock(chunkX + 2, j + 5, chunkZ + 4, Blocks.stonebrick, 0, 2);
            world.setBlock(chunkX + 3, j + 5, chunkZ + 4, Blocks.stonebrick, 0, 2);
            world.setBlock(chunkX + 4, j + 5, chunkZ + 4, Blocks.stonebrick, 0, 2);
            world.setBlock(chunkX + 5, j + 5, chunkZ + 4, Blocks.stonebrick, 0, 2);
            world.setBlock(chunkX + 6, j + 5, chunkZ + 4, Blocks.stonebrick, 0, 2);
            world.setBlock(chunkX + 7, j + 5, chunkZ + 4, Blocks.stonebrick, 0, 2);
            world.setBlock(chunkX + 8, j + 5, chunkZ + 4, Blocks.air, 0, 2);
            world.setBlock(chunkX + 9, j + 5, chunkZ + 4, Blocks.air, 0, 2);
            world.setBlock(chunkX + 10, j + 5, chunkZ + 4, Blocks.air, 0, 2);
            world.setBlock(chunkX + 11, j + 5, chunkZ + 4, Blocks.air, 0, 2);
            world.setBlock(chunkX + 12, j + 5, chunkZ + 4, Blocks.air, 0, 2);
            world.setBlock(chunkX + 13, j + 5, chunkZ + 4, Blocks.air, 0, 2);
            world.setBlock(chunkX + 14, j + 5, chunkZ + 4, Blocks.air, 0, 2);
            world.setBlock(chunkX + 0, j + 5, chunkZ + 5, Blocks.air, 0, 2);
            world.setBlock(chunkX + 1, j + 5, chunkZ + 5, Blocks.stonebrick, 0, 2);
            world.setBlock(chunkX + 2, j + 5, chunkZ + 5, Blocks.air, 0, 2);
            world.setBlock(chunkX + 3, j + 5, chunkZ + 5, Blocks.air, 0, 2);
            world.setBlock(chunkX + 4, j + 5, chunkZ + 5, Blocks.air, 0, 2);
            world.setBlock(chunkX + 5, j + 5, chunkZ + 5, Blocks.air, 0, 2);
            world.setBlock(chunkX + 6, j + 5, chunkZ + 5, Blocks.air, 0, 2);
            world.setBlock(chunkX + 7, j + 5, chunkZ + 5, Blocks.ladder, 4, 2);
            world.setBlock(chunkX + 8, j + 5, chunkZ + 5, Blocks.stonebrick, 0, 2);
            world.setBlock(chunkX + 9, j + 5, chunkZ + 5, Blocks.air, 0, 2);
            world.setBlock(chunkX + 10, j + 5, chunkZ + 5, Blocks.air, 0, 2);
            world.setBlock(chunkX + 11, j + 5, chunkZ + 5, Blocks.air, 0, 2);
            world.setBlock(chunkX + 12, j + 5, chunkZ + 5, Blocks.air, 0, 2);
            world.setBlock(chunkX + 13, j + 5, chunkZ + 5, Blocks.air, 0, 2);
            world.setBlock(chunkX + 14, j + 5, chunkZ + 5, Blocks.air, 0, 2);
            world.setBlock(chunkX + 0, j + 5, chunkZ + 6, Blocks.air, 0, 2);
            world.setBlock(chunkX + 1, j + 5, chunkZ + 6, Blocks.air, 0, 2);
            world.setBlock(chunkX + 2, j + 5, chunkZ + 6, Blocks.stonebrick, 0, 2);
            world.setBlock(chunkX + 3, j + 5, chunkZ + 6, Blocks.stonebrick, 0, 2);
            world.setBlock(chunkX + 4, j + 5, chunkZ + 6, Blocks.stonebrick, 0, 2);
            world.setBlock(chunkX + 5, j + 5, chunkZ + 6, Blocks.stonebrick, 0, 2);
            world.setBlock(chunkX + 6, j + 5, chunkZ + 6, Blocks.stonebrick, 0, 2);
            world.setBlock(chunkX + 7, j + 5, chunkZ + 6, Blocks.stonebrick, 0, 2);
            world.setBlock(chunkX + 8, j + 5, chunkZ + 6, Blocks.air, 0, 2);
            world.setBlock(chunkX + 9, j + 5, chunkZ + 6, Blocks.air, 0, 2);
            world.setBlock(chunkX + 10, j + 5, chunkZ + 6, Blocks.air, 0, 2);
            world.setBlock(chunkX + 11, j + 5, chunkZ + 6, Blocks.air, 0, 2);
            world.setBlock(chunkX + 12, j + 5, chunkZ + 6, Blocks.air, 0, 2);
            world.setBlock(chunkX + 13, j + 5, chunkZ + 6, Blocks.air, 0, 2);
            world.setBlock(chunkX + 14, j + 5, chunkZ + 6, Blocks.air, 0, 2);
            world.setBlock(chunkX + 0, j + 5, chunkZ + 7, Blocks.air, 0, 2);
            world.setBlock(chunkX + 1, j + 5, chunkZ + 7, Blocks.air, 0, 2);
            world.setBlock(chunkX + 2, j + 5, chunkZ + 7, Blocks.air, 0, 2);
            world.setBlock(chunkX + 3, j + 5, chunkZ + 7, Blocks.air, 0, 2);
            world.setBlock(chunkX + 4, j + 5, chunkZ + 7, Blocks.air, 0, 2);
            world.setBlock(chunkX + 5, j + 5, chunkZ + 7, Blocks.air, 0, 2);
            world.setBlock(chunkX + 6, j + 5, chunkZ + 7, Blocks.air, 0, 2);
            world.setBlock(chunkX + 7, j + 5, chunkZ + 7, Blocks.air, 0, 2);
            world.setBlock(chunkX + 8, j + 5, chunkZ + 7, Blocks.air, 0, 2);
            world.setBlock(chunkX + 9, j + 5, chunkZ + 7, Blocks.air, 0, 2);
            world.setBlock(chunkX + 10, j + 5, chunkZ + 7, Blocks.air, 0, 2);
            world.setBlock(chunkX + 11, j + 5, chunkZ + 7, Blocks.air, 0, 2);
            world.setBlock(chunkX + 12, j + 5, chunkZ + 7, Blocks.air, 0, 2);
            world.setBlock(chunkX + 13, j + 5, chunkZ + 7, Blocks.air, 0, 2);
            world.setBlock(chunkX + 14, j + 5, chunkZ + 7, Blocks.air, 0, 2);
            world.setBlock(chunkX + 0, j + 5, chunkZ + 8, Blocks.air, 0, 2);
            world.setBlock(chunkX + 1, j + 5, chunkZ + 8, Blocks.air, 0, 2);
            world.setBlock(chunkX + 2, j + 5, chunkZ + 8, Blocks.air, 0, 2);
            world.setBlock(chunkX + 3, j + 5, chunkZ + 8, Blocks.air, 0, 2);
            world.setBlock(chunkX + 4, j + 5, chunkZ + 8, Blocks.air, 0, 2);
            world.setBlock(chunkX + 5, j + 5, chunkZ + 8, Blocks.air, 0, 2);
            world.setBlock(chunkX + 6, j + 5, chunkZ + 8, Blocks.air, 0, 2);
            world.setBlock(chunkX + 7, j + 5, chunkZ + 8, Blocks.air, 0, 2);
            world.setBlock(chunkX + 8, j + 5, chunkZ + 8, Blocks.air, 0, 2);
            world.setBlock(chunkX + 9, j + 5, chunkZ + 8, Blocks.air, 0, 2);
            world.setBlock(chunkX + 10, j + 5, chunkZ + 8, Blocks.air, 0, 2);
            world.setBlock(chunkX + 11, j + 5, chunkZ + 8, Blocks.air, 0, 2);
            world.setBlock(chunkX + 12, j + 5, chunkZ + 8, Blocks.air, 0, 2);
            world.setBlock(chunkX + 13, j + 5, chunkZ + 8, Blocks.air, 0, 2);
            world.setBlock(chunkX + 14, j + 5, chunkZ + 8, Blocks.air, 0, 2);
            world.setBlock(chunkX + 0, j + 5, chunkZ + 9, Blocks.air, 0, 2);
            world.setBlock(chunkX + 1, j + 5, chunkZ + 9, Blocks.air, 0, 2);
            world.setBlock(chunkX + 2, j + 5, chunkZ + 9, Blocks.air, 0, 2);
            world.setBlock(chunkX + 3, j + 5, chunkZ + 9, Blocks.air, 0, 2);
            world.setBlock(chunkX + 4, j + 5, chunkZ + 9, Blocks.air, 0, 2);
            world.setBlock(chunkX + 5, j + 5, chunkZ + 9, Blocks.air, 0, 2);
            world.setBlock(chunkX + 6, j + 5, chunkZ + 9, Blocks.air, 0, 2);
            world.setBlock(chunkX + 7, j + 5, chunkZ + 9, Blocks.air, 0, 2);
            world.setBlock(chunkX + 8, j + 5, chunkZ + 9, Blocks.air, 0, 2);
            world.setBlock(chunkX + 9, j + 5, chunkZ + 9, Blocks.air, 0, 2);
            world.setBlock(chunkX + 10, j + 5, chunkZ + 9, Blocks.air, 0, 2);
            world.setBlock(chunkX + 11, j + 5, chunkZ + 9, Blocks.air, 0, 2);
            world.setBlock(chunkX + 12, j + 5, chunkZ + 9, Blocks.air, 0, 2);
            world.setBlock(chunkX + 13, j + 5, chunkZ + 9, Blocks.air, 0, 2);
            world.setBlock(chunkX + 14, j + 5, chunkZ + 9, Blocks.air, 0, 2);
            world.setBlock(chunkX + 0, j + 6, chunkZ + 0, Blocks.air, 0, 2);
            world.setBlock(chunkX + 1, j + 6, chunkZ + 0, Blocks.air, 0, 2);
            world.setBlock(chunkX + 2, j + 6, chunkZ + 0, Blocks.air, 0, 2);
            world.setBlock(chunkX + 3, j + 6, chunkZ + 0, Blocks.air, 0, 2);
            world.setBlock(chunkX + 4, j + 6, chunkZ + 0, Blocks.air, 0, 2);
            world.setBlock(chunkX + 5, j + 6, chunkZ + 0, Blocks.air, 0, 2);
            world.setBlock(chunkX + 6, j + 6, chunkZ + 0, Blocks.air, 0, 2);
            world.setBlock(chunkX + 7, j + 6, chunkZ + 0, Blocks.air, 0, 2);
            world.setBlock(chunkX + 8, j + 6, chunkZ + 0, Blocks.air, 0, 2);
            world.setBlock(chunkX + 9, j + 6, chunkZ + 0, Blocks.air, 0, 2);
            world.setBlock(chunkX + 10, j + 6, chunkZ + 0, Blocks.air, 0, 2);
            world.setBlock(chunkX + 11, j + 6, chunkZ + 0, Blocks.air, 0, 2);
            world.setBlock(chunkX + 12, j + 6, chunkZ + 0, Blocks.air, 0, 2);
            world.setBlock(chunkX + 13, j + 6, chunkZ + 0, Blocks.air, 0, 2);
            world.setBlock(chunkX + 14, j + 6, chunkZ + 0, Blocks.air, 0, 2);
            world.setBlock(chunkX + 0, j + 6, chunkZ + 1, Blocks.air, 0, 2);
            world.setBlock(chunkX + 1, j + 6, chunkZ + 1, Blocks.air, 0, 2);
            world.setBlock(chunkX + 2, j + 6, chunkZ + 1, Blocks.air, 0, 2);
            world.setBlock(chunkX + 3, j + 6, chunkZ + 1, Blocks.air, 0, 2);
            world.setBlock(chunkX + 4, j + 6, chunkZ + 1, Blocks.air, 0, 2);
            world.setBlock(chunkX + 5, j + 6, chunkZ + 1, Blocks.air, 0, 2);
            world.setBlock(chunkX + 6, j + 6, chunkZ + 1, Blocks.air, 0, 2);
            world.setBlock(chunkX + 7, j + 6, chunkZ + 1, Blocks.air, 0, 2);
            world.setBlock(chunkX + 8, j + 6, chunkZ + 1, Blocks.air, 0, 2);
            world.setBlock(chunkX + 9, j + 6, chunkZ + 1, Blocks.air, 0, 2);
            world.setBlock(chunkX + 10, j + 6, chunkZ + 1, Blocks.air, 0, 2);
            world.setBlock(chunkX + 11, j + 6, chunkZ + 1, Blocks.air, 0, 2);
            world.setBlock(chunkX + 12, j + 6, chunkZ + 1, Blocks.air, 0, 2);
            world.setBlock(chunkX + 13, j + 6, chunkZ + 1, Blocks.air, 0, 2);
            world.setBlock(chunkX + 14, j + 6, chunkZ + 1, Blocks.air, 0, 2);
            world.setBlock(chunkX + 0, j + 6, chunkZ + 2, Blocks.air, 0, 2);
            world.setBlock(chunkX + 1, j + 6, chunkZ + 2, Blocks.air, 0, 2);
            world.setBlock(chunkX + 2, j + 6, chunkZ + 2, Blocks.air, 0, 2);
            world.setBlock(chunkX + 3, j + 6, chunkZ + 2, Blocks.air, 0, 2);
            world.setBlock(chunkX + 4, j + 6, chunkZ + 2, Blocks.air, 0, 2);
            world.setBlock(chunkX + 5, j + 6, chunkZ + 2, Blocks.air, 0, 2);
            world.setBlock(chunkX + 6, j + 6, chunkZ + 2, Blocks.air, 0, 2);
            world.setBlock(chunkX + 7, j + 6, chunkZ + 2, Blocks.air, 0, 2);
            world.setBlock(chunkX + 8, j + 6, chunkZ + 2, Blocks.air, 0, 2);
            world.setBlock(chunkX + 9, j + 6, chunkZ + 2, Blocks.air, 0, 2);
            world.setBlock(chunkX + 10, j + 6, chunkZ + 2, Blocks.air, 0, 2);
            world.setBlock(chunkX + 11, j + 6, chunkZ + 2, Blocks.air, 0, 2);
            world.setBlock(chunkX + 12, j + 6, chunkZ + 2, Blocks.air, 0, 2);
            world.setBlock(chunkX + 13, j + 6, chunkZ + 2, Blocks.air, 0, 2);
            world.setBlock(chunkX + 14, j + 6, chunkZ + 2, Blocks.air, 0, 2);
            world.setBlock(chunkX + 0, j + 6, chunkZ + 3, Blocks.air, 0, 2);
            world.setBlock(chunkX + 1, j + 6, chunkZ + 3, Blocks.air, 0, 2);
            world.setBlock(chunkX + 2, j + 6, chunkZ + 3, Blocks.air, 0, 2);
            world.setBlock(chunkX + 3, j + 6, chunkZ + 3, Blocks.air, 0, 2);
            world.setBlock(chunkX + 4, j + 6, chunkZ + 3, Blocks.air, 0, 2);
            world.setBlock(chunkX + 5, j + 6, chunkZ + 3, Blocks.air, 0, 2);
            world.setBlock(chunkX + 6, j + 6, chunkZ + 3, Blocks.air, 0, 2);
            world.setBlock(chunkX + 7, j + 6, chunkZ + 3, Blocks.air, 0, 2);
            world.setBlock(chunkX + 8, j + 6, chunkZ + 3, Blocks.air, 0, 2);
            world.setBlock(chunkX + 9, j + 6, chunkZ + 3, Blocks.air, 0, 2);
            world.setBlock(chunkX + 10, j + 6, chunkZ + 3, Blocks.air, 0, 2);
            world.setBlock(chunkX + 11, j + 6, chunkZ + 3, Blocks.air, 0, 2);
            world.setBlock(chunkX + 12, j + 6, chunkZ + 3, Blocks.air, 0, 2);
            world.setBlock(chunkX + 13, j + 6, chunkZ + 3, Blocks.air, 0, 2);
            world.setBlock(chunkX + 14, j + 6, chunkZ + 3, Blocks.air, 0, 2);
            world.setBlock(chunkX + 0, j + 6, chunkZ + 4, Blocks.air, 0, 2);
            world.setBlock(chunkX + 1, j + 6, chunkZ + 4, Blocks.air, 0, 2);
            world.setBlock(chunkX + 2, j + 6, chunkZ + 4, Blocks.stonebrick, 0, 2);
            world.setBlock(chunkX + 3, j + 6, chunkZ + 4, Blocks.stonebrick, 0, 2);
            world.setBlock(chunkX + 4, j + 6, chunkZ + 4, Blocks.stonebrick, 0, 2);
            world.setBlock(chunkX + 5, j + 6, chunkZ + 4, Blocks.stonebrick, 0, 2);
            world.setBlock(chunkX + 6, j + 6, chunkZ + 4, Blocks.stonebrick, 0, 2);
            world.setBlock(chunkX + 7, j + 6, chunkZ + 4, Blocks.stonebrick, 0, 2);
            world.setBlock(chunkX + 8, j + 6, chunkZ + 4, Blocks.air, 0, 2);
            world.setBlock(chunkX + 9, j + 6, chunkZ + 4, Blocks.air, 0, 2);
            world.setBlock(chunkX + 10, j + 6, chunkZ + 4, Blocks.air, 0, 2);
            world.setBlock(chunkX + 11, j + 6, chunkZ + 4, Blocks.air, 0, 2);
            world.setBlock(chunkX + 12, j + 6, chunkZ + 4, Blocks.air, 0, 2);
            world.setBlock(chunkX + 13, j + 6, chunkZ + 4, Blocks.air, 0, 2);
            world.setBlock(chunkX + 14, j + 6, chunkZ + 4, Blocks.air, 0, 2);
            world.setBlock(chunkX + 0, j + 6, chunkZ + 5, Blocks.air, 0, 2);
            world.setBlock(chunkX + 1, j + 6, chunkZ + 5, Blocks.stonebrick, 0, 2);
            world.setBlock(chunkX + 2, j + 6, chunkZ + 5, Blocks.air, 0, 2);
            world.setBlock(chunkX + 3, j + 6, chunkZ + 5, Blocks.air, 0, 2);
            world.setBlock(chunkX + 4, j + 6, chunkZ + 5, Blocks.air, 0, 2);
            world.setBlock(chunkX + 5, j + 6, chunkZ + 5, Blocks.air, 0, 2);
            world.setBlock(chunkX + 6, j + 6, chunkZ + 5, Blocks.air, 0, 2);
            world.setBlock(chunkX + 7, j + 6, chunkZ + 5, Blocks.ladder, 4, 2);
            world.setBlock(chunkX + 8, j + 6, chunkZ + 5, Blocks.stonebrick, 0, 2);
            world.setBlock(chunkX + 9, j + 6, chunkZ + 5, Blocks.air, 0, 2);
            world.setBlock(chunkX + 10, j + 6, chunkZ + 5, Blocks.air, 0, 2);
            world.setBlock(chunkX + 11, j + 6, chunkZ + 5, Blocks.air, 0, 2);
            world.setBlock(chunkX + 12, j + 6, chunkZ + 5, Blocks.air, 0, 2);
            world.setBlock(chunkX + 13, j + 6, chunkZ + 5, Blocks.air, 0, 2);
            world.setBlock(chunkX + 14, j + 6, chunkZ + 5, Blocks.air, 0, 2);
            world.setBlock(chunkX + 0, j + 6, chunkZ + 6, Blocks.air, 0, 2);
            world.setBlock(chunkX + 1, j + 6, chunkZ + 6, Blocks.air, 0, 2);
            world.setBlock(chunkX + 2, j + 6, chunkZ + 6, Blocks.stonebrick, 0, 2);
            world.setBlock(chunkX + 3, j + 6, chunkZ + 6, Blocks.stonebrick, 0, 2);
            world.setBlock(chunkX + 4, j + 6, chunkZ + 6, Blocks.stonebrick, 0, 2);
            world.setBlock(chunkX + 5, j + 6, chunkZ + 6, Blocks.stonebrick, 0, 2);
            world.setBlock(chunkX + 6, j + 6, chunkZ + 6, Blocks.stonebrick, 0, 2);
            world.setBlock(chunkX + 7, j + 6, chunkZ + 6, Blocks.stonebrick, 0, 2);
            world.setBlock(chunkX + 8, j + 6, chunkZ + 6, Blocks.air, 0, 2);
            world.setBlock(chunkX + 9, j + 6, chunkZ + 6, Blocks.air, 0, 2);
            world.setBlock(chunkX + 10, j + 6, chunkZ + 6, Blocks.air, 0, 2);
            world.setBlock(chunkX + 11, j + 6, chunkZ + 6, Blocks.air, 0, 2);
            world.setBlock(chunkX + 12, j + 6, chunkZ + 6, Blocks.air, 0, 2);
            world.setBlock(chunkX + 13, j + 6, chunkZ + 6, Blocks.air, 0, 2);
            world.setBlock(chunkX + 14, j + 6, chunkZ + 6, Blocks.air, 0, 2);
            world.setBlock(chunkX + 0, j + 6, chunkZ + 7, Blocks.air, 0, 2);
            world.setBlock(chunkX + 1, j + 6, chunkZ + 7, Blocks.air, 0, 2);
            world.setBlock(chunkX + 2, j + 6, chunkZ + 7, Blocks.air, 0, 2);
            world.setBlock(chunkX + 3, j + 6, chunkZ + 7, Blocks.air, 0, 2);
            world.setBlock(chunkX + 4, j + 6, chunkZ + 7, Blocks.air, 0, 2);
            world.setBlock(chunkX + 5, j + 6, chunkZ + 7, Blocks.air, 0, 2);
            world.setBlock(chunkX + 6, j + 6, chunkZ + 7, Blocks.air, 0, 2);
            world.setBlock(chunkX + 7, j + 6, chunkZ + 7, Blocks.air, 0, 2);
            world.setBlock(chunkX + 8, j + 6, chunkZ + 7, Blocks.air, 0, 2);
            world.setBlock(chunkX + 9, j + 6, chunkZ + 7, Blocks.air, 0, 2);
            world.setBlock(chunkX + 10, j + 6, chunkZ + 7, Blocks.air, 0, 2);
            world.setBlock(chunkX + 11, j + 6, chunkZ + 7, Blocks.air, 0, 2);
            world.setBlock(chunkX + 12, j + 6, chunkZ + 7, Blocks.air, 0, 2);
            world.setBlock(chunkX + 13, j + 6, chunkZ + 7, Blocks.air, 0, 2);
            world.setBlock(chunkX + 14, j + 6, chunkZ + 7, Blocks.air, 0, 2);
            world.setBlock(chunkX + 0, j + 6, chunkZ + 8, Blocks.air, 0, 2);
            world.setBlock(chunkX + 1, j + 6, chunkZ + 8, Blocks.air, 0, 2);
            world.setBlock(chunkX + 2, j + 6, chunkZ + 8, Blocks.air, 0, 2);
            world.setBlock(chunkX + 3, j + 6, chunkZ + 8, Blocks.air, 0, 2);
            world.setBlock(chunkX + 4, j + 6, chunkZ + 8, Blocks.air, 0, 2);
            world.setBlock(chunkX + 5, j + 6, chunkZ + 8, Blocks.air, 0, 2);
            world.setBlock(chunkX + 6, j + 6, chunkZ + 8, Blocks.air, 0, 2);
            world.setBlock(chunkX + 7, j + 6, chunkZ + 8, Blocks.air, 0, 2);
            world.setBlock(chunkX + 8, j + 6, chunkZ + 8, Blocks.air, 0, 2);
            world.setBlock(chunkX + 9, j + 6, chunkZ + 8, Blocks.air, 0, 2);
            world.setBlock(chunkX + 10, j + 6, chunkZ + 8, Blocks.air, 0, 2);
            world.setBlock(chunkX + 11, j + 6, chunkZ + 8, Blocks.air, 0, 2);
            world.setBlock(chunkX + 12, j + 6, chunkZ + 8, Blocks.air, 0, 2);
            world.setBlock(chunkX + 13, j + 6, chunkZ + 8, Blocks.air, 0, 2);
            world.setBlock(chunkX + 14, j + 6, chunkZ + 8, Blocks.air, 0, 2);
            world.setBlock(chunkX + 0, j + 6, chunkZ + 9, Blocks.air, 0, 2);
            world.setBlock(chunkX + 1, j + 6, chunkZ + 9, Blocks.air, 0, 2);
            world.setBlock(chunkX + 2, j + 6, chunkZ + 9, Blocks.air, 0, 2);
            world.setBlock(chunkX + 3, j + 6, chunkZ + 9, Blocks.air, 0, 2);
            world.setBlock(chunkX + 4, j + 6, chunkZ + 9, Blocks.air, 0, 2);
            world.setBlock(chunkX + 5, j + 6, chunkZ + 9, Blocks.air, 0, 2);
            world.setBlock(chunkX + 6, j + 6, chunkZ + 9, Blocks.air, 0, 2);
            world.setBlock(chunkX + 7, j + 6, chunkZ + 9, Blocks.air, 0, 2);
            world.setBlock(chunkX + 8, j + 6, chunkZ + 9, Blocks.air, 0, 2);
            world.setBlock(chunkX + 9, j + 6, chunkZ + 9, Blocks.air, 0, 2);
            world.setBlock(chunkX + 10, j + 6, chunkZ + 9, Blocks.air, 0, 2);
            world.setBlock(chunkX + 11, j + 6, chunkZ + 9, Blocks.air, 0, 2);
            world.setBlock(chunkX + 12, j + 6, chunkZ + 9, Blocks.air, 0, 2);
            world.setBlock(chunkX + 13, j + 6, chunkZ + 9, Blocks.air, 0, 2);
            world.setBlock(chunkX + 14, j + 6, chunkZ + 9, Blocks.air, 0, 2);
            world.setBlock(chunkX + 0, j + 7, chunkZ + 0, Blocks.air, 0, 2);
            world.setBlock(chunkX + 1, j + 7, chunkZ + 0, Blocks.air, 0, 2);
            world.setBlock(chunkX + 2, j + 7, chunkZ + 0, Blocks.air, 0, 2);
            world.setBlock(chunkX + 3, j + 7, chunkZ + 0, Blocks.air, 0, 2);
            world.setBlock(chunkX + 4, j + 7, chunkZ + 0, Blocks.air, 0, 2);
            world.setBlock(chunkX + 5, j + 7, chunkZ + 0, Blocks.air, 0, 2);
            world.setBlock(chunkX + 6, j + 7, chunkZ + 0, Blocks.air, 0, 2);
            world.setBlock(chunkX + 7, j + 7, chunkZ + 0, Blocks.air, 0, 2);
            world.setBlock(chunkX + 8, j + 7, chunkZ + 0, Blocks.air, 0, 2);
            world.setBlock(chunkX + 9, j + 7, chunkZ + 0, Blocks.air, 0, 2);
            world.setBlock(chunkX + 10, j + 7, chunkZ + 0, Blocks.air, 0, 2);
            world.setBlock(chunkX + 11, j + 7, chunkZ + 0, Blocks.air, 0, 2);
            world.setBlock(chunkX + 12, j + 7, chunkZ + 0, Blocks.air, 0, 2);
            world.setBlock(chunkX + 13, j + 7, chunkZ + 0, Blocks.air, 0, 2);
            world.setBlock(chunkX + 14, j + 7, chunkZ + 0, Blocks.air, 0, 2);
            world.setBlock(chunkX + 0, j + 7, chunkZ + 1, Blocks.air, 0, 2);
            world.setBlock(chunkX + 1, j + 7, chunkZ + 1, Blocks.air, 0, 2);
            world.setBlock(chunkX + 2, j + 7, chunkZ + 1, Blocks.air, 0, 2);
            world.setBlock(chunkX + 3, j + 7, chunkZ + 1, Blocks.air, 0, 2);
            world.setBlock(chunkX + 4, j + 7, chunkZ + 1, Blocks.air, 0, 2);
            world.setBlock(chunkX + 5, j + 7, chunkZ + 1, Blocks.air, 0, 2);
            world.setBlock(chunkX + 6, j + 7, chunkZ + 1, Blocks.air, 0, 2);
            world.setBlock(chunkX + 7, j + 7, chunkZ + 1, Blocks.air, 0, 2);
            world.setBlock(chunkX + 8, j + 7, chunkZ + 1, Blocks.air, 0, 2);
            world.setBlock(chunkX + 9, j + 7, chunkZ + 1, Blocks.air, 0, 2);
            world.setBlock(chunkX + 10, j + 7, chunkZ + 1, Blocks.air, 0, 2);
            world.setBlock(chunkX + 11, j + 7, chunkZ + 1, Blocks.air, 0, 2);
            world.setBlock(chunkX + 12, j + 7, chunkZ + 1, Blocks.air, 0, 2);
            world.setBlock(chunkX + 13, j + 7, chunkZ + 1, Blocks.air, 0, 2);
            world.setBlock(chunkX + 14, j + 7, chunkZ + 1, Blocks.air, 0, 2);
            world.setBlock(chunkX + 0, j + 7, chunkZ + 2, Blocks.air, 0, 2);
            world.setBlock(chunkX + 1, j + 7, chunkZ + 2, Blocks.air, 0, 2);
            world.setBlock(chunkX + 2, j + 7, chunkZ + 2, Blocks.air, 0, 2);
            world.setBlock(chunkX + 3, j + 7, chunkZ + 2, Blocks.air, 0, 2);
            world.setBlock(chunkX + 4, j + 7, chunkZ + 2, Blocks.air, 0, 2);
            world.setBlock(chunkX + 5, j + 7, chunkZ + 2, Blocks.air, 0, 2);
            world.setBlock(chunkX + 6, j + 7, chunkZ + 2, Blocks.air, 0, 2);
            world.setBlock(chunkX + 7, j + 7, chunkZ + 2, Blocks.air, 0, 2);
            world.setBlock(chunkX + 8, j + 7, chunkZ + 2, Blocks.air, 0, 2);
            world.setBlock(chunkX + 9, j + 7, chunkZ + 2, Blocks.air, 0, 2);
            world.setBlock(chunkX + 10, j + 7, chunkZ + 2, Blocks.air, 0, 2);
            world.setBlock(chunkX + 11, j + 7, chunkZ + 2, Blocks.air, 0, 2);
            world.setBlock(chunkX + 12, j + 7, chunkZ + 2, Blocks.air, 0, 2);
            world.setBlock(chunkX + 13, j + 7, chunkZ + 2, Blocks.air, 0, 2);
            world.setBlock(chunkX + 14, j + 7, chunkZ + 2, Blocks.air, 0, 2);
            world.setBlock(chunkX + 0, j + 7, chunkZ + 3, Blocks.air, 0, 2);
            world.setBlock(chunkX + 1, j + 7, chunkZ + 3, Blocks.air, 0, 2);
            world.setBlock(chunkX + 2, j + 7, chunkZ + 3, Blocks.air, 0, 2);
            world.setBlock(chunkX + 3, j + 7, chunkZ + 3, Blocks.air, 0, 2);
            world.setBlock(chunkX + 4, j + 7, chunkZ + 3, Blocks.air, 0, 2);
            world.setBlock(chunkX + 5, j + 7, chunkZ + 3, Blocks.air, 0, 2);
            world.setBlock(chunkX + 6, j + 7, chunkZ + 3, Blocks.air, 0, 2);
            world.setBlock(chunkX + 7, j + 7, chunkZ + 3, Blocks.air, 0, 2);
            world.setBlock(chunkX + 8, j + 7, chunkZ + 3, Blocks.air, 0, 2);
            world.setBlock(chunkX + 9, j + 7, chunkZ + 3, Blocks.air, 0, 2);
            world.setBlock(chunkX + 10, j + 7, chunkZ + 3, Blocks.air, 0, 2);
            world.setBlock(chunkX + 11, j + 7, chunkZ + 3, Blocks.air, 0, 2);
            world.setBlock(chunkX + 12, j + 7, chunkZ + 3, Blocks.air, 0, 2);
            world.setBlock(chunkX + 13, j + 7, chunkZ + 3, Blocks.air, 0, 2);
            world.setBlock(chunkX + 14, j + 7, chunkZ + 3, Blocks.air, 0, 2);
            world.setBlock(chunkX + 0, j + 7, chunkZ + 4, Blocks.air, 0, 2);
            world.setBlock(chunkX + 1, j + 7, chunkZ + 4, Blocks.air, 0, 2);
            world.setBlock(chunkX + 2, j + 7, chunkZ + 4, Blocks.air, 0, 2);
            world.setBlock(chunkX + 3, j + 7, chunkZ + 4, Blocks.air, 0, 2);
            world.setBlock(chunkX + 4, j + 7, chunkZ + 4, Blocks.air, 0, 2);
            world.setBlock(chunkX + 5, j + 7, chunkZ + 4, Blocks.air, 0, 2);
            world.setBlock(chunkX + 6, j + 7, chunkZ + 4, Blocks.air, 0, 2);
            world.setBlock(chunkX + 7, j + 7, chunkZ + 4, Blocks.stonebrick, 0, 2);
            world.setBlock(chunkX + 8, j + 7, chunkZ + 4, Blocks.air, 0, 2);
            world.setBlock(chunkX + 9, j + 7, chunkZ + 4, Blocks.air, 0, 2);
            world.setBlock(chunkX + 10, j + 7, chunkZ + 4, Blocks.air, 0, 2);
            world.setBlock(chunkX + 11, j + 7, chunkZ + 4, Blocks.air, 0, 2);
            world.setBlock(chunkX + 12, j + 7, chunkZ + 4, Blocks.air, 0, 2);
            world.setBlock(chunkX + 13, j + 7, chunkZ + 4, Blocks.air, 0, 2);
            world.setBlock(chunkX + 14, j + 7, chunkZ + 4, Blocks.air, 0, 2);
            world.setBlock(chunkX + 0, j + 7, chunkZ + 5, Blocks.air, 0, 2);
            world.setBlock(chunkX + 1, j + 7, chunkZ + 5, Blocks.air, 0, 2);
            world.setBlock(chunkX + 2, j + 7, chunkZ + 5, Blocks.stonebrick, 0, 2);
            world.setBlock(chunkX + 3, j + 7, chunkZ + 5, Blocks.stonebrick, 0, 2);
            world.setBlock(chunkX + 4, j + 7, chunkZ + 5, Blocks.stonebrick, 0, 2);
            world.setBlock(chunkX + 5, j + 7, chunkZ + 5, Blocks.stonebrick, 0, 2);
            world.setBlock(chunkX + 6, j + 7, chunkZ + 5, Blocks.stonebrick, 0, 2);
            world.setBlock(chunkX + 7, j + 7, chunkZ + 5, Blocks.ladder, 4, 2);
            world.setBlock(chunkX + 8, j + 7, chunkZ + 5, Blocks.stonebrick, 0, 2);
            world.setBlock(chunkX + 9, j + 7, chunkZ + 5, Blocks.air, 0, 2);
            world.setBlock(chunkX + 10, j + 7, chunkZ + 5, Blocks.air, 0, 2);
            world.setBlock(chunkX + 11, j + 7, chunkZ + 5, Blocks.air, 0, 2);
            world.setBlock(chunkX + 12, j + 7, chunkZ + 5, Blocks.air, 0, 2);
            world.setBlock(chunkX + 13, j + 7, chunkZ + 5, Blocks.air, 0, 2);
            world.setBlock(chunkX + 14, j + 7, chunkZ + 5, Blocks.air, 0, 2);
            world.setBlock(chunkX + 0, j + 7, chunkZ + 6, Blocks.air, 0, 2);
            world.setBlock(chunkX + 1, j + 7, chunkZ + 6, Blocks.air, 0, 2);
            world.setBlock(chunkX + 2, j + 7, chunkZ + 6, Blocks.air, 0, 2);
            world.setBlock(chunkX + 3, j + 7, chunkZ + 6, Blocks.air, 0, 2);
            world.setBlock(chunkX + 4, j + 7, chunkZ + 6, Blocks.air, 0, 2);
            world.setBlock(chunkX + 5, j + 7, chunkZ + 6, Blocks.air, 0, 2);
            world.setBlock(chunkX + 6, j + 7, chunkZ + 6, Blocks.air, 0, 2);
            world.setBlock(chunkX + 7, j + 7, chunkZ + 6, Blocks.stonebrick, 0, 2);
            world.setBlock(chunkX + 8, j + 7, chunkZ + 6, Blocks.air, 0, 2);
            world.setBlock(chunkX + 9, j + 7, chunkZ + 6, Blocks.air, 0, 2);
            world.setBlock(chunkX + 10, j + 7, chunkZ + 6, Blocks.air, 0, 2);
            world.setBlock(chunkX + 11, j + 7, chunkZ + 6, Blocks.air, 0, 2);
            world.setBlock(chunkX + 12, j + 7, chunkZ + 6, Blocks.air, 0, 2);
            world.setBlock(chunkX + 13, j + 7, chunkZ + 6, Blocks.air, 0, 2);
            this.generateFin(world, random, chunkX, chunkY, chunkZ);
        }
    }
    
    public void generateFin(final World world, final Random random, final int chunkX, final int chunkY, final int chunkZ) {
        final int j = world.getHeightValue(chunkX, chunkZ);
        world.setBlock(chunkX + 14, j + 7, chunkZ + 6, Blocks.air, 0, 2);
        world.setBlock(chunkX + 0, j + 7, chunkZ + 7, Blocks.air, 0, 2);
        world.setBlock(chunkX + 1, j + 7, chunkZ + 7, Blocks.air, 0, 2);
        world.setBlock(chunkX + 2, j + 7, chunkZ + 7, Blocks.air, 0, 2);
        world.setBlock(chunkX + 3, j + 7, chunkZ + 7, Blocks.air, 0, 2);
        world.setBlock(chunkX + 4, j + 7, chunkZ + 7, Blocks.air, 0, 2);
        world.setBlock(chunkX + 5, j + 7, chunkZ + 7, Blocks.air, 0, 2);
        world.setBlock(chunkX + 6, j + 7, chunkZ + 7, Blocks.air, 0, 2);
        world.setBlock(chunkX + 7, j + 7, chunkZ + 7, Blocks.air, 0, 2);
        world.setBlock(chunkX + 8, j + 7, chunkZ + 7, Blocks.air, 0, 2);
        world.setBlock(chunkX + 9, j + 7, chunkZ + 7, Blocks.air, 0, 2);
        world.setBlock(chunkX + 10, j + 7, chunkZ + 7, Blocks.air, 0, 2);
        world.setBlock(chunkX + 11, j + 7, chunkZ + 7, Blocks.air, 0, 2);
        world.setBlock(chunkX + 12, j + 7, chunkZ + 7, Blocks.air, 0, 2);
        world.setBlock(chunkX + 13, j + 7, chunkZ + 7, Blocks.air, 0, 2);
        world.setBlock(chunkX + 14, j + 7, chunkZ + 7, Blocks.air, 0, 2);
        world.setBlock(chunkX + 0, j + 7, chunkZ + 8, Blocks.air, 0, 2);
        world.setBlock(chunkX + 1, j + 7, chunkZ + 8, Blocks.air, 0, 2);
        world.setBlock(chunkX + 2, j + 7, chunkZ + 8, Blocks.air, 0, 2);
        world.setBlock(chunkX + 3, j + 7, chunkZ + 8, Blocks.air, 0, 2);
        world.setBlock(chunkX + 4, j + 7, chunkZ + 8, Blocks.air, 0, 2);
        world.setBlock(chunkX + 5, j + 7, chunkZ + 8, Blocks.air, 0, 2);
        world.setBlock(chunkX + 6, j + 7, chunkZ + 8, Blocks.air, 0, 2);
        world.setBlock(chunkX + 7, j + 7, chunkZ + 8, Blocks.air, 0, 2);
        world.setBlock(chunkX + 8, j + 7, chunkZ + 8, Blocks.air, 0, 2);
        world.setBlock(chunkX + 9, j + 7, chunkZ + 8, Blocks.air, 0, 2);
        world.setBlock(chunkX + 10, j + 7, chunkZ + 8, Blocks.air, 0, 2);
        world.setBlock(chunkX + 11, j + 7, chunkZ + 8, Blocks.air, 0, 2);
        world.setBlock(chunkX + 12, j + 7, chunkZ + 8, Blocks.air, 0, 2);
        world.setBlock(chunkX + 13, j + 7, chunkZ + 8, Blocks.air, 0, 2);
        world.setBlock(chunkX + 14, j + 7, chunkZ + 8, Blocks.air, 0, 2);
        world.setBlock(chunkX + 0, j + 7, chunkZ + 9, Blocks.air, 0, 2);
        world.setBlock(chunkX + 1, j + 7, chunkZ + 9, Blocks.air, 0, 2);
        world.setBlock(chunkX + 2, j + 7, chunkZ + 9, Blocks.air, 0, 2);
        world.setBlock(chunkX + 3, j + 7, chunkZ + 9, Blocks.air, 0, 2);
        world.setBlock(chunkX + 4, j + 7, chunkZ + 9, Blocks.air, 0, 2);
        world.setBlock(chunkX + 5, j + 7, chunkZ + 9, Blocks.air, 0, 2);
        world.setBlock(chunkX + 6, j + 7, chunkZ + 9, Blocks.air, 0, 2);
        world.setBlock(chunkX + 7, j + 7, chunkZ + 9, Blocks.air, 0, 2);
        world.setBlock(chunkX + 8, j + 7, chunkZ + 9, Blocks.air, 0, 2);
        world.setBlock(chunkX + 9, j + 7, chunkZ + 9, Blocks.air, 0, 2);
        world.setBlock(chunkX + 10, j + 7, chunkZ + 9, Blocks.air, 0, 2);
        world.setBlock(chunkX + 11, j + 7, chunkZ + 9, Blocks.air, 0, 2);
        world.setBlock(chunkX + 12, j + 7, chunkZ + 9, Blocks.air, 0, 2);
        world.setBlock(chunkX + 13, j + 7, chunkZ + 9, Blocks.air, 0, 2);
        world.setBlock(chunkX + 14, j + 7, chunkZ + 9, Blocks.air, 0, 2);
        world.setBlock(chunkX + 0, j + 8, chunkZ + 0, Blocks.air, 0, 2);
        world.setBlock(chunkX + 1, j + 8, chunkZ + 0, Blocks.air, 0, 2);
        world.setBlock(chunkX + 2, j + 8, chunkZ + 0, Blocks.air, 0, 2);
        world.setBlock(chunkX + 3, j + 8, chunkZ + 0, Blocks.air, 0, 2);
        world.setBlock(chunkX + 4, j + 8, chunkZ + 0, Blocks.air, 0, 2);
        world.setBlock(chunkX + 5, j + 8, chunkZ + 0, Blocks.air, 0, 2);
        world.setBlock(chunkX + 6, j + 8, chunkZ + 0, Blocks.air, 0, 2);
        world.setBlock(chunkX + 7, j + 8, chunkZ + 0, Blocks.air, 0, 2);
        world.setBlock(chunkX + 8, j + 8, chunkZ + 0, Blocks.air, 0, 2);
        world.setBlock(chunkX + 9, j + 8, chunkZ + 0, Blocks.air, 0, 2);
        world.setBlock(chunkX + 10, j + 8, chunkZ + 0, Blocks.air, 0, 2);
        world.setBlock(chunkX + 11, j + 8, chunkZ + 0, Blocks.air, 0, 2);
        world.setBlock(chunkX + 12, j + 8, chunkZ + 0, Blocks.air, 0, 2);
        world.setBlock(chunkX + 13, j + 8, chunkZ + 0, Blocks.air, 0, 2);
        world.setBlock(chunkX + 14, j + 8, chunkZ + 0, Blocks.air, 0, 2);
        world.setBlock(chunkX + 0, j + 8, chunkZ + 1, Blocks.air, 0, 2);
        world.setBlock(chunkX + 1, j + 8, chunkZ + 1, Blocks.air, 0, 2);
        world.setBlock(chunkX + 2, j + 8, chunkZ + 1, Blocks.air, 0, 2);
