package apocalypse.fandomcraft.structures;

import net.minecraft.world.*;
import java.util.*;
import net.minecraft.world.biome.*;
import net.minecraft.init.*;
import net.minecraft.block.*;
import net.minecraftforge.common.*;
import net.minecraft.util.*;
import net.minecraft.inventory.*;
import apocalypse.fandomcraft.main.*;
import net.minecraft.tileentity.*;
import net.minecraft.world.gen.structure.*;
import net.minecraft.nbt.*;

public class DungeonGuardTower extends StructureComponent
{
    public void generateSurface(final World world, final Random random, final int chunkX, final int chunkY, final int chunkZ) {
        final int j = world.getHeightValue(chunkX, chunkZ) - 12;
        if (world.getBiomeGenForCoords(chunkX, chunkZ).biomeName.equals(BiomeGenBase.ocean.biomeName) || world.getBiomeGenForCoords(chunkX, chunkZ).biomeName.equals(BiomeGenBase.deepOcean.biomeName)) {
            final boolean place = true;
            if (place && world.getBlock(chunkX, j, chunkZ) == Blocks.water) {
                world.setBlock(chunkX + 5, j + 0, chunkZ + 5, Blocks.log, 0, 2);
                world.setBlock(chunkX + 5, j + 1, chunkZ + 5, Blocks.log, 0, 2);
                world.setBlock(chunkX + 5, j + 2, chunkZ + 5, Blocks.log, 0, 2);
                world.setBlock(chunkX + 5, j + 3, chunkZ + 5, Blocks.log, 0, 2);
                world.setBlock(chunkX + 5, j + 4, chunkZ + 5, Blocks.log, 0, 2);
                world.setBlock(chunkX + 5, j + 5, chunkZ + 5, Blocks.log, 0, 2);
                world.setBlock(chunkX + 5, j + 6, chunkZ + 5, Blocks.log, 0, 2);
                world.setBlock(chunkX + 5, j + 7, chunkZ + 5, Blocks.log, 0, 2);
                world.setBlock(chunkX + 5, j + 8, chunkZ + 5, Blocks.log, 0, 2);
                world.setBlock(chunkX + 5, j + 9, chunkZ + 5, Blocks.log, 0, 2);
                world.setBlock(chunkX + 5, j + 10, chunkZ + 5, Blocks.log, 0, 2);
                world.setBlock(chunkX + 5, j + 11, chunkZ + 5, Blocks.log, 0, 2);
                world.setBlock(chunkX + 6, j + 11, chunkZ + 5, Blocks.ladder, 5, 2);
                world.setBlock(chunkX + 5, j + 12, chunkZ + 5, Blocks.log, 0, 2);
                world.setBlock(chunkX + 6, j + 12, chunkZ + 5, Blocks.ladder, 5, 2);
                world.setBlock(chunkX + 5, j + 13, chunkZ + 5, Blocks.log, 0, 2);
                world.setBlock(chunkX + 6, j + 13, chunkZ + 5, Blocks.ladder, 5, 2);
                world.setBlock(chunkX + 5, j + 14, chunkZ + 5, Blocks.log, 0, 2);
                world.setBlock(chunkX + 6, j + 14, chunkZ + 5, Blocks.ladder, 5, 2);
                world.setBlock(chunkX + 5, j + 15, chunkZ + 5, Blocks.log, 0, 2);
                world.setBlock(chunkX + 6, j + 15, chunkZ + 5, Blocks.ladder, 5, 2);
                world.setBlock(chunkX + 5, j + 16, chunkZ + 5, Blocks.log, 0, 2);
                world.setBlock(chunkX + 6, j + 16, chunkZ + 5, Blocks.ladder, 5, 2);
                world.setBlock(chunkX + 5, j + 17, chunkZ + 5, Blocks.log, 0, 2);
                world.setBlock(chunkX + 6, j + 17, chunkZ + 5, Blocks.ladder, 5, 2);
                world.setBlock(chunkX + 5, j + 18, chunkZ + 5, Blocks.log, 0, 2);
                world.setBlock(chunkX + 6, j + 18, chunkZ + 5, Blocks.ladder, 5, 2);
                world.setBlock(chunkX + 5, j + 19, chunkZ + 5, Blocks.log, 0, 2);
                world.setBlock(chunkX + 6, j + 19, chunkZ + 5, Blocks.ladder, 5, 2);
                world.setBlock(chunkX + 5, j + 20, chunkZ + 5, Blocks.log, 0, 2);
                world.setBlock(chunkX + 6, j + 20, chunkZ + 5, Blocks.ladder, 5, 2);
                world.setBlock(chunkX + 5, j + 21, chunkZ + 5, Blocks.log, 0, 2);
                world.setBlock(chunkX + 6, j + 21, chunkZ + 5, Blocks.ladder, 5, 2);
                world.setBlock(chunkX + 5, j + 22, chunkZ + 5, Blocks.log, 0, 2);
                world.setBlock(chunkX + 6, j + 22, chunkZ + 5, Blocks.ladder, 5, 2);
                world.setBlock(chunkX + 5, j + 23, chunkZ + 5, Blocks.log, 0, 2);
                world.setBlock(chunkX + 6, j + 23, chunkZ + 5, Blocks.ladder, 5, 2);
                world.setBlock(chunkX + 5, j + 24, chunkZ + 5, Blocks.log, 0, 2);
                world.setBlock(chunkX + 6, j + 24, chunkZ + 5, Blocks.ladder, 5, 2);
                world.setBlock(chunkX + 4, j + 25, chunkZ + 3, Blocks.stonebrick, 0, 2);
                world.setBlock(chunkX + 5, j + 25, chunkZ + 3, Blocks.stonebrick, 0, 2);
                world.setBlock(chunkX + 6, j + 25, chunkZ + 3, Blocks.stonebrick, 0, 2);
                world.setBlock(chunkX + 3, j + 25, chunkZ + 4, Blocks.stonebrick, 0, 2);
                world.setBlock(chunkX + 4, j + 25, chunkZ + 4, Blocks.stonebrick, 0, 2);
                world.setBlock(chunkX + 6, j + 25, chunkZ + 4, Blocks.stonebrick, 0, 2);
                world.setBlock(chunkX + 7, j + 25, chunkZ + 4, Blocks.stonebrick, 0, 2);
                world.setBlock(chunkX + 3, j + 25, chunkZ + 5, Blocks.stonebrick, 0, 2);
                world.setBlock(chunkX + 5, j + 25, chunkZ + 5, Blocks.log, 0, 2);
                world.setBlock(chunkX + 6, j + 25, chunkZ + 5, Blocks.ladder, 5, 2);
                world.setBlock(chunkX + 7, j + 25, chunkZ + 5, Blocks.stonebrick, 0, 2);
                world.setBlock(chunkX + 3, j + 25, chunkZ + 6, Blocks.stonebrick, 0, 2);
                world.setBlock(chunkX + 4, j + 25, chunkZ + 6, Blocks.stonebrick, 0, 2);
                world.setBlock(chunkX + 6, j + 25, chunkZ + 6, Blocks.stonebrick, 0, 2);
                world.setBlock(chunkX + 7, j + 25, chunkZ + 6, Blocks.stonebrick, 0, 2);
                world.setBlock(chunkX + 4, j + 25, chunkZ + 7, Blocks.stonebrick, 0, 2);
                world.setBlock(chunkX + 5, j + 25, chunkZ + 7, Blocks.stonebrick, 0, 2);
                world.setBlock(chunkX + 6, j + 25, chunkZ + 7, Blocks.stonebrick, 0, 2);
                world.setBlock(chunkX + 4, j + 26, chunkZ + 2, Blocks.stonebrick, 0, 2);
                world.setBlock(chunkX + 5, j + 26, chunkZ + 2, Blocks.stonebrick, 0, 2);
                world.setBlock(chunkX + 6, j + 26, chunkZ + 2, Blocks.stonebrick, 0, 2);
                world.setBlock(chunkX + 3, j + 26, chunkZ + 3, Blocks.stonebrick, 0, 2);
                world.setBlock(chunkX + 4, j + 26, chunkZ + 3, Blocks.stonebrick, 0, 2);
                world.setBlock(chunkX + 5, j + 26, chunkZ + 3, Blocks.stonebrick, 0, 2);
                world.setBlock(chunkX + 6, j + 26, chunkZ + 3, Blocks.stonebrick, 0, 2);
                world.setBlock(chunkX + 7, j + 26, chunkZ + 3, Blocks.stonebrick, 0, 2);
                world.setBlock(chunkX + 2, j + 26, chunkZ + 4, Blocks.stonebrick, 0, 2);
                world.setBlock(chunkX + 3, j + 26, chunkZ + 4, Blocks.stonebrick, 0, 2);
                world.setBlock(chunkX + 4, j + 26, chunkZ + 4, Blocks.stonebrick, 0, 2);
                world.setBlock(chunkX + 6, j + 26, chunkZ + 4, Blocks.stonebrick, 0, 2);
                world.setBlock(chunkX + 7, j + 26, chunkZ + 4, Blocks.stonebrick, 0, 2);
                world.setBlock(chunkX + 8, j + 26, chunkZ + 4, Blocks.stonebrick, 0, 2);
                world.setBlock(chunkX + 2, j + 26, chunkZ + 5, Blocks.stonebrick, 0, 2);
                world.setBlock(chunkX + 3, j + 26, chunkZ + 5, Blocks.stonebrick, 0, 2);
                world.setBlock(chunkX + 5, j + 26, chunkZ + 5, Blocks.log, 0, 2);
                world.setBlock(chunkX + 6, j + 26, chunkZ + 5, Blocks.ladder, 5, 2);
                world.setBlock(chunkX + 7, j + 26, chunkZ + 5, Blocks.stonebrick, 0, 2);
                world.setBlock(chunkX + 8, j + 26, chunkZ + 5, Blocks.stonebrick, 0, 2);
                world.setBlock(chunkX + 2, j + 26, chunkZ + 6, Blocks.stonebrick, 0, 2);
                world.setBlock(chunkX + 3, j + 26, chunkZ + 6, Blocks.stonebrick, 0, 2);
                world.setBlock(chunkX + 4, j + 26, chunkZ + 6, Blocks.stonebrick, 0, 2);
                world.setBlock(chunkX + 6, j + 26, chunkZ + 6, Blocks.stonebrick, 0, 2);
                world.setBlock(chunkX + 7, j + 26, chunkZ + 6, Blocks.stonebrick, 0, 2);
                world.setBlock(chunkX + 8, j + 26, chunkZ + 6, Blocks.stonebrick, 0, 2);
                world.setBlock(chunkX + 3, j + 26, chunkZ + 7, Blocks.stonebrick, 0, 2);
                world.setBlock(chunkX + 4, j + 26, chunkZ + 7, Blocks.stonebrick, 0, 2);
                world.setBlock(chunkX + 5, j + 26, chunkZ + 7, Blocks.stonebrick, 0, 2);
                world.setBlock(chunkX + 6, j + 26, chunkZ + 7, Blocks.stonebrick, 0, 2);
                world.setBlock(chunkX + 7, j + 26, chunkZ + 7, Blocks.stonebrick, 0, 2);
                world.setBlock(chunkX + 4, j + 26, chunkZ + 8, Blocks.stonebrick, 0, 2);
                world.setBlock(chunkX + 5, j + 26, chunkZ + 8, Blocks.stonebrick, 0, 2);
                world.setBlock(chunkX + 6, j + 26, chunkZ + 8, Blocks.stonebrick, 0, 2);
                world.setBlock(chunkX + 3, j + 27, chunkZ + 1, Blocks.stonebrick, 0, 2);
                world.setBlock(chunkX + 4, j + 27, chunkZ + 1, Blocks.stonebrick, 0, 2);
                world.setBlock(chunkX + 5, j + 27, chunkZ + 1, Blocks.stonebrick, 0, 2);
                world.setBlock(chunkX + 6, j + 27, chunkZ + 1, Blocks.stonebrick, 0, 2);
                world.setBlock(chunkX + 7, j + 27, chunkZ + 1, Blocks.stonebrick, 0, 2);
                world.setBlock(chunkX + 2, j + 27, chunkZ + 2, Blocks.stonebrick, 0, 2);
                world.setBlock(chunkX + 3, j + 27, chunkZ + 2, Blocks.stonebrick, 0, 2);
                world.setBlock(chunkX + 4, j + 27, chunkZ + 2, (Block)Blocks.stone_slab, 5, 2);
                world.setBlock(chunkX + 5, j + 27, chunkZ + 2, (Block)Blocks.stone_slab, 5, 2);
                world.setBlock(chunkX + 6, j + 27, chunkZ + 2, (Block)Blocks.stone_slab, 5, 2);
                world.setBlock(chunkX + 7, j + 27, chunkZ + 2, Blocks.stonebrick, 0, 2);
                world.setBlock(chunkX + 8, j + 27, chunkZ + 2, Blocks.stonebrick, 0, 2);
                world.setBlock(chunkX + 1, j + 27, chunkZ + 3, Blocks.stonebrick, 0, 2);
                world.setBlock(chunkX + 2, j + 27, chunkZ + 3, Blocks.stonebrick, 0, 2);
                world.setBlock(chunkX + 8, j + 27, chunkZ + 3, Blocks.stonebrick, 0, 2);
                world.setBlock(chunkX + 9, j + 27, chunkZ + 3, Blocks.stonebrick, 0, 2);
                world.setBlock(chunkX + 1, j + 27, chunkZ + 4, Blocks.stonebrick, 0, 2);
                world.setBlock(chunkX + 2, j + 27, chunkZ + 4, (Block)Blocks.stone_slab, 5, 2);
                world.setBlock(chunkX + 8, j + 27, chunkZ + 4, (Block)Blocks.stone_slab, 5, 2);
                world.setBlock(chunkX + 9, j + 27, chunkZ + 4, Blocks.stonebrick, 0, 2);
                world.setBlock(chunkX + 1, j + 27, chunkZ + 5, Blocks.stonebrick, 0, 2);
                world.setBlock(chunkX + 2, j + 27, chunkZ + 5, (Block)Blocks.stone_slab, 5, 2);
                world.setBlock(chunkX + 5, j + 27, chunkZ + 5, Blocks.log, 0, 2);
                world.setBlock(chunkX + 6, j + 27, chunkZ + 5, Blocks.ladder, 5, 2);
                world.setBlock(chunkX + 8, j + 27, chunkZ + 5, (Block)Blocks.chest, 4, 2);
                final int xx = chunkX + 8;
                final int yy = j + 27;
                final int zz = chunkZ + 5;
                final TileEntityChest tileentitychest = (TileEntityChest)world.getTileEntity(xx, yy, zz);
                if (tileentitychest != null) {
                    WeightedRandomChestContent.generateChestContents(random, ChestGenHooks.getItems("dungeonChest", random), (IInventory)tileentitychest, ChestGenHooks.getCount("dungeonChest", random));
                }
                world.setBlock(chunkX + 9, j + 27, chunkZ + 5, Blocks.stonebrick, 0, 2);
                world.setBlock(chunkX + 1, j + 27, chunkZ + 6, Blocks.stonebrick, 0, 2);
                world.setBlock(chunkX + 2, j + 27, chunkZ + 6, (Block)Blocks.stone_slab, 5, 2);
                world.setBlock(chunkX + 8, j + 27, chunkZ + 6, (Block)Blocks.stone_slab, 5, 2);
                world.setBlock(chunkX + 9, j + 27, chunkZ + 6, Blocks.stonebrick, 0, 2);
                world.setBlock(chunkX + 1, j + 27, chunkZ + 7, Blocks.stonebrick, 0, 2);
                world.setBlock(chunkX + 2, j + 27, chunkZ + 7, Blocks.stonebrick, 0, 2);
                world.setBlock(chunkX + 8, j + 27, chunkZ + 7, Blocks.stonebrick, 0, 2);
                world.setBlock(chunkX + 9, j + 27, chunkZ + 7, Blocks.stonebrick, 0, 2);
                world.setBlock(chunkX + 2, j + 27, chunkZ + 8, Blocks.stonebrick, 0, 2);
                world.setBlock(chunkX + 3, j + 27, chunkZ + 8, Blocks.stonebrick, 0, 2);
                world.setBlock(chunkX + 4, j + 27, chunkZ + 8, (Block)Blocks.stone_slab, 5, 2);
                world.setBlock(chunkX + 5, j + 27, chunkZ + 8, (Block)Blocks.stone_slab, 5, 2);
                world.setBlock(chunkX + 6, j + 27, chunkZ + 8, (Block)Blocks.stone_slab, 5, 2);
                world.setBlock(chunkX + 7, j + 27, chunkZ + 8, Blocks.stonebrick, 0, 2);
                world.setBlock(chunkX + 8, j + 27, chunkZ + 8, Blocks.stonebrick, 0, 2);
                world.setBlock(chunkX + 3, j + 27, chunkZ + 9, Blocks.stonebrick, 0, 2);
                world.setBlock(chunkX + 4, j + 27, chunkZ + 9, Blocks.stonebrick, 0, 2);
                world.setBlock(chunkX + 5, j + 27, chunkZ + 9, Blocks.stonebrick, 0, 2);
                world.setBlock(chunkX + 6, j + 27, chunkZ + 9, Blocks.stonebrick, 0, 2);
                world.setBlock(chunkX + 7, j + 27, chunkZ + 9, Blocks.stonebrick, 0, 2);
                world.setBlock(chunkX + 2, j + 28, chunkZ + 0, Main.marbleBrick, 0, 2);
                world.setBlock(chunkX + 3, j + 28, chunkZ + 0, Main.marbleBrick, 0, 2);
                world.setBlock(chunkX + 4, j + 28, chunkZ + 0, Main.marbleBrick, 0, 2);
                world.setBlock(chunkX + 5, j + 28, chunkZ + 0, Main.marbleBrick, 0, 2);
                world.setBlock(chunkX + 6, j + 28, chunkZ + 0, Main.marbleBrick, 0, 2);
                world.setBlock(chunkX + 7, j + 28, chunkZ + 0, Main.marbleBrick, 0, 2);
                world.setBlock(chunkX + 8, j + 28, chunkZ + 0, Main.marbleBrick, 0, 2);
                world.setBlock(chunkX + 1, j + 28, chunkZ + 1, Main.marbleBrick, 0, 2);
                world.setBlock(chunkX + 2, j + 28, chunkZ + 1, Main.marbleBrick, 0, 2);
                world.setBlock(chunkX + 5, j + 28, chunkZ + 1, Blocks.stonebrick, 0, 2);
                world.setBlock(chunkX + 8, j + 28, chunkZ + 1, Main.marbleBrick, 0, 2);
                world.setBlock(chunkX + 9, j + 28, chunkZ + 1, Main.marbleBrick, 0, 2);
                world.setBlock(chunkX + 0, j + 28, chunkZ + 2, Main.marbleBrick, 0, 2);
                world.setBlock(chunkX + 1, j + 28, chunkZ + 2, Main.marbleBrick, 0, 2);
                world.setBlock(chunkX + 9, j + 28, chunkZ + 2, Main.marbleBrick, 0, 2);
                world.setBlock(chunkX + 10, j + 28, chunkZ + 2, Main.marbleBrick, 0, 2);
                world.setBlock(chunkX + 0, j + 28, chunkZ + 3, Main.marbleBrick, 0, 2);
                world.setBlock(chunkX + 10, j + 28, chunkZ + 3, Main.marbleBrick, 0, 2);
                world.setBlock(chunkX + 0, j + 28, chunkZ + 4, Main.marbleBrick, 0, 2);
                world.setBlock(chunkX + 10, j + 28, chunkZ + 4, Main.marbleBrick, 0, 2);
                world.setBlock(chunkX + 0, j + 28, chunkZ + 5, Main.marbleBrick, 0, 2);
                world.setBlock(chunkX + 1, j + 28, chunkZ + 5, Blocks.stonebrick, 0, 2);
                world.setBlock(chunkX + 5, j + 28, chunkZ + 5, Blocks.log, 0, 2);
                world.setBlock(chunkX + 6, j + 28, chunkZ + 5, Blocks.ladder, 5, 2);
                world.setBlock(chunkX + 9, j + 28, chunkZ + 5, Blocks.stonebrick, 0, 2);
                world.setBlock(chunkX + 10, j + 28, chunkZ + 5, Main.marbleBrick, 0, 2);
                world.setBlock(chunkX + 0, j + 28, chunkZ + 6, Main.marbleBrick, 0, 2);
                world.setBlock(chunkX + 10, j + 28, chunkZ + 6, Main.marbleBrick, 0, 2);
                world.setBlock(chunkX + 0, j + 28, chunkZ + 7, Main.marbleBrick, 0, 2);
                world.setBlock(chunkX + 10, j + 28, chunkZ + 7, Main.marbleBrick, 0, 2);
                world.setBlock(chunkX + 0, j + 28, chunkZ + 8, Main.marbleBrick, 0, 2);
                world.setBlock(chunkX + 1, j + 28, chunkZ + 8, Main.marbleBrick, 0, 2);
                world.setBlock(chunkX + 9, j + 28, chunkZ + 8, Main.marbleBrick, 0, 2);
                world.setBlock(chunkX + 10, j + 28, chunkZ + 8, Main.marbleBrick, 0, 2);
                world.setBlock(chunkX + 1, j + 28, chunkZ + 9, Main.marbleBrick, 0, 2);
                world.setBlock(chunkX + 2, j + 28, chunkZ + 9, Main.marbleBrick, 0, 2);
                world.setBlock(chunkX + 5, j + 28, chunkZ + 9, Blocks.stonebrick, 0, 2);
                world.setBlock(chunkX + 8, j + 28, chunkZ + 9, Main.marbleBrick, 0, 2);
                world.setBlock(chunkX + 9, j + 28, chunkZ + 9, Main.marbleBrick, 0, 2);
                world.setBlock(chunkX + 2, j + 28, chunkZ + 10, Main.marbleBrick, 0, 2);
                world.setBlock(chunkX + 3, j + 28, chunkZ + 10, Main.marbleBrick, 0, 2);
                world.setBlock(chunkX + 4, j + 28, chunkZ + 10, Main.marbleBrick, 0, 2);
                world.setBlock(chunkX + 5, j + 28, chunkZ + 10, Main.marbleBrick, 0, 2);
                world.setBlock(chunkX + 6, j + 28, chunkZ + 10, Main.marbleBrick, 0, 2);
                world.setBlock(chunkX + 7, j + 28, chunkZ + 10, Main.marbleBrick, 0, 2);
                world.setBlock(chunkX + 8, j + 28, chunkZ + 10, Main.marbleBrick, 0, 2);
                world.setBlock(chunkX + 2, j + 29, chunkZ + 0, Main.whiteWoodFence, 0, 2);
                world.setBlock(chunkX + 5, j + 29, chunkZ + 0, Blocks.stonebrick, 0, 2);
                world.setBlock(chunkX + 8, j + 29, chunkZ + 0, Main.whiteWoodFence, 0, 2);
                world.setBlock(chunkX + 0, j + 29, chunkZ + 2, Main.whiteWoodFence, 0, 2);
                world.setBlock(chunkX + 10, j + 29, chunkZ + 2, Main.whiteWoodFence, 0, 2);
                world.setBlock(chunkX + 0, j + 29, chunkZ + 5, Blocks.stonebrick, 0, 2);
                world.setBlock(chunkX + 5, j + 29, chunkZ + 5, Blocks.log, 0, 2);
                world.setBlock(chunkX + 6, j + 29, chunkZ + 5, Blocks.ladder, 5, 2);
                world.setBlock(chunkX + 10, j + 29, chunkZ + 5, Blocks.stonebrick, 0, 2);
                world.setBlock(chunkX + 0, j + 29, chunkZ + 8, Main.whiteWoodFence, 0, 2);
                world.setBlock(chunkX + 10, j + 29, chunkZ + 8, Main.whiteWoodFence, 0, 2);
                world.setBlock(chunkX + 2, j + 29, chunkZ + 10, Main.whiteWoodFence, 0, 2);
                world.setBlock(chunkX + 5, j + 29, chunkZ + 10, Blocks.stonebrick, 0, 2);
                world.setBlock(chunkX + 8, j + 29, chunkZ + 10, Main.whiteWoodFence, 0, 2);
                world.setBlock(chunkX + 2, j + 30, chunkZ + 0, Main.marbleBrick, 0, 2);
                world.setBlock(chunkX + 3, j + 30, chunkZ + 0, Main.marbleBrick, 0, 2);
                world.setBlock(chunkX + 4, j + 30, chunkZ + 0, Main.marbleBrick, 0, 2);
                world.setBlock(chunkX + 5, j + 30, chunkZ + 0, Main.marbleBrick, 0, 2);
                world.setBlock(chunkX + 6, j + 30, chunkZ + 0, Main.marbleBrick, 0, 2);
                world.setBlock(chunkX + 7, j + 30, chunkZ + 0, Main.marbleBrick, 0, 2);
                world.setBlock(chunkX + 8, j + 30, chunkZ + 0, Main.marbleBrick, 0, 2);
                world.setBlock(chunkX + 1, j + 30, chunkZ + 1, Main.marbleBrick, 0, 2);
                world.setBlock(chunkX + 2, j + 30, chunkZ + 1, Main.marbleBrick, 0, 2);
                world.setBlock(chunkX + 3, j + 30, chunkZ + 1, Main.marbleBrick, 0, 2);
                world.setBlock(chunkX + 4, j + 30, chunkZ + 1, Main.marbleBrick, 0, 2);
                world.setBlock(chunkX + 5, j + 30, chunkZ + 1, Main.marbleBrick, 0, 2);
                world.setBlock(chunkX + 6, j + 30, chunkZ + 1, Main.marbleBrick, 0, 2);
                world.setBlock(chunkX + 7, j + 30, chunkZ + 1, Main.marbleBrick, 0, 2);
                world.setBlock(chunkX + 8, j + 30, chunkZ + 1, Main.marbleBrick, 0, 2);
                world.setBlock(chunkX + 9, j + 30, chunkZ + 1, Main.marbleBrick, 0, 2);
                world.setBlock(chunkX + 0, j + 30, chunkZ + 2, Main.marbleBrick, 0, 2);
                world.setBlock(chunkX + 1, j + 30, chunkZ + 2, Main.marbleBrick, 0, 2);
                world.setBlock(chunkX + 2, j + 30, chunkZ + 2, Main.marbleBrick, 0, 2);
                world.setBlock(chunkX + 3, j + 30, chunkZ + 2, Main.marbleBrick, 0, 2);
                world.setBlock(chunkX + 4, j + 30, chunkZ + 2, Main.marbleBrick, 0, 2);
                world.setBlock(chunkX + 5, j + 30, chunkZ + 2, Main.marbleBrick, 0, 2);
                world.setBlock(chunkX + 6, j + 30, chunkZ + 2, Main.marbleBrick, 0, 2);
                world.setBlock(chunkX + 7, j + 30, chunkZ + 2, Main.marbleBrick, 0, 2);
                world.setBlock(chunkX + 8, j + 30, chunkZ + 2, Main.marbleBrick, 0, 2);
                world.setBlock(chunkX + 9, j + 30, chunkZ + 2, Main.marbleBrick, 0, 2);
                world.setBlock(chunkX + 10, j + 30, chunkZ + 2, Main.marbleBrick, 0, 2);
                world.setBlock(chunkX + 0, j + 30, chunkZ + 3, Main.marbleBrick, 0, 2);
                world.setBlock(chunkX + 1, j + 30, chunkZ + 3, Main.marbleBrick, 0, 2);
                world.setBlock(chunkX + 2, j + 30, chunkZ + 3, Main.marbleBrick, 0, 2);
                world.setBlock(chunkX + 3, j + 30, chunkZ + 3, Main.marbleBrick, 0, 2);
                world.setBlock(chunkX + 4, j + 30, chunkZ + 3, Main.marbleBrick, 0, 2);
                world.setBlock(chunkX + 5, j + 30, chunkZ + 3, Main.marbleBrick, 0, 2);
                world.setBlock(chunkX + 6, j + 30, chunkZ + 3, Main.marbleBrick, 0, 2);
                world.setBlock(chunkX + 7, j + 30, chunkZ + 3, Main.marbleBrick, 0, 2);
                world.setBlock(chunkX + 8, j + 30, chunkZ + 3, Main.marbleBrick, 0, 2);
                world.setBlock(chunkX + 9, j + 30, chunkZ + 3, Main.marbleBrick, 0, 2);
                world.setBlock(chunkX + 10, j + 30, chunkZ + 3, Main.marbleBrick, 0, 2);
                world.setBlock(chunkX + 0, j + 30, chunkZ + 4, Main.marbleBrick, 0, 2);
                world.setBlock(chunkX + 1, j + 30, chunkZ + 4, Main.marbleBrick, 0, 2);
                world.setBlock(chunkX + 2, j + 30, chunkZ + 4, Main.marbleBrick, 0, 2);
                world.setBlock(chunkX + 3, j + 30, chunkZ + 4, Main.marbleBrick, 0, 2);
                world.setBlock(chunkX + 4, j + 30, chunkZ + 4, Main.marbleBrick, 0, 2);
                world.setBlock(chunkX + 5, j + 30, chunkZ + 4, Main.marbleBrick, 0, 2);
                world.setBlock(chunkX + 6, j + 30, chunkZ + 4, Main.marbleBrick, 0, 2);
                world.setBlock(chunkX + 7, j + 30, chunkZ + 4, Main.marbleBrick, 0, 2);
                world.setBlock(chunkX + 8, j + 30, chunkZ + 4, Main.marbleBrick, 0, 2);
                world.setBlock(chunkX + 9, j + 30, chunkZ + 4, Main.marbleBrick, 0, 2);
                world.setBlock(chunkX + 10, j + 30, chunkZ + 4, Main.marbleBrick, 0, 2);
                world.setBlock(chunkX + 0, j + 30, chunkZ + 5, Main.marbleBrick, 0, 2);
                world.setBlock(chunkX + 1, j + 30, chunkZ + 5, Main.marbleBrick, 0, 2);
                world.setBlock(chunkX + 2, j + 30, chunkZ + 5, Main.marbleBrick, 0, 2);
                world.setBlock(chunkX + 3, j + 30, chunkZ + 5, Main.marbleBrick, 0, 2);
                world.setBlock(chunkX + 4, j + 30, chunkZ + 5, Main.marbleBrick, 0, 2);
                world.setBlock(chunkX + 5, j + 30, chunkZ + 5, Blocks.log, 0, 2);
                world.setBlock(chunkX + 6, j + 30, chunkZ + 5, Blocks.ladder, 5, 2);
                world.setBlock(chunkX + 7, j + 30, chunkZ + 5, Main.marbleBrick, 0, 2);
                world.setBlock(chunkX + 8, j + 30, chunkZ + 5, Main.marbleBrick, 0, 2);
                world.setBlock(chunkX + 9, j + 30, chunkZ + 5, Main.marbleBrick, 0, 2);
                world.setBlock(chunkX + 10, j + 30, chunkZ + 5, Main.marbleBrick, 0, 2);
                world.setBlock(chunkX + 0, j + 30, chunkZ + 6, Main.marbleBrick, 0, 2);
                world.setBlock(chunkX + 1, j + 30, chunkZ + 6, Main.marbleBrick, 0, 2);
                world.setBlock(chunkX + 2, j + 30, chunkZ + 6, Main.marbleBrick, 0, 2);
                world.setBlock(chunkX + 3, j + 30, chunkZ + 6, Main.marbleBrick, 0, 2);
                world.setBlock(chunkX + 4, j + 30, chunkZ + 6, Main.marbleBrick, 0, 2);
                world.setBlock(chunkX + 5, j + 30, chunkZ + 6, Main.marbleBrick, 0, 2);
                world.setBlock(chunkX + 6, j + 30, chunkZ + 6, Main.marbleBrick, 0, 2);
                world.setBlock(chunkX + 7, j + 30, chunkZ + 6, Main.marbleBrick, 0, 2);
                world.setBlock(chunkX + 8, j + 30, chunkZ + 6, Main.marbleBrick, 0, 2);
                world.setBlock(chunkX + 9, j + 30, chunkZ + 6, Main.marbleBrick, 0, 2);
                world.setBlock(chunkX + 10, j + 30, chunkZ + 6, Main.marbleBrick, 0, 2);
                world.setBlock(chunkX + 0, j + 30, chunkZ + 7, Main.marbleBrick, 0, 2);
                world.setBlock(chunkX + 1, j + 30, chunkZ + 7, Main.marbleBrick, 0, 2);
                world.setBlock(chunkX + 2, j + 30, chunkZ + 7, Main.marbleBrick, 0, 2);
                world.setBlock(chunkX + 3, j + 30, chunkZ + 7, Main.marbleBrick, 0, 2);
                world.setBlock(chunkX + 4, j + 30, chunkZ + 7, Main.marbleBrick, 0, 2);
                world.setBlock(chunkX + 5, j + 30, chunkZ + 7, Main.marbleBrick, 0, 2);
                world.setBlock(chunkX + 6, j + 30, chunkZ + 7, Main.marbleBrick, 0, 2);
                world.setBlock(chunkX + 7, j + 30, chunkZ + 7, Main.marbleBrick, 0, 2);
                world.setBlock(chunkX + 8, j + 30, chunkZ + 7, Main.marbleBrick, 0, 2);
                world.setBlock(chunkX + 9, j + 30, chunkZ + 7, Main.marbleBrick, 0, 2);
                world.setBlock(chunkX + 10, j + 30, chunkZ + 7, Main.marbleBrick, 0, 2);
                world.setBlock(chunkX + 0, j + 30, chunkZ + 8, Main.marbleBrick, 0, 2);
                world.setBlock(chunkX + 1, j + 30, chunkZ + 8, Main.marbleBrick, 0, 2);
                world.setBlock(chunkX + 2, j + 30, chunkZ + 8, Main.marbleBrick, 0, 2);
                world.setBlock(chunkX + 3, j + 30, chunkZ + 8, Main.marbleBrick, 0, 2);
                world.setBlock(chunkX + 4, j + 30, chunkZ + 8, Main.marbleBrick, 0, 2);
                world.setBlock(chunkX + 5, j + 30, chunkZ + 8, Main.marbleBrick, 0, 2);
                world.setBlock(chunkX + 6, j + 30, chunkZ + 8, Main.marbleBrick, 0, 2);
                world.setBlock(chunkX + 7, j + 30, chunkZ + 8, Main.marbleBrick, 0, 2);
                world.setBlock(chunkX + 8, j + 30, chunkZ + 8, Main.marbleBrick, 0, 2);
                world.setBlock(chunkX + 9, j + 30, chunkZ + 8, Main.marbleBrick, 0, 2);
                world.setBlock(chunkX + 10, j + 30, chunkZ + 8, Main.marbleBrick, 0, 2);
                world.setBlock(chunkX + 1, j + 30, chunkZ + 9, Main.marbleBrick, 0, 2);
                world.setBlock(chunkX + 2, j + 30, chunkZ + 9, Main.marbleBrick, 0, 2);
                world.setBlock(chunkX + 3, j + 30, chunkZ + 9, Main.marbleBrick, 0, 2);
                world.setBlock(chunkX + 4, j + 30, chunkZ + 9, Main.marbleBrick, 0, 2);
                world.setBlock(chunkX + 5, j + 30, chunkZ + 9, Main.marbleBrick, 0, 2);
                world.setBlock(chunkX + 6, j + 30, chunkZ + 9, Main.marbleBrick, 0, 2);
                world.setBlock(chunkX + 7, j + 30, chunkZ + 9, Main.marbleBrick, 0, 2);
                world.setBlock(chunkX + 8, j + 30, chunkZ + 9, Main.marbleBrick, 0, 2);
                world.setBlock(chunkX + 9, j + 30, chunkZ + 9, Main.marbleBrick, 0, 2);
                world.setBlock(chunkX + 2, j + 30, chunkZ + 10, Main.marbleBrick, 0, 2);
                world.setBlock(chunkX + 3, j + 30, chunkZ + 10, Main.marbleBrick, 0, 2);
                world.setBlock(chunkX + 4, j + 30, chunkZ + 10, Main.marbleBrick, 0, 2);
                world.setBlock(chunkX + 5, j + 30, chunkZ + 10, Main.marbleBrick, 0, 2);
                world.setBlock(chunkX + 6, j + 30, chunkZ + 10, Main.marbleBrick, 0, 2);
                world.setBlock(chunkX + 7, j + 30, chunkZ + 10, Main.marbleBrick, 0, 2);
                world.setBlock(chunkX + 8, j + 30, chunkZ + 10, Main.marbleBrick, 0, 2);
                world.setBlock(chunkX + 2, j + 31, chunkZ + 0, Main.whiteWoodFence, 0, 2);
                world.setBlock(chunkX + 3, j + 31, chunkZ + 0, Main.whiteWoodFence, 0, 2);
                world.setBlock(chunkX + 4, j + 31, chunkZ + 0, Main.whiteWoodFence, 0, 2);
                world.setBlock(chunkX + 5, j + 31, chunkZ + 0, Main.whiteWoodFence, 0, 2);
                world.setBlock(chunkX + 6, j + 31, chunkZ + 0, Main.whiteWoodFence, 0, 2);
                world.setBlock(chunkX + 7, j + 31, chunkZ + 0, Main.whiteWoodFence, 0, 2);
                world.setBlock(chunkX + 8, j + 31, chunkZ + 0, Main.whiteWoodFence, 0, 2);
                world.setBlock(chunkX + 2, j + 31, chunkZ + 1, Main.whiteWoodFence, 0, 2);
                world.setBlock(chunkX + 5, j + 31, chunkZ + 1, Main.bluePot, 0, 2);
                world.setBlock(chunkX + 8, j + 31, chunkZ + 1, Main.whiteWoodFence, 0, 2);
                world.setBlock(chunkX + 0, j + 31, chunkZ + 2, Main.whiteWoodFence, 0, 2);
                world.setBlock(chunkX + 1, j + 31, chunkZ + 2, Main.whiteWoodFence, 0, 2);
                world.setBlock(chunkX + 2, j + 31, chunkZ + 2, Blocks.log, 0, 2);
                world.setBlock(chunkX + 8, j + 31, chunkZ + 2, Blocks.log, 0, 2);
                world.setBlock(chunkX + 9, j + 31, chunkZ + 2, Main.whiteWoodFence, 0, 2);
                world.setBlock(chunkX + 10, j + 31, chunkZ + 2, Main.whiteWoodFence, 0, 2);
                world.setBlock(chunkX + 0, j + 31, chunkZ + 3, Main.whiteWoodFence, 0, 2);
                world.setBlock(chunkX + 10, j + 31, chunkZ + 3, Main.whiteWoodFence, 0, 2);
                world.setBlock(chunkX + 0, j + 31, chunkZ + 4, Main.whiteWoodFence, 0, 2);
                world.setBlock(chunkX + 10, j + 31, chunkZ + 4, Main.whiteWoodFence, 0, 2);
                world.setBlock(chunkX + 0, j + 31, chunkZ + 5, Main.whiteWoodFence, 0, 2);
                world.setBlock(chunkX + 1, j + 31, chunkZ + 5, Main.bluePot, 0, 2);
                world.setBlock(chunkX + 5, j + 31, chunkZ + 5, Blocks.mob_spawner, 0, 2);
                final int x = chunkX + 5;
                final int y = j + 31;
                final int z = chunkZ + 5;
                final TileEntityMobSpawner tileentitymobspawner1 = (TileEntityMobSpawner)world.getTileEntity(x, y, z);
                if (tileentitymobspawner1 != null) {
                    tileentitymobspawner1.func_145881_a().setEntityName("EntityBokoblin");
                }
                else {
                    System.err.println("Failed to fetch mob spawner entity at (" + x + ", " + y + ", " + z + ")");
                }
                world.setBlock(chunkX + 9, j + 31, chunkZ + 5, Main.bluePot, 0, 2);
                world.setBlock(chunkX + 10, j + 31, chunkZ + 5, Main.whiteWoodFence, 0, 2);
                world.setBlock(chunkX + 0, j + 31, chunkZ + 6, Main.whiteWoodFence, 0, 2);
                world.setBlock(chunkX + 10, j + 31, chunkZ + 6, Main.whiteWoodFence, 0, 2);
                world.setBlock(chunkX + 0, j + 31, chunkZ + 7, Main.whiteWoodFence, 0, 2);
                world.setBlock(chunkX + 10, j + 31, chunkZ + 7, Main.whiteWoodFence, 0, 2);
                world.setBlock(chunkX + 0, j + 31, chunkZ + 8, Main.whiteWoodFence, 0, 2);
                world.setBlock(chunkX + 1, j + 31, chunkZ + 8, Main.whiteWoodFence, 0, 2);
                world.setBlock(chunkX + 2, j + 31, chunkZ + 8, Blocks.log, 0, 2);
                world.setBlock(chunkX + 8, j + 31, chunkZ + 8, Blocks.log, 0, 2);
                world.setBlock(chunkX + 9, j + 31, chunkZ + 8, Main.whiteWoodFence, 0, 2);
                world.setBlock(chunkX + 10, j + 31, chunkZ + 8, Main.whiteWoodFence, 0, 2);
                world.setBlock(chunkX + 2, j + 31, chunkZ + 9, Main.whiteWoodFence, 0, 2);
                world.setBlock(chunkX + 5, j + 31, chunkZ + 9, Main.bluePot, 0, 2);
                world.setBlock(chunkX + 8, j + 31, chunkZ + 9, Main.whiteWoodFence, 0, 2);
                world.setBlock(chunkX + 2, j + 31, chunkZ + 10, Main.whiteWoodFence, 0, 2);
                world.setBlock(chunkX + 3, j + 31, chunkZ + 10, Main.whiteWoodFence, 0, 2);
                world.setBlock(chunkX + 4, j + 31, chunkZ + 10, Main.whiteWoodFence, 0, 2);
                world.setBlock(chunkX + 5, j + 31, chunkZ + 10, Main.whiteWoodFence, 0, 2);
                world.setBlock(chunkX + 6, j + 31, chunkZ + 10, Main.whiteWoodFence, 0, 2);
                world.setBlock(chunkX + 7, j + 31, chunkZ + 10, Main.whiteWoodFence, 0, 2);
                world.setBlock(chunkX + 8, j + 31, chunkZ + 10, Main.whiteWoodFence, 0, 2);
                world.setBlock(chunkX + 2, j + 32, chunkZ + 2, Blocks.log, 0, 2);
                world.setBlock(chunkX + 8, j + 32, chunkZ + 2, Blocks.log, 0, 2);
                world.setBlock(chunkX + 5, j + 32, chunkZ + 5, Blocks.log, 0, 2);
                world.setBlock(chunkX + 2, j + 32, chunkZ + 8, Blocks.log, 0, 2);
                world.setBlock(chunkX + 8, j + 32, chunkZ + 8, Blocks.log, 0, 2);
                world.setBlock(chunkX + 2, j + 33, chunkZ + 2, Blocks.log, 0, 2);
                world.setBlock(chunkX + 8, j + 33, chunkZ + 2, Blocks.log, 0, 2);
                world.setBlock(chunkX + 5, j + 33, chunkZ + 5, Blocks.log, 0, 2);
                world.setBlock(chunkX + 2, j + 33, chunkZ + 8, Blocks.log, 0, 2);
                world.setBlock(chunkX + 8, j + 33, chunkZ + 8, Blocks.log, 0, 2);
                world.setBlock(chunkX + 2, j + 34, chunkZ + 2, Blocks.log, 0, 2);
                world.setBlock(chunkX + 8, j + 34, chunkZ + 2, Blocks.log, 0, 2);
                world.setBlock(chunkX + 5, j + 34, chunkZ + 5, Blocks.log, 0, 2);
                world.setBlock(chunkX + 2, j + 34, chunkZ + 8, Blocks.log, 0, 2);
                world.setBlock(chunkX + 8, j + 34, chunkZ + 8, Blocks.log, 0, 2);
                world.setBlock(chunkX + 2, j + 35, chunkZ + 0, Blocks.stonebrick, 0, 2);
                world.setBlock(chunkX + 3, j + 35, chunkZ + 0, Blocks.stonebrick, 0, 2);
                world.setBlock(chunkX + 4, j + 35, chunkZ + 0, Blocks.stonebrick, 0, 2);
                world.setBlock(chunkX + 5, j + 35, chunkZ + 0, Blocks.stonebrick, 0, 2);
                world.setBlock(chunkX + 6, j + 35, chunkZ + 0, Blocks.stonebrick, 0, 2);
                world.setBlock(chunkX + 7, j + 35, chunkZ + 0, Blocks.stonebrick, 0, 2);
                world.setBlock(chunkX + 8, j + 35, chunkZ + 0, Blocks.stonebrick, 0, 2);
                world.setBlock(chunkX + 1, j + 35, chunkZ + 1, Blocks.stonebrick, 0, 2);
                world.setBlock(chunkX + 2, j + 35, chunkZ + 1, Blocks.stonebrick, 0, 2);
                world.setBlock(chunkX + 8, j + 35, chunkZ + 1, Blocks.stonebrick, 0, 2);
                world.setBlock(chunkX + 9, j + 35, chunkZ + 1, Blocks.stonebrick, 0, 2);
                world.setBlock(chunkX + 0, j + 35, chunkZ + 2, Blocks.stonebrick, 0, 2);
                world.setBlock(chunkX + 1, j + 35, chunkZ + 2, Blocks.stonebrick, 0, 2);
                world.setBlock(chunkX + 2, j + 35, chunkZ + 2, Blocks.log, 0, 2);
                world.setBlock(chunkX + 8, j + 35, chunkZ + 2, Blocks.log, 0, 2);
                world.setBlock(chunkX + 9, j + 35, chunkZ + 2, Blocks.stonebrick, 0, 2);
                world.setBlock(chunkX + 10, j + 35, chunkZ + 2, Blocks.stonebrick, 0, 2);
                world.setBlock(chunkX + 0, j + 35, chunkZ + 3, Blocks.stonebrick, 0, 2);
                world.setBlock(chunkX + 10, j + 35, chunkZ + 3, Blocks.stonebrick, 0, 2);
                world.setBlock(chunkX + 0, j + 35, chunkZ + 4, Blocks.stonebrick, 0, 2);
                world.setBlock(chunkX + 10, j + 35, chunkZ + 4, Blocks.stonebrick, 0, 2);
                world.setBlock(chunkX + 0, j + 35, chunkZ + 5, Blocks.stonebrick, 0, 2);
                world.setBlock(chunkX + 5, j + 35, chunkZ + 5, Blocks.log, 0, 2);
                world.setBlock(chunkX + 10, j + 35, chunkZ + 5, Blocks.stonebrick, 0, 2);
                world.setBlock(chunkX + 0, j + 35, chunkZ + 6, Blocks.stonebrick, 0, 2);
                world.setBlock(chunkX + 10, j + 35, chunkZ + 6, Blocks.stonebrick, 0, 2);
                world.setBlock(chunkX + 0, j + 35, chunkZ + 7, Blocks.stonebrick, 0, 2);
                world.setBlock(chunkX + 10, j + 35, chunkZ + 7, Blocks.stonebrick, 0, 2);
                world.setBlock(chunkX + 0, j + 35, chunkZ + 8, Blocks.stonebrick, 0, 2);
                world.setBlock(chunkX + 1, j + 35, chunkZ + 8, Blocks.stonebrick, 0, 2);
                world.setBlock(chunkX + 2, j + 35, chunkZ + 8, Blocks.log, 0, 2);
                world.setBlock(chunkX + 8, j + 35, chunkZ + 8, Blocks.log, 0, 2);
                world.setBlock(chunkX + 9, j + 35, chunkZ + 8, Blocks.stonebrick, 0, 2);
                world.setBlock(chunkX + 10, j + 35, chunkZ + 8, Blocks.stonebrick, 0, 2);
                world.setBlock(chunkX + 1, j + 35, chunkZ + 9, Blocks.stonebrick, 0, 2);
                world.setBlock(chunkX + 2, j + 35, chunkZ + 9, Blocks.stonebrick, 0, 2);
                world.setBlock(chunkX + 8, j + 35, chunkZ + 9, Blocks.stonebrick, 0, 2);
                world.setBlock(chunkX + 9, j + 35, chunkZ + 9, Blocks.stonebrick, 0, 2);
                world.setBlock(chunkX + 2, j + 35, chunkZ + 10, Blocks.stonebrick, 0, 2);
                world.setBlock(chunkX + 3, j + 35, chunkZ + 10, Blocks.stonebrick, 0, 2);
                world.setBlock(chunkX + 4, j + 35, chunkZ + 10, Blocks.stonebrick, 0, 2);
                world.setBlock(chunkX + 5, j + 35, chunkZ + 10, Blocks.stonebrick, 0, 2);
                world.setBlock(chunkX + 6, j + 35, chunkZ + 10, Blocks.stonebrick, 0, 2);
                world.setBlock(chunkX + 7, j + 35, chunkZ + 10, Blocks.stonebrick, 0, 2);
                world.setBlock(chunkX + 8, j + 35, chunkZ + 10, Blocks.stonebrick, 0, 2);
                world.setBlock(chunkX + 3, j + 36, chunkZ + 1, Blocks.stonebrick, 0, 2);
                world.setBlock(chunkX + 4, j + 36, chunkZ + 1, Blocks.stonebrick, 0, 2);
                world.setBlock(chunkX + 5, j + 36, chunkZ + 1, Blocks.stonebrick, 0, 2);
                world.setBlock(chunkX + 6, j + 36, chunkZ + 1, Blocks.stonebrick, 0, 2);
                world.setBlock(chunkX + 7, j + 36, chunkZ + 1, Blocks.stonebrick, 0, 2);
                world.setBlock(chunkX + 2, j + 36, chunkZ + 2, Blocks.stonebrick, 0, 2);
                world.setBlock(chunkX + 3, j + 36, chunkZ + 2, Blocks.stonebrick, 0, 2);
                world.setBlock(chunkX + 4, j + 36, chunkZ + 2, Blocks.stonebrick, 0, 2);
                world.setBlock(chunkX + 5, j + 36, chunkZ + 2, Blocks.stonebrick, 0, 2);
                world.setBlock(chunkX + 6, j + 36, chunkZ + 2, Blocks.stonebrick, 0, 2);
                world.setBlock(chunkX + 7, j + 36, chunkZ + 2, Blocks.stonebrick, 0, 2);
                world.setBlock(chunkX + 8, j + 36, chunkZ + 2, Blocks.stonebrick, 0, 2);
                world.setBlock(chunkX + 1, j + 36, chunkZ + 3, Blocks.stonebrick, 0, 2);
                world.setBlock(chunkX + 2, j + 36, chunkZ + 3, Blocks.stonebrick, 0, 2);
                world.setBlock(chunkX + 3, j + 36, chunkZ + 3, Blocks.stonebrick, 0, 2);
                world.setBlock(chunkX + 4, j + 36, chunkZ + 3, Blocks.stonebrick, 0, 2);
                world.setBlock(chunkX + 5, j + 36, chunkZ + 3, Blocks.stonebrick, 0, 2);
                world.setBlock(chunkX + 6, j + 36, chunkZ + 3, Blocks.stonebrick, 0, 2);
                world.setBlock(chunkX + 7, j + 36, chunkZ + 3, Blocks.stonebrick, 0, 2);
                world.setBlock(chunkX + 8, j + 36, chunkZ + 3, Blocks.stonebrick, 0, 2);
                world.setBlock(chunkX + 9, j + 36, chunkZ + 3, Blocks.stonebrick, 0, 2);
                world.setBlock(chunkX + 1, j + 36, chunkZ + 4, Blocks.stonebrick, 0, 2);
                world.setBlock(chunkX + 2, j + 36, chunkZ + 4, Blocks.stonebrick, 0, 2);
                world.setBlock(chunkX + 3, j + 36, chunkZ + 4, Blocks.stonebrick, 0, 2);
                world.setBlock(chunkX + 4, j + 36, chunkZ + 4, Blocks.stonebrick, 0, 2);
                world.setBlock(chunkX + 5, j + 36, chunkZ + 4, Blocks.stonebrick, 0, 2);
                world.setBlock(chunkX + 6, j + 36, chunkZ + 4, Blocks.stonebrick, 0, 2);
                world.setBlock(chunkX + 7, j + 36, chunkZ + 4, Blocks.stonebrick, 0, 2);
                world.setBlock(chunkX + 8, j + 36, chunkZ + 4, Blocks.stonebrick, 0, 2);
                world.setBlock(chunkX + 9, j + 36, chunkZ + 4, Blocks.stonebrick, 0, 2);
                world.setBlock(chunkX + 1, j + 36, chunkZ + 5, Blocks.stonebrick, 0, 2);
                world.setBlock(chunkX + 2, j + 36, chunkZ + 5, Blocks.stonebrick, 0, 2);
                world.setBlock(chunkX + 3, j + 36, chunkZ + 5, Blocks.stonebrick, 0, 2);
                world.setBlock(chunkX + 4, j + 36, chunkZ + 5, Blocks.stonebrick, 0, 2);
                world.setBlock(chunkX + 5, j + 36, chunkZ + 5, Blocks.stonebrick, 0, 2);
                world.setBlock(chunkX + 6, j + 36, chunkZ + 5, Blocks.stonebrick, 0, 2);
                world.setBlock(chunkX + 7, j + 36, chunkZ + 5, Blocks.stonebrick, 0, 2);
                world.setBlock(chunkX + 8, j + 36, chunkZ + 5, Blocks.stonebrick, 0, 2);
                world.setBlock(chunkX + 9, j + 36, chunkZ + 5, Blocks.stonebrick, 0, 2);
                world.setBlock(chunkX + 1, j + 36, chunkZ + 6, Blocks.stonebrick, 0, 2);
                world.setBlock(chunkX + 2, j + 36, chunkZ + 6, Blocks.stonebrick, 0, 2);
                world.setBlock(chunkX + 3, j + 36, chunkZ + 6, Blocks.stonebrick, 0, 2);
                world.setBlock(chunkX + 4, j + 36, chunkZ + 6, Blocks.stonebrick, 0, 2);
                world.setBlock(chunkX + 5, j + 36, chunkZ + 6, Blocks.stonebrick, 0, 2);
                world.setBlock(chunkX + 6, j + 36, chunkZ + 6, Blocks.stonebrick, 0, 2);
                world.setBlock(chunkX + 7, j + 36, chunkZ + 6, Blocks.stonebrick, 0, 2);
                world.setBlock(chunkX + 8, j + 36, chunkZ + 6, Blocks.stonebrick, 0, 2);
                world.setBlock(chunkX + 9, j + 36, chunkZ + 6, Blocks.stonebrick, 0, 2);
                world.setBlock(chunkX + 1, j + 36, chunkZ + 7, Blocks.stonebrick, 0, 2);
                world.setBlock(chunkX + 2, j + 36, chunkZ + 7, Blocks.stonebrick, 0, 2);
                world.setBlock(chunkX + 3, j + 36, chunkZ + 7, Blocks.stonebrick, 0, 2);
                world.setBlock(chunkX + 4, j + 36, chunkZ + 7, Blocks.stonebrick, 0, 2);
                world.setBlock(chunkX + 5, j + 36, chunkZ + 7, Blocks.stonebrick, 0, 2);
                world.setBlock(chunkX + 6, j + 36, chunkZ + 7, Blocks.stonebrick, 0, 2);
                world.setBlock(chunkX + 7, j + 36, chunkZ + 7, Blocks.stonebrick, 0, 2);
                world.setBlock(chunkX + 8, j + 36, chunkZ + 7, Blocks.stonebrick, 0, 2);
                world.setBlock(chunkX + 9, j + 36, chunkZ + 7, Blocks.stonebrick, 0, 2);
                world.setBlock(chunkX + 2, j + 36, chunkZ + 8, Blocks.stonebrick, 0, 2);
                world.setBlock(chunkX + 3, j + 36, chunkZ + 8, Blocks.stonebrick, 0, 2);
                world.setBlock(chunkX + 4, j + 36, chunkZ + 8, Blocks.stonebrick, 0, 2);
                world.setBlock(chunkX + 5, j + 36, chunkZ + 8, Blocks.stonebrick, 0, 2);
                world.setBlock(chunkX + 6, j + 36, chunkZ + 8, Blocks.stonebrick, 0, 2);
                world.setBlock(chunkX + 7, j + 36, chunkZ + 8, Blocks.stonebrick, 0, 2);
                world.setBlock(chunkX + 8, j + 36, chunkZ + 8, Blocks.stonebrick, 0, 2);
                world.setBlock(chunkX + 3, j + 36, chunkZ + 9, Blocks.stonebrick, 0, 2);
                world.setBlock(chunkX + 4, j + 36, chunkZ + 9, Blocks.stonebrick, 0, 2);
                world.setBlock(chunkX + 5, j + 36, chunkZ + 9, Blocks.stonebrick, 0, 2);
                world.setBlock(chunkX + 6, j + 36, chunkZ + 9, Blocks.stonebrick, 0, 2);
                world.setBlock(chunkX + 7, j + 36, chunkZ + 9, Blocks.stonebrick, 0, 2);
                world.setBlock(chunkX + 4, j + 37, chunkZ + 3, Main.marbleBrick, 0, 2);
                world.setBlock(chunkX + 5, j + 37, chunkZ + 3, Main.marbleBrick, 0, 2);
                world.setBlock(chunkX + 6, j + 37, chunkZ + 3, Main.marbleBrick, 0, 2);
                world.setBlock(chunkX + 3, j + 37, chunkZ + 4, Main.marbleBrick, 0, 2);
                world.setBlock(chunkX + 4, j + 37, chunkZ + 4, Main.marbleBrick, 0, 2);
                world.setBlock(chunkX + 5, j + 37, chunkZ + 4, Main.shaleBrick, 0, 2);
                world.setBlock(chunkX + 6, j + 37, chunkZ + 4, Main.marbleBrick, 0, 2);
                world.setBlock(chunkX + 7, j + 37, chunkZ + 4, Main.marbleBrick, 0, 2);
                world.setBlock(chunkX + 3, j + 37, chunkZ + 5, Main.marbleBrick, 0, 2);
                world.setBlock(chunkX + 4, j + 37, chunkZ + 5, Main.shaleBrick, 0, 2);
                world.setBlock(chunkX + 5, j + 37, chunkZ + 5, Main.marbleBrick, 0, 2);
                world.setBlock(chunkX + 6, j + 37, chunkZ + 5, Main.shaleBrick, 0, 2);
                world.setBlock(chunkX + 7, j + 37, chunkZ + 5, Main.marbleBrick, 0, 2);
                world.setBlock(chunkX + 3, j + 37, chunkZ + 6, Main.marbleBrick, 0, 2);
                world.setBlock(chunkX + 4, j + 37, chunkZ + 6, Main.marbleBrick, 0, 2);
                world.setBlock(chunkX + 5, j + 37, chunkZ + 6, Main.shaleBrick, 0, 2);
                world.setBlock(chunkX + 6, j + 37, chunkZ + 6, Main.marbleBrick, 0, 2);
                world.setBlock(chunkX + 7, j + 37, chunkZ + 6, Main.marbleBrick, 0, 2);
                world.setBlock(chunkX + 4, j + 37, chunkZ + 7, Main.marbleBrick, 0, 2);
                world.setBlock(chunkX + 5, j + 37, chunkZ + 7, Main.marbleBrick, 0, 2);
                world.setBlock(chunkX + 6, j + 37, chunkZ + 7, Main.marbleBrick, 0, 2);
                System.out.println("Built a guard tower at (" + chunkX + ", " + j + ", " + chunkZ + ")");
            }
        }
    }

    @Override
    protected void func_143012_a(NBTTagCompound p_143012_1_) {

    }

    @Override
    protected void func_143011_b(NBTTagCompound p_143011_1_) {

    }

    public boolean addComponentParts(final World world, final Random r, final StructureBoundingBox box) {
        this.generateSurface(world, r, this.coordBaseMode, this.coordBaseMode, this.coordBaseMode);
        return true;
    }
    
    protected void writeStructureToNBT(final NBTTagCompound p_143012_1_) {
    }
    
    protected void readStructureFromNBT(final NBTTagCompound p_143011_1_) {
    }
}
