package apocalypse.fandomcraft.structures;

import net.minecraft.world.*;
import java.util.*;
import net.minecraft.init.*;
import apocalypse.fandomcraft.main.*;
import net.minecraftforge.common.*;
import net.minecraft.util.*;
import net.minecraft.inventory.*;
import net.minecraft.tileentity.*;
import net.minecraft.world.gen.structure.*;
import net.minecraft.nbt.*;

public class DungeonWater extends StructureComponent
{
    public boolean place;
    
    public void generateSurface(final World world, final Random random, final int chunkX, final int chunkY, final int chunkZ) {
        final int h = 20 + random.nextInt(30);
        final int x = chunkX;
        final int z = chunkZ;
        final int y = world.getHeightValue(x, z) - h;
        this.place = true;
        if (this.place) {
            world.setBlock(x + 0, y + 0, z + 0, Blocks.stone, 0, 2);
            world.setBlock(x + 1, y + 0, z + 0, Blocks.stone, 0, 2);
            world.setBlock(x + 2, y + 0, z + 0, Blocks.stone, 0, 2);
            world.setBlock(x + 3, y + 0, z + 0, Blocks.stone, 0, 2);
            world.setBlock(x + 4, y + 0, z + 0, Blocks.stone, 0, 2);
            world.setBlock(x + 5, y + 0, z + 0, Blocks.stone, 0, 2);
            world.setBlock(x + 6, y + 0, z + 0, Blocks.stone, 0, 2);
            world.setBlock(x + 7, y + 0, z + 0, Blocks.stone, 0, 2);
            world.setBlock(x + 8, y + 0, z + 0, Blocks.stone, 0, 2);
            world.setBlock(x + 9, y + 0, z + 0, Blocks.stone, 0, 2);
            world.setBlock(x + 10, y + 0, z + 0, Blocks.stone, 0, 2);
            world.setBlock(x + 11, y + 0, z + 0, Blocks.stone, 0, 2);
            world.setBlock(x + 12, y + 0, z + 0, Blocks.stone, 0, 2);
            world.setBlock(x + 13, y + 0, z + 0, Blocks.stone, 0, 2);
            world.setBlock(x + 14, y + 0, z + 0, Blocks.stone, 0, 2);
            world.setBlock(x + 15, y + 0, z + 0, Blocks.stone, 0, 2);
            world.setBlock(x + 16, y + 0, z + 0, Blocks.stone, 0, 2);
            world.setBlock(x + 17, y + 0, z + 0, Blocks.stone, 0, 2);
            world.setBlock(x + 18, y + 0, z + 0, Blocks.stone, 0, 2);
            world.setBlock(x + 0, y + 0, z + 1, Blocks.stone, 0, 2);
            world.setBlock(x + 1, y + 0, z + 1, Blocks.stone, 0, 2);
            world.setBlock(x + 2, y + 0, z + 1, Blocks.stone, 0, 2);
            world.setBlock(x + 3, y + 0, z + 1, Blocks.stone, 0, 2);
            world.setBlock(x + 4, y + 0, z + 1, Blocks.stone, 0, 2);
            world.setBlock(x + 5, y + 0, z + 1, Blocks.stone, 0, 2);
            world.setBlock(x + 6, y + 0, z + 1, Blocks.stone, 0, 2);
            world.setBlock(x + 7, y + 0, z + 1, Blocks.water, 0, 2);
            world.setBlock(x + 8, y + 0, z + 1, Blocks.water, 0, 2);
            world.setBlock(x + 9, y + 0, z + 1, Blocks.water, 0, 2);
            world.setBlock(x + 10, y + 0, z + 1, Blocks.stone, 0, 2);
            world.setBlock(x + 11, y + 0, z + 1, Blocks.stone, 0, 2);
            world.setBlock(x + 12, y + 0, z + 1, Blocks.stone, 0, 2);
            world.setBlock(x + 13, y + 0, z + 1, Blocks.water, 0, 2);
            world.setBlock(x + 14, y + 0, z + 1, Blocks.water, 0, 2);
            world.setBlock(x + 15, y + 0, z + 1, Blocks.water, 0, 2);
            world.setBlock(x + 16, y + 0, z + 1, Blocks.water, 0, 2);
            world.setBlock(x + 17, y + 0, z + 1, Blocks.water, 0, 2);
            world.setBlock(x + 18, y + 0, z + 1, Blocks.stone, 0, 2);
            world.setBlock(x + 0, y + 0, z + 2, Blocks.stone, 0, 2);
            world.setBlock(x + 1, y + 0, z + 2, Blocks.stone, 0, 2);
            world.setBlock(x + 2, y + 0, z + 2, Blocks.stone, 0, 2);
            world.setBlock(x + 3, y + 0, z + 2, Blocks.stone, 0, 2);
            world.setBlock(x + 4, y + 0, z + 2, Blocks.stone, 0, 2);
            world.setBlock(x + 5, y + 0, z + 2, Blocks.stone, 0, 2);
            world.setBlock(x + 6, y + 0, z + 2, Blocks.stone, 0, 2);
            world.setBlock(x + 7, y + 0, z + 2, Blocks.water, 0, 2);
            world.setBlock(x + 8, y + 0, z + 2, Blocks.water, 0, 2);
            world.setBlock(x + 9, y + 0, z + 2, Blocks.water, 0, 2);
            world.setBlock(x + 10, y + 0, z + 2, Blocks.stone, 0, 2);
            world.setBlock(x + 11, y + 0, z + 2, Blocks.stone, 0, 2);
            world.setBlock(x + 12, y + 0, z + 2, Blocks.stone, 0, 2);
            world.setBlock(x + 13, y + 0, z + 2, Blocks.water, 0, 2);
            world.setBlock(x + 14, y + 0, z + 2, Blocks.water, 0, 2);
            world.setBlock(x + 15, y + 0, z + 2, Blocks.water, 0, 2);
            world.setBlock(x + 16, y + 0, z + 2, Blocks.water, 0, 2);
            world.setBlock(x + 17, y + 0, z + 2, Blocks.water, 0, 2);
            world.setBlock(x + 18, y + 0, z + 2, Blocks.stone, 0, 2);
            world.setBlock(x + 0, y + 0, z + 3, Blocks.stone, 0, 2);
            world.setBlock(x + 1, y + 0, z + 3, Blocks.water, 0, 2);
            world.setBlock(x + 2, y + 0, z + 3, Blocks.water, 0, 2);
            world.setBlock(x + 3, y + 0, z + 3, Blocks.water, 0, 2);
            world.setBlock(x + 4, y + 0, z + 3, Blocks.stone, 0, 2);
            world.setBlock(x + 5, y + 0, z + 3, Blocks.stone, 0, 2);
            world.setBlock(x + 6, y + 0, z + 3, Blocks.stone, 0, 2);
            world.setBlock(x + 7, y + 0, z + 3, Blocks.water, 0, 2);
            world.setBlock(x + 8, y + 0, z + 3, Blocks.water, 0, 2);
            world.setBlock(x + 9, y + 0, z + 3, Blocks.water, 0, 2);
            world.setBlock(x + 10, y + 0, z + 3, Blocks.water, 0, 2);
            world.setBlock(x + 11, y + 0, z + 3, Blocks.water, 0, 2);
            world.setBlock(x + 12, y + 0, z + 3, Blocks.water, 0, 2);
            world.setBlock(x + 13, y + 0, z + 3, Blocks.water, 0, 2);
            world.setBlock(x + 14, y + 0, z + 3, Blocks.water, 0, 2);
            world.setBlock(x + 15, y + 0, z + 3, Blocks.water, 0, 2);
            world.setBlock(x + 16, y + 0, z + 3, Blocks.stone, 0, 2);
            world.setBlock(x + 17, y + 0, z + 3, Blocks.stone, 0, 2);
            world.setBlock(x + 18, y + 0, z + 3, Blocks.stone, 0, 2);
            world.setBlock(x + 0, y + 0, z + 4, Blocks.stone, 0, 2);
            world.setBlock(x + 1, y + 0, z + 4, Blocks.water, 0, 2);
            world.setBlock(x + 2, y + 0, z + 4, Blocks.water, 0, 2);
            world.setBlock(x + 3, y + 0, z + 4, Blocks.water, 0, 2);
            world.setBlock(x + 4, y + 0, z + 4, Blocks.stone, 0, 2);
            world.setBlock(x + 5, y + 0, z + 4, Blocks.water, 0, 2);
            world.setBlock(x + 6, y + 0, z + 4, Blocks.water, 0, 2);
            world.setBlock(x + 7, y + 0, z + 4, Main.aquaOre, 0, 2);
            world.setBlock(x + 8, y + 0, z + 4, Blocks.water, 0, 2);
            world.setBlock(x + 9, y + 0, z + 4, Blocks.water, 0, 2);
            world.setBlock(x + 10, y + 0, z + 4, Blocks.water, 0, 2);
            world.setBlock(x + 11, y + 0, z + 4, Blocks.water, 0, 2);
            world.setBlock(x + 12, y + 0, z + 4, Blocks.water, 0, 2);
            world.setBlock(x + 13, y + 0, z + 4, Blocks.water, 0, 2);
            world.setBlock(x + 14, y + 0, z + 4, Blocks.water, 0, 2);
            world.setBlock(x + 15, y + 0, z + 4, Blocks.water, 0, 2);
            world.setBlock(x + 16, y + 0, z + 4, Blocks.stone, 0, 2);
            world.setBlock(x + 17, y + 0, z + 4, Blocks.stone, 0, 2);
            world.setBlock(x + 18, y + 0, z + 4, Blocks.stone, 0, 2);
            world.setBlock(x + 0, y + 0, z + 5, Blocks.stone, 0, 2);
            world.setBlock(x + 1, y + 0, z + 5, Blocks.water, 0, 2);
            world.setBlock(x + 2, y + 0, z + 5, Blocks.water, 0, 2);
            world.setBlock(x + 3, y + 0, z + 5, Blocks.water, 0, 2);
            world.setBlock(x + 4, y + 0, z + 5, Blocks.water, 0, 2);
            world.setBlock(x + 5, y + 0, z + 5, Blocks.water, 0, 2);
            world.setBlock(x + 6, y + 0, z + 5, Blocks.water, 0, 2);
            world.setBlock(x + 7, y + 0, z + 5, Blocks.water, 0, 2);
            world.setBlock(x + 8, y + 0, z + 5, Blocks.water, 0, 2);
            world.setBlock(x + 9, y + 0, z + 5, Blocks.water, 0, 2);
            world.setBlock(x + 10, y + 0, z + 5, Blocks.water, 0, 2);
            world.setBlock(x + 11, y + 0, z + 5, Blocks.water, 0, 2);
            world.setBlock(x + 12, y + 0, z + 5, Blocks.water, 0, 2);
            world.setBlock(x + 13, y + 0, z + 5, Blocks.water, 0, 2);
            world.setBlock(x + 14, y + 0, z + 5, Blocks.water, 0, 2);
            world.setBlock(x + 15, y + 0, z + 5, Blocks.water, 0, 2);
            world.setBlock(x + 16, y + 0, z + 5, Blocks.stone, 0, 2);
            world.setBlock(x + 17, y + 0, z + 5, Blocks.stone, 0, 2);
            world.setBlock(x + 18, y + 0, z + 5, Blocks.stone, 0, 2);
            world.setBlock(x + 0, y + 0, z + 6, Blocks.stone, 0, 2);
            world.setBlock(x + 1, y + 0, z + 6, Blocks.stone, 0, 2);
            world.setBlock(x + 2, y + 0, z + 6, Blocks.stone, 0, 2);
            world.setBlock(x + 3, y + 0, z + 6, Blocks.stone, 0, 2);
            world.setBlock(x + 4, y + 0, z + 6, Blocks.stone, 0, 2);
            world.setBlock(x + 5, y + 0, z + 6, Blocks.stone, 0, 2);
            world.setBlock(x + 6, y + 0, z + 6, Blocks.stone, 0, 2);
            world.setBlock(x + 7, y + 0, z + 6, Blocks.water, 0, 2);
            world.setBlock(x + 8, y + 0, z + 6, Blocks.water, 0, 2);
            world.setBlock(x + 9, y + 0, z + 6, Blocks.water, 0, 2);
            world.setBlock(x + 10, y + 0, z + 6, Blocks.water, 0, 2);
            world.setBlock(x + 11, y + 0, z + 6, Blocks.water, 0, 2);
            world.setBlock(x + 12, y + 0, z + 6, Blocks.water, 0, 2);
            world.setBlock(x + 13, y + 0, z + 6, Blocks.water, 0, 2);
            world.setBlock(x + 14, y + 0, z + 6, Blocks.water, 0, 2);
            world.setBlock(x + 15, y + 0, z + 6, Blocks.water, 0, 2);
            world.setBlock(x + 16, y + 0, z + 6, Blocks.water, 0, 2);
            world.setBlock(x + 17, y + 0, z + 6, Blocks.water, 0, 2);
            world.setBlock(x + 18, y + 0, z + 6, Blocks.stone, 0, 2);
            world.setBlock(x + 0, y + 0, z + 7, Blocks.stone, 0, 2);
            world.setBlock(x + 1, y + 0, z + 7, Blocks.stone, 0, 2);
            world.setBlock(x + 2, y + 0, z + 7, Blocks.stone, 0, 2);
            world.setBlock(x + 3, y + 0, z + 7, Blocks.stone, 0, 2);
            world.setBlock(x + 4, y + 0, z + 7, Blocks.stone, 0, 2);
            world.setBlock(x + 5, y + 0, z + 7, Blocks.stone, 0, 2);
            world.setBlock(x + 6, y + 0, z + 7, Blocks.stone, 0, 2);
            world.setBlock(x + 7, y + 0, z + 7, Blocks.stone, 0, 2);
            world.setBlock(x + 8, y + 0, z + 7, Blocks.stone, 0, 2);
            world.setBlock(x + 9, y + 0, z + 7, Blocks.stone, 0, 2);
            world.setBlock(x + 10, y + 0, z + 7, Blocks.stone, 0, 2);
            world.setBlock(x + 11, y + 0, z + 7, Blocks.stone, 0, 2);
            world.setBlock(x + 12, y + 0, z + 7, Blocks.stone, 0, 2);
            world.setBlock(x + 13, y + 0, z + 7, Blocks.water, 0, 2);
            world.setBlock(x + 14, y + 0, z + 7, Blocks.water, 0, 2);
            world.setBlock(x + 15, y + 0, z + 7, Blocks.water, 0, 2);
            world.setBlock(x + 16, y + 0, z + 7, Blocks.water, 0, 2);
            world.setBlock(x + 17, y + 0, z + 7, Blocks.water, 0, 2);
            world.setBlock(x + 18, y + 0, z + 7, Blocks.stone, 0, 2);
            world.setBlock(x + 0, y + 0, z + 8, Blocks.stone, 0, 2);
            world.setBlock(x + 1, y + 0, z + 8, Blocks.stone, 0, 2);
            world.setBlock(x + 2, y + 0, z + 8, Blocks.stone, 0, 2);
            world.setBlock(x + 3, y + 0, z + 8, Blocks.stone, 0, 2);
            world.setBlock(x + 4, y + 0, z + 8, Blocks.stone, 0, 2);
            world.setBlock(x + 5, y + 0, z + 8, Blocks.water, 0, 2);
            world.setBlock(x + 6, y + 0, z + 8, Blocks.water, 0, 2);
            world.setBlock(x + 7, y + 0, z + 8, Blocks.water, 0, 2);
            world.setBlock(x + 8, y + 0, z + 8, Blocks.stone, 0, 2);
            world.setBlock(x + 9, y + 0, z + 8, Blocks.stone, 0, 2);
            world.setBlock(x + 10, y + 0, z + 8, Blocks.stone, 0, 2);
            world.setBlock(x + 11, y + 0, z + 8, Blocks.water, 0, 2);
            world.setBlock(x + 12, y + 0, z + 8, Blocks.water, 0, 2);
            world.setBlock(x + 13, y + 0, z + 8, Blocks.water, 0, 2);
            world.setBlock(x + 14, y + 0, z + 8, Blocks.water, 0, 2);
            world.setBlock(x + 15, y + 0, z + 8, Blocks.water, 0, 2);
            world.setBlock(x + 16, y + 0, z + 8, Blocks.water, 0, 2);
            world.setBlock(x + 17, y + 0, z + 8, Blocks.water, 0, 2);
            world.setBlock(x + 18, y + 0, z + 8, Blocks.stone, 0, 2);
            world.setBlock(x + 0, y + 0, z + 9, Blocks.stone, 0, 2);
            world.setBlock(x + 1, y + 0, z + 9, Blocks.tnt, 0, 2);
            world.setBlock(x + 2, y + 0, z + 9, Blocks.tnt, 0, 2);
            world.setBlock(x + 3, y + 0, z + 9, Blocks.stone, 0, 2);
            world.setBlock(x + 4, y + 0, z + 9, Blocks.stone, 0, 2);
            world.setBlock(x + 5, y + 0, z + 9, Blocks.water, 0, 2);
            world.setBlock(x + 6, y + 0, z + 9, Blocks.water, 0, 2);
            world.setBlock(x + 7, y + 0, z + 9, Blocks.water, 0, 2);
            world.setBlock(x + 8, y + 0, z + 9, Blocks.stone, 0, 2);
            world.setBlock(x + 9, y + 0, z + 9, Blocks.stone, 0, 2);
            world.setBlock(x + 10, y + 0, z + 9, Blocks.stone, 0, 2);
            world.setBlock(x + 11, y + 0, z + 9, Blocks.water, 0, 2);
            world.setBlock(x + 12, y + 0, z + 9, Blocks.water, 0, 2);
            world.setBlock(x + 13, y + 0, z + 9, Blocks.water, 0, 2);
            world.setBlock(x + 14, y + 0, z + 9, Blocks.water, 0, 2);
            world.setBlock(x + 15, y + 0, z + 9, Blocks.water, 0, 2);
            world.setBlock(x + 16, y + 0, z + 9, Blocks.stone, 0, 2);
            world.setBlock(x + 17, y + 0, z + 9, Blocks.stone, 0, 2);
            world.setBlock(x + 18, y + 0, z + 9, Blocks.stone, 0, 2);
            world.setBlock(x + 0, y + 0, z + 10, Blocks.stone, 0, 2);
            world.setBlock(x + 1, y + 0, z + 10, Blocks.tnt, 0, 2);
            world.setBlock(x + 2, y + 0, z + 10, Blocks.tnt, 0, 2);
            world.setBlock(x + 3, y + 0, z + 10, Blocks.stone, 0, 2);
            world.setBlock(x + 4, y + 0, z + 10, Blocks.stone, 0, 2);
            world.setBlock(x + 5, y + 0, z + 10, Blocks.water, 0, 2);
            world.setBlock(x + 6, y + 0, z + 10, Blocks.water, 0, 2);
            world.setBlock(x + 7, y + 0, z + 10, Blocks.water, 0, 2);
            world.setBlock(x + 8, y + 0, z + 10, Blocks.stone, 0, 2);
            world.setBlock(x + 9, y + 0, z + 10, Blocks.stone, 0, 2);
            world.setBlock(x + 10, y + 0, z + 10, Blocks.stone, 0, 2);
            world.setBlock(x + 11, y + 0, z + 10, Blocks.water, 0, 2);
            world.setBlock(x + 12, y + 0, z + 10, Blocks.water, 0, 2);
            world.setBlock(x + 13, y + 0, z + 10, Blocks.water, 0, 2);
            world.setBlock(x + 14, y + 0, z + 10, Blocks.water, 0, 2);
            world.setBlock(x + 15, y + 0, z + 10, Blocks.stone, 0, 2);
            world.setBlock(x + 16, y + 0, z + 10, Blocks.stone, 0, 2);
            world.setBlock(x + 17, y + 0, z + 10, Blocks.stone, 0, 2);
            world.setBlock(x + 18, y + 0, z + 10, Blocks.stone, 0, 2);
            world.setBlock(x + 0, y + 0, z + 11, Blocks.stone, 0, 2);
            world.setBlock(x + 1, y + 0, z + 11, Blocks.tnt, 0, 2);
            world.setBlock(x + 2, y + 0, z + 11, Blocks.tnt, 0, 2);
            world.setBlock(x + 3, y + 0, z + 11, Blocks.stone, 0, 2);
            world.setBlock(x + 4, y + 0, z + 11, Blocks.stone, 0, 2);
            world.setBlock(x + 5, y + 0, z + 11, Blocks.water, 0, 2);
            world.setBlock(x + 6, y + 0, z + 11, Blocks.water, 0, 2);
            world.setBlock(x + 7, y + 0, z + 11, Blocks.water, 0, 2);
            world.setBlock(x + 8, y + 0, z + 11, Blocks.stone, 0, 2);
            world.setBlock(x + 9, y + 0, z + 11, Blocks.stone, 0, 2);
            world.setBlock(x + 10, y + 0, z + 11, Blocks.stone, 0, 2);
            world.setBlock(x + 11, y + 0, z + 11, Blocks.water, 0, 2);
            world.setBlock(x + 12, y + 0, z + 11, Blocks.water, 0, 2);
            world.setBlock(x + 13, y + 0, z + 11, Blocks.water, 0, 2);
            world.setBlock(x + 14, y + 0, z + 11, Blocks.water, 0, 2);
            world.setBlock(x + 15, y + 0, z + 11, Blocks.stone, 0, 2);
            world.setBlock(x + 16, y + 0, z + 11, Blocks.stone, 0, 2);
            world.setBlock(x + 17, y + 0, z + 11, Blocks.stone, 0, 2);
            world.setBlock(x + 18, y + 0, z + 11, Blocks.stone, 0, 2);
            world.setBlock(x + 0, y + 0, z + 12, Blocks.stone, 0, 2);
            world.setBlock(x + 1, y + 0, z + 12, Blocks.stone, 0, 2);
            world.setBlock(x + 2, y + 0, z + 12, Blocks.stone, 0, 2);
            world.setBlock(x + 3, y + 0, z + 12, Blocks.stone, 0, 2);
            world.setBlock(x + 4, y + 0, z + 12, Blocks.stone, 0, 2);
            world.setBlock(x + 5, y + 0, z + 12, Blocks.stone, 0, 2);
            world.setBlock(x + 6, y + 0, z + 12, Blocks.stone, 0, 2);
            world.setBlock(x + 7, y + 0, z + 12, Blocks.stone, 0, 2);
            world.setBlock(x + 8, y + 0, z + 12, Blocks.stone, 0, 2);
            world.setBlock(x + 9, y + 0, z + 12, Blocks.stone, 0, 2);
            world.setBlock(x + 10, y + 0, z + 12, Blocks.stone, 0, 2);
            world.setBlock(x + 11, y + 0, z + 12, Blocks.stone, 0, 2);
            world.setBlock(x + 12, y + 0, z + 12, Blocks.stone, 0, 2);
            world.setBlock(x + 13, y + 0, z + 12, Blocks.stone, 0, 2);
            world.setBlock(x + 14, y + 0, z + 12, Blocks.stone, 0, 2);
            world.setBlock(x + 15, y + 0, z + 12, Blocks.stone, 0, 2);
            world.setBlock(x + 16, y + 0, z + 12, Blocks.stone, 0, 2);
            world.setBlock(x + 17, y + 0, z + 12, Blocks.stone, 0, 2);
            world.setBlock(x + 18, y + 0, z + 12, Blocks.stone, 0, 2);
            world.setBlock(x + 0, y + 1, z + 0, Blocks.stone, 0, 2);
            world.setBlock(x + 1, y + 1, z + 0, Blocks.stone, 0, 2);
            world.setBlock(x + 2, y + 1, z + 0, Blocks.stone, 0, 2);
            world.setBlock(x + 3, y + 1, z + 0, Blocks.stone, 0, 2);
            world.setBlock(x + 4, y + 1, z + 0, Blocks.stone, 0, 2);
            world.setBlock(x + 5, y + 1, z + 0, Blocks.stone, 0, 2);
            world.setBlock(x + 6, y + 1, z + 0, Blocks.stone, 0, 2);
            world.setBlock(x + 7, y + 1, z + 0, Blocks.stone, 0, 2);
            world.setBlock(x + 8, y + 1, z + 0, Blocks.stone, 0, 2);
            world.setBlock(x + 9, y + 1, z + 0, Blocks.stone, 0, 2);
            world.setBlock(x + 10, y + 1, z + 0, Blocks.stone, 0, 2);
            world.setBlock(x + 11, y + 1, z + 0, Blocks.stone, 0, 2);
            world.setBlock(x + 12, y + 1, z + 0, Blocks.stone, 0, 2);
            world.setBlock(x + 13, y + 1, z + 0, Blocks.stone, 0, 2);
            world.setBlock(x + 14, y + 1, z + 0, Blocks.stone, 0, 2);
            world.setBlock(x + 15, y + 1, z + 0, Blocks.stone, 0, 2);
            world.setBlock(x + 16, y + 1, z + 0, Blocks.stone, 0, 2);
            world.setBlock(x + 17, y + 1, z + 0, Blocks.stone, 0, 2);
            world.setBlock(x + 18, y + 1, z + 0, Blocks.stone, 0, 2);
            world.setBlock(x + 0, y + 1, z + 1, Blocks.stone, 0, 2);
            world.setBlock(x + 1, y + 1, z + 1, Blocks.air, 0, 2);
            world.setBlock(x + 2, y + 1, z + 1, Blocks.trapped_chest, 3, 2);
            final int xx = x + 2;
            final int yy = y + 1;
            final int zz = z + 1;
            final TileEntityChest tileentitychest = (TileEntityChest)world.getTileEntity(xx, yy, zz);
            if (tileentitychest != null) {
                WeightedRandomChestContent.generateChestContents(random, ChestGenHooks.getItems("dungeonChest", random), (IInventory)tileentitychest, ChestGenHooks.getCount("dungeonChest", random));
            }
            world.setBlock(x + 3, y + 1, z + 1, Blocks.air, 0, 2);
            world.setBlock(x + 4, y + 1, z + 1, Blocks.stone, 0, 2);
            world.setBlock(x + 5, y + 1, z + 1, Blocks.air, 0, 2);
            world.setBlock(x + 6, y + 1, z + 1, Main.bluePot, 0, 2);
            world.setBlock(x + 7, y + 1, z + 1, Blocks.air, 0, 2);
            world.setBlock(x + 8, y + 1, z + 1, Blocks.air, 0, 2);
            world.setBlock(x + 9, y + 1, z + 1, Blocks.air, 0, 2);
            world.setBlock(x + 10, y + 1, z + 1, Blocks.air, 0, 2);
            world.setBlock(x + 11, y + 1, z + 1, Blocks.stone, 0, 2);
            world.setBlock(x + 12, y + 1, z + 1, Blocks.air, 0, 2);
            world.setBlock(x + 13, y + 1, z + 1, Blocks.air, 0, 2);
            world.setBlock(x + 14, y + 1, z + 1, Blocks.air, 0, 2);
            world.setBlock(x + 15, y + 1, z + 1, Blocks.air, 0, 2);
            world.setBlock(x + 16, y + 1, z + 1, Blocks.air, 0, 2);
            world.setBlock(x + 17, y + 1, z + 1, Blocks.air, 0, 2);
            world.setBlock(x + 18, y + 1, z + 1, Blocks.stone, 0, 2);
            world.setBlock(x + 0, y + 1, z + 2, Blocks.stone, 0, 2);
            world.setBlock(x + 1, y + 1, z + 2, Blocks.air, 0, 2);
            world.setBlock(x + 2, y + 1, z + 2, Blocks.air, 0, 2);
            world.setBlock(x + 3, y + 1, z + 2, Blocks.air, 0, 2);
            world.setBlock(x + 4, y + 1, z + 2, Blocks.stone, 0, 2);
            world.setBlock(x + 5, y + 1, z + 2, Blocks.air, 0, 2);
            world.setBlock(x + 6, y + 1, z + 2, Blocks.air, 0, 2);
            world.setBlock(x + 7, y + 1, z + 2, Blocks.air, 0, 2);
            world.setBlock(x + 8, y + 1, z + 2, Blocks.air, 0, 2);
            world.setBlock(x + 9, y + 1, z + 2, Blocks.air, 0, 2);
            world.setBlock(x + 10, y + 1, z + 2, Blocks.air, 0, 2);
            world.setBlock(x + 11, y + 1, z + 2, Blocks.air, 0, 2);
            world.setBlock(x + 12, y + 1, z + 2, Blocks.air, 0, 2);
            world.setBlock(x + 13, y + 1, z + 2, Blocks.air, 0, 2);
            world.setBlock(x + 14, y + 1, z + 2, Blocks.air, 0, 2);
            world.setBlock(x + 15, y + 1, z + 2, Blocks.air, 0, 2);
            world.setBlock(x + 16, y + 1, z + 2, Blocks.air, 0, 2);
            world.setBlock(x + 17, y + 1, z + 2, Blocks.air, 0, 2);
            world.setBlock(x + 18, y + 1, z + 2, Blocks.stone, 0, 2);
            world.setBlock(x + 0, y + 1, z + 3, Blocks.stone, 0, 2);
            world.setBlock(x + 1, y + 1, z + 3, Blocks.air, 0, 2);
            world.setBlock(x + 2, y + 1, z + 3, Blocks.air, 0, 2);
            world.setBlock(x + 3, y + 1, z + 3, Blocks.air, 0, 2);
            world.setBlock(x + 4, y + 1, z + 3, Blocks.stone, 0, 2);
            world.setBlock(x + 5, y + 1, z + 3, Main.bluePot, 0, 2);
            world.setBlock(x + 6, y + 1, z + 3, Blocks.air, 0, 2);
            world.setBlock(x + 7, y + 1, z + 3, Blocks.air, 0, 2);
            world.setBlock(x + 8, y + 1, z + 3, Blocks.air, 0, 2);
            world.setBlock(x + 9, y + 1, z + 3, Blocks.air, 0, 2);
            world.setBlock(x + 10, y + 1, z + 3, Blocks.air, 0, 2);
            world.setBlock(x + 11, y + 1, z + 3, Blocks.air, 0, 2);
            world.setBlock(x + 12, y + 1, z + 3, Blocks.air, 0, 2);
            world.setBlock(x + 13, y + 1, z + 3, Blocks.air, 0, 2);
            world.setBlock(x + 14, y + 1, z + 3, Blocks.air, 0, 2);
            world.setBlock(x + 15, y + 1, z + 3, Blocks.air, 0, 2);
            world.setBlock(x + 16, y + 1, z + 3, Blocks.air, 0, 2);
            world.setBlock(x + 17, y + 1, z + 3, Main.bluePot, 0, 2);
            world.setBlock(x + 18, y + 1, z + 3, Blocks.stone, 0, 2);
            world.setBlock(x + 0, y + 1, z + 4, Blocks.stone, 0, 2);
            world.setBlock(x + 1, y + 1, z + 4, Blocks.air, 0, 2);
            world.setBlock(x + 2, y + 1, z + 4, Blocks.air, 0, 2);
            world.setBlock(x + 3, y + 1, z + 4, Blocks.air, 0, 2);
            world.setBlock(x + 4, y + 1, z + 4, Blocks.stone, 0, 2);
            world.setBlock(x + 5, y + 1, z + 4, Blocks.air, 0, 2);
            world.setBlock(x + 6, y + 1, z + 4, Blocks.air, 0, 2);
            world.setBlock(x + 7, y + 1, z + 4, Blocks.air, 0, 2);
            world.setBlock(x + 8, y + 1, z + 4, Blocks.air, 0, 2);
            world.setBlock(x + 9, y + 1, z + 4, Blocks.air, 0, 2);
            world.setBlock(x + 10, y + 1, z + 4, Blocks.air, 0, 2);
            world.setBlock(x + 11, y + 1, z + 4, Blocks.air, 0, 2);
            world.setBlock(x + 12, y + 1, z + 4, Blocks.air, 0, 2);
            world.setBlock(x + 13, y + 1, z + 4, Blocks.air, 0, 2);
            world.setBlock(x + 14, y + 1, z + 4, Blocks.air, 0, 2);
            world.setBlock(x + 15, y + 1, z + 4, Blocks.air, 0, 2);
            world.setBlock(x + 16, y + 1, z + 4, Blocks.air, 0, 2);
            world.setBlock(x + 17, y + 1, z + 4, Main.bluePot, 0, 2);
            world.setBlock(x + 18, y + 1, z + 4, Blocks.stone, 0, 2);
            world.setBlock(x + 0, y + 1, z + 5, Blocks.stone, 0, 2);
            world.setBlock(x + 1, y + 1, z + 5, Blocks.air, 0, 2);
            world.setBlock(x + 2, y + 1, z + 5, Blocks.air, 0, 2);
            world.setBlock(x + 3, y + 1, z + 5, Blocks.air, 0, 2);
            world.setBlock(x + 4, y + 1, z + 5, Blocks.air, 0, 2);
            world.setBlock(x + 5, y + 1, z + 5, Blocks.air, 0, 2);
            world.setBlock(x + 6, y + 1, z + 5, Blocks.air, 0, 2);
            world.setBlock(x + 7, y + 1, z + 5, Blocks.air, 0, 2);
            world.setBlock(x + 8, y + 1, z + 5, Blocks.air, 0, 2);
            world.setBlock(x + 9, y + 1, z + 5, Blocks.air, 0, 2);
            world.setBlock(x + 10, y + 1, z + 5, Blocks.air, 0, 2);
            world.setBlock(x + 11, y + 1, z + 5, Blocks.air, 0, 2);
            world.setBlock(x + 12, y + 1, z + 5, Blocks.air, 0, 2);
            world.setBlock(x + 13, y + 1, z + 5, Blocks.air, 0, 2);
            world.setBlock(x + 14, y + 1, z + 5, Blocks.air, 0, 2);
            world.setBlock(x + 15, y + 1, z + 5, Blocks.air, 0, 2);
            world.setBlock(x + 16, y + 1, z + 5, Blocks.air, 0, 2);
            world.setBlock(x + 17, y + 1, z + 5, Blocks.air, 0, 2);
            world.setBlock(x + 18, y + 1, z + 5, Blocks.stone, 0, 2);
            world.setBlock(x + 0, y + 1, z + 6, Blocks.stone, 0, 2);
            world.setBlock(x + 1, y + 1, z + 6, Blocks.air, 0, 2);
            world.setBlock(x + 2, y + 1, z + 6, Blocks.air, 0, 2);
            world.setBlock(x + 3, y + 1, z + 6, Blocks.air, 0, 2);
            world.setBlock(x + 4, y + 1, z + 6, Blocks.stone, 0, 2);
            world.setBlock(x + 5, y + 1, z + 6, Blocks.air, 0, 2);
            world.setBlock(x + 6, y + 1, z + 6, Blocks.air, 0, 2);
            world.setBlock(x + 7, y + 1, z + 6, Blocks.air, 0, 2);
            world.setBlock(x + 8, y + 1, z + 6, Blocks.air, 0, 2);
            world.setBlock(x + 9, y + 1, z + 6, Blocks.air, 0, 2);
            world.setBlock(x + 10, y + 1, z + 6, Blocks.air, 0, 2);
            world.setBlock(x + 11, y + 1, z + 6, Blocks.air, 0, 2);
            world.setBlock(x + 12, y + 1, z + 6, Blocks.air, 0, 2);
            world.setBlock(x + 13, y + 1, z + 6, Blocks.air, 0, 2);
            world.setBlock(x + 14, y + 1, z + 6, Blocks.air, 0, 2);
            world.setBlock(x + 15, y + 1, z + 6, Blocks.air, 0, 2);
            world.setBlock(x + 16, y + 1, z + 6, Blocks.air, 0, 2);
            world.setBlock(x + 17, y + 1, z + 6, Blocks.air, 0, 2);
            world.setBlock(x + 18, y + 1, z + 6, Blocks.stone, 0, 2);
            world.setBlock(x + 0, y + 1, z + 7, Blocks.stone, 0, 2);
            world.setBlock(x + 1, y + 1, z + 7, Blocks.stone, 0, 2);
            world.setBlock(x + 2, y + 1, z + 7, Blocks.stone, 0, 2);
            world.setBlock(x + 3, y + 1, z + 7, Blocks.stone, 0, 2);
            world.setBlock(x + 4, y + 1, z + 7, Blocks.stone, 0, 2);
            world.setBlock(x + 5, y + 1, z + 7, Blocks.stone, 0, 2);
            world.setBlock(x + 6, y + 1, z + 7, Blocks.stone, 0, 2);
            world.setBlock(x + 7, y + 1, z + 7, Blocks.stone, 0, 2);
            world.setBlock(x + 8, y + 1, z + 7, Blocks.stone, 0, 2);
            world.setBlock(x + 9, y + 1, z + 7, Blocks.mob_spawner, 0, 2);
            final int x2 = x + 9;
            final int y2 = y + 1;
            final int z2 = z + 7;
            final TileEntityMobSpawner tileentitymobspawner = (TileEntityMobSpawner)world.getTileEntity(x2, y2, z2);
            if (tileentitymobspawner != null) {
                tileentitymobspawner.func_145881_a().setEntityName("IceKeese");
            }
            else {
                System.err.println("Failed to fetch mob spawner entity at (" + x2 + ", " + y2 + ", " + z2 + ")");
            }
            world.setBlock(x + 10, y + 1, z + 7, Blocks.stone, 0, 2);
            world.setBlock(x + 11, y + 1, z + 7, Blocks.stone, 0, 2);
            world.setBlock(x + 12, y + 1, z + 7, Blocks.stone, 0, 2);
            world.setBlock(x + 13, y + 1, z + 7, Blocks.air, 0, 2);
            world.setBlock(x + 14, y + 1, z + 7, Blocks.air, 0, 2);
            world.setBlock(x + 15, y + 1, z + 7, Blocks.air, 0, 2);
            world.setBlock(x + 16, y + 1, z + 7, Blocks.air, 0, 2);
            world.setBlock(x + 17, y + 1, z + 7, Blocks.air, 0, 2);
            world.setBlock(x + 18, y + 1, z + 7, Blocks.stone, 0, 2);
            world.setBlock(x + 0, y + 1, z + 8, Blocks.stone, 0, 2);
            world.setBlock(x + 1, y + 1, z + 8, Blocks.stone, 0, 2);
            world.setBlock(x + 2, y + 1, z + 8, Blocks.stone, 0, 2);
            world.setBlock(x + 3, y + 1, z + 8, Blocks.stone, 0, 2);
            world.setBlock(x + 4, y + 1, z + 8, Blocks.stone, 0, 2);
            world.setBlock(x + 5, y + 1, z + 8, Blocks.air, 0, 2);
            world.setBlock(x + 6, y + 1, z + 8, Blocks.air, 0, 2);
            world.setBlock(x + 7, y + 1, z + 8, Blocks.air, 0, 2);
            world.setBlock(x + 8, y + 1, z + 8, Main.bluePot, 0, 2);
            world.setBlock(x + 9, y + 1, z + 8, Blocks.air, 0, 2);
            world.setBlock(x + 10, y + 1, z + 8, Blocks.air, 0, 2);
            world.setBlock(x + 11, y + 1, z + 8, Blocks.air, 0, 2);
            world.setBlock(x + 12, y + 1, z + 8, Blocks.air, 0, 2);
            world.setBlock(x + 13, y + 1, z + 8, Blocks.air, 0, 2);
            world.setBlock(x + 14, y + 1, z + 8, Blocks.air, 0, 2);
            world.setBlock(x + 15, y + 1, z + 8, Blocks.air, 0, 2);
            world.setBlock(x + 16, y + 1, z + 8, Blocks.air, 0, 2);
            world.setBlock(x + 17, y + 1, z + 8, Blocks.air, 0, 2);
            world.setBlock(x + 18, y + 1, z + 8, Blocks.stone, 0, 2);
            world.setBlock(x + 0, y + 1, z + 9, Blocks.stone, 0, 2);
            world.setBlock(x + 1, y + 1, z + 9, Blocks.stone, 0, 2);
            world.setBlock(x + 2, y + 1, z + 9, Blocks.stone, 0, 2);
            world.setBlock(x + 3, y + 1, z + 9, Blocks.air, 0, 2);
            world.setBlock(x + 4, y + 1, z + 9, Blocks.air, 0, 2);
            world.setBlock(x + 5, y + 1, z + 9, Blocks.air, 0, 2);
            world.setBlock(x + 6, y + 1, z + 9, Blocks.air, 0, 2);
            world.setBlock(x + 7, y + 1, z + 9, Blocks.air, 0, 2);
            world.setBlock(x + 8, y + 1, z + 9, Blocks.air, 0, 2);
            world.setBlock(x + 9, y + 1, z + 9, Blocks.air, 0, 2);
            world.setBlock(x + 10, y + 1, z + 9, Blocks.air, 0, 2);
            world.setBlock(x + 11, y + 1, z + 9, Blocks.air, 0, 2);
            world.setBlock(x + 12, y + 1, z + 9, Blocks.air, 0, 2);
            world.setBlock(x + 13, y + 1, z + 9, Blocks.air, 0, 2);
            world.setBlock(x + 14, y + 1, z + 9, Blocks.air, 0, 2);
            world.setBlock(x + 15, y + 1, z + 9, Blocks.air, 0, 2);
            world.setBlock(x + 16, y + 1, z + 9, Blocks.air, 0, 2);
            world.setBlock(x + 17, y + 1, z + 9, Blocks.air, 0, 2);
            world.setBlock(x + 18, y + 1, z + 9, Blocks.stone, 0, 2);
            world.setBlock(x + 0, y + 1, z + 10, Blocks.stone, 0, 2);
            world.setBlock(x + 1, y + 1, z + 10, Blocks.stone, 0, 2);
            world.setBlock(x + 2, y + 1, z + 10, Blocks.stone, 0, 2);
            world.setBlock(x + 3, y + 1, z + 10, Blocks.air, 0, 2);
            world.setBlock(x + 4, y + 1, z + 10, Blocks.air, 0, 2);
            world.setBlock(x + 5, y + 1, z + 10, Blocks.air, 0, 2);
            world.setBlock(x + 6, y + 1, z + 10, Blocks.air, 0, 2);
            world.setBlock(x + 7, y + 1, z + 10, Blocks.air, 0, 2);
            world.setBlock(x + 8, y + 1, z + 10, Blocks.air, 0, 2);
            world.setBlock(x + 9, y + 1, z + 10, Blocks.air, 0, 2);
            world.setBlock(x + 10, y + 1, z + 10, Blocks.air, 0, 2);
            world.setBlock(x + 11, y + 1, z + 10, Blocks.air, 0, 2);
            world.setBlock(x + 12, y + 1, z + 10, Blocks.air, 0, 2);
            world.setBlock(x + 13, y + 1, z + 10, Blocks.air, 0, 2);
            world.setBlock(x + 14, y + 1, z + 10, Blocks.air, 0, 2);
            world.setBlock(x + 15, y + 1, z + 10, Blocks.air, 0, 2);
            world.setBlock(x + 16, y + 1, z + 10, Blocks.air, 0, 2);
            world.setBlock(x + 17, y + 1, z + 10, Main.bluePot, 0, 2);
            world.setBlock(x + 18, y + 1, z + 10, Blocks.stone, 0, 2);
            world.setBlock(x + 0, y + 1, z + 11, Blocks.stone, 0, 2);
            world.setBlock(x + 1, y + 1, z + 11, Blocks.stone, 0, 2);
            world.setBlock(x + 2, y + 1, z + 11, Blocks.stone, 0, 2);
            world.setBlock(x + 3, y + 1, z + 11, Blocks.air, 0, 2);
            world.setBlock(x + 4, y + 1, z + 11, Blocks.air, 0, 2);
            world.setBlock(x + 5, y + 1, z + 11, Blocks.air, 0, 2);
            world.setBlock(x + 6, y + 1, z + 11, Blocks.air, 0, 2);
            world.setBlock(x + 7, y + 1, z + 11, Blocks.air, 0, 2);
            world.setBlock(x + 8, y + 1, z + 11, Blocks.air, 0, 2);
            world.setBlock(x + 9, y + 1, z + 11, Blocks.air, 0, 2);
            world.setBlock(x + 10, y + 1, z + 11, Blocks.air, 0, 2);
            world.setBlock(x + 11, y + 1, z + 11, Blocks.air, 0, 2);
            world.setBlock(x + 12, y + 1, z + 11, Blocks.air, 0, 2);
            world.setBlock(x + 13, y + 1, z + 11, Blocks.air, 0, 2);
            world.setBlock(x + 14, y + 1, z + 11, Blocks.air, 0, 2);
            world.setBlock(x + 15, y + 1, z + 11, Blocks.air, 0, 2);
            world.setBlock(x + 16, y + 1, z + 11, Main.bluePot, 0, 2);
            world.setBlock(x + 17, y + 1, z + 11, Blocks.air, 0, 2);
            world.setBlock(x + 18, y + 1, z + 11, Blocks.stone, 0, 2);
            world.setBlock(x + 0, y + 1, z + 12, Blocks.stone, 0, 2);
            world.setBlock(x + 1, y + 1, z + 12, Blocks.stone, 0, 2);
            world.setBlock(x + 2, y + 1, z + 12, Blocks.stone, 0, 2);
            world.setBlock(x + 3, y + 1, z + 12, Blocks.stone, 0, 2);
            world.setBlock(x + 4, y + 1, z + 12, Blocks.stone, 0, 2);
            world.setBlock(x + 5, y + 1, z + 12, Blocks.stone, 0, 2);
            world.setBlock(x + 6, y + 1, z + 12, Blocks.stone, 0, 2);
            world.setBlock(x + 7, y + 1, z + 12, Blocks.stone, 0, 2);
            world.setBlock(x + 8, y + 1, z + 12, Blocks.stone, 0, 2);
            world.setBlock(x + 9, y + 1, z + 12, Blocks.stone, 0, 2);
            world.setBlock(x + 10, y + 1, z + 12, Blocks.stone, 0, 2);
            world.setBlock(x + 11, y + 1, z + 12, Blocks.stone, 0, 2);
            world.setBlock(x + 12, y + 1, z + 12, Blocks.stone, 0, 2);
            world.setBlock(x + 13, y + 1, z + 12, Blocks.stone, 0, 2);
            world.setBlock(x + 14, y + 1, z + 12, Blocks.stone, 0, 2);
            world.setBlock(x + 15, y + 1, z + 12, Blocks.stone, 0, 2);
            world.setBlock(x + 16, y + 1, z + 12, Blocks.stone, 0, 2);
            world.setBlock(x + 17, y + 1, z + 12, Blocks.stone, 0, 2);
            world.setBlock(x + 18, y + 1, z + 12, Blocks.stone, 0, 2);
            world.setBlock(x + 0, y + 2, z + 0, Blocks.stone, 0, 2);
            world.setBlock(x + 1, y + 2, z + 0, Blocks.stone, 0, 2);
            world.setBlock(x + 2, y + 2, z + 0, Blocks.stone, 0, 2);
            world.setBlock(x + 3, y + 2, z + 0, Blocks.stone, 0, 2);
            world.setBlock(x + 4, y + 2, z + 0, Blocks.stone, 0, 2);
            world.setBlock(x + 5, y + 2, z + 0, Blocks.stone, 0, 2);
            world.setBlock(x + 6, y + 2, z + 0, Blocks.stone, 0, 2);
            world.setBlock(x + 7, y + 2, z + 0, Blocks.stone, 0, 2);
            world.setBlock(x + 8, y + 2, z + 0, Blocks.stone, 0, 2);
            world.setBlock(x + 9, y + 2, z + 0, Blocks.stone, 0, 2);
            world.setBlock(x + 10, y + 2, z + 0, Blocks.stone, 0, 2);
            world.setBlock(x + 11, y + 2, z + 0, Blocks.stone, 0, 2);
            world.setBlock(x + 12, y + 2, z + 0, Blocks.stone, 0, 2);
            world.setBlock(x + 13, y + 2, z + 0, Blocks.stone, 0, 2);
            world.setBlock(x + 14, y + 2, z + 0, Blocks.stone, 0, 2);
            world.setBlock(x + 15, y + 2, z + 0, Blocks.stone, 0, 2);
            world.setBlock(x + 16, y + 2, z + 0, Blocks.stone, 0, 2);
            world.setBlock(x + 17, y + 2, z + 0, Blocks.stone, 0, 2);
            world.setBlock(x + 18, y + 2, z + 0, Blocks.stone, 0, 2);
            world.setBlock(x + 0, y + 2, z + 1, Blocks.stone, 0, 2);
            world.setBlock(x + 1, y + 2, z + 1, Blocks.air, 0, 2);
            world.setBlock(x + 2, y + 2, z + 1, Blocks.air, 0, 2);
            world.setBlock(x + 3, y + 2, z + 1, Blocks.air, 0, 2);
            world.setBlock(x + 4, y + 2, z + 1, Blocks.stone, 0, 2);
            world.setBlock(x + 5, y + 2, z + 1, Blocks.air, 0, 2);
            world.setBlock(x + 6, y + 2, z + 1, Blocks.air, 0, 2);
            world.setBlock(x + 7, y + 2, z + 1, Blocks.air, 0, 2);
            world.setBlock(x + 8, y + 2, z + 1, Blocks.air, 0, 2);
            world.setBlock(x + 9, y + 2, z + 1, Blocks.air, 0, 2);
            world.setBlock(x + 10, y + 2, z + 1, Blocks.air, 0, 2);
            world.setBlock(x + 11, y + 2, z + 1, Blocks.stone, 0, 2);
            world.setBlock(x + 12, y + 2, z + 1, Blocks.air, 0, 2);
            world.setBlock(x + 13, y + 2, z + 1, Blocks.air, 0, 2);
            world.setBlock(x + 14, y + 2, z + 1, Blocks.air, 0, 2);
            world.setBlock(x + 15, y + 2, z + 1, Blocks.air, 0, 2);
            world.setBlock(x + 16, y + 2, z + 1, Blocks.air, 0, 2);
            world.setBlock(x + 17, y + 2, z + 1, Blocks.air, 0, 2);
            world.setBlock(x + 18, y + 2, z + 1, Blocks.stone, 0, 2);
            world.setBlock(x + 0, y + 2, z + 2, Blocks.stone, 0, 2);
            world.setBlock(x + 1, y + 2, z + 2, Blocks.air, 0, 2);
            world.setBlock(x + 2, y + 2, z + 2, Blocks.air, 0, 2);
            world.setBlock(x + 3, y + 2, z + 2, Blocks.air, 0, 2);
            world.setBlock(x + 4, y + 2, z + 2, Blocks.stone, 0, 2);
            world.setBlock(x + 5, y + 2, z + 2, Blocks.air, 0, 2);
            world.setBlock(x + 6, y + 2, z + 2, Blocks.air, 0, 2);
            world.setBlock(x + 7, y + 2, z + 2, Blocks.air, 0, 2);
            world.setBlock(x + 8, y + 2, z + 2, Blocks.air, 0, 2);
            world.setBlock(x + 9, y + 2, z + 2, Blocks.air, 0, 2);
            world.setBlock(x + 10, y + 2, z + 2, Blocks.air, 0, 2);
            world.setBlock(x + 11, y + 2, z + 2, Blocks.air, 0, 2);
            world.setBlock(x + 12, y + 2, z + 2, Blocks.air, 0, 2);
            world.setBlock(x + 13, y + 2, z + 2, Blocks.air, 0, 2);
            world.setBlock(x + 14, y + 2, z + 2, Blocks.air, 0, 2);
            world.setBlock(x + 15, y + 2, z + 2, Blocks.air, 0, 2);
            world.setBlock(x + 16, y + 2, z + 2, Blocks.air, 0, 2);
            world.setBlock(x + 17, y + 2, z + 2, Blocks.air, 0, 2);
            world.setBlock(x + 18, y + 2, z + 2, Blocks.stone, 0, 2);
            world.setBlock(x + 0, y + 2, z + 3, Blocks.stone, 0, 2);
            world.setBlock(x + 1, y + 2, z + 3, Blocks.air, 0, 2);
            world.setBlock(x + 2, y + 2, z + 3, Blocks.air, 0, 2);
            world.setBlock(x + 3, y + 2, z + 3, Blocks.air, 0, 2);
            world.setBlock(x + 4, y + 2, z + 3, Blocks.stone, 0, 2);
            world.setBlock(x + 5, y + 2, z + 3, Blocks.air, 0, 2);
            world.setBlock(x + 6, y + 2, z + 3, Blocks.air, 0, 2);
            world.setBlock(x + 7, y + 2, z + 3, Blocks.air, 0, 2);
            world.setBlock(x + 8, y + 2, z + 3, Blocks.air, 0, 2);
            world.setBlock(x + 9, y + 2, z + 3, Blocks.air, 0, 2);
            world.setBlock(x + 10, y + 2, z + 3, Blocks.air, 0, 2);
            world.setBlock(x + 11, y + 2, z + 3, Blocks.air, 0, 2);
            world.setBlock(x + 12, y + 2, z + 3, Blocks.air, 0, 2);
            world.setBlock(x + 13, y + 2, z + 3, Blocks.air, 0, 2);
            world.setBlock(x + 14, y + 2, z + 3, Blocks.air, 0, 2);
            world.setBlock(x + 15, y + 2, z + 3, Blocks.air, 0, 2);
            world.setBlock(x + 16, y + 2, z + 3, Blocks.air, 0, 2);
            world.setBlock(x + 17, y + 2, z + 3, Blocks.air, 0, 2);
            world.setBlock(x + 18, y + 2, z + 3, Blocks.stone, 0, 2);
            world.setBlock(x + 0, y + 2, z + 4, Blocks.stone, 0, 2);
            world.setBlock(x + 1, y + 2, z + 4, Blocks.air, 0, 2);
            world.setBlock(x + 2, y + 2, z + 4, Blocks.air, 0, 2);
            world.setBlock(x + 3, y + 2, z + 4, Blocks.air, 0, 2);
            world.setBlock(x + 4, y + 2, z + 4, Blocks.stone, 0, 2);
            world.setBlock(x + 5, y + 2, z + 4, Blocks.air, 0, 2);
            world.setBlock(x + 6, y + 2, z + 4, Blocks.air, 0, 2);
            world.setBlock(x + 7, y + 2, z + 4, Blocks.air, 0, 2);
            world.setBlock(x + 8, y + 2, z + 4, Blocks.air, 0, 2);
            world.setBlock(x + 9, y + 2, z + 4, Blocks.air, 0, 2);
            world.setBlock(x + 10, y + 2, z + 4, Blocks.air, 0, 2);
            world.setBlock(x + 11, y + 2, z + 4, Blocks.air, 0, 2);
            world.setBlock(x + 12, y + 2, z + 4, Blocks.air, 0, 2);
            world.setBlock(x + 13, y + 2, z + 4, Blocks.air, 0, 2);
            world.setBlock(x + 14, y + 2, z + 4, Blocks.air, 0, 2);
            world.setBlock(x + 15, y + 2, z + 4, Blocks.air, 0, 2);
            world.setBlock(x + 16, y + 2, z + 4, Blocks.air, 0, 2);
            world.setBlock(x + 17, y + 2, z + 4, Blocks.air, 0, 2);
            world.setBlock(x + 18, y + 2, z + 4, Blocks.stone, 0, 2);
            world.setBlock(x + 0, y + 2, z + 5, Blocks.stone, 0, 2);
            world.setBlock(x + 1, y + 2, z + 5, Blocks.air, 0, 2);
            world.setBlock(x + 2, y + 2, z + 5, Blocks.air, 0, 2);
            world.setBlock(x + 3, y + 2, z + 5, Blocks.air, 0, 2);
            world.setBlock(x + 4, y + 2, z + 5, Blocks.air, 0, 2);
            world.setBlock(x + 5, y + 2, z + 5, Blocks.air, 0, 2);
            world.setBlock(x + 6, y + 2, z + 5, Blocks.air, 0, 2);
            world.setBlock(x + 7, y + 2, z + 5, Blocks.air, 0, 2);
            world.setBlock(x + 8, y + 2, z + 5, Blocks.air, 0, 2);
            world.setBlock(x + 9, y + 2, z + 5, Blocks.air, 0, 2);
            world.setBlock(x + 10, y + 2, z + 5, Blocks.air, 0, 2);
            world.setBlock(x + 11, y + 2, z + 5, Blocks.air, 0, 2);
            world.setBlock(x + 12, y + 2, z + 5, Blocks.air, 0, 2);
            world.setBlock(x + 13, y + 2, z + 5, Blocks.air, 0, 2);
            world.setBlock(x + 14, y + 2, z + 5, Blocks.air, 0, 2);
            world.setBlock(x + 15, y + 2, z + 5, Blocks.air, 0, 2);
            world.setBlock(x + 16, y + 2, z + 5, Blocks.air, 0, 2);
            world.setBlock(x + 17, y + 2, z + 5, Blocks.air, 0, 2);
            world.setBlock(x + 18, y + 2, z + 5, Blocks.stone, 0, 2);
            world.setBlock(x + 0, y + 2, z + 6, Blocks.stone, 0, 2);
            world.setBlock(x + 1, y + 2, z + 6, Blocks.air, 0, 2);
            world.setBlock(x + 2, y + 2, z + 6, Blocks.air, 0, 2);
            world.setBlock(x + 3, y + 2, z + 6, Blocks.air, 0, 2);
            world.setBlock(x + 4, y + 2, z + 6, Blocks.stone, 0, 2);
            world.setBlock(x + 5, y + 2, z + 6, Blocks.air, 0, 2);
            world.setBlock(x + 6, y + 2, z + 6, Blocks.air, 0, 2);
            world.setBlock(x + 7, y + 2, z + 6, Blocks.air, 0, 2);
            world.setBlock(x + 8, y + 2, z + 6, Blocks.air, 0, 2);
            world.setBlock(x + 9, y + 2, z + 6, Blocks.air, 0, 2);
            world.setBlock(x + 10, y + 2, z + 6, Blocks.air, 0, 2);
            world.setBlock(x + 11, y + 2, z + 6, Blocks.air, 0, 2);
            world.setBlock(x + 12, y + 2, z + 6, Blocks.air, 0, 2);
            world.setBlock(x + 13, y + 2, z + 6, Blocks.air, 0, 2);
            world.setBlock(x + 14, y + 2, z + 6, Blocks.air, 0, 2);
            world.setBlock(x + 15, y + 2, z + 6, Blocks.air, 0, 2);
            world.setBlock(x + 16, y + 2, z + 6, Blocks.air, 0, 2);
            world.setBlock(x + 17, y + 2, z + 6, Blocks.air, 0, 2);
            world.setBlock(x + 18, y + 2, z + 6, Blocks.stone, 0, 2);
            world.setBlock(x + 0, y + 2, z + 7, Blocks.stone, 0, 2);
            world.setBlock(x + 1, y + 2, z + 7, Blocks.stone, 0, 2);
            world.setBlock(x + 2, y + 2, z + 7, Blocks.stone, 0, 2);
            world.setBlock(x + 3, y + 2, z + 7, Blocks.stone, 0, 2);
            world.setBlock(x + 4, y + 2, z + 7, Blocks.stone, 0, 2);
            world.setBlock(x + 5, y + 2, z + 7, Blocks.stone, 0, 2);
            world.setBlock(x + 6, y + 2, z + 7, Blocks.stone, 0, 2);
            world.setBlock(x + 7, y + 2, z + 7, Blocks.stone, 0, 2);
            world.setBlock(x + 8, y + 2, z + 7, Blocks.stone, 0, 2);
            world.setBlock(x + 9, y + 2, z + 7, Blocks.stone, 0, 2);
            world.setBlock(x + 10, y + 2, z + 7, Blocks.stone, 0, 2);
            world.setBlock(x + 11, y + 2, z + 7, Blocks.stone, 0, 2);
            world.setBlock(x + 12, y + 2, z + 7, Blocks.stone, 0, 2);
            world.setBlock(x + 13, y + 2, z + 7, Blocks.stone, 0, 2);
            world.setBlock(x + 14, y + 2, z + 7, Blocks.air, 0, 2);
            world.setBlock(x + 15, y + 2, z + 7, Blocks.air, 0, 2);
            world.setBlock(x + 16, y + 2, z + 7, Blocks.air, 0, 2);
            world.setBlock(x + 17, y + 2, z + 7, Blocks.air, 0, 2);
            world.setBlock(x + 18, y + 2, z + 7, Blocks.stone, 0, 2);
            world.setBlock(x + 0, y + 2, z + 8, Blocks.stone, 0, 2);
            world.setBlock(x + 1, y + 2, z + 8, Blocks.stone, 0, 2);
            world.setBlock(x + 2, y + 2, z + 8, Blocks.stone, 0, 2);
            world.setBlock(x + 3, y + 2, z + 8, Blocks.stone, 0, 2);
            world.setBlock(x + 4, y + 2, z + 8, Blocks.stone, 0, 2);
            world.setBlock(x + 5, y + 2, z + 8, Blocks.air, 0, 2);
            world.setBlock(x + 6, y + 2, z + 8, Blocks.air, 0, 2);
            world.setBlock(x + 7, y + 2, z + 8, Blocks.air, 0, 2);
            world.setBlock(x + 8, y + 2, z + 8, Blocks.air, 0, 2);
            world.setBlock(x + 9, y + 2, z + 8, Blocks.air, 0, 2);
            world.setBlock(x + 10, y + 2, z + 8, Blocks.air, 0, 2);
            world.setBlock(x + 11, y + 2, z + 8, Blocks.air, 0, 2);
            world.setBlock(x + 12, y + 2, z + 8, Blocks.air, 0, 2);
            world.setBlock(x + 13, y + 2, z + 8, Blocks.air, 0, 2);
            world.setBlock(x + 14, y + 2, z + 8, Blocks.air, 0, 2);
            world.setBlock(x + 15, y + 2, z + 8, Blocks.air, 0, 2);
            world.setBlock(x + 16, y + 2, z + 8, Blocks.air, 0, 2);
            world.setBlock(x + 17, y + 2, z + 8, Blocks.air, 0, 2);
            world.setBlock(x + 18, y + 2, z + 8, Blocks.stone, 0, 2);
            world.setBlock(x + 0, y + 2, z + 9, Blocks.stone, 0, 2);
            world.setBlock(x + 1, y + 2, z + 9, Blocks.air, 0, 2);
            world.setBlock(x + 2, y + 2, z + 9, Blocks.air, 0, 2);
            world.setBlock(x + 3, y + 2, z + 9, Blocks.air, 0, 2);
            world.setBlock(x + 4, y + 2, z + 9, Blocks.air, 0, 2);
            world.setBlock(x + 5, y + 2, z + 9, Blocks.air, 0, 2);
            world.setBlock(x + 6, y + 2, z + 9, Blocks.air, 0, 2);
            world.setBlock(x + 7, y + 2, z + 9, Blocks.air, 0, 2);
            world.setBlock(x + 8, y + 2, z + 9, Blocks.air, 0, 2);
            world.setBlock(x + 9, y + 2, z + 9, Blocks.air, 0, 2);
            world.setBlock(x + 10, y + 2, z + 9, Blocks.air, 0, 2);
            world.setBlock(x + 11, y + 2, z + 9, Blocks.air, 0, 2);
            world.setBlock(x + 12, y + 2, z + 9, Blocks.air, 0, 2);
            world.setBlock(x + 13, y + 2, z + 9, Blocks.air, 0, 2);
            world.setBlock(x + 14, y + 2, z + 9, Blocks.air, 0, 2);
            world.setBlock(x + 15, y + 2, z + 9, Blocks.air, 0, 2);
            world.setBlock(x + 16, y + 2, z + 9, Blocks.air, 0, 2);
            world.setBlock(x + 17, y + 2, z + 9, Blocks.air, 0, 2);
            world.setBlock(x + 18, y + 2, z + 9, Blocks.stone, 0, 2);
            world.setBlock(x + 0, y + 2, z + 10, Blocks.stone, 0, 2);
            world.setBlock(x + 1, y + 2, z + 10, Blocks.trapped_chest, 5, 2);
            final int xx2 = x + 1;
            final int yy2 = y + 2;
            final int zz2 = z + 10;
            final TileEntityChest tileentitychest2 = (TileEntityChest)world.getTileEntity(xx, yy, zz);
            if (tileentitychest2 != null) {
                WeightedRandomChestContent.generateChestContents(random, ChestGenHooks.getItems("dungeonChest", random), (IInventory)tileentitychest2, ChestGenHooks.getCount("dungeonChest", random));
            }
            world.setBlock(x + 2, y + 2, z + 10, Blocks.air, 0, 2);
            world.setBlock(x + 3, y + 2, z + 10, Blocks.air, 0, 2);
            world.setBlock(x + 4, y + 2, z + 10, Blocks.air, 0, 2);
            world.setBlock(x + 5, y + 2, z + 10, Blocks.air, 0, 2);
            world.setBlock(x + 6, y + 2, z + 10, Blocks.air, 0, 2);
            world.setBlock(x + 7, y + 2, z + 10, Blocks.air, 0, 2);
            world.setBlock(x + 8, y + 2, z + 10, Blocks.air, 0, 2);
            world.setBlock(x + 9, y + 2, z + 10, Blocks.air, 0, 2);
            world.setBlock(x + 10, y + 2, z + 10, Blocks.air, 0, 2);
            world.setBlock(x + 11, y + 2, z + 10, Blocks.air, 0, 2);
            world.setBlock(x + 12, y + 2, z + 10, Blocks.air, 0, 2);
            world.setBlock(x + 13, y + 2, z + 10, Blocks.air, 0, 2);
            world.setBlock(x + 14, y + 2, z + 10, Blocks.air, 0, 2);
            world.setBlock(x + 15, y + 2, z + 10, Blocks.air, 0, 2);
            world.setBlock(x + 16, y + 2, z + 10, Blocks.air, 0, 2);
            world.setBlock(x + 17, y + 2, z + 10, Blocks.air, 0, 2);
            world.setBlock(x + 18, y + 2, z + 10, Blocks.stone, 0, 2);
            world.setBlock(x + 0, y + 2, z + 11, Blocks.stone, 0, 2);
            world.setBlock(x + 1, y + 2, z + 11, Blocks.air, 0, 2);
            world.setBlock(x + 2, y + 2, z + 11, Blocks.air, 0, 2);
            world.setBlock(x + 3, y + 2, z + 11, Blocks.air, 0, 2);
            world.setBlock(x + 4, y + 2, z + 11, Blocks.air, 0, 2);
            world.setBlock(x + 5, y + 2, z + 11, Blocks.air, 0, 2);
            world.setBlock(x + 6, y + 2, z + 11, Blocks.air, 0, 2);
            world.setBlock(x + 7, y + 2, z + 11, Blocks.air, 0, 2);
            world.setBlock(x + 8, y + 2, z + 11, Blocks.air, 0, 2);
            world.setBlock(x + 9, y + 2, z + 11, Blocks.air, 0, 2);
            world.setBlock(x + 10, y + 2, z + 11, Blocks.air, 0, 2);
            world.setBlock(x + 11, y + 2, z + 11, Blocks.air, 0, 2);
            world.setBlock(x + 12, y + 2, z + 11, Blocks.air, 0, 2);
            world.setBlock(x + 13, y + 2, z + 11, Blocks.air, 0, 2);
            world.setBlock(x + 14, y + 2, z + 11, Blocks.air, 0, 2);
            world.setBlock(x + 15, y + 2, z + 11, Blocks.air, 0, 2);
            world.setBlock(x + 16, y + 2, z + 11, Blocks.air, 0, 2);
            world.setBlock(x + 17, y + 2, z + 11, Blocks.air, 0, 2);
            world.setBlock(x + 18, y + 2, z + 11, Blocks.stone, 0, 2);
            world.setBlock(x + 0, y + 2, z + 12, Blocks.stone, 0, 2);
            world.setBlock(x + 1, y + 2, z + 12, Blocks.stone, 0, 2);
            world.setBlock(x + 2, y + 2, z + 12, Blocks.stone, 0, 2);
            world.setBlock(x + 3, y + 2, z + 12, Blocks.stone, 0, 2);
            world.setBlock(x + 4, y + 2, z + 12, Blocks.stone, 0, 2);
            world.setBlock(x + 5, y + 2, z + 12, Blocks.stone, 0, 2);
            world.setBlock(x + 6, y + 2, z + 12, Blocks.stone, 0, 2);
            world.setBlock(x + 7, y + 2, z + 12, Blocks.stone, 0, 2);
            world.setBlock(x + 8, y + 2, z + 12, Blocks.stone, 0, 2);
            world.setBlock(x + 9, y + 2, z + 12, Blocks.stone, 0, 2);
            world.setBlock(x + 10, y + 2, z + 12, Blocks.stone, 0, 2);
            world.setBlock(x + 11, y + 2, z + 12, Blocks.stone, 0, 2);
            world.setBlock(x + 12, y + 2, z + 12, Blocks.stone, 0, 2);
            world.setBlock(x + 13, y + 2, z + 12, Blocks.stone, 0, 2);
            world.setBlock(x + 14, y + 2, z + 12, Blocks.stone, 0, 2);
            world.setBlock(x + 15, y + 2, z + 12, Blocks.stone, 0, 2);
            world.setBlock(x + 16, y + 2, z + 12, Blocks.stone, 0, 2);
            world.setBlock(x + 17, y + 2, z + 12, Blocks.stone, 0, 2);
            world.setBlock(x + 18, y + 2, z + 12, Blocks.stone, 0, 2);
            world.setBlock(x + 0, y + 3, z + 0, Blocks.stone, 0, 2);
            world.setBlock(x + 1, y + 3, z + 0, Blocks.stone, 0, 2);
            world.setBlock(x + 2, y + 3, z + 0, Blocks.stone, 0, 2);
            world.setBlock(x + 3, y + 3, z + 0, Blocks.stone, 0, 2);
            world.setBlock(x + 4, y + 3, z + 0, Blocks.stone, 0, 2);
            world.setBlock(x + 5, y + 3, z + 0, Blocks.stone, 0, 2);
            world.setBlock(x + 6, y + 3, z + 0, Blocks.stone, 0, 2);
            world.setBlock(x + 7, y + 3, z + 0, Blocks.stone, 0, 2);
            world.setBlock(x + 8, y + 3, z + 0, Blocks.stone, 0, 2);
            world.setBlock(x + 9, y + 3, z + 0, Blocks.stone, 0, 2);
            world.setBlock(x + 10, y + 3, z + 0, Blocks.stone, 0, 2);
            world.setBlock(x + 11, y + 3, z + 0, Blocks.stone, 0, 2);
            world.setBlock(x + 12, y + 3, z + 0, Blocks.stone, 0, 2);
            world.setBlock(x + 13, y + 3, z + 0, Blocks.stone, 0, 2);
            world.setBlock(x + 14, y + 3, z + 0, Blocks.stone, 0, 2);
            world.setBlock(x + 15, y + 3, z + 0, Blocks.stone, 0, 2);
            world.setBlock(x + 16, y + 3, z + 0, Blocks.stone, 0, 2);
            world.setBlock(x + 17, y + 3, z + 0, Blocks.stone, 0, 2);
            world.setBlock(x + 18, y + 3, z + 0, Blocks.stone, 0, 2);
            world.setBlock(x + 0, y + 3, z + 1, Blocks.stone, 0, 2);
            world.setBlock(x + 1, y + 3, z + 1, Blocks.air, 0, 2);
            world.setBlock(x + 2, y + 3, z + 1, Blocks.air, 0, 2);
            world.setBlock(x + 3, y + 3, z + 1, Blocks.air, 0, 2);
            world.setBlock(x + 4, y + 3, z + 1, Blocks.stone, 0, 2);
            world.setBlock(x + 5, y + 3, z + 1, Blocks.air, 0, 2);
            world.setBlock(x + 6, y + 3, z + 1, Blocks.air, 0, 2);
            world.setBlock(x + 7, y + 3, z + 1, Blocks.air, 0, 2);
            world.setBlock(x + 8, y + 3, z + 1, Blocks.air, 0, 2);
            world.setBlock(x + 9, y + 3, z + 1, Blocks.air, 0, 2);
            world.setBlock(x + 10, y + 3, z + 1, Blocks.air, 0, 2);
            world.setBlock(x + 11, y + 3, z + 1, Main.bluePot, 0, 2);
            world.setBlock(x + 12, y + 3, z + 1, Blocks.air, 0, 2);
            world.setBlock(x + 13, y + 3, z + 1, Blocks.air, 0, 2);
            world.setBlock(x + 14, y + 3, z + 1, Blocks.air, 0, 2);
            world.setBlock(x + 15, y + 3, z + 1, Blocks.air, 0, 2);
            world.setBlock(x + 16, y + 3, z + 1, Blocks.air, 0, 2);
            world.setBlock(x + 17, y + 3, z + 1, Blocks.air, 0, 2);
            world.setBlock(x + 18, y + 3, z + 1, Blocks.stone, 0, 2);
            world.setBlock(x + 0, y + 3, z + 2, Blocks.stone, 0, 2);
            world.setBlock(x + 1, y + 3, z + 2, Blocks.air, 0, 2);
            world.setBlock(x + 2, y + 3, z + 2, Blocks.air, 0, 2);
            world.setBlock(x + 3, y + 3, z + 2, Blocks.air, 0, 2);
            world.setBlock(x + 4, y + 3, z + 2, Blocks.stone, 0, 2);
            world.setBlock(x + 5, y + 3, z + 2, Blocks.air, 0, 2);
            world.setBlock(x + 6, y + 3, z + 2, Blocks.air, 0, 2);
            world.setBlock(x + 7, y + 3, z + 2, Blocks.air, 0, 2);
            world.setBlock(x + 8, y + 3, z + 2, Blocks.air, 0, 2);
            world.setBlock(x + 9, y + 3, z + 2, Blocks.air, 0, 2);
            world.setBlock(x + 10, y + 3, z + 2, Blocks.air, 0, 2);
            world.setBlock(x + 11, y + 3, z + 2, Blocks.air, 0, 2);
            world.setBlock(x + 12, y + 3, z + 2, Blocks.air, 0, 2);
            world.setBlock(x + 13, y + 3, z + 2, Blocks.air, 0, 2);
            world.setBlock(x + 14, y + 3, z + 2, Blocks.air, 0, 2);
            world.setBlock(x + 15, y + 3, z + 2, Blocks.air, 0, 2);
            world.setBlock(x + 16, y + 3, z + 2, Blocks.air, 0, 2);
            world.setBlock(x + 17, y + 3, z + 2, Blocks.air, 0, 2);
            world.setBlock(x + 18, y + 3, z + 2, Blocks.stone, 0, 2);
            world.setBlock(x + 0, y + 3, z + 3, Blocks.stone, 0, 2);
            world.setBlock(x + 1, y + 3, z + 3, Blocks.air, 0, 2);
            world.setBlock(x + 2, y + 3, z + 3, Blocks.air, 0, 2);
            world.setBlock(x + 3, y + 3, z + 3, Blocks.air, 0, 2);
            world.setBlock(x + 4, y + 3, z + 3, Blocks.stone, 0, 2);
            world.setBlock(x + 5, y + 3, z + 3, Blocks.air, 0, 2);
            world.setBlock(x + 6, y + 3, z + 3, Blocks.air, 0, 2);
            world.setBlock(x + 7, y + 3, z + 3, Blocks.air, 0, 2);
            world.setBlock(x + 8, y + 3, z + 3, Blocks.air, 0, 2);
            world.setBlock(x + 9, y + 3, z + 3, Blocks.air, 0, 2);
            world.setBlock(x + 10, y + 3, z + 3, Blocks.air, 0, 2);
            world.setBlock(x + 11, y + 3, z + 3, Blocks.air, 0, 2);
            world.setBlock(x + 12, y + 3, z + 3, Blocks.air, 0, 2);
            world.setBlock(x + 13, y + 3, z + 3, Blocks.air, 0, 2);
            world.setBlock(x + 14, y + 3, z + 3, Blocks.air, 0, 2);
            world.setBlock(x + 15, y + 3, z + 3, Blocks.air, 0, 2);
            world.setBlock(x + 16, y + 3, z + 3, Blocks.air, 0, 2);
            world.setBlock(x + 17, y + 3, z + 3, Blocks.air, 0, 2);
            world.setBlock(x + 18, y + 3, z + 3, Blocks.stone, 0, 2);
            world.setBlock(x + 0, y + 3, z + 4, Blocks.stone, 0, 2);
            world.setBlock(x + 1, y + 3, z + 4, Blocks.air, 0, 2);
            world.setBlock(x + 2, y + 3, z + 4, Blocks.air, 0, 2);
            world.setBlock(x + 3, y + 3, z + 4, Blocks.air, 0, 2);
            world.setBlock(x + 4, y + 3, z + 4, Blocks.stone, 0, 2);
            world.setBlock(x + 5, y + 3, z + 4, Blocks.air, 0, 2);
            world.setBlock(x + 6, y + 3, z + 4, Blocks.air, 0, 2);
            world.setBlock(x + 7, y + 3, z + 4, Blocks.air, 0, 2);
            world.setBlock(x + 8, y + 3, z + 4, Blocks.air, 0, 2);
            world.setBlock(x + 9, y + 3, z + 4, Blocks.air, 0, 2);
            world.setBlock(x + 10, y + 3, z + 4, Blocks.air, 0, 2);
            world.setBlock(x + 11, y + 3, z + 4, Blocks.air, 0, 2);
            world.setBlock(x + 12, y + 3, z + 4, Blocks.air, 0, 2);
            world.setBlock(x + 13, y + 3, z + 4, Blocks.air, 0, 2);
            world.setBlock(x + 14, y + 3, z + 4, Blocks.air, 0, 2);
            world.setBlock(x + 15, y + 3, z + 4, Blocks.air, 0, 2);
            world.setBlock(x + 16, y + 3, z + 4, Blocks.air, 0, 2);
            world.setBlock(x + 17, y + 3, z + 4, Blocks.air, 0, 2);
            world.setBlock(x + 18, y + 3, z + 4, Blocks.stone, 0, 2);
            world.setBlock(x + 0, y + 3, z + 5, Blocks.stone, 0, 2);
            world.setBlock(x + 1, y + 3, z + 5, Blocks.air, 0, 2);
            world.setBlock(x + 2, y + 3, z + 5, Blocks.air, 0, 2);
            world.setBlock(x + 3, y + 3, z + 5, Blocks.air, 0, 2);
            world.setBlock(x + 4, y + 3, z + 5, Blocks.stone, 0, 2);
            world.setBlock(x + 5, y + 3, z + 5, Blocks.air, 0, 2);
            world.setBlock(x + 6, y + 3, z + 5, Blocks.air, 0, 2);
            world.setBlock(x + 7, y + 3, z + 5, Blocks.air, 0, 2);
            world.setBlock(x + 8, y + 3, z + 5, Blocks.air, 0, 2);
            world.setBlock(x + 9, y + 3, z + 5, Blocks.air, 0, 2);
            world.setBlock(x + 10, y + 3, z + 5, Blocks.air, 0, 2);
            world.setBlock(x + 11, y + 3, z + 5, Blocks.air, 0, 2);
            world.setBlock(x + 12, y + 3, z + 5, Blocks.air, 0, 2);
            world.setBlock(x + 13, y + 3, z + 5, Blocks.air, 0, 2);
            world.setBlock(x + 14, y + 3, z + 5, Blocks.air, 0, 2);
            world.setBlock(x + 15, y + 3, z + 5, Blocks.air, 0, 2);
            world.setBlock(x + 16, y + 3, z + 5, Blocks.air, 0, 2);
            world.setBlock(x + 17, y + 3, z + 5, Blocks.air, 0, 2);
            world.setBlock(x + 18, y + 3, z + 5, Blocks.stone, 0, 2);
            world.setBlock(x + 0, y + 3, z + 6, Blocks.stone, 0, 2);
            world.setBlock(x + 1, y + 3, z + 6, Blocks.air, 0, 2);
            world.setBlock(x + 2, y + 3, z + 6, Blocks.air, 0, 2);
            world.setBlock(x + 3, y + 3, z + 6, Blocks.air, 0, 2);
            world.setBlock(x + 4, y + 3, z + 6, Blocks.stone, 0, 2);
            world.setBlock(x + 5, y + 3, z + 6, Blocks.air, 0, 2);
            world.setBlock(x + 6, y + 3, z + 6, Blocks.air, 0, 2);
            world.setBlock(x + 7, y + 3, z + 6, Blocks.air, 0, 2);
            world.setBlock(x + 8, y + 3, z + 6, Blocks.air, 0, 2);
            world.setBlock(x + 9, y + 3, z + 6, Blocks.air, 0, 2);
            world.setBlock(x + 10, y + 3, z + 6, Blocks.air, 0, 2);
            world.setBlock(x + 11, y + 3, z + 6, Blocks.air, 0, 2);
            world.setBlock(x + 12, y + 3, z + 6, Blocks.air, 0, 2);
            world.setBlock(x + 13, y + 3, z + 6, Blocks.air, 0, 2);
            world.setBlock(x + 14, y + 3, z + 6, Blocks.air, 0, 2);
            world.setBlock(x + 15, y + 3, z + 6, Blocks.air, 0, 2);
            world.setBlock(x + 16, y + 3, z + 6, Blocks.air, 0, 2);
            world.setBlock(x + 17, y + 3, z + 6, Blocks.air, 0, 2);
            world.setBlock(x + 18, y + 3, z + 6, Blocks.stone, 0, 2);
            world.setBlock(x + 0, y + 3, z + 7, Blocks.stone, 0, 2);
            world.setBlock(x + 1, y + 3, z + 7, Blocks.stone, 0, 2);
            world.setBlock(x + 2, y + 3, z + 7, Blocks.stone, 0, 2);
            world.setBlock(x + 3, y + 3, z + 7, Blocks.stone, 0, 2);
            world.setBlock(x + 4, y + 3, z + 7, Blocks.stone, 0, 2);
            world.setBlock(x + 5, y + 3, z + 7, Blocks.stone, 0, 2);
            world.setBlock(x + 6, y + 3, z + 7, Blocks.stone, 0, 2);
            world.setBlock(x + 7, y + 3, z + 7, Blocks.stone, 0, 2);
            world.setBlock(x + 8, y + 3, z + 7, Blocks.stone, 0, 2);
            world.setBlock(x + 9, y + 3, z + 7, Blocks.stone, 0, 2);
            world.setBlock(x + 10, y + 3, z + 7, Blocks.stone, 0, 2);
            world.setBlock(x + 11, y + 3, z + 7, Blocks.stone, 0, 2);
            world.setBlock(x + 12, y + 3, z + 7, Blocks.stone, 0, 2);
            world.setBlock(x + 13, y + 3, z + 7, Main.bluePot, 0, 2);
            world.setBlock(x + 14, y + 3, z + 7, Blocks.air, 0, 2);
            world.setBlock(x + 15, y + 3, z + 7, Blocks.air, 0, 2);
            world.setBlock(x + 16, y + 3, z + 7, Blocks.air, 0, 2);
            world.setBlock(x + 17, y + 3, z + 7, Blocks.air, 0, 2);
            world.setBlock(x + 18, y + 3, z + 7, Blocks.stone, 0, 2);
            world.setBlock(x + 0, y + 3, z + 8, Blocks.stone, 0, 2);
            world.setBlock(x + 1, y + 3, z + 8, Blocks.stone, 0, 2);
            world.setBlock(x + 2, y + 3, z + 8, Blocks.stone, 0, 2);
            world.setBlock(x + 3, y + 3, z + 8, Blocks.stone, 0, 2);
            world.setBlock(x + 4, y + 3, z + 8, Blocks.stone, 0, 2);
            world.setBlock(x + 5, y + 3, z + 8, Blocks.air, 0, 2);
            world.setBlock(x + 6, y + 3, z + 8, Blocks.air, 0, 2);
            world.setBlock(x + 7, y + 3, z + 8, Blocks.air, 0, 2);
            world.setBlock(x + 8, y + 3, z + 8, Blocks.air, 0, 2);
            world.setBlock(x + 9, y + 3, z + 8, Blocks.air, 0, 2);
            world.setBlock(x + 10, y + 3, z + 8, Blocks.air, 0, 2);
            world.setBlock(x + 11, y + 3, z + 8, Blocks.air, 0, 2);
            world.setBlock(x + 12, y + 3, z + 8, Blocks.air, 0, 2);
            world.setBlock(x + 13, y + 3, z + 8, Blocks.air, 0, 2);
            world.setBlock(x + 14, y + 3, z + 8, Blocks.air, 0, 2);
            world.setBlock(x + 15, y + 3, z + 8, Blocks.air, 0, 2);
            world.setBlock(x + 16, y + 3, z + 8, Blocks.air, 0, 2);
            world.setBlock(x + 17, y + 3, z + 8, Blocks.air, 0, 2);
            world.setBlock(x + 18, y + 3, z + 8, Blocks.stone, 0, 2);
            world.setBlock(x + 0, y + 3, z + 9, Blocks.stone, 0, 2);
            world.setBlock(x + 1, y + 3, z + 9, Blocks.air, 0, 2);
            world.setBlock(x + 2, y + 3, z + 9, Blocks.air, 0, 2);
            world.setBlock(x + 3, y + 3, z + 9, Blocks.air, 0, 2);
            world.setBlock(x + 4, y + 3, z + 9, Blocks.air, 0, 2);
            world.setBlock(x + 5, y + 3, z + 9, Blocks.air, 0, 2);
            world.setBlock(x + 6, y + 3, z + 9, Blocks.air, 0, 2);
            world.setBlock(x + 7, y + 3, z + 9, Blocks.air, 0, 2);
            world.setBlock(x + 8, y + 3, z + 9, Blocks.air, 0, 2);
            world.setBlock(x + 9, y + 3, z + 9, Blocks.air, 0, 2);
            world.setBlock(x + 10, y + 3, z + 9, Blocks.air, 0, 2);
            world.setBlock(x + 11, y + 3, z + 9, Blocks.air, 0, 2);
            world.setBlock(x + 12, y + 3, z + 9, Blocks.air, 0, 2);
            world.setBlock(x + 13, y + 3, z + 9, Blocks.air, 0, 2);
            world.setBlock(x + 14, y + 3, z + 9, Blocks.air, 0, 2);
            world.setBlock(x + 15, y + 3, z + 9, Blocks.air, 0, 2);
            world.setBlock(x + 16, y + 3, z + 9, Blocks.air, 0, 2);
            world.setBlock(x + 17, y + 3, z + 9, Blocks.air, 0, 2);
            world.setBlock(x + 18, y + 3, z + 9, Blocks.stone, 0, 2);
            world.setBlock(x + 0, y + 3, z + 10, Blocks.stone, 0, 2);
            world.setBlock(x + 1, y + 3, z + 10, Blocks.air, 0, 2);
            world.setBlock(x + 2, y + 3, z + 10, Blocks.air, 0, 2);
            world.setBlock(x + 3, y + 3, z + 10, Blocks.air, 0, 2);
            world.setBlock(x + 4, y + 3, z + 10, Blocks.air, 0, 2);
            world.setBlock(x + 5, y + 3, z + 10, Blocks.air, 0, 2);
            world.setBlock(x + 6, y + 3, z + 10, Blocks.air, 0, 2);
            world.setBlock(x + 7, y + 3, z + 10, Blocks.air, 0, 2);
            world.setBlock(x + 8, y + 3, z + 10, Blocks.air, 0, 2);
            world.setBlock(x + 9, y + 3, z + 10, Blocks.air, 0, 2);
            world.setBlock(x + 10, y + 3, z + 10, Blocks.air, 0, 2);
            world.setBlock(x + 11, y + 3, z + 10, Blocks.air, 0, 2);
            world.setBlock(x + 12, y + 3, z + 10, Blocks.air, 0, 2);
            world.setBlock(x + 13, y + 3, z + 10, Blocks.air, 0, 2);
            world.setBlock(x + 14, y + 3, z + 10, Blocks.air, 0, 2);
            world.setBlock(x + 15, y + 3, z + 10, Blocks.air, 0, 2);
            world.setBlock(x + 16, y + 3, z + 10, Blocks.air, 0, 2);
            world.setBlock(x + 17, y + 3, z + 10, Blocks.air, 0, 2);
            world.setBlock(x + 18, y + 3, z + 10, Blocks.stone, 0, 2);
            world.setBlock(x + 0, y + 3, z + 11, Blocks.stone, 0, 2);
            world.setBlock(x + 1, y + 3, z + 11, Blocks.air, 0, 2);
            world.setBlock(x + 2, y + 3, z + 11, Blocks.air, 0, 2);
            world.setBlock(x + 3, y + 3, z + 11, Blocks.air, 0, 2);
            world.setBlock(x + 4, y + 3, z + 11, Blocks.air, 0, 2);
            world.setBlock(x + 5, y + 3, z + 11, Blocks.air, 0, 2);
            world.setBlock(x + 6, y + 3, z + 11, Blocks.air, 0, 2);
            world.setBlock(x + 7, y + 3, z + 11, Blocks.air, 0, 2);
            world.setBlock(x + 8, y + 3, z + 11, Blocks.air, 0, 2);
            world.setBlock(x + 9, y + 3, z + 11, Blocks.air, 0, 2);
            world.setBlock(x + 10, y + 3, z + 11, Blocks.air, 0, 2);
            world.setBlock(x + 11, y + 3, z + 11, Blocks.air, 0, 2);
            world.setBlock(x + 12, y + 3, z + 11, Blocks.air, 0, 2);
            world.setBlock(x + 13, y + 3, z + 11, Blocks.air, 0, 2);
            world.setBlock(x + 14, y + 3, z + 11, Blocks.air, 0, 2);
            world.setBlock(x + 15, y + 3, z + 11, Blocks.air, 0, 2);
            world.setBlock(x + 16, y + 3, z + 11, Blocks.air, 0, 2);
            world.setBlock(x + 17, y + 3, z + 11, Blocks.air, 0, 2);
            world.setBlock(x + 18, y + 3, z + 11, Blocks.stone, 0, 2);
            world.setBlock(x + 0, y + 3, z + 12, Blocks.stone, 0, 2);
            world.setBlock(x + 1, y + 3, z + 12, Blocks.stone, 0, 2);
            world.setBlock(x + 2, y + 3, z + 12, Blocks.stone, 0, 2);
            world.setBlock(x + 3, y + 3, z + 12, Blocks.stone, 0, 2);
            world.setBlock(x + 4, y + 3, z + 12, Blocks.stone, 0, 2);
            world.setBlock(x + 5, y + 3, z + 12, Blocks.stone, 0, 2);
            world.setBlock(x + 6, y + 3, z + 12, Blocks.stone, 0, 2);
            world.setBlock(x + 7, y + 3, z + 12, Blocks.stone, 0, 2);
            world.setBlock(x + 8, y + 3, z + 12, Blocks.stone, 0, 2);
            world.setBlock(x + 9, y + 3, z + 12, Blocks.stone, 0, 2);
            world.setBlock(x + 10, y + 3, z + 12, Blocks.stone, 0, 2);
            world.setBlock(x + 11, y + 3, z + 12, Blocks.stone, 0, 2);
            world.setBlock(x + 12, y + 3, z + 12, Blocks.stone, 0, 2);
            world.setBlock(x + 13, y + 3, z + 12, Blocks.stone, 0, 2);
            world.setBlock(x + 14, y + 3, z + 12, Blocks.stone, 0, 2);
            world.setBlock(x + 15, y + 3, z + 12, Blocks.stone, 0, 2);
            world.setBlock(x + 16, y + 3, z + 12, Blocks.stone, 0, 2);
            world.setBlock(x + 17, y + 3, z + 12, Blocks.stone, 0, 2);
            world.setBlock(x + 18, y + 3, z + 12, Blocks.stone, 0, 2);
            world.setBlock(x + 0, y + 4, z + 0, Blocks.stone, 0, 2);
            world.setBlock(x + 1, y + 4, z + 0, Blocks.stone, 0, 2);
            world.setBlock(x + 2, y + 4, z + 0, Blocks.stone, 0, 2);
            world.setBlock(x + 3, y + 4, z + 0, Blocks.stone, 0, 2);
            world.setBlock(x + 4, y + 4, z + 0, Blocks.stone, 0, 2);
            world.setBlock(x + 5, y + 4, z + 0, Blocks.stone, 0, 2);
            world.setBlock(x + 6, y + 4, z + 0, Blocks.stone, 0, 2);
            world.setBlock(x + 7, y + 4, z + 0, Blocks.stone, 0, 2);
            world.setBlock(x + 8, y + 4, z + 0, Blocks.stone, 0, 2);
            world.setBlock(x + 9, y + 4, z + 0, Blocks.stone, 0, 2);
            world.setBlock(x + 10, y + 4, z + 0, Blocks.stone, 0, 2);
            world.setBlock(x + 11, y + 4, z + 0, Blocks.stone, 0, 2);
            world.setBlock(x + 12, y + 4, z + 0, Blocks.stone, 0, 2);
            world.setBlock(x + 13, y + 4, z + 0, Blocks.stone, 0, 2);
            world.setBlock(x + 14, y + 4, z + 0, Blocks.stone, 0, 2);
            world.setBlock(x + 15, y + 4, z + 0, Blocks.stone, 0, 2);
            world.setBlock(x + 16, y + 4, z + 0, Blocks.stone, 0, 2);
            world.setBlock(x + 17, y + 4, z + 0, Blocks.stone, 0, 2);
            world.setBlock(x + 18, y + 4, z + 0, Blocks.stone, 0, 2);
            world.setBlock(x + 0, y + 4, z + 1, Blocks.stone, 0, 2);
            world.setBlock(x + 1, y + 4, z + 1, Blocks.air, 0, 2);
            world.setBlock(x + 2, y + 4, z + 1, Blocks.air, 0, 2);
            world.setBlock(x + 3, y + 4, z + 1, Blocks.air, 0, 2);
            world.setBlock(x + 4, y + 4, z + 1, Blocks.stone, 0, 2);
            world.setBlock(x + 5, y + 4, z + 1, Blocks.air, 0, 2);
            world.setBlock(x + 6, y + 4, z + 1, Blocks.air, 0, 2);
            world.setBlock(x + 7, y + 4, z + 1, Blocks.air, 0, 2);
            world.setBlock(x + 8, y + 4, z + 1, Blocks.air, 0, 2);
            world.setBlock(x + 9, y + 4, z + 1, Blocks.air, 0, 2);
            world.setBlock(x + 10, y + 4, z + 1, Blocks.air, 0, 2);
            world.setBlock(x + 11, y + 4, z + 1, Blocks.air, 0, 2);
            world.setBlock(x + 12, y + 4, z + 1, Blocks.air, 0, 2);
            world.setBlock(x + 13, y + 4, z + 1, Blocks.air, 0, 2);
            world.setBlock(x + 14, y + 4, z + 1, Blocks.air, 0, 2);
            world.setBlock(x + 15, y + 4, z + 1, Blocks.air, 0, 2);
            world.setBlock(x + 16, y + 4, z + 1, Blocks.air, 0, 2);
            world.setBlock(x + 17, y + 4, z + 1, Blocks.air, 0, 2);
            world.setBlock(x + 18, y + 4, z + 1, Blocks.stone, 0, 2);
            world.setBlock(x + 0, y + 4, z + 2, Blocks.stone, 0, 2);
            world.setBlock(x + 1, y + 4, z + 2, Blocks.air, 0, 2);
            world.setBlock(x + 2, y + 4, z + 2, Blocks.air, 0, 2);
            world.setBlock(x + 3, y + 4, z + 2, Blocks.air, 0, 2);
            world.setBlock(x + 4, y + 4, z + 2, Blocks.stone, 0, 2);
            world.setBlock(x + 5, y + 4, z + 2, Blocks.air, 0, 2);
            world.setBlock(x + 6, y + 4, z + 2, Blocks.air, 0, 2);
            world.setBlock(x + 7, y + 4, z + 2, Blocks.air, 0, 2);
            world.setBlock(x + 8, y + 4, z + 2, Blocks.air, 0, 2);
            world.setBlock(x + 9, y + 4, z + 2, Blocks.air, 0, 2);
            world.setBlock(x + 10, y + 4, z + 2, Blocks.air, 0, 2);
            world.setBlock(x + 11, y + 4, z + 2, Blocks.air, 0, 2);
            world.setBlock(x + 12, y + 4, z + 2, Blocks.air, 0, 2);
            world.setBlock(x + 13, y + 4, z + 2, Blocks.air, 0, 2);
            world.setBlock(x + 14, y + 4, z + 2, Blocks.air, 0, 2);
            world.setBlock(x + 15, y + 4, z + 2, Blocks.air, 0, 2);
            world.setBlock(x + 16, y + 4, z + 2, Blocks.air, 0, 2);
            world.setBlock(x + 17, y + 4, z + 2, Blocks.air, 0, 2);
            world.setBlock(x + 18, y + 4, z + 2, Blocks.stone, 0, 2);
            world.setBlock(x + 0, y + 4, z + 3, Blocks.stone, 0, 2);
            world.setBlock(x + 1, y + 4, z + 3, Blocks.air, 0, 2);
            world.setBlock(x + 2, y + 4, z + 3, Blocks.air, 0, 2);
            world.setBlock(x + 3, y + 4, z + 3, Blocks.air, 0, 2);
            world.setBlock(x + 4, y + 4, z + 3, Blocks.stone, 0, 2);
            world.setBlock(x + 5, y + 4, z + 3, Blocks.air, 0, 2);
            world.setBlock(x + 6, y + 4, z + 3, Blocks.air, 0, 2);
            world.setBlock(x + 7, y + 4, z + 3, Blocks.air, 0, 2);
            world.setBlock(x + 8, y + 4, z + 3, Blocks.air, 0, 2);
            world.setBlock(x + 9, y + 4, z + 3, Blocks.air, 0, 2);
            world.setBlock(x + 10, y + 4, z + 3, Blocks.air, 0, 2);
            world.setBlock(x + 11, y + 4, z + 3, Blocks.air, 0, 2);
            world.setBlock(x + 12, y + 4, z + 3, Blocks.air, 0, 2);
            world.setBlock(x + 13, y + 4, z + 3, Blocks.air, 0, 2);
            world.setBlock(x + 14, y + 4, z + 3, Blocks.air, 0, 2);
            world.setBlock(x + 15, y + 4, z + 3, Blocks.air, 0, 2);
            world.setBlock(x + 16, y + 4, z + 3, Blocks.air, 0, 2);
            world.setBlock(x + 17, y + 4, z + 3, Blocks.air, 0, 2);
            world.setBlock(x + 18, y + 4, z + 3, Blocks.stone, 0, 2);
            world.setBlock(x + 0, y + 4, z + 4, Blocks.stone, 0, 2);
            world.setBlock(x + 1, y + 4, z + 4, Blocks.air, 0, 2);
            world.setBlock(x + 2, y + 4, z + 4, Blocks.air, 0, 2);
            world.setBlock(x + 3, y + 4, z + 4, Blocks.air, 0, 2);
            world.setBlock(x + 4, y + 4, z + 4, Blocks.stone, 0, 2);
            world.setBlock(x + 5, y + 4, z + 4, Blocks.air, 0, 2);
            world.setBlock(x + 6, y + 4, z + 4, Blocks.air, 0, 2);
            world.setBlock(x + 7, y + 4, z + 4, Blocks.air, 0, 2);
            world.setBlock(x + 8, y + 4, z + 4, Blocks.air, 0, 2);
            world.setBlock(x + 9, y + 4, z + 4, Blocks.air, 0, 2);
            world.setBlock(x + 10, y + 4, z + 4, Blocks.air, 0, 2);
            world.setBlock(x + 11, y + 4, z + 4, Blocks.air, 0, 2);
            world.setBlock(x + 12, y + 4, z + 4, Blocks.air, 0, 2);
            world.setBlock(x + 13, y + 4, z + 4, Blocks.air, 0, 2);
            world.setBlock(x + 14, y + 4, z + 4, Blocks.air, 0, 2);
            world.setBlock(x + 15, y + 4, z + 4, Blocks.air, 0, 2);
            world.setBlock(x + 16, y + 4, z + 4, Blocks.air, 0, 2);
            world.setBlock(x + 17, y + 4, z + 4, Blocks.air, 0, 2);
            world.setBlock(x + 18, y + 4, z + 4, Blocks.stone, 0, 2);
            world.setBlock(x + 0, y + 4, z + 5, Blocks.stone, 0, 2);
            world.setBlock(x + 1, y + 4, z + 5, Blocks.air, 0, 2);
            world.setBlock(x + 2, y + 4, z + 5, Blocks.air, 0, 2);
            world.setBlock(x + 3, y + 4, z + 5, Blocks.air, 0, 2);
            world.setBlock(x + 4, y + 4, z + 5, Blocks.stone, 0, 2);
            world.setBlock(x + 5, y + 4, z + 5, Blocks.air, 0, 2);
            world.setBlock(x + 6, y + 4, z + 5, Blocks.air, 0, 2);
            world.setBlock(x + 7, y + 4, z + 5, Blocks.air, 0, 2);
            world.setBlock(x + 8, y + 4, z + 5, Blocks.air, 0, 2);
            world.setBlock(x + 9, y + 4, z + 5, Blocks.air, 0, 2);
            world.setBlock(x + 10, y + 4, z + 5, Blocks.air, 0, 2);
            world.setBlock(x + 11, y + 4, z + 5, Blocks.air, 0, 2);
            world.setBlock(x + 12, y + 4, z + 5, Blocks.air, 0, 2);
            world.setBlock(x + 13, y + 4, z + 5, Blocks.air, 0, 2);
            world.setBlock(x + 14, y + 4, z + 5, Blocks.air, 0, 2);
            world.setBlock(x + 15, y + 4, z + 5, Blocks.air, 0, 2);
            world.setBlock(x + 16, y + 4, z + 5, Blocks.air, 0, 2);
            world.setBlock(x + 17, y + 4, z + 5, Blocks.air, 0, 2);
            world.setBlock(x + 18, y + 4, z + 5, Blocks.stone, 0, 2);
            world.setBlock(x + 0, y + 4, z + 6, Blocks.stone, 0, 2);
            world.setBlock(x + 1, y + 4, z + 6, Blocks.air, 0, 2);
            world.setBlock(x + 2, y + 4, z + 6, Blocks.air, 0, 2);
            world.setBlock(x + 3, y + 4, z + 6, Blocks.air, 0, 2);
            world.setBlock(x + 4, y + 4, z + 6, Blocks.stone, 0, 2);
            world.setBlock(x + 5, y + 4, z + 6, Blocks.air, 0, 2);
            world.setBlock(x + 6, y + 4, z + 6, Blocks.air, 0, 2);
            world.setBlock(x + 7, y + 4, z + 6, Blocks.air, 0, 2);
            world.setBlock(x + 8, y + 4, z + 6, Blocks.air, 0, 2);
            world.setBlock(x + 9, y + 4, z + 6, Blocks.air, 0, 2);
            world.setBlock(x + 10, y + 4, z + 6, Blocks.air, 0, 2);
            world.setBlock(x + 11, y + 4, z + 6, Blocks.air, 0, 2);
            world.setBlock(x + 12, y + 4, z + 6, Blocks.air, 0, 2);
            world.setBlock(x + 13, y + 4, z + 6, Blocks.air, 0, 2);
            world.setBlock(x + 14, y + 4, z + 6, Blocks.air, 0, 2);
            world.setBlock(x + 15, y + 4, z + 6, Blocks.air, 0, 2);
            world.setBlock(x + 16, y + 4, z + 6, Blocks.air, 0, 2);
            world.setBlock(x + 17, y + 4, z + 6, Blocks.air, 0, 2);
            world.setBlock(x + 18, y + 4, z + 6, Blocks.stone, 0, 2);
            world.setBlock(x + 0, y + 4, z + 7, Blocks.stone, 0, 2);
            world.setBlock(x + 1, y + 4, z + 7, Blocks.stone, 0, 2);
            world.setBlock(x + 2, y + 4, z + 7, Blocks.stone, 0, 2);
            world.setBlock(x + 3, y + 4, z + 7, Blocks.stone, 0, 2);
            world.setBlock(x + 4, y + 4, z + 7, Blocks.stone, 0, 2);
            world.setBlock(x + 5, y + 4, z + 7, Blocks.stone, 0, 2);
            world.setBlock(x + 6, y + 4, z + 7, Blocks.stone, 0, 2);
            world.setBlock(x + 7, y + 4, z + 7, Blocks.stone, 0, 2);
            world.setBlock(x + 8, y + 4, z + 7, Blocks.stone, 0, 2);
            world.setBlock(x + 9, y + 4, z + 7, Blocks.stone, 0, 2);
            world.setBlock(x + 10, y + 4, z + 7, Blocks.stone, 0, 2);
            world.setBlock(x + 11, y + 4, z + 7, Blocks.stone, 0, 2);
            world.setBlock(x + 12, y + 4, z + 7, Blocks.stone, 0, 2);
            world.setBlock(x + 13, y + 4, z + 7, Blocks.air, 0, 2);
            world.setBlock(x + 14, y + 4, z + 7, Blocks.air, 0, 2);
            world.setBlock(x + 15, y + 4, z + 7, Blocks.air, 0, 2);
            world.setBlock(x + 16, y + 4, z + 7, Blocks.air, 0, 2);
            world.setBlock(x + 17, y + 4, z + 7, Blocks.air, 0, 2);
            world.setBlock(x + 18, y + 4, z + 7, Blocks.stone, 0, 2);
            world.setBlock(x + 0, y + 4, z + 8, Blocks.stone, 0, 2);
            world.setBlock(x + 1, y + 4, z + 8, Blocks.stone, 0, 2);
            world.setBlock(x + 2, y + 4, z + 8, Blocks.stone, 0, 2);
            world.setBlock(x + 3, y + 4, z + 8, Blocks.stone, 0, 2);
            world.setBlock(x + 4, y + 4, z + 8, Blocks.stone, 0, 2);
            world.setBlock(x + 5, y + 4, z + 8, Blocks.air, 0, 2);
            world.setBlock(x + 6, y + 4, z + 8, Blocks.air, 0, 2);
            world.setBlock(x + 7, y + 4, z + 8, Blocks.air, 0, 2);
            world.setBlock(x + 8, y + 4, z + 8, Blocks.air, 0, 2);
            world.setBlock(x + 9, y + 4, z + 8, Blocks.air, 0, 2);
            world.setBlock(x + 10, y + 4, z + 8, Blocks.air, 0, 2);
            world.setBlock(x + 11, y + 4, z + 8, Blocks.air, 0, 2);
            world.setBlock(x + 12, y + 4, z + 8, Blocks.air, 0, 2);
            world.setBlock(x + 13, y + 4, z + 8, Blocks.air, 0, 2);
            world.setBlock(x + 14, y + 4, z + 8, Blocks.air, 0, 2);
            world.setBlock(x + 15, y + 4, z + 8, Blocks.air, 0, 2);
            world.setBlock(x + 16, y + 4, z + 8, Blocks.air, 0, 2);
            world.setBlock(x + 17, y + 4, z + 8, Blocks.air, 0, 2);
            world.setBlock(x + 18, y + 4, z + 8, Blocks.stone, 0, 2);
            world.setBlock(x + 0, y + 4, z + 9, Blocks.stone, 0, 2);
            world.setBlock(x + 1, y + 4, z + 9, Blocks.air, 0, 2);
            world.setBlock(x + 2, y + 4, z + 9, Blocks.air, 0, 2);
            world.setBlock(x + 3, y + 4, z + 9, Blocks.air, 0, 2);
            world.setBlock(x + 4, y + 4, z + 9, Blocks.air, 0, 2);
            world.setBlock(x + 5, y + 4, z + 9, Blocks.air, 0, 2);
            world.setBlock(x + 6, y + 4, z + 9, Blocks.air, 0, 2);
            world.setBlock(x + 7, y + 4, z + 9, Blocks.air, 0, 2);
            world.setBlock(x + 8, y + 4, z + 9, Blocks.air, 0, 2);
            world.setBlock(x + 9, y + 4, z + 9, Blocks.air, 0, 2);
            world.setBlock(x + 10, y + 4, z + 9, Blocks.air, 0, 2);
            world.setBlock(x + 11, y + 4, z + 9, Blocks.air, 0, 2);
            world.setBlock(x + 12, y + 4, z + 9, Blocks.air, 0, 2);
            world.setBlock(x + 13, y + 4, z + 9, Blocks.air, 0, 2);
            world.setBlock(x + 14, y + 4, z + 9, Blocks.air, 0, 2);
            world.setBlock(x + 15, y + 4, z + 9, Blocks.air, 0, 2);
            world.setBlock(x + 16, y + 4, z + 9, Blocks.air, 0, 2);
            world.setBlock(x + 17, y + 4, z + 9, Blocks.air, 0, 2);
            world.setBlock(x + 18, y + 4, z + 9, Blocks.stone, 0, 2);
            world.setBlock(x + 0, y + 4, z + 10, Blocks.stone, 0, 2);
            world.setBlock(x + 1, y + 4, z + 10, Blocks.air, 0, 2);
            world.setBlock(x + 2, y + 4, z + 10, Blocks.air, 0, 2);
            world.setBlock(x + 3, y + 4, z + 10, Blocks.air, 0, 2);
            world.setBlock(x + 4, y + 4, z + 10, Blocks.air, 0, 2);
            world.setBlock(x + 5, y + 4, z + 10, Blocks.air, 0, 2);
            world.setBlock(x + 6, y + 4, z + 10, Blocks.air, 0, 2);
            world.setBlock(x + 7, y + 4, z + 10, Blocks.air, 0, 2);
            world.setBlock(x + 8, y + 4, z + 10, Blocks.air, 0, 2);
            world.setBlock(x + 9, y + 4, z + 10, Blocks.air, 0, 2);
            world.setBlock(x + 10, y + 4, z + 10, Blocks.air, 0, 2);
            world.setBlock(x + 11, y + 4, z + 10, Blocks.air, 0, 2);
            world.setBlock(x + 12, y + 4, z + 10, Blocks.air, 0, 2);
            world.setBlock(x + 13, y + 4, z + 10, Blocks.air, 0, 2);
            world.setBlock(x + 14, y + 4, z + 10, Blocks.air, 0, 2);
            world.setBlock(x + 15, y + 4, z + 10, Blocks.air, 0, 2);
            world.setBlock(x + 16, y + 4, z + 10, Blocks.air, 0, 2);
            world.setBlock(x + 17, y + 4, z + 10, Blocks.air, 0, 2);
            world.setBlock(x + 18, y + 4, z + 10, Blocks.stone, 0, 2);
            world.setBlock(x + 0, y + 4, z + 11, Blocks.stone, 0, 2);
            world.setBlock(x + 1, y + 4, z + 11, Blocks.air, 0, 2);
            world.setBlock(x + 2, y + 4, z + 11, Blocks.air, 0, 2);
            world.setBlock(x + 3, y + 4, z + 11, Blocks.air, 0, 2);
            world.setBlock(x + 4, y + 4, z + 11, Blocks.air, 0, 2);
            world.setBlock(x + 5, y + 4, z + 11, Blocks.air, 0, 2);
            world.setBlock(x + 6, y + 4, z + 11, Blocks.air, 0, 2);
            world.setBlock(x + 7, y + 4, z + 11, Blocks.air, 0, 2);
            world.setBlock(x + 8, y + 4, z + 11, Blocks.air, 0, 2);
            world.setBlock(x + 9, y + 4, z + 11, Blocks.air, 0, 2);
            world.setBlock(x + 10, y + 4, z + 11, Blocks.air, 0, 2);
            world.setBlock(x + 11, y + 4, z + 11, Blocks.air, 0, 2);
            world.setBlock(x + 12, y + 4, z + 11, Blocks.air, 0, 2);
            world.setBlock(x + 13, y + 4, z + 11, Blocks.air, 0, 2);
            world.setBlock(x + 14, y + 4, z + 11, Blocks.air, 0, 2);
            world.setBlock(x + 15, y + 4, z + 11, Blocks.air, 0, 2);
            world.setBlock(x + 16, y + 4, z + 11, Blocks.air, 0, 2);
            world.setBlock(x + 17, y + 4, z + 11, Blocks.air, 0, 2);
            world.setBlock(x + 18, y + 4, z + 11, Blocks.stone, 0, 2);
            world.setBlock(x + 0, y + 4, z + 12, Blocks.stone, 0, 2);
            world.setBlock(x + 1, y + 4, z + 12, Blocks.stone, 0, 2);
            world.setBlock(x + 2, y + 4, z + 12, Blocks.stone, 0, 2);
            world.setBlock(x + 3, y + 4, z + 12, Blocks.stone, 0, 2);
            world.setBlock(x + 4, y + 4, z + 12, Blocks.stone, 0, 2);
            world.setBlock(x + 5, y + 4, z + 12, Blocks.stone, 0, 2);
            world.setBlock(x + 6, y + 4, z + 12, Blocks.stone, 0, 2);
            world.setBlock(x + 7, y + 4, z + 12, Blocks.stone, 0, 2);
            world.setBlock(x + 8, y + 4, z + 12, Blocks.stone, 0, 2);
            world.setBlock(x + 9, y + 4, z + 12, Blocks.stone, 0, 2);
            world.setBlock(x + 10, y + 4, z + 12, Blocks.stone, 0, 2);
            world.setBlock(x + 11, y + 4, z + 12, Blocks.stone, 0, 2);
            world.setBlock(x + 12, y + 4, z + 12, Blocks.stone, 0, 2);
            world.setBlock(x + 13, y + 4, z + 12, Blocks.stone, 0, 2);
            world.setBlock(x + 14, y + 4, z + 12, Blocks.stone, 0, 2);
            world.setBlock(x + 15, y + 4, z + 12, Blocks.stone, 0, 2);
            world.setBlock(x + 16, y + 4, z + 12, Blocks.stone, 0, 2);
            world.setBlock(x + 17, y + 4, z + 12, Blocks.stone, 0, 2);
            world.setBlock(x + 18, y + 4, z + 12, Blocks.stone, 0, 2);
            System.out.println("Built a water dungeon at (" + x2 + ", " + y2 + ", " + z2 + ")");
        }
    }

    @Override
    protected void func_143012_a(NBTTagCompound p_143012_1_) {

    }

    @Override
    protected void func_143011_b(NBTTagCompound p_143011_1_) {

    }

    public boolean addComponentParts(final World world, final Random r, final StructureBoundingBox box) {
        this.generateSurface(world, r, this.coordBaseMode, this.coordBaseMode, this.coordBaseMode);
        return true;
    }
    
    protected void writeStructureToNBT(final NBTTagCompound p_143012_1_) {
    }
    
    protected void readStructureFromNBT(final NBTTagCompound p_143011_1_) {
    }
}
