package apocalypse.fandomcraft.otherworld.structures;

import net.minecraft.world.gen.feature.*;
import cpw.mods.fml.common.*;
import net.minecraft.world.*;
import java.util.*;
import apocalypse.fandomcraft.horror.*;
import net.minecraft.init.*;
import apocalypse.fandomcraft.main.*;
import net.minecraft.world.chunk.*;

public class WorldGenOWBloodTreeLarge extends WorldGenerator implements IWorldGenerator
{
    public boolean generate(final World world, final Random rand, final int x, int y, final int z) {
        y = world.getHeightValue(x, z);
        if (world.getBlock(x + 3, y - 1, z + 3) == HorrorReg.bloodGrass && world.getBlock(x + 3, y + 4, z + 3) == Blocks.air && world.getBlock(x + 3, y + 9, z + 3) == Blocks.air && world.getBlock(x + 3, y + 11, z + 3) == Blocks.air && world.getBlock(x + 3, y + 17, z + 3) == Blocks.air) {
            world.setBlock(x + 3, y, z + 3, Main.bloodstone, 0, 2);
            world.setBlock(x + 4, y, z + 3, Main.bloodstone, 0, 2);
            world.setBlock(x + 3, y, z + 4, Main.bloodstone, 0, 2);
            world.setBlock(x + 4, y, z + 4, Main.bloodstone, 0, 2);
            world.setBlock(x + 3, y + 1, z + 3, Main.bloodstone, 0, 2);
            world.setBlock(x + 4, y + 1, z + 3, Main.bloodstone, 0, 2);
            world.setBlock(x + 3, y + 1, z + 4, Main.bloodstone, 0, 2);
            world.setBlock(x + 4, y + 1, z + 4, Main.bloodstone, 0, 2);
            world.setBlock(x + 3, y + 2, z + 3, Main.bloodstone, 0, 2);
            world.setBlock(x + 4, y + 2, z + 3, Main.bloodstone, 0, 2);
            world.setBlock(x + 3, y + 2, z + 4, Main.bloodstone, 0, 2);
            world.setBlock(x + 4, y + 2, z + 4, Main.bloodstone, 0, 2);
            world.setBlock(x + 3, y + 3, z + 3, Main.bloodstone, 0, 2);
            world.setBlock(x + 4, y + 3, z + 3, Main.bloodstone, 0, 2);
            world.setBlock(x + 3, y + 3, z + 4, Main.bloodstone, 0, 2);
            world.setBlock(x + 4, y + 3, z + 4, Main.bloodstone, 0, 2);
            world.setBlock(x + 3, y + 4, z + 3, Main.bloodstone, 0, 2);
            world.setBlock(x + 4, y + 4, z + 3, Main.bloodstone, 0, 2);
            world.setBlock(x + 3, y + 4, z + 4, Main.bloodstone, 0, 2);
            world.setBlock(x + 4, y + 4, z + 4, Main.bloodstone, 0, 2);
            world.setBlock(x + 3, y + 5, z + 3, Main.bloodstone, 0, 2);
            world.setBlock(x + 4, y + 5, z + 3, Main.bloodstone, 0, 2);
            world.setBlock(x + 3, y + 5, z + 4, Main.bloodstone, 0, 2);
            world.setBlock(x + 4, y + 5, z + 4, Main.bloodstone, 0, 2);
            world.setBlock(x + 3, y + 6, z + 3, Main.bloodstone, 0, 2);
            world.setBlock(x + 4, y + 6, z + 3, Main.bloodstone, 0, 2);
            world.setBlock(x + 3, y + 6, z + 4, Main.bloodstone, 0, 2);
            world.setBlock(x + 4, y + 6, z + 4, Main.bloodstone, 0, 2);
            world.setBlock(x + 3, y + 7, z + 3, Main.bloodstone, 0, 2);
            world.setBlock(x + 4, y + 7, z + 3, Main.bloodstone, 0, 2);
            world.setBlock(x + 3, y + 7, z + 4, Main.bloodstone, 0, 2);
            world.setBlock(x + 4, y + 7, z + 4, Main.bloodstone, 0, 2);
            world.setBlock(x + 3, y + 8, z + 2, HorrorReg.bloodleaf, 0, 2);
            world.setBlock(x + 4, y + 8, z + 2, HorrorReg.bloodleaf, 0, 2);
            world.setBlock(x + 2, y + 8, z + 3, HorrorReg.bloodleaf, 0, 2);
            world.setBlock(x + 3, y + 8, z + 3, Main.bloodstone, 0, 2);
            world.setBlock(x + 4, y + 8, z + 3, Main.bloodstone, 0, 2);
            world.setBlock(x + 5, y + 8, z + 3, HorrorReg.bloodleaf, 0, 2);
            world.setBlock(x + 2, y + 8, z + 4, HorrorReg.bloodleaf, 0, 2);
            world.setBlock(x + 3, y + 8, z + 4, Main.bloodstone, 0, 2);
            world.setBlock(x + 4, y + 8, z + 4, Main.bloodstone, 0, 2);
            world.setBlock(x + 5, y + 8, z + 4, HorrorReg.bloodleaf, 0, 2);
            world.setBlock(x + 3, y + 8, z + 5, HorrorReg.bloodleaf, 0, 2);
            world.setBlock(x + 4, y + 8, z + 5, HorrorReg.bloodleaf, 0, 2);
            world.setBlock(x + 3, y + 9, z + 1, HorrorReg.bloodleaf, 0, 2);
            world.setBlock(x + 4, y + 9, z + 1, HorrorReg.bloodleaf, 0, 2);
            world.setBlock(x + 2, y + 9, z + 2, HorrorReg.bloodleaf, 0, 2);
            world.setBlock(x + 3, y + 9, z + 2, HorrorReg.bloodleaf, 0, 2);
            world.setBlock(x + 4, y + 9, z + 2, HorrorReg.bloodleaf, 0, 2);
            world.setBlock(x + 5, y + 9, z + 2, HorrorReg.bloodleaf, 0, 2);
            world.setBlock(x + 1, y + 9, z + 3, HorrorReg.bloodleaf, 0, 2);
            world.setBlock(x + 2, y + 9, z + 3, HorrorReg.bloodleaf, 0, 2);
            world.setBlock(x + 3, y + 9, z + 3, Main.bloodstone, 0, 2);
            world.setBlock(x + 4, y + 9, z + 3, Main.bloodstone, 0, 2);
            world.setBlock(x + 5, y + 9, z + 3, HorrorReg.bloodleaf, 0, 2);
            world.setBlock(x + 6, y + 9, z + 3, HorrorReg.bloodleaf, 0, 2);
            world.setBlock(x + 1, y + 9, z + 4, HorrorReg.bloodleaf, 0, 2);
            world.setBlock(x + 2, y + 9, z + 4, HorrorReg.bloodleaf, 0, 2);
            world.setBlock(x + 3, y + 9, z + 4, Main.bloodstone, 0, 2);
            world.setBlock(x + 4, y + 9, z + 4, Main.bloodstone, 0, 2);
            world.setBlock(x + 5, y + 9, z + 4, HorrorReg.bloodleaf, 0, 2);
            world.setBlock(x + 6, y + 9, z + 4, HorrorReg.bloodleaf, 0, 2);
            world.setBlock(x + 2, y + 9, z + 5, HorrorReg.bloodleaf, 0, 2);
            world.setBlock(x + 3, y + 9, z + 5, HorrorReg.bloodleaf, 0, 2);
            world.setBlock(x + 4, y + 9, z + 5, HorrorReg.bloodleaf, 0, 2);
            world.setBlock(x + 5, y + 9, z + 5, HorrorReg.bloodleaf, 0, 2);
            world.setBlock(x + 3, y + 9, z + 6, HorrorReg.bloodleaf, 0, 2);
            world.setBlock(x + 4, y + 9, z + 6, HorrorReg.bloodleaf, 0, 2);
            world.setBlock(x + 2, y + 10, z + 1, HorrorReg.bloodleaf, 0, 2);
            world.setBlock(x + 3, y + 10, z + 1, HorrorReg.bloodleaf, 0, 2);
            world.setBlock(x + 4, y + 10, z + 1, HorrorReg.bloodleaf, 0, 2);
            world.setBlock(x + 5, y + 10, z + 1, HorrorReg.bloodleaf, 0, 2);
            world.setBlock(x + 1, y + 10, z + 2, HorrorReg.bloodleaf, 0, 2);
            world.setBlock(x + 2, y + 10, z + 2, HorrorReg.bloodleaf, 0, 2);
            world.setBlock(x + 3, y + 10, z + 2, HorrorReg.bloodleaf, 0, 2);
            world.setBlock(x + 4, y + 10, z + 2, HorrorReg.bloodleaf, 0, 2);
            world.setBlock(x + 5, y + 10, z + 2, HorrorReg.bloodleaf, 0, 2);
            world.setBlock(x + 6, y + 10, z + 2, HorrorReg.bloodleaf, 0, 2);
            world.setBlock(x + 1, y + 10, z + 3, HorrorReg.bloodleaf, 0, 2);
            world.setBlock(x + 2, y + 10, z + 3, HorrorReg.bloodleaf, 0, 2);
            world.setBlock(x + 3, y + 10, z + 3, Main.bloodstone, 0, 2);
            world.setBlock(x + 4, y + 10, z + 3, Main.bloodstone, 0, 2);
            world.setBlock(x + 5, y + 10, z + 3, HorrorReg.bloodleaf, 0, 2);
            world.setBlock(x + 6, y + 10, z + 3, HorrorReg.bloodleaf, 0, 2);
            world.setBlock(x + 1, y + 10, z + 4, HorrorReg.bloodleaf, 0, 2);
            world.setBlock(x + 2, y + 10, z + 4, HorrorReg.bloodleaf, 0, 2);
            world.setBlock(x + 3, y + 10, z + 4, Main.bloodstone, 0, 2);
            world.setBlock(x + 4, y + 10, z + 4, Main.bloodstone, 0, 2);
            world.setBlock(x + 5, y + 10, z + 4, HorrorReg.bloodleaf, 0, 2);
            world.setBlock(x + 6, y + 10, z + 4, HorrorReg.bloodleaf, 0, 2);
            world.setBlock(x + 1, y + 10, z + 5, HorrorReg.bloodleaf, 0, 2);
            world.setBlock(x + 2, y + 10, z + 5, HorrorReg.bloodleaf, 0, 2);
            world.setBlock(x + 3, y + 10, z + 5, HorrorReg.bloodleaf, 0, 2);
            world.setBlock(x + 4, y + 10, z + 5, HorrorReg.bloodleaf, 0, 2);
            world.setBlock(x + 5, y + 10, z + 5, HorrorReg.bloodleaf, 0, 2);
            world.setBlock(x + 6, y + 10, z + 5, HorrorReg.bloodleaf, 0, 2);
            world.setBlock(x + 2, y + 10, z + 6, HorrorReg.bloodleaf, 0, 2);
            world.setBlock(x + 3, y + 10, z + 6, HorrorReg.bloodleaf, 0, 2);
            world.setBlock(x + 4, y + 10, z + 6, HorrorReg.bloodleaf, 0, 2);
            world.setBlock(x + 5, y + 10, z + 6, HorrorReg.bloodleaf, 0, 2);
            world.setBlock(x + 3, y + 11, z, HorrorReg.bloodleaf, 0, 2);
            world.setBlock(x + 4, y + 11, z, HorrorReg.bloodleaf, 0, 2);
            world.setBlock(x + 2, y + 11, z + 1, HorrorReg.bloodleaf, 0, 2);
            world.setBlock(x + 3, y + 11, z + 1, HorrorReg.bloodleaf, 0, 2);
            world.setBlock(x + 4, y + 11, z + 1, HorrorReg.bloodleaf, 0, 2);
            world.setBlock(x + 5, y + 11, z + 1, HorrorReg.bloodleaf, 0, 2);
            world.setBlock(x + 1, y + 11, z + 2, HorrorReg.bloodleaf, 0, 2);
            world.setBlock(x + 2, y + 11, z + 2, HorrorReg.bloodleaf, 0, 2);
            world.setBlock(x + 3, y + 11, z + 2, HorrorReg.bloodleaf, 0, 2);
            world.setBlock(x + 4, y + 11, z + 2, HorrorReg.bloodleaf, 0, 2);
            world.setBlock(x + 5, y + 11, z + 2, HorrorReg.bloodleaf, 0, 2);
            world.setBlock(x + 6, y + 11, z + 2, HorrorReg.bloodleaf, 0, 2);
            world.setBlock(x, y + 11, z + 3, HorrorReg.bloodleaf, 0, 2);
            world.setBlock(x + 1, y + 11, z + 3, HorrorReg.bloodleaf, 0, 2);
            world.setBlock(x + 2, y + 11, z + 3, HorrorReg.bloodleaf, 0, 2);
            world.setBlock(x + 3, y + 11, z + 3, Main.bloodstone, 0, 2);
            world.setBlock(x + 4, y + 11, z + 3, Main.bloodstone, 0, 2);
            world.setBlock(x + 5, y + 11, z + 3, HorrorReg.bloodleaf, 0, 2);
            world.setBlock(x + 6, y + 11, z + 3, HorrorReg.bloodleaf, 0, 2);
            world.setBlock(x + 7, y + 11, z + 3, HorrorReg.bloodleaf, 0, 2);
            world.setBlock(x, y + 11, z + 4, HorrorReg.bloodleaf, 0, 2);
            world.setBlock(x + 1, y + 11, z + 4, HorrorReg.bloodleaf, 0, 2);
            world.setBlock(x + 2, y + 11, z + 4, HorrorReg.bloodleaf, 0, 2);
            world.setBlock(x + 3, y + 11, z + 4, Main.bloodstone, 0, 2);
            world.setBlock(x + 4, y + 11, z + 4, Main.bloodstone, 0, 2);
            world.setBlock(x + 5, y + 11, z + 4, HorrorReg.bloodleaf, 0, 2);
            world.setBlock(x + 6, y + 11, z + 4, HorrorReg.bloodleaf, 0, 2);
            world.setBlock(x + 7, y + 11, z + 4, HorrorReg.bloodleaf, 0, 2);
            world.setBlock(x + 1, y + 11, z + 5, HorrorReg.bloodleaf, 0, 2);
            world.setBlock(x + 2, y + 11, z + 5, HorrorReg.bloodleaf, 0, 2);
            world.setBlock(x + 3, y + 11, z + 5, HorrorReg.bloodleaf, 0, 2);
            world.setBlock(x + 4, y + 11, z + 5, HorrorReg.bloodleaf, 0, 2);
            world.setBlock(x + 5, y + 11, z + 5, HorrorReg.bloodleaf, 0, 2);
            world.setBlock(x + 6, y + 11, z + 5, HorrorReg.bloodleaf, 0, 2);
            world.setBlock(x + 2, y + 11, z + 6, HorrorReg.bloodleaf, 0, 2);
            world.setBlock(x + 3, y + 11, z + 6, HorrorReg.bloodleaf, 0, 2);
            world.setBlock(x + 4, y + 11, z + 6, HorrorReg.bloodleaf, 0, 2);
            world.setBlock(x + 5, y + 11, z + 6, HorrorReg.bloodleaf, 0, 2);
            world.setBlock(x + 3, y + 11, z + 7, HorrorReg.bloodleaf, 0, 2);
            world.setBlock(x + 4, y + 11, z + 7, HorrorReg.bloodleaf, 0, 2);
            world.setBlock(x + 3, y + 12, z, HorrorReg.bloodleaf, 0, 2);
            world.setBlock(x + 4, y + 12, z, HorrorReg.bloodleaf, 0, 2);
            world.setBlock(x + 2, y + 12, z + 1, HorrorReg.bloodleaf, 0, 2);
            world.setBlock(x + 3, y + 12, z + 1, HorrorReg.bloodleaf, 0, 2);
            world.setBlock(x + 4, y + 12, z + 1, HorrorReg.bloodleaf, 0, 2);
            world.setBlock(x + 5, y + 12, z + 1, HorrorReg.bloodleaf, 0, 2);
            world.setBlock(x + 1, y + 12, z + 2, HorrorReg.bloodleaf, 0, 2);
            world.setBlock(x + 2, y + 12, z + 2, HorrorReg.bloodleaf, 0, 2);
            world.setBlock(x + 3, y + 12, z + 2, HorrorReg.bloodleaf, 0, 2);
            world.setBlock(x + 4, y + 12, z + 2, HorrorReg.bloodleaf, 0, 2);
            world.setBlock(x + 5, y + 12, z + 2, HorrorReg.bloodleaf, 0, 2);
            world.setBlock(x + 6, y + 12, z + 2, HorrorReg.bloodleaf, 0, 2);
            world.setBlock(x, y + 12, z + 3, HorrorReg.bloodleaf, 0, 2);
            world.setBlock(x + 1, y + 12, z + 3, HorrorReg.bloodleaf, 0, 2);
            world.setBlock(x + 2, y + 12, z + 3, HorrorReg.bloodleaf, 0, 2);
            world.setBlock(x + 3, y + 12, z + 3, Main.bloodstone, 0, 2);
            world.setBlock(x + 4, y + 12, z + 3, Main.bloodstone, 0, 2);
            world.setBlock(x + 5, y + 12, z + 3, HorrorReg.bloodleaf, 0, 2);
            world.setBlock(x + 6, y + 12, z + 3, HorrorReg.bloodleaf, 0, 2);
            world.setBlock(x + 7, y + 12, z + 3, HorrorReg.bloodleaf, 0, 2);
            world.setBlock(x, y + 12, z + 4, HorrorReg.bloodleaf, 0, 2);
            world.setBlock(x + 1, y + 12, z + 4, HorrorReg.bloodleaf, 0, 2);
            world.setBlock(x + 2, y + 12, z + 4, HorrorReg.bloodleaf, 0, 2);
            world.setBlock(x + 3, y + 12, z + 4, Main.bloodstone, 0, 2);
            world.setBlock(x + 4, y + 12, z + 4, Main.bloodstone, 0, 2);
            world.setBlock(x + 5, y + 12, z + 4, HorrorReg.bloodleaf, 0, 2);
            world.setBlock(x + 6, y + 12, z + 4, HorrorReg.bloodleaf, 0, 2);
            world.setBlock(x + 7, y + 12, z + 4, HorrorReg.bloodleaf, 0, 2);
            world.setBlock(x + 1, y + 12, z + 5, HorrorReg.bloodleaf, 0, 2);
            world.setBlock(x + 2, y + 12, z + 5, HorrorReg.bloodleaf, 0, 2);
            world.setBlock(x + 3, y + 12, z + 5, HorrorReg.bloodleaf, 0, 2);
            world.setBlock(x + 4, y + 12, z + 5, HorrorReg.bloodleaf, 0, 2);
            world.setBlock(x + 5, y + 12, z + 5, HorrorReg.bloodleaf, 0, 2);
            world.setBlock(x + 6, y + 12, z + 5, HorrorReg.bloodleaf, 0, 2);
            world.setBlock(x + 2, y + 12, z + 6, HorrorReg.bloodleaf, 0, 2);
            world.setBlock(x + 3, y + 12, z + 6, HorrorReg.bloodleaf, 0, 2);
            world.setBlock(x + 4, y + 12, z + 6, HorrorReg.bloodleaf, 0, 2);
            world.setBlock(x + 5, y + 12, z + 6, HorrorReg.bloodleaf, 0, 2);
            world.setBlock(x + 3, y + 12, z + 7, HorrorReg.bloodleaf, 0, 2);
            world.setBlock(x + 4, y + 12, z + 7, HorrorReg.bloodleaf, 0, 2);
            world.setBlock(x + 3, y + 13, z, HorrorReg.bloodleaf, 0, 2);
            world.setBlock(x + 4, y + 13, z, HorrorReg.bloodleaf, 0, 2);
            world.setBlock(x + 2, y + 13, z + 1, HorrorReg.bloodleaf, 0, 2);
            world.setBlock(x + 3, y + 13, z + 1, HorrorReg.bloodleaf, 0, 2);
            world.setBlock(x + 4, y + 13, z + 1, HorrorReg.bloodleaf, 0, 2);
            world.setBlock(x + 5, y + 13, z + 1, HorrorReg.bloodleaf, 0, 2);
            world.setBlock(x + 1, y + 13, z + 2, HorrorReg.bloodleaf, 0, 2);
            world.setBlock(x + 2, y + 13, z + 2, HorrorReg.bloodleaf, 0, 2);
            world.setBlock(x + 3, y + 13, z + 2, HorrorReg.bloodleaf, 0, 2);
            world.setBlock(x + 4, y + 13, z + 2, HorrorReg.bloodleaf, 0, 2);
            world.setBlock(x + 5, y + 13, z + 2, HorrorReg.bloodleaf, 0, 2);
            world.setBlock(x + 6, y + 13, z + 2, HorrorReg.bloodleaf, 0, 2);
            world.setBlock(x, y + 13, z + 3, HorrorReg.bloodleaf, 0, 2);
            world.setBlock(x + 1, y + 13, z + 3, HorrorReg.bloodleaf, 0, 2);
            world.setBlock(x + 2, y + 13, z + 3, HorrorReg.bloodleaf, 0, 2);
            world.setBlock(x + 3, y + 13, z + 3, Main.bloodstone, 0, 2);
            world.setBlock(x + 4, y + 13, z + 3, Main.bloodstone, 0, 2);
            world.setBlock(x + 5, y + 13, z + 3, HorrorReg.bloodleaf, 0, 2);
            world.setBlock(x + 6, y + 13, z + 3, HorrorReg.bloodleaf, 0, 2);
            world.setBlock(x + 7, y + 13, z + 3, HorrorReg.bloodleaf, 0, 2);
            world.setBlock(x, y + 13, z + 4, HorrorReg.bloodleaf, 0, 2);
            world.setBlock(x + 1, y + 13, z + 4, HorrorReg.bloodleaf, 0, 2);
            world.setBlock(x + 2, y + 13, z + 4, HorrorReg.bloodleaf, 0, 2);
            world.setBlock(x + 3, y + 13, z + 4, Main.bloodstone, 0, 2);
            world.setBlock(x + 4, y + 13, z + 4, Main.bloodstone, 0, 2);
            world.setBlock(x + 5, y + 13, z + 4, HorrorReg.bloodleaf, 0, 2);
            world.setBlock(x + 6, y + 13, z + 4, HorrorReg.bloodleaf, 0, 2);
            world.setBlock(x + 7, y + 13, z + 4, HorrorReg.bloodleaf, 0, 2);
            world.setBlock(x + 1, y + 13, z + 5, HorrorReg.bloodleaf, 0, 2);
            world.setBlock(x + 2, y + 13, z + 5, HorrorReg.bloodleaf, 0, 2);
            world.setBlock(x + 3, y + 13, z + 5, HorrorReg.bloodleaf, 0, 2);
            world.setBlock(x + 4, y + 13, z + 5, HorrorReg.bloodleaf, 0, 2);
            world.setBlock(x + 5, y + 13, z + 5, HorrorReg.bloodleaf, 0, 2);
            world.setBlock(x + 6, y + 13, z + 5, HorrorReg.bloodleaf, 0, 2);
            world.setBlock(x + 2, y + 13, z + 6, HorrorReg.bloodleaf, 0, 2);
            world.setBlock(x + 3, y + 13, z + 6, HorrorReg.bloodleaf, 0, 2);
            world.setBlock(x + 4, y + 13, z + 6, HorrorReg.bloodleaf, 0, 2);
            world.setBlock(x + 5, y + 13, z + 6, HorrorReg.bloodleaf, 0, 2);
            world.setBlock(x + 3, y + 13, z + 7, HorrorReg.bloodleaf, 0, 2);
            world.setBlock(x + 4, y + 13, z + 7, HorrorReg.bloodleaf, 0, 2);
            world.setBlock(x + 2, y + 14, z + 1, HorrorReg.bloodleaf, 0, 2);
            world.setBlock(x + 3, y + 14, z + 1, HorrorReg.bloodleaf, 0, 2);
            world.setBlock(x + 4, y + 14, z + 1, HorrorReg.bloodleaf, 0, 2);
            world.setBlock(x + 5, y + 14, z + 1, HorrorReg.bloodleaf, 0, 2);
            world.setBlock(x + 1, y + 14, z + 2, HorrorReg.bloodleaf, 0, 2);
            world.setBlock(x + 2, y + 14, z + 2, HorrorReg.bloodleaf, 0, 2);
            world.setBlock(x + 3, y + 14, z + 2, HorrorReg.bloodleaf, 0, 2);
            world.setBlock(x + 4, y + 14, z + 2, HorrorReg.bloodleaf, 0, 2);
            world.setBlock(x + 5, y + 14, z + 2, HorrorReg.bloodleaf, 0, 2);
            world.setBlock(x + 6, y + 14, z + 2, HorrorReg.bloodleaf, 0, 2);
            world.setBlock(x + 1, y + 14, z + 3, HorrorReg.bloodleaf, 0, 2);
            world.setBlock(x + 2, y + 14, z + 3, HorrorReg.bloodleaf, 0, 2);
            world.setBlock(x + 3, y + 14, z + 3, HorrorReg.bloodleaf, 0, 2);
            world.setBlock(x + 4, y + 14, z + 3, HorrorReg.bloodleaf, 0, 2);
            world.setBlock(x + 5, y + 14, z + 3, HorrorReg.bloodleaf, 0, 2);
            world.setBlock(x + 6, y + 14, z + 3, HorrorReg.bloodleaf, 0, 2);
            world.setBlock(x + 1, y + 14, z + 4, HorrorReg.bloodleaf, 0, 2);
            world.setBlock(x + 2, y + 14, z + 4, HorrorReg.bloodleaf, 0, 2);
            world.setBlock(x + 3, y + 14, z + 4, HorrorReg.bloodleaf, 0, 2);
            world.setBlock(x + 4, y + 14, z + 4, HorrorReg.bloodleaf, 0, 2);
            world.setBlock(x + 5, y + 14, z + 4, HorrorReg.bloodleaf, 0, 2);
            world.setBlock(x + 6, y + 14, z + 4, HorrorReg.bloodleaf, 0, 2);
            world.setBlock(x + 1, y + 14, z + 5, HorrorReg.bloodleaf, 0, 2);
            world.setBlock(x + 2, y + 14, z + 5, HorrorReg.bloodleaf, 0, 2);
            world.setBlock(x + 3, y + 14, z + 5, HorrorReg.bloodleaf, 0, 2);
            world.setBlock(x + 4, y + 14, z + 5, HorrorReg.bloodleaf, 0, 2);
            world.setBlock(x + 5, y + 14, z + 5, HorrorReg.bloodleaf, 0, 2);
            world.setBlock(x + 6, y + 14, z + 5, HorrorReg.bloodleaf, 0, 2);
            world.setBlock(x + 2, y + 14, z + 6, HorrorReg.bloodleaf, 0, 2);
            world.setBlock(x + 3, y + 14, z + 6, HorrorReg.bloodleaf, 0, 2);
            world.setBlock(x + 4, y + 14, z + 6, HorrorReg.bloodleaf, 0, 2);
            world.setBlock(x + 5, y + 14, z + 6, HorrorReg.bloodleaf, 0, 2);
            world.setBlock(x + 3, y + 15, z + 1, HorrorReg.bloodleaf, 0, 2);
            world.setBlock(x + 4, y + 15, z + 1, HorrorReg.bloodleaf, 0, 2);
            world.setBlock(x + 2, y + 15, z + 2, HorrorReg.bloodleaf, 0, 2);
            world.setBlock(x + 3, y + 15, z + 2, HorrorReg.bloodleaf, 0, 2);
            world.setBlock(x + 4, y + 15, z + 2, HorrorReg.bloodleaf, 0, 2);
            world.setBlock(x + 5, y + 15, z + 2, HorrorReg.bloodleaf, 0, 2);
            world.setBlock(x + 1, y + 15, z + 3, HorrorReg.bloodleaf, 0, 2);
            world.setBlock(x + 2, y + 15, z + 3, HorrorReg.bloodleaf, 0, 2);
            world.setBlock(x + 3, y + 15, z + 3, HorrorReg.bloodleaf, 0, 2);
            world.setBlock(x + 4, y + 15, z + 3, HorrorReg.bloodleaf, 0, 2);
            world.setBlock(x + 5, y + 15, z + 3, HorrorReg.bloodleaf, 0, 2);
            world.setBlock(x + 6, y + 15, z + 3, HorrorReg.bloodleaf, 0, 2);
            world.setBlock(x + 1, y + 15, z + 4, HorrorReg.bloodleaf, 0, 2);
            world.setBlock(x + 2, y + 15, z + 4, HorrorReg.bloodleaf, 0, 2);
            world.setBlock(x + 3, y + 15, z + 4, HorrorReg.bloodleaf, 0, 2);
            world.setBlock(x + 4, y + 15, z + 4, HorrorReg.bloodleaf, 0, 2);
            world.setBlock(x + 5, y + 15, z + 4, HorrorReg.bloodleaf, 0, 2);
            world.setBlock(x + 6, y + 15, z + 4, HorrorReg.bloodleaf, 0, 2);
            world.setBlock(x + 2, y + 15, z + 5, HorrorReg.bloodleaf, 0, 2);
            world.setBlock(x + 3, y + 15, z + 5, HorrorReg.bloodleaf, 0, 2);
            world.setBlock(x + 4, y + 15, z + 5, HorrorReg.bloodleaf, 0, 2);
            world.setBlock(x + 5, y + 15, z + 5, HorrorReg.bloodleaf, 0, 2);
            world.setBlock(x + 3, y + 15, z + 6, HorrorReg.bloodleaf, 0, 2);
            world.setBlock(x + 4, y + 15, z + 6, HorrorReg.bloodleaf, 0, 2);
            world.setBlock(x + 3, y + 16, z + 2, HorrorReg.bloodleaf, 0, 2);
            world.setBlock(x + 4, y + 16, z + 2, HorrorReg.bloodleaf, 0, 2);
            world.setBlock(x + 2, y + 16, z + 3, HorrorReg.bloodleaf, 0, 2);
            world.setBlock(x + 3, y + 16, z + 3, HorrorReg.bloodleaf, 0, 2);
            world.setBlock(x + 4, y + 16, z + 3, HorrorReg.bloodleaf, 0, 2);
            world.setBlock(x + 5, y + 16, z + 3, HorrorReg.bloodleaf, 0, 2);
            world.setBlock(x + 2, y + 16, z + 4, HorrorReg.bloodleaf, 0, 2);
            world.setBlock(x + 3, y + 16, z + 4, HorrorReg.bloodleaf, 0, 2);
            world.setBlock(x + 4, y + 16, z + 4, HorrorReg.bloodleaf, 0, 2);
            world.setBlock(x + 5, y + 16, z + 4, HorrorReg.bloodleaf, 0, 2);
            world.setBlock(x + 3, y + 16, z + 5, HorrorReg.bloodleaf, 0, 2);
            world.setBlock(x + 4, y + 16, z + 5, HorrorReg.bloodleaf, 0, 2);
            world.setBlock(x + 3, y + 17, z + 3, HorrorReg.bloodleaf, 0, 2);
            world.setBlock(x + 4, y + 17, z + 3, HorrorReg.bloodleaf, 0, 2);
            world.setBlock(x + 3, y + 17, z + 4, HorrorReg.bloodleaf, 0, 2);
            world.setBlock(x + 4, y + 17, z + 4, HorrorReg.bloodleaf, 0, 2);
        }
        return true;
    }
    
    public void generate(final Random random, int x, final int z, final World world, final IChunkProvider chunkGenerator, final IChunkProvider chunkProvider) {
        final int chunkX = x * 16 + random.nextInt(16);
        final int chunkZ = z * 16 + random.nextInt(16);
        final int chunkY = world.getHeightValue(chunkX, chunkZ);
        final int i = 0;
        while (i < 10) {
            this.generate(world, random, chunkX, chunkY, chunkZ);
            ++x;
        }
    }
}
